[2025-10-11T22:17:13.329Z] {"e":"depthUpdate","E":1760221033014,"s":"BTCUSDT","U":77925961861,"u":77925962301,"b":[["110836.55000000","7.18503000"],["110836.24000000","0.00000000"],["110836.23000000","0.10271000"],["110836.22000000","0.00000000"],["110836.21000000","0.00000000"],["110836.20000000","0.00000000"],["110836.19000000","0.29750000"],["110836.18000000","0.00000000"],["110836.17000000","0.00000000"],["110834.12000000","0.04061000"],["110833.68000000","0.00000000"],["110833.12000000","0.00000000"],["110833.02000000","0.00000000"],["110833.01000000","0.37422000"],["110832.64000000","0.06651000"],["110831.83000000","0.04072000"],["110831.78000000","0.00125000"],["110830.96000000","0.18026000"],["110830.91000000","0.00000000"],["110830.72000000","0.04018000"],["110828.54000000","0.00000000"],["110828.20000000","0.00000000"],["110828.06000000","0.01800000"],["110827.53000000","0.00000000"],["110827.44000000","0.18026000"],["110825.46000000","0.00300000"],["110824.70000000","0.00005000"],["110820.86000000","0.04800000"],["110819.68000000","0.00000000"],["110818.52000000","0.04800000"],["110814.00000000","0.00532000"],["110806.17000000","0.00000000"],["110805.23000000","0.22546000"],["110803.81000000","0.00000000"],["110794.55000000","0.00000000"],["110758.62000000","0.10324000"],["110753.70000000","0.00000000"],["110750.01000000","0.33398000"],["110749.02000000","0.00000000"],["110746.09000000","0.02341000"],["110740.78000000","0.03277000"],["110739.62000000","0.00000000"],["110734.01000000","0.08294000"],["110732.40000000","0.00000000"],["110728.33000000","0.00000000"],["110727.55000000","0.09641000"],["110726.70000000","0.00000000"],["110725.91000000","0.02888000"],["110724.38000000","0.00000000"],["110720.85000000","0.00000000"],["110717.39000000","0.07712000"],["110708.37000000","0.00000000"],["110695.83000000","0.99026000"],["110682.41000000","0.00000000"],["110681.90000000","0.36770000"],["110681.01000000","0.00000000"],["110680.24000000","0.00000000"],["110615.58000000","0.04297000"],["110610.06000000","0.02998000"],["110576.70000000","0.00587000"],["110570.56000000","0.02998000"],["110566.14000000","0.00000000"],["109174.00000000","0.00100000"],["109173.63000000","0.00000000"],["105460.97000000","0.09848000"],["99752.00000000","0.00010000"],["88669.24000000","0.00037000"]],"a":[["110836.56000000","0.01408000"],["110836.57000000","0.00065000"],["110836.64000000","0.00010000"],["110837.20000000","0.00005000"],["110839.91000000","0.00010000"],["110840.03000000","0.00000000"],["110841.69000000","0.00000000"],["110841.70000000","0.00563000"],["110842.27000000","0.01814000"],["110842.39000000","0.05573000"],["110842.40000000","0.00000000"],["110842.44000000","0.00310000"],["110843.48000000","0.00010000"],["110843.49000000","0.12805000"],["110843.50000000","0.00010000"],["110843.51000000","0.21845000"],["110843.52000000","0.00010000"],["110843.53000000","0.08010000"],["110843.62000000","0.00010000"],["110843.63000000","0.54005000"],["110844.20000000","0.00149000"],["110846.96000000","0.00000000"],["110846.97000000","0.00000000"],["110847.51000000","0.17216000"],["110847.52000000","0.00000000"],["110847.53000000","0.08386000"],["110847.55000000","0.00000000"],["110847.63000000","0.03613000"],["110847.68000000","0.00000000"],["110847.88000000","0.00000000"],["110848.48000000","0.00005000"],["110848.78000000","0.00000000"],["110849.74000000","0.00154000"],["110850.85000000","0.18710000"],["110851.02000000","0.05285000"],["110851.16000000","0.06240000"],["110851.42000000","0.29736000"],["110851.48000000","0.02708000"],["110851.64000000","0.00000000"],["110852.79000000","0.04503000"],["110853.78000000","0.00000000"],["110854.01000000","0.04070000"],["110855.12000000","0.03997000"],["110856.01000000","0.00000000"],["110856.02000000","0.00000000"],["110856.09000000","0.32438000"],["110856.60000000","0.00000000"],["110856.64000000","0.11886000"],["110859.27000000","0.18026000"],["110859.28000000","0.06646000"],["110859.37000000","0.00450000"],["110859.40000000","0.00000000"],["110863.42000000","0.00000000"],["110863.63000000","0.51135000"],["110863.76000000","0.00000000"],["110864.00000000","0.00005000"],["110864.48000000","0.01964000"],["110866.07000000","0.32435000"],["110867.43000000","3.24539000"],["110867.44000000","0.30235000"],["110867.45000000","0.00000000"],["110869.61000000","0.08567000"],["110871.29000000","0.00000000"],["110872.70000000","0.00000000"],["110886.08000000","0.02800000"],["110899.08000000","0.06779000"],["110917.36000000","1.19644000"],["110923.38000000","0.00000000"],["110923.39000000","0.00000000"],["110923.85000000","0.00000000"],["110931.94000000","0.00005000"],["110936.50000000","0.03538000"],["110941.36000000","0.00000000"],["110950.55000000","0.21132000"],["110965.76000000","0.00000000"],["110966.80000000","0.07712000"],["110967.10000000","0.05430000"],["111042.28000000","0.00000000"],["111055.68000000","0.00331000"],["111079.01000000","0.04947000"],["111118.58000000","0.00000000"],["111315.41000000","0.00000000"],["111316.17000000","0.00000000"],["111329.58000000","0.00082000"],["112499.11000000","0.00100000"],["128001.97000000","0.00040000"]]}
[2025-10-11T22:17:14.328Z] {"e":"depthUpdate","E":1760221034014,"s":"BTCUSDT","U":77925962302,"u":77925962611,"b":[["110836.55000000","6.87404000"],["110836.54000000","0.00010000"],["110836.24000000","0.00010000"],["110836.20000000","0.00010000"],["110835.79000000","0.01358000"],["110834.34000000","0.00361000"],["110834.13000000","0.00010000"],["110834.12000000","0.04066000"],["110833.88000000","0.00005000"],["110833.68000000","0.00010000"],["110833.67000000","0.06222000"],["110833.12000000","0.00005000"],["110833.01000000","0.27967000"],["110833.00000000","0.32450000"],["110832.68000000","0.00541000"],["110832.64000000","0.06646000"],["110831.83000000","0.04067000"],["110831.78000000","0.00000000"],["110830.96000000","0.00000000"],["110830.25000000","0.00000000"],["110830.07000000","0.08567000"],["110829.56000000","0.32446000"],["110827.44000000","0.18026000"],["110826.76000000","0.00005000"],["110825.31000000","0.15543000"],["110823.66000000","0.00005000"],["110822.46000000","0.00000000"],["110816.13000000","0.00149000"],["110815.02000000","0.00000000"],["110805.43000000","0.22546000"],["110805.23000000","0.00000000"],["110793.02000000","0.04800000"],["110790.67000000","0.04800000"],["110768.01000000","0.02998000"],["110761.59000000","0.02998000"],["110743.47000000","0.28033000"],["110728.42000000","0.00000000"],["110728.01000000","0.22546000"],["110727.61000000","0.00000000"],["110727.55000000","0.00000000"],["110727.39000000","0.00000000"],["110727.06000000","0.00000000"],["110727.04000000","0.00000000"],["110724.38000000","0.00000000"],["110724.08000000","0.09641000"],["110720.02000000","0.00167000"],["110702.83000000","0.00000000"],["110700.14000000","0.51971000"],["110666.13000000","0.14293000"],["110609.13000000","0.00066000"],["110592.04000000","0.00000000"],["110550.00000000","0.00027000"],["110529.44000000","0.00000000"],["110520.24000000","0.00333000"],["110000.00000000","11.10646000"],["109174.00000000","0.00100000"],["105472.12000000","0.00000000"],["102500.00000000","27.86671000"],["99752.00000000","0.00010000"],["88669.24000000","0.00037000"],["42000.00000000","1.48198000"]],"a":[["110836.56000000","0.96320000"],["110836.57000000","0.00075000"],["110836.64000000","0.00010000"],["110837.20000000","0.00000000"],["110839.58000000","0.00000000"],["110839.77000000","0.00000000"],["110839.91000000","0.00000000"],["110840.22000000","0.00077000"],["110840.43000000","0.00551000"],["110840.53000000","0.00005000"],["110841.54000000","0.00727000"],["110841.70000000","0.00563000"],["110841.77000000","0.00000000"],["110842.25000000","0.00000000"],["110842.26000000","0.00010000"],["110842.27000000","0.01819000"],["110842.38000000","0.00000000"],["110842.39000000","0.00000000"],["110843.48000000","0.00000000"],["110843.49000000","0.00000000"],["110843.53000000","0.08005000"],["110843.62000000","0.00010000"],["110843.63000000","0.54005000"],["110844.20000000","0.00154000"],["110845.04000000","0.00005000"],["110845.05000000","0.29743000"],["110846.97000000","0.04508000"],["110847.49000000","0.39528000"],["110847.50000000","0.45036000"],["110847.51000000","0.00000000"],["110847.53000000","0.08381000"],["110847.60000000","0.00000000"],["110847.63000000","0.03608000"],["110847.65000000","0.45000000"],["110848.85000000","0.00005000"],["110851.00000000","0.00328000"],["110851.02000000","0.05280000"],["110851.30000000","0.32440000"],["110851.42000000","0.00000000"],["110852.79000000","0.00000000"],["110853.48000000","0.00000000"],["110863.63000000","1.36234000"],["110863.76000000","3.24539000"],["110866.07000000","0.00000000"],["110884.26000000","0.18026000"],["110909.78000000","0.06057000"],["110916.55000000","0.00000000"],["110922.55000000","1.22442000"],["110925.33000000","0.00100000"],["110925.34000000","0.00100000"],["110929.05000000","0.03538000"],["110936.50000000","0.00000000"],["110966.79000000","0.11213000"],["110967.77000000","0.00000000"],["111055.68000000","0.00000000"],["111058.81000000","0.00331000"],["111068.05000000","0.00000000"],["111329.58000000","0.00000000"],["111332.71000000","0.00082000"],["111341.95000000","0.00000000"],["111359.54000000","0.00046000"],["111398.32000000","0.00000000"],["112454.99000000","0.00009000"],["112499.11000000","0.00100000"],["128001.97000000","0.00040000"]]}
[2025-10-11T22:17:15.328Z] {"e":"depthUpdate","E":1760221035014,"s":"BTCUSDT","U":77925962612,"u":77925962946,"b":[["110836.55000000","5.37736000"],["110836.54000000","0.00030000"],["110836.24000000","0.00000000"],["110836.23000000","0.00000000"],["110836.21000000","0.00010000"],["110836.20000000","0.11272000"],["110835.79000000","0.01358000"],["110834.13000000","0.00000000"],["110834.12000000","0.00000000"],["110833.12000000","0.18033000"],["110833.11000000","0.00005000"],["110833.02000000","0.00005000"],["110832.64000000","0.00000000"],["110831.83000000","0.00000000"],["110830.61000000","0.00000000"],["110830.07000000","0.00000000"],["110829.87000000","0.00005000"],["110829.56000000","0.00000000"],["110829.53000000","0.00000000"],["110828.06000000","0.00000000"],["110828.02000000","0.00000000"],["110827.44000000","0.00000000"],["110825.47000000","0.25221000"],["110825.46000000","0.11573000"],["110825.31000000","0.00000000"],["110825.29000000","0.00000000"],["110825.07000000","0.04509000"],["110824.11000000","0.00000000"],["110823.73000000","0.08567000"],["110822.32000000","0.32448000"],["110821.95000000","0.00000000"],["110821.35000000","0.00005000"],["110820.78000000","0.00000000"],["110820.59000000","0.00000000"],["110820.56000000","0.00005000"],["110808.28000000","0.00000000"],["110806.97000000","0.00000000"],["110804.28000000","0.00000000"],["110803.85000000","0.00000000"],["110796.33000000","0.00000000"],["110795.88000000","0.00000000"],["110758.97000000","0.00324000"],["110757.56000000","0.56795000"],["110755.14000000","0.04297000"],["110750.09000000","3.24539000"],["110748.01000000","0.12292000"],["110743.48000000","3.24539000"],["110740.78000000","0.00000000"],["110733.43000000","0.33104000"],["110727.68000000","0.03277000"],["110726.76000000","0.00000000"],["110724.08000000","0.00000000"],["110723.60000000","0.00000000"],["110691.67000000","0.02616000"],["110681.51000000","0.08795000"],["110677.44000000","0.14289000"],["110576.69000000","0.00000000"],["110520.24000000","0.00000000"],["110510.71000000","0.00333000"],["109174.00000000","0.00100000"],["99752.00000000","0.00010000"],["88669.24000000","0.00037000"]],"a":[["110836.56000000","3.62886000"],["110836.57000000","0.00050000"],["110837.30000000","0.00010000"],["110837.31000000","0.04404000"],["110841.70000000","0.00563000"],["110841.83000000","0.29739000"],["110842.20000000","0.00000000"],["110842.21000000","0.00000000"],["110843.50000000","0.00410000"],["110843.63000000","0.54005000"],["110844.82000000","0.00000000"],["110844.83000000","0.00005000"],["110845.04000000","0.00000000"],["110845.05000000","0.00000000"],["110846.80000000","0.32441000"],["110846.97000000","0.04503000"],["110849.13000000","0.00000000"],["110849.22000000","0.00000000"],["110849.74000000","0.00149000"],["110850.85000000","0.08967000"],["110851.30000000","0.00000000"],["110851.43000000","0.32440000"],["110851.48000000","0.02708000"],["110855.84000000","0.18026000"],["110856.00000000","0.00400000"],["110856.59000000","1.32837000"],["110860.00000000","3.24544000"],["110860.90000000","0.00000000"],["110861.54000000","0.00000000"],["110864.76000000","0.00000000"],["110867.42000000","1.29668000"],["110867.44000000","0.00000000"],["110875.02000000","0.00000000"],["110910.70000000","0.03538000"],["110919.68000000","0.08160000"],["110928.98000000","0.15818000"],["110929.05000000","0.00000000"],["110931.85000000","0.00000000"],["110972.44000000","0.05536000"],["111049.23000000","0.00331000"],["111058.81000000","0.00000000"],["111073.39000000","0.00000000"],["111301.78000000","0.00000000"],["111308.13000000","0.67153000"],["111323.12000000","0.00082000"],["111332.71000000","0.00000000"],["111359.54000000","0.00000000"],["111398.32000000","0.00046000"],["112499.11000000","0.00100000"],["128001.97000000","0.03006000"]]}
[2025-10-11T22:17:16.328Z] {"e":"depthUpdate","E":1760221036014,"s":"BTCUSDT","U":77925962947,"u":77925963516,"b":[["110836.55000000","3.76423000"],["110836.54000000","0.00015000"],["110836.21000000","0.00000000"],["110836.20000000","0.00000000"],["110836.19000000","0.00000000"],["110835.80000000","0.00010000"],["110835.79000000","0.01358000"],["110835.72000000","0.00010000"],["110835.71000000","0.29746000"],["110833.67000000","0.06222000"],["110833.13000000","0.00000000"],["110833.12000000","0.00000000"],["110833.11000000","0.00000000"],["110833.02000000","0.00000000"],["110833.01000000","0.00000000"],["110833.00000000","0.00000000"],["110832.87000000","0.00000000"],["110832.68000000","0.00546000"],["110830.72000000","0.00000000"],["110829.46000000","0.00010000"],["110829.45000000","0.15724000"],["110829.44000000","0.18029000"],["110829.43000000","0.00000000"],["110829.16000000","0.32446000"],["110829.12000000","0.04502000"],["110828.00000000","0.00000000"],["110827.61000000","0.00000000"],["110827.53000000","0.00000000"],["110827.52000000","0.00000000"],["110827.45000000","0.00000000"],["110827.44000000","0.04068000"],["110827.07000000","0.36750000"],["110827.06000000","0.00000000"],["110826.72000000","0.00000000"],["110826.50000000","0.04008000"],["110825.47000000","0.00000000"],["110825.46000000","0.45300000"],["110824.00000000","0.18026000"],["110823.89000000","0.00000000"],["110822.32000000","0.00000000"],["110820.77000000","0.00333000"],["110820.63000000","0.59983000"],["110820.62000000","0.45036000"],["110820.61000000","0.18026000"],["110820.60000000","0.00000000"],["110820.33000000","0.06646000"],["110819.92000000","0.11273000"],["110819.35000000","0.32449000"],["110818.99000000","0.32449000"],["110818.63000000","0.00070000"],["110818.08000000","0.00000000"],["110817.78000000","0.00000000"],["110817.77000000","0.00000000"],["110817.26000000","0.00073000"],["110815.57000000","0.00005000"],["110812.38000000","0.20198000"],["110810.00000000","0.28349000"],["110809.05000000","0.00000000"],["110804.29000000","1.23981000"],["110802.64000000","0.13527000"],["110802.07000000","0.00000000"],["110800.98000000","0.04000000"],["110798.17000000","1.22240000"],["110795.88000000","0.00000000"],["110794.06000000","0.13527000"],["110791.76000000","0.02998000"],["110791.17000000","0.00000000"],["110790.89000000","0.45000000"],["110789.49000000","0.00935000"],["110788.26000000","0.00157000"],["110787.86000000","0.02998000"],["110785.45000000","0.04416000"],["110784.51000000","0.02998000"],["110781.61000000","0.02998000"],["110776.70000000","3.30535000"],["110771.18000000","0.21024000"],["110766.87000000","0.03134000"],["110760.01000000","0.05996000"],["110759.92000000","0.00000000"],["110752.79000000","0.02998000"],["110750.10000000","1.34277000"],["110750.01000000","0.00000000"],["110744.22000000","0.00000000"],["110744.01000000","0.04297000"],["110740.56000000","0.13527000"],["110731.98000000","0.13527000"],["110729.36000000","0.04297000"],["110725.91000000","0.00000000"],["110720.03000000","0.00167000"],["110720.02000000","0.00000000"],["110707.28000000","0.00000000"],["110706.43000000","0.03400000"],["110700.14000000","0.19024000"],["110695.83000000","0.00000000"],["110681.90000000","0.64272000"],["110680.74000000","0.99090000"],["110677.14000000","0.08795000"],["110609.14000000","0.00066000"],["110609.13000000","0.00000000"],["110586.31000000","4.70427000"],["110510.71000000","0.00000000"],["110480.86000000","0.00333000"],["110242.49000000","0.02298000"],["109174.00000000","0.00100000"],["99752.00000000","0.00030000"],["95628.15000000","0.00009000"],["88669.24000000","0.00037000"],["42000.00000000","1.48098000"]],"a":[["110836.56000000","4.23919000"],["110836.57000000","0.00050000"],["110837.31000000","0.04409000"],["110838.10000000","0.00000000"],["110838.68000000","0.00010000"],["110838.69000000","0.34657000"],["110838.70000000","0.29745000"],["110838.81000000","0.00085000"],["110839.26000000","0.00000000"],["110839.27000000","0.00000000"],["110839.42000000","0.00005000"],["110839.47000000","0.00000000"],["110840.09000000","0.04005000"],["110840.22000000","0.00000000"],["110840.37000000","0.00000000"],["110840.38000000","0.00000000"],["110840.43000000","0.00556000"],["110840.53000000","0.00000000"],["110841.25000000","0.01809000"],["110841.70000000","0.00563000"],["110841.71000000","0.00274000"],["110841.83000000","0.00000000"],["110841.90000000","0.01809000"],["110842.10000000","0.00000000"],["110842.26000000","0.00000000"],["110842.27000000","0.01809000"],["110842.44000000","0.00315000"],["110843.50000000","0.00400000"],["110843.51000000","0.00000000"],["110843.52000000","0.00000000"],["110843.53000000","0.08000000"],["110843.62000000","0.00000000"],["110843.63000000","0.54000000"],["110844.20000000","0.00159000"],["110844.28000000","0.04526000"],["110844.37000000","0.03996000"],["110844.65000000","0.05007000"],["110844.78000000","0.32442000"],["110844.82000000","0.04521000"],["110844.83000000","0.00000000"],["110845.48000000","0.04076000"],["110846.23000000","0.61578000"],["110846.24000000","0.06646000"],["110846.74000000","0.32441000"],["110846.79000000","0.18026000"],["110846.80000000","0.00000000"],["110846.97000000","0.04508000"],["110847.47000000","0.00000000"],["110847.49000000","0.00000000"],["110847.53000000","0.08381000"],["110847.56000000","0.00000000"],["110847.63000000","0.03613000"],["110847.64000000","0.11723000"],["110847.70000000","0.00000000"],["110848.27000000","0.30417000"],["110848.28000000","0.00313000"],["110848.85000000","0.00000000"],["110850.51000000","0.35573000"],["110850.52000000","0.32440000"],["110850.85000000","0.00000000"],["110850.86000000","0.00332000"],["110851.00000000","0.00000000"],["110851.43000000","0.00000000"],["110851.80000000","0.00000000"],["110852.38000000","0.18026000"],["110853.29000000","0.00000000"],["110854.01000000","0.00000000"],["110854.85000000","0.32444000"],["110855.12000000","0.00000000"],["110856.09000000","0.00000000"],["110856.57000000","2.22334000"],["110856.58000000","3.24539000"],["110856.59000000","0.00000000"],["110858.33000000","0.00000000"],["110859.37000000","0.00000000"],["110859.41000000","0.00000000"],["110863.50000000","0.00000000"],["110864.48000000","0.00000000"],["110864.56000000","0.01964000"],["110871.53000000","0.00000000"],["110878.00000000","1.19264000"],["110884.04000000","0.00000000"],["110885.50000000","0.03150000"],["110888.83000000","0.12245000"],["110896.30000000","0.04507000"],["110897.20000000","0.00000000"],["110898.57000000","0.03538000"],["110902.02000000","0.00000000"],["110903.70000000","0.00000000"],["110910.70000000","0.00000000"],["110913.58000000","0.13522000"],["110922.55000000","0.27438000"],["110925.19000000","0.00000000"],["110966.93000000","0.00000000"],["110992.68000000","0.13755000"],["111001.70000000","0.39394000"],["111004.06000000","0.99473000"],["111019.23000000","0.00331000"],["111049.23000000","0.00000000"],["111081.47000000","4.73901000"],["111085.24000000","0.18174000"],["111101.91000000","0.00000000"],["111107.29000000","0.00000000"],["111293.09000000","0.00082000"],["111308.13000000","0.00000000"],["111323.12000000","0.00000000"],["112499.11000000","0.00105000"],["128001.97000000","0.03006000"]]}
[2025-10-11T22:17:17.329Z] {"e":"depthUpdate","E":1760221037014,"s":"BTCUSDT","U":77925963517,"u":77925964253,"b":[["110836.55000000","4.46180000"],["110836.54000000","0.00000000"],["110836.39000000","0.00907000"],["110836.18000000","0.00010000"],["110836.17000000","0.01358000"],["110835.80000000","0.00000000"],["110835.79000000","0.00010000"],["110835.78000000","0.10865000"],["110835.77000000","0.29746000"],["110835.72000000","0.00000000"],["110835.71000000","0.00000000"],["110833.68000000","0.00000000"],["110833.67000000","0.06222000"],["110833.12000000","0.00000000"],["110833.11000000","0.04514000"],["110832.84000000","0.00000000"],["110832.83000000","0.00000000"],["110832.68000000","0.00546000"],["110832.54000000","0.33648000"],["110832.53000000","0.00000000"],["110832.52000000","0.32445000"],["110831.32000000","0.00000000"],["110830.63000000","0.06646000"],["110830.54000000","0.00013000"],["110830.47000000","0.00000000"],["110830.46000000","0.01805000"],["110830.00000000","0.00400000"],["110829.99000000","0.32446000"],["110829.46000000","0.00000000"],["110829.45000000","0.00000000"],["110829.44000000","0.00000000"],["110829.32000000","0.32446000"],["110829.16000000","0.00000000"],["110829.12000000","0.04502000"],["110827.99000000","0.00000000"],["110827.65000000","0.18026000"],["110827.44000000","0.04063000"],["110827.22000000","0.01964000"],["110827.07000000","0.36750000"],["110827.03000000","0.00000000"],["110826.72000000","0.01796000"],["110825.07000000","0.00000000"],["110824.24000000","0.18026000"],["110824.00000000","0.00000000"],["110823.73000000","0.00000000"],["110822.00000000","0.00327000"],["110820.77000000","0.00000000"],["110820.65000000","0.38825000"],["110820.64000000","0.63062000"],["110820.63000000","0.00000000"],["110820.62000000","0.00000000"],["110820.61000000","0.00000000"],["110819.92000000","0.00000000"],["110819.62000000","0.00000000"],["110819.35000000","0.00000000"],["110818.99000000","0.00000000"],["110818.63000000","0.00000000"],["110817.26000000","0.00000000"],["110812.18000000","0.13527000"],["110809.17000000","0.04000000"],["110808.11000000","3.24539000"],["110805.43000000","0.00000000"],["110804.97000000","0.18031000"],["110804.31000000","2.24893000"],["110804.30000000","3.24539000"],["110804.29000000","0.00000000"],["110804.10000000","0.00000000"],["110800.98000000","0.00000000"],["110798.30000000","0.00000000"],["110796.08000000","0.00000000"],["110794.06000000","0.00000000"],["110789.99000000","0.22546000"],["110788.87000000","0.07200000"],["110787.64000000","0.07200000"],["110766.87000000","0.02998000"],["110765.76000000","0.00000000"],["110758.48000000","0.00000000"],["110750.25000000","0.00000000"],["110750.19000000","0.00000000"],["110750.10000000","0.00000000"],["110750.09000000","0.00000000"],["110747.40000000","0.13527000"],["110746.09000000","0.00000000"],["110744.09000000","0.00000000"],["110744.01000000","0.08594000"],["110743.49000000","0.00000000"],["110743.48000000","0.00000000"],["110743.47000000","0.00000000"],["110742.06000000","0.00000000"],["110737.53000000","0.00000000"],["110736.94000000","0.03277000"],["110733.43000000","0.35445000"],["110733.30000000","0.00000000"],["110732.07000000","0.00000000"],["110731.98000000","0.00000000"],["110729.37000000","0.04297000"],["110729.36000000","0.04297000"],["110728.76000000","0.00000000"],["110728.70000000","0.18031000"],["110728.26000000","0.09641000"],["110728.01000000","0.00000000"],["110727.94000000","0.00000000"],["110727.68000000","0.00000000"],["110726.90000000","0.00000000"],["110726.51000000","0.00000000"],["110722.52000000","0.00000000"],["110720.49000000","0.00000000"],["110718.88000000","0.00000000"],["110706.43000000","0.00000000"],["110697.12000000","0.00000000"],["110669.39000000","0.22061000"],["110480.86000000","0.00000000"],["110480.76000000","0.00333000"],["110467.14000000","0.00000000"],["110444.84000000","0.00000000"],["110000.00000000","11.10673000"],["109174.00000000","0.00100000"],["103188.00000000","0.05714000"],["101969.64000000","0.00000000"],["99752.00000000","0.00010000"],["88669.24000000","0.00037000"],["33000.00000000","3.75190000"]],"a":[["110836.56000000","0.88126000"],["110836.57000000","0.00025000"],["110836.72000000","0.00912000"],["110836.93000000","0.00010000"],["110836.94000000","0.01363000"],["110837.20000000","0.00005000"],["110837.30000000","0.00000000"],["110837.31000000","0.00000000"],["110838.68000000","0.00000000"],["110838.69000000","0.00000000"],["110838.70000000","0.00000000"],["110840.08000000","0.00000000"],["110840.09000000","0.00000000"],["110840.43000000","0.00551000"],["110841.15000000","0.00000000"],["110841.25000000","0.00000000"],["110841.70000000","0.00563000"],["110841.71000000","0.00264000"],["110841.90000000","0.00000000"],["110842.24000000","0.00000000"],["110842.27000000","0.00005000"],["110842.44000000","0.00315000"],["110842.64000000","0.00010000"],["110842.65000000","0.01814000"],["110843.50000000","0.00000000"],["110843.51000000","0.00010000"],["110843.52000000","0.18577000"],["110843.53000000","0.08010000"],["110843.62000000","0.00010000"],["110843.63000000","0.54005000"],["110843.87000000","0.29738000"],["110844.20000000","0.00154000"],["110844.28000000","0.00005000"],["110844.37000000","0.00000000"],["110844.50000000","0.00000000"],["110844.51000000","0.00000000"],["110844.64000000","0.00000000"],["110844.78000000","0.00000000"],["110844.82000000","0.00000000"],["110845.48000000","0.00000000"],["110846.23000000","0.18533000"],["110846.24000000","0.00000000"],["110846.67000000","0.00000000"],["110846.74000000","0.00000000"],["110846.79000000","0.00000000"],["110846.94000000","0.00000000"],["110847.50000000","0.00000000"],["110847.63000000","0.03613000"],["110847.64000000","0.00000000"],["110848.27000000","0.00000000"],["110848.28000000","0.00318000"],["110849.21000000","0.00000000"],["110849.74000000","0.00154000"],["110849.75000000","0.00000000"],["110850.51000000","0.22680000"],["110850.52000000","0.00000000"],["110850.74000000","0.00070000"],["110850.86000000","0.00000000"],["110851.14000000","0.32440000"],["110851.40000000","0.00329000"],["110851.69000000","0.00073000"],["110852.29000000","0.13522000"],["110852.38000000","0.00000000"],["110852.79000000","0.00000000"],["110853.18000000","0.11273000"],["110853.19000000","0.00000000"],["110854.09000000","0.04042000"],["110854.84000000","0.00000000"],["110854.85000000","0.00005000"],["110855.20000000","0.04012000"],["110855.84000000","0.00000000"],["110855.89000000","0.32438000"],["110855.98000000","0.04000000"],["110856.00000000","0.00000000"],["110856.35000000","0.18026000"],["110856.56000000","0.00000000"],["110856.57000000","0.37727000"],["110856.58000000","0.00000000"],["110856.64000000","0.11858000"],["110859.27000000","0.00000000"],["110860.00000000","0.18031000"],["110860.24000000","0.30414000"],["110860.25000000","0.43957000"],["110861.57000000","0.32437000"],["110862.54000000","0.00450000"],["110863.61000000","1.32503000"],["110863.62000000","3.24539000"],["110863.63000000","0.00000000"],["110863.76000000","0.00000000"],["110864.56000000","0.00000000"],["110864.93000000","0.00000000"],["110867.13000000","0.00901000"],["110872.91000000","0.00000000"],["110885.50000000","0.00000000"],["110898.57000000","0.00000000"],["110900.88000000","0.03150000"],["110912.17000000","0.00000000"],["110922.55000000","1.22501000"],["110925.20000000","3.24544000"],["110931.86000000","3.24539000"],["110933.67000000","0.03538000"],["111001.70000000","0.11098000"],["111004.06000000","0.99786000"],["111005.45000000","0.00000000"],["111019.13000000","0.00331000"],["111019.23000000","0.00000000"],["111061.79000000","0.00000000"],["111099.03000000","0.02998000"],["111101.91000000","0.06646000"],["111268.51000000","0.45000000"],["111279.31000000","0.00070000"],["111290.69000000","0.00000000"],["111293.00000000","0.00082000"],["111293.09000000","0.00000000"],["111308.13000000","0.67153000"],["112499.11000000","0.00105000"],["128001.97000000","0.00040000"]]}
[2025-10-11T22:17:18.329Z] {"e":"depthUpdate","E":1760221038014,"s":"BTCUSDT","U":77925964254,"u":77925964512,"b":[["110836.55000000","3.79778000"],["110836.54000000","0.00005000"],["110836.17000000","0.01363000"],["110835.78000000","0.10870000"],["110835.77000000","0.29751000"],["110833.68000000","0.00010000"],["110833.67000000","0.06227000"],["110833.12000000","0.00005000"],["110833.11000000","0.00005000"],["110832.69000000","0.18023000"],["110832.52000000","0.32450000"],["110830.63000000","0.00000000"],["110830.61000000","0.00000000"],["110829.99000000","0.00000000"],["110827.66000000","0.00000000"],["110827.65000000","0.00000000"],["110827.22000000","0.00000000"],["110826.81000000","0.08567000"],["110826.72000000","0.00000000"],["110825.46000000","0.56573000"],["110825.07000000","0.04509000"],["110822.53000000","0.00044000"],["110822.33000000","0.32448000"],["110822.22000000","0.00074000"],["110818.73000000","0.01964000"],["110809.17000000","0.00000000"],["110803.16000000","0.22546000"],["110799.29000000","0.04000000"],["110789.99000000","0.00000000"],["110757.56000000","0.59793000"],["110748.02000000","0.33261000"],["110744.73000000","0.01411000"],["110728.81000000","0.00000000"],["110728.78000000","0.00000000"],["110728.72000000","0.00000000"],["110728.25000000","0.00000000"],["110725.72000000","0.02888000"],["110725.57000000","0.22546000"],["110686.16000000","0.08809000"],["110586.32000000","0.00587000"],["110576.70000000","0.00000000"],["109174.00000000","0.00000000"],["99752.00000000","0.00020000"],["88669.24000000","0.00037000"]],"a":[["110836.56000000","4.57225000"],["110836.57000000","0.00030000"],["110836.94000000","0.01363000"],["110837.20000000","0.00000000"],["110837.55000000","0.00083000"],["110838.31000000","0.00005000"],["110838.81000000","0.00000000"],["110839.42000000","0.00000000"],["110840.43000000","0.00556000"],["110840.95000000","0.00010000"],["110840.96000000","0.05073000"],["110841.52000000","0.00000000"],["110842.05000000","0.01804000"],["110842.65000000","0.01814000"],["110843.00000000","0.00400000"],["110843.49000000","0.00010000"],["110843.50000000","0.40905000"],["110843.51000000","0.45041000"],["110843.52000000","0.00000000"],["110843.53000000","0.08000000"],["110843.62000000","0.00000000"],["110843.63000000","0.54000000"],["110843.87000000","0.00000000"],["110845.61000000","0.04511000"],["110846.23000000","0.25826000"],["110846.59000000","0.00000000"],["110846.87000000","0.32441000"],["110849.14000000","0.00000000"],["110849.74000000","0.00149000"],["110851.69000000","0.00000000"],["110854.09000000","0.00000000"],["110854.64000000","0.04076000"],["110855.00000000","0.00400000"],["110855.88000000","0.81800000"],["110856.35000000","0.00000000"],["110856.57000000","0.00000000"],["110856.64000000","0.11889000"],["110856.69000000","0.32438000"],["110859.99000000","3.24539000"],["110860.25000000","0.11520000"],["110861.57000000","0.00000000"],["110861.83000000","0.01964000"],["110912.05000000","0.03538000"],["110929.29000000","0.00000000"],["110931.83000000","0.01411000"],["110931.86000000","0.00000000"],["110933.67000000","0.00000000"],["110958.97000000","0.07262000"],["111001.70000000","0.39468000"],["112211.66000000","0.00000000"],["112499.11000000","0.00005000"],["112558.65000000","0.00000000"],["112600.00000000","0.27893000"],["112905.64000000","0.00000000"],["113252.62000000","0.00000000"],["113599.61000000","0.00000000"],["113946.60000000","0.00007000"],["114293.58000000","0.00000000"],["114640.57000000","0.00000000"],["114987.56000000","0.00000000"],["115334.54000000","0.00000000"],["115681.53000000","0.00000000"],["116028.52000000","0.00000000"],["116375.50000000","0.00000000"],["116722.49000000","0.00000000"],["117069.48000000","0.00000000"],["117416.46000000","0.00000000"],["117763.45000000","0.00000000"],["118110.44000000","0.00000000"],["118457.42000000","0.00000000"],["118804.41000000","0.00000000"],["119151.40000000","0.00000000"],["119498.38000000","0.00000000"],["119845.37000000","0.00000000"],["120192.36000000","0.00000000"],["120539.34000000","0.00000000"],["120886.33000000","0.00000000"],["121233.32000000","0.00000000"],["128001.97000000","0.00040000"]]}
[2025-10-11T22:17:19.328Z] {"e":"depthUpdate","E":1760221039014,"s":"BTCUSDT","U":77925964513,"u":77925964692,"b":[["110836.55000000","3.68460000"],["110836.54000000","0.00010000"],["110834.34000000","0.00361000"],["110833.67000000","0.06227000"],["110833.12000000","0.00005000"],["110833.11000000","0.04509000"],["110832.70000000","0.00005000"],["110832.69000000","0.18028000"],["110832.68000000","0.00546000"],["110832.54000000","0.21394000"],["110832.52000000","0.32450000"],["110831.57000000","0.00722000"],["110830.37000000","0.06646000"],["110826.72000000","0.01801000"],["110825.07000000","0.00000000"],["110822.53000000","0.00000000"],["110822.08000000","0.00070000"],["110820.00000000","0.01749000"],["110818.73000000","0.00000000"],["110810.00000000","1.16145000"],["110809.26000000","0.01964000"],["110798.17000000","0.00000000"],["110771.16000000","0.06057000"],["110764.98000000","0.00000000"],["110750.06000000","0.00000000"],["110744.73000000","0.00000000"],["110743.47000000","0.31093000"],["110736.94000000","0.00000000"],["110731.75000000","0.04297000"],["110729.48000000","0.03277000"],["110716.87000000","0.09641000"],["110698.60000000","0.00000000"],["110686.00000000","0.08895000"],["110683.32000000","0.08795000"],["110681.15000000","0.08795000"],["110480.76000000","0.00000000"],["110471.72000000","0.03789000"],["110461.52000000","0.00333000"],["109770.65000000","0.00235000"],["105460.98000000","0.00273000"],["99878.23000000","0.00000000"],["99752.00000000","0.00010000"],["88669.24000000","0.00037000"],["39901.16000000","0.00016000"],["22187.00000000","0.01690000"]],"a":[["110836.56000000","4.56978000"],["110836.57000000","0.00045000"],["110836.94000000","0.01368000"],["110838.77000000","0.00361000"],["110839.42000000","0.00005000"],["110840.43000000","0.00556000"],["110840.53000000","0.00005000"],["110840.96000000","0.05073000"],["110841.22000000","0.29739000"],["110841.54000000","0.00727000"],["110841.70000000","0.00563000"],["110841.71000000","0.00269000"],["110842.04000000","0.00010000"],["110842.05000000","0.01814000"],["110842.65000000","0.01819000"],["110843.50000000","0.40890000"],["110843.51000000","0.45036000"],["110844.65000000","0.05012000"],["110848.28000000","0.00313000"],["110850.74000000","0.00000000"],["110855.88000000","1.71062000"],["110861.83000000","0.00000000"],["110864.77000000","0.00000000"],["110878.00000000","0.00100000"],["110896.56000000","0.00000000"],["110908.85000000","0.00224000"],["110931.83000000","0.00000000"],["110940.01000000","0.00000000"],["110948.01000000","0.01411000"],["110999.80000000","0.00331000"],["111010.04000000","0.00000000"],["111018.99000000","0.00000000"],["111019.13000000","0.00000000"],["111019.99000000","0.00090000"],["111273.65000000","0.00082000"],["111283.90000000","0.00000000"],["111293.00000000","0.00000000"],["111308.13000000","0.00000000"],["111315.41000000","0.67153000"],["111888.09000000","0.00230000"],["128001.97000000","0.03006000"]]}
[2025-10-11T22:17:20.328Z] {"e":"depthUpdate","E":1760221040014,"s":"BTCUSDT","U":77925964693,"u":77925965098,"b":[["110836.55000000","3.10857000"],["110836.54000000","0.00020000"],["110836.17000000","0.01358000"],["110835.79000000","0.00000000"],["110835.78000000","0.00000000"],["110835.77000000","0.00000000"],["110833.67000000","0.06222000"],["110833.30000000","0.11289000"],["110833.29000000","0.29746000"],["110833.12000000","0.00000000"],["110833.11000000","0.00000000"],["110832.71000000","0.00010000"],["110832.70000000","0.00005000"],["110832.69000000","0.00000000"],["110832.68000000","0.00546000"],["110832.54000000","0.00000000"],["110832.52000000","0.00000000"],["110831.57000000","0.00727000"],["110830.46000000","0.01810000"],["110830.37000000","0.00000000"],["110830.00000000","0.00000000"],["110829.66000000","0.00000000"],["110829.33000000","0.00000000"],["110829.32000000","0.00000000"],["110829.13000000","0.00005000"],["110829.12000000","0.04507000"],["110828.18000000","0.32446000"],["110827.45000000","0.18024000"],["110826.72000000","0.01824000"],["110825.90000000","0.32447000"],["110825.07000000","0.04509000"],["110824.24000000","0.00000000"],["110824.00000000","0.00009000"],["110823.88000000","0.00000000"],["110822.43000000","0.00000000"],["110822.33000000","0.00000000"],["110820.66000000","0.18026000"],["110820.64000000","0.45036000"],["110819.58000000","0.32449000"],["110810.00000000","0.28349000"],["110808.11000000","0.00000000"],["110804.32000000","3.24539000"],["110804.31000000","1.29366000"],["110804.30000000","0.00000000"],["110799.29000000","0.00000000"],["110795.10000000","0.00000000"],["110793.00000000","1.21550000"],["110790.51000000","0.04000000"],["110751.84000000","0.00196000"],["110750.08000000","1.38612000"],["110750.07000000","3.24539000"],["110748.02000000","0.00000000"],["110743.48000000","0.00000000"],["110682.07000000","0.08795000"],["110461.52000000","0.00000000"],["110453.50000000","0.00333000"],["110000.00000000","11.10763000"],["109770.65000000","0.00000000"],["105445.23000000","0.00000000"],["99752.00000000","0.00010000"],["88669.24000000","0.00037000"],["60000.00000000","56.18404000"],["39901.16000000","0.00048000"]],"a":[["110836.56000000","4.97757000"],["110836.57000000","0.00045000"],["110836.94000000","0.01368000"],["110838.17000000","0.31013000"],["110838.18000000","0.29750000"],["110838.77000000","0.00366000"],["110839.26000000","0.00000000"],["110839.28000000","0.00000000"],["110839.98000000","0.04015000"],["110840.37000000","0.04160000"],["110840.53000000","0.00000000"],["110840.95000000","0.00005000"],["110840.96000000","0.05068000"],["110841.20000000","0.00000000"],["110841.21000000","0.00000000"],["110841.22000000","0.00000000"],["110841.70000000","0.00558000"],["110841.71000000","0.00269000"],["110842.04000000","0.00000000"],["110842.05000000","0.00000000"],["110842.33000000","0.01804000"],["110842.52000000","0.32442000"],["110842.64000000","0.00000000"],["110842.65000000","0.01809000"],["110843.49000000","0.00000000"],["110843.50000000","0.00000000"],["110843.51000000","0.00000000"],["110843.52000000","0.00000000"],["110844.75000000","0.00000000"],["110845.61000000","0.04516000"],["110846.23000000","0.38470000"],["110846.87000000","0.00000000"],["110846.96000000","0.00450000"],["110846.98000000","0.32441000"],["110847.63000000","0.03608000"],["110849.16000000","0.00000000"],["110849.86000000","0.45036000"],["110850.13000000","0.00000000"],["110850.14000000","0.00000000"],["110850.21000000","0.00000000"],["110853.06000000","0.18026000"],["110854.64000000","0.00000000"],["110855.20000000","0.00000000"],["110855.88000000","2.33003000"],["110855.98000000","0.00000000"],["110856.62000000","3.24539000"],["110856.63000000","0.18026000"],["110856.69000000","0.00000000"],["110862.54000000","0.00000000"],["110864.24000000","0.01964000"],["110864.64000000","0.00000000"],["110864.79000000","0.00000000"],["110875.00000000","1.22052000"],["110882.96000000","0.03150000"],["110892.80000000","0.03538000"],["110900.88000000","0.00000000"],["110912.05000000","0.00000000"],["110913.58000000","0.00000000"],["110922.55000000","0.27438000"],["110925.20000000","0.00005000"],["110945.71000000","0.01236000"],["110963.08000000","0.00000000"],["110967.91000000","0.00196000"],["110991.74000000","0.00331000"],["110999.80000000","0.00000000"],["111265.59000000","0.00082000"],["111273.65000000","0.00000000"],["111888.09000000","0.00000000"],["128001.97000000","0.03006000"]]}
[2025-10-11T22:17:21.329Z] {"e":"depthUpdate","E":1760221041014,"s":"BTCUSDT","U":77925965099,"u":77925965930,"b":[["110836.55000000","2.43053000"],["110836.54000000","0.00020000"],["110836.48000000","0.00010000"],["110836.39000000","0.00907000"],["110836.32000000","0.00010000"],["110836.31000000","0.05482000"],["110836.17000000","0.01363000"],["110834.99000000","0.00000000"],["110833.68000000","0.00000000"],["110833.67000000","0.00285000"],["110833.35000000","0.00000000"],["110833.34000000","0.00000000"],["110833.33000000","0.00000000"],["110833.32000000","0.00000000"],["110833.31000000","0.00000000"],["110833.30000000","0.00000000"],["110833.29000000","0.00000000"],["110832.87000000","0.11178000"],["110832.86000000","0.29751000"],["110832.71000000","0.00000000"],["110832.70000000","0.00000000"],["110832.38000000","0.00000000"],["110832.32000000","0.00000000"],["110831.66000000","0.00005000"],["110831.57000000","0.00727000"],["110830.64000000","0.00025000"],["110830.47000000","0.00010000"],["110830.46000000","0.01810000"],["110830.13000000","0.00000000"],["110829.13000000","0.00010000"],["110829.12000000","0.04507000"],["110828.18000000","0.00000000"],["110828.07000000","0.00000000"],["110828.06000000","0.00000000"],["110827.82000000","0.00000000"],["110827.47000000","0.00000000"],["110827.46000000","0.00000000"],["110827.45000000","0.00000000"],["110827.44000000","0.00000000"],["110827.10000000","0.00000000"],["110827.08000000","0.00000000"],["110827.07000000","0.00000000"],["110826.81000000","0.00000000"],["110826.72000000","0.00000000"],["110826.50000000","0.00000000"],["110825.90000000","0.00000000"],["110825.48000000","0.00005000"],["110825.47000000","0.23731000"],["110825.46000000","0.45300000"],["110825.07000000","0.04509000"],["110824.89000000","0.00000000"],["110824.85000000","0.00000000"],["110824.27000000","0.00000000"],["110824.26000000","0.32448000"],["110823.99000000","0.00000000"],["110823.55000000","0.00000000"],["110823.39000000","0.00070000"],["110823.32000000","0.00000000"],["110822.69000000","0.04013000"],["110822.32000000","0.31702000"],["110822.31000000","0.00010000"],["110822.01000000","0.18025000"],["110821.58000000","0.03975000"],["110820.91000000","0.00069000"],["110820.86000000","0.00000000"],["110820.66000000","0.63062000"],["110820.65000000","0.00000000"],["110820.64000000","0.00000000"],["110820.33000000","0.00000000"],["110820.01000000","0.00027000"],["110819.92000000","0.11273000"],["110819.58000000","0.00000000"],["110819.11000000","0.32449000"],["110818.84000000","0.00000000"],["110818.81000000","0.00000000"],["110818.62000000","0.00000000"],["110818.52000000","0.00000000"],["110818.41000000","0.00000000"],["110817.58000000","0.00000000"],["110816.85000000","0.36038000"],["110816.07000000","0.00000000"],["110815.08000000","0.32450000"],["110814.87000000","0.08567000"],["110814.38000000","0.00000000"],["110814.37000000","0.45000000"],["110814.00000000","0.00132000"],["110813.99000000","0.00000000"],["110813.25000000","0.01964000"],["110812.96000000","0.00000000"],["110812.38000000","0.00000000"],["110812.37000000","0.00000000"],["110812.18000000","0.00000000"],["110810.12000000","0.00000000"],["110809.33000000","0.04800000"],["110809.26000000","0.00000000"],["110806.20000000","0.04800000"],["110804.98000000","0.02141000"],["110804.51000000","0.20199000"],["110804.33000000","1.29366000"],["110804.32000000","0.00000000"],["110804.31000000","0.00000000"],["110803.90000000","0.04800000"],["110803.81000000","0.04800000"],["110799.64000000","0.08567000"],["110796.02000000","0.08567000"],["110793.02000000","0.00000000"],["110792.16000000","0.00000000"],["110790.67000000","0.00000000"],["110790.17000000","0.13527000"],["110788.60000000","0.00000000"],["110788.26000000","0.00000000"],["110786.58000000","0.00000000"],["110785.45000000","0.00000000"],["110781.32000000","0.00000000"],["110779.33000000","0.26000000"],["110779.12000000","0.00000000"],["110777.78000000","0.04474000"],["110775.73000000","0.32000000"],["110771.62000000","0.13522000"],["110767.37000000","0.00000000"],["110766.10000000","0.00000000"],["110752.37000000","0.00617000"],["110747.40000000","0.00000000"],["110745.48000000","0.00000000"],["110743.48000000","3.24539000"],["110729.82000000","0.04800000"],["110728.09000000","0.13527000"],["110726.75000000","0.04800000"],["110726.53000000","0.00000000"],["110725.72000000","0.00000000"],["110724.43000000","0.09097000"],["110724.38000000","0.00000000"],["110720.03000000","0.00000000"],["110720.02000000","0.00167000"],["110709.54000000","0.03939000"],["110702.43000000","0.03400000"],["110681.75000000","0.02616000"],["110654.61000000","0.00000000"],["110615.58000000","0.00000000"],["110609.14000000","0.00000000"],["110609.13000000","0.00066000"],["110570.56000000","0.00000000"],["110453.50000000","0.00000000"],["110452.82000000","0.45111000"],["110440.15000000","0.00333000"],["110418.31000000","0.00000000"],["110171.54000000","0.00019000"],["109638.00000000","0.00000000"],["109615.00000000","0.00017000"],["109614.00000000","1.37005000"],["99752.00000000","0.00010000"],["88669.24000000","0.00037000"],["60000.00000000","56.18394000"]],"a":[["110836.56000000","6.29277000"],["110836.57000000","0.00025000"],["110836.93000000","0.00010000"],["110836.94000000","0.01373000"],["110837.81000000","0.00000000"],["110837.82000000","0.00005000"],["110837.92000000","0.00010000"],["110837.93000000","0.00010000"],["110838.16000000","0.00010000"],["110838.17000000","0.31023000"],["110838.18000000","0.29750000"],["110838.25000000","0.00005000"],["110838.26000000","0.00005000"],["110838.53000000","0.03608000"],["110838.77000000","0.00366000"],["110838.80000000","0.01814000"],["110839.28000000","0.00000000"],["110839.29000000","0.00000000"],["110839.88000000","0.04005000"],["110839.91000000","0.00000000"],["110839.98000000","0.00000000"],["110840.03000000","0.00000000"],["110840.37000000","0.00000000"],["110840.43000000","0.00561000"],["110840.95000000","0.00000000"],["110840.96000000","0.05068000"],["110841.15000000","0.08119000"],["110841.54000000","0.00722000"],["110841.59000000","0.00000000"],["110841.71000000","0.00269000"],["110841.85000000","0.00000000"],["110841.98000000","0.00000000"],["110842.33000000","0.01809000"],["110842.39000000","0.03973000"],["110842.44000000","0.00310000"],["110842.99000000","0.30419000"],["110843.00000000","0.00405000"],["110843.50000000","0.04098000"],["110843.53000000","0.00000000"],["110843.61000000","0.00000000"],["110843.63000000","0.00000000"],["110844.20000000","0.00149000"],["110844.65000000","0.05012000"],["110844.66000000","0.00000000"],["110845.60000000","0.00450000"],["110845.61000000","0.04511000"],["110846.22000000","0.18026000"],["110846.23000000","0.38470000"],["110846.62000000","0.06646000"],["110846.96000000","0.00000000"],["110846.97000000","0.04503000"],["110847.53000000","0.08376000"],["110847.63000000","0.03608000"],["110849.85000000","0.00000000"],["110850.51000000","1.32170000"],["110851.40000000","0.00000000"],["110852.31000000","0.32439000"],["110852.45000000","0.13527000"],["110852.85000000","0.08567000"],["110853.26000000","3.24539000"],["110854.49000000","0.13527000"],["110854.83000000","0.08567000"],["110855.89000000","0.00000000"],["110857.15000000","0.00000000"],["110858.94000000","0.00901000"],["110860.24000000","0.00000000"],["110864.24000000","0.00000000"],["110864.27000000","0.01964000"],["110864.52000000","0.00000000"],["110866.89000000","0.02800000"],["110867.13000000","0.00000000"],["110867.98000000","0.22546000"],["110868.04000000","0.00000000"],["110869.34000000","0.18031000"],["110869.62000000","0.22546000"],["110871.54000000","0.00000000"],["110871.62000000","0.00000000"],["110871.68000000","0.00000000"],["110872.71000000","0.00000000"],["110873.82000000","0.00000000"],["110883.12000000","0.13527000"],["110883.54000000","0.00000000"],["110884.61000000","0.00000000"],["110884.99000000","0.13515000"],["110886.08000000","0.00000000"],["110886.17000000","0.00000000"],["110886.24000000","0.00000000"],["110888.62000000","0.04475000"],["110892.80000000","0.00000000"],["110896.30000000","0.00000000"],["110897.96000000","0.00000000"],["110900.04000000","0.00000000"],["110901.43000000","0.03538000"],["110904.91000000","0.00000000"],["110911.73000000","0.00000000"],["110911.87000000","3.24539000"],["110911.88000000","0.17471000"],["110911.89000000","0.00000000"],["110913.50000000","0.13527000"],["110914.36000000","0.00000000"],["110917.36000000","0.26101000"],["110918.54000000","0.00000000"],["110927.56000000","0.00000000"],["110937.13000000","0.00000000"],["110943.75000000","0.13515000"],["110945.57000000","0.22546000"],["110946.48000000","0.26766000"],["110946.93000000","0.18031000"],["110947.21000000","0.22546000"],["110963.76000000","0.00000000"],["110963.83000000","0.00000000"],["110978.32000000","0.00331000"],["110989.22000000","0.43590000"],["110989.23000000","0.99920000"],["110989.99000000","0.08594000"],["110991.74000000","0.00000000"],["110992.68000000","0.00000000"],["110999.44000000","0.02708000"],["111001.70000000","0.11098000"],["111004.06000000","0.00000000"],["111021.60000000","0.00000000"],["111085.24000000","0.00000000"],["111101.91000000","0.00000000"],["111105.23000000","0.00000000"],["111252.16000000","0.00082000"],["111265.59000000","0.00000000"],["111315.41000000","0.00000000"],["128001.97000000","0.00040000"]]}
[2025-10-11T22:17:22.328Z] {"e":"depthUpdate","E":1760221042014,"s":"BTCUSDT","U":77925965931,"u":77925966808,"b":[["110836.55000000","2.58206000"],["110836.54000000","0.00010000"],["110836.39000000","0.00907000"],["110836.33000000","0.00000000"],["110836.32000000","0.00010000"],["110836.31000000","0.00010000"],["110836.18000000","0.00010000"],["110836.17000000","0.01448000"],["110835.39000000","0.00000000"],["110835.38000000","0.00000000"],["110834.99000000","0.00005000"],["110833.62000000","0.00000000"],["110833.61000000","0.00000000"],["110833.12000000","0.00000000"],["110833.11000000","0.00000000"],["110832.88000000","0.00010000"],["110832.87000000","0.06508000"],["110832.86000000","0.00000000"],["110832.68000000","0.00546000"],["110832.62000000","0.00010000"],["110832.61000000","0.00005000"],["110832.30000000","0.00000000"],["110831.57000000","0.00727000"],["110830.47000000","0.00000000"],["110830.46000000","0.01810000"],["110830.34000000","0.00000000"],["110830.33000000","0.00000000"],["110829.42000000","0.29742000"],["110829.32000000","0.00000000"],["110829.31000000","0.00000000"],["110829.13000000","0.00005000"],["110829.12000000","0.04507000"],["110827.44000000","0.00000000"],["110826.85000000","0.00000000"],["110826.72000000","0.00000000"],["110826.50000000","0.00000000"],["110825.48000000","0.00000000"],["110825.07000000","0.04509000"],["110824.27000000","0.00000000"],["110823.39000000","0.00000000"],["110822.80000000","0.00069000"],["110822.70000000","0.00000000"],["110822.69000000","0.03964000"],["110822.32000000","0.48171000"],["110822.08000000","0.00000000"],["110822.01000000","0.00000000"],["110821.58000000","0.04083000"],["110821.23000000","0.08567000"],["110820.91000000","0.00000000"],["110820.66000000","0.00000000"],["110820.55000000","0.00000000"],["110820.24000000","0.18026000"],["110820.23000000","0.00000000"],["110819.97000000","0.32449000"],["110819.11000000","0.00000000"],["110816.86000000","0.38223000"],["110816.84000000","0.00000000"],["110815.26000000","0.08567000"],["110815.08000000","0.00000000"],["110815.00000000","0.01302000"],["110814.87000000","0.00000000"],["110814.57000000","0.32450000"],["110814.53000000","0.32450000"],["110814.07000000","0.07200000"],["110811.77000000","0.08567000"],["110810.58000000","0.04800000"],["110807.81000000","0.07200000"],["110804.51000000","0.00000000"],["110804.35000000","0.00000000"],["110804.34000000","0.00000000"],["110804.33000000","0.00000000"],["110803.88000000","0.22546000"],["110803.19000000","0.00000000"],["110803.16000000","0.00000000"],["110800.50000000","0.00000000"],["110800.31000000","0.00000000"],["110800.00000000","0.78171000"],["110799.64000000","0.00000000"],["110797.41000000","0.00000000"],["110796.02000000","0.00000000"],["110790.51000000","0.00000000"],["110789.92000000","0.04000000"],["110788.87000000","0.00000000"],["110788.07000000","0.13534000"],["110786.43000000","0.02303000"],["110771.62000000","0.00000000"],["110765.98000000","0.06779000"],["110749.77000000","0.00000000"],["110743.88000000","0.00000000"],["110743.49000000","0.00000000"],["110743.48000000","0.00000000"],["110743.47000000","3.24539000"],["110737.03000000","0.13537000"],["110736.81000000","3.24544000"],["110734.20000000","0.03277000"],["110733.29000000","0.07200000"],["110732.07000000","0.00000000"],["110731.27000000","0.00000000"],["110729.83000000","0.02298000"],["110729.48000000","0.00000000"],["110728.81000000","0.00000000"],["110728.78000000","0.22546000"],["110728.70000000","0.20919000"],["110728.09000000","0.00000000"],["110725.99000000","0.03939000"],["110725.57000000","0.00000000"],["110724.38000000","0.04800000"],["110709.54000000","0.00000000"],["110702.43000000","0.00000000"],["110696.70000000","0.02298000"],["110586.31000000","0.00000000"],["110578.09000000","4.73387000"],["110560.48000000","0.02998000"],["110507.47000000","0.17314000"],["110502.35000000","0.03789000"],["110501.86000000","0.03789000"],["110476.15000000","0.01241000"],["110474.36000000","0.00000000"],["110447.66000000","0.00333000"],["110444.10000000","0.00000000"],["110440.15000000","0.00000000"],["110240.11000000","0.02298000"],["110171.54000000","0.00000000"],["109400.00000000","0.33340000"],["101969.64000000","0.00010000"],["99752.00000000","0.00010000"],["88669.24000000","0.00037000"],["39901.16000000","0.00096000"],["33000.00000000","3.75190000"]],"a":[["110836.56000000","4.46027000"],["110836.57000000","0.00025000"],["110836.72000000","0.00912000"],["110836.88000000","0.26938000"],["110836.89000000","0.29745000"],["110836.93000000","0.00000000"],["110836.94000000","0.01368000"],["110837.82000000","0.00000000"],["110837.92000000","0.00000000"],["110837.93000000","0.00000000"],["110838.00000000","0.00010000"],["110838.01000000","0.06651000"],["110838.16000000","0.00000000"],["110838.17000000","0.00000000"],["110838.18000000","0.00000000"],["110838.25000000","0.00000000"],["110838.26000000","0.00000000"],["110838.52000000","0.00000000"],["110838.53000000","0.00000000"],["110838.77000000","0.00371000"],["110838.80000000","0.00000000"],["110839.04000000","0.00010000"],["110839.05000000","0.03613000"],["110839.17000000","0.00000000"],["110839.18000000","0.00000000"],["110839.31000000","0.00010000"],["110839.32000000","0.04747000"],["110839.33000000","0.00000000"],["110839.42000000","0.00000000"],["110839.87000000","0.00000000"],["110839.88000000","0.00000000"],["110840.43000000","0.00556000"],["110840.47000000","0.00000000"],["110840.57000000","0.01809000"],["110840.58000000","0.32443000"],["110840.96000000","0.00000000"],["110841.14000000","0.00000000"],["110841.15000000","0.00000000"],["110841.27000000","0.00000000"],["110841.28000000","0.00000000"],["110841.48000000","0.00000000"],["110841.49000000","0.00000000"],["110841.54000000","0.00722000"],["110841.70000000","0.00558000"],["110841.71000000","0.00264000"],["110842.33000000","0.00000000"],["110842.39000000","0.00000000"],["110842.44000000","0.00310000"],["110842.52000000","0.00000000"],["110842.64000000","0.00000000"],["110842.65000000","0.34251000"],["110842.99000000","0.00000000"],["110843.00000000","0.00000000"],["110843.35000000","0.03608000"],["110843.50000000","0.00410000"],["110844.08000000","0.04000000"],["110844.11000000","0.00000000"],["110844.12000000","0.04511000"],["110844.32000000","0.00000000"],["110844.64000000","0.00000000"],["110844.65000000","0.05012000"],["110844.88000000","0.00000000"],["110844.94000000","0.00005000"],["110845.05000000","0.06651000"],["110845.43000000","0.00000000"],["110845.55000000","0.01822000"],["110845.60000000","0.00000000"],["110845.61000000","0.00000000"],["110846.22000000","0.18026000"],["110846.62000000","0.00005000"],["110846.97000000","0.04513000"],["110846.98000000","0.00000000"],["110847.26000000","0.32441000"],["110847.51000000","0.04142000"],["110847.53000000","0.08381000"],["110847.63000000","0.03608000"],["110848.28000000","0.00313000"],["110848.62000000","0.03956000"],["110849.34000000","0.00000000"],["110849.85000000","0.00000000"],["110850.09000000","0.00000000"],["110850.15000000","0.00000000"],["110850.21000000","0.00000000"],["110850.50000000","0.18026000"],["110850.51000000","1.21774000"],["110850.58000000","0.00000000"],["110851.14000000","0.00000000"],["110851.86000000","0.32440000"],["110852.29000000","0.00000000"],["110852.31000000","0.00000000"],["110852.45000000","0.00000000"],["110852.85000000","0.00000000"],["110853.06000000","0.00000000"],["110853.17000000","3.24539000"],["110853.26000000","0.00000000"],["110853.31000000","0.00332000"],["110853.85000000","0.13522000"],["110854.83000000","0.00000000"],["110855.87000000","0.00450000"],["110855.88000000","2.31580000"],["110855.95000000","0.00000000"],["110856.37000000","0.00000000"],["110856.44000000","0.00000000"],["110856.62000000","3.24539000"],["110856.88000000","0.00000000"],["110857.97000000","0.14400000"],["110862.54000000","0.30414000"],["110862.55000000","0.00000000"],["110864.27000000","0.00000000"],["110864.81000000","0.01964000"],["110865.68000000","0.00000000"],["110866.89000000","0.00000000"],["110868.47000000","0.08567000"],["110869.88000000","0.13527000"],["110871.23000000","0.08567000"],["110880.97000000","0.02800000"],["110882.96000000","0.00000000"],["110883.12000000","0.00000000"],["110887.82000000","0.05576000"],["110895.50000000","0.03150000"],["110901.43000000","0.00000000"],["110915.93000000","0.00000000"],["110918.53000000","0.00000000"],["110921.21000000","0.03538000"],["110931.96000000","0.13527000"],["110948.01000000","0.00000000"],["110973.39000000","0.09894000"],["110978.32000000","0.00000000"],["110985.87000000","0.00331000"],["110987.95000000","0.00000000"],["110989.22000000","0.00000000"],["110989.23000000","0.00000000"],["110997.64000000","0.99229000"],["111078.37000000","4.60916000"],["111081.47000000","0.00000000"],["111085.24000000","0.00000000"],["111098.55000000","0.03015000"],["111099.03000000","0.00000000"],["111101.91000000","0.00000000"],["111173.91000000","0.03789000"],["111174.17000000","0.03789000"],["111252.16000000","0.00000000"],["111259.71000000","0.00082000"],["128001.97000000","0.00040000"]]}
[2025-10-11T22:17:23.328Z] {"e":"depthUpdate","E":1760221043014,"s":"BTCUSDT","U":77925966809,"u":77925967127,"b":[["110836.55000000","2.86260000"],["110836.54000000","0.00005000"],["110836.53000000","0.00000000"],["110836.39000000","0.00907000"],["110836.32000000","0.00000000"],["110836.31000000","0.00000000"],["110836.17000000","0.01453000"],["110834.99000000","0.00000000"],["110832.88000000","0.00000000"],["110832.87000000","0.00000000"],["110832.68000000","0.00546000"],["110832.62000000","0.00000000"],["110832.61000000","0.00000000"],["110832.56000000","0.00010000"],["110832.55000000","0.14082000"],["110832.54000000","0.29751000"],["110830.64000000","0.00000000"],["110830.47000000","0.00000000"],["110830.46000000","0.01815000"],["110829.44000000","0.00000000"],["110829.43000000","0.00000000"],["110829.42000000","0.00000000"],["110829.13000000","0.00010000"],["110829.12000000","0.04507000"],["110826.80000000","0.00005000"],["110826.79000000","0.26309000"],["110826.78000000","0.32447000"],["110826.72000000","0.01814000"],["110825.48000000","0.00000000"],["110825.47000000","0.00000000"],["110824.50000000","0.00000000"],["110824.26000000","0.00000000"],["110822.34000000","0.47969000"],["110822.33000000","0.45036000"],["110822.32000000","0.00000000"],["110822.00000000","0.00327000"],["110816.86000000","0.18026000"],["110815.08000000","0.32450000"],["110814.53000000","0.00000000"],["110813.25000000","0.00000000"],["110812.57000000","0.07200000"],["110810.59000000","0.20198000"],["110808.95000000","0.01964000"],["110807.81000000","0.00000000"],["110793.00000000","0.00000000"],["110787.00000000","0.04800000"],["110779.33000000","0.10000000"],["110777.13000000","0.16005000"],["110745.48000000","0.13537000"],["110743.48000000","1.27968000"],["110730.87000000","0.00000000"],["110728.70000000","0.18031000"],["110728.39000000","0.02888000"],["110681.90000000","0.36770000"],["110680.74000000","0.00005000"],["110677.96000000","0.49059000"],["110677.95000000","0.99088000"],["110677.44000000","0.00000000"],["110577.63000000","0.00000000"],["110565.47000000","0.00250000"],["110447.66000000","0.00000000"],["110426.54000000","0.00333000"],["110171.54000000","0.00019000"],["101969.64000000","0.00000000"],["99752.00000000","0.00010000"],["88669.24000000","0.00037000"]],"a":[["110836.56000000","4.74972000"],["110836.57000000","0.00000000"],["110836.87000000","0.00010000"],["110836.88000000","0.26943000"],["110836.89000000","0.29750000"],["110836.94000000","0.01373000"],["110838.01000000","0.06656000"],["110842.44000000","0.00315000"],["110842.65000000","0.01809000"],["110842.96000000","0.32442000"],["110847.53000000","0.08376000"],["110850.69000000","0.00325000"],["110852.28000000","0.00000000"],["110853.31000000","0.00000000"],["110875.00000000","0.00000000"],["110901.54000000","0.00000000"],["110911.86000000","1.18384000"],["110911.88000000","0.00000000"],["110914.46000000","0.00000000"],["110918.62000000","0.03538000"],["110919.67000000","0.02998000"],["110921.21000000","0.00000000"],["110964.65000000","0.00331000"],["110972.44000000","0.07782000"],["110985.87000000","0.00000000"],["110997.64000000","0.99363000"],["111238.47000000","0.00082000"],["111259.71000000","0.00000000"],["111268.75000000","0.00250000"],["111279.88000000","0.00000000"],["111300.86000000","0.00000000"],["128001.97000000","0.03006000"]]}
[2025-10-11T22:17:24.328Z] {"e":"depthUpdate","E":1760221044014,"s":"BTCUSDT","U":77925967128,"u":77925967454,"b":[["110836.55000000","2.57437000"],["110836.54000000","0.00020000"],["110836.53000000","0.00000000"],["110836.52000000","0.00000000"],["110836.17000000","0.01453000"],["110835.28000000","0.00000000"],["110835.27000000","0.00000000"],["110834.99000000","0.00005000"],["110832.93000000","0.00010000"],["110832.92000000","0.05065000"],["110832.68000000","0.00546000"],["110832.56000000","0.00000000"],["110832.55000000","0.00000000"],["110832.54000000","0.00000000"],["110832.38000000","0.00010000"],["110832.37000000","0.29751000"],["110830.46000000","0.01815000"],["110829.12000000","0.04507000"],["110829.04000000","0.00000000"],["110829.03000000","0.00005000"],["110829.02000000","0.00000000"],["110826.80000000","0.00000000"],["110826.79000000","0.00000000"],["110826.78000000","0.00000000"],["110826.72000000","0.00000000"],["110826.64000000","0.00005000"],["110826.63000000","0.43149000"],["110826.62000000","0.32447000"],["110825.47000000","0.00000000"],["110825.46000000","0.45300000"],["110825.07000000","0.04509000"],["110824.27000000","0.32448000"],["110819.92000000","0.00000000"],["110814.57000000","0.00000000"],["110814.38000000","0.11273000"],["110803.89000000","0.33876000"],["110792.58000000","1.21272000"],["110746.36000000","0.00000000"],["110738.93000000","1.48985000"],["110732.21000000","0.02888000"],["110728.39000000","0.00000000"],["110720.03000000","0.00167000"],["110720.02000000","0.00000000"],["110708.28000000","0.03400000"],["110609.14000000","0.00066000"],["110609.13000000","0.00000000"],["110587.48000000","0.00587000"],["110586.32000000","0.00000000"],["110582.94000000","0.00000000"],["110568.79000000","0.07572000"],["110171.54000000","0.00000000"],["109000.00000000","81.18413000"],["105460.98000000","0.00330000"],["99752.00000000","0.00010000"],["88669.24000000","0.00037000"]],"a":[["110836.56000000","4.57563000"],["110836.57000000","0.00005000"],["110836.94000000","0.01373000"],["110837.94000000","0.06656000"],["110838.00000000","0.00000000"],["110838.01000000","0.00000000"],["110839.05000000","0.03613000"],["110840.57000000","0.01809000"],["110840.58000000","0.00000000"],["110840.88000000","0.32443000"],["110841.54000000","0.00722000"],["110842.90000000","0.32442000"],["110842.96000000","0.00000000"],["110846.22000000","0.00000000"],["110847.53000000","0.08381000"],["110847.63000000","0.03608000"],["110852.35000000","0.00000000"],["110854.16000000","0.13527000"],["110854.49000000","0.00000000"],["110855.03000000","0.13527000"],["110864.41000000","0.01964000"],["110864.81000000","0.00000000"],["110867.98000000","0.00000000"],["110868.51000000","0.22546000"],["110869.88000000","0.00000000"],["110871.95000000","1.17826000"],["110884.99000000","0.00000000"],["110885.29000000","3.38054000"],["110913.50000000","0.00000000"],["110914.46000000","0.13635000"],["110917.11000000","0.13527000"],["110921.52000000","0.13527000"],["110931.96000000","0.00000000"],["110943.75000000","0.00000000"],["110945.57000000","0.00000000"],["110946.10000000","0.22546000"],["110947.37000000","0.13515000"],["110994.60000000","0.48337000"],["110997.64000000","0.99125000"],["111085.24000000","0.00000000"],["128001.97000000","0.03006000"]]}
[2025-10-11T22:17:25.333Z] {"e":"depthUpdate","E":1760221045017,"s":"BTCUSDT","U":77925967455,"u":77925968068,"b":[["110836.55000000","1.97828000"],["110836.54000000","0.00015000"],["110836.48000000","0.00010000"],["110836.17000000","0.01453000"],["110835.45000000","0.00010000"],["110835.44000000","0.00010000"],["110834.99000000","0.00005000"],["110834.67000000","0.00010000"],["110834.66000000","0.00020000"],["110834.65000000","0.29751000"],["110833.69000000","0.00005000"],["110833.68000000","0.00005000"],["110833.51000000","0.00000000"],["110833.11000000","0.00005000"],["110832.93000000","0.00000000"],["110832.92000000","0.05060000"],["110832.68000000","0.00546000"],["110832.38000000","0.00000000"],["110832.37000000","0.00000000"],["110831.66000000","0.00000000"],["110831.57000000","0.00722000"],["110831.00000000","0.00400000"],["110830.99000000","0.00000000"],["110830.98000000","0.32446000"],["110830.46000000","0.01805000"],["110829.13000000","0.00000000"],["110829.12000000","0.04502000"],["110829.03000000","0.00000000"],["110828.93000000","0.00000000"],["110828.92000000","0.00000000"],["110828.23000000","0.00000000"],["110828.03000000","0.32447000"],["110827.65000000","0.00000000"],["110826.72000000","0.01804000"],["110826.64000000","0.00000000"],["110826.63000000","0.00000000"],["110826.62000000","0.00000000"],["110825.07000000","0.00000000"],["110824.28000000","0.00000000"],["110823.25000000","0.08567000"],["110822.69000000","0.00000000"],["110822.34000000","0.35683000"],["110821.58000000","0.00000000"],["110821.23000000","0.00000000"],["110820.24000000","0.00000000"],["110820.16000000","0.00000000"],["110819.97000000","0.00000000"],["110819.24000000","0.00000000"],["110815.08000000","0.00000000"],["110814.38000000","0.00000000"],["110808.95000000","0.00000000"],["110808.29000000","0.00000000"],["110805.33000000","0.00000000"],["110803.89000000","1.27614000"],["110803.88000000","0.00000000"],["110803.42000000","0.04000000"],["110800.67000000","3.24539000"],["110797.65000000","0.24135000"],["110796.09000000","0.22546000"],["110790.17000000","0.00000000"],["110789.92000000","0.00000000"],["110788.07000000","0.00012000"],["110771.61000000","0.00000000"],["110751.78000000","0.03277000"],["110749.68000000","0.02888000"],["110743.49000000","3.24539000"],["110743.47000000","0.00000000"],["110738.93000000","0.52110000"],["110737.59000000","0.01624000"],["110737.03000000","0.00010000"],["110736.81000000","0.00005000"],["110735.71000000","0.00050000"],["110734.20000000","0.00000000"],["110732.21000000","0.00000000"],["110728.78000000","0.00000000"],["110725.99000000","0.00000000"],["110718.50000000","0.22546000"],["110708.28000000","0.00000000"],["110686.97000000","0.07376000"],["110560.48000000","0.00000000"],["110432.98000000","0.00333000"],["110426.54000000","0.00000000"],["108000.00000000","77.45841000"],["105460.98000000","0.00425000"],["99752.00000000","0.00010000"],["88669.24000000","0.00037000"]],"a":[["110836.56000000","5.43834000"],["110836.57000000","0.00005000"],["110836.88000000","0.00010000"],["110836.89000000","0.00000000"],["110836.94000000","0.01368000"],["110837.93000000","0.00000000"],["110837.94000000","0.00000000"],["110838.77000000","0.00366000"],["110839.04000000","0.00000000"],["110839.05000000","0.00000000"],["110839.16000000","0.00000000"],["110839.17000000","0.00000000"],["110839.32000000","0.00010000"],["110840.43000000","0.00551000"],["110840.57000000","0.00000000"],["110840.88000000","0.00000000"],["110841.54000000","0.00727000"],["110841.69000000","0.11014000"],["110841.70000000","0.00563000"],["110842.23000000","0.00010000"],["110842.24000000","0.00010000"],["110842.29000000","0.00000000"],["110842.56000000","0.00000000"],["110842.65000000","0.01814000"],["110842.89000000","0.00000000"],["110842.90000000","0.00000000"],["110843.34000000","0.00010000"],["110843.50000000","0.00000000"],["110844.07000000","0.00000000"],["110844.08000000","0.00000000"],["110844.12000000","0.00000000"],["110844.64000000","0.00005000"],["110844.65000000","0.05007000"],["110844.89000000","0.00000000"],["110845.05000000","0.00000000"],["110845.55000000","0.00000000"],["110845.83000000","0.00000000"],["110846.58000000","0.00000000"],["110847.26000000","0.00000000"],["110847.53000000","0.08381000"],["110847.62000000","0.18026000"],["110847.63000000","0.03613000"],["110847.65000000","0.45000000"],["110847.70000000","0.00000000"],["110848.28000000","0.00318000"],["110849.74000000","0.00149000"],["110849.81000000","0.00000000"],["110849.84000000","0.00000000"],["110850.50000000","0.00000000"],["110850.51000000","0.37257000"],["110851.47000000","0.04000000"],["110851.57000000","0.00000000"],["110851.86000000","0.00000000"],["110852.76000000","0.32439000"],["110853.16000000","0.18026000"],["110853.17000000","0.00000000"],["110853.32000000","0.13522000"],["110853.85000000","0.00000000"],["110853.87000000","0.00000000"],["110854.16000000","0.00000000"],["110855.86000000","3.24539000"],["110855.88000000","1.38219000"],["110856.62000000","0.00000000"],["110856.69000000","0.32438000"],["110859.52000000","0.00000000"],["110862.53000000","0.00000000"],["110864.41000000","0.00000000"],["110871.13000000","0.13527000"],["110908.85000000","0.00000000"],["110915.40000000","0.00000000"],["110917.36000000","1.28069000"],["110918.53000000","3.24539000"],["110918.62000000","0.00000000"],["110931.43000000","0.03538000"],["110946.10000000","0.00000000"],["110964.65000000","0.00000000"],["110968.57000000","0.04785000"],["110971.12000000","0.00331000"],["110977.17000000","0.11202000"],["110990.35000000","0.11154000"],["110997.64000000","0.99726000"],["111019.99000000","0.00000000"],["111085.24000000","0.18174000"],["111101.91000000","0.06646000"],["111238.47000000","0.00000000"],["111244.95000000","0.00082000"],["111290.69000000","0.00000000"],["111300.86000000","0.00000000"],["128001.97000000","0.00040000"]]}
[2025-10-11T22:17:26.328Z] {"e":"depthUpdate","E":1760221046014,"s":"BTCUSDT","U":77925968069,"u":77925968854,"b":[["110836.55000000","1.91676000"],["110836.54000000","0.00035000"],["110836.17000000","0.01453000"],["110835.45000000","0.00000000"],["110835.44000000","0.00000000"],["110835.11000000","0.00010000"],["110835.10000000","0.29751000"],["110834.67000000","0.00000000"],["110834.66000000","0.00000000"],["110834.65000000","0.00000000"],["110833.69000000","0.00000000"],["110833.68000000","0.00000000"],["110833.11000000","0.00000000"],["110832.93000000","0.00000000"],["110832.92000000","0.00000000"],["110832.60000000","0.00000000"],["110832.34000000","0.00000000"],["110832.05000000","0.00000000"],["110831.66000000","0.00005000"],["110831.57000000","0.00727000"],["110831.49000000","0.00000000"],["110831.31000000","0.00000000"],["110831.00000000","0.00000000"],["110830.99000000","0.00000000"],["110830.98000000","0.00000000"],["110830.47000000","0.00000000"],["110830.46000000","0.01815000"],["110829.40000000","0.00010000"],["110829.39000000","0.12233000"],["110829.38000000","0.00000000"],["110829.13000000","0.00010000"],["110829.12000000","0.04507000"],["110828.71000000","0.32446000"],["110828.41000000","0.00005000"],["110828.40000000","0.00005000"],["110828.34000000","0.00000000"],["110828.33000000","0.03973000"],["110828.04000000","0.00000000"],["110828.03000000","0.00000000"],["110827.23000000","0.00000000"],["110827.22000000","0.03993000"],["110826.72000000","0.00000000"],["110826.66000000","0.00000000"],["110826.33000000","0.31924000"],["110826.32000000","0.32447000"],["110825.47000000","0.00000000"],["110825.46000000","0.45300000"],["110825.07000000","0.04509000"],["110824.27000000","0.00000000"],["110823.56000000","0.00069000"],["110823.45000000","0.00000000"],["110823.25000000","0.00000000"],["110822.89000000","0.00000000"],["110822.80000000","0.00000000"],["110822.69000000","0.11273000"],["110822.45000000","0.00000000"],["110822.34000000","0.26598000"],["110822.33000000","0.00000000"],["110822.28000000","0.00000000"],["110822.10000000","0.08567000"],["110820.75000000","0.00000000"],["110820.68000000","0.32449000"],["110820.45000000","0.00000000"],["110816.89000000","0.32450000"],["110816.87000000","0.00000000"],["110816.86000000","0.00000000"],["110816.85000000","0.24516000"],["110816.58000000","0.00000000"],["110816.55000000","0.00000000"],["110815.26000000","0.00000000"],["110815.00000000","0.00902000"],["110814.67000000","0.00070000"],["110814.38000000","0.18026000"],["110813.50000000","0.00000000"],["110811.77000000","0.00000000"],["110808.53000000","0.00000000"],["110808.30000000","0.01964000"],["110803.89000000","0.33876000"],["110803.42000000","0.00000000"],["110802.27000000","0.08567000"],["110800.67000000","0.00000000"],["110800.52000000","0.00000000"],["110796.32000000","0.00000000"],["110793.32000000","0.08567000"],["110792.23000000","0.00000000"],["110789.93000000","0.04000000"],["110784.63000000","0.04800000"],["110784.15000000","0.13527000"],["110783.84000000","0.00000000"],["110766.95000000","0.13522000"],["110754.04000000","0.07167000"],["110749.68000000","0.00000000"],["110743.48000000","0.00000000"],["110736.83000000","3.24539000"],["110731.72000000","0.00000000"],["110725.78000000","0.02888000"],["110722.07000000","0.13527000"],["110705.38000000","0.03400000"],["110704.87000000","0.03939000"],["110704.53000000","0.02298000"],["110686.97000000","0.00000000"],["110678.08000000","0.08794000"],["110569.46000000","0.00000000"],["110562.32000000","0.02998000"],["110561.02000000","0.00470000"],["110453.20000000","0.00333000"],["110447.66000000","0.00000000"],["110432.98000000","0.00000000"],["110227.13000000","0.02822000"],["109500.00000000","9.48567000"],["108500.00000000","44.12961000"],["99752.00000000","0.00010000"],["88669.24000000","0.00037000"]],"a":[["110836.56000000","6.04267000"],["110836.57000000","0.00005000"],["110836.72000000","0.00917000"],["110836.76000000","0.03618000"],["110836.87000000","0.00000000"],["110836.88000000","0.00000000"],["110836.93000000","0.00010000"],["110836.94000000","0.01373000"],["110838.37000000","0.04059000"],["110838.72000000","0.21165000"],["110838.73000000","0.06651000"],["110838.77000000","0.00366000"],["110839.31000000","0.00000000"],["110839.32000000","0.00000000"],["110839.42000000","0.00005000"],["110839.47000000","0.00000000"],["110839.48000000","0.04025000"],["110839.61000000","0.00000000"],["110839.68000000","0.00000000"],["110839.83000000","0.00000000"],["110839.89000000","0.00000000"],["110840.23000000","0.04516000"],["110840.43000000","0.00561000"],["110840.82000000","0.04511000"],["110840.89000000","0.04516000"],["110840.94000000","0.01804000"],["110841.39000000","0.00000000"],["110841.54000000","0.00722000"],["110841.59000000","0.18026000"],["110841.66000000","0.00000000"],["110841.68000000","0.00000000"],["110841.69000000","0.00000000"],["110841.70000000","0.00558000"],["110841.71000000","0.00264000"],["110841.74000000","0.00000000"],["110842.08000000","0.00000000"],["110842.22000000","0.32442000"],["110842.23000000","0.00000000"],["110842.24000000","0.00000000"],["110842.45000000","0.00000000"],["110842.64000000","0.00000000"],["110842.65000000","0.01814000"],["110842.76000000","0.01804000"],["110843.34000000","0.01804000"],["110843.35000000","0.03613000"],["110843.50000000","0.00400000"],["110843.96000000","0.00000000"],["110843.97000000","0.00000000"],["110844.11000000","0.00000000"],["110844.62000000","0.32442000"],["110844.64000000","0.00000000"],["110844.65000000","0.05012000"],["110845.28000000","0.18026000"],["110845.55000000","0.01768000"],["110846.83000000","0.06646000"],["110846.97000000","0.04503000"],["110847.51000000","0.00000000"],["110847.53000000","0.08376000"],["110847.57000000","0.00000000"],["110847.62000000","0.00000000"],["110847.63000000","0.03608000"],["110848.28000000","0.00313000"],["110848.62000000","0.00000000"],["110849.36000000","0.32440000"],["110849.72000000","0.18026000"],["110850.51000000","1.29613000"],["110850.69000000","0.00000000"],["110850.72000000","0.32440000"],["110851.47000000","0.00000000"],["110852.51000000","3.24539000"],["110852.76000000","0.00000000"],["110853.18000000","0.24800000"],["110853.87000000","0.00000000"],["110855.03000000","0.00000000"],["110855.48000000","0.08567000"],["110855.85000000","2.48191000"],["110855.88000000","0.00000000"],["110856.27000000","0.00000000"],["110856.69000000","0.00000000"],["110862.99000000","0.00000000"],["110864.11000000","0.01964000"],["110867.61000000","0.22546000"],["110868.47000000","0.00000000"],["110868.51000000","0.00000000"],["110871.13000000","0.00000000"],["110878.00000000","0.03250000"],["110881.41000000","0.00000000"],["110883.12000000","0.00000000"],["110883.66000000","0.13515000"],["110885.29000000","3.24539000"],["110886.42000000","0.00000000"],["110895.50000000","0.00000000"],["110899.27000000","0.00000000"],["110899.53000000","0.00000000"],["110905.70000000","0.03538000"],["110908.85000000","0.00224000"],["110912.47000000","0.00000000"],["110913.35000000","0.00000000"],["110913.42000000","0.00000000"],["110916.68000000","0.13527000"],["110917.11000000","0.00000000"],["110917.36000000","0.26101000"],["110918.53000000","0.00000000"],["110921.52000000","0.00000000"],["110925.98000000","0.00000000"],["110931.43000000","0.00000000"],["110943.49000000","0.00000000"],["110944.60000000","0.00000000"],["110944.80000000","0.00000000"],["110945.20000000","0.22546000"],["110945.58000000","0.18031000"],["110946.93000000","0.00000000"],["110947.37000000","0.00000000"],["110950.35000000","0.13515000"],["110971.12000000","0.00000000"],["110972.44000000","0.10839000"],["110985.87000000","0.00000000"],["110991.44000000","0.00331000"],["110997.64000000","0.99550000"],["111002.86000000","0.17314000"],["111008.43000000","0.00000000"],["111019.99000000","0.00090000"],["111085.24000000","0.00000000"],["111101.91000000","0.00000000"],["111148.67000000","0.00000000"],["111244.95000000","0.00000000"],["111259.71000000","0.00000000"],["111265.28000000","0.00082000"],["111612.41000000","0.00013000"],["112400.00000000","0.32324000"],["128001.97000000","0.00040000"]]}
[2025-10-11T22:17:27.329Z] {"e":"depthUpdate","E":1760221047014,"s":"BTCUSDT","U":77925968855,"u":77925970173,"b":[["110836.55000000","0.00000000"],["110836.54000000","0.00000000"],["110836.48000000","0.00000000"],["110836.39000000","0.00000000"],["110836.38000000","0.00000000"],["110836.18000000","0.00000000"],["110836.17000000","0.00000000"],["110835.11000000","0.00000000"],["110835.10000000","0.00000000"],["110834.99000000","0.00000000"],["110834.82000000","0.00000000"],["110834.34000000","0.00000000"],["110833.88000000","0.00000000"],["110833.87000000","0.00000000"],["110833.67000000","0.00000000"],["110833.53000000","0.00000000"],["110833.11000000","0.00000000"],["110833.07000000","0.00000000"],["110832.68000000","0.00617000"],["110832.67000000","0.00060000"],["110831.90000000","0.00000000"],["110831.89000000","0.00000000"],["110830.85000000","0.00005000"],["110830.47000000","0.00010000"],["110830.46000000","0.01815000"],["110829.40000000","0.00000000"],["110829.39000000","0.00000000"],["110829.12000000","0.04512000"],["110828.72000000","0.00000000"],["110828.71000000","0.00000000"],["110828.41000000","0.00000000"],["110828.40000000","0.00000000"],["110828.34000000","0.00000000"],["110828.33000000","0.00000000"],["110827.48000000","0.00010000"],["110827.47000000","0.00010000"],["110827.23000000","0.00000000"],["110827.22000000","0.00000000"],["110826.33000000","0.00000000"],["110826.32000000","0.00000000"],["110826.24000000","0.00000000"],["110825.46000000","0.00300000"],["110825.08000000","0.00000000"],["110825.07000000","0.00000000"],["110824.93000000","0.00000000"],["110823.82000000","0.00000000"],["110823.56000000","0.00000000"],["110823.51000000","0.00069000"],["110823.41000000","0.00000000"],["110822.69000000","0.00000000"],["110822.35000000","0.00000000"],["110822.34000000","0.00000000"],["110822.24000000","0.00000000"],["110822.22000000","0.00000000"],["110822.10000000","0.00000000"],["110822.00000000","0.00000000"],["110821.83000000","0.00069000"],["110821.12000000","0.00000000"],["110820.68000000","0.00000000"],["110820.01000000","0.00037000"],["110820.00000000","0.01759000"],["110819.81000000","0.00000000"],["110819.80000000","0.00000000"],["110819.11000000","0.04109000"],["110818.71000000","0.03404000"],["110818.70000000","0.11093000"],["110818.00000000","0.04153000"],["110817.84000000","0.32449000"],["110816.89000000","0.00000000"],["110816.85000000","0.27647000"],["110816.80000000","0.00000000"],["110816.59000000","0.00000000"],["110815.66000000","0.00000000"],["110815.56000000","0.00000000"],["110815.50000000","0.00010000"],["110814.97000000","0.01767000"],["110814.38000000","0.00000000"],["110814.07000000","0.00000000"],["110813.99000000","0.00000000"],["110812.87000000","0.08567000"],["110812.57000000","0.00000000"],["110811.09000000","0.32451000"],["110810.59000000","0.00000000"],["110810.58000000","0.00000000"],["110810.14000000","0.00000000"],["110808.84000000","0.11273000"],["110808.30000000","0.00000000"],["110806.77000000","0.00000000"],["110806.47000000","0.00072000"],["110805.03000000","0.00324000"],["110803.91000000","0.00000000"],["110803.89000000","0.23429000"],["110803.39000000","0.00000000"],["110802.64000000","0.00000000"],["110802.62000000","0.00000000"],["110802.50000000","0.00000000"],["110800.07000000","0.57603000"],["110799.95000000","0.00000000"],["110797.81000000","0.00285000"],["110797.66000000","0.00000000"],["110796.95000000","0.00000000"],["110789.93000000","0.00000000"],["110789.20000000","0.13527000"],["110788.99000000","0.20202000"],["110783.95000000","0.04000000"],["110780.92000000","0.00446000"],["110779.52000000","0.00007000"],["110779.33000000","0.00000000"],["110779.15000000","0.00276000"],["110777.13000000","0.00005000"],["110777.03000000","0.00000000"],["110775.73000000","0.00000000"],["110775.23000000","0.00000000"],["110773.63000000","0.00000000"],["110772.93000000","0.00000000"],["110772.53000000","0.24000000"],["110771.53000000","0.06000000"],["110771.33000000","0.32000000"],["110770.75000000","0.00000000"],["110770.09000000","0.00000000"],["110765.98000000","0.00000000"],["110755.57000000","0.00623000"],["110754.04000000","0.00000000"],["110752.97000000","0.00625000"],["110752.18000000","0.00000000"],["110751.78000000","0.00000000"],["110745.48000000","0.00000000"],["110743.50000000","1.27968000"],["110742.35000000","0.00000000"],["110738.00000000","0.02307000"],["110737.56000000","0.00000000"],["110730.17000000","3.24539000"],["110728.79000000","0.00000000"],["110728.26000000","0.00000000"],["110726.40000000","0.00000000"],["110725.81000000","0.03277000"],["110725.78000000","0.00000000"],["110724.43000000","0.04800000"],["110720.04000000","0.00000000"],["110720.03000000","0.00000000"],["110718.94000000","0.00000000"],["110717.39000000","0.00000000"],["110705.38000000","0.00000000"],["110703.57000000","0.07238000"],["110690.73000000","0.09641000"],["110686.12000000","0.07712000"],["110677.96000000","0.19481000"],["110677.95000000","0.00000000"],["110670.74000000","0.08694000"],["110662.26000000","0.99123000"],["110609.15000000","0.00000000"],["110609.14000000","0.00000000"],["110607.37000000","0.00000000"],["110562.32000000","0.00000000"],["110536.55000000","0.00000000"],["110473.75000000","0.00000000"],["99752.00000000","0.00010000"],["88669.24000000","0.00015000"],["88666.15000000","0.00022000"],["55463.58000000","0.00040000"],["55446.00000000","0.00040000"],["33000.00000000","3.75190000"]],"a":[["110832.69000000","15.74700000"],["110833.12000000","0.00000000"],["110833.54000000","0.00000000"],["110833.88000000","9.43905000"],["110833.89000000","1.48742000"],["110834.12000000","0.00000000"],["110834.25000000","0.00000000"],["110834.32000000","0.00000000"],["110834.34000000","0.00000000"],["110834.35000000","0.08565000"],["110834.41000000","0.00083000"],["110834.83000000","0.00000000"],["110835.00000000","0.00000000"],["110836.15000000","0.00000000"],["110836.17000000","0.00000000"],["110836.18000000","0.00000000"],["110836.19000000","0.00000000"],["110836.37000000","0.00000000"],["110836.39000000","0.04800000"],["110836.40000000","1.05652000"],["110836.48000000","0.00010000"],["110836.49000000","0.00000000"],["110836.53000000","0.00000000"],["110836.55000000","0.00010000"],["110836.56000000","0.40302000"],["110836.57000000","0.00000000"],["110836.64000000","0.00000000"],["110836.76000000","0.03613000"],["110836.93000000","0.00000000"],["110836.94000000","0.01373000"],["110837.53000000","0.03613000"],["110837.55000000","0.00000000"],["110838.37000000","0.04049000"],["110838.72000000","0.00000000"],["110838.73000000","0.06646000"],["110839.17000000","0.00005000"],["110839.42000000","0.00000000"],["110839.43000000","0.00075000"],["110839.47000000","0.00000000"],["110839.48000000","0.04030000"],["110839.64000000","0.32443000"],["110839.86000000","0.04511000"],["110840.09000000","0.04511000"],["110840.23000000","0.04511000"],["110840.43000000","0.00561000"],["110840.69000000","0.03608000"],["110840.84000000","3.24539000"],["110841.45000000","0.00005000"],["110841.54000000","0.00727000"],["110841.58000000","0.00000000"],["110841.68000000","0.01804000"],["110842.76000000","0.01809000"],["110843.08000000","0.05870000"],["110843.13000000","0.32442000"],["110843.24000000","0.01804000"],["110844.19000000","3.24539000"],["110844.20000000","0.00149000"],["110844.28000000","0.00000000"],["110844.31000000","0.01804000"],["110844.62000000","0.00000000"],["110844.65000000","0.00000000"],["110845.19000000","0.00000000"],["110845.22000000","0.00007000"],["110845.55000000","0.01763000"],["110846.23000000","1.40954000"],["110846.62000000","0.00000000"],["110846.97000000","0.00000000"],["110847.52000000","3.24539000"],["110849.36000000","0.00000000"],["110849.88000000","0.00044000"],["110850.72000000","0.00000000"],["110851.12000000","0.00000000"],["110851.26000000","0.00007000"],["110851.61000000","0.00000000"],["110852.80000000","0.00000000"],["110853.09000000","0.00000000"],["110853.18000000","0.00000000"],["110853.32000000","0.00000000"],["110854.67000000","0.12000000"],["110855.00000000","0.00400000"],["110855.02000000","0.10560000"],["110855.69000000","0.08567000"],["110855.87000000","0.00000000"],["110857.26000000","0.01580000"],["110859.48000000","0.03538000"],["110862.54000000","0.00000000"],["110862.59000000","0.02800000"],["110864.11000000","0.00000000"],["110865.56000000","0.05588000"],["110866.30000000","0.00000000"],["110866.49000000","0.00000000"],["110867.61000000","0.00000000"],["110867.75000000","0.00000000"],["110869.34000000","0.00000000"],["110869.61000000","0.00000000"],["110869.62000000","0.00000000"],["110871.23000000","0.00000000"],["110875.07000000","0.00000000"],["110875.30000000","0.00000000"],["110877.07000000","0.00000000"],["110880.97000000","0.00000000"],["110881.73000000","0.06593000"],["110883.12000000","0.00000000"],["110883.66000000","0.00000000"],["110887.82000000","0.00000000"],["110890.18000000","0.00629000"],["110891.94000000","3.24544000"],["110892.77000000","0.00623000"],["110898.59000000","0.00000000"],["110899.08000000","0.00000000"],["110899.60000000","0.00000000"],["110901.56000000","0.09639000"],["110905.24000000","0.00000000"],["110905.70000000","0.00000000"],["110907.94000000","0.00000000"],["110908.86000000","0.00000000"],["110910.29000000","0.13527000"],["110911.86000000","0.21541000"],["110911.87000000","0.00000000"],["110912.67000000","0.00000000"],["110912.72000000","0.00000000"],["110913.20000000","0.00000000"],["110913.69000000","0.00000000"],["110916.68000000","0.00000000"],["110917.08000000","0.00000000"],["110919.84000000","0.00000000"],["110931.94000000","0.00000000"],["110943.63000000","0.00000000"],["110945.20000000","0.00000000"],["110945.58000000","0.00000000"],["110946.48000000","0.13527000"],["110947.21000000","0.00000000"],["110950.30000000","0.00000000"],["110950.35000000","0.00000000"],["110984.51000000","0.99640000"],["110994.60000000","0.21507000"],["110997.64000000","0.00000000"],["111056.63000000","0.04947000"],["111068.57000000","0.00000000"],["111079.01000000","0.00000000"],["111098.55000000","0.00017000"],["111152.12000000","0.02345000"],["111257.42000000","0.45000000"],["111268.51000000","0.00000000"],["111308.13000000","0.00000000"],["111353.99000000","0.00000000"],["111359.54000000","0.00046000"],["111398.32000000","0.00000000"],["128001.97000000","0.00040000"]]}
[2025-10-11T22:17:28.329Z] {"e":"depthUpdate","E":1760221048014,"s":"BTCUSDT","U":77925970174,"u":77925971407,"b":[["110832.68000000","0.00000000"],["110832.67000000","0.00000000"],["110831.66000000","0.00000000"],["110831.57000000","0.00000000"],["110831.34000000","0.00000000"],["110830.85000000","0.00000000"],["110830.54000000","0.00000000"],["110830.47000000","0.00000000"],["110830.46000000","0.00000000"],["110830.26000000","0.00000000"],["110830.23000000","0.00000000"],["110829.87000000","0.00000000"],["110829.13000000","0.00000000"],["110829.12000000","0.00000000"],["110828.05000000","0.00000000"],["110827.48000000","0.00000000"],["110827.47000000","0.00000000"],["110826.76000000","0.00000000"],["110825.46000000","0.00000000"],["110825.28000000","0.00000000"],["110824.70000000","0.00000000"],["110824.00000000","0.00000000"],["110823.68000000","0.00000000"],["110823.66000000","0.00000000"],["110823.51000000","0.00000000"],["110822.31000000","0.00000000"],["110822.03000000","0.00000000"],["110821.83000000","0.00000000"],["110821.35000000","0.00000000"],["110820.57000000","0.00000000"],["110820.56000000","5.83537000"],["110820.55000000","0.00000000"],["110820.48000000","0.00010000"],["110820.01000000","0.00027000"],["110820.00000000","0.01754000"],["110819.78000000","0.00000000"],["110819.77000000","0.11416000"],["110819.76000000","0.29750000"],["110819.45000000","0.00005000"],["110819.26000000","0.00000000"],["110819.13000000","0.00000000"],["110819.12000000","0.00000000"],["110819.11000000","0.04119000"],["110818.72000000","0.00000000"],["110818.71000000","0.00000000"],["110818.70000000","0.00000000"],["110818.01000000","0.00000000"],["110818.00000000","0.04158000"],["110817.84000000","0.00000000"],["110817.46000000","0.00000000"],["110817.32000000","0.00000000"],["110816.86000000","0.00000000"],["110816.85000000","0.40719000"],["110816.12000000","0.00005000"],["110816.05000000","0.04509000"],["110816.01000000","0.32450000"],["110815.57000000","0.00000000"],["110815.50000000","0.00000000"],["110815.21000000","0.32450000"],["110815.00000000","0.00902000"],["110814.99000000","0.00000000"],["110814.98000000","0.04800000"],["110814.97000000","0.01767000"],["110814.85000000","0.06646000"],["110814.67000000","0.00000000"],["110814.37000000","0.00000000"],["110814.24000000","0.04800000"],["110813.97000000","0.18026000"],["110813.55000000","0.00000000"],["110813.30000000","0.20197000"],["110813.17000000","0.00000000"],["110813.06000000","0.00000000"],["110812.87000000","0.00000000"],["110812.24000000","0.11273000"],["110811.11000000","0.67817000"],["110811.10000000","0.00000000"],["110810.44000000","0.18026000"],["110810.00000000","0.00132000"],["110809.48000000","0.00150000"],["110808.84000000","0.00000000"],["110807.50000000","0.00400000"],["110806.47000000","0.00000000"],["110806.23000000","0.32453000"],["110806.15000000","0.10025000"],["110806.09000000","0.00000000"],["110805.15000000","0.13527000"],["110805.03000000","0.00000000"],["110803.94000000","0.00149000"],["110803.89000000","0.32718000"],["110802.78000000","0.06646000"],["110802.41000000","0.07200000"],["110801.99000000","0.01500000"],["110801.33000000","0.00000000"],["110801.18000000","0.07200000"],["110800.06000000","0.13527000"],["110800.00000000","0.77720000"],["110798.83000000","0.01964000"],["110797.69000000","0.04800000"],["110795.84000000","0.00000000"],["110794.55000000","0.00005000"],["110792.58000000","0.00000000"],["110792.54000000","0.04000000"],["110790.60000000","0.00005000"],["110789.20000000","0.00000000"],["110788.99000000","0.00000000"],["110787.64000000","0.00000000"],["110787.32000000","0.04508000"],["110787.31000000","0.00300000"],["110786.42000000","0.00000000"],["110784.15000000","0.00000000"],["110783.95000000","0.00000000"],["110782.78000000","0.13522000"],["110779.54000000","1.23565000"],["110776.80000000","0.00005000"],["110772.53000000","0.00000000"],["110771.53000000","0.00000000"],["110771.33000000","0.00000000"],["110770.74000000","0.00005000"],["110768.33000000","0.62000000"],["110766.95000000","0.00000000"],["110763.78000000","0.00000000"],["110763.62000000","0.06650000"],["110758.86000000","0.00000000"],["110751.24000000","0.03277000"],["110747.26000000","0.02888000"],["110744.47000000","0.00000000"],["110743.97000000","0.00661000"],["110742.90000000","0.13527000"],["110742.28000000","0.00006000"],["110742.23000000","0.00000000"],["110740.56000000","0.00000000"],["110740.15000000","0.00000000"],["110738.93000000","1.46218000"],["110737.55000000","0.13527000"],["110737.03000000","0.13360000"],["110736.81000000","0.00000000"],["110732.93000000","0.09600000"],["110732.07000000","0.00000000"],["110730.61000000","0.00005000"],["110728.82000000","0.04800000"],["110728.70000000","0.00000000"],["110728.13000000","0.00000000"],["110728.01000000","0.00225000"],["110726.52000000","0.00000000"],["110725.81000000","0.00000000"],["110725.61000000","0.00000000"],["110725.33000000","0.00000000"],["110722.50000000","0.00005000"],["110722.07000000","0.00000000"],["110720.72000000","0.03939000"],["110718.50000000","0.00000000"],["110716.02000000","0.00167000"],["110714.45000000","0.01411000"],["110705.55000000","0.00000000"],["110704.87000000","0.00000000"],["110688.93000000","0.00000000"],["110678.87000000","0.99895000"],["110677.44000000","0.00160000"],["110662.26000000","0.00000000"],["110622.42000000","0.04297000"],["110605.07000000","0.00066000"],["110545.73000000","0.04947000"],["110512.23000000","0.00000000"],["110507.47000000","0.00000000"],["110500.37000000","0.17314000"],["110487.70000000","0.04297000"],["110476.15000000","0.00005000"],["110469.61000000","0.01241000"],["110468.77000000","0.00010000"],["110463.23000000","0.00010000"],["110457.69000000","0.00010000"],["110456.42000000","0.00333000"],["110453.20000000","0.00000000"],["110452.82000000","0.00000000"],["110452.15000000","0.00000000"],["110448.78000000","0.45118000"],["110445.71000000","0.00000000"],["110330.12000000","0.00749000"],["110000.00000000","11.10773000"],["105800.00000000","12.01381000"],["101969.64000000","0.00000000"],["99752.00000000","0.00000000"],["99738.00000000","0.00010000"],["88666.15000000","0.00000000"],["88656.45000000","0.00022000"],["55416.34000000","0.00040000"]],"a":[["110820.57000000","0.44797000"],["110820.65000000","0.00010000"],["110820.88000000","0.00000000"],["110822.04000000","0.00000000"],["110822.32000000","0.00000000"],["110823.28000000","0.00000000"],["110824.34000000","0.00000000"],["110824.36000000","0.00000000"],["110824.50000000","0.00000000"],["110824.51000000","0.00000000"],["110825.28000000","0.00005000"],["110825.30000000","0.00000000"],["110825.31000000","0.00000000"],["110825.32000000","0.00000000"],["110825.33000000","0.00000000"],["110826.10000000","0.00000000"],["110826.11000000","0.00000000"],["110826.52000000","0.00000000"],["110826.53000000","0.00000000"],["110826.97000000","0.00000000"],["110827.14000000","0.00000000"],["110827.19000000","0.00000000"],["110827.20000000","0.00000000"],["110827.48000000","0.00000000"],["110827.63000000","0.00000000"],["110827.64000000","0.00000000"],["110828.15000000","0.00000000"],["110829.02000000","0.00000000"],["110829.03000000","0.00000000"],["110829.13000000","0.00000000"],["110829.73000000","0.00000000"],["110829.74000000","0.00000000"],["110829.91000000","0.00010000"],["110829.92000000","0.05803000"],["110830.24000000","0.00000000"],["110830.27000000","0.00000000"],["110830.47000000","0.00000000"],["110831.20000000","0.00000000"],["110831.21000000","0.00000000"],["110831.34000000","0.00005000"],["110831.50000000","0.00000000"],["110831.58000000","0.00000000"],["110832.21000000","0.00005000"],["110832.31000000","0.00000000"],["110832.32000000","0.00000000"],["110832.57000000","0.00010000"],["110832.58000000","0.29746000"],["110832.66000000","0.00010000"],["110832.67000000","1.06249000"],["110832.68000000","0.00010000"],["110832.69000000","3.86560000"],["110832.77000000","0.00000000"],["110833.58000000","0.00000000"],["110833.87000000","0.00010000"],["110833.88000000","0.48285000"],["110833.89000000","0.00000000"],["110834.05000000","0.00000000"],["110834.13000000","0.00007000"],["110834.17000000","0.00070000"],["110834.35000000","0.04513000"],["110834.39000000","0.00072000"],["110834.40000000","0.00069000"],["110834.63000000","0.00010000"],["110834.89000000","0.00069000"],["110835.59000000","0.00000000"],["110835.77000000","0.00000000"],["110836.39000000","0.04005000"],["110836.40000000","0.66833000"],["110836.48000000","0.00000000"],["110836.55000000","0.00000000"],["110836.56000000","0.00005000"],["110836.72000000","0.00912000"],["110836.76000000","0.00000000"],["110836.94000000","0.01363000"],["110837.48000000","0.00007000"],["110837.53000000","0.00000000"],["110837.93000000","0.00000000"],["110838.04000000","0.04563000"],["110838.22000000","0.00000000"],["110838.23000000","0.00000000"],["110838.31000000","0.00000000"],["110838.33000000","0.32443000"],["110838.37000000","0.00005000"],["110838.72000000","0.00000000"],["110838.77000000","0.00361000"],["110838.84000000","0.00000000"],["110839.48000000","0.00000000"],["110839.52000000","0.00006000"],["110839.64000000","0.00000000"],["110839.86000000","0.00000000"],["110840.09000000","0.00000000"],["110840.17000000","0.00010000"],["110840.23000000","0.00005000"],["110840.43000000","0.00546000"],["110840.69000000","0.03613000"],["110840.80000000","0.00000000"],["110840.81000000","0.00000000"],["110840.82000000","0.00000000"],["110840.83000000","0.14915000"],["110840.84000000","0.00000000"],["110840.89000000","0.00000000"],["110840.94000000","0.00000000"],["110841.54000000","0.00727000"],["110841.59000000","0.00000000"],["110841.68000000","0.00000000"],["110841.70000000","0.00558000"],["110841.71000000","0.00264000"],["110841.98000000","0.00000000"],["110842.22000000","0.00000000"],["110842.44000000","0.00305000"],["110842.65000000","0.01804000"],["110842.73000000","0.11273000"],["110842.74000000","0.00300000"],["110842.76000000","0.00000000"],["110842.96000000","0.32442000"],["110843.08000000","0.00000000"],["110843.13000000","0.00000000"],["110843.24000000","0.00000000"],["110843.34000000","0.00000000"],["110843.35000000","0.03608000"],["110843.97000000","0.04000000"],["110844.17000000","0.00450000"],["110844.18000000","0.00000000"],["110844.19000000","0.00000000"],["110844.20000000","0.00000000"],["110844.78000000","0.11520000"],["110845.28000000","0.00000000"],["110845.78000000","0.12240000"],["110846.22000000","0.18026000"],["110846.99000000","0.14400000"],["110847.53000000","0.00000000"],["110848.57000000","0.00000000"],["110848.69000000","0.00000000"],["110848.73000000","0.01964000"],["110848.81000000","0.00000000"],["110849.31000000","0.08160000"],["110849.60000000","0.00000000"],["110849.71000000","0.30417000"],["110849.74000000","0.00000000"],["110849.88000000","0.00000000"],["110849.91000000","0.19680000"],["110849.94000000","0.00000000"],["110850.13000000","0.00012000"],["110850.14000000","0.13527000"],["110850.28000000","0.13522000"],["110850.55000000","0.00901000"],["110851.26000000","0.00000000"],["110851.68000000","0.00271000"],["110852.91000000","0.13527000"],["110853.81000000","0.04509000"],["110854.05000000","0.00437000"],["110855.21000000","0.08567000"],["110856.36000000","0.00000000"],["110857.26000000","0.00000000"],["110857.97000000","0.00000000"],["110858.94000000","0.00000000"],["110859.27000000","0.00225000"],["110859.47000000","0.00180000"],["110859.48000000","0.48066000"],["110860.25000000","0.00000000"],["110861.03000000","1.18307000"],["110864.15000000","0.00000000"],["110865.50000000","0.00000000"],["110865.57000000","0.18031000"],["110865.86000000","0.22546000"],["110866.15000000","0.00000000"],["110868.41000000","0.00000000"],["110869.44000000","0.00000000"],["110869.99000000","0.00000000"],["110870.99000000","0.22546000"],["110871.59000000","0.00000000"],["110871.95000000","0.00000000"],["110872.33000000","0.00000000"],["110872.99000000","0.00000000"],["110875.06000000","0.00000000"],["110878.00000000","0.00100000"],["110878.94000000","0.00000000"],["110879.82000000","0.00000000"],["110880.53000000","0.13515000"],["110885.88000000","0.00000000"],["110890.58000000","0.03150000"],["110895.38000000","0.18190000"],["110897.93000000","0.13522000"],["110898.59000000","3.24539000"],["110900.14000000","0.00000000"],["110911.24000000","0.13527000"],["110915.19000000","0.03538000"],["110919.89000000","0.00000000"],["110922.99000000","0.00000000"],["110929.20000000","0.00000000"],["110931.83000000","0.01411000"],["110933.79000000","0.22546000"],["110937.12000000","0.13515000"],["110937.95000000","0.00000000"],["110938.20000000","0.00000000"],["110938.50000000","0.00000000"],["110943.15000000","0.18031000"],["110943.44000000","0.22546000"],["110950.30000000","0.12000000"],["110977.17000000","0.00000000"],["110983.91000000","0.00000000"],["110984.51000000","0.00000000"],["110991.44000000","0.00000000"],["110994.67000000","0.00331000"],["110995.14000000","0.99028000"],["111007.36000000","0.00000000"],["111035.27000000","0.41323000"],["111042.49000000","0.00000000"],["111046.31000000","0.00000000"],["111051.91000000","0.23925000"],["111054.19000000","0.00000000"],["111057.53000000","0.00000000"],["111068.57000000","0.23925000"],["111158.44000000","0.00000000"],["111162.31000000","0.00000000"],["111165.79000000","0.00000000"],["111257.42000000","0.45000000"],["111257.74000000","0.00000000"],["111265.28000000","0.00000000"],["111268.51000000","0.45082000"],["111343.00000000","0.00671000"],["111359.54000000","0.00000000"],["111398.32000000","0.00046000"],["115000.00000000","47.94681000"],["128001.97000000","0.03006000"]]}
[2025-10-11T22:17:29.328Z] {"e":"depthUpdate","E":1760221049014,"s":"BTCUSDT","U":77925971408,"u":77925971667,"b":[["110820.56000000","5.47523000"],["110820.01000000","0.00037000"],["110819.78000000","0.00010000"],["110819.77000000","0.11426000"],["110819.76000000","0.29745000"],["110819.13000000","0.00000000"],["110819.12000000","0.00010000"],["110819.11000000","0.04114000"],["110818.34000000","0.00005000"],["110818.01000000","0.00005000"],["110816.85000000","0.40714000"],["110816.69000000","0.00541000"],["110815.58000000","0.00722000"],["110814.85000000","0.00000000"],["110813.97000000","0.00000000"],["110813.79000000","0.18026000"],["110805.17000000","0.52803000"],["110805.16000000","0.36050000"],["110804.97000000","0.00000000"],["110804.41000000","0.04800000"],["110804.40000000","0.04800000"],["110804.07000000","0.01500000"],["110803.89000000","0.00000000"],["110802.92000000","0.00000000"],["110801.99000000","0.00000000"],["110793.03000000","0.00000000"],["110792.15000000","0.00000000"],["110789.35000000","0.18031000"],["110789.21000000","0.22546000"],["110787.85000000","0.01810000"],["110787.32000000","0.00000000"],["110787.31000000","0.00309000"],["110780.44000000","0.00000000"],["110772.77000000","0.13515000"],["110769.67000000","0.00000000"],["110763.62000000","0.00000000"],["110754.07000000","0.00009000"],["110737.03000000","0.00010000"],["110736.42000000","0.00000000"],["110733.71000000","0.00005000"],["110733.43000000","1.27314000"],["110732.07000000","0.07200000"],["110723.96000000","0.01411000"],["110720.82000000","0.00009000"],["110716.02000000","0.00000000"],["110714.45000000","0.00000000"],["110713.16000000","0.00000000"],["110712.42000000","0.18031000"],["110712.16000000","0.00000000"],["110711.72000000","0.22546000"],["110710.71000000","0.13515000"],["110704.01000000","0.00167000"],["110703.17000000","0.00000000"],["110695.52000000","0.07572000"],["110687.58000000","0.00009000"],["110681.90000000","0.67920000"],["110669.92000000","0.00000000"],["110669.67000000","0.08595000"],["110654.33000000","0.00009000"],["110605.07000000","0.00000000"],["110592.72000000","0.00066000"],["110587.48000000","0.00000000"],["110578.10000000","0.00587000"],["110468.12000000","0.00333000"],["110456.42000000","0.00000000"],["110155.64000000","0.00000000"],["105460.61000000","0.00000000"],["99738.00000000","0.00010000"],["88656.45000000","0.00022000"],["39895.40000000","0.00016000"]],"a":[["110820.57000000","2.67439000"],["110822.78000000","0.00366000"],["110823.49000000","0.00000000"],["110823.50000000","0.00010000"],["110823.88000000","0.00005000"],["110824.44000000","0.00551000"],["110824.99000000","0.00005000"],["110825.22000000","0.00010000"],["110825.23000000","0.04337000"],["110827.48000000","0.00010000"],["110827.49000000","0.08893000"],["110827.50000000","0.29748000"],["110828.05000000","0.00005000"],["110829.91000000","0.00000000"],["110829.92000000","0.00000000"],["110830.05000000","0.00000000"],["110830.06000000","0.00000000"],["110831.65000000","0.00010000"],["110831.66000000","0.45005000"],["110832.02000000","0.00089000"],["110832.21000000","0.00000000"],["110832.57000000","0.00000000"],["110832.58000000","0.00000000"],["110832.68000000","0.00000000"],["110832.69000000","3.86560000"],["110832.96000000","0.00005000"],["110833.28000000","0.32450000"],["110833.87000000","0.00000000"],["110833.88000000","0.22202000"],["110834.05000000","0.04008000"],["110834.35000000","0.04508000"],["110834.41000000","0.00000000"],["110835.16000000","0.03974000"],["110835.83000000","0.32444000"],["110836.39000000","0.00000000"],["110836.40000000","0.45036000"],["110836.72000000","0.00907000"],["110838.04000000","0.04568000"],["110838.33000000","0.00000000"],["110838.72000000","0.00450000"],["110838.77000000","0.00366000"],["110840.23000000","0.00000000"],["110840.43000000","0.00000000"],["110840.69000000","0.03608000"],["110840.83000000","0.20769000"],["110841.53000000","0.00000000"],["110841.54000000","0.00000000"],["110841.70000000","0.00553000"],["110841.71000000","0.00259000"],["110842.44000000","0.00300000"],["110842.89000000","0.18026000"],["110842.95000000","0.00000000"],["110844.17000000","0.00000000"],["110847.28000000","0.32441000"],["110848.85000000","0.00005000"],["110853.15000000","0.36050000"],["110853.81000000","0.00000000"],["110853.82000000","0.00009000"],["110868.25000000","0.00000000"],["110869.43000000","0.00000000"],["110876.02000000","0.14400000"],["110887.06000000","0.00009000"],["110892.76000000","0.00224000"],["110895.38000000","1.12747000"],["110902.68000000","0.00000000"],["110908.85000000","0.00000000"],["110909.99000000","0.00225000"],["110915.19000000","0.00000000"],["110920.31000000","0.00009000"],["110922.54000000","0.00000000"],["110935.93000000","0.00000000"],["110937.94000000","0.00000000"],["110953.55000000","0.00009000"],["110966.36000000","0.00901000"],["110969.18000000","0.00000000"],["110969.99000000","0.00090000"],["110983.41000000","0.00000000"],["110983.42000000","0.48858000"],["110984.51000000","0.00000000"],["110986.80000000","0.00009000"],["110993.23000000","0.99464000"],["110994.67000000","0.00000000"],["110995.14000000","0.00000000"],["111002.43000000","0.00000000"],["111003.99000000","0.00090000"],["111006.42000000","0.00331000"],["111019.99000000","0.00000000"],["111021.36000000","0.00090000"],["111033.99000000","0.00000000"],["111042.49000000","0.03370000"],["111050.44000000","0.00000000"],["111268.51000000","0.45000000"],["111280.27000000","0.00082000"],["111308.13000000","0.67153000"],["111483.80000000","0.00000000"],["128001.97000000","0.03006000"]]}
[2025-10-11T22:17:30.328Z] {"e":"depthUpdate","E":1760221050014,"s":"BTCUSDT","U":77925971668,"u":77925972135,"b":[["110820.56000000","4.54151000"],["110820.55000000","0.00010000"],["110820.45000000","0.00000000"],["110820.44000000","0.00000000"],["110820.17000000","0.29745000"],["110820.01000000","0.00037000"],["110820.00000000","0.01749000"],["110819.78000000","0.00000000"],["110819.77000000","0.00000000"],["110819.76000000","0.00000000"],["110819.13000000","0.00000000"],["110819.12000000","0.00010000"],["110818.01000000","0.10140000"],["110818.00000000","0.04153000"],["110817.50000000","0.00010000"],["110817.49000000","0.00000000"],["110816.86000000","0.00010000"],["110816.85000000","0.19183000"],["110816.43000000","0.32450000"],["110816.05000000","0.00000000"],["110816.01000000","0.00000000"],["110815.22000000","0.00000000"],["110815.21000000","0.00000000"],["110814.99000000","0.00000000"],["110814.25000000","0.00000000"],["110813.79000000","0.00000000"],["110813.50000000","0.00000000"],["110813.39000000","0.00000000"],["110813.31000000","0.32451000"],["110813.30000000","0.00000000"],["110812.25000000","0.00000000"],["110811.12000000","0.18026000"],["110811.11000000","0.47821000"],["110810.45000000","0.18027000"],["110810.44000000","0.00000000"],["110809.47000000","0.04509000"],["110807.51000000","0.00000000"],["110807.09000000","0.00069000"],["110807.00000000","0.00072000"],["110806.74000000","0.08567000"],["110806.23000000","0.00000000"],["110805.67000000","0.00330000"],["110805.61000000","0.32453000"],["110805.17000000","0.35488000"],["110805.16000000","0.00000000"],["110805.15000000","0.00000000"],["110802.01000000","0.20199000"],["110800.98000000","0.00000000"],["110800.08000000","0.00000000"],["110800.06000000","0.00000000"],["110798.83000000","0.00000000"],["110797.29000000","0.00000000"],["110796.09000000","0.00000000"],["110793.63000000","0.36053000"],["110793.62000000","0.48700000"],["110793.61000000","0.00000000"],["110792.54000000","0.00000000"],["110788.65000000","0.13527000"],["110788.55000000","0.00000000"],["110788.43000000","0.22546000"],["110785.76000000","0.04000000"],["110783.86000000","0.13527000"],["110782.78000000","0.00000000"],["110766.42000000","0.13522000"],["110763.59000000","0.06605000"],["110751.24000000","0.00000000"],["110747.26000000","0.00000000"],["110742.90000000","0.00000000"],["110737.55000000","0.00000000"],["110736.23000000","0.03277000"],["110734.07000000","0.00000000"],["110726.59000000","0.13527000"],["110726.04000000","0.29337000"],["110725.42000000","0.00000000"],["110723.52000000","3.24539000"],["110721.80000000","0.13527000"],["110720.72000000","0.00000000"],["110712.95000000","0.02888000"],["110712.63000000","0.22546000"],["110704.36000000","0.03939000"],["110681.90000000","0.36770000"],["110678.87000000","0.00000000"],["110668.18000000","0.08595000"],["110665.18000000","0.99733000"],["110578.09000000","0.00000000"],["110576.15000000","4.63736000"],["110468.12000000","0.00000000"],["110451.77000000","0.00333000"],["110402.31000000","0.45000000"],["110155.64000000","0.00000000"],["109712.36000000","0.00005000"],["99738.00000000","0.00010000"],["88656.45000000","0.00022000"],["60000.00000000","56.18404000"],["39895.40000000","0.00032000"]],"a":[["110820.57000000","5.69034000"],["110820.58000000","0.00050000"],["110820.59000000","0.00005000"],["110822.31000000","0.22922000"],["110822.32000000","0.29749000"],["110822.77000000","0.00005000"],["110823.50000000","0.00005000"],["110824.44000000","0.00556000"],["110824.98000000","0.04005000"],["110824.99000000","0.00000000"],["110825.13000000","0.00000000"],["110825.14000000","0.00000000"],["110825.15000000","0.00000000"],["110825.23000000","0.04352000"],["110825.79000000","0.00005000"],["110826.10000000","0.00010000"],["110826.11000000","0.04513000"],["110826.92000000","0.06656000"],["110827.48000000","0.00000000"],["110827.49000000","0.00000000"],["110827.50000000","0.00000000"],["110827.84000000","0.00000000"],["110828.05000000","0.01839000"],["110828.07000000","0.00000000"],["110829.87000000","0.00079000"],["110830.90000000","0.00000000"],["110830.91000000","0.32446000"],["110831.40000000","0.00005000"],["110831.50000000","0.00400000"],["110831.65000000","0.00000000"],["110831.66000000","0.45000000"],["110832.02000000","0.00000000"],["110832.08000000","0.04005000"],["110832.66000000","0.00450000"],["110832.67000000","1.06244000"],["110832.69000000","3.86555000"],["110833.28000000","0.00000000"],["110833.88000000","0.38046000"],["110834.05000000","0.00000000"],["110834.17000000","0.00000000"],["110834.35000000","0.00005000"],["110834.39000000","0.00000000"],["110834.40000000","0.00000000"],["110834.89000000","0.00000000"],["110835.15000000","0.00000000"],["110835.16000000","0.00000000"],["110836.06000000","0.00005000"],["110836.72000000","0.00907000"],["110836.89000000","0.00000000"],["110836.93000000","0.00000000"],["110836.94000000","0.01358000"],["110837.39000000","0.13522000"],["110837.52000000","0.00000000"],["110838.04000000","0.04563000"],["110838.72000000","0.00000000"],["110838.73000000","0.06651000"],["110838.77000000","0.00361000"],["110839.36000000","0.18026000"],["110840.71000000","0.32443000"],["110840.83000000","1.05665000"],["110842.96000000","0.00000000"],["110843.89000000","3.24539000"],["110843.97000000","0.00000000"],["110846.98000000","0.36050000"],["110847.28000000","0.00000000"],["110850.28000000","0.00000000"],["110853.15000000","0.00000000"],["110864.90000000","0.00000000"],["110867.12000000","0.13522000"],["110872.90000000","0.03150000"],["110890.58000000","0.00000000"],["110897.93000000","0.00000000"],["110904.16000000","0.03538000"],["110928.34000000","0.00000000"],["110963.50000000","0.10739000"],["110967.63000000","0.06000000"],["110983.42000000","0.68474000"],["110984.51000000","0.99683000"],["110990.00000000","0.00463000"],["110993.23000000","0.00000000"],["111006.42000000","0.00000000"],["111054.19000000","1.19405000"],["111068.57000000","0.00000000"],["111068.99000000","4.74104000"],["111078.37000000","0.00000000"],["111150.00000000","0.03111000"],["111263.83000000","0.00082000"],["111268.51000000","0.00000000"],["111280.00000000","0.00098000"],["111280.27000000","0.00000000"],["111374.66000000","0.00121000"],["128001.97000000","0.00040000"]]}
[2025-10-11T22:17:31.328Z] {"e":"depthUpdate","E":1760221051014,"s":"BTCUSDT","U":77925972136,"u":77925972412,"b":[["110820.56000000","4.54312000"],["110820.55000000","0.00020000"],["110820.19000000","0.00010000"],["110820.18000000","0.14977000"],["110820.01000000","0.00027000"],["110819.11000000","0.04109000"],["110818.02000000","0.00000000"],["110818.01000000","0.00010000"],["110817.50000000","0.00000000"],["110816.86000000","0.00005000"],["110816.85000000","0.19183000"],["110813.31000000","0.00000000"],["110807.09000000","0.00000000"],["110806.97000000","0.00069000"],["110804.27000000","0.32453000"],["110797.77000000","0.00000000"],["110793.21000000","0.01964000"],["110736.23000000","0.00000000"],["110730.42000000","0.00000000"],["110726.04000000","1.22985000"],["110723.70000000","0.03277000"],["110712.95000000","0.00000000"],["110710.35000000","0.02888000"],["110556.82000000","0.34629000"],["110516.03000000","0.00000000"],["110455.34000000","0.07396000"],["110451.77000000","0.00000000"],["110443.77000000","0.00361000"],["110227.13000000","0.00000000"],["109300.00000000","0.57645000"],["99738.00000000","0.00010000"],["88656.45000000","0.00022000"],["60000.00000000","56.18394000"],["33000.00000000","3.75190000"]],"a":[["110820.57000000","5.67674000"],["110820.58000000","0.00045000"],["110820.59000000","0.00000000"],["110821.68000000","0.13807000"],["110821.69000000","0.29749000"],["110822.30000000","0.00000000"],["110822.31000000","0.00000000"],["110822.32000000","0.00000000"],["110822.78000000","0.00371000"],["110823.50000000","0.00000000"],["110823.73000000","0.04148000"],["110824.44000000","0.00556000"],["110824.73000000","0.00000000"],["110824.84000000","0.04073000"],["110824.97000000","0.00000000"],["110824.98000000","0.00000000"],["110825.23000000","0.04352000"],["110825.79000000","0.00000000"],["110826.92000000","0.06656000"],["110827.45000000","0.00000000"],["110827.46000000","0.00000000"],["110828.05000000","0.01839000"],["110829.86000000","0.00005000"],["110830.91000000","0.32446000"],["110831.66000000","0.45000000"],["110833.97000000","0.00000000"],["110834.35000000","0.00000000"],["110834.75000000","0.00005000"],["110837.06000000","0.13522000"],["110837.39000000","0.00000000"],["110839.36000000","0.00000000"],["110839.56000000","0.18026000"],["110840.01000000","0.32443000"],["110840.43000000","2.25640000"],["110840.44000000","3.24539000"],["110840.45000000","0.32443000"],["110840.69000000","0.03608000"],["110840.71000000","0.00000000"],["110840.83000000","0.00000000"],["110861.55000000","0.00000000"],["110867.12000000","0.00000000"],["110891.78000000","0.00420000"],["110895.38000000","0.18190000"],["110897.59000000","0.00000000"],["110897.98000000","0.13522000"],["110898.59000000","0.00000000"],["110898.81000000","0.03538000"],["110904.16000000","0.00000000"],["110907.27000000","0.00100000"],["110907.28000000","0.00100000"],["110907.29000000","0.00000000"],["110916.41000000","0.00005000"],["110917.07000000","0.00000000"],["110925.33000000","0.00000000"],["110925.34000000","0.00000000"],["110981.96000000","0.00331000"],["110984.51000000","0.99618000"],["110990.00000000","0.00132000"],["110992.78000000","0.00000000"],["111007.36000000","0.49395000"],["111046.42000000","0.34339000"],["111255.79000000","0.00082000"],["111263.83000000","0.00000000"],["128001.97000000","0.00040000"]]}
[2025-10-11T22:17:32.328Z] {"e":"depthUpdate","E":1760221052014,"s":"BTCUSDT","U":77925972413,"u":77925973201,"b":[["110820.56000000","4.76087000"],["110820.55000000","0.00005000"],["110820.41000000","0.29745000"],["110820.19000000","0.00010000"],["110820.18000000","0.04431000"],["110820.17000000","0.00000000"],["110820.01000000","0.00037000"],["110820.00000000","0.01759000"],["110819.12000000","0.00010000"],["110819.11000000","0.04119000"],["110818.01000000","0.00010000"],["110818.00000000","0.04163000"],["110817.74000000","0.00000000"],["110816.86000000","0.00005000"],["110816.85000000","0.33902000"],["110816.69000000","0.00546000"],["110816.43000000","0.00000000"],["110816.05000000","0.04514000"],["110815.79000000","0.32450000"],["110815.58000000","0.00727000"],["110815.34000000","0.00000000"],["110815.33000000","0.00000000"],["110815.00000000","0.00907000"],["110814.47000000","0.01805000"],["110814.25000000","0.00000000"],["110813.68000000","0.08567000"],["110813.43000000","0.18026000"],["110813.42000000","0.00000000"],["110813.35000000","0.32451000"],["110812.24000000","0.00000000"],["110811.09000000","0.00000000"],["110810.97000000","0.00000000"],["110810.45000000","0.00000000"],["110809.47000000","0.00000000"],["110809.04000000","0.32452000"],["110807.14000000","0.00072000"],["110807.00000000","0.00000000"],["110806.97000000","0.00000000"],["110806.74000000","0.00000000"],["110806.70000000","0.11273000"],["110806.61000000","0.00000000"],["110806.00000000","0.00459000"],["110805.67000000","0.00000000"],["110805.61000000","0.00000000"],["110805.03000000","0.32453000"],["110804.27000000","0.00000000"],["110798.75000000","0.00000000"],["110795.86000000","0.00000000"],["110793.79000000","0.01964000"],["110793.65000000","1.56923000"],["110793.64000000","3.24539000"],["110793.62000000","0.00000000"],["110793.21000000","0.00000000"],["110791.86000000","0.00000000"],["110789.36000000","0.22546000"],["110789.35000000","0.00000000"],["110789.21000000","0.00000000"],["110789.20000000","0.18031000"],["110788.43000000","0.00000000"],["110785.87000000","0.04000000"],["110785.76000000","0.00000000"],["110785.48000000","0.22546000"],["110779.54000000","0.00000000"],["110777.97000000","1.21283000"],["110774.01000000","0.02998000"],["110773.68000000","0.13515000"],["110772.77000000","0.00000000"],["110758.80000000","0.00000000"],["110747.39000000","0.00000000"],["110743.81000000","0.00000000"],["110743.35000000","0.00000000"],["110741.28000000","0.00000000"],["110739.44000000","0.00430000"],["110736.99000000","0.13190000"],["110735.32000000","0.00000000"],["110730.54000000","0.03277000"],["110729.65000000","0.00000000"],["110726.04000000","0.29337000"],["110723.70000000","0.00000000"],["110723.52000000","0.00000000"],["110719.05000000","0.02888000"],["110716.79000000","0.22115000"],["110713.33000000","0.00000000"],["110712.63000000","0.00000000"],["110712.51000000","0.18031000"],["110712.42000000","0.00000000"],["110712.16000000","0.00000000"],["110712.05000000","0.22546000"],["110711.78000000","0.22546000"],["110711.72000000","0.00000000"],["110711.62000000","0.13515000"],["110710.71000000","0.00000000"],["110710.35000000","0.00000000"],["110592.41000000","0.02998000"],["110552.32000000","0.02998000"],["110445.61000000","0.00333000"],["110443.77000000","0.00028000"],["110433.56000000","0.00000000"],["105460.97000000","0.00000000"],["101000.00000000","41.53259000"],["99738.00000000","0.00010000"],["88656.45000000","0.00022000"],["39895.40000000","0.00048000"]],"a":[["110820.57000000","3.74039000"],["110820.58000000","0.00050000"],["110820.71000000","0.00010000"],["110820.72000000","0.16008000"],["110820.73000000","0.00912000"],["110820.94000000","0.00010000"],["110820.95000000","0.01364000"],["110821.55000000","0.00010000"],["110821.56000000","0.00010000"],["110821.67000000","0.00000000"],["110821.68000000","0.00000000"],["110821.69000000","0.00000000"],["110822.77000000","0.00000000"],["110822.78000000","0.00366000"],["110823.72000000","0.00000000"],["110823.73000000","0.00000000"],["110823.89000000","0.00000000"],["110824.05000000","0.29744000"],["110824.11000000","0.00000000"],["110824.12000000","0.00000000"],["110824.44000000","0.00551000"],["110824.83000000","0.00000000"],["110824.84000000","0.00000000"],["110824.85000000","0.00010000"],["110824.86000000","0.05542000"],["110825.22000000","0.00000000"],["110825.23000000","0.00000000"],["110825.75000000","0.00000000"],["110826.10000000","0.00005000"],["110826.11000000","0.04508000"],["110826.27000000","0.00000000"],["110826.28000000","0.00000000"],["110826.44000000","0.00000000"],["110826.45000000","0.00000000"],["110826.75000000","0.00005000"],["110826.92000000","0.00000000"],["110827.88000000","0.00010000"],["110827.93000000","0.00082000"],["110827.98000000","0.00000000"],["110828.05000000","0.00005000"],["110828.14000000","0.06656000"],["110828.82000000","0.00000000"],["110828.83000000","0.00000000"],["110829.64000000","0.00000000"],["110829.77000000","0.00000000"],["110829.87000000","0.00000000"],["110830.21000000","0.00000000"],["110830.63000000","0.00000000"],["110830.91000000","0.00000000"],["110831.50000000","0.00405000"],["110831.65000000","0.00000000"],["110831.66000000","0.45000000"],["110831.74000000","0.00000000"],["110831.88000000","0.04000000"],["110832.08000000","0.00000000"],["110832.21000000","0.00005000"],["110832.52000000","0.00000000"],["110832.53000000","0.00000000"],["110832.66000000","0.00000000"],["110832.67000000","1.06244000"],["110832.68000000","0.00000000"],["110832.69000000","3.86555000"],["110833.25000000","0.04101000"],["110833.48000000","0.01788000"],["110833.52000000","0.00000000"],["110833.87000000","0.00000000"],["110833.88000000","0.38046000"],["110833.93000000","0.00000000"],["110834.07000000","0.00000000"],["110834.34000000","0.00455000"],["110834.35000000","0.00000000"],["110834.36000000","0.03963000"],["110834.56000000","0.00000000"],["110834.64000000","0.00069000"],["110835.82000000","0.00000000"],["110835.83000000","0.00000000"],["110836.39000000","0.00000000"],["110836.71000000","0.32444000"],["110836.72000000","0.00902000"],["110836.94000000","0.00000000"],["110837.43000000","0.32444000"],["110838.03000000","0.00000000"],["110838.04000000","0.04563000"],["110838.37000000","0.00000000"],["110838.73000000","0.06646000"],["110838.81000000","0.00000000"],["110839.56000000","0.00000000"],["110840.00000000","0.00005000"],["110840.01000000","0.00000000"],["110840.27000000","0.00000000"],["110840.43000000","0.08619000"],["110840.44000000","0.00000000"],["110840.45000000","0.00000000"],["110841.87000000","0.32442000"],["110842.43000000","0.00000000"],["110842.65000000","0.00000000"],["110842.73000000","0.00000000"],["110842.87000000","0.18026000"],["110842.89000000","0.00000000"],["110843.89000000","0.00000000"],["110845.14000000","0.00000000"],["110846.98000000","0.00000000"],["110848.73000000","0.00000000"],["110848.78000000","0.01964000"],["110852.14000000","0.36053000"],["110859.88000000","1.23345000"],["110861.03000000","0.00000000"],["110872.90000000","0.00000000"],["110888.27000000","0.03150000"],["110891.78000000","0.00000000"],["110895.38000000","1.12747000"],["110896.91000000","0.00460000"],["110898.59000000","3.24539000"],["110898.81000000","0.00000000"],["110907.26000000","0.00000000"],["110907.27000000","0.00000000"],["110907.28000000","0.00000000"],["110908.21000000","0.00000000"],["110908.22000000","0.00000000"],["110909.21000000","0.00000000"],["110909.22000000","0.00000000"],["110910.16000000","0.00100000"],["110910.17000000","0.00100000"],["110910.65000000","0.03538000"],["110916.14000000","0.00000000"],["110928.87000000","0.00000000"],["110933.57000000","0.39822000"],["110938.57000000","0.34629000"],["110940.00000000","0.01935000"],["110971.70000000","0.00000000"],["110981.96000000","0.00000000"],["110983.42000000","0.48858000"],["110983.81000000","0.00331000"],["110984.51000000","0.00000000"],["110990.35000000","0.11154000"],["110992.33000000","0.00000000"],["111050.00000000","0.01148000"],["111068.57000000","0.23925000"],["111087.06000000","0.00000000"],["111245.52000000","0.00000000"],["111255.79000000","0.00000000"],["111257.57000000","0.00082000"],["111268.51000000","0.00000000"],["111289.94000000","0.00000000"],["111308.13000000","0.00000000"],["128001.97000000","0.03006000"]]}
[2025-10-11T22:17:33.328Z] {"e":"depthUpdate","E":1760221053014,"s":"BTCUSDT","U":77925973202,"u":77925973691,"b":[["110820.56000000","5.67509000"],["110820.55000000","0.00010000"],["110820.43000000","0.00010000"],["110820.42000000","0.11970000"],["110820.41000000","0.29755000"],["110820.19000000","0.00000000"],["110820.18000000","0.01359000"],["110820.02000000","0.00000000"],["110820.01000000","0.00027000"],["110820.00000000","0.00070000"],["110819.12000000","0.00010000"],["110819.11000000","0.04114000"],["110818.01000000","0.00010000"],["110818.00000000","0.04158000"],["110816.86000000","0.00005000"],["110816.05000000","0.04514000"],["110815.58000000","0.00722000"],["110815.43000000","0.18026000"],["110815.00000000","0.00902000"],["110814.90000000","0.06646000"],["110813.68000000","0.00000000"],["110813.53000000","0.04425000"],["110813.43000000","0.00000000"],["110811.97000000","0.32451000"],["110807.24000000","0.00000000"],["110807.14000000","0.00000000"],["110806.70000000","0.00000000"],["110806.00000000","0.00132000"],["110805.03000000","0.00000000"],["110804.39000000","0.13527000"],["110802.01000000","0.00000000"],["110799.74000000","0.13527000"],["110797.81000000","0.00000000"],["110797.75000000","0.04000000"],["110789.36000000","0.00000000"],["110789.31000000","0.18031000"],["110789.20000000","0.00000000"],["110788.88000000","0.22546000"],["110788.65000000","0.00000000"],["110785.87000000","0.00000000"],["110783.86000000","0.00000000"],["110774.01000000","0.02998000"],["110773.68000000","0.00000000"],["110773.46000000","0.13515000"],["110742.10000000","0.13527000"],["110741.00000000","0.68526000"],["110738.70000000","0.02888000"],["110736.62000000","0.13527000"],["110726.59000000","0.00000000"],["110721.80000000","0.00000000"],["110719.05000000","0.00000000"],["110716.79000000","0.22115000"],["110713.71000000","0.00000000"],["110712.60000000","0.00000000"],["110712.51000000","0.00000000"],["110712.08000000","0.00000000"],["110712.05000000","0.00000000"],["110711.78000000","0.00000000"],["110711.73000000","0.18031000"],["110711.62000000","0.00000000"],["110711.40000000","0.13520000"],["110711.30000000","0.22546000"],["110671.84000000","0.08495000"],["101969.64000000","0.00010000"],["99738.50000000","0.00020000"],["99738.00000000","0.00010000"],["88656.45000000","0.00022000"],["39895.40000000","0.00080000"]],"a":[["110820.57000000","1.32991000"],["110820.58000000","0.00035000"],["110820.71000000","0.00000000"],["110820.72000000","0.00000000"],["110820.94000000","0.00010000"],["110820.95000000","0.01364000"],["110821.55000000","0.00000000"],["110821.56000000","0.00000000"],["110824.04000000","0.00000000"],["110824.05000000","0.00000000"],["110824.44000000","0.00551000"],["110824.85000000","0.00000000"],["110824.86000000","0.00000000"],["110825.90000000","0.00000000"],["110825.91000000","0.00000000"],["110825.92000000","0.00000000"],["110826.10000000","0.00000000"],["110826.11000000","0.00005000"],["110826.60000000","0.00000000"],["110826.61000000","0.00000000"],["110826.67000000","0.29743000"],["110826.69000000","0.00010000"],["110826.70000000","0.00005000"],["110827.88000000","0.00000000"],["110828.13000000","0.00000000"],["110828.14000000","0.00000000"],["110829.04000000","0.00010000"],["110829.05000000","0.05359000"],["110829.72000000","0.00010000"],["110829.73000000","0.00005000"],["110831.50000000","0.00000000"],["110831.65000000","0.00010000"],["110831.66000000","0.45005000"],["110831.87000000","0.00000000"],["110831.88000000","0.00000000"],["110832.00000000","0.00000000"],["110832.09000000","0.32445000"],["110832.21000000","0.00000000"],["110832.66000000","0.00000000"],["110832.67000000","1.06249000"],["110832.68000000","0.00000000"],["110832.69000000","3.86560000"],["110833.25000000","0.00000000"],["110833.41000000","0.00070000"],["110833.48000000","0.00000000"],["110833.88000000","0.38046000"],["110833.95000000","0.00005000"],["110834.13000000","0.00081000"],["110834.32000000","0.32445000"],["110834.34000000","0.00000000"],["110834.35000000","0.04503000"],["110834.36000000","0.00000000"],["110835.07000000","0.00068000"],["110835.37000000","0.00005000"],["110836.48000000","0.04007000"],["110836.71000000","0.00000000"],["110836.72000000","0.00907000"],["110837.19000000","0.00000000"],["110837.42000000","0.00000000"],["110837.87000000","0.00000000"],["110838.04000000","0.00000000"],["110838.10000000","0.00005000"],["110838.73000000","0.06646000"],["110840.17000000","0.04010000"],["110840.43000000","0.29288000"],["110840.53000000","0.00005000"],["110841.69000000","0.00450000"],["110842.73000000","0.11273000"],["110844.19000000","0.00000000"],["110848.61000000","0.01964000"],["110848.78000000","0.00000000"],["110910.65000000","0.00000000"],["110923.75000000","0.00000000"],["110931.83000000","0.00000000"],["110967.10000000","0.00000000"],["110979.10000000","0.05430000"],["110984.51000000","0.00000000"],["110992.13000000","0.99556000"],["111142.05000000","0.07572000"],["111155.93000000","0.00000000"],["111268.51000000","0.45000000"],["128001.97000000","0.03006000"]]}
[2025-10-11T22:17:34.329Z] {"e":"depthUpdate","E":1760221054014,"s":"BTCUSDT","U":77925973692,"u":77925975886,"b":[["110832.68000000","6.64699000"],["110832.67000000","0.00000000"],["110832.61000000","0.00010000"],["110831.34000000","0.00005000"],["110831.00000000","0.04109000"],["110829.90000000","0.00010000"],["110829.89000000","0.04087000"],["110829.75000000","0.23935000"],["110829.74000000","0.29747000"],["110829.08000000","0.00005000"],["110829.07000000","0.18028000"],["110829.06000000","0.00010000"],["110829.05000000","0.05417000"],["110829.04000000","0.00008000"],["110829.03000000","0.00000000"],["110828.36000000","0.00000000"],["110828.34000000","0.00000000"],["110828.33000000","0.00000000"],["110828.04000000","0.00000000"],["110827.75000000","0.00000000"],["110827.45000000","0.00000000"],["110827.44000000","0.00000000"],["110826.76000000","0.01793000"],["110826.75000000","0.00000000"],["110826.74000000","0.00000000"],["110826.57000000","0.00000000"],["110826.17000000","0.00000000"],["110825.88000000","0.00010000"],["110825.87000000","0.04075000"],["110825.28000000","0.00005000"],["110825.27000000","0.00000000"],["110824.47000000","0.23981000"],["110824.46000000","0.00005000"],["110824.45000000","0.00000000"],["110824.44000000","0.00000000"],["110824.43000000","0.22483000"],["110824.36000000","0.00000000"],["110823.91000000","0.00000000"],["110823.89000000","0.00005000"],["110823.88000000","0.00000000"],["110823.87000000","0.04509000"],["110823.79000000","0.00000000"],["110822.83000000","0.08567000"],["110822.78000000","0.20196000"],["110822.77000000","0.00000000"],["110822.50000000","0.00400000"],["110822.26000000","0.00000000"],["110822.24000000","0.00000000"],["110822.23000000","0.00000000"],["110821.65000000","0.00000000"],["110821.60000000","0.57643000"],["110821.59000000","0.45000000"],["110821.35000000","0.00005000"],["110821.06000000","0.00000000"],["110820.97000000","0.00000000"],["110820.94000000","0.18026000"],["110820.93000000","0.00000000"],["110820.72000000","0.00000000"],["110820.64000000","0.00000000"],["110820.59000000","0.00000000"],["110820.58000000","0.00000000"],["110820.57000000","0.45036000"],["110820.56000000","0.15211000"],["110820.55000000","0.00000000"],["110820.48000000","0.00000000"],["110820.43000000","0.00000000"],["110820.42000000","0.00000000"],["110820.41000000","0.29745000"],["110820.18000000","0.01354000"],["110820.01000000","0.00568000"],["110819.45000000","0.00000000"],["110819.12000000","0.00000000"],["110819.11000000","0.00000000"],["110818.83000000","0.00010000"],["110818.76000000","0.00326000"],["110818.34000000","0.00000000"],["110818.15000000","0.00000000"],["110818.01000000","0.00000000"],["110818.00000000","0.00137000"],["110817.87000000","0.05009000"],["110817.81000000","0.00000000"],["110817.61000000","0.32450000"],["110816.86000000","0.00000000"],["110816.85000000","0.19052000"],["110816.69000000","0.00541000"],["110816.05000000","0.00000000"],["110815.79000000","0.00000000"],["110815.62000000","0.00000000"],["110815.58000000","0.00000000"],["110815.43000000","0.00000000"],["110815.28000000","0.00000000"],["110815.02000000","0.18026000"],["110815.01000000","0.11273000"],["110814.90000000","0.00000000"],["110814.79000000","0.32450000"],["110814.63000000","0.12051000"],["110813.91000000","0.00000000"],["110813.53000000","0.00000000"],["110813.35000000","0.00000000"],["110811.97000000","0.00000000"],["110811.11000000","0.35675000"],["110810.51000000","0.00300000"],["110810.40000000","0.00000000"],["110809.48000000","0.00000000"],["110809.18000000","0.08567000"],["110809.04000000","0.00000000"],["110808.04000000","0.07200000"],["110806.80000000","0.07200000"],["110806.15000000","0.00000000"],["110804.51000000","0.01964000"],["110803.94000000","0.00000000"],["110802.41000000","0.00000000"],["110801.18000000","0.00000000"],["110800.44000000","0.22546000"],["110800.07000000","1.38924000"],["110797.76000000","3.24539000"],["110797.65000000","0.00000000"],["110797.41000000","0.18031000"],["110793.79000000","0.00000000"],["110793.76000000","0.24256000"],["110793.32000000","0.00000000"],["110791.20000000","0.00000000"],["110790.60000000","0.00000000"],["110789.31000000","0.00000000"],["110788.88000000","0.00000000"],["110787.85000000","0.01805000"],["110787.31000000","0.00009000"],["110785.52000000","0.00000000"],["110785.48000000","0.00000000"],["110785.30000000","0.00000000"],["110784.97000000","0.00000000"],["110783.52000000","0.00000000"],["110782.85000000","0.13522000"],["110780.14000000","0.06000000"],["110776.80000000","0.00000000"],["110775.44000000","0.13515000"],["110774.01000000","0.02998000"],["110773.46000000","0.00000000"],["110772.40000000","0.00000000"],["110770.74000000","0.00000000"],["110769.16000000","0.00624000"],["110768.87000000","0.00000000"],["110768.33000000","0.56000000"],["110767.29000000","0.00623000"],["110766.42000000","0.00000000"],["110761.28000000","0.00420000"],["110759.88000000","0.00651000"],["110759.31000000","0.07402000"],["110757.40000000","0.00000000"],["110756.35000000","0.02888000"],["110756.22000000","0.00000000"],["110755.57000000","0.00000000"],["110754.94000000","0.03277000"],["110752.97000000","0.00000000"],["110747.33000000","0.13527000"],["110744.67000000","0.00000000"],["110743.97000000","0.00000000"],["110742.10000000","0.00000000"],["110740.01000000","0.13527000"],["110738.70000000","0.00000000"],["110736.62000000","0.00000000"],["110736.10000000","0.00224000"],["110734.13000000","0.09641000"],["110733.43000000","0.35445000"],["110732.07000000","0.00000000"],["110730.61000000","0.00000000"],["110730.54000000","0.00000000"],["110730.25000000","0.00000000"],["110730.17000000","0.00000000"],["110728.01000000","0.00000000"],["110724.40000000","0.22546000"],["110723.96000000","0.00000000"],["110722.50000000","0.00000000"],["110722.27000000","0.26674000"],["110722.26000000","0.18031000"],["110722.02000000","0.00000000"],["110721.20000000","0.22546000"],["110720.78000000","0.07936000"],["110713.72000000","0.00000000"],["110713.11000000","0.00000000"],["110711.73000000","0.00000000"],["110711.40000000","0.00005000"],["110711.30000000","0.00000000"],["110704.36000000","0.00000000"],["110703.57000000","0.00000000"],["110690.73000000","0.00000000"],["110686.25000000","0.99719000"],["110685.88000000","0.00000000"],["110681.90000000","0.00000000"],["110679.61000000","0.00160000"],["110677.96000000","0.00000000"],["110677.75000000","0.00000000"],["110677.44000000","0.00000000"],["110677.43000000","0.00000000"],["110677.14000000","0.00000000"],["110676.92000000","0.00000000"],["110674.34000000","0.00000000"],["110674.01000000","0.00000000"],["110671.84000000","0.00000000"],["110670.74000000","0.00000000"],["110670.09000000","0.00000000"],["110669.67000000","0.00000000"],["110669.39000000","0.00000000"],["110669.38000000","0.00000000"],["110669.05000000","0.00000000"],["110668.18000000","0.00000000"],["110666.90000000","0.00007000"],["110666.13000000","0.00000000"],["110665.57000000","0.00000000"],["110665.18000000","0.00000000"],["110662.52000000","0.00000000"],["110616.13000000","0.00000000"],["110592.41000000","0.00000000"],["110552.32000000","0.00000000"],["110482.52000000","0.00000000"],["110472.08000000","0.00010000"],["110463.23000000","0.00000000"],["110461.16000000","0.00333000"],["110457.69000000","0.00000000"],["110445.61000000","0.00000000"],["108997.11000000","0.00000000"],["101969.64000000","0.00000000"],["99749.41000000","0.00012000"],["99738.50000000","0.00012000"],["99738.00000000","0.00010000"],["88666.15000000","0.00022000"],["88656.45000000","0.00000000"]],"a":[["110820.57000000","0.00000000"],["110820.58000000","0.00000000"],["110820.65000000","0.00000000"],["110820.73000000","0.00000000"],["110820.94000000","0.00000000"],["110820.95000000","0.00000000"],["110822.78000000","0.00000000"],["110823.88000000","0.00000000"],["110823.89000000","0.00000000"],["110823.90000000","0.00000000"],["110824.44000000","0.00000000"],["110824.45000000","0.00000000"],["110824.99000000","0.00000000"],["110825.28000000","0.00000000"],["110826.11000000","0.00000000"],["110826.18000000","0.00000000"],["110826.58000000","0.00000000"],["110826.65000000","0.00000000"],["110826.66000000","0.00000000"],["110826.67000000","0.00000000"],["110826.69000000","0.00000000"],["110826.70000000","0.00000000"],["110826.75000000","0.00000000"],["110827.73000000","0.00000000"],["110827.76000000","0.00000000"],["110827.93000000","0.00000000"],["110828.05000000","0.00000000"],["110828.33000000","0.00000000"],["110828.34000000","0.00000000"],["110829.04000000","0.00000000"],["110829.05000000","0.00000000"],["110829.06000000","0.00000000"],["110829.48000000","0.00000000"],["110829.49000000","0.00000000"],["110829.72000000","0.00000000"],["110829.73000000","0.00000000"],["110829.86000000","0.00000000"],["110831.34000000","0.00000000"],["110831.40000000","0.00000000"],["110831.65000000","0.00000000"],["110831.66000000","0.00000000"],["110832.08000000","0.00000000"],["110832.09000000","0.00000000"],["110832.66000000","0.00000000"],["110832.67000000","0.00000000"],["110832.68000000","0.00000000"],["110832.69000000","2.79329000"],["110832.70000000","0.00070000"],["110832.77000000","0.00010000"],["110832.96000000","0.00000000"],["110833.41000000","0.00000000"],["110833.88000000","0.00000000"],["110833.95000000","0.00000000"],["110834.02000000","0.00010000"],["110834.03000000","0.29751000"],["110834.13000000","0.00000000"],["110834.31000000","0.00000000"],["110834.32000000","0.00000000"],["110834.35000000","0.00000000"],["110834.41000000","0.00000000"],["110834.63000000","0.00000000"],["110834.64000000","0.00000000"],["110834.82000000","0.00000000"],["110835.07000000","0.00000000"],["110835.19000000","0.00010000"],["110835.20000000","0.29299000"],["110835.21000000","0.00010000"],["110835.22000000","0.48010000"],["110835.37000000","0.00000000"],["110835.48000000","0.00000000"],["110836.01000000","0.00010000"],["110836.02000000","0.14010000"],["110836.39000000","0.00000000"],["110836.40000000","0.00000000"],["110836.48000000","0.00000000"],["110836.72000000","0.00907000"],["110837.06000000","0.00000000"],["110837.20000000","0.00000000"],["110837.21000000","0.00000000"],["110837.43000000","0.00000000"],["110837.48000000","0.00000000"],["110837.63000000","0.00005000"],["110837.64000000","0.32449000"],["110838.23000000","0.04503000"],["110838.28000000","0.00000000"],["110838.29000000","0.00000000"],["110838.37000000","0.00000000"],["110838.73000000","0.00005000"],["110838.77000000","0.00366000"],["110839.42000000","0.00000000"],["110840.17000000","0.00010000"],["110840.31000000","0.04083000"],["110840.42000000","0.00005000"],["110840.43000000","0.13538000"],["110840.50000000","0.00000000"],["110840.53000000","0.00000000"],["110840.69000000","0.00000000"],["110841.06000000","0.00005000"],["110841.27000000","0.00000000"],["110841.41000000","0.00000000"],["110841.42000000","0.03980000"],["110841.69000000","0.00000000"],["110841.70000000","0.00558000"],["110841.71000000","0.00269000"],["110841.87000000","0.00000000"],["110842.00000000","0.00400000"],["110842.14000000","0.00000000"],["110842.15000000","0.32442000"],["110842.44000000","0.00300000"],["110842.73000000","0.00000000"],["110842.74000000","0.00005000"],["110842.87000000","0.00000000"],["110842.97000000","0.00000000"],["110843.35000000","0.03608000"],["110843.50000000","0.00005000"],["110843.66000000","0.04005000"],["110843.77000000","0.11273000"],["110844.31000000","0.01809000"],["110844.39000000","0.00000000"],["110844.86000000","0.00000000"],["110845.45000000","0.00000000"],["110845.55000000","0.01768000"],["110845.67000000","0.00149000"],["110846.22000000","0.18026000"],["110846.23000000","0.56819000"],["110846.69000000","0.00000000"],["110846.83000000","0.00000000"],["110846.84000000","0.32441000"],["110847.01000000","0.00000000"],["110847.10000000","0.08014000"],["110847.16000000","0.00018000"],["110847.52000000","0.00000000"],["110848.25000000","0.00333000"],["110848.27000000","0.00000000"],["110848.38000000","0.00069000"],["110848.61000000","0.00000000"],["110849.31000000","0.08309000"],["110849.58000000","0.00000000"],["110849.60000000","0.00007000"],["110849.70000000","0.00000000"],["110849.71000000","0.00450000"],["110850.14000000","0.00000000"],["110850.51000000","0.37257000"],["110850.55000000","0.00000000"],["110851.58000000","0.00005000"],["110852.07000000","0.32439000"],["110852.13000000","0.00000000"],["110852.14000000","0.00000000"],["110852.51000000","0.00000000"],["110852.91000000","0.00000000"],["110853.15000000","0.00000000"],["110854.32000000","0.13522000"],["110855.21000000","0.00000000"],["110855.59000000","0.08567000"],["110857.28000000","0.01964000"],["110857.63000000","0.00901000"],["110858.65000000","0.00000000"],["110858.66000000","0.30415000"],["110859.27000000","0.00000000"],["110861.55000000","0.00005000"],["110862.27000000","0.13527000"],["110862.58000000","0.00000000"],["110862.59000000","0.00000000"],["110863.60000000","0.36051000"],["110865.56000000","0.00000000"],["110865.94000000","0.00300000"],["110866.23000000","0.13527000"],["110871.29000000","0.00225000"],["110875.10000000","0.02800000"],["110879.82000000","0.00005000"],["110881.73000000","0.00000000"],["110882.87000000","0.08160000"],["110883.98000000","0.00000000"],["110884.37000000","0.00000000"],["110884.81000000","0.00000000"],["110884.87000000","0.06850000"],["110885.02000000","0.12000000"],["110885.15000000","0.10560000"],["110885.88000000","0.00005000"],["110887.17000000","0.05599000"],["110888.27000000","0.00000000"],["110890.18000000","0.00000000"],["110892.76000000","0.00000000"],["110895.99000000","0.00000000"],["110896.91000000","0.00000000"],["110900.00000000","0.00120000"],["110901.55000000","0.00224000"],["110901.56000000","1.08156000"],["110902.91000000","0.00000000"],["110903.92000000","0.00629000"],["110905.24000000","3.24539000"],["110908.59000000","0.03150000"],["110909.99000000","0.00000000"],["110910.16000000","0.00000000"],["110910.17000000","0.00000000"],["110910.21000000","0.14400000"],["110910.22000000","0.00000000"],["110911.21000000","0.00000000"],["110911.22000000","0.00000000"],["110911.85000000","3.24539000"],["110912.49000000","0.00000000"],["110916.26000000","0.00100000"],["110916.27000000","0.00100000"],["110916.78000000","0.00000000"],["110918.47000000","0.00225000"],["110924.18000000","0.00005000"],["110926.10000000","0.00000000"],["110929.89000000","0.00000000"],["110938.57000000","0.00000000"],["110942.90000000","0.03538000"],["110950.30000000","0.00000000"],["110950.56000000","0.00000000"],["110953.47000000","0.34629000"],["110963.50000000","0.00000000"],["110969.99000000","0.00000000"],["110972.43000000","0.00090000"],["110983.81000000","0.00000000"],["110990.35000000","0.11154000"],["110992.13000000","0.00000000"],["110992.43000000","0.99157000"],["110999.44000000","0.03039000"],["111002.85000000","0.00000000"],["111003.99000000","0.00000000"],["111006.74000000","0.00090000"],["111021.36000000","0.00000000"],["111029.85000000","0.00090000"],["111085.24000000","0.18174000"],["111101.91000000","0.06646000"],["111156.77000000","0.00010000"],["111162.31000000","0.00000000"],["111257.57000000","0.00000000"],["111273.28000000","0.00082000"],["111319.05000000","0.67153000"],["128001.97000000","0.00040000"]]}
[2025-10-11T22:17:35.328Z] {"e":"depthUpdate","E":1760221055014,"s":"BTCUSDT","U":77925975887,"u":77925976153,"b":[["110832.68000000","6.69433000"],["110832.06000000","0.00010000"],["110832.05000000","0.16749000"],["110832.04000000","0.29752000"],["110831.01000000","0.00010000"],["110831.00000000","0.00010000"],["110830.55000000","0.00005000"],["110829.89000000","0.00010000"],["110829.79000000","0.00000000"],["110829.78000000","0.00000000"],["110829.77000000","0.00000000"],["110829.76000000","0.00000000"],["110829.75000000","0.00000000"],["110829.74000000","0.00000000"],["110829.44000000","0.00005000"],["110829.39000000","0.04096000"],["110829.07000000","0.18028000"],["110829.06000000","0.00000000"],["110829.05000000","0.00000000"],["110828.28000000","0.04055000"],["110827.22000000","0.00005000"],["110826.76000000","0.00005000"],["110826.11000000","0.26323000"],["110826.10000000","0.32452000"],["110825.88000000","0.00000000"],["110825.87000000","0.04075000"],["110824.47000000","0.00000000"],["110824.46000000","0.00000000"],["110824.43000000","0.18158000"],["110824.01000000","0.32448000"],["110823.89000000","0.00000000"],["110823.87000000","0.04509000"],["110820.41000000","0.00000000"],["110819.13000000","0.00000000"],["110816.80000000","0.00006000"],["110816.12000000","0.00000000"],["110807.24000000","0.00005000"],["110799.43000000","0.00009000"],["110793.77000000","0.22546000"],["110791.20000000","0.00005000"],["110787.31000000","0.00000000"],["110766.18000000","0.00009000"],["110754.07000000","0.00000000"],["110751.84000000","0.00000000"],["110740.25000000","0.00196000"],["110732.93000000","0.09609000"],["110732.07000000","0.07200000"],["110724.01000000","0.06913000"],["110720.82000000","0.00000000"],["110716.76000000","0.13515000"],["110716.02000000","0.00167000"],["110704.01000000","0.00000000"],["110699.68000000","0.00009000"],["110688.93000000","0.00160000"],["110687.58000000","0.00000000"],["110679.61000000","0.00000000"],["110666.43000000","0.00009000"],["110654.33000000","0.00000000"],["110579.83000000","0.00587000"],["110578.10000000","0.00000000"],["110565.81000000","0.05430000"],["110516.40000000","0.00000000"],["110492.99000000","0.04297000"],["110469.67000000","0.00000000"],["110367.63000000","0.00000000"],["109979.40000000","0.00000000"],["109900.00000000","0.15318000"],["99749.00000000","0.00000000"],["99748.00000000","0.00010000"],["99738.00000000","0.00000000"],["88666.15000000","0.00022000"]],"a":[["110832.69000000","4.12965000"],["110832.70000000","0.00070000"],["110833.32000000","0.00077000"],["110836.09000000","0.00005000"],["110836.72000000","0.00912000"],["110837.64000000","0.32449000"],["110837.98000000","0.04511000"],["110838.23000000","0.04508000"],["110838.68000000","0.01804000"],["110841.42000000","0.03975000"],["110843.77000000","0.00000000"],["110844.31000000","0.01804000"],["110845.55000000","0.01763000"],["110846.03000000","0.00000000"],["110846.06000000","0.00000000"],["110851.58000000","0.11278000"],["110853.82000000","0.00000000"],["110860.00000000","0.18026000"],["110864.90000000","0.00005000"],["110865.94000000","0.00309000"],["110887.06000000","0.00000000"],["110897.98000000","0.00000000"],["110899.19000000","0.00009000"],["110911.84000000","1.18477000"],["110911.86000000","0.00000000"],["110919.89000000","0.00005000"],["110920.31000000","0.00000000"],["110922.99000000","0.00005000"],["110932.44000000","0.00009000"],["110948.18000000","0.00000000"],["110953.55000000","0.00000000"],["110960.74000000","0.00196000"],["110965.69000000","0.00009000"],["110967.91000000","0.00000000"],["110972.43000000","0.00000000"],["110978.20000000","0.10952000"],["110978.21000000","0.10773000"],["110979.65000000","0.00000000"],["110983.41000000","0.00090000"],["110986.80000000","0.00000000"],["110992.43000000","0.99196000"],["110998.94000000","0.00009000"],["111001.14000000","0.00000000"],["111193.51000000","0.00000000"],["112200.00000000","0.29176000"],["128001.97000000","0.00040000"]]}
[2025-10-11T22:17:36.328Z] {"e":"depthUpdate","E":1760221056014,"s":"BTCUSDT","U":77925976154,"u":77925976459,"b":[["110832.68000000","2.83023000"],["110832.06000000","0.00000000"],["110832.05000000","0.00000000"],["110832.04000000","0.00000000"],["110831.01000000","0.00000000"],["110831.00000000","0.00000000"],["110830.55000000","0.00000000"],["110829.90000000","0.00000000"],["110829.89000000","0.00000000"],["110829.66000000","0.13160000"],["110829.65000000","0.00005000"],["110829.64000000","0.00005000"],["110829.48000000","0.29742000"],["110829.40000000","0.00000000"],["110829.39000000","0.00000000"],["110829.08000000","0.00000000"],["110829.07000000","0.00000000"],["110828.29000000","0.00000000"],["110828.28000000","0.00000000"],["110827.46000000","0.00000000"],["110827.45000000","0.00000000"],["110827.15000000","0.03986000"],["110827.07000000","0.00000000"],["110826.76000000","0.00000000"],["110826.35000000","0.00010000"],["110826.34000000","0.03966000"],["110826.12000000","0.00010000"],["110826.11000000","0.16577000"],["110826.10000000","0.00000000"],["110825.88000000","0.00010000"],["110825.87000000","0.04075000"],["110824.43000000","0.00132000"],["110824.03000000","0.00005000"],["110824.02000000","0.18030000"],["110824.01000000","0.00000000"],["110823.87000000","0.04514000"],["110822.83000000","0.00005000"],["110822.78000000","0.00000000"],["110822.50000000","0.00000000"],["110821.99000000","0.45049000"],["110821.98000000","0.32448000"],["110821.60000000","0.00000000"],["110820.94000000","0.00000000"],["110820.57000000","0.00000000"],["110820.56000000","0.00005000"],["110819.32000000","0.00073000"],["110818.78000000","0.00070000"],["110818.35000000","0.18026000"],["110816.86000000","0.20197000"],["110816.85000000","0.35950000"],["110815.98000000","0.08567000"],["110815.02000000","0.18026000"],["110813.66000000","0.00000000"],["110811.79000000","0.32451000"],["110804.51000000","0.00000000"],["110800.00000000","0.77765000"],["110797.75000000","0.00000000"],["110793.67000000","0.00000000"],["110790.98000000","0.04000000"],["110789.75000000","1.22585000"],["110777.97000000","0.00000000"],["110761.28000000","0.00000000"],["110757.95000000","0.00451000"],["110754.94000000","0.00000000"],["110742.28000000","0.03283000"],["110686.26000000","0.73374000"],["110584.33000000","4.83213000"],["110576.15000000","0.00000000"],["110461.16000000","0.00000000"],["110433.06000000","0.00333000"],["110278.52000000","0.00122000"],["109890.60000000","0.00081000"],["109888.00000000","0.00378000"],["109004.42000000","0.00072000"],["106531.44000000","0.00000000"],["106179.89000000","0.00185000"],["105457.29000000","0.00090000"],["99749.00000000","0.00000000"],["88666.15000000","0.00022000"]],"a":[["110832.69000000","5.11668000"],["110832.70000000","0.00040000"],["110833.87000000","0.00005000"],["110834.03000000","0.29751000"],["110834.98000000","0.00005000"],["110835.18000000","0.56045000"],["110835.19000000","0.45056000"],["110835.20000000","0.00010000"],["110835.22000000","0.48010000"],["110835.55000000","0.32449000"],["110835.56000000","0.03614000"],["110836.01000000","0.00005000"],["110836.02000000","0.14005000"],["110836.72000000","0.00917000"],["110837.63000000","0.00000000"],["110837.64000000","0.32449000"],["110837.98000000","0.04511000"],["110838.23000000","0.04508000"],["110838.68000000","0.01804000"],["110840.31000000","0.04078000"],["110840.42000000","0.00000000"],["110840.43000000","0.13533000"],["110841.41000000","0.00450000"],["110843.50000000","0.00000000"],["110843.66000000","0.04000000"],["110844.49000000","0.06646000"],["110846.23000000","1.48042000"],["110848.38000000","0.00000000"],["110849.71000000","3.24539000"],["110852.07000000","0.00000000"],["110854.04000000","0.00705000"],["110859.88000000","0.00000000"],["110868.76000000","1.19089000"],["110890.97000000","0.03150000"],["110908.59000000","0.00000000"],["110915.68000000","0.03538000"],["110931.94000000","0.00005000"],["110942.90000000","0.00000000"],["110971.20000000","0.00331000"],["110978.20000000","0.00000000"],["110978.21000000","0.00000000"],["110989.30000000","0.10909000"],["110990.35000000","0.37547000"],["110999.44000000","0.02708000"],["111068.99000000","0.00000000"],["111074.94000000","4.72806000"],["111101.91000000","0.00000000"],["111245.03000000","0.00082000"],["111273.28000000","0.00000000"],["111325.47000000","0.00000000"],["113322.00000000","0.02662000"],["128001.97000000","0.00040000"]]}
[2025-10-11T22:17:37.329Z] {"e":"depthUpdate","E":1760221057014,"s":"BTCUSDT","U":77925976460,"u":77925976985,"b":[["110832.68000000","0.83802000"],["110832.67000000","0.00045000"],["110832.52000000","0.00907000"],["110829.69000000","0.00000000"],["110829.68000000","0.00000000"],["110829.67000000","0.00000000"],["110829.66000000","0.00000000"],["110829.65000000","0.00000000"],["110829.64000000","0.00000000"],["110829.49000000","0.00000000"],["110829.48000000","0.00000000"],["110829.44000000","0.00000000"],["110829.29000000","0.00010000"],["110829.28000000","0.04567000"],["110828.81000000","0.29742000"],["110827.29000000","0.00000000"],["110827.28000000","0.00000000"],["110827.22000000","0.00000000"],["110827.16000000","0.00000000"],["110827.15000000","0.00000000"],["110826.76000000","0.00005000"],["110826.35000000","0.00000000"],["110826.34000000","0.00000000"],["110826.31000000","0.00010000"],["110826.30000000","0.00000000"],["110826.12000000","0.00000000"],["110826.11000000","0.00000000"],["110825.88000000","0.00000000"],["110825.87000000","0.00000000"],["110825.33000000","0.00000000"],["110825.03000000","0.00010000"],["110825.02000000","0.04112000"],["110824.70000000","0.00005000"],["110824.23000000","0.00010000"],["110824.22000000","0.03988000"],["110824.03000000","0.00000000"],["110824.02000000","0.00000000"],["110823.95000000","0.00000000"],["110823.88000000","0.00010000"],["110823.87000000","0.04514000"],["110823.66000000","0.00005000"],["110822.83000000","0.00000000"],["110822.00000000","0.00000000"],["110821.99000000","0.32553000"],["110821.98000000","0.00000000"],["110821.71000000","0.32448000"],["110821.60000000","0.00000000"],["110819.79000000","0.00070000"],["110819.68000000","0.32449000"],["110818.78000000","0.00070000"],["110818.77000000","0.18025000"],["110817.61000000","0.00000000"],["110817.03000000","0.00070000"],["110816.86000000","0.00000000"],["110816.05000000","0.00000000"],["110815.01000000","0.00000000"],["110814.79000000","0.00000000"],["110814.47000000","0.00000000"],["110814.29000000","0.32451000"],["110810.51000000","0.11573000"],["110810.02000000","0.00000000"],["110810.00000000","0.00132000"],["110809.10000000","0.00000000"],["110807.50000000","0.00000000"],["110805.78000000","0.00000000"],["110804.07000000","0.00000000"],["110803.91000000","0.20199000"],["110803.59000000","0.00000000"],["110780.14000000","0.04000000"],["110777.78000000","0.00000000"],["110774.34000000","0.02000000"],["110768.13000000","0.04432000"],["110756.35000000","0.00000000"],["110751.08000000","0.02888000"],["110743.93000000","0.00000000"],["110730.94000000","0.00000000"],["110716.03000000","0.00000000"],["110716.02000000","0.00167000"],["110699.36000000","0.03400000"],["110694.79000000","0.17456000"],["110688.41000000","0.04097000"],["110686.91000000","0.47475000"],["110686.26000000","0.00000000"],["110686.25000000","0.00000000"],["110685.77000000","0.04097000"],["110682.67000000","0.04097000"],["110670.86000000","0.99657000"],["110605.07000000","0.00066000"],["110592.72000000","0.00000000"],["110036.56000000","0.00040000"],["109539.68000000","0.90310000"],["106531.67000000","0.00361000"],["106179.89000000","0.00005000"],["105460.98000000","0.00152000"],["99749.00000000","0.00000000"],["99748.00000000","0.00010000"],["88666.15000000","0.00022000"],["60000.00000000","56.18427000"],["33000.00000000","3.75190000"]],"a":[["110832.69000000","6.39381000"],["110832.70000000","0.00010000"],["110833.07000000","0.01368000"],["110834.02000000","0.00000000"],["110834.03000000","0.33360000"],["110834.61000000","0.01814000"],["110834.99000000","0.06656000"],["110835.18000000","0.40889000"],["110835.19000000","0.45041000"],["110835.20000000","0.00000000"],["110835.21000000","0.00000000"],["110835.22000000","0.00000000"],["110835.54000000","0.30421000"],["110835.56000000","0.03619000"],["110835.57000000","0.04521000"],["110835.73000000","0.04000000"],["110836.01000000","0.00000000"],["110836.02000000","0.00000000"],["110836.09000000","0.00000000"],["110836.72000000","0.00907000"],["110837.64000000","0.00000000"],["110837.98000000","0.04511000"],["110838.23000000","0.15781000"],["110838.34000000","0.32443000"],["110840.31000000","0.04083000"],["110840.43000000","0.19916000"],["110842.89000000","0.00000000"],["110843.35000000","0.03613000"],["110843.66000000","0.04000000"],["110844.31000000","0.01804000"],["110846.20000000","2.57308000"],["110846.21000000","3.24539000"],["110846.23000000","0.00000000"],["110846.72000000","0.00000000"],["110848.25000000","0.00000000"],["110849.32000000","0.13527000"],["110851.04000000","0.00901000"],["110851.58000000","0.00005000"],["110857.63000000","0.00000000"],["110858.66000000","0.00000000"],["110862.27000000","0.00000000"],["110863.96000000","0.00000000"],["110870.99000000","0.00000000"],["110878.96000000","0.04428000"],["110879.24000000","0.13527000"],["110879.84000000","0.13515000"],["110880.53000000","0.00000000"],["110888.62000000","0.00000000"],["110902.89000000","0.00124000"],["110904.89000000","0.00000000"],["110908.43000000","0.00124000"],["110908.86000000","0.00000000"],["110910.43000000","0.02141000"],["110911.24000000","0.00000000"],["110911.84000000","0.00000000"],["110911.85000000","0.00000000"],["110915.10000000","0.00100000"],["110915.11000000","0.00100000"],["110916.26000000","0.00000000"],["110916.27000000","0.00000000"],["110933.57000000","0.27046000"],["110933.79000000","0.00000000"],["110937.12000000","0.00000000"],["110939.42000000","0.55219000"],["110940.15000000","0.08640000"],["110940.86000000","0.22546000"],["110940.91000000","0.00000000"],["110941.91000000","0.13515000"],["110979.09000000","0.07731000"],["111085.24000000","0.00000000"],["111325.70000000","0.00035000"],["128001.97000000","0.03006000"]]}
[2025-10-11T22:17:38.327Z] {"e":"depthUpdate","E":1760221058014,"s":"BTCUSDT","U":77925976986,"u":77925977260,"b":[["110832.68000000","0.99508000"],["110832.67000000","0.00045000"],["110832.52000000","0.00907000"],["110829.66000000","0.00010000"],["110829.65000000","0.05664000"],["110829.29000000","0.00000000"],["110829.28000000","0.00000000"],["110828.83000000","0.00000000"],["110828.82000000","0.00010000"],["110828.81000000","0.29752000"],["110827.22000000","0.00005000"],["110826.31000000","0.00000000"],["110825.04000000","0.00010000"],["110825.03000000","0.02611000"],["110825.02000000","0.00000000"],["110824.23000000","0.00000000"],["110824.22000000","0.00000000"],["110823.89000000","0.00000000"],["110823.88000000","0.00010000"],["110823.87000000","0.04519000"],["110823.78000000","0.00010000"],["110823.77000000","0.04150000"],["110822.67000000","0.00000000"],["110822.66000000","0.04051000"],["110822.00000000","0.00000000"],["110821.99000000","0.32553000"],["110821.71000000","0.00000000"],["110821.60000000","0.00000000"],["110821.59000000","0.45005000"],["110820.18000000","0.01354000"],["110820.01000000","0.00568000"],["110819.79000000","0.00000000"],["110819.58000000","0.00070000"],["110818.35000000","0.00000000"],["110817.46000000","0.00005000"],["110812.27000000","0.01500000"],["110751.08000000","0.00000000"],["110746.96000000","0.00000000"],["110742.28000000","0.00006000"],["110732.15000000","0.00000000"],["110728.64000000","0.02888000"],["110726.35000000","0.03277000"],["110699.36000000","0.00000000"],["110686.91000000","0.39457000"],["110681.65000000","0.04097000"],["110670.87000000","0.47414000"],["110555.88000000","0.02998000"],["110433.06000000","0.00000000"],["110422.99000000","0.00333000"],["110167.69000000","0.00000000"],["103188.00000000","0.05708000"],["99749.41000000","0.00032000"],["99749.00000000","0.00000000"],["99748.00000000","0.00010000"],["88666.15000000","0.00022000"]],"a":[["110832.69000000","6.61765000"],["110835.19000000","0.45041000"],["110835.54000000","0.00000000"],["110835.57000000","0.04521000"],["110840.43000000","0.28177000"],["110841.40000000","0.30419000"],["110842.62000000","0.18026000"],["110843.35000000","0.03608000"],["110879.24000000","0.13527000"],["110899.44000000","0.06058000"],["110909.78000000","0.00000000"],["110909.95000000","0.03538000"],["110912.12000000","0.21563000"],["110915.10000000","0.00000000"],["110915.11000000","0.00000000"],["110915.68000000","0.00000000"],["110916.10000000","0.00100000"],["110916.11000000","0.00100000"],["110928.73000000","0.00000000"],["110940.13000000","0.01411000"],["110940.55000000","0.00000000"],["110940.80000000","0.00000000"],["110940.86000000","0.00000000"],["110961.08000000","0.00331000"],["110971.20000000","0.00000000"],["111234.90000000","0.00082000"],["111245.03000000","0.00000000"],["113000.00000000","17.88744000"],["115000.00000000","47.93801000"],["128001.97000000","0.03006000"]]}
[2025-10-11T22:18:22.333Z] {"e":"depthUpdate","E":1760221102014,"s":"BTCUSDT","U":77926017664,"u":77926018840,"b":[["110787.85000000","0.00000000"],["110787.84000000","0.00000000"],["110787.78000000","0.00000000"],["110787.77000000","0.00000000"],["110787.69000000","0.00000000"],["110787.48000000","0.00000000"],["110787.47000000","0.00000000"],["110787.31000000","0.00000000"],["110786.00000000","0.00394000"],["110785.99000000","0.00075000"],["110785.81000000","0.00000000"],["110785.72000000","0.00010000"],["110785.42000000","0.03171000"],["110784.94000000","0.00000000"],["110784.92000000","0.00010000"],["110784.31000000","0.00000000"],["110784.28000000","0.00010000"],["110783.94000000","0.00015000"],["110783.38000000","0.00000000"],["110783.13000000","0.00000000"],["110783.12000000","0.00000000"],["110782.99000000","0.00000000"],["110782.98000000","0.00000000"],["110782.83000000","0.00000000"],["110782.04000000","0.00000000"],["110781.77000000","0.00010000"],["110781.76000000","0.01815000"],["110781.61000000","0.00010000"],["110781.60000000","0.01815000"],["110781.50000000","0.00000000"],["110781.23000000","0.00000000"],["110781.22000000","0.00000000"],["110780.46000000","0.00149000"],["110779.85000000","0.00010000"],["110779.84000000","0.04992000"],["110779.68000000","0.00000000"],["110779.29000000","0.00000000"],["110779.20000000","0.00000000"],["110778.92000000","0.00000000"],["110778.13000000","0.00000000"],["110777.61000000","0.00000000"],["110777.60000000","0.00000000"],["110777.38000000","0.00000000"],["110776.73000000","0.00005000"],["110776.72000000","0.29761000"],["110776.16000000","0.00000000"],["110776.13000000","0.04686000"],["110775.32000000","0.00000000"],["110774.68000000","0.00134000"],["110774.60000000","0.00069000"],["110774.59000000","0.00000000"],["110774.36000000","0.00000000"],["110774.00000000","0.00204000"],["110773.99000000","0.00070000"],["110773.95000000","0.00000000"],["110773.94000000","0.00000000"],["110773.83000000","0.00000000"],["110773.30000000","0.00000000"],["110773.29000000","0.00000000"],["110773.28000000","0.00000000"],["110771.64000000","0.00000000"],["110771.60000000","0.10490000"],["110771.48000000","0.00000000"],["110771.43000000","0.04120000"],["110771.42000000","0.00387000"],["110771.38000000","0.04841000"],["110771.36000000","0.37582000"],["110771.34000000","0.00000000"],["110771.26000000","0.00000000"],["110771.23000000","0.00000000"],["110770.98000000","0.00000000"],["110770.50000000","0.32463000"],["110770.37000000","0.04018000"],["110769.38000000","0.00149000"],["110768.69000000","0.00000000"],["110768.68000000","0.18026000"],["110768.39000000","0.00000000"],["110768.22000000","0.08567000"],["110768.06000000","0.00000000"],["110767.35000000","0.32464000"],["110766.60000000","0.28386000"],["110765.69000000","0.00000000"],["110763.46000000","0.32465000"],["110762.90000000","0.00000000"],["110762.28000000","0.00000000"],["110762.21000000","0.00000000"],["110760.15000000","0.11273000"],["110760.12000000","0.00000000"],["110760.11000000","0.00000000"],["110759.98000000","0.00403000"],["110759.64000000","0.00000000"],["110759.25000000","0.32467000"],["110759.16000000","0.00000000"],["110757.70000000","0.00005000"],["110755.69000000","0.00000000"],["110755.39000000","0.32968000"],["110752.76000000","0.00300000"],["110752.51000000","0.00000000"],["110752.50000000","0.36067000"],["110751.20000000","0.00000000"],["110749.41000000","0.20209000"],["110748.12000000","0.08567000"],["110746.79000000","0.13527000"],["110745.52000000","0.00403000"],["110738.27000000","0.00000000"],["110735.83000000","0.00000000"],["110732.25000000","0.00012000"],["110730.01000000","0.05996000"],["110721.16000000","0.00000000"],["110720.58000000","0.00000000"],["110719.57000000","0.13522000"],["110718.38000000","0.00000000"],["110717.46000000","0.00000000"],["110717.28000000","0.00000000"],["110713.12000000","0.47527000"],["110706.04000000","0.00617000"],["110700.23000000","0.00000000"],["110696.71000000","0.00000000"],["110693.02000000","0.00224000"],["110692.01000000","0.03997000"],["110691.86000000","0.00000000"],["110691.50000000","0.00005000"],["110689.01000000","0.00000000"],["110686.38000000","0.02402000"],["110684.74000000","0.13527000"],["110681.68000000","0.00000000"],["110679.52000000","0.00000000"],["110677.99000000","0.00000000"],["110674.36000000","0.00010000"],["110673.78000000","0.00000000"],["110671.30000000","0.00167000"],["110671.29000000","0.00000000"],["110668.99000000","0.00000000"],["110663.22000000","0.00000000"],["110659.05000000","0.00000000"],["110658.41000000","0.00000000"],["110657.52000000","0.03939000"],["110657.23000000","0.00000000"],["110654.31000000","0.00000000"],["110651.60000000","0.00000000"],["110650.84000000","0.00000000"],["110649.83000000","0.00000000"],["110647.02000000","0.03997000"],["110646.73000000","0.00000000"],["110644.68000000","0.00000000"],["110644.67000000","0.07017000"],["110641.77000000","0.00160000"],["110640.63000000","0.00000000"],["110640.44000000","0.00000000"],["110625.75000000","0.99431000"],["110621.39000000","0.05430000"],["110620.12000000","0.00000000"],["110603.05000000","0.00000000"],["110599.13000000","0.01086000"],["110570.00000000","0.09894000"],["110566.39000000","0.00000000"],["110560.43000000","0.00067000"],["110560.42000000","0.00006000"],["110554.26000000","0.00606000"],["110550.83000000","0.00000000"],["110511.73000000","0.00010000"],["110508.78000000","0.00000000"],["110481.72000000","0.02617000"],["110476.39000000","0.05430000"],["110451.53000000","0.00000000"],["110437.88000000","0.00000000"],["110436.08000000","0.00000000"],["110431.16000000","0.00000000"],["110417.82000000","0.00333000"],["110410.87000000","0.00000000"],["110408.31000000","0.00000000"],["110401.98000000","0.00000000"],["110334.42000000","0.00000000"],["110196.26000000","0.00000000"],["110196.23000000","0.00000000"],["110195.94000000","0.00000000"],["110195.56000000","0.00000000"],["110195.23000000","0.00000000"],["110195.15000000","0.00000000"],["110195.05000000","0.00007000"],["110194.97000000","0.00000000"],["110145.28000000","0.01806000"],["110000.00000000","11.03477000"],["99709.00000000","0.00000000"],["99708.00000000","0.00048000"],["88630.28000000","0.00000000"],["88628.80000000","0.00022000"],["39882.96000000","0.00016000"],["33000.00000000","3.75190000"]],"a":[["110786.01000000","23.21402000"],["110786.09000000","0.00010000"],["110787.32000000","0.00000000"],["110787.38000000","0.00000000"],["110787.45000000","0.00000000"],["110787.47000000","0.47673000"],["110787.48000000","0.00000000"],["110787.49000000","0.00000000"],["110787.67000000","0.00000000"],["110787.68000000","0.51878000"],["110787.69000000","0.00000000"],["110787.70000000","0.00000000"],["110787.78000000","0.00000000"],["110787.79000000","0.50446000"],["110787.82000000","0.00000000"],["110787.83000000","0.29758000"],["110787.84000000","0.00000000"],["110787.85000000","0.00000000"],["110787.86000000","0.44907000"],["110787.94000000","0.00000000"],["110788.00000000","0.00000000"],["110788.01000000","0.00005000"],["110788.02000000","0.00913000"],["110788.06000000","0.04518000"],["110788.24000000","0.01369000"],["110788.68000000","0.00000000"],["110788.70000000","0.00000000"],["110788.76000000","0.03966000"],["110788.91000000","0.01815000"],["110789.43000000","0.03610000"],["110789.46000000","0.03610000"],["110789.50000000","0.00133000"],["110789.87000000","0.04124000"],["110790.11000000","0.04518000"],["110790.40000000","0.03615000"],["110790.59000000","0.00000000"],["110790.72000000","0.03620000"],["110791.35000000","0.04513000"],["110791.42000000","0.36195000"],["110791.43000000","0.04513000"],["110791.60000000","0.00000000"],["110791.61000000","0.06651000"],["110791.93000000","0.04513000"],["110792.01000000","0.00010000"],["110792.63000000","0.01815000"],["110793.10000000","0.01805000"],["110793.44000000","0.01801000"],["110793.72000000","0.03610000"],["110793.83000000","0.00000000"],["110793.86000000","0.04232000"],["110793.99000000","0.00000000"],["110794.00000000","0.04370000"],["110794.04000000","0.01805000"],["110794.30000000","0.03615000"],["110794.55000000","0.00005000"],["110794.75000000","0.01810000"],["110795.00000000","0.03960000"],["110795.34000000","0.00000000"],["110795.36000000","0.00000000"],["110795.94000000","0.00450000"],["110795.96000000","0.02709000"],["110795.99000000","1.27647000"],["110796.00000000","0.03960000"],["110797.09000000","0.32763000"],["110797.16000000","0.00000000"],["110797.50000000","0.01649000"],["110797.61000000","0.05760000"],["110797.71000000","0.00259000"],["110798.22000000","3.24539000"],["110798.66000000","0.12240000"],["110798.90000000","0.00000000"],["110799.12000000","0.00000000"],["110799.84000000","0.00010000"],["110799.91000000","0.14400000"],["110800.00000000","0.06051000"],["110800.41000000","0.07889000"],["110801.55000000","1.44995000"],["110801.57000000","0.00000000"],["110802.13000000","0.10080000"],["110802.92000000","0.00007000"],["110802.95000000","0.00800000"],["110803.38000000","0.00000000"],["110803.80000000","0.00000000"],["110803.94000000","0.45036000"],["110804.48000000","0.00000000"],["110804.50000000","0.13527000"],["110804.77000000","0.00000000"],["110805.20000000","0.00000000"],["110806.41000000","0.00000000"],["110806.66000000","2.21515000"],["110807.37000000","0.00000000"],["110808.39000000","0.00000000"],["110808.73000000","0.00000000"],["110808.92000000","0.05618000"],["110808.94000000","0.00901000"],["110809.07000000","0.00012000"],["110810.38000000","0.00000000"],["110811.61000000","0.00000000"],["110812.02000000","0.01173000"],["110812.22000000","0.08600000"],["110814.53000000","0.00000000"],["110815.39000000","0.00000000"],["110816.75000000","0.03150000"],["110816.86000000","0.02139000"],["110818.87000000","0.22546000"],["110819.52000000","0.08000000"],["110820.81000000","0.00000000"],["110821.11000000","0.00000000"],["110821.19000000","0.02800000"],["110822.51000000","0.00000000"],["110823.93000000","0.00000000"],["110824.77000000","0.49794000"],["110825.54000000","0.04824000"],["110826.62000000","0.00000000"],["110827.33000000","0.00000000"],["110828.09000000","0.00225000"],["110830.58000000","0.00000000"],["110830.63000000","0.00000000"],["110832.68000000","0.00929000"],["110833.82000000","0.03538000"],["110834.22000000","0.00000000"],["110834.40000000","0.00000000"],["110836.24000000","0.00000000"],["110837.27000000","0.00000000"],["110839.41000000","0.00000000"],["110839.90000000","0.00000000"],["110840.78000000","0.00000000"],["110841.05000000","0.00000000"],["110841.70000000","0.05056000"],["110844.53000000","0.00000000"],["110847.25000000","0.00000000"],["110847.89000000","0.00000000"],["110850.19000000","0.00652000"],["110851.31000000","0.00000000"],["110851.32000000","0.00000000"],["110855.47000000","0.00624000"],["110857.00000000","0.38629000"],["110857.96000000","0.00000000"],["110862.13000000","0.13537000"],["110863.82000000","0.13527000"],["110864.61000000","0.00000000"],["110865.73000000","0.00000000"],["110866.78000000","0.00000000"],["110869.44000000","0.00000000"],["110870.80000000","0.00000000"],["110877.73000000","0.00000000"],["110893.16000000","0.13515000"],["110894.57000000","0.01959000"],["110895.68000000","0.18031000"],["110895.98000000","0.00000000"],["110896.43000000","0.22546000"],["110899.07000000","0.00000000"],["110901.56000000","0.00000000"],["110901.99000000","0.00000000"],["110902.87000000","0.00000000"],["110907.99000000","0.02527000"],["110942.26000000","0.99447000"],["110948.18000000","0.08594000"],["110950.52000000","0.00000000"],["110950.53000000","0.00000000"],["110950.77000000","0.08594000"],["110954.57000000","0.08594000"],["110955.88000000","0.00331000"],["110957.01000000","0.08594000"],["110959.44000000","0.08594000"],["110961.67000000","0.00000000"],["110964.67000000","0.01900000"],["110976.05000000","0.00000000"],["110983.42000000","0.42988000"],["110994.60000000","0.00000000"],["111007.36000000","0.00000000"],["111013.12000000","0.00000000"],["111019.70000000","0.08598000"],["111029.79000000","0.00000000"],["111099.34000000","0.00000000"],["111113.25000000","0.00000000"],["111130.80000000","0.07395000"],["111229.67000000","0.00082000"],["111235.19000000","0.00000000"],["111249.85000000","0.00000000"],["111253.55000000","0.00000000"],["111340.57000000","0.00000000"],["111896.82000000","0.00000000"],["128001.97000000","0.03006000"]]}
[2025-10-11T22:18:23.332Z] {"e":"depthUpdate","E":1760221103014,"s":"BTCUSDT","U":77926018841,"u":77926020478,"b":[["110786.00000000","0.00000000"],["110785.99000000","0.00000000"],["110785.72000000","0.00000000"],["110785.43000000","0.00000000"],["110785.42000000","0.00000000"],["110785.41000000","0.00000000"],["110785.05000000","0.00000000"],["110784.92000000","0.00000000"],["110784.50000000","0.00000000"],["110784.28000000","0.00000000"],["110784.00000000","0.00000000"],["110783.94000000","0.00000000"],["110783.33000000","0.00000000"],["110783.32000000","0.00000000"],["110782.86000000","0.00000000"],["110782.00000000","0.00000000"],["110781.77000000","0.00000000"],["110781.76000000","0.00000000"],["110781.75000000","0.00000000"],["110781.61000000","0.00000000"],["110781.60000000","0.02027000"],["110781.59000000","0.00040000"],["110780.61000000","0.00005000"],["110780.46000000","0.00000000"],["110780.23000000","0.00000000"],["110779.85000000","0.00000000"],["110779.84000000","0.00000000"],["110778.38000000","0.00010000"],["110778.29000000","0.00010000"],["110778.14000000","0.00010000"],["110776.85000000","0.00010000"],["110776.83000000","0.00010000"],["110776.73000000","0.00000000"],["110776.72000000","0.00000000"],["110776.17000000","0.00005000"],["110776.14000000","0.00000000"],["110776.13000000","0.00000000"],["110774.68000000","0.00000000"],["110774.60000000","0.00000000"],["110774.47000000","0.00000000"],["110774.00000000","0.00132000"],["110773.99000000","0.00000000"],["110771.61000000","0.00010000"],["110771.60000000","0.10495000"],["110771.55000000","0.00000000"],["110771.54000000","0.00000000"],["110771.44000000","0.00000000"],["110771.43000000","0.00000000"],["110771.42000000","0.00000000"],["110771.40000000","0.00000000"],["110771.39000000","0.00000000"],["110771.38000000","0.00000000"],["110771.36000000","0.00000000"],["110770.92000000","0.00005000"],["110770.53000000","0.05823000"],["110770.50000000","0.00000000"],["110770.37000000","0.00000000"],["110769.95000000","0.00000000"],["110769.83000000","0.00000000"],["110769.82000000","0.00000000"],["110769.23000000","0.00000000"],["110769.04000000","0.00000000"],["110768.82000000","0.00010000"],["110768.81000000","0.00010000"],["110768.80000000","0.00000000"],["110768.69000000","0.00000000"],["110768.68000000","0.00000000"],["110768.67000000","0.00000000"],["110768.22000000","0.00000000"],["110767.94000000","0.00000000"],["110767.90000000","0.00000000"],["110767.72000000","0.00069000"],["110767.53000000","0.00000000"],["110767.43000000","0.00000000"],["110767.38000000","0.00000000"],["110767.35000000","0.00000000"],["110766.90000000","0.00000000"],["110766.88000000","0.00134000"],["110766.84000000","0.00010000"],["110766.83000000","0.04089000"],["110766.61000000","0.00010000"],["110766.60000000","0.10883000"],["110766.58000000","0.00000000"],["110766.56000000","0.00000000"],["110766.54000000","0.00000000"],["110766.53000000","0.02052000"],["110766.32000000","0.00000000"],["110765.97000000","0.00000000"],["110765.62000000","0.00000000"],["110765.43000000","0.00000000"],["110765.14000000","0.00150000"],["110764.52000000","0.00000000"],["110764.48000000","0.00000000"],["110763.98000000","0.00000000"],["110763.90000000","0.00000000"],["110763.71000000","0.01777000"],["110763.46000000","0.00000000"],["110763.22000000","0.00000000"],["110762.81000000","0.08567000"],["110762.39000000","0.00000000"],["110761.97000000","0.00000000"],["110761.69000000","0.00000000"],["110761.32000000","0.00000000"],["110761.09000000","0.00070000"],["110761.07000000","0.00069000"],["110760.37000000","0.00073000"],["110760.15000000","0.00000000"],["110760.13000000","0.38892000"],["110760.00000000","0.01953000"],["110759.96000000","0.00000000"],["110759.60000000","0.04509000"],["110759.25000000","0.00000000"],["110758.14000000","0.00000000"],["110757.53000000","0.00324000"],["110757.05000000","0.04800000"],["110756.10000000","0.00000000"],["110755.42000000","0.04805000"],["110755.38000000","0.00000000"],["110755.30000000","0.00000000"],["110754.52000000","0.32468000"],["110754.47000000","0.04800000"],["110754.06000000","0.11273000"],["110751.27000000","0.04508000"],["110750.15000000","0.00000000"],["110750.11000000","0.04800000"],["110750.00000000","0.14986000"],["110749.57000000","0.03162000"],["110749.41000000","0.00000000"],["110749.27000000","0.00000000"],["110749.14000000","0.00000000"],["110748.86000000","0.00000000"],["110747.79000000","0.62677000"],["110747.40000000","0.00000000"],["110747.39000000","0.00000000"],["110747.38000000","0.00000000"],["110747.16000000","0.00000000"],["110744.31000000","0.00000000"],["110742.94000000","0.00000000"],["110742.26000000","0.08567000"],["110741.74000000","0.01765000"],["110741.01000000","0.20211000"],["110739.58000000","0.24903000"],["110739.18000000","0.00014000"],["110738.20000000","0.25122000"],["110737.34000000","0.00000000"],["110735.16000000","0.00000000"],["110733.85000000","0.00000000"],["110733.29000000","0.07200000"],["110731.16000000","0.04000000"],["110728.84000000","0.00000000"],["110728.32000000","0.00005000"],["110726.76000000","0.01895000"],["110726.75000000","0.04800000"],["110726.45000000","0.00000000"],["110725.01000000","0.02998000"],["110724.65000000","0.04297000"],["110724.15000000","0.00000000"],["110723.91000000","0.22546000"],["110723.54000000","0.00000000"],["110722.65000000","0.02000000"],["110722.35000000","0.04000000"],["110722.04000000","0.04297000"],["110721.55000000","0.08000000"],["110721.35000000","0.16000000"],["110720.15000000","0.32000000"],["110719.88000000","0.00000000"],["110718.01000000","0.04297000"],["110717.64000000","0.01713000"],["110717.51000000","0.08567000"],["110717.16000000","0.00000000"],["110716.83000000","0.00000000"],["110714.87000000","0.00010000"],["110714.54000000","0.10293000"],["110714.48000000","0.00000000"],["110713.22000000","0.00000000"],["110712.52000000","0.00000000"],["110711.59000000","0.02836000"],["110711.08000000","0.04297000"],["110711.07000000","0.00000000"],["110708.45000000","0.05996000"],["110708.26000000","0.07295000"],["110706.11000000","0.00000000"],["110704.44000000","0.00625000"],["110703.79000000","0.09107000"],["110702.27000000","0.00619000"],["110700.75000000","0.00000000"],["110699.01000000","0.13094000"],["110698.76000000","0.00000000"],["110698.18000000","0.03997000"],["110698.09000000","0.00000000"],["110696.01000000","0.08595000"],["110695.80000000","0.00659000"],["110695.15000000","0.02527000"],["110693.72000000","0.00000000"],["110693.02000000","0.00000000"],["110691.20000000","0.00007000"],["110690.90000000","0.50721000"],["110690.89000000","0.00000000"],["110690.87000000","0.00000000"],["110690.31000000","0.00000000"],["110690.01000000","0.03997000"],["110688.98000000","0.00224000"],["110688.96000000","0.00000000"],["110688.61000000","0.00000000"],["110688.58000000","0.00000000"],["110686.90000000","0.00000000"],["110686.16000000","0.00014000"],["110685.93000000","0.00000000"],["110685.64000000","0.01624000"],["110685.05000000","0.00000000"],["110682.68000000","1.41949000"],["110679.54000000","0.01629000"],["110679.19000000","0.00000000"],["110678.36000000","0.04800000"],["110677.74000000","0.00000000"],["110676.05000000","0.04800000"],["110674.35000000","0.04800000"],["110674.30000000","3.24539000"],["110674.15000000","0.01624000"],["110674.14000000","0.00000000"],["110673.80000000","0.00000000"],["110673.66000000","0.02341000"],["110673.32000000","0.04800000"],["110672.47000000","0.01367000"],["110671.30000000","0.00000000"],["110670.15000000","0.23150000"],["110670.13000000","0.00000000"],["110670.09000000","0.04048000"],["110669.04000000","0.00000000"],["110668.30000000","0.02423000"],["110667.88000000","0.00000000"],["110665.00000000","0.00167000"],["110660.98000000","0.02527000"],["110659.98000000","0.00000000"],["110654.23000000","0.00000000"],["110652.85000000","0.00000000"],["110647.79000000","0.00000000"],["110647.41000000","0.00000000"],["110646.36000000","0.22546000"],["110644.12000000","0.00000000"],["110641.77000000","0.00000000"],["110641.67000000","0.02617000"],["110635.96000000","0.02617000"],["110635.37000000","0.00159000"],["110633.47000000","0.02527000"],["110630.62000000","0.02527000"],["110626.49000000","0.02617000"],["110625.76000000","0.44055000"],["110625.75000000","0.00000000"],["110623.04000000","0.00000000"],["110622.29000000","0.02527000"],["110621.44000000","0.00000000"],["110621.06000000","0.00000000"],["110620.26000000","0.00000000"],["110619.73000000","0.00000000"],["110619.16000000","0.00000000"],["110619.02000000","0.00000000"],["110611.23000000","0.99439000"],["110608.16000000","0.02617000"],["110604.43000000","0.00000000"],["110599.66000000","0.02632000"],["110586.95000000","0.01895000"],["110585.33000000","0.00000000"],["110577.00000000","0.00090000"],["110573.22000000","0.04297000"],["110560.43000000","0.00000000"],["110554.36000000","0.00067000"],["110542.44000000","0.00000000"],["110534.90000000","0.00000000"],["110528.63000000","4.89157000"],["110525.69000000","0.00064000"],["110520.48000000","0.00000000"],["110478.19000000","0.00000000"],["110475.78000000","0.02617000"],["110474.63000000","0.00000000"],["110470.84000000","0.02527000"],["110466.32000000","0.00000000"],["110466.21000000","0.00000000"],["110464.68000000","0.00000000"],["110463.24000000","0.00000000"],["110458.48000000","0.00000000"],["110458.42000000","0.00000000"],["110457.50000000","0.00000000"],["110455.50000000","0.00010000"],["110452.22000000","0.00000000"],["110451.97000000","0.00000000"],["110451.75000000","0.00000000"],["110449.82000000","0.00000000"],["110440.64000000","0.04297000"],["110437.80000000","0.03791000"],["110433.34000000","0.03791000"],["110433.12000000","0.03791000"],["110432.85000000","0.07582000"],["110432.84000000","0.03791000"],["110432.71000000","0.03791000"],["110423.55000000","0.00000000"],["110417.82000000","0.00000000"],["110398.25000000","0.02998000"],["110394.88000000","0.02998000"],["110392.21000000","0.02998000"],["110387.30000000","0.00000000"],["110379.61000000","0.00000000"],["110346.90000000","0.45000000"],["110337.64000000","0.00000000"],["110337.28000000","0.02527000"],["110334.71000000","0.00333000"],["110325.59000000","0.02527000"],["110313.78000000","0.02527000"],["110306.73000000","0.02437000"],["110184.74000000","0.02298000"],["110183.51000000","0.02298000"],["110183.11000000","0.02298000"],["110182.64000000","0.02298000"],["110182.31000000","0.02298000"],["110182.17000000","0.02298000"],["110181.95000000","0.02298000"],["110181.67000000","0.02298000"],["110181.61000000","0.02298000"],["110000.68000000","0.00909000"],["103179.00000000","0.02568000"],["102012.00000000","0.00989000"],["99708.00000000","0.00038000"],["99707.00000000","0.00010000"],["88628.80000000","0.00000000"],["88625.28000000","0.00022000"],["42000.00000000","1.48098000"],["39882.96000000","0.00032000"],["39881.38000000","0.00016000"]],"a":[["110781.61000000","30.17800000"],["110781.62000000","0.00000000"],["110781.69000000","0.00010000"],["110781.74000000","0.00000000"],["110781.75000000","0.62917000"],["110781.76000000","0.33273000"],["110781.77000000","0.69845000"],["110781.78000000","0.00000000"],["110781.85000000","0.00000000"],["110782.01000000","0.00000000"],["110782.86000000","0.00005000"],["110782.87000000","0.09036000"],["110783.33000000","0.00000000"],["110783.34000000","0.00000000"],["110783.92000000","0.00000000"],["110783.93000000","0.00128000"],["110783.95000000","0.00000000"],["110784.00000000","0.00000000"],["110784.01000000","0.00000000"],["110784.10000000","0.03620000"],["110784.26000000","0.00000000"],["110784.28000000","0.00000000"],["110784.29000000","0.00000000"],["110784.48000000","0.00000000"],["110784.50000000","0.00000000"],["110784.51000000","0.00000000"],["110784.83000000","0.00000000"],["110784.90000000","0.00000000"],["110784.92000000","0.29759000"],["110784.93000000","0.00000000"],["110785.06000000","0.00000000"],["110785.40000000","0.00000000"],["110785.41000000","0.29759000"],["110785.42000000","0.00000000"],["110785.43000000","0.04017000"],["110785.44000000","0.00000000"],["110785.73000000","0.00000000"],["110785.75000000","0.00000000"],["110785.86000000","0.00000000"],["110785.98000000","0.00000000"],["110786.00000000","0.00000000"],["110786.01000000","0.48613000"],["110786.09000000","0.00000000"],["110787.47000000","0.00000000"],["110787.68000000","0.00000000"],["110787.78000000","0.00450000"],["110787.79000000","0.45036000"],["110787.83000000","0.29753000"],["110787.86000000","0.07571000"],["110788.02000000","0.00908000"],["110788.05000000","0.00005000"],["110788.06000000","0.04513000"],["110788.24000000","0.01364000"],["110788.68000000","0.18026000"],["110788.76000000","0.03961000"],["110789.48000000","0.00000000"],["110789.50000000","0.00010000"],["110789.52000000","0.00005000"],["110790.11000000","0.04513000"],["110790.40000000","0.00005000"],["110791.20000000","0.00005000"],["110791.42000000","1.21070000"],["110791.61000000","0.06651000"],["110791.92000000","0.05117000"],["110791.93000000","0.04518000"],["110792.01000000","0.00000000"],["110792.04000000","0.18026000"],["110792.62000000","0.00000000"],["110792.63000000","0.01815000"],["110792.82000000","0.00000000"],["110792.92000000","0.00079000"],["110793.10000000","0.01810000"],["110793.39000000","0.00000000"],["110793.44000000","0.01796000"],["110793.72000000","0.03615000"],["110793.78000000","0.06245000"],["110793.84000000","0.00000000"],["110793.86000000","0.00000000"],["110794.00000000","0.00400000"],["110794.08000000","0.00006000"],["110794.30000000","0.03610000"],["110794.48000000","0.08567000"],["110794.57000000","3.24539000"],["110794.72000000","0.00000000"],["110794.75000000","0.01805000"],["110794.78000000","0.07680000"],["110795.00000000","0.00000000"],["110795.44000000","0.00010000"],["110795.94000000","0.00000000"],["110796.00000000","0.00000000"],["110797.00000000","0.00000000"],["110797.09000000","0.00307000"],["110797.50000000","0.00000000"],["110798.52000000","0.00007000"],["110799.48000000","0.00044000"],["110801.29000000","0.00000000"],["110801.53000000","0.00000000"],["110802.43000000","0.00901000"],["110802.92000000","0.00000000"],["110803.07000000","0.19680000"],["110803.46000000","0.10560000"],["110803.84000000","0.00010000"],["110804.50000000","0.00000000"],["110805.96000000","0.08567000"],["110806.10000000","0.01713000"],["110807.67000000","0.00000000"],["110808.94000000","0.00000000"],["110812.47000000","0.18031000"],["110812.84000000","0.22546000"],["110813.32000000","0.00000000"],["110814.19000000","0.00000000"],["110814.54000000","0.00000000"],["110815.10000000","0.00000000"],["110816.57000000","0.04509000"],["110817.64000000","0.00000000"],["110818.70000000","0.00000000"],["110818.87000000","0.00000000"],["110819.12000000","0.00000000"],["110819.40000000","0.00000000"],["110819.75000000","0.03997000"],["110820.22000000","0.08463000"],["110820.37000000","0.49806000"],["110820.50000000","0.00180000"],["110821.78000000","0.03997000"],["110822.41000000","0.03997000"],["110824.08000000","0.03997000"],["110824.50000000","0.00000000"],["110824.77000000","0.00000000"],["110827.71000000","0.22394000"],["110828.14000000","0.13527000"],["110828.77000000","0.00000000"],["110829.12000000","2.55267000"],["110829.73000000","0.03538000"],["110830.00000000","0.00000000"],["110832.55000000","0.00000000"],["110832.56000000","0.00000000"],["110833.82000000","0.00000000"],["110835.80000000","0.04389000"],["110836.39000000","0.00000000"],["110837.09000000","0.00000000"],["110837.22000000","0.00000000"],["110837.40000000","0.00000000"],["110841.31000000","0.10080000"],["110841.70000000","0.00553000"],["110842.49000000","0.00620000"],["110843.39000000","0.00626000"],["110844.66000000","0.00000000"],["110844.67000000","0.00000000"],["110856.69000000","0.00000000"],["110857.00000000","0.00000000"],["110857.30000000","0.10560000"],["110858.04000000","0.13527000"],["110859.63000000","0.00000000"],["110860.25000000","0.00000000"],["110862.13000000","0.00010000"],["110863.52000000","0.30365000"],["110863.82000000","0.00000000"],["110867.79000000","0.00000000"],["110868.52000000","0.90097000"],["110872.37000000","0.00331000"],["110873.00000000","0.03997000"],["110873.01000000","0.00000000"],["110877.44000000","0.00000000"],["110877.45000000","0.00000000"],["110877.60000000","0.00000000"],["110881.07000000","0.03997000"],["110881.55000000","0.00000000"],["110882.62000000","0.00000000"],["110883.33000000","0.07712000"],["110884.85000000","0.00000000"],["110884.86000000","0.00000000"],["110887.99000000","0.03997000"],["110890.02000000","0.00000000"],["110890.39000000","0.00000000"],["110891.64000000","0.00000000"],["110891.98000000","0.03997000"],["110893.04000000","0.00000000"],["110893.16000000","0.00000000"],["110893.57000000","0.00000000"],["110893.66000000","0.00000000"],["110893.67000000","0.00000000"],["110893.96000000","0.00000000"],["110894.57000000","0.01959000"],["110895.68000000","0.00000000"],["110896.26000000","0.00000000"],["110896.43000000","0.00000000"],["110899.99000000","0.03997000"],["110901.57000000","0.14000000"],["110906.06000000","0.00000000"],["110906.51000000","0.00000000"],["110910.72000000","0.00000000"],["110912.12000000","0.00000000"],["110917.15000000","0.00000000"],["110917.49000000","0.00000000"],["110922.90000000","0.00000000"],["110924.14000000","0.00000000"],["110925.22000000","0.00000000"],["110933.92000000","0.00000000"],["110935.98000000","0.00000000"],["110937.96000000","0.00000000"],["110937.98000000","0.00000000"],["110937.99000000","0.00000000"],["110939.42000000","0.00000000"],["110942.26000000","0.00000000"],["110942.27000000","0.99816000"],["110945.99000000","0.08494000"],["110948.41000000","0.08494000"],["110949.70000000","0.00000000"],["110951.27000000","0.08494000"],["110952.79000000","0.08494000"],["110953.12000000","0.00000000"],["110954.90000000","0.08494000"],["110955.88000000","0.00000000"],["110958.07000000","0.00000000"],["110967.77000000","0.00000000"],["110973.98000000","0.00000000"],["110979.09000000","0.00000000"],["110983.42000000","0.00000000"],["110989.98000000","0.00090000"],["110990.36000000","0.00000000"],["110992.77000000","0.00000000"],["110996.54000000","0.00000000"],["111017.54000000","0.08394000"],["111019.70000000","0.00000000"],["111023.87000000","4.71453000"],["111036.11000000","0.00000000"],["111049.53000000","0.00000000"],["111107.72000000","0.00000000"],["111146.08000000","0.00082000"],["111154.25000000","0.02437000"],["111178.25000000","0.02778000"],["111178.42000000","0.02949000"],["111191.24000000","0.00000000"],["111198.97000000","0.00000000"],["111227.40000000","0.00000000"],["111229.67000000","0.00000000"],["111260.24000000","0.00000000"],["111260.30000000","0.00000000"],["128001.97000000","0.00040000"]]}
