[2025-10-11T22:18:24.336Z] {"e":"depthUpdate","E":1760221104014,"s":"BTCUSDT","U":77926020479,"u":77926025503,"b":[["110781.60000000","0.00000000"],["110781.59000000","0.00000000"],["110781.15000000","0.00000000"],["110780.61000000","0.00000000"],["110780.00000000","0.00000000"],["110778.38000000","0.00000000"],["110778.29000000","0.00000000"],["110778.14000000","0.00000000"],["110778.00000000","0.00000000"],["110777.80000000","0.00000000"],["110777.60000000","0.00000000"],["110777.13000000","0.00000000"],["110777.12000000","0.00000000"],["110777.05000000","0.00000000"],["110777.04000000","0.00000000"],["110776.85000000","0.00000000"],["110776.83000000","0.00000000"],["110776.80000000","0.00000000"],["110776.76000000","0.00000000"],["110776.17000000","0.00000000"],["110776.00000000","0.00000000"],["110775.68000000","0.00000000"],["110775.07000000","0.00000000"],["110775.06000000","0.00000000"],["110775.05000000","0.00000000"],["110774.45000000","0.00000000"],["110774.38000000","0.00000000"],["110774.00000000","0.00000000"],["110772.54000000","0.00000000"],["110772.00000000","0.00000000"],["110771.98000000","0.00000000"],["110771.61000000","0.00000000"],["110771.60000000","0.00000000"],["110771.16000000","0.00000000"],["110771.15000000","0.00000000"],["110771.10000000","0.00000000"],["110770.92000000","0.00000000"],["110770.74000000","0.00000000"],["110770.54000000","0.00000000"],["110770.53000000","0.00000000"],["110770.38000000","0.00000000"],["110770.00000000","0.00000000"],["110769.61000000","0.00000000"],["110769.58000000","0.00000000"],["110769.38000000","0.00000000"],["110768.82000000","0.00000000"],["110768.81000000","0.00000000"],["110768.48000000","0.00000000"],["110768.00000000","0.00000000"],["110767.82000000","0.00000000"],["110767.75000000","0.00000000"],["110767.72000000","0.00000000"],["110766.88000000","0.00000000"],["110766.87000000","0.00000000"],["110766.84000000","0.00000000"],["110766.83000000","0.00000000"],["110766.61000000","0.00000000"],["110766.60000000","0.00000000"],["110766.54000000","0.00000000"],["110766.53000000","0.00000000"],["110766.17000000","0.00000000"],["110766.00000000","0.00000000"],["110765.99000000","0.00000000"],["110765.98000000","0.00000000"],["110765.14000000","0.00000000"],["110765.12000000","0.00000000"],["110765.08000000","0.00000000"],["110765.04000000","0.00000000"],["110764.85000000","0.00000000"],["110764.84000000","0.00000000"],["110764.72000000","0.00000000"],["110764.68000000","0.00000000"],["110764.40000000","0.00000000"],["110764.34000000","0.00000000"],["110764.06000000","0.00000000"],["110764.00000000","0.00000000"],["110763.97000000","0.00000000"],["110763.71000000","0.00000000"],["110763.42000000","0.00000000"],["110763.35000000","0.00000000"],["110763.34000000","0.00000000"],["110763.03000000","0.00000000"],["110762.82000000","0.00000000"],["110762.81000000","0.00000000"],["110762.24000000","0.00000000"],["110762.23000000","0.00000000"],["110762.13000000","0.00000000"],["110762.00000000","0.00000000"],["110761.99000000","0.00000000"],["110761.95000000","0.00000000"],["110761.62000000","0.00000000"],["110761.28000000","0.00000000"],["110761.24000000","0.00000000"],["110761.23000000","0.00000000"],["110761.09000000","0.00000000"],["110761.07000000","0.00000000"],["110761.05000000","0.00000000"],["110760.99000000","0.00000000"],["110760.67000000","0.00000000"],["110760.66000000","0.00000000"],["110760.63000000","0.00000000"],["110760.37000000","0.00000000"],["110760.13000000","0.00000000"],["110760.01000000","0.00000000"],["110760.00000000","0.00000000"],["110759.99000000","0.00000000"],["110759.98000000","0.00000000"],["110759.88000000","0.00000000"],["110759.75000000","0.00000000"],["110759.60000000","0.00000000"],["110759.52000000","0.00000000"],["110759.38000000","0.00000000"],["110759.15000000","0.00000000"],["110759.03000000","0.00000000"],["110759.02000000","0.00000000"],["110758.97000000","0.00834000"],["110758.96000000","0.00080000"],["110758.52000000","0.00000000"],["110757.59000000","0.00000000"],["110757.58000000","0.00000000"],["110757.57000000","0.00000000"],["110757.56000000","0.00000000"],["110757.53000000","0.00000000"],["110757.44000000","0.00000000"],["110757.06000000","0.00000000"],["110757.05000000","0.00000000"],["110756.97000000","0.00000000"],["110756.96000000","0.00000000"],["110756.59000000","0.00000000"],["110756.57000000","0.00010000"],["110756.56000000","0.05284000"],["110756.40000000","0.00000000"],["110756.39000000","0.00000000"],["110756.30000000","0.00000000"],["110756.22000000","0.00000000"],["110755.81000000","0.00010000"],["110755.68000000","0.00000000"],["110755.64000000","0.00010000"],["110755.51000000","0.00010000"],["110755.45000000","0.00000000"],["110755.42000000","0.00000000"],["110755.39000000","0.00000000"],["110755.38000000","0.00000000"],["110755.32000000","0.00000000"],["110755.10000000","0.00547000"],["110755.07000000","0.00000000"],["110754.95000000","0.00000000"],["110754.61000000","0.00300000"],["110754.52000000","0.00000000"],["110754.47000000","0.00000000"],["110754.35000000","0.00005000"],["110754.06000000","0.00000000"],["110753.99000000","0.00727000"],["110753.84000000","0.00000000"],["110753.43000000","0.00149000"],["110752.95000000","0.00000000"],["110752.89000000","0.00000000"],["110752.76000000","0.00000000"],["110752.50000000","0.00000000"],["110752.49000000","0.00000000"],["110752.48000000","0.00000000"],["110752.43000000","0.00000000"],["110752.27000000","0.00000000"],["110752.05000000","0.00000000"],["110751.76000000","0.00070000"],["110751.28000000","0.00000000"],["110751.27000000","0.00000000"],["110751.23000000","0.00000000"],["110751.22000000","0.00000000"],["110751.06000000","0.00000000"],["110750.14000000","0.00000000"],["110750.11000000","0.00000000"],["110750.01000000","0.00010000"],["110750.00000000","0.14996000"],["110749.57000000","0.00000000"],["110749.52000000","0.00000000"],["110749.51000000","0.00000000"],["110749.40000000","0.00941000"],["110748.65000000","0.00000000"],["110748.64000000","0.00000000"],["110748.36000000","0.00000000"],["110748.35000000","0.00000000"],["110748.12000000","0.00000000"],["110747.89000000","0.00149000"],["110747.79000000","0.00000000"],["110747.78000000","0.00000000"],["110747.38000000","0.00000000"],["110747.36000000","0.00069000"],["110746.95000000","0.00000000"],["110746.92000000","0.00000000"],["110746.84000000","0.00010000"],["110746.83000000","0.03172000"],["110746.79000000","0.00000000"],["110746.49000000","0.00070000"],["110746.47000000","0.00000000"],["110746.46000000","0.00010000"],["110746.45000000","0.45010000"],["110746.40000000","0.00000000"],["110746.36000000","0.00000000"],["110746.27000000","0.00000000"],["110746.03000000","0.00000000"],["110745.83000000","0.00000000"],["110745.61000000","0.00005000"],["110745.60000000","0.08575000"],["110745.26000000","0.04940000"],["110745.14000000","0.00404000"],["110745.12000000","0.04509000"],["110744.84000000","0.00000000"],["110744.76000000","0.00000000"],["110744.59000000","0.04112000"],["110744.30000000","0.00000000"],["110744.14000000","0.00010000"],["110744.09000000","0.00903000"],["110744.08000000","0.29765000"],["110744.04000000","0.00000000"],["110744.02000000","0.00000000"],["110744.00000000","0.00132000"],["110743.89000000","0.00839000"],["110743.65000000","0.04017000"],["110743.54000000","0.00000000"],["110743.47000000","0.00000000"],["110743.46000000","0.00000000"],["110743.26000000","0.00000000"],["110743.11000000","0.00000000"],["110742.81000000","0.00333000"],["110742.51000000","0.00022000"],["110742.36000000","0.00149000"],["110742.26000000","0.00000000"],["110742.01000000","0.00000000"],["110741.74000000","0.00000000"],["110741.43000000","0.00000000"],["110741.02000000","0.00000000"],["110741.01000000","0.00000000"],["110741.00000000","0.00000000"],["110740.76000000","0.00000000"],["110740.73000000","0.00000000"],["110740.40000000","0.00000000"],["110740.39000000","0.00000000"],["110740.28000000","0.01827000"],["110740.12000000","0.00000000"],["110740.00000000","0.02017000"],["110739.95000000","0.00000000"],["110739.83000000","0.32472000"],["110739.73000000","0.00000000"],["110739.58000000","0.00000000"],["110739.26000000","0.00000000"],["110739.18000000","0.00014000"],["110739.08000000","0.00000000"],["110738.60000000","0.00010000"],["110738.21000000","0.26952000"],["110738.20000000","0.00000000"],["110738.00000000","0.00137000"],["110737.78000000","0.00000000"],["110737.28000000","0.00000000"],["110737.26000000","0.00000000"],["110736.95000000","0.00000000"],["110736.81000000","0.00300000"],["110736.50000000","0.00000000"],["110735.36000000","0.45043000"],["110735.35000000","0.04800000"],["110735.08000000","0.00005000"],["110734.86000000","0.00000000"],["110734.37000000","0.32474000"],["110734.08000000","0.00000000"],["110733.84000000","0.00000000"],["110733.32000000","0.00000000"],["110733.31000000","0.00000000"],["110733.30000000","0.00000000"],["110733.11000000","0.00073000"],["110733.05000000","0.00000000"],["110732.25000000","0.00000000"],["110732.24000000","0.00000000"],["110732.23000000","0.00000000"],["110731.76000000","0.00000000"],["110731.49000000","0.08577000"],["110731.28000000","0.11273000"],["110731.16000000","0.00000000"],["110730.87000000","0.00000000"],["110730.81000000","0.00000000"],["110730.01000000","0.00000000"],["110729.72000000","0.00000000"],["110729.48000000","0.00000000"],["110728.73000000","0.32476000"],["110728.70000000","0.00000000"],["110728.32000000","0.04805000"],["110727.44000000","0.00000000"],["110727.43000000","0.00000000"],["110726.76000000","0.20213000"],["110726.57000000","0.00000000"],["110726.44000000","0.00000000"],["110726.01000000","0.00000000"],["110725.82000000","0.08567000"],["110725.74000000","0.00309000"],["110725.37000000","0.00000000"],["110725.01000000","0.00000000"],["110724.66000000","0.36077000"],["110724.65000000","0.00000000"],["110724.01000000","0.00000000"],["110723.57000000","0.00000000"],["110723.35000000","0.22546000"],["110722.71000000","0.00441000"],["110722.65000000","0.00000000"],["110722.55000000","0.02141000"],["110722.35000000","0.00000000"],["110722.26000000","0.00005000"],["110722.04000000","0.00000000"],["110721.55000000","0.00000000"],["110721.38000000","0.00000000"],["110721.35000000","0.00000000"],["110720.81000000","0.00000000"],["110720.57000000","0.08567000"],["110720.34000000","0.00271000"],["110720.25000000","0.00000000"],["110720.15000000","0.00000000"],["110720.01000000","0.00000000"],["110719.57000000","0.00000000"],["110719.37000000","0.00000000"],["110718.65000000","0.00000000"],["110718.42000000","0.18031000"],["110718.13000000","0.01768000"],["110718.01000000","0.00000000"],["110717.73000000","0.00142000"],["110717.23000000","0.25167000"],["110717.22000000","0.24903000"],["110717.15000000","0.00000000"],["110716.42000000","0.02139000"],["110716.27000000","0.08567000"],["110716.20000000","0.00005000"],["110716.15000000","0.00000000"],["110715.45000000","0.00000000"],["110714.75000000","0.00005000"],["110714.55000000","0.00000000"],["110714.54000000","0.02618000"],["110714.15000000","0.21817000"],["110713.58000000","0.00000000"],["110713.55000000","0.00000000"],["110713.12000000","0.45000000"],["110712.55000000","0.00000000"],["110711.78000000","0.00000000"],["110711.59000000","0.00000000"],["110710.88000000","0.04000000"],["110710.68000000","0.13527000"],["110710.63000000","0.00012000"],["110710.59000000","1.21777000"],["110710.55000000","0.00000000"],["110710.14000000","0.00005000"],["110710.01000000","0.02437000"],["110709.43000000","0.06646000"],["110708.65000000","0.00000000"],["110708.45000000","0.00000000"],["110708.35000000","0.00000000"],["110708.34000000","0.00000000"],["110708.26000000","0.04297000"],["110707.55000000","0.00000000"],["110707.01000000","0.00000000"],["110706.78000000","0.00000000"],["110706.76000000","0.13527000"],["110706.64000000","0.00000000"],["110706.35000000","0.00000000"],["110706.04000000","0.00000000"],["110705.85000000","0.00000000"],["110705.53000000","0.00390000"],["110705.44000000","0.00000000"],["110705.00000000","0.00000000"],["110704.75000000","0.00000000"],["110704.44000000","0.00000000"],["110704.39000000","0.00000000"],["110704.25000000","0.08567000"],["110704.13000000","0.00000000"],["110704.08000000","0.00005000"],["110703.95000000","0.00000000"],["110703.41000000","0.08567000"],["110702.85000000","0.00000000"],["110702.27000000","0.00000000"],["110702.25000000","0.00000000"],["110702.09000000","0.03997000"],["110701.99000000","0.00000000"],["110701.84000000","0.00000000"],["110701.55000000","0.02000000"],["110701.42000000","0.00000000"],["110701.23000000","0.00000000"],["110701.08000000","0.04800000"],["110700.85000000","0.04000000"],["110700.38000000","0.00000000"],["110700.14000000","0.19024000"],["110700.00000000","0.04802000"],["110699.65000000","0.08000000"],["110699.01000000","0.16092000"],["110698.99000000","0.00000000"],["110698.69000000","0.00000000"],["110698.54000000","0.00000000"],["110698.53000000","0.00000000"],["110698.18000000","0.00000000"],["110697.65000000","0.00000000"],["110696.99000000","0.00000000"],["110696.75000000","0.48000000"],["110696.72000000","0.00000000"],["110696.32000000","0.00000000"],["110696.01000000","0.00000000"],["110695.96000000","0.00000000"],["110695.81000000","0.00000000"],["110695.80000000","0.00000000"],["110695.15000000","0.00000000"],["110694.79000000","0.15536000"],["110694.27000000","0.18026000"],["110693.90000000","0.00000000"],["110693.01000000","0.00000000"],["110692.52000000","0.00000000"],["110692.51000000","0.00009000"],["110692.38000000","0.00000000"],["110692.01000000","0.05892000"],["110691.79000000","0.00000000"],["110691.41000000","0.00000000"],["110691.24000000","0.00000000"],["110690.90000000","0.45000000"],["110690.35000000","0.00000000"],["110690.18000000","0.06896000"],["110690.01000000","0.00000000"],["110689.33000000","0.02141000"],["110688.98000000","0.02998000"],["110688.70000000","0.00000000"],["110688.14000000","0.00000000"],["110688.01000000","0.00000000"],["110687.70000000","0.13522000"],["110687.68000000","0.00616000"],["110687.62000000","0.18026000"],["110687.61000000","1.12133000"],["110687.52000000","0.00000000"],["110687.15000000","0.00000000"],["110687.11000000","0.00000000"],["110686.17000000","0.00000000"],["110686.04000000","0.00622000"],["110686.00000000","0.00100000"],["110685.97000000","0.00000000"],["110685.88000000","0.00000000"],["110685.64000000","0.00000000"],["110685.63000000","0.00000000"],["110685.50000000","0.00000000"],["110684.74000000","0.00000000"],["110684.15000000","0.03997000"],["110683.76000000","0.03997000"],["110683.34000000","0.00000000"],["110683.32000000","0.00000000"],["110683.10000000","0.00000000"],["110682.72000000","0.00000000"],["110682.69000000","0.18026000"],["110682.09000000","0.00000000"],["110682.07000000","0.00000000"],["110681.89000000","0.00000000"],["110681.51000000","0.00000000"],["110681.26000000","0.03997000"],["110681.15000000","0.00000000"],["110681.13000000","0.00000000"],["110680.53000000","0.00000000"],["110680.48000000","0.00006000"],["110680.38000000","0.00136000"],["110679.80000000","0.04800000"],["110679.66000000","0.00000000"],["110679.54000000","0.00005000"],["110679.53000000","0.00000000"],["110678.23000000","0.00000000"],["110678.22000000","0.00653000"],["110678.21000000","0.00000000"],["110677.82000000","0.07200000"],["110677.75000000","1.14615000"],["110677.26000000","0.09600000"],["110677.01000000","0.03997000"],["110676.75000000","0.00000000"],["110676.48000000","0.02998000"],["110676.10000000","0.18026000"],["110675.58000000","0.00000000"],["110675.56000000","0.02180000"],["110675.54000000","0.00000000"],["110675.41000000","0.04800000"],["110675.05000000","0.07200000"],["110674.36000000","0.00010000"],["110674.35000000","0.04800000"],["110674.32000000","0.45036000"],["110674.31000000","0.01624000"],["110674.15000000","0.00000000"],["110673.94000000","0.00000000"],["110673.66000000","0.00000000"],["110673.32000000","0.00000000"],["110673.15000000","0.00633000"],["110672.27000000","0.00000000"],["110671.69000000","0.00000000"],["110671.63000000","0.00000000"],["110671.53000000","0.04800000"],["110671.28000000","0.04800000"],["110671.27000000","0.00000000"],["110670.15000000","1.18080000"],["110670.09000000","0.00000000"],["110668.96000000","0.04800000"],["110668.91000000","0.04800000"],["110668.62000000","0.00005000"],["110668.30000000","0.00000000"],["110668.29000000","0.00000000"],["110667.65000000","3.24539000"],["110667.44000000","0.00000000"],["110666.90000000","0.01631000"],["110666.67000000","0.00225000"],["110666.44000000","0.08460000"],["110666.21000000","0.02639000"],["110665.83000000","0.00000000"],["110665.54000000","0.00000000"],["110665.41000000","0.00000000"],["110665.21000000","0.00000000"],["110665.00000000","0.00000000"],["110663.99000000","0.00000000"],["110661.78000000","0.00000000"],["110661.28000000","0.01624000"],["110661.27000000","0.00000000"],["110661.09000000","1.20469000"],["110661.08000000","3.24539000"],["110661.03000000","0.00000000"],["110661.02000000","0.00000000"],["110660.98000000","0.00000000"],["110660.85000000","0.00000000"],["110660.76000000","0.00000000"],["110660.66000000","0.00112000"],["110660.58000000","0.03741000"],["110660.51000000","0.00005000"],["110660.02000000","0.00000000"],["110660.00000000","0.00211000"],["110659.77000000","0.00000000"],["110659.33000000","0.00000000"],["110659.29000000","0.00009000"],["110659.09000000","0.00000000"],["110658.63000000","0.00000000"],["110658.62000000","0.05622000"],["110658.08000000","0.00007000"],["110658.01000000","0.02998000"],["110657.52000000","0.00000000"],["110655.58000000","0.00000000"],["110655.16000000","0.00005000"],["110654.90000000","0.00000000"],["110654.43000000","3.24539000"],["110654.15000000","0.00000000"],["110653.92000000","0.00000000"],["110653.78000000","0.00000000"],["110652.94000000","0.00015000"],["110652.86000000","0.00000000"],["110652.72000000","0.01715000"],["110652.01000000","0.01625000"],["110651.93000000","0.00000000"],["110651.76000000","0.00000000"],["110651.10000000","0.00000000"],["110650.63000000","0.04800000"],["110650.35000000","0.00167000"],["110649.63000000","0.03996000"],["110648.99000000","0.00000000"],["110648.65000000","0.13527000"],["110648.31000000","0.02438000"],["110648.30000000","0.02341000"],["110647.44000000","0.02527000"],["110647.26000000","0.01625000"],["110647.04000000","0.00007000"],["110646.80000000","0.01625000"],["110646.11000000","0.00000000"],["110645.90000000","0.00000000"],["110644.67000000","0.00000000"],["110644.66000000","0.00000000"],["110644.60000000","0.03939000"],["110643.54000000","0.00000000"],["110643.36000000","0.00000000"],["110642.20000000","0.00000000"],["110641.95000000","0.00000000"],["110641.86000000","0.00000000"],["110641.55000000","0.00000000"],["110640.93000000","0.00000000"],["110636.00000000","0.00107000"],["110635.37000000","0.00000000"],["110634.74000000","0.02998000"],["110634.14000000","0.00000000"],["110633.46000000","0.00000000"],["110632.81000000","0.00000000"],["110632.75000000","0.02618000"],["110632.43000000","0.22546000"],["110632.17000000","0.00000000"],["110631.20000000","0.13515000"],["110627.51000000","0.18031000"],["110627.38000000","0.00000000"],["110626.50000000","0.00000000"],["110626.06000000","0.00009000"],["110625.76000000","0.00000000"],["110625.66000000","0.02618000"],["110624.25000000","0.14247000"],["110622.81000000","0.00000000"],["110622.56000000","0.00000000"],["110622.54000000","0.09641000"],["110621.67000000","0.00000000"],["110621.60000000","0.08494000"],["110621.40000000","0.03778000"],["110621.39000000","0.00000000"],["110621.37000000","0.00000000"],["110620.37000000","0.07712000"],["110620.03000000","0.02618000"],["110618.56000000","0.00000000"],["110617.08000000","0.08494000"],["110615.97000000","0.00159000"],["110615.96000000","0.00042000"],["110615.29000000","0.00000000"],["110615.09000000","0.04097000"],["110614.90000000","0.00000000"],["110614.74000000","0.08494000"],["110614.06000000","0.14283000"],["110614.05000000","0.00005000"],["110613.01000000","0.00000000"],["110612.76000000","0.00000000"],["110611.93000000","0.08494000"],["110611.48000000","0.04097000"],["110611.24000000","0.00000000"],["110611.23000000","0.00000000"],["110610.70000000","0.00000000"],["110610.11000000","0.02618000"],["110610.01000000","0.00000000"],["110609.12000000","0.00000000"],["110608.53000000","0.07109000"],["110607.49000000","0.00000000"],["110607.36000000","0.00000000"],["110606.58000000","0.08494000"],["110606.00000000","0.00100000"],["110605.79000000","0.00000000"],["110605.06000000","0.00000000"],["110605.01000000","0.24241000"],["110604.91000000","0.00087000"],["110604.10000000","0.00000000"],["110603.51000000","0.00000000"],["110602.91000000","0.08494000"],["110601.28000000","0.00000000"],["110600.99000000","0.00000000"],["110600.45000000","0.00000000"],["110600.37000000","0.00000000"],["110599.69000000","0.00000000"],["110599.58000000","0.08494000"],["110599.13000000","0.00000000"],["110598.47000000","0.08794000"],["110597.66000000","0.99643000"],["110596.87000000","0.08494000"],["110595.57000000","0.00000000"],["110594.67000000","0.08494000"],["110594.12000000","0.00000000"],["110593.51000000","0.08539000"],["110592.83000000","0.00009000"],["110591.69000000","0.02618000"],["110590.29000000","0.00000000"],["110589.14000000","0.00000000"],["110588.57000000","0.00000000"],["110588.40000000","0.00000000"],["110586.95000000","0.00000000"],["110585.13000000","0.00000000"],["110584.53000000","0.05430000"],["110584.36000000","0.00000000"],["110583.22000000","0.00000000"],["110582.72000000","0.02618000"],["110577.00000000","0.00000000"],["110576.26000000","0.02998000"],["110575.39000000","0.02998000"],["110574.45000000","0.00000000"],["110570.49000000","0.02998000"],["110570.00000000","0.00000000"],["110569.62000000","0.01895000"],["110569.45000000","0.02998000"],["110564.44000000","0.01086000"],["110558.69000000","0.02998000"],["110558.61000000","0.00000000"],["110557.28000000","0.02998000"],["110556.99000000","0.00000000"],["110555.63000000","0.00000000"],["110555.46000000","0.00000000"],["110555.19000000","0.00000000"],["110554.80000000","0.00000000"],["110554.71000000","0.00090000"],["110554.70000000","0.00000000"],["110554.49000000","0.00000000"],["110554.36000000","0.00000000"],["110554.12000000","0.00000000"],["110553.89000000","0.08394000"],["110552.96000000","0.00000000"],["110551.42000000","0.08394000"],["110550.94000000","0.00000000"],["110549.70000000","0.08394000"],["110548.66000000","0.08394000"],["110547.89000000","0.00000000"],["110547.59000000","0.23925000"],["110546.90000000","0.08394000"],["110544.39000000","0.08394000"],["110542.99000000","0.08394000"],["110542.15000000","0.00000000"],["110541.45000000","0.00000000"],["110541.06000000","0.08394000"],["110540.13000000","0.00000000"],["110540.08000000","0.00000000"],["110539.60000000","0.09894000"],["110539.33000000","0.08394000"],["110539.23000000","0.00067000"],["110538.20000000","0.08394000"],["110538.19000000","0.00000000"],["110537.30000000","0.08394000"],["110535.82000000","0.00000000"],["110535.35000000","0.00000000"],["110535.02000000","0.00000000"],["110533.65000000","0.00017000"],["110529.60000000","0.00862000"],["110528.46000000","0.00010000"],["110525.69000000","0.00000000"],["110522.48000000","0.02527000"],["110521.53000000","0.00000000"],["110520.79000000","0.02527000"],["110520.74000000","0.02998000"],["110520.39000000","0.02527000"],["110520.04000000","0.00000000"],["110519.99000000","0.02527000"],["110519.64000000","0.02527000"],["110519.30000000","0.02527000"],["110519.10000000","0.02998000"],["110518.77000000","0.00000000"],["110518.35000000","0.02527000"],["110518.34000000","0.02527000"],["110516.34000000","0.00000000"],["110513.98000000","0.00000000"],["110510.29000000","0.34629000"],["110508.59000000","0.00000000"],["110508.20000000","0.00000000"],["110505.42000000","0.90393000"],["110504.09000000","0.00064000"],["110502.99000000","0.00000000"],["110495.17000000","0.00000000"],["110493.89000000","0.00000000"],["110493.12000000","0.04947000"],["110492.16000000","0.69990000"],["110491.90000000","0.00000000"],["110482.20000000","0.00000000"],["110480.93000000","0.00471000"],["110480.32000000","0.00000000"],["110477.54000000","0.00000000"],["110476.39000000","0.00000000"],["110473.98000000","0.00000000"],["110473.70000000","0.00000000"],["110472.65000000","0.00000000"],["110472.56000000","0.00000000"],["110471.72000000","0.00000000"],["110471.43000000","0.00000000"],["110471.33000000","0.00000000"],["110470.84000000","0.00000000"],["110469.55000000","0.00000000"],["110468.69000000","0.00000000"],["110467.84000000","0.00005000"],["110467.40000000","0.00000000"],["110464.83000000","0.00000000"],["110464.53000000","0.00000000"],["110464.12000000","0.00000000"],["110463.37000000","0.00000000"],["110463.00000000","0.02618000"],["110462.95000000","0.95459000"],["110462.37000000","0.00000000"],["110462.23000000","0.00000000"],["110462.22000000","0.00000000"],["110462.04000000","0.00000000"],["110461.86000000","0.00000000"],["110461.69000000","0.00007000"],["110461.59000000","0.00000000"],["110461.58000000","0.00000000"],["110461.51000000","0.00000000"],["110461.32000000","0.00000000"],["110461.11000000","0.00000000"],["110460.88000000","0.00000000"],["110460.75000000","0.00000000"],["110460.70000000","0.00000000"],["110460.14000000","0.00000000"],["110460.10000000","0.17314000"],["110459.89000000","0.00000000"],["110458.86000000","0.00000000"],["110458.77000000","0.00000000"],["110458.14000000","0.00000000"],["110457.49000000","0.00000000"],["110455.89000000","0.00000000"],["110454.98000000","0.00000000"],["110454.65000000","0.00000000"],["110453.83000000","0.00000000"],["110453.71000000","0.00000000"],["110452.28000000","0.00000000"],["110452.18000000","0.00005000"],["110451.49000000","0.00000000"],["110451.01000000","0.00000000"],["110450.24000000","0.00000000"],["110450.13000000","0.00000000"],["110449.44000000","0.05430000"],["110449.26000000","0.00000000"],["110448.76000000","0.00000000"],["110448.44000000","0.00000000"],["110448.06000000","0.00000000"],["110446.67000000","0.45000000"],["110444.67000000","0.00000000"],["110443.02000000","0.00005000"],["110441.18000000","0.02437000"],["110440.86000000","0.00000000"],["110439.59000000","0.00000000"],["110438.68000000","0.00000000"],["110437.48000000","0.00010000"],["110437.44000000","0.04297000"],["110436.12000000","0.04297000"],["110435.75000000","0.04297000"],["110435.34000000","0.04297000"],["110434.45000000","0.00010000"],["110433.80000000","0.00000000"],["110433.59000000","0.07582000"],["110433.46000000","0.00000000"],["110433.33000000","0.07582000"],["110433.28000000","0.00000000"],["110433.25000000","0.04297000"],["110432.81000000","0.03791000"],["110432.80000000","0.00000000"],["110431.95000000","0.00000000"],["110431.75000000","0.02437000"],["110430.59000000","0.00000000"],["110430.33000000","0.03791000"],["110429.98000000","0.03791000"],["110429.60000000","0.03791000"],["110429.14000000","0.03791000"],["110428.97000000","0.02437000"],["110428.73000000","0.03791000"],["110428.72000000","0.03791000"],["110428.36000000","0.02618000"],["110428.17000000","0.03791000"],["110428.12000000","0.00000000"],["110428.00000000","0.03791000"],["110427.75000000","0.04297000"],["110427.73000000","0.03791000"],["110426.84000000","0.00010000"],["110426.14000000","0.02618000"],["110425.06000000","0.00000000"],["110425.00000000","0.00000000"],["110423.69000000","0.02618000"],["110422.83000000","0.04297000"],["110421.31000000","0.00000000"],["110419.65000000","0.01236000"],["110419.43000000","0.00000000"],["110418.68000000","0.02618000"],["110418.38000000","0.04297000"],["110418.26000000","0.00000000"],["110417.83000000","0.00000000"],["110417.80000000","0.00000000"],["110417.45000000","0.00000000"],["110417.30000000","0.00000000"],["110417.23000000","0.00000000"],["110416.49000000","0.00000000"],["110416.12000000","0.00000000"],["110415.23000000","0.03791000"],["110414.99000000","0.06409000"],["110414.76000000","0.03791000"],["110414.07000000","0.00000000"],["110414.01000000","0.04297000"],["110413.89000000","0.00000000"],["110413.62000000","0.03791000"],["110413.61000000","0.03791000"],["110413.47000000","0.00000000"],["110413.43000000","0.00000000"],["110412.68000000","0.03791000"],["110412.67000000","0.03791000"],["110412.63000000","0.02618000"],["110411.45000000","0.04297000"],["110411.13000000","0.04297000"],["110410.44000000","0.02618000"],["110410.30000000","0.03791000"],["110408.64000000","0.03791000"],["110408.26000000","0.02618000"],["110406.01000000","0.02618000"],["110405.97000000","0.00000000"],["110404.05000000","0.00000000"],["110403.31000000","0.00000000"],["110401.45000000","0.00000000"],["110401.38000000","0.00000000"],["110401.30000000","0.00000000"],["110398.56000000","0.00000000"],["110398.25000000","0.00000000"],["110389.13000000","0.45140000"],["110378.64000000","0.02998000"],["110378.15000000","0.02998000"],["110377.51000000","0.02998000"],["110376.95000000","0.02998000"],["110375.85000000","0.02998000"],["110372.76000000","0.03004000"],["110370.53000000","0.00000000"],["110370.41000000","0.02998000"],["110358.86000000","0.00000000"],["110354.62000000","0.00000000"],["110349.33000000","0.00333000"],["110347.13000000","0.00000000"],["110342.77000000","0.02764000"],["110334.78000000","0.00000000"],["110334.71000000","0.00000000"],["110332.62000000","0.00000000"],["110328.74000000","0.00000000"],["110322.54000000","0.00000000"],["110320.60000000","0.02437000"],["110320.04000000","0.00000000"],["110315.09000000","0.17637000"],["110314.77000000","0.11033000"],["110313.66000000","0.45000000"],["110309.30000000","0.02437000"],["110301.00000000","0.02437000"],["110299.08000000","0.02437000"],["110298.19000000","0.02437000"],["110290.00000000","0.04874000"],["110287.61000000","0.02437000"],["110283.09000000","0.02437000"],["110270.13000000","0.00000000"],["110209.40000000","0.00000000"],["110200.82000000","0.00000000"],["110200.79000000","0.00000000"],["110200.59000000","0.00000000"],["110199.89000000","0.00000000"],["110199.80000000","0.00000000"],["110199.78000000","0.00000000"],["110198.75000000","0.00000000"],["110198.51000000","0.00000000"],["110198.02000000","0.00000000"],["110197.84000000","0.00000000"],["110197.15000000","0.00000000"],["110184.74000000","0.00000000"],["110181.95000000","0.00000000"],["110181.67000000","0.00000000"],["110181.61000000","0.00000000"],["110162.35000000","0.02398000"],["110162.04000000","0.02398000"],["110149.27000000","0.32646000"],["110007.27000000","0.00000000"],["109600.00000000","0.34989000"],["105403.05000000","0.00095000"],["102000.00000000","94.09693000"],["101905.53000000","0.00000000"],["99707.00000000","0.00000000"],["99697.00000000","0.00010000"],["99683.00000000","0.00014000"],["88625.28000000","0.00000000"],["88608.00000000","0.00000000"],["88607.18000000","0.00022000"]],"a":[["110758.98000000","16.03370000"],["110759.06000000","0.00010000"],["110759.17000000","0.00000000"],["110759.24000000","0.00000000"],["110759.26000000","0.04910000"],["110759.27000000","0.33778000"],["110759.35000000","0.00000000"],["110759.39000000","0.00000000"],["110759.53000000","0.00000000"],["110759.98000000","0.00000000"],["110760.00000000","2.01261000"],["110760.01000000","0.85603000"],["110760.02000000","0.00000000"],["110760.09000000","0.00000000"],["110760.64000000","0.00000000"],["110761.06000000","0.00000000"],["110761.19000000","0.00361000"],["110761.24000000","0.00000000"],["110761.98000000","0.00000000"],["110762.00000000","0.00000000"],["110762.01000000","0.29770000"],["110762.24000000","0.04524000"],["110762.34000000","0.01815000"],["110762.59000000","0.21652000"],["110762.84000000","0.00005000"],["110762.85000000","0.00547000"],["110762.94000000","0.32471000"],["110763.43000000","0.00000000"],["110763.77000000","0.00000000"],["110763.84000000","0.00000000"],["110763.86000000","0.00000000"],["110763.87000000","0.04012000"],["110763.88000000","0.03616000"],["110764.14000000","0.00000000"],["110764.35000000","0.00000000"],["110764.52000000","0.00000000"],["110764.68000000","0.00005000"],["110764.72000000","0.00000000"],["110764.73000000","0.00000000"],["110764.80000000","0.11273000"],["110764.83000000","0.00000000"],["110764.85000000","0.04519000"],["110764.86000000","0.04012000"],["110765.05000000","0.00000000"],["110765.09000000","0.00000000"],["110765.97000000","0.00000000"],["110765.98000000","0.00455000"],["110765.99000000","0.18026000"],["110766.00000000","0.34166000"],["110766.01000000","0.37847000"],["110766.09000000","0.00000000"],["110766.18000000","0.00000000"],["110766.54000000","0.00000000"],["110766.80000000","0.32464000"],["110766.88000000","3.24539000"],["110766.89000000","0.00000000"],["110766.97000000","0.00000000"],["110767.09000000","0.05132000"],["110767.12000000","0.04145000"],["110767.72000000","0.00000000"],["110767.73000000","0.00000000"],["110767.76000000","0.00000000"],["110767.83000000","0.00000000"],["110767.84000000","0.01805000"],["110768.01000000","0.00000000"],["110768.22000000","0.03621000"],["110768.49000000","0.00000000"],["110768.94000000","0.00000000"],["110768.99000000","0.00044000"],["110769.39000000","0.00000000"],["110769.56000000","0.00000000"],["110769.58000000","0.00000000"],["110769.59000000","0.00000000"],["110770.01000000","0.00000000"],["110770.06000000","0.00300000"],["110770.26000000","3.24539000"],["110770.39000000","0.00000000"],["110770.74000000","0.00005000"],["110770.84000000","0.08567000"],["110770.91000000","0.04524000"],["110771.06000000","0.00000000"],["110771.09000000","0.45000000"],["110771.12000000","0.00000000"],["110771.13000000","0.00000000"],["110771.14000000","0.00000000"],["110771.15000000","0.18026000"],["110771.16000000","0.00000000"],["110771.17000000","0.00000000"],["110771.18000000","0.02629000"],["110771.25000000","0.00000000"],["110771.62000000","0.00000000"],["110771.91000000","0.00000000"],["110772.00000000","0.00000000"],["110772.01000000","0.00000000"],["110772.08000000","0.00000000"],["110772.20000000","0.03616000"],["110772.55000000","0.00000000"],["110773.23000000","0.01810000"],["110773.42000000","0.01810000"],["110773.48000000","0.00044000"],["110773.56000000","0.00000000"],["110773.63000000","0.00000000"],["110773.65000000","0.00000000"],["110773.66000000","0.00000000"],["110773.67000000","3.24539000"],["110773.71000000","0.00000000"],["110773.74000000","0.00000000"],["110773.79000000","0.13527000"],["110773.84000000","0.00010000"],["110773.98000000","0.00000000"],["110774.00000000","0.00000000"],["110774.01000000","4.80000000"],["110774.22000000","0.00000000"],["110774.33000000","0.00000000"],["110774.40000000","0.00000000"],["110774.41000000","0.10533000"],["110774.42000000","0.00000000"],["110774.43000000","0.00000000"],["110774.46000000","0.45036000"],["110774.56000000","0.00188000"],["110774.79000000","0.13527000"],["110775.04000000","0.00000000"],["110775.05000000","0.18026000"],["110775.06000000","0.00000000"],["110775.07000000","0.00000000"],["110775.08000000","0.00000000"],["110775.16000000","0.00000000"],["110775.22000000","0.00000000"],["110775.46000000","0.00000000"],["110775.49000000","0.08567000"],["110775.53000000","0.00000000"],["110775.55000000","0.00000000"],["110775.56000000","0.00000000"],["110775.59000000","0.00005000"],["110775.69000000","0.00000000"],["110775.81000000","0.06240000"],["110775.89000000","0.00000000"],["110776.00000000","0.00000000"],["110776.01000000","0.01778000"],["110776.18000000","0.00000000"],["110776.46000000","0.00000000"],["110776.77000000","0.00000000"],["110776.79000000","0.13440000"],["110776.80000000","0.00005000"],["110776.81000000","0.00000000"],["110776.83000000","0.01805000"],["110776.84000000","0.00000000"],["110776.86000000","0.00000000"],["110776.91000000","0.00007000"],["110777.06000000","0.00000000"],["110777.11000000","0.00000000"],["110777.13000000","3.24539000"],["110777.14000000","1.28000000"],["110777.35000000","0.00000000"],["110777.47000000","0.00000000"],["110777.54000000","0.00000000"],["110777.56000000","0.00000000"],["110777.57000000","0.00000000"],["110777.81000000","0.00000000"],["110778.01000000","0.00000000"],["110778.15000000","0.00000000"],["110778.30000000","0.00000000"],["110778.39000000","0.00000000"],["110778.45000000","0.00044000"],["110778.50000000","0.03610000"],["110778.60000000","0.00901000"],["110778.68000000","0.00007000"],["110778.74000000","0.00000000"],["110778.77000000","0.00000000"],["110778.87000000","1.22015000"],["110778.88000000","0.00000000"],["110779.25000000","0.00000000"],["110779.31000000","0.36073000"],["110779.32000000","0.04000000"],["110779.60000000","0.00000000"],["110779.78000000","0.00000000"],["110780.00000000","0.00005000"],["110780.01000000","0.00000000"],["110780.22000000","0.08160000"],["110780.36000000","0.01964000"],["110780.50000000","3.24539000"],["110780.60000000","0.00000000"],["110780.69000000","0.00000000"],["110780.72000000","0.00010000"],["110781.14000000","0.00300000"],["110781.29000000","0.00000000"],["110781.30000000","0.10080000"],["110781.32000000","0.00000000"],["110781.47000000","0.00000000"],["110781.58000000","0.00000000"],["110781.60000000","0.18026000"],["110781.61000000","0.00000000"],["110781.69000000","0.00000000"],["110781.75000000","0.00000000"],["110781.76000000","0.00000000"],["110781.77000000","0.00000000"],["110782.00000000","0.00400000"],["110782.22000000","0.19680000"],["110782.26000000","0.00005000"],["110782.38000000","0.12000000"],["110782.54000000","0.10560000"],["110782.72000000","0.00006000"],["110782.87000000","0.00000000"],["110783.08000000","0.11520000"],["110783.27000000","0.02638000"],["110783.79000000","0.00000000"],["110783.93000000","2.44393000"],["110783.94000000","3.24539000"],["110784.05000000","0.00000000"],["110784.09000000","0.00000000"],["110784.10000000","0.00000000"],["110784.54000000","0.05618000"],["110784.92000000","0.00000000"],["110784.97000000","0.02800000"],["110785.00000000","0.00010000"],["110785.39000000","0.14400000"],["110785.40000000","0.00000000"],["110785.41000000","0.00000000"],["110785.43000000","0.04007000"],["110786.00000000","0.00018000"],["110786.01000000","0.30590000"],["110786.15000000","0.45000000"],["110786.63000000","0.08567000"],["110786.64000000","0.00000000"],["110786.67000000","0.00000000"],["110787.58000000","3.24539000"],["110787.78000000","0.00000000"],["110787.83000000","0.00000000"],["110787.86000000","0.04007000"],["110788.01000000","0.00000000"],["110788.02000000","0.00903000"],["110788.05000000","0.00000000"],["110788.06000000","0.00000000"],["110788.24000000","0.01354000"],["110788.61000000","0.00000000"],["110788.76000000","0.00000000"],["110788.91000000","0.00010000"],["110789.43000000","0.00000000"],["110789.46000000","0.00000000"],["110789.47000000","0.00000000"],["110789.50000000","0.00000000"],["110789.62000000","0.00000000"],["110789.77000000","0.00007000"],["110789.87000000","0.00000000"],["110789.90000000","0.05280000"],["110789.95000000","0.12240000"],["110790.10000000","0.00012000"],["110790.11000000","0.00000000"],["110790.40000000","0.00000000"],["110790.61000000","0.00000000"],["110790.72000000","0.03610000"],["110791.05000000","2.16054000"],["110791.06000000","3.24539000"],["110791.18000000","0.00000000"],["110791.35000000","0.00000000"],["110791.42000000","0.00000000"],["110791.61000000","0.06646000"],["110791.62000000","0.00084000"],["110791.69000000","0.00000000"],["110791.70000000","0.00000000"],["110791.78000000","0.00010000"],["110791.84000000","0.18031000"],["110791.92000000","0.00000000"],["110791.93000000","0.00000000"],["110791.98000000","0.00000000"],["110792.14000000","0.22546000"],["110792.21000000","0.00009000"],["110792.37000000","0.02141000"],["110792.63000000","0.00005000"],["110792.79000000","0.00000000"],["110792.89000000","0.01173000"],["110792.92000000","0.00000000"],["110793.10000000","0.01805000"],["110793.44000000","0.01791000"],["110793.52000000","0.00000000"],["110793.71000000","0.08160000"],["110793.72000000","0.00000000"],["110793.78000000","0.00000000"],["110793.88000000","0.00275000"],["110794.04000000","0.00000000"],["110794.29000000","0.00438000"],["110794.30000000","0.00000000"],["110794.48000000","0.00000000"],["110794.75000000","0.00000000"],["110795.91000000","0.00000000"],["110796.91000000","0.00000000"],["110797.09000000","0.00300000"],["110797.57000000","0.00000000"],["110797.60000000","0.00225000"],["110797.61000000","0.49806000"],["110798.52000000","0.00000000"],["110798.63000000","0.04357000"],["110798.66000000","0.00000000"],["110798.67000000","0.00000000"],["110798.93000000","0.08567000"],["110799.17000000","0.01625000"],["110799.18000000","0.03150000"],["110799.48000000","0.00000000"],["110799.91000000","0.00000000"],["110799.99000000","0.04002000"],["110800.00000000","0.03543000"],["110800.41000000","0.00000000"],["110801.54000000","0.03997000"],["110801.69000000","0.00022000"],["110802.12000000","0.00000000"],["110802.43000000","0.00000000"],["110802.95000000","0.00000000"],["110803.07000000","0.00000000"],["110803.08000000","0.48997000"],["110803.46000000","0.00000000"],["110803.60000000","0.00000000"],["110804.66000000","0.00000000"],["110804.67000000","0.00000000"],["110805.54000000","0.00000000"],["110805.58000000","0.00000000"],["110805.98000000","0.00000000"],["110806.04000000","0.11520000"],["110806.35000000","0.00000000"],["110806.50000000","0.00000000"],["110806.61000000","0.00000000"],["110806.82000000","0.13515000"],["110807.11000000","0.00010000"],["110807.23000000","0.00000000"],["110807.35000000","0.00000000"],["110808.15000000","0.00000000"],["110808.63000000","0.00000000"],["110808.72000000","0.00000000"],["110808.92000000","0.00000000"],["110809.07000000","0.00000000"],["110809.17000000","0.03997000"],["110809.18000000","0.00000000"],["110809.31000000","0.00000000"],["110809.77000000","0.00000000"],["110810.02000000","0.00000000"],["110811.96000000","0.25814000"],["110812.22000000","0.08160000"],["110812.47000000","0.00000000"],["110812.84000000","0.00000000"],["110813.30000000","0.00000000"],["110813.56000000","0.00000000"],["110813.77000000","0.00000000"],["110813.80000000","0.00000000"],["110814.15000000","0.00000000"],["110815.28000000","0.00000000"],["110815.56000000","0.00000000"],["110816.47000000","0.02141000"],["110816.57000000","0.00000000"],["110816.75000000","0.00000000"],["110817.98000000","0.02527000"],["110817.99000000","0.00000000"],["110818.00000000","0.00005000"],["110818.01000000","0.00000000"],["110818.50000000","0.00000000"],["110819.22000000","0.00000000"],["110819.96000000","0.00000000"],["110820.37000000","0.00000000"],["110820.50000000","0.00000000"],["110820.64000000","0.00000000"],["110821.10000000","0.00000000"],["110821.19000000","0.00000000"],["110821.35000000","0.00000000"],["110821.60000000","0.00000000"],["110821.77000000","0.03997000"],["110821.80000000","0.00000000"],["110822.16000000","0.00000000"],["110822.34000000","0.00000000"],["110822.42000000","0.00000000"],["110822.48000000","0.02216000"],["110822.77000000","0.32580000"],["110822.96000000","0.00000000"],["110823.41000000","0.00630000"],["110823.67000000","0.00000000"],["110823.96000000","0.03997000"],["110824.08000000","0.03997000"],["110824.09000000","0.00000000"],["110824.39000000","0.00000000"],["110824.94000000","0.00000000"],["110824.99000000","0.00000000"],["110825.28000000","0.00000000"],["110825.44000000","0.00009000"],["110825.45000000","0.00007000"],["110825.61000000","0.00000000"],["110826.74000000","0.00627000"],["110827.91000000","0.00618000"],["110828.09000000","0.00000000"],["110828.14000000","0.00000000"],["110829.12000000","0.23000000"],["110829.13000000","0.00000000"],["110829.73000000","0.00000000"],["110829.80000000","0.00000000"],["110831.34000000","0.00000000"],["110831.93000000","0.00224000"],["110832.74000000","0.00000000"],["110834.52000000","0.00655000"],["110835.12000000","0.13527000"],["110835.80000000","0.00000000"],["110835.86000000","0.13527000"],["110835.98000000","0.24906000"],["110836.39000000","0.00000000"],["110836.40000000","0.00000000"],["110838.25000000","0.13369000"],["110839.14000000","0.00000000"],["110839.31000000","0.22118000"],["110840.24000000","0.00000000"],["110841.32000000","0.00000000"],["110842.24000000","0.00000000"],["110842.25000000","0.00333000"],["110842.49000000","0.00000000"],["110843.39000000","0.00000000"],["110844.86000000","0.00551000"],["110845.97000000","0.02146000"],["110846.26000000","0.90115000"],["110846.64000000","0.01895000"],["110846.93000000","0.00000000"],["110849.09000000","0.00000000"],["110850.19000000","0.00000000"],["110850.41000000","0.00000000"],["110850.49000000","0.14062000"],["110850.50000000","0.00000000"],["110852.17000000","0.00000000"],["110852.30000000","0.00000000"],["110854.33000000","0.00000000"],["110855.47000000","0.00000000"],["110856.63000000","0.00000000"],["110857.00000000","0.35918000"],["110857.79000000","0.00000000"],["110858.04000000","0.00000000"],["110858.60000000","0.00110000"],["110858.66000000","0.00009000"],["110858.74000000","0.00450000"],["110859.98000000","0.00000000"],["110860.00000000","0.00120000"],["110860.89000000","0.00000000"],["110862.79000000","0.04056000"],["110862.87000000","0.00000000"],["110863.20000000","0.02441000"],["110863.52000000","0.02617000"],["110863.53000000","0.00000000"],["110863.76000000","0.00000000"],["110864.00000000","0.00137000"],["110865.61000000","0.00000000"],["110866.00000000","0.00132000"],["110866.13000000","0.13515000"],["110866.41000000","0.00000000"],["110866.76000000","0.00225000"],["110866.77000000","0.00000000"],["110867.10000000","0.00000000"],["110867.79000000","0.51402000"],["110868.00000000","0.00132000"],["110868.41000000","0.00000000"],["110869.25000000","0.00000000"],["110869.37000000","0.18031000"],["110869.67000000","0.22546000"],["110869.88000000","0.02998000"],["110869.89000000","0.02617000"],["110870.00000000","0.00132000"],["110872.00000000","0.00132000"],["110872.08000000","0.00000000"],["110872.37000000","0.00000000"],["110873.31000000","0.00000000"],["110874.00000000","0.00132000"],["110876.42000000","0.00000000"],["110876.95000000","0.09641000"],["110877.47000000","0.00000000"],["110878.43000000","0.00000000"],["110878.92000000","0.02998000"],["110878.93000000","0.00000000"],["110879.26000000","0.00000000"],["110879.81000000","0.08780000"],["110880.00000000","0.01941000"],["110881.08000000","0.00000000"],["110882.21000000","0.00000000"],["110882.66000000","0.00000000"],["110883.53000000","0.00000000"],["110883.59000000","0.00000000"],["110884.03000000","0.00000000"],["110884.10000000","0.00000000"],["110884.86000000","0.00000000"],["110884.87000000","0.00000000"],["110885.03000000","0.00000000"],["110887.06000000","0.00331000"],["110887.57000000","0.00000000"],["110888.80000000","0.09641000"],["110890.08000000","0.00000000"],["110891.89000000","0.00009000"],["110893.04000000","0.00000000"],["110893.05000000","0.00000000"],["110894.57000000","0.00000000"],["110900.00000000","0.00132000"],["110901.56000000","0.00000000"],["110902.48000000","0.00000000"],["110906.06000000","0.00000000"],["110912.12000000","0.00000000"],["110912.13000000","0.00000000"],["110912.50000000","0.00000000"],["110914.41000000","0.99154000"],["110915.06000000","0.08668000"],["110915.75000000","0.00000000"],["110917.15000000","0.00000000"],["110919.50000000","0.02998000"],["110920.00000000","0.00137000"],["110920.81000000","0.00000000"],["110922.90000000","0.00000000"],["110925.12000000","0.00009000"],["110925.20000000","0.00000000"],["110926.37000000","0.00000000"],["110927.98000000","0.01624000"],["110928.75000000","0.00000000"],["110930.40000000","0.00000000"],["110932.96000000","0.00000000"],["110933.90000000","0.00000000"],["110933.94000000","0.00007000"],["110933.95000000","0.00000000"],["110938.04000000","0.00000000"],["110939.42000000","0.00000000"],["110940.00000000","0.00132000"],["110941.99000000","0.00090000"],["110942.27000000","0.00000000"],["110947.46000000","0.10928000"],["110950.57000000","0.00000000"],["110952.85000000","0.00000000"],["110953.14000000","0.00000000"],["110954.04000000","0.00000000"],["110955.12000000","0.00000000"],["110957.09000000","0.00000000"],["110959.96000000","0.00000000"],["110959.98000000","0.00000000"],["110960.00000000","0.00137000"],["110961.65000000","0.00000000"],["110961.67000000","0.00000000"],["110963.27000000","0.00000000"],["110963.36000000","0.00000000"],["110967.36000000","0.00000000"],["110971.26000000","0.00000000"],["110972.98000000","0.00000000"],["110980.77000000","0.00000000"],["110980.78000000","0.00000000"],["110983.42000000","0.00000000"],["110985.97000000","0.14851000"],["110985.99000000","0.00000000"],["110987.77000000","0.00006000"],["110989.99000000","0.00000000"],["110994.60000000","0.00000000"],["110996.43000000","0.08394000"],["110996.96000000","0.00000000"],["111000.00000000","0.00288000"],["111000.24000000","0.00000000"],["111000.48000000","0.00000000"],["111005.30000000","0.00000000"],["111005.56000000","0.00000000"],["111007.36000000","0.00000000"],["111007.93000000","0.00403000"],["111011.30000000","0.02528000"],["111011.57000000","0.00000000"],["111011.74000000","0.02528000"],["111012.53000000","0.02528000"],["111013.13000000","0.00000000"],["111014.67000000","0.02528000"],["111019.23000000","0.00000000"],["111023.86000000","0.00000000"],["111027.40000000","0.00008000"],["111031.10000000","0.21705000"],["111035.28000000","0.00000000"],["111056.07000000","0.04297000"],["111058.32000000","0.00007000"],["111059.95000000","0.00000000"],["111075.25000000","0.04297000"],["111077.90000000","0.04297000"],["111078.26000000","0.04297000"],["111079.08000000","0.03791000"],["111079.24000000","0.03791000"],["111079.55000000","0.03791000"],["111079.70000000","0.03791000"],["111079.86000000","0.03791000"],["111080.10000000","0.03791000"],["111080.52000000","0.00000000"],["111086.06000000","0.00000000"],["111086.45000000","0.07406000"],["111088.19000000","0.07395000"],["111089.05000000","0.00007000"],["111090.71000000","0.07395000"],["111091.05000000","0.00000000"],["111091.56000000","0.00000000"],["111091.60000000","0.00000000"],["111092.09000000","0.07395000"],["111092.33000000","0.00000000"],["111092.80000000","0.00000000"],["111094.31000000","0.00000000"],["111094.36000000","0.00000000"],["111095.22000000","0.00005000"],["111096.63000000","0.00000000"],["111097.54000000","0.00000000"],["111098.00000000","0.00032000"],["111098.17000000","0.00000000"],["111100.05000000","0.03791000"],["111102.68000000","0.00000000"],["111118.48000000","0.00000000"],["111144.68000000","0.00000000"],["111146.08000000","0.00000000"],["111153.51000000","0.02437000"],["111154.92000000","0.02437000"],["111160.77000000","0.00082000"],["111165.29000000","0.94995000"],["111168.59000000","0.00000000"],["111170.82000000","0.00006000"],["111171.40000000","0.00000000"],["111172.90000000","0.00000000"],["111173.02000000","0.00000000"],["111173.91000000","0.00000000"],["111174.17000000","0.00000000"],["111179.72000000","0.45000000"],["111179.75000000","0.00000000"],["111190.80000000","0.45000000"],["111190.83000000","0.00000000"],["111190.86000000","0.00000000"],["111192.21000000","0.17723000"],["111196.02000000","0.00000000"],["111199.52000000","0.00000000"],["111201.83000000","0.00000000"],["111201.95000000","0.00000000"],["111204.05000000","0.00000000"],["111207.88000000","0.00133000"],["111211.83000000","0.00000000"],["111213.03000000","0.00000000"],["111215.77000000","0.00000000"],["111218.21000000","0.00000000"],["111219.62000000","0.00000000"],["111221.04000000","0.00000000"],["111258.97000000","0.00331000"],["111263.45000000","0.00000000"],["111281.44000000","0.00000000"],["111282.03000000","0.00000000"],["111311.77000000","0.67153000"],["111319.83000000","0.00081000"],["111354.00000000","0.00046000"],["111359.54000000","0.00000000"],["111429.78000000","0.00000000"],["111604.99000000","0.00000000"],["111943.06000000","4.46164000"],["112184.05000000","0.00000000"],["128001.97000000","0.00040000"]]}
[2025-10-11T22:18:25.331Z] {"e":"depthUpdate","E":1760221105014,"s":"BTCUSDT","U":77926025504,"u":77926026510,"b":[["110758.97000000","0.00000000"],["110758.96000000","0.00000000"],["110758.62000000","0.00000000"],["110758.00000000","0.00000000"],["110757.70000000","0.00000000"],["110757.25000000","0.00000000"],["110756.57000000","0.00000000"],["110756.56000000","0.00000000"],["110756.00000000","0.00000000"],["110755.81000000","0.00000000"],["110755.64000000","0.00000000"],["110755.51000000","0.00000000"],["110755.10000000","0.00000000"],["110754.61000000","0.00000000"],["110754.35000000","0.00000000"],["110754.22000000","0.00000000"],["110754.05000000","0.00000000"],["110754.00000000","0.00000000"],["110753.99000000","0.00000000"],["110753.65000000","0.00000000"],["110753.50000000","0.00000000"],["110753.43000000","0.00000000"],["110752.56000000","0.00000000"],["110752.00000000","0.00000000"],["110751.76000000","0.00000000"],["110751.01000000","0.00000000"],["110751.00000000","0.00000000"],["110750.01000000","0.00000000"],["110750.00000000","4.87535000"],["110749.99000000","0.00065000"],["110749.92000000","0.00010000"],["110749.67000000","0.00000000"],["110749.40000000","0.00941000"],["110749.21000000","0.00000000"],["110748.23000000","0.00010000"],["110748.22000000","0.04686000"],["110748.11000000","0.00000000"],["110747.89000000","0.00000000"],["110747.36000000","0.00000000"],["110746.84000000","0.00000000"],["110746.83000000","0.00000000"],["110746.46000000","0.00000000"],["110746.45000000","0.00000000"],["110746.29000000","0.00010000"],["110746.28000000","0.03173000"],["110746.11000000","0.00000000"],["110745.61000000","0.00000000"],["110745.60000000","0.00000000"],["110745.52000000","0.00000000"],["110745.27000000","0.00000000"],["110745.26000000","0.00000000"],["110745.14000000","0.00000000"],["110745.13000000","0.00000000"],["110745.12000000","0.00000000"],["110744.59000000","0.00000000"],["110744.47000000","0.00010000"],["110744.46000000","0.11278000"],["110744.09000000","0.00000000"],["110744.08000000","0.00000000"],["110743.98000000","0.00010000"],["110743.97000000","0.19227000"],["110743.96000000","0.29770000"],["110743.89000000","0.00000000"],["110743.66000000","0.00000000"],["110743.65000000","0.00000000"],["110743.55000000","0.00000000"],["110742.44000000","0.00000000"],["110741.59000000","0.00000000"],["110741.38000000","0.00000000"],["110741.22000000","0.00000000"],["110741.18000000","0.00000000"],["110740.49000000","0.00000000"],["110740.48000000","0.00000000"],["110740.33000000","0.00000000"],["110740.29000000","0.00000000"],["110740.28000000","0.00000000"],["110740.01000000","0.00000000"],["110740.00000000","0.02022000"],["110739.83000000","0.00000000"],["110739.27000000","0.00000000"],["110739.26000000","0.32478000"],["110739.23000000","0.00000000"],["110739.22000000","0.04008000"],["110739.17000000","0.00000000"],["110738.93000000","0.00000000"],["110738.92000000","0.04658000"],["110738.46000000","0.00000000"],["110738.40000000","0.00000000"],["110738.34000000","0.02710000"],["110738.21000000","0.00000000"],["110737.41000000","0.00000000"],["110737.16000000","0.00000000"],["110737.15000000","0.29882000"],["110737.14000000","0.00000000"],["110736.52000000","0.00000000"],["110736.04000000","0.00000000"],["110735.60000000","0.09298000"],["110735.37000000","0.00000000"],["110735.36000000","0.00007000"],["110733.39000000","0.00149000"],["110733.30000000","0.30183000"],["110731.28000000","0.00000000"],["110730.79000000","0.06646000"],["110729.22000000","0.04800000"],["110728.28000000","0.00000000"],["110726.77000000","0.51517000"],["110726.76000000","0.00000000"],["110725.37000000","0.32477000"],["110724.67000000","0.20214000"],["110724.66000000","0.00000000"],["110723.86000000","0.00403000"],["110720.79000000","0.28429000"],["110720.78000000","0.00000000"],["110720.38000000","0.02638000"],["110716.78000000","0.04508000"],["110716.77000000","0.00300000"],["110710.59000000","0.00000000"],["110709.33000000","0.00413000"],["110707.72000000","0.00000000"],["110705.67000000","1.22549000"],["110700.14000000","0.30580000"],["110698.02000000","0.00005000"],["110690.18000000","0.00000000"],["110682.60000000","0.06830000"],["110673.37000000","0.00000000"],["110673.32000000","0.04800000"],["110670.16000000","0.18026000"],["110666.67000000","0.00000000"],["110659.32000000","0.00000000"],["110657.76000000","0.00006000"],["110657.58000000","0.00225000"],["110656.23000000","0.00005000"],["110654.44000000","1.33370000"],["110652.77000000","0.00005000"],["110650.63000000","0.00000000"],["110650.35000000","0.00000000"],["110650.34000000","1.55698000"],["110647.78000000","3.24539000"],["110647.67000000","0.00000000"],["110644.61000000","0.04840000"],["110643.80000000","0.00005000"],["110642.98000000","0.02592000"],["110639.42000000","0.01488000"],["110636.02000000","0.00000000"],["110634.82000000","0.01380000"],["110633.48000000","0.00167000"],["110633.46000000","0.42079000"],["110632.89000000","0.02528000"],["110627.52000000","0.23111000"],["110626.51000000","0.09641000"],["110624.25000000","0.00000000"],["110622.63000000","0.00000000"],["110622.54000000","0.00000000"],["110621.88000000","0.00000000"],["110621.61000000","0.13189000"],["110621.40000000","0.00000000"],["110621.17000000","0.00000000"],["110616.28000000","0.08395000"],["110615.97000000","0.00000000"],["110613.50000000","0.08395000"],["110610.47000000","0.02528000"],["110610.16000000","0.08395000"],["110610.12000000","0.33331000"],["110610.10000000","0.06009000"],["110607.34000000","0.02528000"],["110606.59000000","0.00160000"],["110605.30000000","0.08395000"],["110601.53000000","0.08395000"],["110599.59000000","0.39437000"],["110598.39000000","0.02528000"],["110598.35000000","0.08395000"],["110596.55000000","0.08395000"],["110595.13000000","0.02618000"],["110594.61000000","0.08395000"],["110593.51000000","0.35455000"],["110576.95000000","0.02618000"],["110539.60000000","0.00000000"],["110531.01000000","0.09894000"],["110529.60000000","0.00000000"],["110515.20000000","0.00882000"],["110510.29000000","0.00000000"],["110506.01000000","0.02528000"],["110505.49000000","0.02528000"],["110505.20000000","0.02528000"],["110504.85000000","0.02528000"],["110504.50000000","0.02528000"],["110503.76000000","0.02528000"],["110502.45000000","0.02528000"],["110500.92000000","0.02528000"],["110496.44000000","0.34629000"],["110493.12000000","0.00000000"],["110479.77000000","0.04947000"],["110460.10000000","0.00000000"],["110447.96000000","0.02618000"],["110445.86000000","0.17314000"],["110420.97000000","0.00010000"],["110419.65000000","0.00000000"],["110415.44000000","0.00010000"],["110409.91000000","0.00010000"],["110407.08000000","0.01236000"],["110404.38000000","0.00000000"],["110389.13000000","0.00000000"],["110388.90000000","0.07395000"],["110388.60000000","0.07395000"],["110387.53000000","0.07395000"],["110385.88000000","0.07395000"],["110384.70000000","0.07395000"],["110382.79000000","0.07395000"],["110382.30000000","0.07395000"],["110381.81000000","0.07469000"],["110380.39000000","0.07395000"],["110378.99000000","0.07395000"],["110376.72000000","0.45146000"],["110291.50000000","0.45000000"],["110182.52000000","0.00000000"],["110152.31000000","0.02398000"],["109170.18000000","0.00000000"],["105429.94000000","0.00000000"],["105387.68000000","0.00090000"],["99697.00000000","0.00000000"],["99682.00000000","0.00000000"],["99675.00000000","0.04016000"],["88607.18000000","0.00000000"],["88600.00000000","3.24442000"],["39870.00000000","0.00032000"]],"a":[["110750.01000000","10.38533000"],["110750.02000000","0.00000000"],["110750.09000000","0.00010000"],["110751.15000000","0.00010000"],["110751.16000000","0.04015000"],["110751.24000000","0.00010000"],["110751.25000000","0.11061000"],["110751.26000000","0.04524000"],["110751.74000000","0.00005000"],["110752.56000000","0.00005000"],["110753.42000000","0.00010000"],["110753.43000000","0.32478000"],["110753.44000000","0.00000000"],["110753.51000000","0.00000000"],["110753.66000000","0.00000000"],["110753.84000000","0.00000000"],["110753.96000000","0.00005000"],["110754.00000000","0.00000000"],["110754.62000000","0.00000000"],["110755.11000000","0.00000000"],["110755.65000000","0.00000000"],["110755.82000000","0.00000000"],["110756.57000000","0.00000000"],["110756.58000000","0.00000000"],["110757.26000000","0.00000000"],["110758.62000000","0.00005000"],["110758.95000000","0.00000000"],["110758.96000000","2.94325000"],["110758.97000000","0.18031000"],["110758.98000000","8.40076000"],["110759.06000000","0.00000000"],["110759.26000000","0.00005000"],["110759.27000000","0.33773000"],["110760.00000000","0.00005000"],["110760.01000000","0.66283000"],["110761.19000000","0.00366000"],["110761.76000000","0.01785000"],["110762.01000000","0.29760000"],["110762.24000000","0.04519000"],["110762.34000000","0.01810000"],["110762.59000000","0.21647000"],["110762.83000000","0.00800000"],["110762.84000000","0.00000000"],["110762.85000000","0.00542000"],["110762.94000000","0.32466000"],["110763.48000000","0.00044000"],["110763.84000000","0.00010000"],["110764.84000000","1.36124000"],["110764.86000000","0.04017000"],["110765.19000000","0.05349000"],["110765.98000000","0.00455000"],["110766.00000000","0.04412000"],["110766.01000000","0.10673000"],["110766.62000000","0.00150000"],["110766.80000000","0.00000000"],["110766.91000000","0.00007000"],["110767.09000000","0.00000000"],["110767.12000000","0.03983000"],["110767.59000000","0.00007000"],["110768.22000000","0.03611000"],["110768.99000000","0.00000000"],["110769.37000000","0.00010000"],["110769.61000000","0.05280000"],["110770.25000000","1.21461000"],["110770.85000000","0.05760000"],["110770.86000000","0.05760000"],["110770.91000000","0.04514000"],["110771.36000000","0.00006000"],["110771.82000000","0.12240000"],["110772.20000000","0.03611000"],["110773.07000000","0.14400000"],["110773.23000000","0.01805000"],["110773.42000000","0.01805000"],["110773.48000000","0.00000000"],["110773.66000000","4.14847000"],["110774.38000000","0.00022000"],["110774.41000000","0.00000000"],["110774.56000000","0.00000000"],["110774.62000000","0.08160000"],["110774.93000000","0.00005000"],["110775.59000000","0.00000000"],["110776.15000000","0.01173000"],["110776.91000000","0.00000000"],["110777.80000000","0.00005000"],["110778.45000000","0.00000000"],["110783.08000000","0.00000000"],["110783.23000000","0.04509000"],["110783.24000000","0.00300000"],["110783.27000000","0.00000000"],["110784.85000000","1.22497000"],["110785.39000000","0.00000000"],["110785.99000000","0.00027000"],["110786.00000000","0.00000000"],["110788.58000000","0.00180000"],["110788.60000000","0.00180000"],["110788.64000000","0.49806000"],["110789.05000000","0.00089000"],["110789.90000000","0.00000000"],["110789.95000000","0.00000000"],["110791.62000000","0.00000000"],["110791.72000000","0.08000000"],["110792.13000000","0.22546000"],["110793.71000000","0.00000000"],["110794.78000000","0.00000000"],["110797.09000000","0.00000000"],["110797.61000000","0.00000000"],["110798.00000000","0.00100000"],["110798.63000000","0.03997000"],["110799.99000000","0.03997000"],["110800.00000000","0.00114000"],["110801.69000000","0.00000000"],["110802.00000000","0.00100000"],["110802.13000000","0.00000000"],["110804.00000000","0.00100000"],["110805.50000000","0.00000000"],["110806.00000000","0.00100000"],["110807.10000000","0.00000000"],["110807.76000000","0.06736000"],["110808.00000000","0.00100000"],["110810.00000000","0.00100000"],["110811.95000000","0.19758000"],["110812.00000000","0.00100000"],["110812.02000000","0.00000000"],["110813.16000000","0.00000000"],["110813.31000000","0.03538000"],["110814.00000000","0.00100000"],["110816.00000000","0.00100000"],["110818.00000000","0.00105000"],["110818.03000000","0.35345000"],["110820.00000000","0.00100000"],["110821.76000000","0.03997000"],["110822.00000000","0.00100000"],["110822.77000000","0.22793000"],["110824.00000000","0.00100000"],["110826.00000000","0.00100000"],["110827.71000000","0.26391000"],["110828.00000000","0.00100000"],["110829.12000000","0.03997000"],["110830.00000000","0.00100000"],["110830.90000000","0.13522000"],["110832.00000000","0.00100000"],["110834.00000000","0.00100000"],["110835.11000000","0.22793000"],["110835.98000000","0.00000000"],["110838.25000000","0.00000000"],["110839.31000000","0.00000000"],["110839.99000000","0.00224000"],["110846.25000000","0.00000000"],["110846.65000000","0.00000000"],["110848.12000000","0.00000000"],["110850.40000000","0.02255000"],["110850.49000000","0.00000000"],["110851.58000000","0.00000000"],["110857.00000000","0.00000000"],["110858.74000000","0.00000000"],["110860.68000000","0.00430000"],["110864.77000000","0.22546000"],["110865.37000000","0.00000000"],["110866.76000000","0.00000000"],["110867.79000000","0.00000000"],["110872.99000000","0.03997000"],["110893.70000000","0.00000000"],["110907.57000000","0.06000000"],["110911.37000000","0.02998000"],["110911.80000000","0.00000000"],["110914.40000000","0.00000000"],["110914.41000000","0.99374000"],["110917.90000000","0.03162000"],["110926.28000000","0.00000000"],["110949.72000000","0.00000000"],["110950.57000000","0.00000000"],["110957.10000000","0.02615000"],["110961.67000000","0.00000000"],["110974.35000000","0.08395000"],["110975.98000000","0.08395000"],["110976.09000000","0.00007000"],["110976.26000000","0.00010000"],["110977.83000000","0.08395000"],["110979.62000000","0.00007000"],["110979.93000000","0.08395000"],["110983.42000000","0.00000000"],["110985.97000000","0.00000000"],["110989.39000000","0.00000000"],["111000.00000000","0.00362000"],["111069.44000000","0.00000000"],["111074.98000000","0.00000000"],["111077.78000000","0.04297000"],["111120.90000000","0.02998000"],["111128.33000000","0.02998000"],["111196.27000000","0.00000000"],["112409.94000000","2.01063000"],["112462.00000000","0.00000000"],["112484.49000000","0.00000000"],["112579.33000000","0.00000000"],["128001.97000000","0.03006000"]]}
[2025-10-11T22:18:26.331Z] {"e":"depthUpdate","E":1760221106014,"s":"BTCUSDT","U":77926026511,"u":77926027134,"b":[["110750.00000000","3.37081000"],["110749.99000000","0.00090000"],["110749.40000000","0.00941000"],["110748.26000000","0.00010000"],["110748.25000000","0.05031000"],["110748.23000000","0.00000000"],["110748.22000000","0.00000000"],["110746.88000000","0.00000000"],["110746.87000000","0.00000000"],["110746.49000000","0.00000000"],["110746.41000000","0.00010000"],["110746.40000000","0.29775000"],["110746.28000000","0.03173000"],["110744.47000000","0.00000000"],["110744.46000000","0.00000000"],["110743.97000000","0.07171000"],["110743.96000000","0.00000000"],["110742.81000000","0.00000000"],["110742.30000000","0.00000000"],["110742.10000000","0.00000000"],["110741.60000000","0.00000000"],["110741.42000000","0.32472000"],["110740.33000000","0.00000000"],["110740.00000000","0.01948000"],["110739.28000000","0.00005000"],["110739.27000000","0.18043000"],["110739.26000000","0.00000000"],["110739.22000000","0.04008000"],["110738.38000000","0.32473000"],["110738.34000000","0.00000000"],["110738.28000000","0.00000000"],["110738.26000000","0.00000000"],["110737.69000000","0.00074000"],["110737.67000000","0.00000000"],["110737.12000000","0.00000000"],["110736.15000000","0.11273000"],["110736.04000000","0.00000000"],["110735.35000000","0.00000000"],["110735.30000000","0.00000000"],["110735.28000000","0.00000000"],["110735.22000000","0.01777000"],["110733.03000000","0.00069000"],["110728.96000000","0.32476000"],["110728.92000000","0.00000000"],["110728.86000000","0.00000000"],["110728.73000000","0.00000000"],["110728.51000000","0.00000000"],["110728.42000000","0.00325000"],["110725.37000000","0.00000000"],["110724.25000000","0.04800000"],["110716.78000000","0.00000000"],["110711.08000000","0.00000000"],["110708.26000000","0.00000000"],["110707.53000000","0.00000000"],["110701.55000000","0.00000000"],["110700.85000000","0.00000000"],["110700.47000000","0.04476000"],["110699.65000000","0.00000000"],["110698.46000000","0.06000000"],["110698.00000000","0.00120000"],["110696.75000000","0.00000000"],["110696.00000000","0.00120000"],["110695.76000000","0.08000000"],["110695.56000000","0.48000000"],["110694.79000000","0.11539000"],["110694.00000000","0.00120000"],["110692.00000000","0.00120000"],["110691.42000000","0.00000000"],["110690.00000000","0.00120000"],["110688.00000000","0.00120000"],["110686.00000000","0.00120000"],["110684.00000000","0.00125000"],["110683.76000000","0.00000000"],["110682.60000000","0.00000000"],["110682.00000000","0.00120000"],["110680.00000000","0.00145000"],["110678.00000000","0.00120000"],["110677.01000000","0.00000000"],["110676.00000000","0.00120000"],["110674.00000000","0.00120000"],["110672.00000000","0.00120000"],["110671.89000000","0.00000000"],["110670.00000000","0.00120000"],["110668.00000000","0.00120000"],["110666.00000000","0.00120000"],["110664.00000000","0.00120000"],["110662.42000000","0.00005000"],["110662.00000000","0.00120000"],["110660.66000000","0.00000000"],["110660.00000000","0.00231000"],["110658.00000000","0.00120000"],["110656.00000000","0.00120000"],["110654.00000000","0.00120000"],["110652.07000000","0.00000000"],["110652.00000000","1.01120000"],["110650.00000000","0.00120000"],["110649.49000000","0.00000000"],["110648.00000000","0.00120000"],["110647.09000000","0.00000000"],["110646.00000000","0.00120000"],["110644.00000000","0.00120000"],["110642.00000000","0.00120000"],["110640.66000000","0.00110000"],["110640.00000000","0.00145000"],["110638.00000000","0.00120000"],["110636.00000000","0.00127000"],["110634.00000000","0.00120000"],["110633.49000000","0.00167000"],["110633.48000000","0.00000000"],["110633.13000000","0.05680000"],["110632.00000000","0.00120000"],["110630.00000000","0.00120000"],["110628.00000000","0.00120000"],["110626.51000000","0.00000000"],["110626.00000000","0.00120000"],["110625.76000000","0.00000000"],["110625.71000000","0.09641000"],["110624.00000000","0.00120000"],["110622.00000000","0.00120000"],["110620.74000000","0.00000000"],["110620.54000000","0.00012000"],["110620.34000000","0.03400000"],["110620.29000000","0.00000000"],["110620.23000000","0.00000000"],["110620.00000000","0.00120000"],["110618.00000000","0.00120000"],["110617.00000000","0.00005000"],["110616.00000000","0.00120000"],["110615.10000000","0.22365000"],["110614.06000000","0.00000000"],["110614.00000000","0.00120000"],["110612.00000000","0.00120000"],["110610.00000000","0.00120000"],["110608.00000000","0.00120000"],["110606.00000000","0.00120000"],["110600.00000000","0.23895000"],["110594.05000000","0.02618000"],["110593.50000000","0.00000000"],["110592.03000000","0.00000000"],["110589.02000000","0.00000000"],["110575.29000000","0.02618000"],["110539.23000000","0.00000000"],["110522.49000000","0.00067000"],["110476.27000000","0.00000000"],["110459.30000000","0.00005000"],["110388.58000000","0.07395000"],["110388.25000000","0.07395000"],["110386.97000000","0.07395000"],["110385.70000000","0.07395000"],["110384.44000000","0.07395000"],["110382.56000000","0.07395000"],["110382.02000000","0.07395000"],["110381.58000000","0.07395000"],["110379.48000000","0.07395000"],["110378.60000000","0.07395000"],["110349.33000000","0.00000000"],["110324.86000000","0.00333000"],["110183.51000000","0.00000000"],["110183.11000000","0.00000000"],["110182.64000000","0.00000000"],["110085.50000000","0.00019000"],["109964.08000000","0.00036000"],["109320.72000000","0.00000000"],["109106.30000000","0.00430000"],["106179.89000000","0.00185000"],["105378.62000000","0.00058000"],["99675.00000000","0.04016000"],["88600.00000000","3.24442000"],["39870.00000000","0.00048000"]],"a":[["110750.01000000","10.93425000"],["110750.34000000","0.03621000"],["110751.15000000","0.00000000"],["110751.16000000","0.00000000"],["110751.25000000","0.11051000"],["110751.26000000","0.00005000"],["110753.00000000","0.00010000"],["110753.24000000","0.00000000"],["110753.29000000","0.00000000"],["110753.30000000","0.00000000"],["110753.42000000","0.00000000"],["110753.43000000","0.00000000"],["110753.96000000","0.00000000"],["110755.36000000","0.00000000"],["110755.52000000","0.00000000"],["110755.53000000","0.00000000"],["110757.70000000","0.32482000"],["110758.96000000","0.53544000"],["110758.98000000","0.52110000"],["110759.27000000","0.04012000"],["110760.01000000","0.60867000"],["110761.18000000","0.30441000"],["110761.76000000","0.01785000"],["110762.94000000","0.00000000"],["110763.88000000","0.03611000"],["110764.85000000","0.00005000"],["110765.56000000","0.32465000"],["110767.12000000","0.03978000"],["110767.22000000","0.45986000"],["110767.84000000","0.01810000"],["110773.23000000","0.00000000"],["110779.32000000","0.00000000"],["110783.23000000","0.00000000"],["110784.81000000","0.00000000"],["110786.61000000","0.00077000"],["110789.05000000","0.00000000"],["110796.53000000","0.13522000"],["110800.39000000","0.03538000"],["110811.23000000","0.04480000"],["110813.31000000","0.00000000"],["110818.00000000","0.00100000"],["110820.00000000","0.00120000"],["110822.00000000","0.00120000"],["110822.77000000","0.31713000"],["110824.00000000","0.00120000"],["110826.00000000","0.00120000"],["110828.00000000","0.00120000"],["110828.23000000","0.25824000"],["110828.51000000","0.00000000"],["110830.00000000","0.00120000"],["110830.90000000","0.00000000"],["110832.00000000","0.00120000"],["110834.00000000","0.00120000"],["110836.00000000","0.00120000"],["110838.00000000","0.00120000"],["110840.00000000","0.00125000"],["110842.00000000","0.00120000"],["110842.55000000","0.02483000"],["110844.00000000","0.00120000"],["110846.00000000","0.00120000"],["110846.25000000","0.54445000"],["110848.00000000","0.00120000"],["110850.00000000","0.00120000"],["110852.00000000","0.00120000"],["110854.00000000","0.00120000"],["110857.10000000","0.24756000"],["110862.47000000","0.00331000"],["110863.20000000","0.00000000"],["110863.76000000","0.26770000"],["110865.37000000","0.08160000"],["110867.79000000","0.63338000"],["110887.06000000","0.00000000"],["110901.34000000","0.13491000"],["110914.40000000","0.35576000"],["110917.15000000","0.19053000"],["110917.46000000","0.08395000"],["110919.53000000","0.08395000"],["110923.98000000","0.08395000"],["110926.27000000","0.00000000"],["110931.80000000","0.02710000"],["110970.03000000","0.09894000"],["110973.99000000","0.00000000"],["110975.99000000","0.00000000"],["111002.00000000","0.00012000"],["111004.00000000","0.00012000"],["111006.00000000","0.00012000"],["111008.00000000","0.00012000"],["111010.00000000","0.00012000"],["111012.00000000","0.00012000"],["111014.00000000","0.00012000"],["111016.00000000","0.00012000"],["111018.00000000","0.00012000"],["111020.00000000","0.00012000"],["111022.00000000","0.00012000"],["111024.00000000","0.00012000"],["111026.00000000","0.00012000"],["111028.00000000","0.00012000"],["111030.00000000","0.00012000"],["111032.00000000","0.00012000"],["111034.00000000","0.00012000"],["111036.00000000","0.00012000"],["111038.00000000","0.00012000"],["111040.00000000","0.00017000"],["111040.50000000","0.02618000"],["111042.00000000","0.00012000"],["111044.00000000","0.00012000"],["111046.00000000","0.00012000"],["111048.00000000","0.00012000"],["111050.00000000","0.01039000"],["111052.00000000","0.00012000"],["111054.00000000","0.00012000"],["111056.00000000","0.08506000"],["111058.00000000","0.00012000"],["111060.00000000","0.00125000"],["111062.00000000","0.00012000"],["111064.00000000","0.00012000"],["111064.93000000","0.07575000"],["111066.00000000","0.00012000"],["111068.00000000","0.00012000"],["111070.00000000","0.00012000"],["111072.00000000","0.00012000"],["111074.00000000","0.00012000"],["111076.00000000","0.00012000"],["111078.00000000","0.00012000"],["111080.00000000","0.00081000"],["111082.00000000","0.00012000"],["111084.00000000","0.00012000"],["111086.00000000","0.00012000"],["111088.00000000","0.00018000"],["111090.00000000","0.10012000"],["111092.00000000","0.00012000"],["111094.00000000","0.00012000"],["111096.00000000","0.00012000"],["111098.00000000","0.00012000"],["111100.00000000","0.18931000"],["111114.32000000","0.00000000"],["111136.16000000","0.00082000"],["111160.77000000","0.00000000"],["111210.04000000","0.00000000"],["111228.08000000","0.00000000"],["111311.77000000","0.00000000"],["111342.92000000","0.00046000"],["111354.00000000","0.00000000"],["112399.00000000","0.00429000"],["112620.51000000","0.00000000"],["128001.97000000","0.03006000"]]}
[2025-10-11T22:18:27.330Z] {"e":"depthUpdate","E":1760221107014,"s":"BTCUSDT","U":77926027135,"u":77926027654,"b":[["110750.00000000","3.58869000"],["110749.99000000","0.00055000"],["110749.63000000","0.00010000"],["110749.62000000","0.01364000"],["110749.40000000","0.00941000"],["110748.96000000","0.00010000"],["110748.95000000","0.00020000"],["110748.94000000","0.00010000"],["110748.25000000","0.00010000"],["110746.42000000","0.00000000"],["110746.41000000","0.00000000"],["110746.40000000","0.00000000"],["110746.28000000","0.03168000"],["110745.82000000","0.29765000"],["110744.19000000","0.00000000"],["110744.18000000","0.00005000"],["110744.17000000","0.00005000"],["110743.98000000","0.00000000"],["110743.97000000","0.00000000"],["110743.91000000","0.01806000"],["110741.43000000","0.00000000"],["110741.42000000","0.00000000"],["110740.33000000","0.00000000"],["110740.00000000","0.01943000"],["110739.28000000","0.00000000"],["110739.27000000","0.18038000"],["110739.22000000","0.00000000"],["110737.09000000","0.00000000"],["110737.08000000","0.02710000"],["110735.22000000","0.00000000"],["110733.30000000","0.33669000"],["110732.51000000","0.32474000"],["110730.80000000","0.20212000"],["110728.96000000","0.00000000"],["110728.90000000","0.00000000"],["110728.89000000","0.32476000"],["110726.77000000","0.36267000"],["110724.67000000","0.00000000"],["110722.06000000","0.00000000"],["110712.01000000","0.15790000"],["110681.07000000","0.06814000"],["110671.72000000","0.00005000"],["110652.07000000","0.04800000"],["110640.61000000","0.03277000"],["110635.02000000","0.00000000"],["110620.34000000","0.00000000"],["110604.00000000","0.00120000"],["110603.06000000","0.08405000"],["110602.00000000","0.00120000"],["110600.00000000","0.23915000"],["110599.97000000","0.08395000"],["110597.26000000","0.08395000"],["110595.75000000","0.08395000"],["110593.52000000","0.08395000"],["110554.26000000","0.00019000"],["110536.47000000","0.08395000"],["110535.36000000","0.08395000"],["110533.47000000","0.08395000"],["110531.25000000","0.08410000"],["110529.43000000","0.08395000"],["110527.35000000","0.08395000"],["110525.88000000","0.08395000"],["110513.01000000","0.00588000"],["110451.57000000","0.00005000"],["110450.00000000","0.00190000"],["110408.64000000","0.00000000"],["110386.92000000","0.07395000"],["110386.38000000","0.07395000"],["110385.28000000","0.07395000"],["110383.66000000","0.07395000"],["110382.54000000","0.07395000"],["110380.83000000","0.07395000"],["110380.36000000","0.07395000"],["110379.84000000","0.07395000"],["110085.50000000","0.00019000"],["106179.89000000","0.00005000"],["105424.03000000","0.00000000"],["99675.00000000","0.04016000"],["88600.00000000","3.24442000"],["33000.00000000","3.75190000"]],"a":[["110750.01000000","10.71201000"],["110750.02000000","0.00015000"],["110750.17000000","0.00908000"],["110750.32000000","0.00010000"],["110750.33000000","0.10653000"],["110750.34000000","0.00000000"],["110750.38000000","0.00010000"],["110750.39000000","0.01374000"],["110751.24000000","0.00000000"],["110751.25000000","0.00000000"],["110751.26000000","0.00000000"],["110751.74000000","0.00000000"],["110752.57000000","0.06646000"],["110752.93000000","0.00010000"],["110752.94000000","0.00010000"],["110753.00000000","0.00000000"],["110753.40000000","0.00010000"],["110753.62000000","0.00000000"],["110753.96000000","0.00005000"],["110754.46000000","0.01810000"],["110755.45000000","0.32468000"],["110755.60000000","0.00000000"],["110755.61000000","0.00000000"],["110757.70000000","0.00005000"],["110757.91000000","0.00000000"],["110757.92000000","0.32472000"],["110758.95000000","0.00000000"],["110758.96000000","0.32646000"],["110758.97000000","0.00000000"],["110758.98000000","0.52110000"],["110759.27000000","0.00000000"],["110760.01000000","0.56855000"],["110761.18000000","0.00000000"],["110761.76000000","0.01785000"],["110762.01000000","0.29760000"],["110762.24000000","0.04519000"],["110763.86000000","0.30441000"],["110763.88000000","0.03616000"],["110764.02000000","0.00000000"],["110765.56000000","0.00000000"],["110765.62000000","0.00000000"],["110766.62000000","0.00150000"],["110767.12000000","0.03973000"],["110767.22000000","0.32464000"],["110767.46000000","0.00000000"],["110767.84000000","0.01805000"],["110768.22000000","0.03611000"],["110771.18000000","0.00000000"],["110781.60000000","0.18052000"],["110784.28000000","0.00076000"],["110786.61000000","0.00000000"],["110788.24000000","0.00000000"],["110793.95000000","0.00000000"],["110796.53000000","0.13522000"],["110800.39000000","0.00000000"],["110807.16000000","0.03538000"],["110818.00000000","0.00105000"],["110827.64000000","0.00000000"],["110832.23000000","0.00000000"],["110832.24000000","0.00000000"],["110833.23000000","0.00100000"],["110835.90000000","0.00000000"],["110839.31000000","0.20604000"],["110850.59000000","0.08689000"],["110877.24000000","0.00000000"],["110877.25000000","0.00000000"],["110899.65000000","0.06000000"],["110940.71000000","0.00000000"],["110985.97000000","0.00000000"],["111127.83000000","0.02998000"],["111143.47000000","0.00000000"],["125360.00000000","0.00898000"],["125740.00000000","0.00512000"],["126120.00000000","0.00286000"],["128001.97000000","0.00040000"]]}
[2025-10-11T22:18:28.333Z] {"e":"depthUpdate","E":1760221108014,"s":"BTCUSDT","U":77926027655,"u":77926030368,"b":[["110750.00000000","0.00000000"],["110749.99000000","0.00000000"],["110749.92000000","0.00000000"],["110749.63000000","0.00000000"],["110749.62000000","0.00000000"],["110749.40000000","0.00000000"],["110748.96000000","0.00000000"],["110748.95000000","0.00000000"],["110748.94000000","0.00000000"],["110748.26000000","0.00000000"],["110748.25000000","0.00000000"],["110748.00000000","0.00000000"],["110747.99000000","0.00000000"],["110747.96000000","0.00000000"],["110747.95000000","0.00000000"],["110746.50000000","0.00000000"],["110746.29000000","0.00000000"],["110746.28000000","0.00000000"],["110746.00000000","0.00000000"],["110745.84000000","0.00000000"],["110745.83000000","0.00000000"],["110745.82000000","0.00000000"],["110745.57000000","0.00000000"],["110745.11000000","0.00000000"],["110745.10000000","0.00000000"],["110745.05000000","0.00000000"],["110744.18000000","0.00000000"],["110744.17000000","0.00000000"],["110744.14000000","0.00000000"],["110744.00000000","0.00000000"],["110743.92000000","0.00000000"],["110743.91000000","0.00000000"],["110743.90000000","0.00000000"],["110743.12000000","0.00000000"],["110743.01000000","0.00000000"],["110742.95000000","0.00000000"],["110742.57000000","0.00000000"],["110742.51000000","0.00000000"],["110742.36000000","0.00000000"],["110742.28000000","0.00000000"],["110742.00000000","0.00000000"],["110741.71000000","0.00000000"],["110741.04000000","0.00000000"],["110740.96000000","0.00000000"],["110740.95000000","0.00000000"],["110740.94000000","0.00000000"],["110740.55000000","0.00000000"],["110740.44000000","0.00000000"],["110740.19000000","0.00180000"],["110740.18000000","0.00070000"],["110740.01000000","0.00010000"],["110740.00000000","0.01948000"],["110739.91000000","0.00000000"],["110739.28000000","0.00000000"],["110739.27000000","0.00000000"],["110739.15000000","0.00000000"],["110738.93000000","0.00000000"],["110738.92000000","0.00000000"],["110738.39000000","0.00000000"],["110738.38000000","0.00000000"],["110738.08000000","0.00000000"],["110738.04000000","0.00000000"],["110737.69000000","0.00000000"],["110737.30000000","0.00000000"],["110737.15000000","0.00000000"],["110737.08000000","0.00000000"],["110737.01000000","0.00000000"],["110736.99000000","0.00000000"],["110736.98000000","0.00000000"],["110736.81000000","0.00000000"],["110736.64000000","0.00000000"],["110736.63000000","0.00000000"],["110736.26000000","0.00000000"],["110736.19000000","0.00000000"],["110736.15000000","0.00000000"],["110736.14000000","0.00152000"],["110735.61000000","0.00010000"],["110735.60000000","0.00000000"],["110735.43000000","0.00000000"],["110735.36000000","0.00000000"],["110735.35000000","0.00000000"],["110735.34000000","0.00000000"],["110735.24000000","0.00000000"],["110735.08000000","0.00000000"],["110734.97000000","0.00000000"],["110734.75000000","0.00000000"],["110734.58000000","0.00000000"],["110734.37000000","0.00000000"],["110733.48000000","0.00000000"],["110733.47000000","0.00000000"],["110733.44000000","0.00000000"],["110733.38000000","0.00000000"],["110733.30000000","0.00000000"],["110733.29000000","0.00000000"],["110733.11000000","0.00000000"],["110733.03000000","0.00000000"],["110733.00000000","0.00000000"],["110732.99000000","0.00000000"],["110732.98000000","0.00000000"],["110732.93000000","0.00000000"],["110732.76000000","0.00000000"],["110732.51000000","0.00000000"],["110732.41000000","0.05519000"],["110732.19000000","0.00074000"],["110732.08000000","0.00000000"],["110732.07000000","0.00000000"],["110731.88000000","0.00000000"],["110731.53000000","0.00000000"],["110731.49000000","0.00010000"],["110731.28000000","0.00000000"],["110731.03000000","0.00000000"],["110731.01000000","0.00000000"],["110730.80000000","0.00000000"],["110730.79000000","0.00000000"],["110730.20000000","0.00000000"],["110729.82000000","0.00000000"],["110729.51000000","0.10913000"],["110729.22000000","0.00000000"],["110728.89000000","0.00000000"],["110728.82000000","0.00000000"],["110728.79000000","0.00000000"],["110728.67000000","0.00046000"],["110728.50000000","0.00149000"],["110728.49000000","0.00000000"],["110728.43000000","0.00000000"],["110728.42000000","0.00000000"],["110728.32000000","0.00005000"],["110728.27000000","0.00000000"],["110727.99000000","0.00000000"],["110727.84000000","0.00000000"],["110727.59000000","0.00000000"],["110727.56000000","0.00000000"],["110727.45000000","0.00000000"],["110726.92000000","0.00000000"],["110726.77000000","0.00000000"],["110726.75000000","0.00000000"],["110725.92000000","0.00000000"],["110725.83000000","0.00000000"],["110725.82000000","0.00000000"],["110725.77000000","0.00010000"],["110725.76000000","0.38195000"],["110725.75000000","0.18040000"],["110725.74000000","0.00300000"],["110725.63000000","0.00000000"],["110724.79000000","0.00000000"],["110724.52000000","0.00000000"],["110724.43000000","0.00000000"],["110724.39000000","0.00000000"],["110724.38000000","0.00000000"],["110724.25000000","0.00000000"],["110724.24000000","0.00000000"],["110724.22000000","0.29770000"],["110723.91000000","0.00000000"],["110723.41000000","0.00000000"],["110723.35000000","0.00000000"],["110722.72000000","0.00000000"],["110722.71000000","0.00000000"],["110722.55000000","0.00000000"],["110722.46000000","0.00000000"],["110722.41000000","0.00000000"],["110722.18000000","0.00000000"],["110720.81000000","0.00000000"],["110720.79000000","0.28429000"],["110720.57000000","0.00000000"],["110720.34000000","0.00000000"],["110720.13000000","0.00000000"],["110719.74000000","0.00000000"],["110719.55000000","0.00022000"],["110719.42000000","0.32478000"],["110718.84000000","0.00072000"],["110718.43000000","0.00000000"],["110718.42000000","0.00000000"],["110717.73000000","0.00000000"],["110717.68000000","0.00070000"],["110717.64000000","0.00000000"],["110717.51000000","0.00000000"],["110717.42000000","0.11273000"],["110717.23000000","0.00000000"],["110717.22000000","0.00000000"],["110716.91000000","0.41189000"],["110716.78000000","0.04508000"],["110716.49000000","0.04800000"],["110716.27000000","0.00000000"],["110715.54000000","0.00000000"],["110715.27000000","0.00005000"],["110714.76000000","0.32480000"],["110714.56000000","0.00000000"],["110714.55000000","0.00000000"],["110714.54000000","0.00000000"],["110714.15000000","0.18026000"],["110714.13000000","0.00000000"],["110712.60000000","0.00330000"],["110712.01000000","0.00000000"],["110711.88000000","0.00300000"],["110711.36000000","0.00000000"],["110711.35000000","0.27004000"],["110710.88000000","0.00000000"],["110710.68000000","0.00000000"],["110710.63000000","0.00000000"],["110710.34000000","0.00000000"],["110710.28000000","0.08567000"],["110710.01000000","0.00000000"],["110709.29000000","0.00937000"],["110708.01000000","0.00000000"],["110707.69000000","0.03163000"],["110707.55000000","0.20217000"],["110707.48000000","0.00000000"],["110706.97000000","0.00009000"],["110706.76000000","0.00000000"],["110705.67000000","0.00000000"],["110705.53000000","0.00000000"],["110705.21000000","0.00000000"],["110705.20000000","0.00000000"],["110704.42000000","0.24958000"],["110703.79000000","0.04810000"],["110703.60000000","0.00000000"],["110703.43000000","0.00450000"],["110703.38000000","0.02141000"],["110702.09000000","0.00000000"],["110701.08000000","0.00000000"],["110701.05000000","0.05070000"],["110700.61000000","0.00000000"],["110700.27000000","0.08567000"],["110700.20000000","0.25211000"],["110700.14000000","0.11556000"],["110699.01000000","0.07798000"],["110698.46000000","0.00000000"],["110697.82000000","0.00000000"],["110697.38000000","0.08567000"],["110696.70000000","0.04800000"],["110696.01000000","0.02437000"],["110695.76000000","0.00000000"],["110695.56000000","0.00000000"],["110694.86000000","0.00000000"],["110694.79000000","0.09644000"],["110694.68000000","0.13527000"],["110694.26000000","1.49834000"],["110693.66000000","0.00000000"],["110692.51000000","0.00000000"],["110692.36000000","0.00000000"],["110692.22000000","0.22546000"],["110692.01000000","0.00000000"],["110691.96000000","0.00005000"],["110691.95000000","0.00012000"],["110691.66000000","0.00000000"],["110691.27000000","0.22546000"],["110690.26000000","0.00000000"],["110689.56000000","0.00000000"],["110689.52000000","0.04000000"],["110688.97000000","0.00000000"],["110688.06000000","0.03882000"],["110687.86000000","0.00000000"],["110687.70000000","0.00000000"],["110687.68000000","0.00000000"],["110686.46000000","0.00000000"],["110686.38000000","0.00000000"],["110686.36000000","0.00000000"],["110686.04000000","0.00000000"],["110685.90000000","0.00005000"],["110685.42000000","0.18031000"],["110685.33000000","0.01713000"],["110685.20000000","0.08567000"],["110685.11000000","0.00000000"],["110684.15000000","0.00000000"],["110681.76000000","0.30000000"],["110681.26000000","0.00000000"],["110681.07000000","0.00000000"],["110681.01000000","0.00005000"],["110680.07000000","0.00000000"],["110679.90000000","0.06061000"],["110679.72000000","0.00142000"],["110679.23000000","0.00000000"],["110678.47000000","0.00000000"],["110678.26000000","0.32000000"],["110678.22000000","0.00000000"],["110677.67000000","0.00000000"],["110676.73000000","0.00000000"],["110676.09000000","0.00000000"],["110675.56000000","0.00000000"],["110675.09000000","0.00000000"],["110674.47000000","0.00000000"],["110674.31000000","0.00000000"],["110674.11000000","0.00000000"],["110673.93000000","0.00000000"],["110673.75000000","0.00009000"],["110673.51000000","0.02998000"],["110673.30000000","0.00000000"],["110673.15000000","0.00000000"],["110673.01000000","0.01896000"],["110673.00000000","0.00000000"],["110672.75000000","0.00000000"],["110672.47000000","0.00000000"],["110672.01000000","0.01896000"],["110671.90000000","0.13522000"],["110670.14000000","0.00000000"],["110668.12000000","0.00000000"],["110667.79000000","0.00000000"],["110666.99000000","0.00000000"],["110666.90000000","0.03005000"],["110666.89000000","0.00000000"],["110665.40000000","0.00000000"],["110664.99000000","0.00000000"],["110664.78000000","0.06804000"],["110663.71000000","0.00000000"],["110663.51000000","0.18036000"],["110662.50000000","0.00667000"],["110661.28000000","0.00000000"],["110661.07000000","0.00000000"],["110660.58000000","0.00000000"],["110660.06000000","0.00000000"],["110660.01000000","0.00000000"],["110659.29000000","0.00000000"],["110658.62000000","0.01625000"],["110657.58000000","0.00000000"],["110656.86000000","0.18026000"],["110656.43000000","0.00615000"],["110655.51000000","0.00000000"],["110654.45000000","0.45036000"],["110654.12000000","0.00000000"],["110653.13000000","0.00005000"],["110652.98000000","0.02403000"],["110652.96000000","0.00000000"],["110651.82000000","0.00000000"],["110650.63000000","0.04800000"],["110650.33000000","0.00000000"],["110650.03000000","0.00000000"],["110649.63000000","0.00000000"],["110649.60000000","0.00000000"],["110648.65000000","0.00000000"],["110648.32000000","0.04800000"],["110648.31000000","0.00000000"],["110648.30000000","0.00000000"],["110647.97000000","0.00000000"],["110647.79000000","0.00225000"],["110647.59000000","0.00000000"],["110647.44000000","0.00000000"],["110647.02000000","0.00000000"],["110646.62000000","0.04800000"],["110646.36000000","0.00000000"],["110644.61000000","1.04339000"],["110644.60000000","0.00000000"],["110644.37000000","0.02198000"],["110643.80000000","0.04805000"],["110643.55000000","0.04800000"],["110643.52000000","0.00000000"],["110642.98000000","0.04217000"],["110641.76000000","0.00000000"],["110641.67000000","0.00000000"],["110641.23000000","0.04800000"],["110641.13000000","3.24539000"],["110640.61000000","0.00000000"],["110640.52000000","0.00009000"],["110640.01000000","0.01625000"],["110639.25000000","0.01569000"],["110638.99000000","0.00000000"],["110638.85000000","0.01367000"],["110638.00000000","0.01745000"],["110637.43000000","0.13527000"],["110635.96000000","0.00000000"],["110634.82000000","0.00000000"],["110634.48000000","3.24539000"],["110634.42000000","0.02341000"],["110634.21000000","0.01412000"],["110633.49000000","0.00000000"],["110633.48000000","0.00000000"],["110633.47000000","0.00000000"],["110632.75000000","0.00000000"],["110632.66000000","0.13527000"],["110632.39000000","0.03277000"],["110630.95000000","0.00000000"],["110630.62000000","0.00000000"],["110630.08000000","0.00000000"],["110630.00000000","0.00209000"],["110628.36000000","0.02479000"],["110628.02000000","0.00167000"],["110628.01000000","0.04297000"],["110627.07000000","0.04045000"],["110626.49000000","0.00000000"],["110626.06000000","0.00000000"],["110625.66000000","0.00000000"],["110624.96000000","0.00007000"],["110623.10000000","0.03742000"],["110622.29000000","0.00000000"],["110621.61000000","0.00000000"],["110620.03000000","0.00000000"],["110614.69000000","0.22546000"],["110612.93000000","0.00000000"],["110611.30000000","0.00000000"],["110610.79000000","0.00000000"],["110610.11000000","0.00000000"],["110609.83000000","0.00000000"],["110608.73000000","0.00000000"],["110608.16000000","0.00000000"],["110607.30000000","0.00009000"],["110606.59000000","0.00000000"],["110599.66000000","0.00015000"],["110599.59000000","0.00000000"],["110597.66000000","0.00000000"],["110597.27000000","0.00160000"],["110593.53000000","0.24364000"],["110593.51000000","0.08539000"],["110592.83000000","0.00000000"],["110591.69000000","0.00000000"],["110591.23000000","0.00000000"],["110590.48000000","0.00000000"],["110590.24000000","0.00000000"],["110589.17000000","0.00000000"],["110588.46000000","0.00000000"],["110586.97000000","0.00000000"],["110585.32000000","0.00000000"],["110585.17000000","0.00000000"],["110585.09000000","0.00000000"],["110584.53000000","0.00000000"],["110583.28000000","0.00000000"],["110582.72000000","0.00000000"],["110582.43000000","0.99120000"],["110582.42000000","0.00000000"],["110582.03000000","0.00000000"],["110581.64000000","0.04297000"],["110581.52000000","0.00000000"],["110581.50000000","0.00000000"],["110581.04000000","0.00000000"],["110580.24000000","0.00000000"],["110579.29000000","0.00000000"],["110576.99000000","0.00000000"],["110574.74000000","0.16065000"],["110574.08000000","0.00009000"],["110573.22000000","0.00000000"],["110572.03000000","0.00000000"],["110569.62000000","0.00000000"],["110566.86000000","0.04297000"],["110566.81000000","0.05430000"],["110564.44000000","0.00000000"],["110558.70000000","0.02998000"],["110553.63000000","0.04297000"],["110551.70000000","0.01896000"],["110550.18000000","0.01086000"],["110549.96000000","0.04297000"],["110547.27000000","0.04297000"],["110546.50000000","0.02998000"],["110544.87000000","0.04297000"],["110540.47000000","0.04297000"],["110536.96000000","0.00000000"],["110536.64000000","0.00000000"],["110536.29000000","0.00007000"],["110533.07000000","0.04297000"],["110522.49000000","0.00000000"],["110522.48000000","0.00000000"],["110520.79000000","0.00000000"],["110520.39000000","0.00000000"],["110519.99000000","0.00000000"],["110519.64000000","0.00000000"],["110519.30000000","0.00000000"],["110518.35000000","0.00000000"],["110518.34000000","0.00000000"],["110517.30000000","0.00067000"],["110508.29000000","0.02998000"],["110504.09000000","0.00000000"],["110492.16000000","0.00000000"],["110486.79000000","0.00000000"],["110485.42000000","0.00064000"],["110481.72000000","0.00000000"],["110475.96000000","0.00000000"],["110475.78000000","0.00000000"],["110473.85000000","0.00000000"],["110472.85000000","0.90420000"],["110469.23000000","0.00000000"],["110453.47000000","0.00000000"],["110452.99000000","0.00000000"],["110452.80000000","0.00000000"],["110452.62000000","0.00000000"],["110449.44000000","0.00000000"],["110448.95000000","0.00000000"],["110446.96000000","0.00000000"],["110445.89000000","0.00000000"],["110444.26000000","0.00000000"],["110442.08000000","0.00000000"],["110441.18000000","0.00000000"],["110440.64000000","0.00000000"],["110439.02000000","0.00000000"],["110438.81000000","0.00000000"],["110438.26000000","0.00000000"],["110438.08000000","0.05430000"],["110437.89000000","0.00000000"],["110437.31000000","0.00000000"],["110436.57000000","0.00000000"],["110435.33000000","0.00000000"],["110435.10000000","0.00000000"],["110434.30000000","0.00000000"],["110434.26000000","0.00000000"],["110433.33000000","0.03791000"],["110433.12000000","0.00000000"],["110432.85000000","0.00000000"],["110432.84000000","0.00000000"],["110432.81000000","0.00000000"],["110432.71000000","0.00000000"],["110431.22000000","0.00000000"],["110431.05000000","0.00010000"],["110431.04000000","0.00000000"],["110429.60000000","0.00000000"],["110429.14000000","0.00000000"],["110428.97000000","0.00000000"],["110428.95000000","0.00000000"],["110428.73000000","0.00000000"],["110428.72000000","0.00000000"],["110428.17000000","0.00000000"],["110428.06000000","0.00000000"],["110428.00000000","0.00000000"],["110427.97000000","0.00000000"],["110427.73000000","0.00000000"],["110427.16000000","0.00000000"],["110425.56000000","0.00000000"],["110424.88000000","0.02437000"],["110424.67000000","0.00000000"],["110424.18000000","0.00000000"],["110423.79000000","0.00000000"],["110422.81000000","0.00000000"],["110422.26000000","0.00000000"],["110419.83000000","0.02437000"],["110418.47000000","0.00000000"],["110412.20000000","0.06319000"],["110409.91000000","0.00000000"],["110409.77000000","0.00010000"],["110409.09000000","0.03882000"],["110408.81000000","0.03882000"],["110408.32000000","0.03882000"],["110408.02000000","0.03882000"],["110404.99000000","0.03882000"],["110404.25000000","0.04373000"],["110404.24000000","0.00000000"],["110403.18000000","0.03882000"],["110402.47000000","0.03882000"],["110401.45000000","0.03882000"],["110400.73000000","0.04297000"],["110399.92000000","0.02437000"],["110399.52000000","0.04297000"],["110399.43000000","0.03882000"],["110399.06000000","0.03882000"],["110398.88000000","0.03882000"],["110398.70000000","0.03882000"],["110398.46000000","0.03882000"],["110397.73000000","0.03882000"],["110397.22000000","0.04297000"],["110395.94000000","0.03882000"],["110394.88000000","0.00000000"],["110394.80000000","0.03882000"],["110394.79000000","0.03882000"],["110394.74000000","0.03882000"],["110392.21000000","0.00000000"],["110388.98000000","0.00000000"],["110378.15000000","0.00000000"],["110377.51000000","0.00000000"],["110376.95000000","0.00000000"],["110375.85000000","0.00000000"],["110373.60000000","0.07395000"],["110371.95000000","0.07395000"],["110370.12000000","0.07395000"],["110369.38000000","0.07395000"],["110369.07000000","0.22213000"],["110368.48000000","0.07395000"],["110367.56000000","0.07395000"],["110366.19000000","0.07395000"],["110364.85000000","0.00000000"],["110363.95000000","0.07395000"],["110363.50000000","0.00000000"],["110360.53000000","0.00000000"],["110357.92000000","0.00000000"],["110337.28000000","0.00000000"],["110325.59000000","0.00000000"],["110324.86000000","0.00000000"],["110320.60000000","0.00000000"],["110319.15000000","0.00333000"],["110313.78000000","0.00000000"],["110309.30000000","0.00000000"],["110306.73000000","0.00000000"],["110302.03000000","0.00494000"],["110298.19000000","0.00000000"],["110291.14000000","0.02437000"],["110286.96000000","0.02437000"],["110279.45000000","0.02437000"],["110276.28000000","0.02437000"],["110274.10000000","0.02437000"],["110269.34000000","0.45000000"],["110188.98000000","0.00005000"],["110182.31000000","0.00000000"],["110182.17000000","0.00000000"],["110133.36000000","0.00000000"],["110085.50000000","0.00000000"],["109985.29000000","0.40724000"],["109799.24000000","0.00000000"],["109563.64000000","0.32821000"],["99675.00000000","0.04006000"],["99673.00000000","0.00000000"],["99670.00000000","0.00243000"],["88600.00000000","3.24420000"],["88592.16000000","0.00022000"],["80000.00000000","44.72245000"],["39869.28000000","0.00096000"]],"a":[["110740.20000000","16.76074000"],["110740.29000000","0.00000000"],["110740.36000000","0.62650000"],["110740.38000000","0.01806000"],["110740.39000000","1.56246000"],["110740.44000000","0.00005000"],["110740.45000000","0.00000000"],["110742.52000000","0.00000000"],["110742.58000000","0.00000000"],["110742.96000000","0.00000000"],["110743.89000000","0.32471000"],["110743.91000000","5.56054000"],["110743.92000000","0.48403000"],["110744.00000000","0.00010000"],["110745.11000000","5.87872000"],["110745.12000000","0.78223000"],["110745.20000000","0.00000000"],["110745.58000000","0.00000000"],["110746.01000000","0.00000000"],["110746.19000000","0.00005000"],["110746.27000000","0.00000000"],["110746.28000000","0.45041000"],["110746.29000000","0.00000000"],["110746.50000000","0.00005000"],["110747.05000000","0.03621000"],["110747.53000000","0.00005000"],["110747.58000000","0.00005000"],["110747.98000000","0.00000000"],["110748.00000000","0.18031000"],["110748.01000000","0.33781000"],["110748.09000000","0.00000000"],["110748.93000000","0.00000000"],["110748.94000000","0.00000000"],["110748.95000000","0.00000000"],["110748.96000000","0.27071000"],["110749.31000000","0.00000000"],["110749.38000000","0.00000000"],["110749.40000000","0.29764000"],["110749.41000000","0.04017000"],["110749.63000000","0.00000000"],["110749.92000000","0.03611000"],["110749.98000000","0.00000000"],["110750.00000000","0.00000000"],["110750.01000000","0.14471000"],["110750.02000000","0.00000000"],["110750.04000000","0.04514000"],["110750.09000000","0.00000000"],["110750.17000000","0.00908000"],["110750.26000000","0.03611000"],["110750.32000000","0.00000000"],["110750.33000000","0.00010000"],["110750.34000000","0.03611000"],["110750.38000000","0.00000000"],["110750.39000000","0.01369000"],["110750.65000000","0.11273000"],["110750.66000000","0.00000000"],["110750.74000000","0.00005000"],["110750.97000000","0.03611000"],["110751.12000000","0.04081000"],["110751.27000000","0.00043000"],["110751.42000000","0.03611000"],["110751.80000000","3.24539000"],["110752.12000000","0.00000000"],["110752.57000000","0.06651000"],["110752.85000000","0.00000000"],["110752.90000000","0.00044000"],["110752.93000000","1.23250000"],["110752.94000000","0.04519000"],["110752.97000000","0.00000000"],["110753.11000000","0.04514000"],["110753.40000000","0.00000000"],["110753.81000000","0.00000000"],["110753.96000000","0.00000000"],["110754.03000000","0.00010000"],["110754.46000000","0.00005000"],["110754.50000000","0.00410000"],["110754.82000000","0.18026000"],["110754.91000000","0.04605000"],["110755.35000000","3.24539000"],["110755.45000000","0.00000000"],["110755.60000000","0.01810000"],["110756.19000000","0.00046000"],["110756.20000000","0.00300000"],["110756.35000000","0.01805000"],["110756.50000000","0.00007000"],["110756.73000000","0.00000000"],["110756.99000000","0.00000000"],["110757.20000000","0.00007000"],["110757.39000000","0.00044000"],["110757.91000000","1.42570000"],["110757.92000000","0.00000000"],["110758.16000000","0.08567000"],["110758.34000000","0.18026000"],["110758.78000000","0.13527000"],["110758.81000000","0.08567000"],["110758.95000000","0.00010000"],["110758.96000000","0.00000000"],["110758.98000000","0.27304000"],["110759.00000000","0.00000000"],["110759.09000000","0.45000000"],["110759.26000000","0.00000000"],["110759.67000000","0.00183000"],["110759.69000000","3.24539000"],["110760.00000000","0.00011000"],["110760.01000000","0.52347000"],["110760.82000000","0.00000000"],["110760.90000000","0.00902000"],["110761.09000000","0.00000000"],["110761.19000000","0.00361000"],["110762.01000000","0.00000000"],["110762.02000000","0.00000000"],["110762.24000000","0.00000000"],["110762.34000000","0.00000000"],["110762.59000000","0.18026000"],["110762.83000000","0.00000000"],["110762.99000000","0.06240000"],["110763.03000000","2.06106000"],["110763.04000000","3.24539000"],["110763.19000000","0.00000000"],["110763.48000000","0.00000000"],["110763.56000000","0.00044000"],["110763.86000000","0.00000000"],["110763.87000000","0.04007000"],["110763.88000000","0.00000000"],["110764.80000000","0.00000000"],["110764.84000000","0.00000000"],["110764.85000000","0.00000000"],["110764.86000000","0.04007000"],["110764.91000000","0.00000000"],["110765.19000000","0.00000000"],["110765.98000000","0.00000000"],["110766.00000000","0.04407000"],["110766.01000000","0.06646000"],["110766.60000000","0.00000000"],["110766.62000000","0.00000000"],["110766.91000000","0.00000000"],["110767.12000000","0.00000000"],["110767.22000000","0.00000000"],["110767.54000000","0.08160000"],["110768.22000000","0.00000000"],["110768.62000000","0.10080000"],["110769.71000000","0.12000000"],["110770.91000000","0.00000000"],["110771.34000000","0.00012000"],["110771.94000000","0.00000000"],["110772.20000000","0.00000000"],["110773.42000000","0.00009000"],["110773.64000000","0.00270000"],["110773.79000000","0.00000000"],["110774.75000000","0.08567000"],["110774.79000000","0.00000000"],["110774.88000000","0.01713000"],["110775.49000000","0.00000000"],["110775.81000000","0.00000000"],["110776.02000000","0.00442000"],["110778.50000000","0.00000000"],["110778.60000000","0.00000000"],["110779.21000000","0.00000000"],["110780.22000000","0.00000000"],["110780.36000000","0.00000000"],["110781.14000000","0.00000000"],["110781.23000000","0.03150000"],["110781.30000000","0.18543000"],["110781.61000000","0.00018000"],["110782.00000000","0.00000000"],["110782.07000000","0.00080000"],["110782.38000000","0.00000000"],["110782.48000000","0.00180000"],["110782.49000000","0.00180000"],["110782.53000000","0.00000000"],["110783.23000000","0.04509000"],["110783.73000000","0.00000000"],["110783.93000000","0.00000000"],["110784.28000000","0.00000000"],["110784.85000000","0.00000000"],["110784.99000000","0.08567000"],["110785.78000000","0.02139000"],["110786.62000000","0.00000000"],["110786.63000000","0.00000000"],["110788.60000000","0.00000000"],["110788.64000000","0.00000000"],["110789.31000000","0.03538000"],["110790.10000000","0.00000000"],["110791.05000000","0.00000000"],["110791.15000000","0.02221000"],["110791.64000000","0.00000000"],["110791.84000000","0.00000000"],["110792.13000000","0.00000000"],["110792.14000000","0.00000000"],["110792.21000000","0.00000000"],["110792.88000000","0.02437000"],["110793.44000000","0.00000000"],["110793.88000000","0.00000000"],["110794.00000000","0.00000000"],["110794.29000000","0.00000000"],["110794.53000000","0.00000000"],["110795.99000000","0.00000000"],["110796.53000000","0.00000000"],["110797.87000000","0.00000000"],["110798.22000000","0.00000000"],["110799.18000000","0.00000000"],["110800.61000000","0.01412000"],["110801.04000000","0.00000000"],["110801.55000000","0.00000000"],["110801.56000000","0.00000000"],["110803.07000000","0.01896000"],["110805.96000000","0.00000000"],["110806.10000000","0.00632000"],["110806.64000000","0.00009000"],["110806.66000000","0.00000000"],["110806.67000000","0.00000000"],["110806.82000000","0.00000000"],["110807.16000000","0.00000000"],["110810.33000000","0.00000000"],["110811.04000000","0.02156000"],["110814.25000000","0.00000000"],["110816.86000000","0.00000000"],["110818.03000000","0.00000000"],["110818.60000000","0.00000000"],["110819.99000000","0.03997000"],["110820.22000000","0.00000000"],["110820.74000000","0.13527000"],["110821.05000000","0.56075000"],["110822.48000000","0.00000000"],["110822.77000000","0.00000000"],["110823.41000000","0.00000000"],["110823.60000000","0.07377000"],["110823.95000000","0.00000000"],["110825.44000000","0.00000000"],["110826.74000000","0.00000000"],["110827.02000000","0.00000000"],["110827.03000000","0.00100000"],["110827.91000000","0.00000000"],["110828.22000000","0.03997000"],["110828.23000000","0.19680000"],["110828.57000000","0.10560000"],["110828.62000000","0.00000000"],["110833.22000000","0.00100000"],["110833.23000000","0.00000000"],["110834.52000000","0.00000000"],["110835.11000000","0.00000000"],["110835.12000000","0.00000000"],["110835.86000000","0.00000000"],["110835.99000000","0.00000000"],["110836.06000000","0.00116000"],["110839.31000000","0.00000000"],["110839.32000000","0.00000000"],["110839.87000000","0.00009000"],["110840.00000000","0.00137000"],["110842.00000000","0.00132000"],["110842.27000000","0.00000000"],["110842.28000000","0.03962000"],["110843.30000000","0.00000000"],["110844.00000000","0.00132000"],["110844.83000000","0.07712000"],["110845.37000000","0.00000000"],["110845.97000000","0.00000000"],["110846.00000000","0.00132000"],["110846.25000000","0.00000000"],["110847.45000000","0.13544000"],["110848.00000000","0.00132000"],["110848.65000000","0.00000000"],["110848.68000000","0.22546000"],["110848.94000000","0.00000000"],["110850.00000000","0.00132000"],["110850.59000000","0.00000000"],["110851.99000000","0.08394000"],["110852.00000000","0.00132000"],["110853.98000000","0.08394000"],["110854.00000000","0.00132000"],["110854.11000000","0.08394000"],["110856.00000000","0.00132000"],["110856.52000000","0.00000000"],["110856.55000000","0.00000000"],["110856.61000000","0.00000000"],["110856.72000000","0.08394000"],["110856.73000000","0.00331000"],["110857.10000000","0.00000000"],["110858.00000000","0.00132000"],["110858.32000000","0.00000000"],["110858.60000000","0.00000000"],["110858.66000000","0.00000000"],["110859.29000000","0.00000000"],["110859.58000000","0.00000000"],["110859.61000000","0.12391000"],["110859.89000000","0.00000000"],["110860.00000000","0.00132000"],["110862.00000000","0.00132000"],["110862.32000000","0.00000000"],["110862.33000000","0.00000000"],["110862.47000000","0.00000000"],["110862.79000000","0.00000000"],["110863.40000000","0.01625000"],["110863.76000000","0.00000000"],["110864.77000000","0.00000000"],["110866.13000000","0.00000000"],["110867.79000000","0.00000000"],["110867.80000000","0.00000000"],["110868.52000000","0.94094000"],["110869.37000000","0.00000000"],["110869.67000000","0.00000000"],["110871.98000000","0.01625000"],["110872.98000000","0.01625000"],["110873.09000000","0.00009000"],["110877.48000000","0.45000000"],["110878.11000000","0.00000000"],["110878.60000000","0.08610000"],["110883.33000000","0.00000000"],["110884.25000000","0.00000000"],["110885.04000000","0.00000000"],["110891.89000000","0.00000000"],["110896.87000000","0.99792000"],["110905.19000000","0.00000000"],["110906.31000000","0.00009000"],["110907.46000000","0.24459000"],["110909.68000000","0.02710000"],["110911.36000000","0.08394000"],["110913.99000000","0.08394000"],["110914.40000000","0.00000000"],["110914.41000000","0.00000000"],["110915.06000000","0.00000000"],["110917.10000000","0.08394000"],["110917.15000000","0.00000000"],["110923.65000000","0.00000000"],["110923.66000000","0.00000000"],["110925.12000000","0.00000000"],["110931.80000000","0.00000000"],["110942.25000000","0.00000000"],["110944.22000000","0.00000000"],["110957.10000000","0.00000000"],["110961.67000000","0.00000000"],["110962.90000000","0.00000000"],["110963.98000000","0.00000000"],["110964.06000000","0.00006000"],["110964.67000000","0.00000000"],["110964.98000000","0.00000000"],["110964.99000000","0.00000000"],["110965.09000000","0.00000000"],["110965.99000000","0.00000000"],["110967.37000000","0.00000000"],["110968.57000000","0.00000000"],["110969.32000000","0.02524000"],["110974.21000000","0.00008000"],["110978.30000000","0.00000000"],["110991.87000000","0.00017000"],["111000.00000000","0.15110000"],["111000.25000000","0.00000000"],["111002.00000000","0.00000000"],["111003.06000000","0.00000000"],["111004.00000000","0.00000000"],["111006.00000000","0.00000000"],["111008.00000000","0.00000000"],["111010.00000000","0.00000000"],["111012.00000000","0.00000000"],["111014.00000000","0.00000000"],["111016.00000000","0.00000000"],["111016.44000000","0.00000000"],["111018.00000000","0.00000000"],["111020.00000000","0.00000000"],["111022.00000000","0.00000000"],["111023.19000000","0.00000000"],["111023.65000000","0.00000000"],["111024.00000000","0.00000000"],["111025.00000000","0.00005000"],["111026.00000000","0.00006000"],["111028.00000000","0.00000000"],["111030.00000000","0.00000000"],["111032.00000000","0.00000000"],["111034.00000000","0.00000000"],["111036.00000000","0.00000000"],["111038.00000000","0.00000000"],["111040.00000000","0.00005000"],["111042.00000000","0.00000000"],["111044.00000000","0.00000000"],["111046.00000000","0.00000000"],["111048.00000000","0.00000000"],["111050.00000000","0.01027000"],["111052.00000000","0.00000000"],["111054.00000000","0.00000000"],["111055.86000000","0.02437000"],["111056.00000000","0.00000000"],["111058.00000000","0.00000000"],["111060.00000000","0.02550000"],["111060.17000000","0.00000000"],["111062.00000000","0.00000000"],["111063.90000000","0.00000000"],["111064.00000000","0.00000000"],["111066.00000000","0.00000000"],["111068.00000000","0.00000000"],["111070.00000000","0.00000000"],["111072.00000000","0.00000000"],["111074.00000000","0.00000000"],["111076.00000000","0.00000000"],["111076.23000000","0.00000000"],["111078.00000000","0.00000000"],["111080.00000000","0.00069000"],["111082.00000000","0.00000000"],["111083.25000000","0.00000000"],["111084.00000000","0.00000000"],["111086.00000000","0.00000000"],["111088.00000000","0.00006000"],["111090.00000000","0.10000000"],["111092.00000000","0.00000000"],["111094.00000000","0.00000000"],["111096.00000000","0.00000000"],["111098.00000000","0.00000000"],["111100.00000000","0.19519000"],["111130.41000000","0.00082000"],["111130.51000000","0.00000000"],["111136.16000000","0.00000000"],["111147.15000000","0.02775000"],["111179.72000000","0.45000000"],["111182.25000000","0.00494000"],["111188.48000000","0.00000000"],["111190.80000000","0.00000000"],["111196.05000000","0.00000000"],["111204.34000000","0.00212000"],["111207.45000000","0.00000000"],["111227.08000000","0.00000000"],["111227.39000000","0.00000000"],["111251.48000000","0.00000000"],["111251.88000000","0.00000000"],["111259.84000000","0.00000000"],["111274.79000000","0.00000000"],["111337.38000000","0.00046000"],["111342.92000000","0.00000000"],["111354.00000000","0.00000000"],["128001.97000000","0.00040000"]]}
[2025-10-11T22:18:29.331Z] {"e":"depthUpdate","E":1760221109014,"s":"BTCUSDT","U":77926030369,"u":77926031605,"b":[["110740.19000000","0.00000000"],["110740.18000000","0.00000000"],["110740.01000000","0.00000000"],["110740.00000000","4.71021000"],["110739.99000000","0.00055000"],["110739.92000000","0.00010000"],["110739.59000000","0.00010000"],["110739.58000000","0.27594000"],["110739.57000000","0.29771000"],["110737.03000000","0.00000000"],["110737.00000000","0.00010000"],["110736.99000000","0.05762000"],["110736.26000000","0.00000000"],["110736.21000000","0.00000000"],["110736.20000000","0.00000000"],["110736.19000000","0.00000000"],["110736.13000000","0.00547000"],["110735.92000000","0.00000000"],["110735.61000000","0.00000000"],["110735.02000000","0.00727000"],["110734.47000000","0.00010000"],["110734.46000000","0.11278000"],["110734.06000000","0.32479000"],["110733.04000000","0.00005000"],["110733.03000000","0.23979000"],["110733.02000000","0.00000000"],["110732.42000000","0.00000000"],["110732.41000000","0.00000000"],["110732.19000000","0.00000000"],["110731.78000000","0.00000000"],["110731.77000000","0.00000000"],["110731.49000000","0.00000000"],["110731.03000000","0.00005000"],["110730.90000000","0.00005000"],["110729.53000000","0.00000000"],["110729.52000000","0.00000000"],["110729.51000000","0.10913000"],["110729.33000000","0.18040000"],["110729.32000000","0.32475000"],["110728.50000000","0.00149000"],["110728.49000000","0.04509000"],["110727.18000000","0.26422000"],["110727.17000000","0.20213000"],["110727.16000000","0.00000000"],["110727.15000000","0.00000000"],["110726.69000000","0.00000000"],["110726.68000000","0.00000000"],["110725.77000000","0.00000000"],["110725.76000000","0.00000000"],["110725.75000000","0.00000000"],["110724.40000000","0.00000000"],["110724.38000000","0.32477000"],["110724.25000000","0.00000000"],["110724.24000000","0.18026000"],["110724.23000000","0.45000000"],["110724.22000000","0.00000000"],["110724.05000000","0.32477000"],["110723.39000000","0.04235000"],["110722.28000000","0.04115000"],["110721.84000000","0.07805000"],["110721.83000000","0.00000000"],["110720.81000000","0.00000000"],["110720.79000000","0.00000000"],["110720.09000000","0.00074000"],["110719.43000000","0.00000000"],["110719.42000000","0.00000000"],["110717.42000000","0.00000000"],["110716.78000000","0.00000000"],["110714.76000000","0.00000000"],["110714.56000000","0.00006000"],["110712.27000000","0.04800000"],["110711.83000000","0.01964000"],["110711.35000000","0.18931000"],["110711.17000000","0.07200000"],["110710.99000000","0.13527000"],["110710.64000000","0.08567000"],["110709.93000000","0.07200000"],["110709.29000000","0.00000000"],["110708.71000000","0.00000000"],["110708.40000000","0.04800000"],["110707.80000000","0.03163000"],["110707.69000000","0.00000000"],["110707.55000000","0.00000000"],["110705.55000000","0.00000000"],["110705.48000000","0.00000000"],["110704.43000000","3.24539000"],["110704.33000000","0.00000000"],["110702.09000000","0.07395000"],["110701.05000000","0.00270000"],["110700.47000000","0.00000000"],["110700.21000000","0.21692000"],["110700.14000000","0.00000000"],["110698.62000000","0.04000000"],["110698.59000000","0.13527000"],["110698.00000000","0.00132000"],["110697.42000000","0.00000000"],["110696.00000000","0.00132000"],["110694.00000000","0.00132000"],["110692.87000000","0.00000000"],["110692.00000000","0.00132000"],["110690.00000000","1.16644000"],["110689.52000000","0.00000000"],["110688.00000000","0.00132000"],["110687.49000000","0.13522000"],["110686.00000000","0.00132000"],["110685.63000000","0.00000000"],["110684.00000000","0.00137000"],["110682.76000000","0.04465000"],["110682.00000000","0.00132000"],["110680.00000000","0.00157000"],["110678.00000000","0.00132000"],["110676.00000000","0.00132000"],["110674.01000000","0.02618000"],["110674.00000000","0.00132000"],["110672.29000000","0.03277000"],["110672.00000000","0.00132000"],["110671.90000000","0.00000000"],["110670.00000000","0.00132000"],["110669.23000000","0.00000000"],["110669.20000000","0.00937000"],["110668.00000000","0.00132000"],["110667.65000000","3.27157000"],["110666.21000000","0.00451000"],["110666.00000000","0.00132000"],["110664.78000000","0.00000000"],["110664.75000000","0.06881000"],["110664.00000000","0.00132000"],["110662.00000000","0.00132000"],["110660.00000000","0.00243000"],["110659.03000000","0.02888000"],["110658.00000000","0.00132000"],["110656.00000000","0.00132000"],["110654.00000000","0.00132000"],["110653.45000000","0.00000000"],["110652.00000000","1.01132000"],["110650.34000000","0.55530000"],["110650.09000000","0.07200000"],["110650.00000000","0.00132000"],["110649.53000000","0.09600000"],["110648.00000000","0.00132000"],["110647.67000000","0.04800000"],["110647.32000000","0.07200000"],["110646.00000000","0.00132000"],["110645.59000000","0.04800000"],["110645.02000000","0.00005000"],["110644.00000000","0.00132000"],["110642.00000000","0.00132000"],["110641.18000000","0.04800000"],["110640.00000000","0.00157000"],["110638.00000000","0.01757000"],["110636.00000000","0.00139000"],["110635.28000000","0.00000000"],["110634.75000000","0.04097000"],["110634.48000000","0.00000000"],["110634.21000000","0.00000000"],["110634.00000000","0.00132000"],["110632.68000000","0.00000000"],["110632.66000000","0.00000000"],["110632.39000000","0.00000000"],["110632.01000000","0.04097000"],["110632.00000000","0.00132000"],["110631.09000000","0.02195000"],["110630.00000000","0.00221000"],["110628.37000000","0.04097000"],["110628.00000000","0.00132000"],["110626.00000000","0.00132000"],["110625.47000000","0.03939000"],["110624.33000000","0.00000000"],["110624.25000000","0.04097000"],["110624.00000000","0.00132000"],["110623.11000000","0.02618000"],["110622.00000000","0.00132000"],["110620.19000000","0.02500000"],["110620.00000000","0.00132000"],["110619.59000000","0.10743000"],["110618.00000000","0.00132000"],["110616.36000000","0.04097000"],["110616.00000000","0.00132000"],["110614.94000000","0.01380000"],["110614.00000000","0.00132000"],["110612.00000000","0.00132000"],["110611.72000000","0.02618000"],["110610.34000000","0.04097000"],["110610.00000000","0.00132000"],["110609.76000000","0.00000000"],["110608.92000000","0.00000000"],["110608.00000000","0.00132000"],["110607.69000000","0.00000000"],["110607.51000000","0.09641000"],["110606.00000000","0.00132000"],["110604.00000000","0.00132000"],["110602.00000000","0.00132000"],["110600.62000000","0.02618000"],["110600.00000000","0.23332000"],["110598.29000000","0.08394000"],["110597.98000000","0.04097000"],["110593.71000000","0.02618000"],["110593.62000000","0.08394000"],["110591.41000000","0.04097000"],["110589.62000000","0.08394000"],["110588.99000000","0.00000000"],["110588.76000000","0.04097000"],["110588.08000000","0.02618000"],["110586.05000000","0.08394000"],["110585.17000000","0.04097000"],["110584.30000000","0.08394000"],["110582.43000000","0.00000000"],["110582.27000000","0.08394000"],["110578.64000000","0.05236000"],["110560.01000000","0.05236000"],["110535.88000000","0.04297000"],["110529.52000000","0.04297000"],["110524.96000000","0.08394000"],["110523.30000000","0.08394000"],["110520.77000000","0.08394000"],["110519.57000000","0.08394000"],["110518.51000000","0.08394000"],["110516.98000000","0.08394000"],["110515.61000000","0.08394000"],["110513.52000000","0.08421000"],["110511.57000000","0.08394000"],["110509.29000000","0.08394000"],["110494.82000000","0.02528000"],["110493.81000000","0.02528000"],["110493.72000000","0.02528000"],["110493.25000000","0.02528000"],["110492.69000000","0.02528000"],["110491.88000000","0.02528000"],["110491.02000000","0.02528000"],["110490.71000000","0.02528000"],["110490.34000000","0.02528000"],["110489.95000000","0.02528000"],["110488.66000000","0.02528000"],["110476.58000000","0.00000000"],["110476.56000000","0.00000000"],["110475.79000000","0.00000000"],["110475.77000000","0.69990000"],["110443.84000000","0.00005000"],["110443.31000000","0.02618000"],["110433.33000000","0.00000000"],["110433.25000000","0.00000000"],["110430.07000000","0.00000000"],["110423.89000000","0.00010000"],["110405.44000000","0.00010000"],["110401.62000000","0.02618000"],["110399.91000000","0.00000000"],["110399.36000000","0.02618000"],["110397.12000000","0.02618000"],["110396.82000000","0.04297000"],["110396.49000000","0.04306000"],["110394.50000000","0.02618000"],["110394.07000000","0.03882000"],["110390.30000000","0.02618000"],["110387.64000000","0.02618000"],["110385.03000000","0.02618000"],["110382.79000000","0.10013000"],["110380.62000000","0.02618000"],["110378.26000000","0.02618000"],["110368.89000000","0.07395000"],["110367.89000000","0.07395000"],["110367.22000000","0.07395000"],["110366.63000000","0.07395000"],["110366.20000000","0.07395000"],["110342.50000000","0.00333000"],["110329.41000000","0.00000000"],["110319.15000000","0.00000000"],["110145.60000000","0.02398000"],["110137.01000000","0.04796000"],["110136.05000000","0.02398000"],["110136.04000000","0.02398000"],["110134.45000000","0.02398000"],["110134.44000000","0.02398000"],["110134.23000000","0.04796000"],["110134.18000000","0.04796000"],["110133.96000000","0.04796000"],["110133.05000000","0.02398000"],["110133.03000000","0.02406000"],["110132.04000000","0.02398000"],["110131.98000000","0.02398000"],["110131.42000000","0.04796000"],["110131.24000000","0.02398000"],["110131.23000000","0.02398000"],["110131.22000000","0.02398000"],["110075.56000000","0.00019000"],["109088.75000000","0.00010000"],["101905.53000000","0.00010000"],["99670.00000000","0.00233000"],["99666.00000000","5.01685000"],["88592.16000000","0.00000000"],["88592.00000000","0.00022000"]],"a":[["110740.01000000","17.39406000"],["110740.09000000","0.00010000"],["110740.17000000","0.00000000"],["110740.18000000","0.00000000"],["110740.19000000","0.00000000"],["110740.20000000","0.00000000"],["110740.28000000","0.00000000"],["110740.36000000","0.00000000"],["110740.37000000","0.00010000"],["110740.38000000","0.40126000"],["110740.39000000","1.26435000"],["110742.22000000","0.00366000"],["110743.09000000","0.00000000"],["110743.34000000","0.00000000"],["110743.65000000","0.29765000"],["110743.88000000","0.00547000"],["110743.89000000","0.00000000"],["110743.91000000","0.00000000"],["110743.92000000","0.06110000"],["110744.00000000","0.00000000"],["110745.09000000","0.00000000"],["110745.10000000","0.00010000"],["110745.11000000","0.14128000"],["110745.12000000","0.04508000"],["110746.19000000","0.00000000"],["110746.24000000","0.04005000"],["110746.27000000","0.00000000"],["110746.28000000","0.00000000"],["110746.56000000","0.00000000"],["110746.57000000","0.00010000"],["110746.58000000","0.00005000"],["110747.05000000","0.00000000"],["110747.53000000","0.00000000"],["110747.58000000","0.00000000"],["110747.65000000","0.00005000"],["110747.67000000","0.00000000"],["110748.00000000","0.00000000"],["110748.01000000","0.00000000"],["110748.64000000","0.00006000"],["110748.96000000","0.00000000"],["110749.40000000","0.00000000"],["110749.41000000","0.00005000"],["110749.50000000","0.32470000"],["110749.92000000","0.03621000"],["110750.00000000","0.00036000"],["110750.01000000","0.03974000"],["110750.04000000","0.00000000"],["110750.17000000","0.00913000"],["110750.25000000","0.00451000"],["110750.33000000","0.00005000"],["110750.34000000","0.00000000"],["110750.39000000","0.01364000"],["110750.64000000","0.00000000"],["110750.65000000","0.00000000"],["110751.12000000","0.04076000"],["110751.42000000","0.00000000"],["110751.73000000","0.00005000"],["110751.74000000","0.16906000"],["110751.75000000","0.32469000"],["110751.79000000","0.00000000"],["110751.80000000","0.00000000"],["110752.57000000","0.06646000"],["110752.90000000","0.00000000"],["110752.93000000","0.00000000"],["110752.94000000","0.00000000"],["110753.10000000","0.00000000"],["110753.11000000","0.00000000"],["110753.85000000","0.00000000"],["110754.17000000","0.00328000"],["110754.37000000","0.00000000"],["110754.50000000","0.00405000"],["110754.82000000","0.00000000"],["110754.91000000","0.04610000"],["110755.35000000","0.00000000"],["110755.60000000","0.00000000"],["110755.80000000","0.12481000"],["110755.89000000","0.00000000"],["110755.90000000","0.13522000"],["110756.20000000","0.00305000"],["110756.35000000","0.00000000"],["110756.57000000","0.32467000"],["110757.30000000","0.05280000"],["110757.90000000","0.18026000"],["110757.91000000","0.52629000"],["110757.97000000","0.00000000"],["110758.16000000","0.00000000"],["110758.33000000","0.00000000"],["110758.34000000","0.00000000"],["110758.35000000","0.00000000"],["110758.43000000","0.13440000"],["110758.53000000","0.11520000"],["110758.78000000","0.00000000"],["110758.81000000","0.00000000"],["110759.15000000","0.00000000"],["110759.49000000","0.12240000"],["110759.69000000","0.00000000"],["110760.27000000","0.00800000"],["110760.74000000","0.14400000"],["110761.18000000","0.30441000"],["110762.31000000","0.08160000"],["110762.68000000","0.19680000"],["110762.85000000","0.00000000"],["110763.12000000","0.10560000"],["110763.65000000","0.01964000"],["110763.84000000","0.00010000"],["110764.64000000","0.13527000"],["110767.39000000","0.02800000"],["110769.50000000","1.20056000"],["110769.61000000","0.00000000"],["110770.85000000","0.00000000"],["110770.86000000","0.00000000"],["110771.77000000","0.08567000"],["110771.82000000","0.00000000"],["110772.68000000","0.02618000"],["110772.69000000","0.00000000"],["110773.07000000","0.00000000"],["110773.46000000","0.18031000"],["110773.66000000","0.00000000"],["110774.01000000","0.00000000"],["110774.59000000","0.13527000"],["110774.62000000","0.00000000"],["110775.03000000","0.08567000"],["110776.79000000","0.00000000"],["110777.14000000","0.00000000"],["110778.61000000","0.49916000"],["110779.29000000","0.22546000"],["110779.31000000","0.00000000"],["110779.48000000","0.00079000"],["110781.23000000","0.00000000"],["110781.30000000","0.08463000"],["110782.07000000","0.00000000"],["110782.22000000","0.00000000"],["110782.26000000","0.00000000"],["110782.54000000","0.00000000"],["110783.23000000","0.00000000"],["110784.97000000","0.00000000"],["110786.53000000","0.22546000"],["110787.63000000","0.04134000"],["110788.21000000","0.13544000"],["110788.58000000","0.00000000"],["110789.31000000","0.00000000"],["110790.01000000","0.00010000"],["110793.51000000","0.04347000"],["110794.86000000","0.00000000"],["110801.22000000","3.24539000"],["110803.04000000","0.00656000"],["110805.48000000","0.00000000"],["110807.87000000","3.24539000"],["110808.20000000","0.03150000"],["110811.23000000","0.00000000"],["110812.76000000","0.05280000"],["110813.90000000","0.07680000"],["110814.52000000","0.00000000"],["110814.65000000","0.00000000"],["110815.87000000","0.00000000"],["110817.92000000","0.13522000"],["110823.82000000","0.00036000"],["110824.42000000","0.03538000"],["110825.04000000","0.00000000"],["110825.05000000","0.00000000"],["110825.14000000","0.13527000"],["110826.15000000","0.00100000"],["110826.16000000","0.00100000"],["110827.03000000","0.00000000"],["110829.99000000","0.02528000"],["110833.22000000","0.00000000"],["110836.86000000","0.02706000"],["110842.40000000","0.02255000"],["110844.86000000","0.00000000"],["110847.45000000","0.00000000"],["110847.81000000","0.13544000"],["110848.68000000","0.00000000"],["110850.40000000","0.00000000"],["110850.95000000","0.00525000"],["110851.28000000","0.22546000"],["110852.48000000","0.18031000"],["110853.40000000","0.22546000"],["110856.73000000","0.00000000"],["110863.41000000","0.00000000"],["110864.69000000","0.05760000"],["110865.37000000","0.00000000"],["110865.99000000","0.02618000"],["110867.04000000","0.00000000"],["110873.99000000","0.03997000"],["110879.37000000","0.03163000"],["110879.40000000","0.00000000"],["110880.20000000","0.00331000"],["110888.38000000","0.00000000"],["110889.63000000","0.00000000"],["110891.74000000","0.06000000"],["110893.90000000","0.00000000"],["110896.87000000","0.00000000"],["110901.57000000","0.09521000"],["110917.90000000","0.00000000"],["110928.89000000","0.00000000"],["110930.94000000","0.00901000"],["110934.31000000","0.02618000"],["110935.67000000","0.00000000"],["110966.36000000","0.00000000"],["110971.21000000","0.00937000"],["110972.96000000","0.08394000"],["110976.91000000","0.14856000"],["110989.03000000","0.04097000"],["110991.15000000","0.02528000"],["110991.80000000","0.04097000"],["110991.99000000","0.00000000"],["110992.47000000","0.02528000"],["111011.41000000","0.00000000"],["111037.18000000","0.02618000"],["111130.41000000","0.00000000"],["111140.72000000","0.00000000"],["111153.89000000","0.00082000"],["111190.80000000","0.45000000"],["111257.19000000","0.67153000"],["128001.97000000","0.03006000"]]}
[2025-10-11T22:18:30.331Z] {"e":"depthUpdate","E":1760221110014,"s":"BTCUSDT","U":77926031606,"u":77926031976,"b":[["110740.00000000","4.26748000"],["110739.99000000","0.00065000"],["110737.20000000","0.00000000"],["110736.99000000","0.05762000"],["110736.30000000","0.00010000"],["110736.29000000","0.32478000"],["110736.24000000","0.00000000"],["110736.23000000","0.00000000"],["110736.13000000","0.00547000"],["110736.09000000","0.00000000"],["110735.78000000","0.00005000"],["110735.77000000","0.04056000"],["110735.02000000","0.00727000"],["110734.67000000","0.00000000"],["110734.66000000","0.04080000"],["110734.47000000","0.00000000"],["110734.46000000","0.00000000"],["110734.07000000","0.00000000"],["110734.06000000","0.00000000"],["110733.04000000","0.00000000"],["110733.03000000","0.23979000"],["110731.69000000","0.11273000"],["110731.03000000","0.01760000"],["110729.51000000","0.10913000"],["110729.33000000","0.18040000"],["110727.66000000","0.18026000"],["110727.55000000","0.00005000"],["110727.18000000","0.42433000"],["110724.56000000","0.32477000"],["110724.11000000","0.00000000"],["110724.05000000","0.00000000"],["110723.39000000","0.00149000"],["110722.28000000","0.00000000"],["110712.78000000","0.00000000"],["110712.50000000","0.00000000"],["110712.43000000","0.01964000"],["110712.20000000","0.00000000"],["110711.83000000","0.00000000"],["110711.82000000","0.00000000"],["110709.29000000","0.00937000"],["110704.44000000","2.40546000"],["110704.34000000","0.00000000"],["110703.43000000","0.08744000"],["110694.68000000","0.00000000"],["110690.00000000","1.19262000"],["110678.01000000","0.02998000"],["110672.29000000","0.00000000"],["110672.01000000","0.04894000"],["110669.20000000","0.00000000"],["110668.01000000","0.02998000"],["110664.75000000","0.00000000"],["110664.07000000","0.06720000"],["110659.34000000","0.03277000"],["110659.03000000","0.00000000"],["110650.34000000","1.22299000"],["110647.48000000","0.13527000"],["110646.93000000","0.00005000"],["110645.72000000","0.02888000"],["110620.64000000","0.03997000"],["110617.62000000","0.04097000"],["110616.34000000","0.03997000"],["110608.00000000","0.04129000"],["110605.61000000","0.04097000"],["110601.09000000","0.02398000"],["110599.40000000","0.04097000"],["110596.25000000","0.04097000"],["110593.03000000","0.04097000"],["110590.40000000","0.08294000"],["110588.07000000","0.08294000"],["110587.86000000","0.00056000"],["110586.06000000","1.25666000"],["110585.71000000","0.08294000"],["110582.42000000","0.99779000"],["110572.03000000","0.00000000"],["110555.12000000","0.02618000"],["110533.07000000","0.06197000"],["110520.15000000","0.08294000"],["110519.25000000","0.08294000"],["110518.00000000","0.08294000"],["110516.44000000","0.08294000"],["110504.20000000","0.00000000"],["110464.77000000","0.02998000"],["110455.72000000","0.02398000"],["110436.11000000","0.00005000"],["110382.62000000","0.02618000"],["110368.24000000","0.00333000"],["110362.52000000","0.02998000"],["110361.59000000","0.02998000"],["110360.61000000","0.02998000"],["110359.56000000","0.02998000"],["110357.14000000","0.03050000"],["110354.54000000","0.02998000"],["110342.50000000","0.00000000"],["110286.27000000","0.02398000"],["110075.56000000","0.00019000"],["109965.37000000","0.00000000"],["109358.15000000","0.00000000"],["108891.99000000","0.00452000"],["108850.56000000","0.00000000"],["108750.94000000","0.00000000"],["108143.72000000","0.00000000"],["107536.51000000","0.00000000"],["106929.30000000","0.00000000"],["106322.08000000","0.00000000"],["105714.87000000","0.00000000"],["105107.66000000","0.00000000"],["104500.44000000","0.00000000"],["103893.23000000","0.00005000"],["103286.01000000","0.00000000"],["102678.80000000","0.00000000"],["102071.59000000","0.00000000"],["101905.53000000","0.00000000"],["101464.37000000","0.00000000"],["100857.16000000","0.00000000"],["100249.95000000","0.00008000"],["99666.00000000","5.01685000"],["88592.00000000","0.00022000"],["60000.00000000","56.18404000"],["39866.40000000","0.00032000"]],"a":[["110740.01000000","17.39406000"],["110740.39000000","1.26435000"],["110742.86000000","0.00005000"],["110743.64000000","0.00010000"],["110743.65000000","0.29770000"],["110743.92000000","0.06115000"],["110744.14000000","0.06656000"],["110744.52000000","0.00000000"],["110745.10000000","0.00000000"],["110745.11000000","0.14254000"],["110745.36000000","0.00000000"],["110746.24000000","0.04005000"],["110746.57000000","0.00000000"],["110746.58000000","0.00000000"],["110748.71000000","0.00005000"],["110748.72000000","0.32470000"],["110749.49000000","0.00000000"],["110749.50000000","0.00000000"],["110749.64000000","0.00000000"],["110749.65000000","0.00000000"],["110749.92000000","0.03616000"],["110750.00000000","0.00018000"],["110751.00000000","0.00005000"],["110751.73000000","0.00010000"],["110751.74000000","0.16906000"],["110752.57000000","0.06651000"],["110754.46000000","0.00000000"],["110754.50000000","0.18431000"],["110755.80000000","0.00000000"],["110756.20000000","0.00300000"],["110756.62000000","0.11273000"],["110757.39000000","0.00000000"],["110757.89000000","1.64631000"],["110757.90000000","3.42565000"],["110757.91000000","0.00000000"],["110758.98000000","0.10924000"],["110759.67000000","0.00000000"],["110760.27000000","0.00000000"],["110761.12000000","0.32466000"],["110762.06000000","0.00000000"],["110763.56000000","0.00000000"],["110767.39000000","0.00000000"],["110779.91000000","0.02800000"],["110781.60000000","0.18026000"],["110781.61000000","0.00000000"],["110783.93000000","2.54699000"],["110788.00000000","0.00017000"],["110790.00000000","0.00100000"],["110790.44000000","0.19680000"],["110792.00000000","0.00100000"],["110794.00000000","0.00100000"],["110796.00000000","0.00100000"],["110808.00000000","0.00120000"],["110810.00000000","0.00120000"],["110811.30000000","0.00000000"],["110812.00000000","0.00120000"],["110814.00000000","0.00120000"],["110816.00000000","0.00120000"],["110818.00000000","0.00125000"],["110819.42000000","0.48911000"],["110824.42000000","0.00000000"],["110830.01000000","0.00000000"],["110840.00000000","0.01941000"],["110843.02000000","0.03538000"],["110860.00000000","0.01936000"],["110865.37000000","0.08160000"],["110868.51000000","0.35353000"],["110880.20000000","0.00000000"],["110896.87000000","0.99224000"],["110901.33000000","0.07745000"],["110906.06000000","0.00331000"],["110906.59000000","0.00000000"],["110917.72000000","0.01900000"],["110927.51000000","0.02618000"],["110939.42000000","0.30362000"],["110976.91000000","0.00005000"],["111153.89000000","0.00000000"],["111179.77000000","0.00082000"],["111179.79000000","0.00000000"],["111374.66000000","0.00000000"],["111787.01000000","0.00000000"],["112394.22000000","0.00000000"],["113001.44000000","0.00000000"],["113608.65000000","0.00000000"],["114215.86000000","0.00000000"],["114823.08000000","0.00000000"],["115430.29000000","0.00000000"],["116037.50000000","0.00000000"],["116644.72000000","0.00000000"],["117251.93000000","0.00000000"],["117859.15000000","0.00008000"],["118466.36000000","0.00000000"],["119073.57000000","0.00000000"],["119680.79000000","0.00000000"],["120288.00000000","0.00019000"],["120895.22000000","0.00000000"],["128001.97000000","0.03006000"]]}
[2025-10-11T22:18:31.331Z] {"e":"depthUpdate","E":1760221111014,"s":"BTCUSDT","U":77926031977,"u":77926032506,"b":[["110740.00000000","4.23811000"],["110739.99000000","0.00030000"],["110739.58000000","0.38109000"],["110739.57000000","0.29776000"],["110739.04000000","0.00010000"],["110739.03000000","0.04084000"],["110736.99000000","0.05767000"],["110736.37000000","0.00005000"],["110736.36000000","0.32478000"],["110736.30000000","0.00000000"],["110736.29000000","0.00000000"],["110735.78000000","0.00000000"],["110735.77000000","0.04056000"],["110734.67000000","0.00000000"],["110734.66000000","0.04080000"],["110734.65000000","0.04509000"],["110734.08000000","0.20212000"],["110734.07000000","0.32474000"],["110733.03000000","0.34615000"],["110731.67000000","0.32475000"],["110731.01000000","0.18026000"],["110729.50000000","0.00400000"],["110728.49000000","0.00000000"],["110727.67000000","0.26537000"],["110727.38000000","0.06646000"],["110727.18000000","0.00000000"],["110727.17000000","0.00000000"],["110725.63000000","0.00000000"],["110724.56000000","0.00000000"],["110724.38000000","0.00000000"],["110722.82000000","0.04800000"],["110721.80000000","0.04800000"],["110718.84000000","0.00000000"],["110718.25000000","0.04800000"],["110717.68000000","0.00000000"],["110717.50000000","0.00400000"],["110716.03000000","0.04800000"],["110715.89000000","0.04800000"],["110715.86000000","0.08567000"],["110714.64000000","0.13527000"],["110712.43000000","0.00000000"],["110712.00000000","0.00132000"],["110711.76000000","0.00000000"],["110711.37000000","2.26896000"],["110711.36000000","3.24539000"],["110711.35000000","0.00000000"],["110709.62000000","0.04000000"],["110708.10000000","0.22546000"],["110707.84000000","3.24539000"],["110703.79000000","0.00010000"],["110702.08000000","0.00000000"],["110700.27000000","0.00000000"],["110699.01000000","0.02998000"],["110698.62000000","0.00000000"],["110698.59000000","0.00000000"],["110696.70000000","0.00000000"],["110696.64000000","0.00000000"],["110694.28000000","0.02998000"],["110692.23000000","0.02998000"],["110691.27000000","0.00000000"],["110688.36000000","0.04472000"],["110688.06000000","0.06880000"],["110684.11000000","0.00005000"],["110684.01000000","0.02998000"],["110682.76000000","0.00000000"],["110682.01000000","0.02998000"],["110681.51000000","0.00000000"],["110679.29000000","0.00000000"],["110678.36000000","0.07798000"],["110672.01000000","0.07892000"],["110670.36000000","0.00634000"],["110670.05000000","0.00630000"],["110668.01000000","0.05996000"],["110667.63000000","0.03277000"],["110666.87000000","0.02888000"],["110665.33000000","0.00451000"],["110659.34000000","0.00000000"],["110652.06000000","0.00000000"],["110650.66000000","0.13573000"],["110650.34000000","0.00000000"],["110647.78000000","0.00000000"],["110646.62000000","0.00000000"],["110645.72000000","0.00000000"],["110644.61000000","0.04840000"],["110643.55000000","0.00000000"],["110641.13000000","0.00000000"],["110637.43000000","0.00000000"],["110632.43000000","0.00000000"],["110630.92000000","0.22546000"],["110630.57000000","0.00000000"],["110628.37000000","0.08094000"],["110624.47000000","0.03997000"],["110620.65000000","0.11357000"],["110615.05000000","0.03997000"],["110593.43000000","0.04097000"],["110590.41000000","0.02528000"],["110571.44000000","0.13260000"],["110565.47000000","0.00000000"],["110554.64000000","0.00250000"],["110528.63000000","0.00000000"],["110508.29000000","0.00000000"],["110465.17000000","0.02998000"],["110464.77000000","0.00000000"],["110428.38000000","0.00005000"],["110396.49000000","0.00009000"],["110368.24000000","0.00000000"],["110358.35000000","0.00333000"],["110338.91000000","0.02802000"],["110075.56000000","0.00000000"],["108136.08000000","0.00000000"],["99666.00000000","5.01685000"],["88592.00000000","0.00022000"],["60000.00000000","56.18394000"],["42000.00000000","1.48198000"],["39866.40000000","0.00064000"],["33000.00000000","3.75190000"]],"a":[["110740.01000000","14.45496000"],["110740.02000000","0.00030000"],["110740.38000000","0.40131000"],["110740.39000000","1.26440000"],["110741.15000000","0.05165000"],["110741.31000000","0.00000000"],["110741.32000000","0.00000000"],["110743.64000000","0.00000000"],["110743.65000000","0.00000000"],["110743.88000000","0.00547000"],["110743.92000000","0.00128000"],["110744.14000000","0.00000000"],["110744.56000000","0.00000000"],["110745.08000000","0.00005000"],["110745.10000000","0.00000000"],["110745.11000000","0.01514000"],["110745.12000000","0.00000000"],["110746.24000000","0.00000000"],["110746.61000000","0.00000000"],["110746.62000000","0.00000000"],["110748.71000000","0.00000000"],["110748.72000000","0.00000000"],["110749.03000000","0.00000000"],["110749.92000000","0.03616000"],["110750.01000000","0.00005000"],["110750.17000000","0.00918000"],["110750.26000000","0.03621000"],["110750.38000000","0.06509000"],["110750.39000000","0.01359000"],["110750.41000000","0.00000000"],["110750.74000000","0.00000000"],["110750.97000000","0.00000000"],["110751.12000000","0.00000000"],["110751.46000000","0.04513000"],["110751.73000000","0.00000000"],["110751.74000000","0.00000000"],["110751.75000000","0.00000000"],["110752.57000000","0.00005000"],["110753.55000000","0.00074000"],["110753.92000000","0.04159000"],["110753.93000000","0.04000000"],["110754.17000000","0.00333000"],["110754.32000000","0.00070000"],["110754.35000000","0.00005000"],["110754.50000000","0.00405000"],["110754.91000000","0.04615000"],["110755.03000000","0.04155000"],["110755.17000000","0.00000000"],["110755.89000000","0.00010000"],["110756.20000000","0.00300000"],["110756.57000000","0.00000000"],["110756.61000000","0.00010000"],["110757.88000000","0.00000000"],["110757.89000000","0.53457000"],["110757.90000000","0.18026000"],["110760.27000000","0.00800000"],["110760.90000000","0.00000000"],["110761.12000000","0.00000000"],["110761.18000000","0.00000000"],["110762.62000000","0.32466000"],["110763.65000000","0.00000000"],["110764.90000000","0.00000000"],["110766.87000000","0.00000000"],["110767.27000000","0.30440000"],["110767.28000000","0.32464000"],["110767.80000000","0.01964000"],["110769.50000000","0.00000000"],["110769.81000000","0.00901000"],["110771.76000000","0.00000000"],["110773.66000000","2.23828000"],["110774.45000000","0.00000000"],["110777.01000000","0.00083000"],["110779.48000000","0.00000000"],["110780.85000000","1.20254000"],["110790.68000000","0.05760000"],["110793.51000000","0.00000000"],["110796.17000000","0.10560000"],["110799.12000000","0.04423000"],["110807.15000000","0.00630000"],["110807.47000000","0.00634000"],["110807.86000000","0.99731000"],["110807.95000000","0.00000000"],["110808.20000000","0.00000000"],["110811.94000000","0.00225000"],["110820.65000000","0.00000000"],["110826.15000000","0.00000000"],["110826.16000000","0.00000000"],["110826.18000000","0.00100000"],["110826.19000000","0.00100000"],["110831.93000000","0.00000000"],["110832.68000000","0.00011000"],["110835.82000000","0.03150000"],["110843.02000000","0.00000000"],["110846.25000000","0.58495000"],["110850.12000000","0.00000000"],["110857.01000000","0.00000000"],["110857.30000000","0.00000000"],["110864.69000000","0.00000000"],["110890.64000000","0.06000000"],["110896.13000000","0.00331000"],["110896.86000000","0.00010000"],["110896.87000000","0.00000000"],["110906.06000000","0.00000000"],["110906.79000000","0.99655000"],["110907.57000000","0.00000000"],["110922.74000000","0.00090000"],["110927.97000000","0.01768000"],["110941.99000000","0.00000000"],["110961.50000000","0.02000000"],["110976.91000000","0.14856000"],["110993.56000000","0.06646000"],["110997.67000000","0.02528000"],["111023.87000000","0.00000000"],["111081.84000000","0.04297000"],["111140.45000000","0.02802000"],["111169.83000000","0.00082000"],["111171.10000000","0.00000000"],["111179.77000000","0.00000000"],["111239.00000000","0.67153000"],["111257.19000000","0.00000000"],["111257.40000000","0.00250000"],["111268.75000000","0.00000000"],["111293.70000000","0.00121000"],["111315.22000000","0.00046000"],["111337.38000000","0.00000000"],["128001.97000000","0.00040000"]]}
[2025-10-11T22:18:32.331Z] {"e":"depthUpdate","E":1760221112014,"s":"BTCUSDT","U":77926032507,"u":77926032907,"b":[["110740.00000000","4.51702000"],["110739.99000000","0.00015000"],["110739.63000000","0.00010000"],["110739.62000000","0.01359000"],["110737.00000000","0.00005000"],["110736.99000000","0.05762000"],["110736.37000000","0.00000000"],["110734.66000000","0.04075000"],["110734.65000000","0.04509000"],["110734.08000000","0.00000000"],["110733.91000000","0.01806000"],["110731.04000000","0.20212000"],["110728.89000000","0.00074000"],["110728.49000000","0.00000000"],["110728.47000000","0.00000000"],["110728.45000000","0.02710000"],["110728.31000000","0.00000000"],["110726.01000000","0.00327000"],["110725.84000000","0.00000000"],["110722.94000000","0.04800000"],["110721.84000000","0.11901000"],["110721.71000000","0.09600000"],["110720.85000000","0.00005000"],["110720.75000000","0.07200000"],["110720.09000000","0.00000000"],["110719.50000000","0.07200000"],["110717.21000000","0.04800000"],["110712.60000000","0.00000000"],["110711.89000000","0.00000000"],["110711.80000000","0.01964000"],["110711.78000000","0.00000000"],["110711.17000000","0.00000000"],["110709.93000000","0.00000000"],["110706.10000000","0.00000000"],["110705.19000000","0.00000000"],["110703.14000000","0.00000000"],["110687.21000000","0.00005000"],["110679.90000000","0.09059000"],["110678.37000000","0.04397000"],["110674.36000000","0.04407000"],["110673.01000000","0.04894000"],["110666.43000000","0.00000000"],["110666.22000000","0.02998000"],["110658.01000000","0.07395000"],["110648.33000000","0.26544000"],["110646.63000000","0.04800000"],["110643.55000000","0.04800000"],["110634.76000000","0.02528000"],["110631.28000000","0.00000000"],["110630.92000000","0.00000000"],["110628.02000000","0.00000000"],["110623.54000000","0.02528000"],["110623.12000000","0.00167000"],["110609.94000000","0.07577000"],["110599.98000000","0.29987000"],["110597.69000000","0.99806000"],["110582.42000000","0.00000000"],["110517.30000000","0.00000000"],["110513.01000000","0.00000000"],["110511.74000000","0.00067000"],["110511.58000000","0.00588000"],["110494.55000000","4.77202000"],["110420.65000000","0.00005000"],["110411.18000000","0.04397000"],["99666.00000000","5.01685000"],["88592.00000000","0.00022000"]],"a":[["110740.01000000","11.66610000"],["110740.02000000","0.00050000"],["110740.17000000","0.00908000"],["110740.39000000","1.27794000"],["110741.15000000","0.00000000"],["110743.92000000","0.00128000"],["110745.10000000","0.00010000"],["110745.11000000","0.19344000"],["110745.12000000","0.00000000"],["110745.56000000","0.00010000"],["110745.57000000","0.32010000"],["110746.49000000","0.00000000"],["110747.24000000","0.00000000"],["110748.38000000","0.05839000"],["110749.41000000","0.00000000"],["110749.60000000","0.00000000"],["110749.61000000","0.00000000"],["110749.75000000","0.00005000"],["110749.76000000","0.29769000"],["110749.92000000","0.00000000"],["110750.25000000","0.05734000"],["110750.26000000","0.03611000"],["110750.33000000","0.00000000"],["110750.37000000","0.00005000"],["110750.38000000","0.00000000"],["110750.39000000","0.00005000"],["110751.46000000","0.04508000"],["110752.65000000","0.00000000"],["110753.92000000","0.00000000"],["110754.91000000","0.04610000"],["110755.03000000","0.00000000"],["110755.20000000","0.00000000"],["110755.40000000","0.00000000"],["110755.89000000","0.00000000"],["110756.20000000","0.00300000"],["110756.36000000","0.32468000"],["110756.61000000","0.00000000"],["110757.90000000","0.00000000"],["110758.41000000","0.32467000"],["110759.08000000","0.18026000"],["110760.27000000","0.00800000"],["110763.03000000","1.11555000"],["110763.04000000","0.00000000"],["110763.87000000","0.00000000"],["110764.86000000","0.00000000"],["110765.61000000","0.00005000"],["110766.00000000","0.00400000"],["110767.27000000","0.00000000"],["110769.13000000","0.00000000"],["110769.26000000","0.00000000"],["110770.24000000","0.30439000"],["110774.67000000","0.00083000"],["110777.01000000","0.00000000"],["110788.02000000","0.00000000"],["110791.05000000","2.07837000"],["110791.85000000","0.12240000"],["110793.09000000","0.14400000"],["110794.60000000","0.08160000"],["110814.52000000","3.24539000"],["110822.79000000","0.32377000"],["110826.18000000","0.00000000"],["110826.19000000","0.00000000"],["110827.12000000","0.00000000"],["110827.13000000","0.00000000"],["110828.07000000","0.00000000"],["110828.08000000","0.00000000"],["110829.07000000","0.00100000"],["110829.08000000","0.00100000"],["110835.82000000","0.00000000"],["110847.71000000","0.03150000"],["110857.11000000","0.30475000"],["110857.12000000","0.00000000"],["110865.37000000","0.00000000"],["110872.97000000","0.03997000"],["110888.83000000","0.00000000"],["110891.98000000","0.32526000"],["110900.00000000","0.01963000"],["110906.79000000","0.99743000"],["110922.90000000","0.16802000"],["110987.81000000","4.88607000"],["128001.97000000","0.00040000"]]}
[2025-10-11T22:18:33.333Z] {"e":"depthUpdate","E":1760221113014,"s":"BTCUSDT","U":77926032908,"u":77926036864,"b":[["110756.19000000","8.15887000"],["110756.11000000","0.00010000"],["110753.86000000","0.00000000"],["110753.84000000","0.42877000"],["110753.83000000","0.04238000"],["110753.82000000","0.00000000"],["110753.51000000","0.00000000"],["110753.50000000","0.45010000"],["110753.26000000","0.00000000"],["110752.97000000","0.00000000"],["110752.90000000","0.00000000"],["110752.88000000","0.00000000"],["110752.87000000","0.00000000"],["110752.72000000","0.04151000"],["110752.59000000","0.00000000"],["110752.58000000","0.00000000"],["110752.56000000","0.00005000"],["110752.55000000","0.22551000"],["110752.48000000","0.00000000"],["110751.94000000","0.18031000"],["110751.27000000","0.00000000"],["110751.18000000","0.00000000"],["110751.17000000","0.00000000"],["110751.02000000","0.00000000"],["110751.00000000","0.00000000"],["110750.99000000","0.36095000"],["110750.56000000","0.00000000"],["110750.26000000","0.00000000"],["110750.17000000","0.00000000"],["110750.16000000","0.00000000"],["110750.00000000","0.36219000"],["110749.99000000","0.26583000"],["110749.35000000","0.00000000"],["110749.28000000","0.00000000"],["110749.26000000","0.00000000"],["110749.25000000","0.00000000"],["110749.24000000","0.00000000"],["110749.22000000","0.04430000"],["110749.21000000","0.18031000"],["110749.20000000","0.00000000"],["110747.67000000","0.00000000"],["110747.65000000","0.00000000"],["110747.64000000","0.22019000"],["110747.29000000","0.00000000"],["110746.59000000","0.00000000"],["110746.53000000","0.00000000"],["110746.52000000","0.00000000"],["110746.50000000","0.00005000"],["110746.49000000","0.05764000"],["110746.42000000","0.00000000"],["110746.11000000","0.00005000"],["110746.06000000","0.00000000"],["110745.97000000","0.00000000"],["110745.96000000","0.00000000"],["110745.95000000","0.03993000"],["110745.54000000","0.00000000"],["110745.26000000","0.00000000"],["110745.17000000","0.00000000"],["110745.16000000","0.03993000"],["110745.15000000","0.00000000"],["110745.11000000","0.00300000"],["110745.08000000","0.00000000"],["110745.07000000","0.45036000"],["110745.00000000","0.00000000"],["110744.00000000","0.00000000"],["110743.93000000","0.37307000"],["110743.92000000","0.36072000"],["110743.91000000","0.18026000"],["110743.89000000","0.00000000"],["110743.88000000","0.00000000"],["110743.87000000","0.03993000"],["110743.69000000","0.04074000"],["110743.67000000","0.00149000"],["110743.50000000","0.00400000"],["110743.17000000","0.04800000"],["110743.01000000","0.00005000"],["110743.00000000","0.00000000"],["110742.85000000","0.00000000"],["110742.61000000","0.02141000"],["110742.37000000","0.00010000"],["110742.21000000","0.04800000"],["110742.12000000","0.08567000"],["110742.00000000","0.00000000"],["110741.79000000","0.10464000"],["110741.73000000","0.00000000"],["110741.71000000","0.00000000"],["110741.70000000","0.03993000"],["110741.20000000","0.08567000"],["110741.01000000","0.00000000"],["110741.00000000","0.00000000"],["110740.86000000","0.00000000"],["110740.79000000","0.00000000"],["110740.77000000","0.00000000"],["110740.76000000","0.03993000"],["110740.71000000","0.00000000"],["110740.63000000","0.00000000"],["110740.44000000","0.00005000"],["110740.43000000","0.18026000"],["110740.38000000","0.00000000"],["110740.37000000","0.00000000"],["110740.32000000","0.00000000"],["110740.23000000","0.00000000"],["110740.16000000","0.00000000"],["110740.13000000","0.00000000"],["110740.08000000","0.00000000"],["110740.06000000","0.00000000"],["110740.03000000","0.00000000"],["110740.01000000","0.00000000"],["110740.00000000","0.04097000"],["110739.99000000","0.00000000"],["110739.92000000","0.00000000"],["110739.63000000","0.00000000"],["110739.62000000","0.01354000"],["110739.59000000","0.00000000"],["110739.58000000","0.00000000"],["110739.57000000","0.00000000"],["110739.04000000","0.00000000"],["110739.03000000","0.00000000"],["110738.73000000","0.00010000"],["110738.14000000","0.00149000"],["110738.00000000","0.00137000"],["110737.67000000","0.04800000"],["110737.28000000","0.00006000"],["110737.00000000","0.00000000"],["110736.99000000","0.00000000"],["110736.72000000","0.00000000"],["110736.54000000","0.04800000"],["110736.37000000","1.06095000"],["110736.36000000","0.04800000"],["110736.13000000","0.00542000"],["110735.77000000","0.00000000"],["110735.70000000","0.04000000"],["110735.43000000","0.04924000"],["110735.39000000","0.00010000"],["110735.36000000","0.00007000"],["110735.02000000","0.00722000"],["110734.81000000","0.00000000"],["110734.66000000","0.00000000"],["110734.65000000","0.00000000"],["110734.36000000","3.42565000"],["110734.21000000","0.04800000"],["110734.07000000","0.00000000"],["110733.71000000","0.00005000"],["110733.50000000","0.01000000"],["110733.39000000","0.00000000"],["110733.03000000","1.20370000"],["110731.77000000","0.04800000"],["110731.70000000","0.45036000"],["110731.69000000","0.00000000"],["110731.67000000","0.00000000"],["110731.34000000","0.00010000"],["110731.04000000","0.00000000"],["110731.02000000","3.24539000"],["110730.43000000","0.13527000"],["110729.51000000","0.00000000"],["110729.33000000","0.00000000"],["110729.32000000","0.00000000"],["110728.50000000","0.00000000"],["110727.69000000","2.32592000"],["110727.68000000","3.24539000"],["110727.67000000","0.00000000"],["110726.33000000","0.01713000"],["110726.20000000","0.08567000"],["110726.03000000","0.00000000"],["110726.01000000","0.00000000"],["110725.92000000","0.07206000"],["110724.68000000","0.07200000"],["110724.51000000","0.00000000"],["110724.25000000","3.24539000"],["110723.82000000","0.00440000"],["110723.62000000","0.00000000"],["110723.39000000","0.00000000"],["110723.15000000","0.04800000"],["110722.82000000","0.00000000"],["110721.84000000","1.01336000"],["110721.80000000","0.00000000"],["110721.28000000","0.00272000"],["110720.75000000","0.00000000"],["110720.29000000","3.24539000"],["110720.04000000","0.04508000"],["110719.50000000","0.00000000"],["110718.22000000","0.00000000"],["110718.07000000","0.13522000"],["110717.58000000","0.24970000"],["110717.50000000","0.00405000"],["110717.21000000","0.00000000"],["110716.93000000","1.43003000"],["110716.92000000","3.24539000"],["110716.91000000","0.00000000"],["110716.49000000","0.00000000"],["110716.03000000","0.00000000"],["110715.89000000","0.00000000"],["110715.86000000","0.00000000"],["110715.22000000","0.00000000"],["110714.64000000","0.00000000"],["110713.97000000","0.25201000"],["110713.94000000","0.00000000"],["110712.15000000","0.00012000"],["110711.94000000","0.01964000"],["110711.88000000","0.00000000"],["110711.80000000","0.00000000"],["110710.99000000","0.00000000"],["110710.64000000","0.00000000"],["110710.28000000","0.00000000"],["110709.70000000","0.02888000"],["110709.62000000","0.00000000"],["110708.40000000","0.00000000"],["110708.10000000","0.00000000"],["110706.56000000","0.06000000"],["110706.28000000","1.19847000"],["110706.00000000","0.00532000"],["110705.46000000","0.24000000"],["110704.68000000","0.03277000"],["110704.42000000","0.00000000"],["110703.60000000","0.00000000"],["110703.43000000","0.08294000"],["110703.38000000","0.00000000"],["110702.69000000","0.00000000"],["110701.86000000","0.32000000"],["110701.05000000","0.00000000"],["110700.21000000","0.11172000"],["110700.20000000","0.00000000"],["110699.07000000","0.00625000"],["110698.02000000","0.00000000"],["110697.94000000","0.00631000"],["110695.91000000","0.04343000"],["110694.96000000","0.00000000"],["110693.48000000","0.00000000"],["110692.22000000","0.00000000"],["110691.96000000","0.00000000"],["110691.95000000","0.00000000"],["110690.90000000","0.47618000"],["110690.00000000","0.02750000"],["110688.36000000","0.00000000"],["110687.68000000","0.02298000"],["110687.61000000","0.00000000"],["110687.60000000","0.00000000"],["110687.49000000","0.00000000"],["110686.89000000","0.00627000"],["110686.31000000","0.00000000"],["110685.90000000","0.00000000"],["110685.42000000","0.00000000"],["110685.33000000","0.00000000"],["110685.20000000","0.00000000"],["110684.63000000","0.00000000"],["110684.06000000","0.00000000"],["110682.99000000","0.06764000"],["110682.68000000","0.00000000"],["110681.76000000","0.00000000"],["110680.95000000","0.00000000"],["110679.87000000","0.13527000"],["110678.95000000","0.00000000"],["110678.26000000","0.00000000"],["110677.75000000","0.25943000"],["110677.67000000","0.00667000"],["110675.59000000","0.13527000"],["110675.37000000","0.02221000"],["110674.30000000","0.00000000"],["110673.10000000","0.00000000"],["110671.58000000","0.00010000"],["110671.40000000","0.00000000"],["110671.22000000","0.00000000"],["110670.36000000","0.00000000"],["110670.15000000","0.20623000"],["110670.05000000","0.00000000"],["110667.95000000","0.07328000"],["110667.65000000","0.02618000"],["110667.63000000","0.00000000"],["110667.29000000","0.02149000"],["110666.87000000","0.00000000"],["110665.20000000","0.00000000"],["110664.07000000","0.00000000"],["110663.52000000","0.00224000"],["110663.11000000","0.09641000"],["110662.50000000","0.00000000"],["110662.49000000","0.00325000"],["110661.09000000","0.00000000"],["110661.08000000","0.00000000"],["110660.54000000","0.00112000"],["110657.58000000","0.18892000"],["110656.43000000","0.00000000"],["110656.04000000","0.03939000"],["110655.66000000","0.90270000"],["110654.45000000","0.00000000"],["110654.44000000","0.00000000"],["110654.43000000","0.00000000"],["110654.35000000","0.02341000"],["110653.13000000","0.00000000"],["110652.77000000","0.00000000"],["110652.07000000","0.00000000"],["110650.66000000","0.00046000"],["110649.01000000","0.02298000"],["110648.45000000","0.02440000"],["110648.13000000","0.04040000"],["110647.79000000","0.00000000"],["110647.48000000","0.00000000"],["110645.06000000","0.09641000"],["110645.02000000","0.00000000"],["110644.37000000","0.00000000"],["110641.58000000","0.00000000"],["110640.66000000","0.00000000"],["110634.42000000","0.00000000"],["110631.58000000","0.00000000"],["110631.20000000","0.00000000"],["110631.09000000","0.00000000"],["110628.36000000","0.00000000"],["110627.54000000","0.03400000"],["110627.51000000","0.00000000"],["110627.07000000","0.00000000"],["110625.71000000","0.00000000"],["110625.47000000","0.00000000"],["110621.63000000","0.04097000"],["110616.23000000","0.02298000"],["110614.69000000","0.00000000"],["110612.01000000","0.00160000"],["110608.53000000","0.00000000"],["110607.51000000","0.00000000"],["110607.41000000","0.02528000"],["110605.89000000","0.64150000"],["110605.88000000","0.99234000"],["110605.01000000","0.00000000"],["110597.69000000","0.00000000"],["110597.27000000","0.00000000"],["110593.62000000","0.00000000"],["110593.52000000","0.00000000"],["110590.40000000","0.00000000"],["110589.62000000","0.00000000"],["110588.07000000","0.00000000"],["110586.05000000","0.00000000"],["110585.71000000","0.00000000"],["110584.30000000","0.00000000"],["110582.27000000","0.00000000"],["110560.01000000","0.00000000"],["110557.28000000","0.00000000"],["110555.94000000","0.00000000"],["110555.64000000","0.00000000"],["110555.12000000","0.00000000"],["110554.71000000","0.00000000"],["110552.93000000","0.00090000"],["110546.50000000","0.00000000"],["110519.10000000","0.00000000"],["110502.46000000","0.00064000"],["110488.66000000","0.00000000"],["110485.42000000","0.00000000"],["110443.31000000","0.00000000"],["110420.97000000","0.00000000"],["110415.44000000","0.00000000"],["110409.77000000","0.00000000"],["110405.44000000","0.00000000"],["110398.79000000","0.00333000"],["110397.75000000","0.02437000"],["110397.22000000","0.00000000"],["110396.82000000","0.00000000"],["110394.88000000","0.02438000"],["110392.49000000","0.02438000"],["110358.35000000","0.00000000"],["110354.54000000","0.00000000"],["110279.45000000","0.00000000"],["110276.28000000","0.00000000"],["110274.10000000","0.00000000"],["110269.34000000","0.00000000"],["110225.51000000","0.04596000"],["110225.07000000","0.02298000"],["110224.32000000","0.04596000"],["110224.00000000","0.02298000"],["110223.73000000","0.02298000"],["110188.98000000","0.00000000"],["110133.05000000","0.00000000"],["110133.03000000","0.00008000"],["110132.04000000","0.00000000"],["110131.98000000","0.00000000"],["110131.42000000","0.00000000"],["110131.24000000","0.00000000"],["110131.23000000","0.00000000"],["110131.22000000","0.00000000"],["109247.54000000","0.00000000"],["106200.00000000","1.59844000"],["105369.11000000","0.09855000"],["99677.00000000","0.00651000"],["99666.00000000","5.01685000"],["88604.96000000","0.00022000"],["88596.13000000","0.00000000"],["88592.00000000","0.00000000"],["42000.00000000","1.48098000"],["39866.40000000","0.00080000"]],"a":[["110740.01000000","0.00000000"],["110740.02000000","0.00000000"],["110740.09000000","0.00000000"],["110740.17000000","0.00000000"],["110740.24000000","0.00000000"],["110740.37000000","0.00000000"],["110740.38000000","0.00000000"],["110740.39000000","0.00000000"],["110740.44000000","0.00000000"],["110740.64000000","0.00000000"],["110741.71000000","0.00000000"],["110741.72000000","0.00000000"],["110742.21000000","0.00000000"],["110742.22000000","0.00000000"],["110742.86000000","0.00000000"],["110743.88000000","0.00000000"],["110743.92000000","0.00000000"],["110745.08000000","0.00000000"],["110745.10000000","0.00000000"],["110745.11000000","0.00000000"],["110745.16000000","0.00000000"],["110745.17000000","0.00000000"],["110745.56000000","0.00000000"],["110745.57000000","0.00000000"],["110745.96000000","0.00000000"],["110745.97000000","0.00000000"],["110746.50000000","0.00000000"],["110747.30000000","0.00000000"],["110747.65000000","0.00000000"],["110748.38000000","0.00000000"],["110748.64000000","0.00000000"],["110749.07000000","0.00000000"],["110749.21000000","0.00000000"],["110749.22000000","0.00000000"],["110749.23000000","0.00000000"],["110749.67000000","0.00000000"],["110749.75000000","0.00000000"],["110749.76000000","0.00000000"],["110750.00000000","0.00000000"],["110750.01000000","0.00000000"],["110750.17000000","0.00000000"],["110750.24000000","0.00000000"],["110750.25000000","0.00000000"],["110750.26000000","0.00000000"],["110750.27000000","0.00000000"],["110750.37000000","0.00000000"],["110750.39000000","0.00000000"],["110750.56000000","0.00000000"],["110750.57000000","0.00000000"],["110750.58000000","0.00000000"],["110751.00000000","0.00000000"],["110751.01000000","0.00000000"],["110751.27000000","0.00000000"],["110751.46000000","0.00000000"],["110752.08000000","0.00000000"],["110752.56000000","0.00000000"],["110752.57000000","0.00000000"],["110753.27000000","0.00000000"],["110753.32000000","0.00000000"],["110753.55000000","0.00000000"],["110753.74000000","0.00000000"],["110753.83000000","0.00000000"],["110753.84000000","0.00000000"],["110753.85000000","0.00000000"],["110753.86000000","0.00000000"],["110753.92000000","0.00000000"],["110753.93000000","0.00000000"],["110754.03000000","0.00000000"],["110754.17000000","0.00000000"],["110754.32000000","0.00000000"],["110754.35000000","0.00000000"],["110754.50000000","0.00000000"],["110754.91000000","0.00000000"],["110754.94000000","0.00000000"],["110754.95000000","0.00000000"],["110755.25000000","0.00000000"],["110755.77000000","0.00000000"],["110755.78000000","0.00000000"],["110755.84000000","0.00000000"],["110755.89000000","0.00000000"],["110755.90000000","0.00000000"],["110756.12000000","0.00000000"],["110756.19000000","0.00000000"],["110756.20000000","0.00125000"],["110756.21000000","0.00095000"],["110756.36000000","0.00000000"],["110756.50000000","0.00000000"],["110756.62000000","0.00000000"],["110756.95000000","0.00000000"],["110756.99000000","0.00000000"],["110757.00000000","0.00000000"],["110757.20000000","0.00000000"],["110757.29000000","0.00005000"],["110757.30000000","0.00000000"],["110757.87000000","0.00000000"],["110757.88000000","0.00000000"],["110757.89000000","0.00000000"],["110758.14000000","0.00000000"],["110758.41000000","0.00000000"],["110758.43000000","0.00000000"],["110758.51000000","0.00000000"],["110758.52000000","0.00000000"],["110758.53000000","0.00000000"],["110758.95000000","0.00000000"],["110758.97000000","0.00000000"],["110758.98000000","0.00000000"],["110759.05000000","0.00010000"],["110759.07000000","0.00000000"],["110759.08000000","0.00000000"],["110759.09000000","0.00000000"],["110759.49000000","0.00000000"],["110759.80000000","0.00000000"],["110759.93000000","0.00000000"],["110760.00000000","0.00005000"],["110760.01000000","0.00000000"],["110760.18000000","0.00000000"],["110760.27000000","0.00005000"],["110760.30000000","0.00010000"],["110760.35000000","0.00010000"],["110760.46000000","0.00000000"],["110760.74000000","0.00000000"],["110761.05000000","0.00005000"],["110761.19000000","0.00366000"],["110761.76000000","0.00000000"],["110761.77000000","0.00010000"],["110761.78000000","0.02015000"],["110761.86000000","0.00000000"],["110762.15000000","0.00000000"],["110762.17000000","0.00000000"],["110762.18000000","0.00000000"],["110762.26000000","0.00000000"],["110762.29000000","0.00000000"],["110762.30000000","0.00000000"],["110762.31000000","0.00000000"],["110762.59000000","0.00000000"],["110762.62000000","0.00000000"],["110762.68000000","0.00000000"],["110762.86000000","0.00000000"],["110762.98000000","0.00000000"],["110762.99000000","0.00000000"],["110763.03000000","0.00000000"],["110763.12000000","0.00000000"],["110763.26000000","0.00018000"],["110763.37000000","0.00000000"],["110763.48000000","0.00000000"],["110763.97000000","0.00000000"],["110764.20000000","0.00000000"],["110764.64000000","0.00000000"],["110764.76000000","0.00010000"],["110764.77000000","0.20831000"],["110764.78000000","0.60010000"],["110765.01000000","0.00000000"],["110765.39000000","0.00010000"],["110765.40000000","0.09566000"],["110765.89000000","0.00069000"],["110765.99000000","0.00000000"],["110766.00000000","0.00000000"],["110766.01000000","0.00000000"],["110766.30000000","0.00000000"],["110766.83000000","0.00070000"],["110766.88000000","0.00000000"],["110767.16000000","0.00000000"],["110767.17000000","0.03621000"],["110767.20000000","0.00008000"],["110767.26000000","0.00005000"],["110767.27000000","0.16375000"],["110767.28000000","0.00000000"],["110767.41000000","0.00000000"],["110767.54000000","0.00000000"],["110767.61000000","0.00000000"],["110767.69000000","0.00000000"],["110767.80000000","0.00000000"],["110767.84000000","0.00000000"],["110768.25000000","0.00000000"],["110768.62000000","0.00000000"],["110768.96000000","0.00000000"],["110769.12000000","0.00000000"],["110769.18000000","0.00010000"],["110769.40000000","0.00073000"],["110769.44000000","0.04863000"],["110769.46000000","0.00000000"],["110769.70000000","0.00000000"],["110769.71000000","0.00000000"],["110769.81000000","0.00000000"],["110770.06000000","0.00370000"],["110770.23000000","0.00000000"],["110770.24000000","0.00000000"],["110770.25000000","0.00000000"],["110770.26000000","0.00000000"],["110770.74000000","0.00005000"],["110770.84000000","0.00000000"],["110771.08000000","0.00000000"],["110771.09000000","0.45005000"],["110771.15000000","0.00000000"],["110771.34000000","0.00000000"],["110771.36000000","0.00000000"],["110771.42000000","0.00000000"],["110771.63000000","0.00000000"],["110771.77000000","0.00000000"],["110771.94000000","0.00000000"],["110772.05000000","0.00000000"],["110772.13000000","0.00000000"],["110772.28000000","0.00005000"],["110772.44000000","0.00084000"],["110772.68000000","0.00000000"],["110772.81000000","0.04662000"],["110772.84000000","0.00000000"],["110773.10000000","0.00007000"],["110773.11000000","0.00000000"],["110773.39000000","0.00000000"],["110773.45000000","0.00000000"],["110773.46000000","0.00000000"],["110773.64000000","0.00000000"],["110773.65000000","0.00000000"],["110773.66000000","0.28206000"],["110773.67000000","0.00000000"],["110773.94000000","0.00005000"],["110774.10000000","0.04149000"],["110774.22000000","0.00000000"],["110774.35000000","0.00000000"],["110774.46000000","0.45036000"],["110774.59000000","0.00000000"],["110774.67000000","0.00000000"],["110774.68000000","0.29757000"],["110774.75000000","0.00000000"],["110774.88000000","0.00000000"],["110775.03000000","0.00000000"],["110775.05000000","0.00000000"],["110775.21000000","0.04019000"],["110775.93000000","0.00000000"],["110776.02000000","0.00000000"],["110776.19000000","0.00000000"],["110776.61000000","0.00000000"],["110777.12000000","0.04000000"],["110777.13000000","0.00000000"],["110777.14000000","0.00000000"],["110777.58000000","0.00010000"],["110777.95000000","0.00000000"],["110778.60000000","0.00000000"],["110778.61000000","0.00000000"],["110778.68000000","0.00007000"],["110778.87000000","0.00000000"],["110779.29000000","0.00000000"],["110779.91000000","0.00000000"],["110780.09000000","0.00000000"],["110780.50000000","0.00000000"],["110780.76000000","0.32460000"],["110780.85000000","0.00000000"],["110780.95000000","0.00000000"],["110781.30000000","0.00000000"],["110781.60000000","0.00000000"],["110782.34000000","0.00000000"],["110782.48000000","0.00000000"],["110782.49000000","0.00000000"],["110783.01000000","0.00000000"],["110783.05000000","0.10012000"],["110783.06000000","0.00000000"],["110783.09000000","0.00000000"],["110783.23000000","0.00450000"],["110783.31000000","0.00330000"],["110783.88000000","0.11273000"],["110783.92000000","0.18026000"],["110783.93000000","0.48820000"],["110783.94000000","0.00000000"],["110784.37000000","0.01964000"],["110784.54000000","0.00000000"],["110784.99000000","0.00000000"],["110785.31000000","0.32459000"],["110785.43000000","0.00000000"],["110785.78000000","0.00000000"],["110786.01000000","0.00000000"],["110786.20000000","0.00000000"],["110786.28000000","0.04509000"],["110786.53000000","0.00000000"],["110787.11000000","0.00000000"],["110787.57000000","0.00000000"],["110787.58000000","0.00000000"],["110787.63000000","0.00000000"],["110787.93000000","0.00000000"],["110788.28000000","0.05760000"],["110788.92000000","0.06245000"],["110789.12000000","0.13522000"],["110789.43000000","0.00300000"],["110789.79000000","0.32458000"],["110790.68000000","0.00000000"],["110790.72000000","0.00000000"],["110791.15000000","0.00000000"],["110791.43000000","0.00000000"],["110791.65000000","0.08160000"],["110791.69000000","0.00000000"],["110791.75000000","0.00180000"],["110791.79000000","0.36072000"],["110791.80000000","0.49940000"],["110791.85000000","0.00000000"],["110792.37000000","0.00012000"],["110792.88000000","0.00000000"],["110792.92000000","0.13527000"],["110792.94000000","0.00000000"],["110793.09000000","0.00000000"],["110793.10000000","0.00000000"],["110793.73000000","0.00180000"],["110793.89000000","0.32457000"],["110793.94000000","0.00273000"],["110794.16000000","0.10080000"],["110794.40000000","0.00450000"],["110794.60000000","0.00000000"],["110795.21000000","0.12000000"],["110795.94000000","0.00224000"],["110796.16000000","0.00000000"],["110796.86000000","0.13527000"],["110797.60000000","0.00000000"],["110798.38000000","0.08567000"],["110799.12000000","0.00000000"],["110799.23000000","1.20423000"],["110799.67000000","0.30431000"],["110799.68000000","0.00000000"],["110800.61000000","0.00000000"],["110801.04000000","0.00005000"],["110801.21000000","1.34232000"],["110802.49000000","0.08567000"],["110803.04000000","0.00000000"],["110803.07000000","0.00000000"],["110804.60000000","0.00000000"],["110806.10000000","0.00000000"],["110806.31000000","0.02141000"],["110806.62000000","0.18031000"],["110806.67000000","0.04367000"],["110807.10000000","0.00005000"],["110807.15000000","0.00000000"],["110807.47000000","0.00000000"],["110807.76000000","0.00000000"],["110808.52000000","0.00000000"],["110810.52000000","0.00000000"],["110810.64000000","0.05598000"],["110810.71000000","0.00000000"],["110810.84000000","0.08567000"],["110810.97000000","0.01713000"],["110811.06000000","0.00000000"],["110811.85000000","0.08567000"],["110811.93000000","0.00000000"],["110811.94000000","0.00000000"],["110812.20000000","0.02144000"],["110812.42000000","0.02800000"],["110812.91000000","0.00000000"],["110813.65000000","0.00000000"],["110814.03000000","0.00000000"],["110814.39000000","0.00000000"],["110814.69000000","0.00000000"],["110817.03000000","0.22546000"],["110817.36000000","0.00000000"],["110820.22000000","0.00000000"],["110821.05000000","0.00000000"],["110821.17000000","3.24539000"],["110821.70000000","0.02204000"],["110821.74000000","0.00225000"],["110821.75000000","0.00000000"],["110821.98000000","0.08463000"],["110823.60000000","0.00000000"],["110825.27000000","0.08567000"],["110825.65000000","0.00000000"],["110827.22000000","0.00000000"],["110827.82000000","3.24539000"],["110828.00000000","0.00132000"],["110829.07000000","0.00000000"],["110829.08000000","0.00000000"],["110829.99000000","0.00000000"],["110830.00000000","0.00132000"],["110832.00000000","0.00132000"],["110834.00000000","0.00132000"],["110834.47000000","3.24539000"],["110835.19000000","0.00619000"],["110836.00000000","0.00132000"],["110836.06000000","0.00005000"],["110836.26000000","0.00625000"],["110838.00000000","0.00132000"],["110838.68000000","0.00661000"],["110839.99000000","0.00000000"],["110841.12000000","3.24539000"],["110841.36000000","0.00623000"],["110841.50000000","0.00000000"],["110842.25000000","0.00000000"],["110842.28000000","0.00000000"],["110842.55000000","0.00000000"],["110844.83000000","0.00000000"],["110845.98000000","0.00224000"],["110846.25000000","0.00000000"],["110846.26000000","0.00000000"],["110847.64000000","3.24539000"],["110847.71000000","0.00000000"],["110850.72000000","0.00000000"],["110850.95000000","0.00000000"],["110851.27000000","0.33475000"],["110852.48000000","0.00000000"],["110854.29000000","3.24539000"],["110854.91000000","0.19680000"],["110855.44000000","0.14400000"],["110855.96000000","0.19680000"],["110856.31000000","0.10567000"],["110856.64000000","0.07313000"],["110859.86000000","0.00111000"],["110860.68000000","0.00000000"],["110860.94000000","3.24539000"],["110862.61000000","0.12240000"],["110863.13000000","0.02475000"],["110863.40000000","0.00000000"],["110864.69000000","0.05760000"],["110864.82000000","0.04042000"],["110865.36000000","0.00000000"],["110865.99000000","0.00000000"],["110868.30000000","0.55954000"],["110870.11000000","0.12000000"],["110871.08000000","0.00525000"],["110872.98000000","0.00000000"],["110876.06000000","0.07712000"],["110876.95000000","0.00000000"],["110878.60000000","0.00000000"],["110882.63000000","0.05760000"],["110882.64000000","0.05760000"],["110884.15000000","0.18031000"],["110885.99000000","0.01896000"],["110886.00000000","0.20641000"],["110889.61000000","0.01715000"],["110892.42000000","0.05760000"],["110895.99000000","0.01715000"],["110896.13000000","0.00000000"],["110899.64000000","0.03997000"],["110901.33000000","0.00000000"],["110901.34000000","0.00000000"],["110902.93000000","0.00000000"],["110904.47000000","0.00000000"],["110905.99000000","0.00090000"],["110906.17000000","0.06240000"],["110906.79000000","0.00000000"],["110907.61000000","0.00000000"],["110909.68000000","0.00000000"],["110910.16000000","0.09641000"],["110911.53000000","0.10080000"],["110914.40000000","0.00000000"],["110915.28000000","0.08717000"],["110917.15000000","0.40161000"],["110922.73000000","0.00000000"],["110922.74000000","0.00000000"],["110925.52000000","0.00000000"],["110927.51000000","0.00000000"],["110931.80000000","0.02710000"],["110933.99000000","0.00090000"],["110936.77000000","0.00331000"],["110937.49000000","0.99678000"],["110939.12000000","0.00000000"],["110950.57000000","0.42012000"],["110957.00000000","0.00090000"],["110964.97000000","0.00010000"],["110989.98000000","0.00000000"],["111010.21000000","0.07311000"],["111024.75000000","0.89970000"],["111026.87000000","0.06646000"],["111043.53000000","0.23925000"],["111053.30000000","0.00000000"],["111055.86000000","0.00000000"],["111057.39000000","0.00000000"],["111058.98000000","0.00010000"],["111060.00000000","0.00113000"],["111060.16000000","0.00000000"],["111062.08000000","0.00000000"],["111067.61000000","0.00000000"],["111128.33000000","0.00000000"],["111137.86000000","0.00000000"],["111156.86000000","0.00000000"],["111169.83000000","0.00000000"],["111201.88000000","0.45000000"],["111210.51000000","0.00082000"],["111226.34000000","0.02438000"],["111236.97000000","0.02437000"],["111239.00000000","0.00000000"],["111241.28000000","0.02437000"],["111249.91000000","0.67153000"],["128001.97000000","0.03006000"]]}
[2025-10-11T22:18:34.331Z] {"e":"depthUpdate","E":1760221114014,"s":"BTCUSDT","U":77926036865,"u":77926038079,"b":[["110764.76000000","5.39774000"],["110764.69000000","0.00010000"],["110764.67000000","0.00000000"],["110764.15000000","0.00010000"],["110764.14000000","0.02001000"],["110764.13000000","0.00000000"],["110764.12000000","0.00000000"],["110764.11000000","0.00000000"],["110763.83000000","0.00000000"],["110763.67000000","0.00000000"],["110763.66000000","0.00000000"],["110763.65000000","0.00000000"],["110763.40000000","0.00010000"],["110763.39000000","0.06656000"],["110763.01000000","0.00000000"],["110763.00000000","0.00000000"],["110762.85000000","0.00005000"],["110762.55000000","0.00361000"],["110761.77000000","0.00000000"],["110761.34000000","0.00000000"],["110761.21000000","0.00010000"],["110761.20000000","0.18055000"],["110761.19000000","0.19835000"],["110761.18000000","0.00000000"],["110760.89000000","0.00542000"],["110760.63000000","0.00005000"],["110760.23000000","0.00000000"],["110760.00000000","0.00005000"],["110759.99000000","0.00000000"],["110759.84000000","0.00000000"],["110759.83000000","0.00000000"],["110759.82000000","0.00000000"],["110759.78000000","0.00000000"],["110759.56000000","0.00000000"],["110759.28000000","0.08572000"],["110759.22000000","0.00149000"],["110759.04000000","0.00000000"],["110758.88000000","0.00005000"],["110758.62000000","0.00005000"],["110758.45000000","0.00000000"],["110757.77000000","0.04054000"],["110757.72000000","0.00000000"],["110757.70000000","0.00005000"],["110757.69000000","0.00000000"],["110756.22000000","0.00000000"],["110756.20000000","0.00000000"],["110756.19000000","0.53643000"],["110756.11000000","0.00000000"],["110756.00000000","0.00400000"],["110755.49000000","0.18026000"],["110755.42000000","0.00005000"],["110753.85000000","0.00000000"],["110753.84000000","0.30470000"],["110753.83000000","0.00201000"],["110753.68000000","0.45000000"],["110753.50000000","0.00000000"],["110752.72000000","0.00000000"],["110752.55000000","0.00000000"],["110752.31000000","0.00005000"],["110752.08000000","0.04800000"],["110751.94000000","0.18026000"],["110751.88000000","0.05738000"],["110750.99000000","0.22546000"],["110750.94000000","0.00010000"],["110750.48000000","0.04800000"],["110750.47000000","0.04800000"],["110750.36000000","0.10510000"],["110750.01000000","0.20209000"],["110750.00000000","0.36214000"],["110749.87000000","0.07200000"],["110749.22000000","0.00000000"],["110749.21000000","0.00000000"],["110748.27000000","0.07200000"],["110748.15000000","0.00149000"],["110748.14000000","0.11273000"],["110747.26000000","0.04800000"],["110747.10000000","0.04800000"],["110746.40000000","0.00007000"],["110745.41000000","0.00010000"],["110744.83000000","0.04800000"],["110743.92000000","0.00000000"],["110743.67000000","0.00000000"],["110743.16000000","0.00000000"],["110742.60000000","0.00300000"],["110742.19000000","0.04800000"],["110741.79000000","0.00000000"],["110741.21000000","0.36072000"],["110740.00000000","0.00109000"],["110739.84000000","0.00005000"],["110739.73000000","0.13527000"],["110738.56000000","0.00403000"],["110738.14000000","0.00000000"],["110737.70000000","0.00000000"],["110737.69000000","0.00000000"],["110736.37000000","0.00000000"],["110736.13000000","0.00000000"],["110735.43000000","0.00000000"],["110735.02000000","0.00000000"],["110731.77000000","0.00000000"],["110726.16000000","0.25201000"],["110726.14000000","0.24970000"],["110725.14000000","0.18031000"],["110722.47000000","1.22582000"],["110720.04000000","0.00000000"],["110718.25000000","0.00000000"],["110718.13000000","0.00000000"],["110717.96000000","0.06000000"],["110717.61000000","0.13544000"],["110717.58000000","0.00000000"],["110716.77000000","0.00000000"],["110715.27000000","0.00000000"],["110713.97000000","0.00000000"],["110713.83000000","0.04422000"],["110709.70000000","0.00000000"],["110709.33000000","0.00010000"],["110706.56000000","0.00000000"],["110706.28000000","0.00000000"],["110704.68000000","0.00000000"],["110704.08000000","0.00000000"],["110702.61000000","0.00000000"],["110695.91000000","0.00000000"],["110694.82000000","0.00000000"],["110694.29000000","3.24539000"],["110694.26000000","0.00000000"],["110694.25000000","0.00000000"],["110693.62000000","0.00649000"],["110689.90000000","0.00000000"],["110689.34000000","0.03997000"],["110688.07000000","0.11349000"],["110686.01000000","0.03997000"],["110681.57000000","0.02900000"],["110681.45000000","0.04080000"],["110679.87000000","0.00000000"],["110678.26000000","0.90252000"],["110677.69000000","0.13527000"],["110677.67000000","0.00000000"],["110677.40000000","0.03277000"],["110676.11000000","0.03997000"],["110674.37000000","0.02998000"],["110672.86000000","0.03997000"],["110672.02000000","0.00224000"],["110671.90000000","0.02341000"],["110670.05000000","0.03966000"],["110668.97000000","0.03997000"],["110668.29000000","0.02425000"],["110665.33000000","0.00000000"],["110664.01000000","0.02998000"],["110663.52000000","0.00000000"],["110662.42000000","0.00000000"],["110660.51000000","0.00000000"],["110658.62000000","0.05622000"],["110656.86000000","0.00000000"],["110655.99000000","0.00000000"],["110655.95000000","0.00000000"],["110655.67000000","0.69974000"],["110655.57000000","0.13544000"],["110655.40000000","0.18031000"],["110654.44000000","0.22546000"],["110654.35000000","0.00000000"],["110654.01000000","0.03997000"],["110653.67000000","0.00000000"],["110652.06000000","0.00000000"],["110650.34000000","0.22546000"],["110650.09000000","0.00000000"],["110649.53000000","0.00000000"],["110649.01000000","0.06295000"],["110648.45000000","0.00000000"],["110648.33000000","0.26711000"],["110648.13000000","0.00000000"],["110647.67000000","0.00000000"],["110647.32000000","0.00000000"],["110645.59000000","0.00000000"],["110644.01000000","0.03997000"],["110636.31000000","0.04075000"],["110625.64000000","0.99287000"],["110623.12000000","0.00000000"],["110621.64000000","0.00160000"],["110612.01000000","0.00000000"],["110605.89000000","0.00000000"],["110605.88000000","0.00000000"],["110585.17000000","0.00000000"],["110572.89000000","0.02998000"],["110558.69000000","0.00000000"],["110542.81000000","0.04297000"],["110529.52000000","0.00000000"],["110495.75000000","0.02998000"],["110472.85000000","0.00000000"],["110432.96000000","0.04297000"],["110426.84000000","0.00000000"],["110423.89000000","0.00000000"],["110398.79000000","0.00000000"],["110386.86000000","0.02998000"],["110381.70000000","0.00333000"],["110133.96000000","0.00000000"],["109349.55000000","0.00429000"],["109106.30000000","0.00000000"],["99687.00000000","0.00010000"],["99680.00000000","0.00406000"],["99666.00000000","5.01675000"],["98000.00000000","109.05912000"],["88611.81000000","0.00022000"],["88604.96000000","0.00000000"],["39875.32000000","0.00016000"]],"a":[["110756.20000000","0.00000000"],["110756.21000000","0.00000000"],["110757.29000000","0.00000000"],["110757.70000000","0.00000000"],["110758.62000000","0.00000000"],["110759.05000000","0.00000000"],["110760.00000000","0.00000000"],["110760.27000000","0.00000000"],["110760.30000000","0.00000000"],["110760.35000000","0.00000000"],["110761.05000000","0.00000000"],["110761.19000000","0.00000000"],["110761.77000000","0.00000000"],["110761.78000000","0.00000000"],["110763.26000000","0.00000000"],["110763.84000000","0.00000000"],["110764.68000000","0.00000000"],["110764.76000000","0.00000000"],["110764.77000000","3.97212000"],["110764.78000000","0.00075000"],["110764.85000000","0.00010000"],["110765.39000000","0.00000000"],["110765.40000000","0.00000000"],["110765.61000000","0.00000000"],["110765.88000000","0.00000000"],["110765.89000000","0.00000000"],["110766.83000000","0.00000000"],["110767.16000000","0.00000000"],["110767.17000000","0.00000000"],["110767.20000000","0.00000000"],["110767.26000000","0.00000000"],["110767.27000000","0.00000000"],["110767.59000000","0.00000000"],["110768.19000000","0.00000000"],["110768.46000000","0.00010000"],["110768.47000000","0.05210000"],["110768.64000000","0.00542000"],["110769.18000000","0.00005000"],["110769.37000000","0.00000000"],["110769.40000000","0.00000000"],["110769.43000000","0.00000000"],["110769.44000000","0.00000000"],["110769.50000000","0.00000000"],["110769.51000000","0.00078000"],["110769.75000000","0.00722000"],["110769.98000000","0.00010000"],["110769.99000000","0.04010000"],["110770.06000000","0.00305000"],["110770.96000000","0.00010000"],["110770.97000000","0.05505000"],["110771.09000000","0.00000000"],["110771.78000000","0.00010000"],["110771.79000000","0.02020000"],["110772.00000000","0.00005000"],["110772.01000000","0.25616000"],["110772.02000000","0.29763000"],["110772.17000000","0.00000000"],["110772.18000000","0.00000000"],["110772.19000000","0.24005000"],["110772.28000000","0.00000000"],["110772.29000000","0.32005000"],["110772.44000000","0.00000000"],["110772.80000000","0.00000000"],["110772.81000000","0.04513000"],["110773.10000000","0.00000000"],["110773.65000000","0.00000000"],["110773.66000000","0.15787000"],["110773.92000000","0.04000000"],["110773.94000000","0.00000000"],["110774.09000000","0.00000000"],["110774.10000000","0.00000000"],["110774.46000000","0.45036000"],["110774.68000000","0.00000000"],["110774.70000000","0.00000000"],["110775.21000000","0.00000000"],["110775.47000000","0.00000000"],["110775.85000000","0.00149000"],["110776.01000000","0.00000000"],["110776.15000000","0.00000000"],["110776.37000000","0.00000000"],["110776.58000000","0.00000000"],["110776.83000000","0.00000000"],["110777.12000000","0.00000000"],["110777.69000000","0.00000000"],["110777.71000000","0.00005000"],["110777.77000000","0.03616000"],["110778.02000000","0.25178000"],["110778.03000000","0.32461000"],["110778.61000000","0.00005000"],["110778.65000000","0.04064000"],["110779.15000000","0.00000000"],["110779.16000000","0.00000000"],["110779.17000000","0.08669000"],["110779.75000000","0.00450000"],["110779.76000000","0.04090000"],["110779.94000000","0.00000000"],["110780.34000000","0.00000000"],["110780.49000000","0.32460000"],["110780.73000000","0.00000000"],["110780.75000000","0.00000000"],["110780.76000000","0.00000000"],["110781.38000000","0.00154000"],["110781.58000000","0.00000000"],["110781.67000000","0.00007000"],["110782.17000000","0.00000000"],["110782.26000000","0.00005000"],["110782.44000000","0.30435000"],["110782.45000000","0.01777000"],["110782.63000000","0.00000000"],["110783.05000000","0.00000000"],["110783.23000000","0.00000000"],["110783.24000000","0.00300000"],["110783.88000000","0.11273000"],["110783.92000000","0.00000000"],["110784.37000000","0.00000000"],["110785.10000000","0.18026000"],["110785.11000000","0.00000000"],["110785.18000000","0.32459000"],["110785.31000000","0.00000000"],["110785.32000000","0.00000000"],["110785.94000000","0.00074000"],["110786.14000000","0.00000000"],["110786.28000000","0.00000000"],["110786.67000000","0.00070000"],["110787.50000000","0.00000000"],["110787.86000000","0.00000000"],["110788.00000000","0.00100000"],["110788.21000000","0.00000000"],["110789.11000000","0.00000000"],["110789.25000000","0.32458000"],["110789.79000000","0.00000000"],["110789.83000000","0.07680000"],["110789.99000000","0.11520000"],["110790.43000000","0.36072000"],["110790.46000000","0.01964000"],["110790.59000000","0.00005000"],["110790.98000000","0.01173000"],["110791.79000000","0.00000000"],["110792.20000000","0.14400000"],["110792.50000000","0.05280000"],["110792.92000000","0.00000000"],["110793.89000000","0.00000000"],["110794.56000000","0.00000000"],["110794.57000000","3.24539000"],["110794.74000000","0.12240000"],["110795.94000000","0.00000000"],["110796.16000000","0.00000000"],["110796.20000000","0.08567000"],["110797.50000000","0.08160000"],["110797.87000000","0.08567000"],["110798.38000000","0.00000000"],["110798.53000000","0.01789000"],["110799.66000000","0.00000000"],["110799.67000000","0.00000000"],["110800.25000000","0.00901000"],["110803.92000000","0.00224000"],["110804.60000000","0.00005000"],["110806.04000000","0.00000000"],["110806.67000000","0.00000000"],["110808.62000000","0.13527000"],["110810.33000000","0.22546000"],["110811.04000000","0.00000000"],["110811.85000000","0.00000000"],["110811.95000000","1.11966000"],["110812.22000000","0.00000000"],["110812.76000000","0.00000000"],["110813.16000000","0.00005000"],["110813.99000000","0.02437000"],["110817.85000000","0.00000000"],["110819.22000000","0.00005000"],["110819.90000000","0.00000000"],["110820.37000000","0.00000000"],["110820.74000000","0.00000000"],["110821.74000000","0.00000000"],["110822.94000000","0.00000000"],["110823.82000000","0.00000000"],["110824.57000000","0.00000000"],["110824.61000000","0.04480000"],["110825.78000000","0.06733000"],["110834.90000000","0.13544000"],["110836.85000000","0.00225000"],["110839.26000000","0.03150000"],["110845.98000000","0.00000000"],["110846.46000000","0.02178000"],["110847.63000000","1.23859000"],["110847.81000000","0.00000000"],["110851.28000000","0.00000000"],["110854.28000000","0.00225000"],["110856.92000000","0.00000000"],["110868.48000000","0.13527000"],["110871.08000000","0.00000000"],["110874.65000000","0.00000000"],["110878.33000000","0.05280000"],["110879.45000000","0.00000000"],["110883.17000000","0.00000000"],["110887.40000000","0.00525000"],["110890.34000000","0.00000000"],["110891.78000000","0.00036000"],["110892.42000000","0.00000000"],["110895.98000000","0.16890000"],["110895.99000000","0.15259000"],["110898.09000000","0.22546000"],["110905.99000000","0.00000000"],["110906.17000000","0.00000000"],["110911.53000000","0.00000000"],["110913.96000000","0.00000000"],["110914.44000000","0.00090000"],["110917.72000000","0.00000000"],["110919.59000000","0.00331000"],["110931.80000000","0.00000000"],["110933.99000000","0.00000000"],["110936.77000000","0.00000000"],["110937.48000000","0.44031000"],["110937.49000000","0.99758000"],["110947.45000000","0.00090000"],["110957.00000000","0.00000000"],["110964.96000000","0.00090000"],["110968.86000000","0.02618000"],["110984.98000000","1.72802000"],["111040.50000000","0.00000000"],["111057.80000000","0.02618000"],["111066.15000000","0.00010000"],["111070.96000000","0.02618000"],["111071.68000000","0.00010000"],["111193.33000000","0.00082000"],["111210.51000000","0.00000000"],["111246.20000000","0.45000000"],["112399.00000000","0.00000000"],["112650.34000000","0.00428000"],["128001.97000000","0.00040000"]]}
