[2025-10-11T22:18:35.331Z] {"e":"depthUpdate","E":1760221115014,"s":"BTCUSDT","U":77926038080,"u":77926038512,"b":[["110764.76000000","3.30137000"],["110764.15000000","0.00000000"],["110764.14000000","0.00000000"],["110763.40000000","0.00000000"],["110763.39000000","0.00000000"],["110762.85000000","0.00000000"],["110761.21000000","0.00000000"],["110761.20000000","0.00010000"],["110761.19000000","0.02790000"],["110760.89000000","0.00547000"],["110759.29000000","0.00000000"],["110759.28000000","0.00000000"],["110758.88000000","0.00000000"],["110758.52000000","0.00005000"],["110757.78000000","0.00010000"],["110757.77000000","0.04059000"],["110756.21000000","0.00000000"],["110756.20000000","0.00010000"],["110756.19000000","0.04519000"],["110756.00000000","0.00000000"],["110755.50000000","0.00010000"],["110755.49000000","0.18036000"],["110753.86000000","0.00005000"],["110753.85000000","0.18041000"],["110753.84000000","0.30475000"],["110753.68000000","0.45005000"],["110752.23000000","0.08567000"],["110750.99000000","0.00000000"],["110750.74000000","0.00074000"],["110750.01000000","0.00000000"],["110749.52000000","0.00327000"],["110749.21000000","0.00005000"],["110749.02000000","0.00070000"],["110747.64000000","0.18026000"],["110747.27000000","0.00000000"],["110746.49000000","0.01771000"],["110745.95000000","0.00000000"],["110745.16000000","0.00000000"],["110743.94000000","0.20210000"],["110743.93000000","0.25479000"],["110743.87000000","0.00000000"],["110743.69000000","0.00000000"],["110741.70000000","0.00000000"],["110741.21000000","0.00000000"],["110740.76000000","0.00000000"],["110740.65000000","0.00005000"],["110740.00000000","0.00010000"],["110737.68000000","0.36072000"],["110735.70000000","0.00000000"],["110734.21000000","0.00000000"],["110731.91000000","0.00000000"],["110731.53000000","0.00009000"],["110728.92000000","0.00000000"],["110724.63000000","0.22546000"],["110723.92000000","0.04000000"],["110722.48000000","1.53659000"],["110721.84000000","0.00000000"],["110719.84000000","0.22546000"],["110714.67000000","0.04800000"],["110712.24000000","0.04800000"],["110711.94000000","0.00000000"],["110706.97000000","0.00000000"],["110698.30000000","0.00009000"],["110684.01000000","0.06995000"],["110681.57000000","0.00012000"],["110681.45000000","0.08077000"],["110680.39000000","0.04297000"],["110680.23000000","0.52137000"],["110677.40000000","0.07274000"],["110674.01000000","0.06915000"],["110673.75000000","0.00000000"],["110673.51000000","0.06995000"],["110671.90000000","0.00000000"],["110670.17000000","0.03997000"],["110667.88000000","0.02888000"],["110666.90000000","0.07002000"],["110665.07000000","0.00009000"],["110659.17000000","0.02341000"],["110656.04000000","0.07936000"],["110652.01000000","0.05622000"],["110650.34000000","0.00000000"],["110647.26000000","0.05622000"],["110644.61000000","0.11101000"],["110643.59000000","0.03997000"],["110642.30000000","0.22546000"],["110640.52000000","0.00000000"],["110634.81000000","0.03997000"],["110631.84000000","0.00009000"],["110625.64000000","0.00000000"],["110623.29000000","0.06000000"],["110607.30000000","0.00000000"],["110604.46000000","0.99667000"],["110598.61000000","0.00009000"],["110574.08000000","0.00000000"],["110381.70000000","0.00000000"],["110363.95000000","0.00000000"],["110338.18000000","0.00333000"],["110239.76000000","0.02298000"],["110238.66000000","0.02298000"],["110174.67000000","0.02298000"],["110173.92000000","0.02298000"],["110100.18000000","0.00000000"],["109161.10000000","0.00055000"],["105392.66000000","0.00273000"],["105000.00000000","233.38782000"],["103000.00000000","76.14900000"],["101905.53000000","0.00000000"],["99688.00000000","0.01141000"],["99687.00000000","0.00010000"],["88611.81000000","0.00022000"],["39875.32000000","0.00048000"]],"a":[["110764.77000000","4.44956000"],["110764.78000000","0.00090000"],["110768.47000000","0.05215000"],["110768.55000000","0.00000000"],["110768.56000000","0.00000000"],["110768.64000000","0.00557000"],["110769.42000000","0.00010000"],["110769.43000000","0.04524000"],["110769.50000000","0.00010000"],["110769.51000000","0.30124000"],["110769.52000000","0.29768000"],["110769.75000000","0.00727000"],["110769.98000000","0.00005000"],["110769.99000000","0.04005000"],["110770.06000000","0.00310000"],["110770.26000000","0.01815000"],["110770.62000000","0.01810000"],["110770.96000000","0.00000000"],["110770.97000000","0.05495000"],["110771.78000000","0.00000000"],["110771.79000000","0.02015000"],["110772.00000000","0.00400000"],["110772.01000000","0.00000000"],["110772.02000000","0.00000000"],["110772.19000000","0.24000000"],["110772.29000000","0.32000000"],["110772.81000000","0.04503000"],["110773.42000000","0.00000000"],["110773.66000000","0.23586000"],["110773.92000000","0.04010000"],["110774.45000000","0.00005000"],["110775.84000000","0.00000000"],["110775.85000000","0.32611000"],["110776.35000000","0.06646000"],["110777.76000000","0.00450000"],["110778.01000000","0.18026000"],["110778.03000000","0.00000000"],["110778.36000000","0.00000000"],["110779.09000000","0.00000000"],["110779.17000000","0.08664000"],["110779.75000000","0.00000000"],["110779.76000000","0.04085000"],["110781.38000000","0.00149000"],["110781.77000000","0.18026000"],["110783.50000000","0.00400000"],["110783.86000000","2.48068000"],["110783.87000000","3.24539000"],["110783.93000000","0.00000000"],["110785.94000000","0.00000000"],["110786.51000000","0.02033000"],["110786.67000000","0.00000000"],["110787.67000000","3.24539000"],["110789.20000000","0.01964000"],["110790.46000000","0.00000000"],["110792.88000000","0.13527000"],["110798.00000000","0.00109000"],["110806.64000000","0.00000000"],["110808.62000000","0.00000000"],["110817.92000000","0.00000000"],["110819.38000000","0.13544000"],["110819.42000000","1.21941000"],["110831.23000000","0.00009000"],["110834.90000000","0.00000000"],["110839.87000000","0.00000000"],["110855.36000000","0.13527000"],["110857.11000000","0.30475000"],["110860.94000000","0.00000000"],["110864.46000000","0.00009000"],["110865.37000000","0.08160000"],["110868.48000000","0.00000000"],["110873.09000000","0.00000000"],["110875.00000000","0.03538000"],["110875.86000000","0.00331000"],["110879.62000000","0.13544000"],["110882.85000000","0.00000000"],["110895.99000000","0.01715000"],["110897.69000000","0.00009000"],["110901.56000000","0.03718000"],["110906.31000000","0.00000000"],["110917.09000000","0.02527000"],["110919.59000000","0.00000000"],["110930.92000000","0.00009000"],["110932.96000000","0.02710000"],["110937.48000000","0.00000000"],["110937.49000000","0.99650000"],["110947.45000000","0.11470000"],["110951.98000000","0.02616000"],["110977.82000000","0.08500000"],["111043.53000000","0.00000000"],["111149.14000000","0.02998000"],["111149.56000000","0.00082000"],["111193.33000000","0.00000000"],["111315.22000000","0.00044000"],["112426.24000000","0.00010000"],["128001.97000000","0.00040000"]]}
[2025-10-11T22:18:36.331Z] {"e":"depthUpdate","E":1760221116014,"s":"BTCUSDT","U":77926038513,"u":77926039416,"b":[["110767.99000000","8.26146000"],["110767.92000000","0.00010000"],["110764.84000000","0.00000000"],["110764.79000000","0.00000000"],["110764.78000000","0.39500000"],["110764.77000000","0.38242000"],["110764.76000000","0.80170000"],["110764.69000000","0.00000000"],["110764.68000000","0.00005000"],["110762.56000000","0.00000000"],["110761.62000000","0.00005000"],["110761.22000000","0.15725000"],["110761.21000000","0.00000000"],["110761.20000000","0.00000000"],["110761.19000000","0.00000000"],["110760.90000000","0.00000000"],["110760.89000000","0.00547000"],["110760.14000000","0.00000000"],["110760.13000000","0.06651000"],["110759.68000000","0.11278000"],["110758.91000000","0.05269000"],["110758.90000000","0.18031000"],["110758.89000000","0.00000000"],["110758.88000000","0.04090000"],["110758.13000000","0.00074000"],["110757.79000000","0.00000000"],["110757.78000000","0.00000000"],["110757.77000000","0.04049000"],["110757.72000000","0.01827000"],["110756.91000000","0.00300000"],["110756.20000000","0.00000000"],["110756.19000000","0.00000000"],["110755.50000000","0.00000000"],["110755.49000000","0.18026000"],["110755.00000000","0.00400000"],["110754.35000000","0.00005000"],["110754.17000000","0.00010000"],["110753.86000000","0.00000000"],["110753.85000000","0.00000000"],["110753.84000000","0.30470000"],["110753.68000000","0.45000000"],["110752.24000000","0.36070000"],["110752.23000000","0.00000000"],["110751.88000000","0.00000000"],["110750.74000000","0.00000000"],["110749.52000000","0.00000000"],["110749.02000000","0.00000000"],["110748.64000000","0.00006000"],["110748.15000000","0.00000000"],["110748.14000000","0.00000000"],["110743.94000000","0.00000000"],["110742.01000000","0.00022000"],["110739.91000000","0.00005000"],["110739.81000000","0.04000000"],["110739.78000000","0.01964000"],["110739.72000000","0.00000000"],["110737.69000000","3.24539000"],["110737.68000000","0.00000000"],["110734.37000000","0.97177000"],["110730.59000000","0.00012000"],["110729.36000000","0.24940000"],["110728.89000000","0.00000000"],["110726.14000000","0.00000000"],["110725.74000000","0.00000000"],["110725.14000000","0.00000000"],["110724.63000000","0.00000000"],["110723.92000000","0.00000000"],["110720.87000000","0.13544000"],["110719.84000000","0.00000000"],["110719.55000000","0.00000000"],["110718.23000000","0.00000000"],["110717.62000000","0.02618000"],["110717.61000000","0.00000000"],["110717.00000000","0.06062000"],["110712.28000000","0.02618000"],["110712.15000000","0.00000000"],["110710.14000000","0.00000000"],["110700.90000000","3.27157000"],["110694.89000000","0.03277000"],["110694.30000000","0.00000000"],["110694.29000000","0.00000000"],["110687.55000000","0.02888000"],["110679.90000000","0.02998000"],["110677.40000000","0.03997000"],["110668.62000000","0.00000000"],["110667.88000000","0.00000000"],["110667.80000000","0.05660000"],["110663.51000000","0.00010000"],["110659.53000000","0.00000000"],["110658.87000000","0.00000000"],["110658.85000000","0.00000000"],["110658.83000000","0.13544000"],["110658.75000000","0.18031000"],["110658.08000000","0.00007000"],["110657.95000000","0.22553000"],["110655.57000000","0.00000000"],["110655.40000000","0.00000000"],["110654.44000000","0.00000000"],["110654.01000000","0.07994000"],["110650.01000000","0.03997000"],["110644.61000000","0.00000000"],["110643.80000000","0.00005000"],["110643.55000000","0.00000000"],["110642.30000000","0.00000000"],["110640.32000000","0.03997000"],["110633.13000000","0.00000000"],["110615.24000000","0.00000000"],["110608.88000000","0.16306000"],["110607.38000000","0.13215000"],["110604.46000000","0.00000000"],["110574.74000000","0.00000000"],["110571.44000000","0.00000000"],["110540.48000000","0.00067000"],["110511.74000000","0.00000000"],["110431.05000000","0.00000000"],["110357.14000000","0.00052000"],["110278.52000000","0.00000000"],["110100.18000000","0.00000000"],["109890.60000000","0.00000000"],["109500.00000000","9.48385000"],["109250.00000000","0.20466000"],["103452.00000000","0.00014000"],["99688.00000000","0.01141000"],["99687.00000000","0.00010000"],["88614.40000000","0.00022000"],["88611.81000000","0.00000000"],["39875.32000000","0.00064000"]],"a":[["110764.77000000","0.00000000"],["110764.78000000","0.00000000"],["110764.85000000","0.00000000"],["110768.00000000","1.25673000"],["110768.01000000","0.00095000"],["110768.08000000","0.00010000"],["110768.46000000","0.00000000"],["110768.47000000","0.00005000"],["110768.64000000","0.00552000"],["110769.42000000","0.00000000"],["110769.43000000","0.00000000"],["110769.50000000","0.00000000"],["110769.51000000","0.00000000"],["110769.52000000","0.00000000"],["110769.75000000","0.00727000"],["110769.98000000","0.00000000"],["110769.99000000","0.00000000"],["110770.06000000","0.00310000"],["110770.26000000","0.00000000"],["110770.62000000","0.00000000"],["110770.95000000","0.00010000"],["110770.96000000","0.02274000"],["110770.97000000","0.05505000"],["110771.78000000","0.00010000"],["110771.79000000","0.02015000"],["110772.00000000","0.00000000"],["110772.17000000","0.00000000"],["110772.18000000","0.00000000"],["110772.19000000","0.00000000"],["110772.29000000","0.00000000"],["110772.55000000","0.00000000"],["110772.81000000","0.00000000"],["110773.65000000","0.00010000"],["110773.66000000","0.23596000"],["110773.92000000","0.00000000"],["110774.08000000","0.00005000"],["110774.09000000","0.52005000"],["110774.19000000","0.08010000"],["110774.24000000","0.04395000"],["110774.45000000","0.00010000"],["110774.46000000","0.45041000"],["110775.16000000","0.00000000"],["110775.85000000","0.00000000"],["110776.35000000","0.00000000"],["110777.71000000","0.00000000"],["110777.76000000","0.00000000"],["110777.77000000","0.00010000"],["110777.86000000","0.00000000"],["110778.01000000","0.00000000"],["110778.02000000","0.13837000"],["110778.27000000","0.00000000"],["110778.45000000","0.00073000"],["110778.61000000","0.04503000"],["110778.65000000","0.00000000"],["110778.69000000","0.00000000"],["110778.72000000","0.00069000"],["110779.16000000","0.00000000"],["110779.17000000","0.08659000"],["110779.76000000","0.00005000"],["110780.30000000","0.00000000"],["110780.40000000","0.00000000"],["110780.48000000","0.00000000"],["110780.49000000","0.00000000"],["110781.38000000","0.00159000"],["110781.45000000","0.03611000"],["110781.50000000","0.00000000"],["110781.67000000","0.00000000"],["110781.69000000","0.29755000"],["110781.77000000","0.00000000"],["110781.85000000","0.00069000"],["110781.87000000","0.03965000"],["110782.44000000","0.00000000"],["110782.45000000","0.00000000"],["110782.61000000","0.04130000"],["110782.67000000","0.00070000"],["110783.24000000","0.00305000"],["110783.31000000","0.00330000"],["110783.50000000","0.00000000"],["110783.80000000","0.00000000"],["110783.86000000","0.50213000"],["110783.87000000","0.00000000"],["110784.24000000","0.00000000"],["110784.90000000","0.00007000"],["110785.00000000","0.01803000"],["110785.09000000","0.00000000"],["110785.10000000","0.00000000"],["110785.18000000","0.00000000"],["110785.24000000","0.00000000"],["110785.99000000","0.00000000"],["110786.14000000","0.00000000"],["110786.51000000","0.00000000"],["110787.12000000","0.32458000"],["110787.50000000","0.00000000"],["110787.67000000","0.00000000"],["110787.99000000","0.00000000"],["110788.40000000","0.04000000"],["110789.25000000","0.00000000"],["110789.43000000","0.00000000"],["110789.61000000","0.32458000"],["110789.82000000","0.00000000"],["110790.43000000","0.00450000"],["110791.61000000","0.00000000"],["110792.88000000","0.00000000"],["110794.15000000","0.00000000"],["110794.88000000","0.32456000"],["110795.20000000","0.00000000"],["110796.16000000","0.57100000"],["110797.40000000","0.32455000"],["110797.87000000","0.00000000"],["110798.52000000","0.30431000"],["110799.99000000","0.00000000"],["110801.20000000","0.36070000"],["110801.24000000","0.00300000"],["110803.08000000","0.45000000"],["110804.78000000","0.08567000"],["110808.68000000","0.13527000"],["110825.78000000","0.00000000"],["110826.16000000","0.00000000"],["110827.39000000","0.06925000"],["110834.46000000","1.21516000"],["110842.61000000","0.13522000"],["110850.12000000","0.00000000"],["110850.13000000","0.00000000"],["110860.94000000","3.24539000"],["110868.29000000","0.55637000"],["110868.51000000","0.00000000"],["110875.00000000","0.00000000"],["110906.06000000","0.27155000"],["110907.46000000","0.08394000"],["110919.37000000","0.00000000"],["110920.45000000","0.00000000"],["110936.38000000","0.05430000"],["110937.49000000","0.99113000"],["110942.76000000","0.15857000"],["110957.99000000","0.10516000"],["110979.10000000","0.00000000"],["110989.02000000","0.06086000"],["111043.53000000","0.23925000"],["111060.19000000","0.09304000"],["111242.64000000","0.67153000"],["111249.91000000","0.00000000"],["111309.68000000","0.00046000"],["111315.22000000","0.00000000"],["128001.97000000","0.00040000"]]}
[2025-10-11T22:18:37.332Z] {"e":"depthUpdate","E":1760221117014,"s":"BTCUSDT","U":77926039417,"u":77926042266,"b":[["110788.19000000","8.98711000"],["110788.11000000","0.00010000"],["110788.00000000","0.00000000"],["110787.99000000","0.00000000"],["110787.78000000","0.00000000"],["110787.71000000","0.01227000"],["110787.70000000","0.04088000"],["110787.36000000","0.00000000"],["110786.45000000","0.00000000"],["110784.60000000","0.00000000"],["110783.85000000","0.00000000"],["110783.26000000","0.00000000"],["110783.25000000","1.67234000"],["110783.24000000","0.20223000"],["110783.23000000","0.28670000"],["110782.86000000","0.00005000"],["110782.83000000","0.00005000"],["110782.71000000","0.00000000"],["110782.50000000","0.01405000"],["110782.20000000","0.00000000"],["110782.19000000","0.00015000"],["110782.18000000","0.39907000"],["110782.08000000","0.00000000"],["110782.02000000","0.00908000"],["110781.80000000","0.01359000"],["110781.59000000","0.08567000"],["110781.44000000","0.00000000"],["110781.37000000","0.00000000"],["110780.98000000","0.00000000"],["110780.49000000","0.00000000"],["110780.00000000","0.00005000"],["110779.16000000","0.00000000"],["110779.15000000","0.00000000"],["110778.78000000","0.00000000"],["110778.77000000","0.00000000"],["110778.76000000","0.00000000"],["110778.37000000","0.00000000"],["110777.79000000","0.00000000"],["110776.80000000","0.00005000"],["110776.79000000","0.00000000"],["110776.36000000","0.00000000"],["110776.31000000","0.00000000"],["110776.30000000","0.32168000"],["110776.29000000","0.18026000"],["110776.28000000","0.08236000"],["110776.20000000","0.00000000"],["110775.91000000","0.00000000"],["110775.68000000","0.00000000"],["110774.95000000","0.00000000"],["110774.94000000","0.00000000"],["110774.93000000","0.06646000"],["110774.72000000","0.00000000"],["110774.45000000","0.00000000"],["110774.36000000","0.00010000"],["110774.32000000","0.03981000"],["110774.23000000","0.00000000"],["110774.18000000","0.00000000"],["110774.08000000","0.00000000"],["110773.88000000","0.00000000"],["110773.83000000","0.00000000"],["110773.79000000","0.11911000"],["110773.65000000","0.00000000"],["110773.54000000","0.00000000"],["110773.21000000","0.04098000"],["110772.48000000","0.18026000"],["110771.78000000","0.00000000"],["110770.96000000","0.00000000"],["110770.94000000","0.04734000"],["110770.74000000","0.00005000"],["110770.63000000","0.01829000"],["110770.19000000","0.00000000"],["110770.05000000","0.00000000"],["110769.78000000","0.00333000"],["110769.74000000","0.00000000"],["110769.17000000","0.00000000"],["110768.63000000","0.00000000"],["110768.48000000","0.00007000"],["110768.46000000","0.00000000"],["110768.32000000","0.00010000"],["110768.13000000","0.17997000"],["110768.12000000","0.18026000"],["110768.07000000","0.00000000"],["110768.02000000","0.00000000"],["110768.01000000","0.00000000"],["110768.00000000","0.23149000"],["110767.99000000","0.24000000"],["110767.92000000","0.00000000"],["110767.78000000","0.00000000"],["110767.75000000","0.00005000"],["110765.06000000","0.04800000"],["110764.78000000","0.10578000"],["110764.77000000","0.18026000"],["110764.76000000","0.00459000"],["110762.72000000","0.13527000"],["110762.34000000","0.00010000"],["110761.88000000","0.00000000"],["110761.22000000","0.33793000"],["110760.89000000","0.00542000"],["110760.63000000","0.00000000"],["110760.13000000","0.06646000"],["110760.02000000","0.00000000"],["110760.00000000","0.00011000"],["110759.95000000","0.04800000"],["110759.68000000","0.00000000"],["110759.22000000","0.00000000"],["110758.91000000","0.00000000"],["110758.90000000","0.18026000"],["110758.88000000","0.00000000"],["110758.49000000","0.45036000"],["110757.78000000","0.08567000"],["110757.77000000","0.00000000"],["110757.58000000","0.13527000"],["110757.44000000","0.00007000"],["110757.26000000","0.00010000"],["110757.14000000","0.08567000"],["110755.89000000","0.00403000"],["110755.59000000","0.04000000"],["110755.25000000","0.04800000"],["110753.84000000","1.29224000"],["110753.83000000","0.00000000"],["110753.62000000","0.00705000"],["110753.38000000","3.29339000"],["110753.25000000","0.04800000"],["110752.90000000","0.07200000"],["110750.36000000","0.00000000"],["110750.02000000","2.64203000"],["110750.01000000","3.24539000"],["110750.00000000","0.00000000"],["110749.66000000","0.25158000"],["110749.59000000","0.24936000"],["110748.27000000","0.00000000"],["110748.14000000","0.01715000"],["110748.13000000","0.01964000"],["110747.16000000","0.02144000"],["110746.84000000","0.08567000"],["110746.78000000","0.00000000"],["110746.70000000","0.08567000"],["110746.49000000","0.00000000"],["110745.95000000","0.08567000"],["110744.83000000","3.29339000"],["110744.64000000","0.00000000"],["110743.93000000","1.20886000"],["110743.61000000","0.00000000"],["110743.58000000","0.00000000"],["110743.50000000","0.00000000"],["110743.35000000","0.00438000"],["110743.17000000","0.00000000"],["110743.05000000","0.04508000"],["110743.00000000","0.00400000"],["110742.21000000","0.00000000"],["110742.12000000","0.00000000"],["110741.48000000","3.24539000"],["110741.20000000","0.00000000"],["110740.65000000","0.00000000"],["110739.89000000","0.00270000"],["110739.81000000","0.00000000"],["110739.78000000","0.00000000"],["110739.62000000","0.00000000"],["110738.46000000","0.04000000"],["110737.70000000","2.00147000"],["110737.67000000","0.04800000"],["110737.66000000","0.00000000"],["110736.54000000","0.00000000"],["110736.36000000","0.00000000"],["110736.32000000","1.19849000"],["110736.14000000","0.00000000"],["110735.52000000","0.02141000"],["110734.37000000","0.00000000"],["110733.91000000","0.00000000"],["110733.57000000","0.13522000"],["110731.03000000","0.00000000"],["110730.43000000","0.00000000"],["110729.76000000","0.16000000"],["110729.66000000","0.02000000"],["110729.50000000","0.00000000"],["110729.37000000","0.00000000"],["110729.36000000","0.00000000"],["110729.06000000","0.08000000"],["110728.32000000","0.00000000"],["110727.36000000","0.00000000"],["110726.16000000","0.00000000"],["110725.90000000","0.00000000"],["110725.75000000","0.00000000"],["110724.16000000","0.32000000"],["110723.86000000","0.00000000"],["110723.82000000","0.00000000"],["110722.48000000","1.10905000"],["110722.47000000","0.00000000"],["110722.26000000","0.00000000"],["110721.28000000","0.00000000"],["110720.89000000","0.04457000"],["110720.87000000","0.00000000"],["110720.38000000","0.00000000"],["110719.37000000","0.02618000"],["110718.07000000","0.00000000"],["110717.96000000","0.00000000"],["110717.50000000","0.00005000"],["110716.42000000","0.00000000"],["110716.20000000","0.00000000"],["110714.92000000","0.02888000"],["110714.68000000","0.02617000"],["110713.83000000","0.00000000"],["110711.37000000","0.00000000"],["110711.36000000","0.00000000"],["110711.01000000","0.02637000"],["110709.58000000","0.04800000"],["110709.44000000","0.08938000"],["110708.76000000","0.00661000"],["110707.95000000","0.03277000"],["110707.84000000","0.00000000"],["110706.73000000","0.00000000"],["110706.00000000","0.00132000"],["110705.46000000","0.00000000"],["110704.47000000","0.04800000"],["110704.44000000","0.37635000"],["110704.43000000","0.00000000"],["110704.25000000","0.00000000"],["110703.51000000","0.04800000"],["110703.41000000","0.00000000"],["110702.13000000","0.00624000"],["110701.86000000","0.00000000"],["110700.90000000","0.02618000"],["110700.20000000","0.06871000"],["110699.07000000","0.00000000"],["110697.94000000","0.00005000"],["110697.91000000","0.04800000"],["110697.78000000","0.04800000"],["110697.38000000","0.00000000"],["110694.89000000","0.00000000"],["110694.21000000","0.17969000"],["110694.20000000","0.00000000"],["110693.62000000","0.00000000"],["110691.50000000","0.00000000"],["110689.33000000","0.00000000"],["110688.07000000","0.11349000"],["110687.62000000","0.00000000"],["110687.55000000","0.00000000"],["110686.89000000","0.00000000"],["110685.39000000","0.09641000"],["110684.11000000","0.00000000"],["110683.84000000","0.00000000"],["110683.75000000","0.00225000"],["110683.74000000","0.00000000"],["110682.99000000","0.00000000"],["110682.69000000","0.00000000"],["110681.63000000","0.00111000"],["110679.17000000","0.02346000"],["110677.92000000","0.00000000"],["110677.75000000","0.25943000"],["110677.69000000","0.00000000"],["110676.96000000","0.18031000"],["110676.81000000","0.13544000"],["110676.22000000","0.22546000"],["110676.10000000","0.00000000"],["110675.59000000","0.00000000"],["110674.32000000","0.00000000"],["110673.33000000","0.04297000"],["110673.06000000","0.00000000"],["110672.16000000","0.00000000"],["110672.02000000","0.00000000"],["110671.72000000","0.00000000"],["110671.53000000","0.08739000"],["110670.17000000","0.24682000"],["110670.16000000","0.00000000"],["110670.15000000","0.00000000"],["110668.96000000","0.00000000"],["110668.53000000","0.00000000"],["110668.48000000","0.00000000"],["110667.68000000","0.00000000"],["110667.62000000","0.00000000"],["110666.77000000","0.00000000"],["110666.67000000","0.00167000"],["110666.44000000","0.08460000"],["110664.68000000","0.00000000"],["110662.75000000","0.00000000"],["110660.54000000","0.00000000"],["110659.31000000","0.00000000"],["110659.17000000","0.00000000"],["110658.83000000","0.00000000"],["110658.75000000","0.00000000"],["110657.95000000","0.00007000"],["110657.80000000","0.07712000"],["110656.04000000","0.03997000"],["110648.33000000","0.34839000"],["110646.81000000","0.08295000"],["110645.06000000","0.00000000"],["110642.99000000","0.13757000"],["110642.95000000","0.08295000"],["110642.53000000","0.04097000"],["110641.23000000","0.00000000"],["110641.18000000","0.00000000"],["110640.32000000","0.12292000"],["110639.77000000","0.04097000"],["110638.86000000","0.00160000"],["110638.00000000","0.00132000"],["110637.50000000","0.08295000"],["110636.23000000","0.04097000"],["110631.51000000","0.08295000"],["110630.70000000","0.08967000"],["110628.40000000","0.08295000"],["110627.52000000","0.52582000"],["110626.53000000","0.99085000"],["110626.38000000","0.06000000"],["110624.90000000","0.08295000"],["110621.81000000","0.08295000"],["110621.64000000","0.00000000"],["110620.37000000","0.00000000"],["110619.14000000","0.08295000"],["110617.00000000","0.00000000"],["110610.12000000","0.00000000"],["110609.95000000","0.42654000"],["110608.00000000","0.00132000"],["110607.41000000","0.00000000"],["110599.98000000","0.00000000"],["110598.47000000","0.00000000"],["110597.98000000","0.00000000"],["110596.25000000","0.00000000"],["110594.61000000","0.00000000"],["110593.53000000","0.00000000"],["110593.43000000","0.00000000"],["110593.03000000","0.00000000"],["110591.41000000","0.00000000"],["110588.76000000","0.00000000"],["110586.06000000","0.00000000"],["110576.95000000","0.00000000"],["110575.29000000","0.00000000"],["110558.70000000","0.00000000"],["110533.07000000","0.00000000"],["110527.36000000","0.00588000"],["110518.00000000","0.00000000"],["110516.98000000","0.00000000"],["110516.44000000","0.00000000"],["110515.61000000","0.00000000"],["110513.52000000","0.00027000"],["110511.58000000","0.00000000"],["110511.57000000","0.00000000"],["110509.29000000","0.00000000"],["110495.75000000","0.00000000"],["110494.55000000","0.00000000"],["110490.34000000","0.00000000"],["110489.95000000","0.00000000"],["110446.19000000","0.04297000"],["110444.42000000","0.00000000"],["110441.40000000","0.00000000"],["110437.48000000","0.00000000"],["110434.45000000","0.00000000"],["110400.73000000","0.00000000"],["110399.52000000","0.00000000"],["110390.87000000","0.02527000"],["110390.14000000","0.02527000"],["110372.69000000","0.00333000"],["110367.89000000","0.00000000"],["110367.56000000","0.00000000"],["110367.22000000","0.00000000"],["110366.63000000","0.00000000"],["110366.20000000","0.00000000"],["110366.19000000","0.00000000"],["110361.01000000","0.00000000"],["110338.18000000","0.00000000"],["110314.26000000","0.02527000"],["110291.50000000","0.00000000"],["110287.61000000","0.00000000"],["110286.96000000","0.00000000"],["110283.09000000","0.00000000"],["110222.40000000","0.00122000"],["110134.23000000","0.02398000"],["110134.18000000","0.00000000"],["110103.39000000","0.00000000"],["109834.68000000","0.00081000"],["99698.00000000","0.00030000"],["99691.00000000","0.00024000"],["99687.00000000","0.00000000"],["88630.56000000","0.00022000"],["88621.03000000","0.00000000"],["88614.40000000","0.00000000"],["33000.00000000","3.75190000"]],"a":[["110768.00000000","0.00000000"],["110768.01000000","0.00000000"],["110768.02000000","0.00000000"],["110768.08000000","0.00000000"],["110768.47000000","0.00000000"],["110768.64000000","0.00000000"],["110769.18000000","0.00000000"],["110769.75000000","0.00000000"],["110770.06000000","0.00000000"],["110770.50000000","0.00000000"],["110770.74000000","0.00000000"],["110770.95000000","0.00000000"],["110770.96000000","0.00000000"],["110770.97000000","0.00000000"],["110771.78000000","0.00000000"],["110771.79000000","0.00000000"],["110773.65000000","0.00000000"],["110773.66000000","0.00000000"],["110773.84000000","0.00000000"],["110773.88000000","0.00000000"],["110773.89000000","0.00000000"],["110774.08000000","0.00000000"],["110774.09000000","0.00000000"],["110774.18000000","0.00000000"],["110774.19000000","0.00000000"],["110774.23000000","0.00000000"],["110774.24000000","0.00000000"],["110774.38000000","0.00000000"],["110774.45000000","0.00000000"],["110774.46000000","0.00000000"],["110774.93000000","0.00000000"],["110775.68000000","0.00000000"],["110775.69000000","0.00000000"],["110776.28000000","0.00000000"],["110776.29000000","0.00000000"],["110776.30000000","0.00000000"],["110776.37000000","0.00000000"],["110776.80000000","0.00000000"],["110777.49000000","0.00000000"],["110777.58000000","0.00000000"],["110777.77000000","0.00000000"],["110777.80000000","0.00000000"],["110778.01000000","0.00000000"],["110778.02000000","0.00000000"],["110778.38000000","0.00000000"],["110778.45000000","0.00000000"],["110778.61000000","0.00000000"],["110778.68000000","0.00000000"],["110778.69000000","0.00000000"],["110778.72000000","0.00000000"],["110778.77000000","0.00000000"],["110778.78000000","0.00000000"],["110778.79000000","0.00000000"],["110779.15000000","0.00000000"],["110779.16000000","0.00000000"],["110779.17000000","0.00000000"],["110779.76000000","0.00000000"],["110780.00000000","0.00000000"],["110780.49000000","0.00000000"],["110780.50000000","0.00000000"],["110780.72000000","0.00000000"],["110780.98000000","0.00000000"],["110780.99000000","0.00000000"],["110781.15000000","0.00000000"],["110781.38000000","0.00000000"],["110781.44000000","0.00000000"],["110781.45000000","0.00000000"],["110781.69000000","0.00000000"],["110781.85000000","0.00000000"],["110781.87000000","0.00000000"],["110782.18000000","0.00000000"],["110782.19000000","0.00000000"],["110782.20000000","0.00000000"],["110782.26000000","0.00000000"],["110782.27000000","0.00000000"],["110782.57000000","0.00000000"],["110782.61000000","0.00000000"],["110782.67000000","0.00000000"],["110782.72000000","0.00000000"],["110782.86000000","0.00000000"],["110783.24000000","0.00000000"],["110783.25000000","0.00000000"],["110783.31000000","0.00000000"],["110783.85000000","0.00000000"],["110783.86000000","0.00000000"],["110783.88000000","0.00000000"],["110783.93000000","0.00000000"],["110784.21000000","0.00000000"],["110784.60000000","0.00000000"],["110784.61000000","0.00000000"],["110784.90000000","0.00000000"],["110784.98000000","0.00000000"],["110784.99000000","0.00000000"],["110785.00000000","0.00000000"],["110785.02000000","0.00000000"],["110785.70000000","0.00000000"],["110786.09000000","0.00000000"],["110786.10000000","0.00000000"],["110786.14000000","0.00000000"],["110786.15000000","0.00000000"],["110786.30000000","0.00000000"],["110786.45000000","0.00000000"],["110786.46000000","0.00000000"],["110786.47000000","0.00000000"],["110786.73000000","0.00000000"],["110786.76000000","0.00000000"],["110786.90000000","0.00000000"],["110787.12000000","0.00000000"],["110787.36000000","0.00000000"],["110787.37000000","0.00000000"],["110787.45000000","0.00000000"],["110787.78000000","0.00000000"],["110787.79000000","0.00000000"],["110787.84000000","0.00000000"],["110788.00000000","0.00000000"],["110788.01000000","0.00000000"],["110788.19000000","0.00000000"],["110788.20000000","2.02463000"],["110788.21000000","0.00010000"],["110788.27000000","0.00010000"],["110788.28000000","0.01825000"],["110788.29000000","0.00000000"],["110788.40000000","0.00000000"],["110788.68000000","0.00000000"],["110788.84000000","0.00000000"],["110788.85000000","0.00000000"],["110788.91000000","0.00000000"],["110788.92000000","0.00005000"],["110789.12000000","0.00000000"],["110789.20000000","0.00000000"],["110789.61000000","0.00000000"],["110789.77000000","0.00000000"],["110789.81000000","0.00000000"],["110789.82000000","0.00000000"],["110789.83000000","0.00005000"],["110789.98000000","0.00000000"],["110789.99000000","0.00000000"],["110790.00000000","0.00100000"],["110790.15000000","0.00000000"],["110790.43000000","0.00000000"],["110790.44000000","0.00000000"],["110790.59000000","0.00000000"],["110790.69000000","0.00000000"],["110790.90000000","0.00000000"],["110790.98000000","0.00005000"],["110791.05000000","0.00000000"],["110791.06000000","0.00000000"],["110791.44000000","0.05115000"],["110791.65000000","0.00000000"],["110791.72000000","0.00000000"],["110791.75000000","0.00000000"],["110791.78000000","0.00000000"],["110791.80000000","0.00000000"],["110791.83000000","0.00000000"],["110791.84000000","0.00000000"],["110791.91000000","0.00000000"],["110792.00000000","0.00100000"],["110792.01000000","0.00000000"],["110792.04000000","0.00000000"],["110792.20000000","0.00000000"],["110792.25000000","0.00000000"],["110792.37000000","0.00000000"],["110792.43000000","0.00000000"],["110792.50000000","0.00000000"],["110792.89000000","0.00000000"],["110792.90000000","0.00005000"],["110792.91000000","0.00005000"],["110793.09000000","0.00000000"],["110793.20000000","0.00000000"],["110793.35000000","0.00000000"],["110793.36000000","0.00000000"],["110793.73000000","0.00000000"],["110793.86000000","0.00000000"],["110793.94000000","0.00000000"],["110793.99000000","0.00000000"],["110794.00000000","0.00105000"],["110794.08000000","0.00000000"],["110794.16000000","0.00000000"],["110794.20000000","0.00000000"],["110794.40000000","0.00000000"],["110794.57000000","0.00000000"],["110794.72000000","0.00010000"],["110794.73000000","0.16203000"],["110794.74000000","0.00000000"],["110794.88000000","0.00000000"],["110795.21000000","0.00000000"],["110795.77000000","0.00000000"],["110795.95000000","0.00010000"],["110795.96000000","0.00015000"],["110796.00000000","0.00105000"],["110796.16000000","0.00000000"],["110796.17000000","0.00000000"],["110796.20000000","0.00000000"],["110796.40000000","0.02709000"],["110796.58000000","0.00000000"],["110796.59000000","0.00005000"],["110796.84000000","0.00000000"],["110796.86000000","0.00000000"],["110797.17000000","0.00000000"],["110797.30000000","0.00010000"],["110797.31000000","0.29761000"],["110797.32000000","0.00005000"],["110797.33000000","0.03615000"],["110797.40000000","0.00000000"],["110797.50000000","0.00000000"],["110797.59000000","0.00000000"],["110797.64000000","0.00330000"],["110797.71000000","0.00264000"],["110797.87000000","0.00000000"],["110797.95000000","0.04041000"],["110798.00000000","0.00114000"],["110798.44000000","0.00000000"],["110798.52000000","0.00000000"],["110798.53000000","0.01799000"],["110798.63000000","0.00000000"],["110798.81000000","0.00154000"],["110798.91000000","0.00005000"],["110798.92000000","0.00000000"],["110798.93000000","0.00000000"],["110799.10000000","0.00000000"],["110799.16000000","0.00000000"],["110799.17000000","0.00000000"],["110799.23000000","0.00000000"],["110799.27000000","0.04503000"],["110799.55000000","0.00018000"],["110799.79000000","0.00000000"],["110799.85000000","0.00005000"],["110800.00000000","0.00119000"],["110800.01000000","0.01001000"],["110800.11000000","0.00000000"],["110800.15000000","0.00000000"],["110800.25000000","0.00000000"],["110800.66000000","0.00022000"],["110800.74000000","0.00000000"],["110801.20000000","0.00000000"],["110801.21000000","0.61755000"],["110801.22000000","0.00000000"],["110801.49000000","0.00000000"],["110801.54000000","0.00000000"],["110801.65000000","0.00000000"],["110801.66000000","0.00000000"],["110802.21000000","0.00000000"],["110802.49000000","0.00000000"],["110802.59000000","0.00073000"],["110802.60000000","0.08061000"],["110802.79000000","0.00000000"],["110802.80000000","0.00000000"],["110803.22000000","0.02638000"],["110803.68000000","0.00069000"],["110803.92000000","0.00000000"],["110804.07000000","0.00000000"],["110804.34000000","0.11273000"],["110804.40000000","0.13522000"],["110804.43000000","0.32453000"],["110804.78000000","0.00000000"],["110804.82000000","0.00149000"],["110805.11000000","0.00007000"],["110805.49000000","0.04000000"],["110805.73000000","0.00000000"],["110806.30000000","0.00000000"],["110806.31000000","0.00000000"],["110806.62000000","0.00000000"],["110807.17000000","0.00000000"],["110807.18000000","0.00000000"],["110807.23000000","0.00005000"],["110807.86000000","1.45538000"],["110807.99000000","0.00000000"],["110808.48000000","0.01173000"],["110808.68000000","0.00000000"],["110809.01000000","0.00000000"],["110809.06000000","0.00000000"],["110809.17000000","0.00000000"],["110809.52000000","0.04509000"],["110809.96000000","0.00460000"],["110809.97000000","0.32452000"],["110810.32000000","0.00000000"],["110810.64000000","0.00000000"],["110811.24000000","0.00017000"],["110811.63000000","0.06240000"],["110811.96000000","0.18026000"],["110812.19000000","0.08567000"],["110812.42000000","0.00000000"],["110812.46000000","0.00000000"],["110812.48000000","0.13527000"],["110812.81000000","0.00270000"],["110813.99000000","0.00000000"],["110814.55000000","0.32450000"],["110814.88000000","0.00000000"],["110814.91000000","0.00446000"],["110815.28000000","0.00000000"],["110815.93000000","0.08160000"],["110816.41000000","0.01964000"],["110817.04000000","0.10080000"],["110817.89000000","0.00901000"],["110817.97000000","0.00000000"],["110817.98000000","0.00000000"],["110818.10000000","0.12000000"],["110818.99000000","0.36066000"],["110819.00000000","0.08567000"],["110819.52000000","0.00000000"],["110819.97000000","0.08000000"],["110819.99000000","0.00000000"],["110821.16000000","0.30425000"],["110821.76000000","0.00000000"],["110821.77000000","0.00000000"],["110821.91000000","1.16458000"],["110821.94000000","0.08567000"],["110821.97000000","0.00225000"],["110822.17000000","0.05280000"],["110822.79000000","1.26795000"],["110823.09000000","0.01173000"],["110823.76000000","0.08567000"],["110823.96000000","0.00000000"],["110824.61000000","0.00000000"],["110825.14000000","0.00000000"],["110825.16000000","0.13527000"],["110825.28000000","0.00005000"],["110825.54000000","0.00000000"],["110826.61000000","0.02141000"],["110826.70000000","0.00180000"],["110826.80000000","0.49872000"],["110827.39000000","0.00000000"],["110827.71000000","0.24921000"],["110828.22000000","0.00000000"],["110828.23000000","0.48326000"],["110828.55000000","0.00000000"],["110828.92000000","0.00000000"],["110830.64000000","0.00000000"],["110831.34000000","0.00005000"],["110831.68000000","0.04495000"],["110832.04000000","0.00000000"],["110832.31000000","0.00000000"],["110833.97000000","0.00000000"],["110834.97000000","0.08000000"],["110835.19000000","0.00000000"],["110835.54000000","0.00000000"],["110836.26000000","0.00000000"],["110836.84000000","0.00000000"],["110836.85000000","0.00000000"],["110836.86000000","0.00000000"],["110837.40000000","0.00005000"],["110838.09000000","0.00000000"],["110838.59000000","0.18026000"],["110838.68000000","0.00000000"],["110838.91000000","0.05598000"],["110839.26000000","0.00000000"],["110841.11000000","1.08685000"],["110841.36000000","0.00000000"],["110841.70000000","0.18584000"],["110842.33000000","0.02800000"],["110842.40000000","0.00000000"],["110843.46000000","0.00015000"],["110843.65000000","0.00000000"],["110843.86000000","0.00000000"],["110843.99000000","0.03791000"],["110844.33000000","0.00000000"],["110845.24000000","0.18026000"],["110845.40000000","0.00000000"],["110849.40000000","0.00015000"],["110849.85000000","0.00000000"],["110851.26000000","0.18026000"],["110851.27000000","1.24797000"],["110851.99000000","0.00000000"],["110853.40000000","0.00000000"],["110853.83000000","0.00000000"],["110853.98000000","0.00000000"],["110854.11000000","0.00000000"],["110854.12000000","0.00000000"],["110854.28000000","0.00000000"],["110854.84000000","0.00661000"],["110855.24000000","0.00000000"],["110855.25000000","0.00000000"],["110856.50000000","0.00630000"],["110856.64000000","0.00000000"],["110856.72000000","0.00000000"],["110857.10000000","0.18026000"],["110857.11000000","1.18717000"],["110857.79000000","0.00005000"],["110859.61000000","0.00000000"],["110859.86000000","0.00000000"],["110860.89000000","0.00005000"],["110860.93000000","0.00224000"],["110863.13000000","0.00000000"],["110863.51000000","0.19716000"],["110864.82000000","0.00000000"],["110865.99000000","0.00000000"],["110866.73000000","0.03150000"],["110867.58000000","1.52850000"],["110867.59000000","3.24539000"],["110868.29000000","0.00000000"],["110868.52000000","0.00000000"],["110869.88000000","0.00000000"],["110871.94000000","0.13527000"],["110871.98000000","0.00000000"],["110872.97000000","0.00000000"],["110872.99000000","0.00224000"],["110873.98000000","1.08496000"],["110873.99000000","0.03997000"],["110874.24000000","3.24539000"],["110875.86000000","0.00000000"],["110876.06000000","0.00000000"],["110877.99000000","0.03997000"],["110878.33000000","0.00000000"],["110878.91000000","1.08044000"],["110878.92000000","0.00000000"],["110879.81000000","0.00000000"],["110880.88000000","0.03997000"],["110880.89000000","3.24539000"],["110882.65000000","0.11158000"],["110883.17000000","0.00000000"],["110883.41000000","0.00112000"],["110883.63000000","0.02473000"],["110883.69000000","0.19680000"],["110884.15000000","0.00000000"],["110885.99000000","0.03997000"],["110886.47000000","0.04051000"],["110887.40000000","0.00000000"],["110888.80000000","0.00000000"],["110889.61000000","0.03997000"],["110891.97000000","0.03997000"],["110892.42000000","0.00000000"],["110895.47000000","0.03997000"],["110895.48000000","0.07313000"],["110895.99000000","0.00000000"],["110897.84000000","0.00000000"],["110897.99000000","0.01715000"],["110898.80000000","0.00000000"],["110900.00000000","0.03766000"],["110905.98000000","0.03997000"],["110905.99000000","0.01715000"],["110906.18000000","0.06240000"],["110907.46000000","0.10289000"],["110908.58000000","0.00331000"],["110908.69000000","0.07712000"],["110909.96000000","0.03997000"],["110909.97000000","0.01715000"],["110911.33000000","0.08907000"],["110911.37000000","0.11617000"],["110911.54000000","0.10080000"],["110913.17000000","0.22546000"],["110914.44000000","0.00000000"],["110915.27000000","0.03997000"],["110917.56000000","0.18031000"],["110917.99000000","0.01715000"],["110919.50000000","0.00000000"],["110919.99000000","0.03997000"],["110920.25000000","0.09641000"],["110925.64000000","0.00090000"],["110925.91000000","0.00000000"],["110928.77000000","0.03997000"],["110932.96000000","0.00000000"],["110934.31000000","0.00000000"],["110936.38000000","0.00000000"],["110937.48000000","0.14253000"],["110937.49000000","0.00000000"],["110937.68000000","0.00000000"],["110946.35000000","0.11380000"],["110946.36000000","0.00000000"],["110947.45000000","0.00000000"],["110950.44000000","0.02618000"],["110955.12000000","0.02710000"],["110956.39000000","0.05430000"],["110958.71000000","0.02618000"],["110959.43000000","0.00090000"],["110961.67000000","0.45620000"],["110964.96000000","0.00000000"],["110967.98000000","0.34624000"],["110972.16000000","0.00000000"],["110972.98000000","0.11797000"],["110976.90000000","0.00090000"],["110984.98000000","0.26953000"],["110987.81000000","0.00000000"],["110989.02000000","0.00000000"],["110989.03000000","0.00000000"],["110991.15000000","0.00000000"],["110991.80000000","0.00000000"],["110992.47000000","0.00000000"],["110993.55000000","0.02028000"],["110994.60000000","0.26479000"],["110997.67000000","0.00000000"],["111007.36000000","0.46043000"],["111012.52000000","0.08311000"],["111019.23000000","0.23549000"],["111037.18000000","0.00000000"],["111042.96000000","0.02527000"],["111043.73000000","0.02527000"],["111044.53000000","0.02527000"],["111045.32000000","0.02527000"],["111047.08000000","0.02527000"],["111047.89000000","0.89952000"],["111056.07000000","0.00000000"],["111061.93000000","0.00017000"],["111075.25000000","0.00000000"],["111076.85000000","0.06646000"],["111077.67000000","0.00010000"],["111077.78000000","0.00000000"],["111077.90000000","0.00000000"],["111078.26000000","0.00000000"],["111078.83000000","0.02618000"],["111079.86000000","0.00000000"],["111080.10000000","0.00000000"],["111081.84000000","0.00000000"],["111083.20000000","0.00010000"],["111088.73000000","0.00010000"],["111094.26000000","0.00000000"],["111094.63000000","0.00010000"],["111100.16000000","0.00015000"],["111106.17000000","0.00000000"],["111120.90000000","0.00000000"],["111124.39000000","0.03791000"],["111127.83000000","0.00000000"],["111128.14000000","0.03791000"],["111149.56000000","0.00000000"],["111153.51000000","0.00000000"],["111155.44000000","0.00000000"],["111155.64000000","0.02998000"],["111156.66000000","0.02998000"],["111159.45000000","0.00000000"],["111161.85000000","0.00000000"],["111172.53000000","0.00000000"],["111182.32000000","0.00082000"],["111226.34000000","0.00000000"],["111242.64000000","0.00000000"],["111243.76000000","0.02527000"],["111253.98000000","0.02527000"],["111254.10000000","0.02532000"],["111257.28000000","0.45000000"],["111340.57000000","0.00005000"],["128001.97000000","0.03006000"]]}
[2025-10-11T22:18:38.331Z] {"e":"depthUpdate","E":1760221118014,"s":"BTCUSDT","U":77926042267,"u":77926042811,"b":[["110788.19000000","8.96987000"],["110787.72000000","0.00010000"],["110787.71000000","0.01237000"],["110787.70000000","0.04088000"],["110785.23000000","0.00000000"],["110785.22000000","0.00000000"],["110784.78000000","0.32459000"],["110783.28000000","0.00010000"],["110783.27000000","0.18046000"],["110783.26000000","0.32037000"],["110783.25000000","0.00000000"],["110783.24000000","0.00005000"],["110783.23000000","0.00025000"],["110782.50000000","0.01405000"],["110782.19000000","0.00000000"],["110782.18000000","0.38087000"],["110781.80000000","0.01359000"],["110779.98000000","0.00000000"],["110779.97000000","0.00000000"],["110779.88000000","0.11273000"],["110779.20000000","0.00000000"],["110779.17000000","0.18026000"],["110777.45000000","0.00000000"],["110777.44000000","0.00000000"],["110777.41000000","0.00000000"],["110777.36000000","0.00000000"],["110777.35000000","0.00000000"],["110777.29000000","0.00000000"],["110777.26000000","0.00000000"],["110777.25000000","0.00000000"],["110777.24000000","0.00000000"],["110777.23000000","0.02709000"],["110777.11000000","0.00300000"],["110776.32000000","0.30331000"],["110776.31000000","0.20204000"],["110776.30000000","0.00000000"],["110776.29000000","0.00000000"],["110776.28000000","0.29874000"],["110775.84000000","0.18026000"],["110774.32000000","0.04108000"],["110773.21000000","0.04046000"],["110772.69000000","0.32463000"],["110770.64000000","0.04800000"],["110769.54000000","0.04800000"],["110769.53000000","0.04800000"],["110769.34000000","0.09600000"],["110768.37000000","0.07200000"],["110767.99000000","0.20007000"],["110767.13000000","0.07200000"],["110766.16000000","0.04800000"],["110765.66000000","0.04800000"],["110763.76000000","0.04800000"],["110763.26000000","0.00005000"],["110761.22000000","1.24899000"],["110759.95000000","0.06764000"],["110756.73000000","3.24539000"],["110755.25000000","0.00000000"],["110752.90000000","0.00000000"],["110752.20000000","0.22546000"],["110752.08000000","0.00000000"],["110751.00000000","0.00005000"],["110750.48000000","0.00000000"],["110750.47000000","0.00000000"],["110750.00000000","0.00045000"],["110749.87000000","0.00000000"],["110749.44000000","0.18031000"],["110749.14000000","0.02708000"],["110748.13000000","0.00000000"],["110747.59000000","0.02257000"],["110747.10000000","0.00000000"],["110744.83000000","3.24539000"],["110743.05000000","0.00000000"],["110742.60000000","0.00000000"],["110741.79000000","0.04800000"],["110741.00000000","0.00018000"],["110739.84000000","0.00000000"],["110738.60000000","0.00000000"],["110733.26000000","0.13544000"],["110732.14000000","0.04423000"],["110728.45000000","0.00000000"],["110720.89000000","0.00000000"],["110716.93000000","0.39118000"],["110716.92000000","0.00000000"],["110714.92000000","0.00000000"],["110702.22000000","0.02888000"],["110701.17000000","0.00196000"],["110693.77000000","0.13527000"],["110688.07000000","0.14347000"],["110679.80000000","0.00000000"],["110679.18000000","0.02998000"],["110678.36000000","0.02998000"],["110677.75000000","0.39965000"],["110676.82000000","0.22546000"],["110674.37000000","0.15190000"],["110673.32000000","0.00000000"],["110671.28000000","0.00000000"],["110670.17000000","0.29482000"],["110668.98000000","0.12192000"],["110666.91000000","0.14272000"],["110666.90000000","0.15197000"],["110666.44000000","0.00000000"],["110663.12000000","0.08195000"],["110660.73000000","0.04007000"],["110660.72000000","0.08195000"],["110654.01000000","0.12091000"],["110651.89000000","0.04097000"],["110650.63000000","0.00000000"],["110648.33000000","0.27745000"],["110648.32000000","0.00000000"],["110648.29000000","0.04097000"],["110646.63000000","0.00000000"],["110644.65000000","0.02527000"],["110642.99000000","0.41217000"],["110640.58000000","0.99292000"],["110627.52000000","0.33691000"],["110626.53000000","0.00000000"],["110622.31000000","0.01412000"],["110571.54000000","0.08195000"],["110570.64000000","0.08195000"],["110538.29000000","4.80313000"],["110518.51000000","0.00000000"],["110478.51000000","0.02998000"],["107300.00000000","0.41223000"],["105403.05000000","0.00000000"],["99709.00000000","0.00010000"],["99698.00000000","0.00000000"],["88630.56000000","0.00022000"],["39883.75000000","0.00016000"]],"a":[["110788.20000000","3.46039000"],["110788.21000000","0.00326000"],["110788.26000000","0.00010000"],["110788.27000000","0.10807000"],["110788.28000000","0.01825000"],["110790.00000000","0.00105000"],["110790.59000000","0.00005000"],["110791.40000000","0.00010000"],["110791.41000000","0.29762000"],["110791.43000000","0.00010000"],["110791.44000000","0.05125000"],["110792.90000000","0.00000000"],["110794.00000000","0.00100000"],["110794.57000000","0.00000000"],["110794.58000000","0.00000000"],["110794.73000000","0.16198000"],["110795.95000000","0.00000000"],["110795.96000000","0.00005000"],["110796.00000000","0.00105000"],["110796.39000000","0.00000000"],["110796.40000000","0.00000000"],["110796.41000000","0.00000000"],["110796.42000000","0.00000000"],["110796.72000000","0.00000000"],["110796.75000000","0.00000000"],["110796.76000000","0.00000000"],["110796.79000000","0.02714000"],["110796.80000000","0.00000000"],["110796.81000000","0.00000000"],["110797.30000000","0.00000000"],["110797.31000000","0.00000000"],["110797.32000000","0.00000000"],["110797.33000000","0.36070000"],["110797.71000000","0.00259000"],["110797.95000000","0.00005000"],["110798.00000000","0.00109000"],["110798.53000000","0.00005000"],["110798.81000000","0.00159000"],["110798.91000000","0.00000000"],["110799.27000000","0.04508000"],["110799.53000000","0.32460000"],["110799.87000000","0.00000000"],["110800.00000000","0.00119000"],["110800.01000000","0.00991000"],["110800.37000000","0.00000000"],["110800.98000000","0.00000000"],["110801.45000000","0.00000000"],["110801.56000000","0.04156000"],["110801.83000000","0.00000000"],["110801.85000000","0.00000000"],["110802.09000000","0.00000000"],["110802.56000000","0.04131000"],["110809.52000000","0.00000000"],["110810.36000000","0.00300000"],["110812.61000000","0.05760000"],["110812.63000000","0.05760000"],["110812.64000000","0.05760000"],["110813.62000000","0.12240000"],["110814.46000000","0.00000000"],["110814.55000000","0.00000000"],["110814.86000000","0.14400000"],["110815.56000000","0.00005000"],["110816.49000000","0.08160000"],["110821.44000000","0.00300000"],["110822.54000000","0.01838000"],["110827.71000000","0.10521000"],["110831.68000000","0.00000000"],["110834.88000000","0.00000000"],["110837.64000000","0.00000000"],["110842.93000000","0.04505000"],["110849.40000000","0.00000000"],["110851.58000000","0.00005000"],["110851.81000000","0.06789000"],["110853.87000000","0.00045000"],["110859.41000000","0.02255000"],["110867.10000000","0.00005000"],["110878.34000000","0.05280000"],["110879.46000000","0.07680000"],["110882.65000000","0.02998000"],["110883.18000000","0.14400000"],["110883.68000000","0.32156000"],["110884.05000000","0.10560000"],["110886.00000000","0.00132000"],["110890.35000000","0.12240000"],["110892.17000000","0.01412000"],["110892.43000000","0.00000000"],["110893.11000000","0.00000000"],["110906.18000000","0.00000000"],["110908.58000000","0.00000000"],["110910.37000000","0.00000000"],["110910.38000000","0.00000000"],["110911.37000000","0.21037000"],["110911.54000000","0.00000000"],["110911.80000000","0.00005000"],["110914.45000000","0.00341000"],["110916.47000000","0.00196000"],["110927.97000000","0.02737000"],["110946.34000000","0.32254000"],["110946.35000000","0.99599000"],["110956.66000000","0.18784000"],["110956.67000000","0.08195000"],["110957.99000000","0.00000000"],["110960.75000000","0.08195000"],["110963.51000000","0.08195000"],["110965.91000000","0.08195000"],["110967.98000000","0.05643000"],["111024.33000000","0.37649000"],["111032.52000000","1.43613000"],["111032.53000000","4.72613000"],["111174.67000000","0.02998000"],["111177.28000000","0.02998000"],["111182.32000000","0.00000000"],["111188.20000000","0.00082000"],["128001.97000000","0.03006000"]]}
[2025-10-11T22:18:39.330Z] {"e":"depthUpdate","E":1760221119014,"s":"BTCUSDT","U":77926042812,"u":77926042954,"b":[["110788.19000000","8.47486000"],["110787.71000000","0.10774000"],["110787.70000000","0.04088000"],["110785.98000000","0.00361000"],["110784.79000000","0.00005000"],["110784.78000000","0.32469000"],["110784.32000000","0.00542000"],["110783.26000000","0.23786000"],["110783.24000000","0.00000000"],["110783.23000000","0.00020000"],["110782.18000000","0.42596000"],["110779.88000000","0.00000000"],["110777.12000000","0.60288000"],["110777.11000000","0.56573000"],["110776.84000000","0.00074000"],["110776.32000000","0.00000000"],["110773.95000000","0.00005000"],["110764.76000000","0.00360000"],["110760.89000000","0.00000000"],["110759.96000000","0.01964000"],["110759.95000000","0.04800000"],["110758.13000000","0.00000000"],["110754.95000000","0.00009000"],["110747.26000000","0.00000000"],["110731.53000000","0.00000000"],["110721.72000000","0.00009000"],["110716.01000000","0.04297000"],["110708.98000000","0.00180000"],["110700.01000000","0.04297000"],["110698.30000000","0.00000000"],["110695.41000000","0.04800000"],["110688.48000000","0.00009000"],["110686.93000000","0.04800000"],["110685.40000000","0.04297000"],["110674.37000000","0.19187000"],["110674.35000000","0.00000000"],["110670.18000000","0.31446000"],["110670.17000000","0.08797000"],["110668.98000000","0.16189000"],["110665.07000000","0.00000000"],["110660.73000000","0.08004000"],["110655.24000000","0.00009000"],["110647.55000000","0.06000000"],["110647.48000000","0.04097000"],["110644.85000000","0.02527000"],["110631.84000000","0.00000000"],["110629.83000000","0.00000000"],["110622.31000000","0.00000000"],["110622.01000000","0.00009000"],["110610.10000000","0.00009000"],["110600.00000000","0.23327000"],["110598.61000000","0.00000000"],["110455.33000000","0.04297000"],["110262.71000000","0.02298000"],["110261.85000000","0.02298000"],["110198.00000000","0.02298000"],["109748.30000000","0.00235000"],["99709.37000000","0.00020000"],["99709.00000000","0.00010000"],["88630.56000000","0.00022000"]],"a":[["110788.20000000","4.07264000"],["110792.07000000","0.00542000"],["110793.18000000","0.00722000"],["110798.00000000","0.00100000"],["110802.09000000","0.01806000"],["110807.95000000","0.00005000"],["110810.96000000","0.30428000"],["110821.16000000","0.00000000"],["110821.44000000","0.00309000"],["110831.23000000","0.00000000"],["110845.37000000","0.00005000"],["110854.67000000","0.00009000"],["110864.46000000","0.00000000"],["110873.31000000","0.00005000"],["110874.20000000","0.00000000"],["110874.21000000","0.00000000"],["110887.91000000","0.00009000"],["110891.70000000","0.00180000"],["110893.11000000","0.08160000"],["110897.69000000","0.00000000"],["110921.15000000","0.00009000"],["110930.92000000","0.00000000"],["110939.45000000","0.13214000"],["110954.38000000","0.00009000"],["111253.55000000","0.00000000"],["111865.32000000","0.00230000"],["128001.97000000","0.00040000"]]}
[2025-10-11T22:18:40.330Z] {"e":"depthUpdate","E":1760221120014,"s":"BTCUSDT","U":77926042955,"u":77926043309,"b":[["110788.19000000","3.47256000"],["110788.18000000","0.00055000"],["110787.88000000","0.00010000"],["110787.87000000","0.13511000"],["110787.86000000","0.29763000"],["110787.72000000","0.00000000"],["110787.71000000","0.00010000"],["110787.70000000","0.04088000"],["110785.28000000","0.00000000"],["110785.27000000","0.00000000"],["110785.26000000","0.00000000"],["110785.05000000","0.00005000"],["110784.80000000","0.00000000"],["110784.79000000","0.00000000"],["110784.78000000","0.00000000"],["110784.32000000","0.00547000"],["110783.29000000","0.00005000"],["110783.28000000","0.17545000"],["110783.27000000","0.18036000"],["110783.26000000","0.32460000"],["110782.18000000","0.04514000"],["110781.80000000","0.01354000"],["110781.59000000","0.00000000"],["110781.15000000","0.00005000"],["110781.11000000","0.32460000"],["110779.17000000","0.00000000"],["110777.11000000","0.45300000"],["110776.31000000","0.00000000"],["110774.44000000","0.00073000"],["110774.32000000","0.04108000"],["110773.18000000","0.08567000"],["110772.71000000","0.45036000"],["110772.70000000","0.20205000"],["110771.69000000","0.44849000"],["110771.68000000","0.00000000"],["110771.57000000","0.11273000"],["110771.36000000","0.00006000"],["110768.13000000","0.00000000"],["110760.12000000","0.00000000"],["110759.96000000","0.00000000"],["110759.95000000","0.04800000"],["110755.59000000","0.00000000"],["110748.42000000","0.04000000"],["110748.15000000","0.02527000"],["110743.36000000","0.02298000"],["110739.73000000","0.00000000"],["110717.50000000","0.00000000"],["110714.15000000","0.20324000"],["110707.95000000","0.00000000"],["110702.22000000","0.00000000"],["110695.18000000","0.03277000"],["110692.92000000","0.13527000"],["110687.62000000","0.02888000"],["110608.59000000","0.02527000"],["110596.84000000","0.02527000"],["110589.89000000","0.01900000"],["109748.30000000","0.00000000"],["100000.00000000","233.03751000"],["99709.37000000","0.00000000"],["99709.00000000","0.00010000"],["88630.56000000","0.00022000"],["60000.00000000","56.18404000"],["39883.75000000","0.00064000"]],"a":[["110788.20000000","4.15146000"],["110788.21000000","0.00356000"],["110788.27000000","0.06746000"],["110788.28000000","0.01830000"],["110788.89000000","0.00010000"],["110788.90000000","0.04010000"],["110790.92000000","0.29753000"],["110791.40000000","0.00000000"],["110791.41000000","0.00000000"],["110791.44000000","0.05125000"],["110792.00000000","0.00105000"],["110792.07000000","0.00552000"],["110793.18000000","0.00737000"],["110793.42000000","0.00005000"],["110793.43000000","0.04518000"],["110793.72000000","0.00005000"],["110793.73000000","0.04508000"],["110793.74000000","0.00005000"],["110794.00000000","0.00105000"],["110794.24000000","0.01810000"],["110794.72000000","0.00000000"],["110794.73000000","0.16193000"],["110795.02000000","0.32456000"],["110796.79000000","0.02714000"],["110797.33000000","0.03610000"],["110798.81000000","0.00149000"],["110799.27000000","0.00000000"],["110799.53000000","0.32455000"],["110800.00000000","0.00114000"],["110801.00000000","0.00400000"],["110801.55000000","0.00450000"],["110802.59000000","0.00000000"],["110805.49000000","0.00000000"],["110805.71000000","0.32453000"],["110806.62000000","0.00800000"],["110809.96000000","0.00010000"],["110809.97000000","0.00000000"],["110824.67000000","0.00000000"],["110842.27000000","0.00005000"],["110842.61000000","0.00000000"],["110860.93000000","0.00000000"],["110865.79000000","0.00000000"],["110866.55000000","0.13522000"],["110875.14000000","0.00100000"],["110875.15000000","0.00100000"],["110876.42000000","0.00005000"],["110923.97000000","0.03997000"],["110959.43000000","0.00000000"],["110974.34000000","0.01900000"],["111174.21000000","0.02998000"],["111177.16000000","0.02998000"],["111865.32000000","0.00000000"],["128001.97000000","0.00040000"]]}
[2025-10-11T22:18:41.330Z] {"e":"depthUpdate","E":1760221121014,"s":"BTCUSDT","U":77926043310,"u":77926043550,"b":[["110788.19000000","4.03346000"],["110788.18000000","0.00060000"],["110787.70000000","0.04088000"],["110784.32000000","0.00547000"],["110783.69000000","0.00010000"],["110783.68000000","0.32469000"],["110783.28000000","0.17540000"],["110783.27000000","0.18036000"],["110783.26000000","0.00000000"],["110782.02000000","0.00903000"],["110777.80000000","0.00005000"],["110774.50000000","0.00000000"],["110774.02000000","0.00005000"],["110770.84000000","0.00000000"],["110764.76000000","0.00370000"],["110743.55000000","1.21613000"],["110740.00000000","0.00110000"],["110736.32000000","0.00000000"],["110720.85000000","0.00000000"],["110720.37000000","0.00936000"],["110719.52000000","0.00629000"],["110719.36000000","0.00000000"],["110719.20000000","0.00621000"],["110718.88000000","0.03162000"],["110718.01000000","0.08395000"],["110709.29000000","0.00000000"],["110707.80000000","0.00000000"],["110706.01000000","0.02527000"],["110704.01000000","0.02527000"],["110700.21000000","0.15781000"],["110699.01000000","0.07295000"],["110685.40000000","0.08594000"],["110677.83000000","0.03997000"],["110672.01000000","0.11889000"],["110668.29000000","0.06422000"],["110660.22000000","0.03997000"],["110659.66000000","0.02527000"],["110656.78000000","0.08395000"],["110655.53000000","0.07577000"],["110654.40000000","0.02527000"],["110654.28000000","0.08395000"],["110651.66000000","0.02527000"],["110649.91000000","0.08395000"],["110646.48000000","0.08395000"],["110646.09000000","0.00903000"],["110644.33000000","0.04097000"],["110643.44000000","0.08395000"],["110643.33000000","0.02527000"],["110640.78000000","0.08395000"],["110637.65000000","0.08395000"],["110637.51000000","0.22508000"],["110635.36000000","0.00000000"],["110609.94000000","0.00000000"],["110542.82000000","0.00588000"],["110527.36000000","0.00000000"],["110500.00000000","0.93378000"],["110418.31000000","0.45131000"],["110376.72000000","0.00000000"],["101905.53000000","0.00000000"],["99709.00000000","0.00010000"],["88630.56000000","0.00022000"],["60000.00000000","56.18394000"],["42000.00000000","1.48198000"]],"a":[["110788.20000000","4.00789000"],["110788.21000000","0.00356000"],["110788.27000000","0.15055000"],["110788.28000000","0.01825000"],["110788.89000000","0.00000000"],["110788.90000000","0.00000000"],["110789.48000000","0.00005000"],["110790.91000000","0.00010000"],["110790.92000000","0.29763000"],["110791.44000000","0.05130000"],["110791.67000000","0.00005000"],["110791.68000000","0.04005000"],["110793.42000000","0.00000000"],["110793.72000000","0.00000000"],["110794.24000000","0.01805000"],["110795.02000000","0.00000000"],["110797.15000000","0.00000000"],["110801.86000000","0.00000000"],["110801.88000000","0.00072000"],["110809.28000000","0.32452000"],["110811.07000000","0.05280000"],["110811.30000000","0.00005000"],["110821.91000000","0.00000000"],["110822.17000000","0.00000000"],["110824.79000000","1.19989000"],["110847.73000000","0.00000000"],["110856.89000000","0.00621000"],["110857.21000000","0.00629000"],["110860.92000000","0.00224000"],["110866.55000000","0.00000000"],["110867.42000000","0.13522000"],["110879.37000000","0.00000000"],["110881.79000000","0.01412000"],["110885.36000000","0.00005000"],["110890.46000000","0.03162000"],["110890.64000000","0.00000000"],["110891.74000000","0.00000000"],["110892.17000000","0.00000000"],["110895.98000000","0.11594000"],["110899.65000000","0.00000000"],["110971.20000000","0.00090000"],["110971.21000000","0.00000000"],["110982.31000000","0.00936000"],["111078.83000000","0.00000000"],["111094.53000000","0.02617000"],["111264.47000000","0.67153000"],["128001.97000000","0.00040000"]]}
[2025-10-11T22:18:42.330Z] {"e":"depthUpdate","E":1760221122014,"s":"BTCUSDT","U":77926043551,"u":77926043877,"b":[["110788.19000000","4.07100000"],["110788.18000000","0.00075000"],["110788.03000000","0.00908000"],["110787.87000000","0.20354000"],["110787.86000000","0.29763000"],["110787.81000000","0.01364000"],["110787.70000000","0.04088000"],["110785.02000000","0.00010000"],["110785.01000000","0.06651000"],["110783.68000000","0.32464000"],["110783.29000000","0.00000000"],["110783.28000000","0.17535000"],["110783.27000000","0.18031000"],["110782.50000000","0.01400000"],["110782.18000000","0.04509000"],["110781.98000000","0.01820000"],["110781.80000000","0.00000000"],["110781.49000000","0.05551000"],["110779.24000000","0.18026000"],["110774.45000000","0.00005000"],["110774.44000000","0.00000000"],["110774.32000000","0.04021000"],["110773.95000000","0.00000000"],["110773.21000000","0.04097000"],["110770.94000000","0.00000000"],["110764.76000000","0.00375000"],["110763.07000000","0.00000000"],["110759.98000000","0.01964000"],["110756.16000000","0.22546000"],["110752.20000000","0.00000000"],["110724.20000000","0.00000000"],["110693.01000000","0.08495000"],["110678.60000000","0.22546000"],["110676.97000000","0.03997000"],["110676.82000000","0.00000000"],["110671.54000000","0.03997000"],["110662.70000000","0.03997000"],["110655.01000000","0.08495000"],["110650.52000000","0.08495000"],["110649.32000000","0.00000000"],["110648.81000000","0.04097000"],["110648.33000000","0.36873000"],["110647.66000000","0.08495000"],["110644.91000000","0.08495000"],["110643.02000000","0.08495000"],["110640.59000000","0.08495000"],["110488.19000000","0.00000000"],["110123.47000000","0.00000000"],["99709.00000000","0.00010000"],["88630.56000000","0.00022000"],["33000.00000000","3.75190000"]],"a":[["110788.20000000","2.95056000"],["110788.21000000","0.00356000"],["110788.27000000","0.03258000"],["110788.28000000","0.01830000"],["110788.57000000","0.00010000"],["110788.58000000","0.01364000"],["110789.48000000","0.00000000"],["110790.00000000","0.00105000"],["110790.90000000","0.00005000"],["110790.91000000","0.04328000"],["110790.92000000","0.00000000"],["110791.43000000","0.00000000"],["110791.44000000","0.00005000"],["110791.67000000","0.00010000"],["110791.68000000","0.04005000"],["110793.18000000","0.00727000"],["110793.34000000","0.00000000"],["110793.42000000","0.00000000"],["110793.43000000","0.00000000"],["110793.72000000","0.00000000"],["110793.73000000","0.00000000"],["110794.00000000","0.00105000"],["110794.24000000","0.00000000"],["110794.29000000","0.01810000"],["110794.72000000","0.00000000"],["110794.73000000","0.12435000"],["110796.27000000","0.29751000"],["110796.78000000","0.00000000"],["110796.79000000","0.02719000"],["110797.01000000","0.05169000"],["110797.33000000","0.03610000"],["110798.00000000","0.00110000"],["110798.53000000","0.00000000"],["110798.81000000","0.00149000"],["110798.91000000","0.00000000"],["110799.27000000","0.04503000"],["110799.53000000","0.00000000"],["110800.00000000","0.00114000"],["110800.27000000","0.32455000"],["110801.87000000","0.00000000"],["110802.53000000","0.00000000"],["110803.93000000","0.00000000"],["110804.39000000","0.18026000"],["110804.43000000","0.00000000"],["110804.53000000","0.32453000"],["110805.71000000","0.00000000"],["110807.38000000","0.00000000"],["110807.85000000","0.18026000"],["110807.86000000","1.23622000"],["110807.87000000","0.00000000"],["110808.31000000","0.03395000"],["110810.95000000","3.24539000"],["110812.75000000","0.32451000"],["110814.65000000","0.00005000"],["110814.82000000","0.00000000"],["110860.91000000","0.00224000"],["110860.92000000","0.00000000"],["110860.93000000","0.18026000"],["110971.19000000","0.00090000"],["110971.20000000","0.00000000"],["111060.00000000","0.00024000"],["113472.85000000","0.00000000"],["113720.24000000","0.00021000"],["126000.00000000","76.05023000"],["128001.97000000","0.03006000"]]}
[2025-10-11T22:18:43.330Z] {"e":"depthUpdate","E":1760221123014,"s":"BTCUSDT","U":77926043878,"u":77926044088,"b":[["110788.19000000","4.00343000"],["110788.18000000","0.00060000"],["110787.87000000","0.13511000"],["110787.70000000","0.04088000"],["110785.02000000","0.00000000"],["110785.01000000","0.00000000"],["110784.32000000","0.00547000"],["110783.89000000","0.32459000"],["110783.69000000","0.00000000"],["110783.68000000","0.00000000"],["110783.29000000","0.00010000"],["110783.28000000","0.17540000"],["110783.27000000","0.18036000"],["110782.50000000","0.01405000"],["110781.98000000","0.00000000"],["110779.24000000","0.00000000"],["110777.13000000","0.00005000"],["110774.42000000","0.00072000"],["110770.92000000","0.00005000"],["110770.60000000","0.00000000"],["110765.62000000","0.00005000"],["110760.20000000","0.00000000"],["110759.98000000","0.00000000"],["110759.96000000","0.01964000"],["110720.63000000","0.00000000"],["110717.92000000","0.00000000"],["110716.80000000","0.06817000"],["110700.22000000","0.04297000"],["110700.20000000","0.00000000"],["110694.21000000","0.25642000"],["110685.40000000","0.12891000"],["110647.08000000","0.04097000"],["110641.46000000","0.08495000"],["110123.47000000","0.00000000"],["105414.97000000","0.00095000"],["105387.68000000","0.00000000"],["99709.00000000","0.00010000"],["88630.56000000","0.00022000"],["42000.00000000","1.48098000"]],"a":[["110788.20000000","4.08254000"],["110788.21000000","0.00361000"],["110788.27000000","0.12971000"],["110788.57000000","0.00000000"],["110789.48000000","0.00005000"],["110790.00000000","0.00100000"],["110790.90000000","0.00010000"],["110790.91000000","0.34081000"],["110792.07000000","0.00557000"],["110792.59000000","0.00005000"],["110792.60000000","0.04518000"],["110793.18000000","0.00737000"],["110793.40000000","0.01810000"],["110793.73000000","0.04503000"],["110793.74000000","0.00005000"],["110793.75000000","0.00000000"],["110794.29000000","0.01805000"],["110794.73000000","0.21773000"],["110795.38000000","0.32456000"],["110796.27000000","0.00000000"],["110798.00000000","0.00100000"],["110798.02000000","0.32455000"],["110799.27000000","0.00000000"],["110800.27000000","0.00000000"],["110802.09000000","0.00000000"],["110802.18000000","0.00000000"],["110802.37000000","0.01803000"],["110808.31000000","0.00000000"],["110812.75000000","0.00000000"],["110821.35000000","0.00005000"],["110866.63000000","0.13522000"],["110867.42000000","0.00000000"],["110939.45000000","0.13795000"],["110946.82000000","0.06000000"],["111009.78000000","0.06000000"],["111121.77000000","0.00000000"],["111264.47000000","0.00000000"],["111275.39000000","0.67153000"],["112450.02000000","0.00005000"],["128001.97000000","0.03006000"]]}
[2025-10-11T22:18:44.330Z] {"e":"depthUpdate","E":1760221124014,"s":"BTCUSDT","U":77926044089,"u":77926044212,"b":[["110788.19000000","3.55317000"],["110788.18000000","0.00060000"],["110787.87000000","0.13511000"],["110787.70000000","0.04088000"],["110784.32000000","0.00547000"],["110783.90000000","0.00000000"],["110783.89000000","0.00000000"],["110783.28000000","0.17540000"],["110783.13000000","0.32460000"],["110782.50000000","0.01405000"],["110780.23000000","0.00005000"],["110777.23000000","0.00000000"],["110777.19000000","0.00000000"],["110777.18000000","0.00000000"],["110777.16000000","0.02709000"],["110771.62000000","0.00000000"],["110767.82000000","0.00005000"],["110759.96000000","0.00000000"],["110745.12000000","0.08595000"],["110735.53000000","0.04097000"],["110724.20000000","0.00005000"],["110700.01000000","0.08594000"],["110688.07000000","0.18801000"],["110685.40000000","0.17188000"],["110476.18000000","0.07495000"],["110426.64000000","0.07495000"],["110426.29000000","0.07495000"],["110425.94000000","0.07495000"],["110425.55000000","0.07495000"],["110423.92000000","0.07495000"],["99709.00000000","0.00010000"],["88630.56000000","0.00022000"]],"a":[["110788.20000000","4.04770000"],["110788.21000000","0.00356000"],["110794.73000000","0.13760000"],["110795.38000000","0.00000000"],["110795.81000000","0.32456000"],["110798.02000000","0.00000000"],["110800.78000000","0.32454000"],["110801.85000000","0.00000000"],["110801.88000000","0.00000000"],["110807.97000000","0.32452000"],["110809.28000000","0.00000000"],["110866.39000000","0.13522000"],["110866.63000000","0.00000000"],["110881.79000000","0.00000000"],["111010.00000000","0.00089000"],["128001.97000000","0.03006000"]]}
[2025-10-11T22:18:45.330Z] {"e":"depthUpdate","E":1760221125014,"s":"BTCUSDT","U":77926044213,"u":77926044353,"b":[["110788.19000000","3.99656000"],["110788.18000000","0.00060000"],["110787.87000000","0.18771000"],["110787.81000000","0.01364000"],["110787.71000000","0.00000000"],["110787.70000000","0.00000000"],["110785.32000000","0.00010000"],["110785.31000000","0.32469000"],["110784.61000000","0.00010000"],["110784.60000000","0.04083000"],["110783.33000000","0.00005000"],["110783.28000000","0.17535000"],["110783.27000000","0.18036000"],["110783.13000000","0.00000000"],["110782.50000000","0.01400000"],["110777.16000000","0.00000000"],["110777.13000000","0.02714000"],["110774.58000000","0.00000000"],["110771.10000000","0.00005000"],["110764.72000000","0.00005000"],["110760.84000000","0.01964000"],["110727.55000000","0.00000000"],["110699.01000000","0.11692000"],["110685.40000000","0.21585000"],["110668.29000000","0.10419000"],["110659.74000000","0.03997000"],["110614.94000000","0.00000000"],["105000.00000000","233.39258000"],["99709.00000000","0.00010000"],["88630.56000000","0.00022000"],["39883.75000000","0.00080000"]],"a":[["110788.20000000","4.04701000"],["110788.21000000","0.00361000"],["110788.58000000","0.01364000"],["110790.00000000","0.00105000"],["110790.39000000","0.00005000"],["110790.40000000","0.03620000"],["110790.91000000","0.34076000"],["110792.59000000","0.00000000"],["110793.40000000","0.01805000"],["110797.71000000","0.00264000"],["110797.95000000","0.00000000"],["110800.77000000","0.18026000"],["110801.91000000","0.00000000"],["110808.31000000","0.05939000"],["110826.05000000","0.00093000"],["110905.65000000","0.00331000"],["110914.45000000","0.00010000"],["110927.97000000","0.04402000"],["110929.59000000","0.06000000"],["111179.39000000","0.00082000"],["111188.20000000","0.00000000"],["128001.97000000","0.00040000"]]}
[2025-10-11T22:18:46.330Z] {"e":"depthUpdate","E":1760221126014,"s":"BTCUSDT","U":77926044354,"u":77926044532,"b":[["110788.19000000","3.54609000"],["110788.18000000","0.00060000"],["110787.87000000","0.13511000"],["110787.81000000","0.01364000"],["110785.32000000","0.00000000"],["110785.31000000","0.00000000"],["110784.60000000","0.04088000"],["110783.28000000","0.26235000"],["110783.27000000","0.18036000"],["110783.19000000","0.32465000"],["110777.18000000","0.00000000"],["110777.17000000","0.00000000"],["110777.15000000","0.00000000"],["110777.13000000","0.00005000"],["110777.12000000","0.60288000"],["110777.10000000","0.00000000"],["110777.08000000","0.00000000"],["110777.07000000","0.00000000"],["110777.06000000","0.02709000"],["110777.05000000","0.00000000"],["110774.62000000","0.00069000"],["110764.82000000","0.27499000"],["110764.81000000","0.55000000"],["110764.78000000","0.00000000"],["110764.40000000","0.00005000"],["110760.84000000","0.00000000"],["110730.90000000","0.00000000"],["110538.29000000","0.00000000"],["110538.26000000","4.82763000"],["103143.00000000","0.00006000"],["101905.53000000","0.00010000"],["99709.00000000","0.00010000"],["88630.56000000","0.00022000"],["39883.75000000","0.00112000"]],"a":[["110788.20000000","4.27066000"],["110788.21000000","0.00361000"],["110788.58000000","0.01364000"],["110790.00000000","0.00105000"],["110790.15000000","0.00010000"],["110790.16000000","0.03620000"],["110790.39000000","0.00000000"],["110790.40000000","0.00000000"],["110790.41000000","0.00000000"],["110793.74000000","0.00000000"],["110797.71000000","0.00264000"],["110798.00000000","0.00105000"],["110801.72000000","0.00000000"],["110801.73000000","0.00000000"],["110801.75000000","0.00000000"],["110803.68000000","0.00000000"],["110808.31000000","0.00000000"],["110866.25000000","0.13522000"],["110866.39000000","0.00000000"],["111031.72000000","4.76244000"],["111032.52000000","0.00000000"],["111032.53000000","0.00000000"],["111064.93000000","0.00000000"],["111103.69000000","0.07576000"],["111253.55000000","0.00000000"],["111275.39000000","0.00000000"],["128001.97000000","0.00040000"]]}
[2025-10-11T22:18:47.334Z] {"e":"depthUpdate","E":1760221127014,"s":"BTCUSDT","U":77926044533,"u":77926048583,"b":[["110788.19000000","0.00000000"],["110788.18000000","0.00000000"],["110788.11000000","0.00000000"],["110788.03000000","0.00000000"],["110787.88000000","0.00000000"],["110787.87000000","0.00000000"],["110787.86000000","0.00000000"],["110787.82000000","0.00000000"],["110787.81000000","0.00000000"],["110785.98000000","0.00000000"],["110785.14000000","0.00000000"],["110785.05000000","0.00000000"],["110784.61000000","0.00000000"],["110784.60000000","0.00000000"],["110784.32000000","0.00000000"],["110784.31000000","0.00000000"],["110783.68000000","0.00000000"],["110783.67000000","0.00000000"],["110783.33000000","0.00000000"],["110783.29000000","0.00000000"],["110783.28000000","0.00000000"],["110783.27000000","0.00000000"],["110783.23000000","0.00000000"],["110783.19000000","0.00000000"],["110782.86000000","0.00000000"],["110782.85000000","0.00000000"],["110782.83000000","0.00000000"],["110782.51000000","0.00000000"],["110782.50000000","0.00000000"],["110782.18000000","0.00000000"],["110782.02000000","0.00000000"],["110782.01000000","0.00000000"],["110781.50000000","0.00000000"],["110781.49000000","0.00000000"],["110781.15000000","0.00000000"],["110781.14000000","0.00000000"],["110781.11000000","0.00000000"],["110780.23000000","0.00000000"],["110780.00000000","0.00000000"],["110779.99000000","0.00000000"],["110779.67000000","0.00000000"],["110779.66000000","0.00000000"],["110779.62000000","0.00000000"],["110777.80000000","0.00000000"],["110777.14000000","0.00000000"],["110777.13000000","0.00000000"],["110777.12000000","0.00000000"],["110777.11000000","0.00000000"],["110777.10000000","0.00000000"],["110777.08000000","0.00000000"],["110777.06000000","0.00000000"],["110777.05000000","0.00000000"],["110777.04000000","0.00000000"],["110776.95000000","0.00000000"],["110776.84000000","0.00000000"],["110776.80000000","0.00000000"],["110776.73000000","0.00000000"],["110776.29000000","0.00000000"],["110776.28000000","0.00000000"],["110776.17000000","0.00000000"],["110776.16000000","0.00000000"],["110776.15000000","0.00000000"],["110776.14000000","0.00000000"],["110775.84000000","0.00000000"],["110775.16000000","0.00000000"],["110774.94000000","0.00000000"],["110774.93000000","0.00000000"],["110774.68000000","0.00000000"],["110774.62000000","0.00000000"],["110774.49000000","0.00000000"],["110774.45000000","0.00085000"],["110774.44000000","0.00055000"],["110774.42000000","0.00000000"],["110774.36000000","0.00000000"],["110774.34000000","0.00000000"],["110774.32000000","0.00000000"],["110774.02000000","0.00000000"],["110773.79000000","0.00000000"],["110773.63000000","0.00000000"],["110773.41000000","0.00000000"],["110773.21000000","0.00000000"],["110773.18000000","0.00000000"],["110772.71000000","0.00000000"],["110772.70000000","0.00000000"],["110772.69000000","0.00000000"],["110772.48000000","0.00000000"],["110772.29000000","0.00000000"],["110772.10000000","0.00010000"],["110772.05000000","0.00000000"],["110772.04000000","0.00101000"],["110771.85000000","0.00010000"],["110771.73000000","0.00005000"],["110771.69000000","0.00000000"],["110771.64000000","0.00000000"],["110771.57000000","0.00000000"],["110771.36000000","0.00000000"],["110771.03000000","0.00010000"],["110771.02000000","0.01816000"],["110770.65000000","0.00000000"],["110770.64000000","0.00000000"],["110770.63000000","0.00000000"],["110770.53000000","0.00000000"],["110770.52000000","0.00000000"],["110770.38000000","0.00000000"],["110770.30000000","0.00000000"],["110770.22000000","0.00000000"],["110769.95000000","0.00000000"],["110769.79000000","0.00010000"],["110769.78000000","0.00000000"],["110769.54000000","0.00000000"],["110769.53000000","0.00000000"],["110769.34000000","0.00000000"],["110769.21000000","0.00000000"],["110769.14000000","0.00000000"],["110769.12000000","0.00000000"],["110768.78000000","0.00000000"],["110768.48000000","0.00000000"],["110768.37000000","0.00000000"],["110768.33000000","0.00000000"],["110768.32000000","0.00000000"],["110768.24000000","0.00000000"],["110768.12000000","0.00000000"],["110768.11000000","0.00000000"],["110768.00000000","0.00203000"],["110767.99000000","0.00000000"],["110767.55000000","0.00000000"],["110767.36000000","0.00010000"],["110767.35000000","0.05525000"],["110767.16000000","0.00000000"],["110767.13000000","0.00000000"],["110767.02000000","0.00000000"],["110766.74000000","0.00000000"],["110766.73000000","0.00000000"],["110766.70000000","0.00000000"],["110766.69000000","0.00000000"],["110766.66000000","0.00149000"],["110766.41000000","0.00000000"],["110766.19000000","0.00000000"],["110766.18000000","0.00000000"],["110766.17000000","0.00000000"],["110766.16000000","0.00000000"],["110766.07000000","0.05359000"],["110766.04000000","0.00000000"],["110766.03000000","0.00000000"],["110765.96000000","0.00000000"],["110765.95000000","0.00000000"],["110765.66000000","0.00000000"],["110765.62000000","0.00000000"],["110765.33000000","0.00000000"],["110765.32000000","0.00000000"],["110765.06000000","0.00000000"],["110764.83000000","0.00000000"],["110764.82000000","0.00010000"],["110764.81000000","0.55010000"],["110764.77000000","0.00000000"],["110764.21000000","0.00000000"],["110763.98000000","0.00000000"],["110763.81000000","0.00000000"],["110763.80000000","0.00000000"],["110763.76000000","0.00000000"],["110763.31000000","0.00000000"],["110762.72000000","0.00000000"],["110762.56000000","0.00000000"],["110762.20000000","0.00000000"],["110762.09000000","0.00000000"],["110761.78000000","0.00010000"],["110761.77000000","0.09971000"],["110761.50000000","0.00000000"],["110761.35000000","0.00000000"],["110761.23000000","0.00005000"],["110761.22000000","0.12116000"],["110760.49000000","0.00000000"],["110760.13000000","0.00000000"],["110760.00000000","0.00005000"],["110759.95000000","0.00000000"],["110759.82000000","0.00000000"],["110759.44000000","0.00000000"],["110759.17000000","0.00000000"],["110759.13000000","0.00000000"],["110759.12000000","0.00000000"],["110758.99000000","0.00000000"],["110758.90000000","0.00000000"],["110758.71000000","0.00000000"],["110758.49000000","0.00000000"],["110758.48000000","0.00070000"],["110758.17000000","0.00000000"],["110758.13000000","0.04095000"],["110757.78000000","0.00000000"],["110757.77000000","0.00073000"],["110757.72000000","0.00000000"],["110757.58000000","0.00000000"],["110757.30000000","0.00005000"],["110757.15000000","0.00000000"],["110757.14000000","0.00000000"],["110757.02000000","0.04112000"],["110756.92000000","0.00000000"],["110756.91000000","0.00300000"],["110756.73000000","0.00000000"],["110756.70000000","0.00000000"],["110756.16000000","0.00000000"],["110755.49000000","0.00000000"],["110755.40000000","0.00000000"],["110755.39000000","0.00000000"],["110755.17000000","0.04800000"],["110755.00000000","0.00000000"],["110754.95000000","0.04518000"],["110754.04000000","0.00000000"],["110753.84000000","0.30470000"],["110753.83000000","0.01812000"],["110753.59000000","0.32468000"],["110753.38000000","0.00000000"],["110753.25000000","0.00000000"],["110752.55000000","0.08567000"],["110752.25000000","0.18035000"],["110752.24000000","0.00000000"],["110751.86000000","0.00325000"],["110751.01000000","0.00000000"],["110750.07000000","0.32469000"],["110750.02000000","0.32181000"],["110750.01000000","0.00000000"],["110749.99000000","0.00000000"],["110749.66000000","0.00000000"],["110749.59000000","0.00000000"],["110749.44000000","0.00000000"],["110749.41000000","0.11273000"],["110749.14000000","0.00000000"],["110748.42000000","0.00000000"],["110748.16000000","0.00000000"],["110748.15000000","0.04800000"],["110748.14000000","0.00000000"],["110747.59000000","0.00000000"],["110747.16000000","0.00000000"],["110746.84000000","0.00000000"],["110746.77000000","0.32470000"],["110746.70000000","0.00000000"],["110746.44000000","0.04508000"],["110746.21000000","0.32470000"],["110746.20000000","0.00000000"],["110746.06000000","0.00000000"],["110745.95000000","0.00000000"],["110745.12000000","0.00000000"],["110745.11000000","0.00300000"],["110744.84000000","0.00000000"],["110744.83000000","0.00000000"],["110744.14000000","0.00027000"],["110743.93000000","0.35595000"],["110743.71000000","0.04800000"],["110743.55000000","0.00000000"],["110743.46000000","0.00000000"],["110743.36000000","0.00000000"],["110743.35000000","0.00000000"],["110743.00000000","0.00000000"],["110742.61000000","0.38209000"],["110742.60000000","0.45000000"],["110741.48000000","0.00000000"],["110741.45000000","0.04800000"],["110741.34000000","0.04800000"],["110741.26000000","0.04800000"],["110740.66000000","0.00000000"],["110740.00000000","0.00532000"],["110739.89000000","0.00000000"],["110738.60000000","0.00000000"],["110738.46000000","0.00000000"],["110738.06000000","0.00000000"],["110737.71000000","0.20211000"],["110737.70000000","1.29685000"],["110737.69000000","0.00000000"],["110737.36000000","0.00000000"],["110736.76000000","0.00000000"],["110736.03000000","0.49731000"],["110735.65000000","0.00000000"],["110735.52000000","0.00000000"],["110735.35000000","0.22546000"],["110734.90000000","0.08567000"],["110734.77000000","0.00000000"],["110734.75000000","0.01775000"],["110733.57000000","0.00000000"],["110733.41000000","0.08567000"],["110733.27000000","0.00000000"],["110731.91000000","0.13527000"],["110730.37000000","0.00000000"],["110729.76000000","0.00000000"],["110729.68000000","1.21344000"],["110729.66000000","0.00000000"],["110729.07000000","0.00000000"],["110729.06000000","0.00000000"],["110728.66000000","0.22546000"],["110728.32000000","0.00005000"],["110727.27000000","0.00007000"],["110726.67000000","0.00000000"],["110726.27000000","0.00000000"],["110725.37000000","0.00000000"],["110725.27000000","0.00000000"],["110725.04000000","0.00446000"],["110724.88000000","0.00000000"],["110724.27000000","0.00000000"],["110724.16000000","0.00000000"],["110723.87000000","0.00000000"],["110723.67000000","0.00000000"],["110722.26000000","0.00005000"],["110721.97000000","0.00000000"],["110721.91000000","0.00000000"],["110721.57000000","0.00269000"],["110721.28000000","0.04000000"],["110720.98000000","0.18031000"],["110720.97000000","0.02000000"],["110720.77000000","0.00000000"],["110720.67000000","0.00000000"],["110719.52000000","0.00000000"],["110719.20000000","0.00000000"],["110718.57000000","0.00000000"],["110717.53000000","0.08567000"],["110716.93000000","1.34134000"],["110716.80000000","0.00000000"],["110716.67000000","0.60000000"],["110714.94000000","0.00000000"],["110714.15000000","0.18026000"],["110714.12000000","0.00000000"],["110713.64000000","3.24539000"],["110711.93000000","0.00000000"],["110710.99000000","0.00000000"],["110710.47000000","0.00000000"],["110710.03000000","0.02144000"],["110708.82000000","0.00000000"],["110708.76000000","0.00000000"],["110708.69000000","0.13522000"],["110708.50000000","0.00000000"],["110708.19000000","0.00000000"],["110707.88000000","0.00000000"],["110707.14000000","0.00000000"],["110706.99000000","3.24539000"],["110706.07000000","0.00000000"],["110705.36000000","0.00000000"],["110704.63000000","0.00000000"],["110704.29000000","0.00630000"],["110703.40000000","0.08567000"],["110702.49000000","0.00616000"],["110702.43000000","0.00000000"],["110702.13000000","0.00624000"],["110701.99000000","0.06862000"],["110700.34000000","3.24539000"],["110698.80000000","0.08567000"],["110695.18000000","0.00000000"],["110693.77000000","0.00000000"],["110693.69000000","3.24539000"],["110692.92000000","0.00000000"],["110692.46000000","0.00656000"],["110691.50000000","0.00005000"],["110688.96000000","0.02141000"],["110687.62000000","0.00000000"],["110687.04000000","3.24539000"],["110685.39000000","0.00000000"],["110684.15000000","0.13527000"],["110683.06000000","0.00000000"],["110682.19000000","0.00000000"],["110681.85000000","0.04800000"],["110681.63000000","0.00000000"],["110680.40000000","3.24539000"],["110679.17000000","0.00005000"],["110678.85000000","0.00000000"],["110676.34000000","0.00000000"],["110676.22000000","0.00000000"],["110675.77000000","0.04800000"],["110674.37000000","0.10992000"],["110672.29000000","0.00000000"],["110671.61000000","0.00000000"],["110671.60000000","0.00000000"],["110671.53000000","0.04800000"],["110669.87000000","0.13527000"],["110668.98000000","0.07994000"],["110668.09000000","0.00000000"],["110668.00000000","0.00132000"],["110667.98000000","0.00000000"],["110667.29000000","0.02149000"],["110666.91000000","0.00000000"],["110666.90000000","0.07002000"],["110666.67000000","0.00000000"],["110666.38000000","0.00000000"],["110666.01000000","0.01895000"],["110663.13000000","0.00000000"],["110663.12000000","0.00000000"],["110663.11000000","0.00000000"],["110661.38000000","0.00111000"],["110660.72000000","0.00000000"],["110660.23000000","0.00167000"],["110659.86000000","0.03939000"],["110659.20000000","0.00100000"],["110658.63000000","0.30175000"],["110657.79000000","0.22546000"],["110657.58000000","0.00000000"],["110649.53000000","0.00000000"],["110648.32000000","0.04800000"],["110646.99000000","0.00000000"],["110643.80000000","0.04805000"],["110642.99000000","0.13757000"],["110642.43000000","0.04800000"],["110641.17000000","0.00000000"],["110640.58000000","0.00000000"],["110638.86000000","0.00000000"],["110631.35000000","0.00160000"],["110631.34000000","0.09641000"],["110623.54000000","0.00000000"],["110616.37000000","0.00000000"],["110609.92000000","0.99883000"],["110608.59000000","0.00000000"],["110596.84000000","0.00000000"],["110562.04000000","0.08994000"],["110560.41000000","0.00000000"],["110555.94000000","0.08994000"],["110551.71000000","0.00000000"],["110551.43000000","0.00587000"],["110549.71000000","0.00067000"],["110542.82000000","0.00000000"],["110540.48000000","0.00000000"],["110479.57000000","0.00000000"],["110476.18000000","0.00000000"],["110465.17000000","0.00000000"],["110462.66000000","0.05430000"],["110446.36000000","0.00010000"],["110442.55000000","0.00010000"],["110438.08000000","0.00000000"],["110437.02000000","0.00000000"],["110418.31000000","0.00000000"],["110396.69000000","0.45135000"],["110396.22000000","0.07495000"],["110390.87000000","0.00000000"],["110390.14000000","0.00000000"],["110384.05000000","0.02898000"],["110372.69000000","0.00000000"],["110346.41000000","0.00338000"],["110305.54000000","0.02527000"],["110299.03000000","0.02527000"],["110262.71000000","0.00000000"],["110261.85000000","0.00000000"],["110123.47000000","0.00000000"],["105378.62000000","0.00000000"],["101905.53000000","0.00000000"],["99709.00000000","0.00000000"],["99699.00000000","0.01160000"],["88630.56000000","0.00000000"],["88626.01000000","0.00000000"],["88619.56000000","0.00022000"],["33000.00000000","3.75190000"]],"a":[["110774.46000000","13.18943000"],["110774.54000000","0.00010000"],["110775.45000000","0.00000000"],["110775.52000000","0.00005000"],["110775.54000000","0.00005000"],["110775.55000000","0.04022000"],["110776.14000000","3.29873000"],["110776.15000000","0.00005000"],["110776.17000000","0.00005000"],["110776.18000000","0.33769000"],["110776.54000000","0.00000000"],["110776.61000000","0.00000000"],["110776.63000000","0.00000000"],["110776.64000000","0.00000000"],["110776.74000000","0.00000000"],["110776.75000000","0.04513000"],["110776.80000000","0.00005000"],["110776.81000000","0.00000000"],["110777.05000000","0.18031000"],["110777.09000000","0.00000000"],["110777.11000000","0.00000000"],["110777.12000000","1.15399000"],["110777.20000000","0.00000000"],["110777.28000000","0.00913000"],["110777.50000000","0.01354000"],["110777.81000000","0.00000000"],["110779.04000000","0.32461000"],["110779.67000000","0.00000000"],["110779.68000000","0.15349000"],["110779.98000000","0.00000000"],["110780.00000000","0.00005000"],["110780.01000000","0.00000000"],["110780.22000000","0.44826000"],["110780.23000000","0.04518000"],["110781.13000000","0.00000000"],["110781.15000000","0.00000000"],["110781.16000000","0.04012000"],["110781.50000000","0.00000000"],["110781.51000000","0.00000000"],["110781.67000000","0.00000000"],["110781.74000000","0.00000000"],["110781.76000000","0.29755000"],["110781.77000000","0.00000000"],["110782.01000000","0.00005000"],["110782.02000000","0.18026000"],["110782.03000000","0.12619000"],["110782.11000000","0.00000000"],["110782.42000000","0.00000000"],["110782.48000000","0.00000000"],["110782.50000000","0.00000000"],["110782.51000000","0.00000000"],["110782.52000000","0.22546000"],["110782.65000000","0.11273000"],["110782.70000000","0.00000000"],["110782.72000000","0.00000000"],["110782.79000000","0.00000000"],["110782.81000000","0.00000000"],["110782.82000000","0.00000000"],["110782.84000000","0.32460000"],["110782.85000000","0.00000000"],["110782.86000000","0.04547000"],["110782.87000000","0.04012000"],["110783.14000000","0.04062000"],["110783.18000000","0.00000000"],["110783.19000000","0.00000000"],["110783.20000000","0.00000000"],["110783.21000000","0.01805000"],["110783.23000000","0.00000000"],["110783.24000000","0.00087000"],["110783.26000000","0.00000000"],["110783.27000000","0.00000000"],["110783.28000000","0.00000000"],["110783.29000000","0.00000000"],["110783.30000000","0.00000000"],["110783.31000000","0.00000000"],["110783.33000000","0.00000000"],["110783.34000000","0.00000000"],["110783.40000000","0.00000000"],["110783.58000000","0.00000000"],["110783.67000000","0.09974000"],["110783.68000000","0.04012000"],["110783.89000000","0.00000000"],["110784.03000000","0.00000000"],["110784.30000000","0.00000000"],["110784.32000000","1.56217000"],["110784.33000000","0.13527000"],["110784.38000000","0.32459000"],["110784.39000000","0.00000000"],["110784.41000000","0.00000000"],["110784.58000000","0.00000000"],["110784.60000000","0.00000000"],["110784.61000000","0.04012000"],["110784.62000000","0.00000000"],["110785.06000000","0.00000000"],["110785.10000000","0.03615000"],["110785.35000000","0.00000000"],["110785.99000000","0.00000000"],["110786.46000000","0.00005000"],["110786.86000000","0.01805000"],["110787.42000000","3.24539000"],["110787.43000000","0.00000000"],["110787.45000000","0.00000000"],["110787.46000000","0.04012000"],["110787.79000000","0.00000000"],["110787.81000000","0.00000000"],["110787.82000000","0.03610000"],["110787.85000000","0.00005000"],["110787.87000000","0.00000000"],["110787.88000000","0.00000000"],["110787.89000000","0.00000000"],["110788.04000000","0.00000000"],["110788.12000000","0.00000000"],["110788.17000000","0.00000000"],["110788.19000000","0.45036000"],["110788.20000000","0.50910000"],["110788.21000000","0.00296000"],["110788.26000000","0.00000000"],["110788.27000000","0.00000000"],["110788.28000000","0.00000000"],["110788.36000000","0.00000000"],["110788.44000000","0.00000000"],["110788.45000000","0.00000000"],["110788.51000000","0.01805000"],["110788.58000000","0.00000000"],["110788.68000000","0.18026000"],["110788.71000000","0.03610000"],["110788.76000000","0.01834000"],["110789.48000000","0.00000000"],["110789.50000000","0.00400000"],["110789.75000000","0.00000000"],["110789.77000000","0.00007000"],["110789.83000000","0.00000000"],["110790.00000000","0.00100000"],["110790.07000000","0.01805000"],["110790.15000000","0.00000000"],["110790.16000000","0.00000000"],["110790.58000000","0.08520000"],["110790.59000000","0.00000000"],["110790.89000000","1.05519000"],["110790.90000000","3.24539000"],["110790.91000000","0.00000000"],["110790.95000000","0.00010000"],["110790.98000000","0.00000000"],["110791.02000000","0.00000000"],["110791.03000000","0.00000000"],["110791.12000000","0.06240000"],["110791.15000000","0.08567000"],["110791.23000000","0.04000000"],["110791.34000000","0.00000000"],["110791.44000000","0.00000000"],["110791.67000000","0.00000000"],["110791.68000000","0.00000000"],["110791.99000000","0.00000000"],["110792.00000000","0.00100000"],["110792.01000000","0.05760000"],["110792.07000000","0.00542000"],["110792.12000000","0.01805000"],["110792.23000000","0.00007000"],["110792.55000000","0.01882000"],["110792.59000000","0.00000000"],["110792.60000000","0.00000000"],["110792.91000000","0.00000000"],["110792.98000000","0.10080000"],["110793.18000000","0.00722000"],["110793.36000000","0.00015000"],["110793.40000000","0.00000000"],["110793.50000000","0.18026000"],["110793.73000000","0.00000000"],["110793.76000000","0.01805000"],["110794.00000000","0.00100000"],["110794.03000000","0.00000000"],["110794.08000000","0.00006000"],["110794.29000000","0.00000000"],["110794.73000000","1.93777000"],["110795.09000000","0.08567000"],["110795.15000000","0.08160000"],["110795.52000000","3.24539000"],["110795.80000000","0.00000000"],["110795.81000000","0.00000000"],["110795.89000000","0.00000000"],["110795.96000000","0.00000000"],["110796.00000000","0.00100000"],["110796.19000000","0.00000000"],["110796.59000000","0.00000000"],["110796.78000000","0.00000000"],["110796.79000000","0.02709000"],["110796.92000000","0.00000000"],["110797.01000000","0.00000000"],["110797.26000000","0.18026000"],["110797.36000000","0.12000000"],["110797.49000000","0.10560000"],["110797.64000000","0.00000000"],["110797.71000000","0.00259000"],["110798.00000000","0.00100000"],["110798.28000000","0.19680000"],["110798.81000000","0.00000000"],["110798.93000000","3.24539000"],["110799.43000000","0.00000000"],["110800.78000000","0.00000000"],["110801.21000000","1.46951000"],["110801.48000000","0.08567000"],["110801.55000000","0.00000000"],["110801.56000000","0.00000000"],["110801.71000000","0.00000000"],["110801.75000000","0.00000000"],["110802.46000000","0.06646000"],["110802.56000000","0.00000000"],["110802.60000000","0.00000000"],["110803.81000000","0.00000000"],["110803.93000000","3.24539000"],["110804.34000000","0.00000000"],["110804.40000000","0.00000000"],["110804.53000000","0.00000000"],["110804.82000000","0.00000000"],["110804.88000000","0.00901000"],["110805.11000000","0.00000000"],["110806.38000000","0.03538000"],["110806.62000000","0.00000000"],["110806.80000000","0.00000000"],["110807.44000000","2.24150000"],["110807.45000000","3.24539000"],["110807.86000000","0.00000000"],["110807.97000000","0.00000000"],["110808.62000000","0.00000000"],["110809.33000000","0.00000000"],["110810.33000000","0.00000000"],["110810.96000000","0.00000000"],["110811.63000000","0.00000000"],["110812.19000000","0.00000000"],["110812.48000000","0.00000000"],["110812.50000000","0.00400000"],["110812.61000000","0.00000000"],["110812.91000000","0.04509000"],["110812.96000000","0.00180000"],["110813.01000000","0.49538000"],["110813.94000000","0.05598000"],["110815.56000000","0.00000000"],["110815.67000000","0.00000000"],["110815.93000000","0.00000000"],["110816.41000000","0.00000000"],["110817.03000000","0.00000000"],["110817.89000000","0.00000000"],["110818.00000000","0.00120000"],["110818.18000000","0.00180000"],["110818.23000000","0.00000000"],["110819.00000000","0.00000000"],["110819.38000000","0.00000000"],["110820.11000000","0.02800000"],["110820.53000000","0.00180000"],["110821.35000000","0.00000000"],["110821.94000000","0.00000000"],["110823.65000000","0.00005000"],["110824.23000000","0.00000000"],["110824.79000000","0.00000000"],["110825.16000000","0.00000000"],["110826.22000000","0.03150000"],["110826.70000000","0.00000000"],["110826.80000000","0.00000000"],["110831.34000000","0.00000000"],["110832.84000000","0.00000000"],["110834.01000000","0.06728000"],["110834.74000000","0.00000000"],["110837.40000000","0.00000000"],["110838.91000000","0.00000000"],["110839.82000000","0.00615000"],["110839.92000000","0.00648000"],["110840.99000000","0.00623000"],["110841.62000000","0.00630000"],["110841.70000000","0.00553000"],["110842.33000000","0.00000000"],["110843.31000000","0.04996000"],["110843.46000000","0.00010000"],["110845.09000000","0.00000000"],["110850.40000000","0.00551000"],["110850.93000000","0.00000000"],["110851.27000000","0.00000000"],["110851.81000000","0.00000000"],["110852.87000000","0.00000000"],["110853.87000000","0.00000000"],["110854.11000000","0.00000000"],["110854.29000000","0.00000000"],["110854.84000000","0.00000000"],["110854.91000000","0.11520000"],["110855.08000000","0.00000000"],["110855.36000000","0.00000000"],["110856.50000000","0.00000000"],["110856.89000000","0.00000000"],["110857.11000000","0.30475000"],["110857.21000000","0.00000000"],["110859.41000000","0.00000000"],["110860.94000000","0.00000000"],["110861.66000000","0.00112000"],["110862.95000000","0.02452000"],["110864.33000000","0.03969000"],["110866.25000000","0.00000000"],["110866.73000000","0.00000000"],["110867.26000000","0.00000000"],["110867.58000000","0.00000000"],["110867.59000000","0.00000000"],["110871.05000000","0.90095000"],["110871.94000000","0.00000000"],["110873.31000000","0.00000000"],["110873.98000000","0.14806000"],["110874.24000000","0.00000000"],["110876.42000000","0.00000000"],["110877.60000000","0.00000000"],["110878.91000000","0.16837000"],["110879.62000000","0.00000000"],["110880.45000000","0.00000000"],["110880.55000000","0.09641000"],["110880.89000000","0.00000000"],["110883.41000000","0.00000000"],["110883.63000000","0.00000000"],["110883.68000000","0.00000000"],["110884.05000000","0.00000000"],["110884.13000000","0.00331000"],["110885.36000000","0.00000000"],["110886.47000000","0.00000000"],["110887.03000000","0.00000000"],["110891.98000000","0.03997000"],["110893.46000000","0.00000000"],["110895.98000000","0.04864000"],["110897.80000000","0.00000000"],["110898.09000000","0.00000000"],["110898.10000000","0.00000000"],["110899.63000000","0.03997000"],["110905.65000000","0.00000000"],["110906.06000000","0.00000000"],["110907.75000000","0.00525000"],["110911.37000000","0.00000000"],["110913.17000000","0.00000000"],["110917.15000000","0.00000000"],["110917.56000000","0.00000000"],["110920.25000000","0.00000000"],["110922.90000000","0.00000000"],["110927.97000000","0.00000000"],["110932.96000000","0.02710000"],["110935.07000000","0.99241000"],["110937.48000000","0.00000000"],["110939.42000000","0.39186000"],["110946.34000000","0.00000000"],["110946.35000000","0.00000000"],["110950.57000000","0.00000000"],["110955.12000000","0.00000000"],["110956.66000000","0.00000000"],["110961.67000000","0.00000000"],["110966.72000000","0.02617000"],["110967.98000000","0.00000000"],["110972.98000000","0.00000000"],["110977.82000000","0.00000000"],["110983.42000000","0.40425000"],["110984.98000000","0.00000000"],["110993.55000000","0.00000000"],["110994.60000000","0.00000000"],["111007.36000000","0.00000000"],["111012.52000000","0.00000000"],["111019.23000000","0.00000000"],["111024.33000000","0.00000000"],["111026.87000000","0.05981000"],["111043.53000000","0.00000000"],["111047.89000000","0.00000000"],["111060.19000000","0.00000000"],["111076.85000000","0.00000000"],["111094.53000000","0.00000000"],["111100.16000000","0.00005000"],["111157.86000000","0.00082000"],["111179.39000000","0.00000000"],["111246.20000000","0.00000000"],["111257.28000000","0.00000000"],["111340.57000000","0.00000000"],["112500.00000000","3.47558000"],["116326.25000000","0.00020000"],["116571.01000000","0.00010000"],["117500.55000000","0.00025000"],["128001.97000000","0.03006000"]]}
[2025-10-11T22:18:48.333Z] {"e":"depthUpdate","E":1760221128014,"s":"BTCUSDT","U":77926048584,"u":77926050341,"b":[["110774.45000000","0.00000000"],["110774.44000000","0.00000000"],["110772.10000000","0.00000000"],["110772.04000000","0.00000000"],["110772.03000000","0.00000000"],["110771.85000000","0.00000000"],["110771.73000000","0.00000000"],["110771.10000000","0.00000000"],["110771.03000000","0.00000000"],["110771.02000000","0.00000000"],["110771.01000000","0.00000000"],["110770.92000000","0.00000000"],["110770.74000000","0.00000000"],["110770.62000000","0.00000000"],["110769.83000000","0.00000000"],["110769.79000000","0.00000000"],["110768.61000000","0.00000000"],["110768.10000000","0.00000000"],["110768.00000000","0.00000000"],["110767.82000000","0.00000000"],["110767.75000000","0.00000000"],["110767.36000000","0.00000000"],["110767.35000000","0.00000000"],["110766.66000000","0.00000000"],["110766.08000000","0.00000000"],["110766.07000000","0.00000000"],["110764.82000000","0.00000000"],["110764.81000000","0.55301000"],["110764.80000000","0.00060000"],["110764.73000000","0.00010000"],["110764.72000000","0.00000000"],["110763.26000000","0.00000000"],["110762.34000000","0.00000000"],["110761.78000000","0.00000000"],["110761.77000000","0.00000000"],["110761.74000000","0.00005000"],["110761.62000000","0.00000000"],["110761.49000000","0.00000000"],["110761.42000000","0.00000000"],["110761.41000000","0.00000000"],["110761.38000000","0.00000000"],["110761.23000000","0.00000000"],["110761.22000000","0.00000000"],["110761.05000000","0.00005000"],["110760.45000000","0.00000000"],["110760.14000000","0.00000000"],["110760.13000000","0.00000000"],["110760.12000000","0.00000000"],["110759.94000000","0.00150000"],["110759.80000000","0.00000000"],["110759.79000000","0.00000000"],["110759.32000000","0.00000000"],["110759.31000000","0.00000000"],["110759.24000000","0.00000000"],["110759.23000000","0.00000000"],["110759.22000000","0.00000000"],["110758.48000000","0.00000000"],["110758.13000000","0.00000000"],["110757.77000000","0.00000000"],["110757.30000000","0.00000000"],["110757.07000000","0.00000000"],["110757.02000000","0.00000000"],["110756.93000000","0.00000000"],["110756.92000000","0.00000000"],["110756.23000000","0.00000000"],["110756.22000000","0.00000000"],["110755.96000000","0.00000000"],["110755.94000000","0.00000000"],["110755.93000000","0.00000000"],["110755.92000000","0.00000000"],["110755.89000000","0.00000000"],["110755.53000000","0.00000000"],["110755.52000000","0.00000000"],["110755.18000000","0.00000000"],["110755.17000000","0.00000000"],["110754.96000000","0.00000000"],["110754.95000000","0.00009000"],["110754.68000000","0.00000000"],["110754.40000000","0.00149000"],["110754.05000000","0.00000000"],["110754.04000000","0.00000000"],["110753.85000000","0.00000000"],["110753.84000000","0.00000000"],["110753.83000000","0.00000000"],["110753.72000000","0.00000000"],["110753.69000000","0.00010000"],["110753.68000000","0.45005000"],["110753.62000000","0.00710000"],["110753.59000000","0.00000000"],["110753.54000000","0.00000000"],["110753.31000000","0.00000000"],["110752.94000000","0.00000000"],["110752.93000000","0.00000000"],["110752.55000000","0.00000000"],["110752.54000000","0.00000000"],["110752.26000000","0.00000000"],["110752.25000000","0.00000000"],["110752.24000000","0.00000000"],["110752.07000000","0.00000000"],["110752.03000000","0.00000000"],["110751.95000000","0.00000000"],["110751.94000000","0.00000000"],["110751.86000000","0.00000000"],["110751.13000000","0.00000000"],["110750.99000000","0.00000000"],["110750.42000000","0.00010000"],["110750.41000000","0.09521000"],["110750.40000000","0.00000000"],["110750.27000000","0.00000000"],["110750.07000000","0.00000000"],["110750.03000000","0.00010000"],["110750.02000000","0.24431000"],["110749.45000000","0.00000000"],["110749.41000000","0.00000000"],["110749.08000000","0.04035000"],["110749.07000000","0.00000000"],["110748.98000000","0.00005000"],["110748.64000000","0.00000000"],["110748.21000000","0.00010000"],["110748.20000000","0.18191000"],["110748.19000000","0.04514000"],["110748.15000000","0.04805000"],["110747.97000000","0.04084000"],["110747.64000000","0.00000000"],["110746.77000000","0.00000000"],["110746.56000000","0.00005000"],["110746.55000000","0.32470000"],["110746.44000000","0.00000000"],["110746.21000000","0.00000000"],["110746.19000000","0.08567000"],["110745.68000000","0.04800000"],["110745.07000000","0.00000000"],["110744.78000000","0.00069000"],["110744.53000000","0.04800000"],["110744.14000000","0.00000000"],["110744.09000000","0.00073000"],["110743.93000000","0.47703000"],["110743.56000000","0.07200000"],["110742.65000000","0.11273000"],["110742.61000000","0.02141000"],["110742.32000000","0.07200000"],["110741.77000000","0.32472000"],["110741.66000000","0.00000000"],["110741.21000000","0.00300000"],["110740.93000000","0.00000000"],["110740.83000000","0.00000000"],["110740.75000000","0.00000000"],["110740.73000000","0.04800000"],["110740.46000000","0.00000000"],["110739.90000000","0.00005000"],["110738.43000000","0.00404000"],["110737.71000000","0.00000000"],["110737.70000000","0.41280000"],["110736.79000000","0.32473000"],["110736.46000000","0.00328000"],["110736.14000000","0.00127000"],["110735.53000000","0.00000000"],["110734.36000000","0.18026000"],["110733.42000000","0.36073000"],["110733.03000000","0.72067000"],["110732.14000000","0.00000000"],["110731.59000000","0.04508000"],["110731.03000000","0.20212000"],["110731.02000000","0.00000000"],["110730.59000000","0.00000000"],["110725.92000000","0.00006000"],["110724.68000000","0.00000000"],["110723.15000000","0.00000000"],["110722.12000000","0.13527000"],["110720.97000000","0.00000000"],["110719.37000000","0.00000000"],["110717.47000000","0.00000000"],["110716.67000000","0.00000000"],["110716.20000000","0.00005000"],["110716.01000000","0.00000000"],["110715.63000000","0.00000000"],["110714.68000000","0.00000000"],["110713.97000000","0.00000000"],["110711.47000000","0.02000000"],["110710.77000000","0.04000000"],["110710.14000000","0.00005000"],["110709.94000000","0.00012000"],["110709.44000000","1.08094000"],["110708.27000000","0.56000000"],["110706.01000000","0.00000000"],["110704.29000000","0.00000000"],["110704.01000000","0.00000000"],["110702.49000000","0.00000000"],["110702.13000000","0.00000000"],["110701.99000000","0.00000000"],["110701.85000000","0.00000000"],["110701.28000000","0.00000000"],["110701.17000000","0.00000000"],["110700.22000000","0.00000000"],["110700.01000000","0.00000000"],["110700.00000000","0.04892000"],["110699.18000000","0.00000000"],["110699.01000000","0.02998000"],["110698.91000000","0.00000000"],["110697.98000000","0.00000000"],["110695.85000000","0.00000000"],["110693.70000000","0.45036000"],["110693.40000000","0.00000000"],["110690.27000000","0.00629000"],["110688.07000000","0.15803000"],["110687.18000000","0.00634000"],["110686.71000000","0.00631000"],["110685.40000000","0.00000000"],["110684.54000000","0.04800000"],["110683.75000000","0.00000000"],["110680.23000000","0.00000000"],["110679.18000000","0.00000000"],["110678.26000000","0.00000000"],["110677.92000000","0.00005000"],["110676.00000000","0.00137000"],["110674.82000000","0.00000000"],["110674.41000000","0.00196000"],["110673.75000000","3.24539000"],["110672.02000000","0.00224000"],["110667.68000000","0.00000000"],["110667.10000000","3.24539000"],["110666.91000000","0.08906000"],["110662.13000000","0.02341000"],["110659.66000000","0.00000000"],["110657.80000000","0.00000000"],["110657.58000000","0.02298000"],["110654.40000000","0.00000000"],["110653.00000000","0.01380000"],["110651.66000000","0.00000000"],["110650.09000000","0.07200000"],["110649.53000000","0.00000000"],["110648.32000000","0.00000000"],["110647.67000000","0.00000000"],["110647.58000000","0.02527000"],["110647.32000000","0.07200000"],["110644.85000000","0.00000000"],["110644.65000000","0.00000000"],["110643.80000000","0.00005000"],["110643.33000000","0.00000000"],["110642.43000000","0.00000000"],["110639.77000000","0.05509000"],["110634.93000000","0.00000000"],["110631.35000000","0.00000000"],["110631.34000000","0.00000000"],["110630.70000000","0.00000000"],["110626.02000000","0.07712000"],["110623.90000000","0.02298000"],["110621.64000000","0.00160000"],["110619.05000000","0.04197000"],["110611.90000000","0.08794000"],["110609.92000000","0.00000000"],["110607.38000000","0.00000000"],["110605.52000000","0.00000000"],["110601.66000000","0.02527000"],["110598.54000000","0.08811000"],["110598.30000000","0.99962000"],["110570.02000000","0.02618000"],["110569.04000000","0.02618000"],["110566.35000000","0.02898000"],["110519.29000000","0.02527000"],["110518.00000000","0.02527000"],["110500.32000000","0.90397000"],["110489.21000000","0.02898000"],["110478.51000000","0.00000000"],["110435.78000000","0.00010000"],["110430.25000000","0.00000000"],["110396.69000000","0.00000000"],["110381.90000000","0.45140000"],["110346.41000000","0.00005000"],["110319.15000000","0.00000000"],["110198.00000000","0.00000000"],["110175.09000000","0.02823000"],["110168.28000000","0.02298000"],["110167.64000000","0.02298000"],["110106.40000000","0.00000000"],["99699.00000000","0.01150000"],["99693.00000000","0.00010000"],["88619.56000000","0.00000000"],["88616.82000000","0.00000000"],["88611.85000000","0.00022000"],["39877.57000000","0.00016000"],["39875.33000000","0.00016000"]],"a":[["110764.82000000","13.17158000"],["110764.83000000","0.00000000"],["110764.90000000","0.00010000"],["110764.99000000","0.00000000"],["110765.49000000","0.00000000"],["110766.08000000","0.93620000"],["110766.09000000","0.00010000"],["110766.13000000","0.03626000"],["110766.79000000","0.01820000"],["110767.33000000","0.04529000"],["110767.36000000","0.00000000"],["110767.37000000","0.00000000"],["110767.69000000","0.32469000"],["110767.73000000","0.00000000"],["110767.78000000","0.01801000"],["110767.79000000","0.04128000"],["110768.62000000","0.00000000"],["110768.84000000","0.04131000"],["110769.50000000","0.00005000"],["110769.84000000","0.00000000"],["110770.35000000","0.11278000"],["110770.62000000","0.01810000"],["110770.74000000","0.00005000"],["110770.76000000","0.00081000"],["110770.97000000","0.64926000"],["110771.00000000","0.00000000"],["110771.02000000","0.16050000"],["110771.03000000","0.39690000"],["110771.11000000","0.00000000"],["110772.02000000","0.00000000"],["110772.03000000","0.00000000"],["110772.04000000","0.00000000"],["110772.05000000","0.33792000"],["110772.11000000","0.00000000"],["110772.13000000","0.00000000"],["110772.25000000","0.01805000"],["110774.44000000","0.00000000"],["110774.45000000","0.39137000"],["110774.46000000","0.54016000"],["110774.54000000","0.00000000"],["110775.52000000","0.00000000"],["110775.54000000","0.00000000"],["110775.55000000","0.04017000"],["110775.90000000","0.45017000"],["110776.14000000","0.00000000"],["110776.15000000","0.00000000"],["110776.17000000","0.00000000"],["110776.18000000","0.04012000"],["110776.38000000","0.08567000"],["110776.75000000","0.04518000"],["110777.00000000","0.00405000"],["110777.05000000","0.18026000"],["110777.12000000","0.07617000"],["110777.28000000","0.00908000"],["110777.50000000","0.01359000"],["110778.25000000","0.04399000"],["110778.65000000","0.00010000"],["110778.68000000","0.00007000"],["110779.04000000","0.00000000"],["110779.22000000","0.09116000"],["110779.68000000","0.00000000"],["110780.17000000","0.00000000"],["110780.22000000","1.10899000"],["110780.23000000","0.00005000"],["110780.67000000","3.24539000"],["110781.16000000","0.04012000"],["110781.72000000","0.00007000"],["110781.76000000","0.00000000"],["110782.01000000","0.00000000"],["110782.03000000","0.04012000"],["110782.11000000","0.00095000"],["110782.65000000","0.00000000"],["110782.72000000","0.00006000"],["110782.84000000","0.00000000"],["110782.86000000","0.00005000"],["110782.87000000","0.04007000"],["110783.14000000","0.00000000"],["110783.24000000","0.00000000"],["110783.67000000","0.00000000"],["110783.68000000","0.04007000"],["110784.07000000","2.45590000"],["110784.08000000","3.24539000"],["110784.32000000","0.00000000"],["110784.33000000","0.00000000"],["110784.38000000","0.00000000"],["110784.61000000","0.04007000"],["110785.10000000","0.03610000"],["110785.54000000","0.00300000"],["110785.88000000","0.00010000"],["110786.46000000","0.00000000"],["110786.86000000","0.01805000"],["110787.19000000","0.11520000"],["110787.43000000","0.05280000"],["110787.46000000","0.04007000"],["110787.68000000","0.03538000"],["110787.82000000","0.00000000"],["110788.16000000","0.12240000"],["110788.18000000","0.00018000"],["110788.20000000","0.50831000"],["110788.21000000","0.00296000"],["110788.51000000","0.00000000"],["110788.63000000","0.07680000"],["110788.96000000","0.00000000"],["110789.18000000","0.13527000"],["110789.40000000","0.14400000"],["110790.50000000","0.00000000"],["110790.58000000","0.00000000"],["110790.85000000","0.08160000"],["110791.20000000","0.01178000"],["110791.23000000","0.00000000"],["110791.99000000","0.05598000"],["110792.14000000","0.00901000"],["110792.23000000","0.00000000"],["110792.94000000","0.00012000"],["110793.36000000","0.00000000"],["110793.76000000","0.00000000"],["110794.52000000","0.00270000"],["110796.57000000","0.00445000"],["110798.04000000","0.04509000"],["110798.66000000","0.00000000"],["110799.55000000","0.00000000"],["110801.00000000","0.00000000"],["110801.21000000","1.48846000"],["110801.48000000","0.00000000"],["110802.61000000","0.02800000"],["110802.98000000","0.18031000"],["110803.22000000","0.02818000"],["110803.27000000","0.22546000"],["110803.29000000","0.49630000"],["110803.30000000","0.00180000"],["110803.59000000","1.19615000"],["110804.88000000","0.00000000"],["110806.38000000","0.00000000"],["110807.23000000","0.00000000"],["110808.38000000","0.03150000"],["110809.58000000","0.00000000"],["110810.54000000","0.00000000"],["110810.60000000","0.00000000"],["110811.24000000","0.00005000"],["110811.35000000","0.13527000"],["110812.50000000","0.00000000"],["110812.81000000","0.00000000"],["110812.91000000","0.00000000"],["110812.96000000","0.00000000"],["110813.01000000","0.00000000"],["110813.94000000","0.00000000"],["110814.91000000","0.00000000"],["110818.00000000","0.00125000"],["110818.10000000","0.00000000"],["110818.18000000","0.00000000"],["110818.58000000","0.13527000"],["110820.11000000","0.00000000"],["110820.53000000","0.00000000"],["110821.44000000","0.00009000"],["110822.54000000","0.00000000"],["110823.09000000","0.00000000"],["110824.14000000","0.00631000"],["110825.28000000","0.00000000"],["110826.22000000","0.00000000"],["110826.38000000","0.00000000"],["110827.66000000","0.00634000"],["110834.32000000","0.00000000"],["110839.82000000","0.00000000"],["110841.11000000","0.00000000"],["110841.12000000","0.00000000"],["110841.62000000","0.00000000"],["110842.93000000","0.00000000"],["110843.79000000","0.00000000"],["110844.86000000","0.00000000"],["110847.63000000","0.00000000"],["110847.64000000","0.00000000"],["110854.91000000","0.19680000"],["110856.73000000","0.00331000"],["110867.10000000","0.00000000"],["110868.29000000","0.49481000"],["110870.11000000","0.12000000"],["110874.32000000","0.00000000"],["110876.08000000","0.00000000"],["110877.05000000","0.00000000"],["110877.35000000","0.00000000"],["110878.34000000","0.00000000"],["110878.91000000","0.00000000"],["110879.46000000","0.00000000"],["110880.52000000","0.00000000"],["110880.81000000","0.00000000"],["110882.63000000","0.00000000"],["110882.64000000","0.00000000"],["110883.18000000","0.00000000"],["110883.69000000","0.00000000"],["110883.80000000","0.00000000"],["110884.13000000","0.00000000"],["110890.35000000","0.00000000"],["110893.11000000","0.00000000"],["110916.47000000","0.00000000"],["110917.15000000","0.40407000"],["110919.41000000","0.99299000"],["110928.77000000","0.00000000"],["110930.63000000","0.00000000"],["110931.82000000","0.00000000"],["110932.96000000","0.00000000"],["110935.07000000","0.00000000"],["110939.42000000","0.00000000"],["110950.57000000","0.42014000"],["110952.78000000","0.00000000"],["110983.42000000","0.40425000"],["111010.21000000","0.14622000"],["111026.87000000","0.17942000"],["111043.53000000","0.00000000"],["111088.73000000","0.00000000"],["111094.63000000","0.00000000"],["111130.42000000","0.00082000"],["111145.10000000","0.02527000"],["111146.18000000","0.02527000"],["111157.86000000","0.00000000"],["111201.88000000","0.45000000"],["111253.98000000","0.00000000"],["111254.10000000","0.00005000"],["111275.39000000","0.67153000"],["128001.97000000","0.03006000"]]}
[2025-10-11T22:18:49.331Z] {"e":"depthUpdate","E":1760221129014,"s":"BTCUSDT","U":77926050342,"u":77926051225,"b":[["110764.81000000","3.15216000"],["110764.80000000","0.00025000"],["110762.96000000","0.00010000"],["110762.95000000","0.09013000"],["110762.94000000","0.29770000"],["110762.60000000","0.00361000"],["110762.55000000","0.00000000"],["110760.94000000","0.00542000"],["110760.54000000","0.00000000"],["110759.83000000","0.00722000"],["110759.29000000","0.00010000"],["110759.28000000","0.04508000"],["110759.27000000","0.00000000"],["110758.04000000","0.00000000"],["110757.74000000","0.00000000"],["110757.73000000","0.00000000"],["110757.57000000","0.00000000"],["110756.91000000","0.00000000"],["110756.51000000","0.00010000"],["110756.50000000","0.00005000"],["110755.33000000","0.00000000"],["110755.32000000","0.00000000"],["110755.31000000","0.00000000"],["110755.04000000","0.00005000"],["110755.03000000","0.42664000"],["110755.02000000","0.32473000"],["110754.95000000","0.04514000"],["110753.73000000","0.11273000"],["110753.70000000","0.00000000"],["110753.69000000","0.00000000"],["110753.68000000","0.45005000"],["110753.62000000","0.00710000"],["110753.09000000","0.00000000"],["110752.33000000","0.00000000"],["110750.94000000","0.18036000"],["110750.58000000","0.00000000"],["110750.57000000","0.32469000"],["110750.42000000","0.00000000"],["110750.41000000","0.09516000"],["110750.03000000","0.00000000"],["110750.02000000","0.41085000"],["110749.19000000","0.00000000"],["110749.09000000","0.00000000"],["110749.08000000","0.04030000"],["110748.21000000","0.00000000"],["110748.20000000","0.18186000"],["110748.19000000","0.00000000"],["110748.15000000","0.04800000"],["110747.76000000","0.00000000"],["110747.65000000","0.00005000"],["110747.30000000","0.18026000"],["110746.56000000","0.00000000"],["110745.69000000","0.20210000"],["110745.09000000","0.45036000"],["110745.08000000","0.32471000"],["110742.65000000","0.00000000"],["110742.03000000","0.04800000"],["110741.77000000","0.00000000"],["110737.05000000","0.00000000"],["110736.79000000","0.00000000"],["110736.78000000","0.01964000"],["110736.63000000","0.00000000"],["110736.58000000","0.00000000"],["110736.46000000","0.00328000"],["110733.67000000","0.00000000"],["110733.03000000","1.56997000"],["110731.92000000","3.24539000"],["110731.58000000","0.00309000"],["110731.03000000","0.00000000"],["110730.60000000","0.02257000"],["110730.37000000","0.04000000"],["110729.68000000","0.00000000"],["110721.72000000","0.00000000"],["110721.71000000","0.04800000"],["110721.28000000","0.00000000"],["110720.51000000","0.00070000"],["110713.33000000","0.07200000"],["110712.08000000","0.07200000"],["110711.47000000","0.00000000"],["110710.77000000","0.00000000"],["110710.17000000","0.02000000"],["110709.02000000","0.04466000"],["110708.77000000","0.04000000"],["110704.12000000","0.00000000"],["110698.35000000","0.00009000"],["110694.21000000","1.29338000"],["110692.98000000","0.06866000"],["110688.48000000","0.00000000"],["110686.15000000","0.00451000"],["110682.63000000","0.00000000"],["110671.72000000","0.00005000"],["110670.05000000","0.03966000"],["110668.26000000","0.00005000"],["110667.68000000","0.04800000"],["110667.10000000","0.00000000"],["110665.12000000","0.00009000"],["110664.05000000","0.00000000"],["110662.75000000","0.00000000"],["110657.45000000","0.03277000"],["110656.40000000","0.02888000"],["110655.24000000","0.00000000"],["110654.15000000","0.00000000"],["110651.31000000","0.00000000"],["110650.09000000","0.00000000"],["110649.80000000","0.00000000"],["110649.53000000","0.04800000"],["110648.23000000","0.00000000"],["110647.32000000","0.00000000"],["110645.74000000","0.00000000"],["110644.50000000","0.09641000"],["110642.99000000","0.19156000"],["110639.77000000","0.04097000"],["110631.89000000","0.00009000"],["110622.01000000","0.00000000"],["110607.85000000","0.99465000"],["110600.79000000","0.13494000"],["110598.66000000","0.00009000"],["110598.30000000","0.00000000"],["110543.34000000","0.08994000"],["110542.20000000","0.08994000"],["110540.95000000","0.08994000"],["110491.49000000","0.02898000"],["110295.43000000","0.02437000"],["109964.08000000","0.00000000"],["99693.00000000","0.00000000"],["99688.00000000","0.01141000"],["99687.00000000","0.00010000"],["88611.85000000","0.00022000"],["39875.33000000","0.00032000"]],"a":[["110764.82000000","10.22315000"],["110764.92000000","0.00010000"],["110764.93000000","0.26150000"],["110764.94000000","0.29770000"],["110766.07000000","0.00000000"],["110766.08000000","0.00000000"],["110766.09000000","0.00000000"],["110766.12000000","0.00000000"],["110766.13000000","0.00000000"],["110766.17000000","0.00005000"],["110766.26000000","0.00010000"],["110766.27000000","0.04529000"],["110766.79000000","0.00000000"],["110767.03000000","0.00361000"],["110767.09000000","0.00000000"],["110767.28000000","0.00005000"],["110767.32000000","0.00000000"],["110767.33000000","0.00000000"],["110767.62000000","0.00010000"],["110767.63000000","0.03626000"],["110767.68000000","0.00000000"],["110767.69000000","0.00000000"],["110767.78000000","0.00000000"],["110767.79000000","0.00000000"],["110767.80000000","0.00000000"],["110767.81000000","0.00000000"],["110767.84000000","0.00000000"],["110767.85000000","0.00000000"],["110768.69000000","0.00542000"],["110768.84000000","0.00000000"],["110769.25000000","0.00000000"],["110769.35000000","0.00000000"],["110769.80000000","0.00722000"],["110769.92000000","0.00000000"],["110769.93000000","0.00000000"],["110770.05000000","0.00000000"],["110770.13000000","0.00810000"],["110770.14000000","0.34278000"],["110770.21000000","0.00000000"],["110770.34000000","0.00000000"],["110770.35000000","0.00000000"],["110770.50000000","0.00000000"],["110770.62000000","0.00005000"],["110770.96000000","0.00005000"],["110770.97000000","0.06651000"],["110771.02000000","0.00000000"],["110771.03000000","0.04508000"],["110771.32000000","0.00000000"],["110771.68000000","0.00000000"],["110771.69000000","0.04005000"],["110772.04000000","0.00000000"],["110772.05000000","0.00005000"],["110772.25000000","0.00000000"],["110772.33000000","0.00000000"],["110774.44000000","0.00000000"],["110774.45000000","0.39137000"],["110774.46000000","0.45491000"],["110774.53000000","0.00000000"],["110774.54000000","0.04107000"],["110775.12000000","0.32462000"],["110775.55000000","0.00000000"],["110775.65000000","0.04121000"],["110775.89000000","0.11273000"],["110776.18000000","0.00000000"],["110776.38000000","0.00000000"],["110776.75000000","0.00005000"],["110777.00000000","0.00400000"],["110777.05000000","0.00000000"],["110777.12000000","0.00000000"],["110777.22000000","0.00000000"],["110778.09000000","0.00000000"],["110778.10000000","0.00000000"],["110778.25000000","0.04399000"],["110779.10000000","0.00000000"],["110779.22000000","0.09126000"],["110779.87000000","0.29592000"],["110779.88000000","0.32461000"],["110780.22000000","0.00000000"],["110780.23000000","0.00000000"],["110780.54000000","0.05760000"],["110780.67000000","0.00000000"],["110780.86000000","0.13527000"],["110781.16000000","0.00000000"],["110781.29000000","0.06646000"],["110782.03000000","0.00000000"],["110782.86000000","0.00005000"],["110782.87000000","0.04007000"],["110783.21000000","0.01805000"],["110783.35000000","0.32460000"],["110785.10000000","0.00000000"],["110786.16000000","0.04708000"],["110786.56000000","0.13522000"],["110786.90000000","0.01964000"],["110786.98000000","0.00300000"],["110787.68000000","0.00000000"],["110789.17000000","0.30434000"],["110790.09000000","0.08567000"],["110791.99000000","0.00000000"],["110792.01000000","0.00000000"],["110792.07000000","0.00000000"],["110792.55000000","0.00000000"],["110793.18000000","0.00000000"],["110798.05000000","0.00009000"],["110803.59000000","0.00000000"],["110808.38000000","0.00000000"],["110810.36000000","0.00000000"],["110813.63000000","0.05598000"],["110817.91000000","0.13544000"],["110818.42000000","0.00000000"],["110819.80000000","0.04412000"],["110821.44000000","0.00000000"],["110821.56000000","0.03150000"],["110831.28000000","0.00009000"],["110836.86000000","0.02706000"],["110842.16000000","0.03538000"],["110842.47000000","0.00331000"],["110842.71000000","0.13522000"],["110846.45000000","0.28334000"],["110849.01000000","0.00440000"],["110854.67000000","0.00000000"],["110856.73000000","0.00000000"],["110864.51000000","0.00009000"],["110873.54000000","0.13544000"],["110875.05000000","0.22546000"],["110876.54000000","0.18031000"],["110876.90000000","0.22546000"],["110885.55000000","0.00196000"],["110887.91000000","0.00000000"],["110893.70000000","0.27708000"],["110897.74000000","0.00009000"],["110909.58000000","0.06000000"],["110919.40000000","0.00000000"],["110919.41000000","0.00000000"],["110921.15000000","0.00000000"],["110922.90000000","0.46794000"],["110927.82000000","0.99008000"],["110930.97000000","0.00009000"],["110931.80000000","0.02710000"],["110947.46000000","0.00000000"],["110948.23000000","0.08794000"],["110954.38000000","0.00000000"],["110955.70000000","0.10785000"],["110956.38000000","0.20378000"],["111026.87000000","0.00000000"],["111043.53000000","0.00000000"],["111116.15000000","0.00082000"],["111130.42000000","0.00000000"],["111238.13000000","0.02437000"],["111304.14000000","0.00046000"],["111309.68000000","0.00000000"],["128001.97000000","0.03006000"]]}
[2025-10-11T22:18:50.332Z] {"e":"depthUpdate","E":1760221130014,"s":"BTCUSDT","U":77926051226,"u":77926051839,"b":[["110764.81000000","1.91778000"],["110764.80000000","0.00025000"],["110763.81000000","0.00010000"],["110763.80000000","0.05924000"],["110762.96000000","0.00000000"],["110762.95000000","0.00000000"],["110762.94000000","0.00000000"],["110760.94000000","0.00547000"],["110760.02000000","0.00000000"],["110759.83000000","0.00727000"],["110759.80000000","0.00000000"],["110759.79000000","0.00000000"],["110759.29000000","0.00000000"],["110759.28000000","0.00000000"],["110759.24000000","0.00010000"],["110759.23000000","0.11571000"],["110759.22000000","0.29771000"],["110757.41000000","0.00000000"],["110757.40000000","0.00000000"],["110757.39000000","0.00000000"],["110756.51000000","0.00000000"],["110756.50000000","0.00000000"],["110756.46000000","0.00000000"],["110756.45000000","0.00000000"],["110756.44000000","0.00000000"],["110755.35000000","0.00010000"],["110755.34000000","0.00010000"],["110755.04000000","0.00010000"],["110755.03000000","0.32353000"],["110755.02000000","0.00000000"],["110754.96000000","0.00000000"],["110754.95000000","0.00000000"],["110753.74000000","0.00000000"],["110753.73000000","0.00000000"],["110753.69000000","0.00000000"],["110753.68000000","0.45005000"],["110753.62000000","0.00710000"],["110753.51000000","0.00000000"],["110753.50000000","0.00000000"],["110753.37000000","0.00000000"],["110753.36000000","0.00000000"],["110753.21000000","0.32468000"],["110752.14000000","0.00000000"],["110752.13000000","0.02710000"],["110750.97000000","0.00000000"],["110750.96000000","0.11273000"],["110750.95000000","0.00000000"],["110750.94000000","0.18036000"],["110750.57000000","0.00000000"],["110750.43000000","0.00000000"],["110750.42000000","0.00000000"],["110750.41000000","0.09516000"],["110748.19000000","0.04509000"],["110747.49000000","0.32470000"],["110747.17000000","0.00000000"],["110746.55000000","0.00000000"],["110746.31000000","0.00000000"],["110746.30000000","0.20210000"],["110746.29000000","0.01788000"],["110745.69000000","0.00000000"],["110745.08000000","0.00000000"],["110744.30000000","0.00005000"],["110743.06000000","0.32471000"],["110742.62000000","0.00000000"],["110741.41000000","0.32472000"],["110741.34000000","0.04800000"],["110740.50000000","0.00000000"],["110740.41000000","0.00000000"],["110738.57000000","0.00000000"],["110737.79000000","0.00000000"],["110736.97000000","0.01964000"],["110736.78000000","0.00000000"],["110736.59000000","0.00000000"],["110734.68000000","0.00000000"],["110731.59000000","0.00000000"],["110730.37000000","0.00000000"],["110727.58000000","0.00000000"],["110724.79000000","0.00000000"],["110720.99000000","0.00000000"],["110720.80000000","1.39364000"],["110718.09000000","0.04000000"],["110692.91000000","0.00000000"],["110684.54000000","0.09197000"],["110684.11000000","0.00005000"],["110680.41000000","1.25450000"],["110674.42000000","0.04397000"],["110657.45000000","0.00000000"],["110656.40000000","0.00000000"],["110655.51000000","0.03277000"],["110653.21000000","0.04397000"],["110647.73000000","0.00000000"],["110645.58000000","0.00000000"],["110644.50000000","0.00000000"],["110643.36000000","0.29210000"],["110643.35000000","0.09641000"],["110643.17000000","0.09641000"],["110642.99000000","0.00000000"],["110642.14000000","0.00000000"],["110640.95000000","0.00000000"],["110607.86000000","0.99892000"],["110607.85000000","0.00000000"],["110600.79000000","0.00000000"],["110427.37000000","0.04397000"],["110100.23000000","0.00000000"],["109500.00000000","9.48430000"],["109102.00000000","0.00092000"],["105392.72000000","0.00090000"],["99688.00000000","0.01141000"],["99687.00000000","0.00010000"],["88611.85000000","0.00022000"],["60000.00000000","56.18404000"],["39875.33000000","0.00048000"]],"a":[["110764.82000000","10.42511000"],["110764.92000000","0.00010000"],["110764.93000000","0.26150000"],["110764.94000000","0.29770000"],["110765.39000000","0.00010000"],["110765.40000000","0.00010000"],["110766.26000000","0.00010000"],["110766.27000000","0.04539000"],["110766.75000000","0.00005000"],["110766.76000000","0.03616000"],["110767.03000000","0.00366000"],["110767.45000000","0.01810000"],["110767.62000000","0.00000000"],["110767.63000000","0.03626000"],["110767.79000000","0.00000000"],["110767.87000000","0.00000000"],["110768.08000000","0.04514000"],["110768.69000000","0.00552000"],["110769.14000000","0.00087000"],["110769.80000000","0.00727000"],["110770.13000000","0.00800000"],["110770.14000000","0.34273000"],["110770.62000000","0.00000000"],["110770.76000000","0.00000000"],["110770.96000000","0.00000000"],["110770.97000000","0.06651000"],["110771.03000000","0.00000000"],["110771.69000000","0.00000000"],["110772.04000000","0.00203000"],["110774.44000000","0.18026000"],["110774.45000000","0.39142000"],["110775.90000000","0.45000000"],["110777.00000000","0.00405000"],["110777.22000000","0.01780000"],["110778.24000000","0.30437000"],["110778.67000000","0.18026000"],["110779.22000000","0.09116000"],["110780.22000000","0.00005000"],["110780.38000000","0.32460000"],["110783.35000000","0.00000000"],["110789.17000000","0.00000000"],["110798.04000000","0.00000000"],["110800.51000000","1.21516000"],["110804.01000000","0.03150000"],["110808.09000000","0.00000000"],["110814.65000000","0.00000000"],["110821.56000000","0.00000000"],["110824.83000000","0.00000000"],["110825.90000000","0.00480000"],["110828.36000000","0.00331000"],["110840.98000000","0.11845000"],["110841.94000000","0.07102000"],["110842.16000000","0.00000000"],["110842.47000000","0.00000000"],["110842.71000000","0.00000000"],["110842.85000000","0.00000000"],["110848.17000000","0.00000000"],["110864.23000000","0.03538000"],["110873.98000000","0.32138000"],["110877.61000000","0.01412000"],["110895.48000000","0.00000000"],["110906.06000000","0.28880000"],["110939.42000000","0.39186000"],["110972.98000000","0.12391000"],["111102.03000000","0.00082000"],["111116.15000000","0.00000000"],["128001.97000000","0.00040000"],["560000.00000000","0.38187000"]]}
[2025-10-11T22:18:51.331Z] {"e":"depthUpdate","E":1760221131014,"s":"BTCUSDT","U":77926051840,"u":77926053313,"b":[["110773.17000000","7.58139000"],["110773.10000000","0.00010000"],["110772.18000000","0.00000000"],["110772.03000000","0.00000000"],["110771.55000000","0.06646000"],["110770.74000000","0.00005000"],["110770.16000000","0.32463000"],["110770.12000000","0.00000000"],["110769.79000000","0.00000000"],["110769.32000000","0.00000000"],["110769.13000000","0.00000000"],["110768.89000000","0.00000000"],["110768.68000000","0.00000000"],["110767.62000000","0.00000000"],["110767.27000000","0.48942000"],["110767.02000000","0.00000000"],["110766.32000000","0.00000000"],["110766.26000000","0.00000000"],["110766.02000000","0.18026000"],["110765.55000000","0.00000000"],["110764.89000000","0.00000000"],["110764.84000000","0.00000000"],["110764.82000000","2.03684000"],["110764.81000000","1.48823000"],["110764.80000000","0.00000000"],["110764.73000000","0.00000000"],["110764.50000000","0.06656000"],["110764.41000000","0.00000000"],["110764.40000000","0.00015000"],["110764.39000000","0.29770000"],["110763.82000000","0.00000000"],["110763.81000000","0.00000000"],["110763.80000000","0.00005000"],["110763.70000000","0.01797000"],["110763.17000000","0.00000000"],["110762.06000000","0.00000000"],["110761.83000000","0.00000000"],["110761.82000000","0.00000000"],["110761.74000000","0.00000000"],["110760.94000000","0.00547000"],["110760.53000000","0.00000000"],["110760.52000000","0.04122000"],["110760.39000000","0.00000000"],["110760.38000000","0.27455000"],["110760.37000000","0.32466000"],["110759.97000000","0.04793000"],["110759.83000000","0.00722000"],["110759.41000000","0.04044000"],["110759.24000000","0.00000000"],["110759.23000000","0.00000000"],["110759.22000000","0.00000000"],["110759.03000000","0.18026000"],["110758.77000000","0.07567000"],["110757.93000000","0.00000000"],["110757.84000000","0.00000000"],["110757.50000000","0.00400000"],["110757.48000000","0.06646000"],["110757.26000000","0.32477000"],["110757.19000000","0.00000000"],["110755.56000000","0.47495000"],["110755.55000000","0.00000000"],["110755.52000000","0.00000000"],["110755.35000000","0.00000000"],["110755.34000000","0.00000000"],["110755.05000000","0.00000000"],["110755.04000000","0.18026000"],["110755.03000000","0.00000000"],["110754.96000000","0.00000000"],["110754.95000000","0.00000000"],["110753.69000000","0.00000000"],["110753.68000000","0.45000000"],["110753.62000000","0.00705000"],["110753.21000000","0.00000000"],["110752.16000000","0.02710000"],["110752.13000000","0.00000000"],["110752.12000000","0.08567000"],["110750.96000000","0.00000000"],["110750.41000000","0.00000000"],["110750.02000000","0.24426000"],["110749.72000000","0.08567000"],["110749.08000000","0.00000000"],["110748.64000000","0.00006000"],["110748.20000000","0.00000000"],["110748.19000000","0.00000000"],["110748.14000000","0.00000000"],["110748.13000000","0.13527000"],["110747.97000000","0.00000000"],["110747.49000000","0.00000000"],["110746.30000000","0.00000000"],["110746.19000000","0.00000000"],["110746.00000000","0.00400000"],["110745.95000000","0.06646000"],["110745.13000000","0.01964000"],["110744.78000000","0.00000000"],["110744.09000000","0.00000000"],["110743.97000000","0.00000000"],["110743.93000000","1.32837000"],["110743.87000000","0.00000000"],["110743.06000000","0.00000000"],["110741.41000000","0.00000000"],["110739.94000000","0.04508000"],["110739.60000000","3.24539000"],["110739.47000000","0.04000000"],["110738.11000000","0.13527000"],["110737.70000000","1.23907000"],["110737.40000000","0.00000000"],["110736.97000000","0.00000000"],["110736.46000000","0.00000000"],["110736.04000000","3.24539000"],["110736.03000000","0.24962000"],["110735.35000000","0.00000000"],["110734.90000000","0.00000000"],["110734.72000000","0.24778000"],["110734.50000000","0.00400000"],["110733.41000000","0.00000000"],["110733.26000000","0.00000000"],["110732.48000000","0.00000000"],["110728.66000000","0.00000000"],["110728.58000000","0.00012000"],["110725.72000000","0.13522000"],["110720.98000000","0.00000000"],["110720.77000000","0.04000000"],["110718.09000000","0.00000000"],["110716.78000000","0.04372000"],["110716.20000000","0.00000000"],["110710.14000000","0.00000000"],["110709.94000000","0.00000000"],["110709.02000000","0.00000000"],["110708.77000000","0.00000000"],["110708.69000000","0.00000000"],["110703.96000000","0.00630000"],["110703.25000000","0.00000000"],["110701.04000000","0.00617000"],["110697.68000000","0.03277000"],["110690.40000000","0.02888000"],["110690.27000000","0.00000000"],["110688.07000000","1.11750000"],["110686.71000000","0.00000000"],["110684.15000000","0.00000000"],["110680.41000000","0.00000000"],["110680.40000000","0.00000000"],["110678.60000000","0.00000000"],["110677.80000000","0.90252000"],["110676.96000000","0.00000000"],["110676.81000000","0.00000000"],["110676.00000000","0.00132000"],["110674.67000000","0.00000000"],["110673.75000000","0.00000000"],["110671.58000000","0.00010000"],["110669.87000000","0.00000000"],["110668.26000000","0.00000000"],["110664.36000000","0.22546000"],["110663.68000000","0.03939000"],["110661.28000000","0.13544000"],["110660.11000000","0.18031000"],["110659.86000000","0.00000000"],["110659.31000000","0.22546000"],["110658.63000000","0.00000000"],["110657.79000000","0.00000000"],["110655.51000000","0.00000000"],["110654.94000000","0.00000000"],["110654.06000000","0.00000000"],["110621.54000000","0.99742000"],["110617.71000000","0.04197000"],["110607.86000000","0.00000000"],["110600.79000000","0.13643000"],["110566.35000000","0.00000000"],["110542.46000000","0.08694000"],["110533.46000000","0.00000000"],["110500.32000000","0.00000000"],["110498.28000000","0.07576000"],["110491.49000000","0.00000000"],["110489.21000000","0.00000000"],["110438.61000000","0.00010000"],["110435.78000000","0.00000000"],["110404.25000000","0.00076000"],["110371.72000000","0.00037000"],["110359.56000000","0.00000000"],["110165.86000000","0.02298000"],["109637.61000000","0.00037000"],["108921.14000000","0.00000000"],["106179.89000000","0.00005000"],["105392.66000000","0.00000000"],["99687.00000000","0.00010000"],["88618.54000000","0.00022000"],["88611.85000000","0.00000000"],["60000.00000000","56.18394000"],["42000.00000000","1.48198000"],["39875.33000000","0.00064000"],["33000.00000000","3.75190000"]],"a":[["110764.82000000","0.00000000"],["110764.83000000","0.00000000"],["110764.90000000","0.00000000"],["110764.92000000","0.00000000"],["110764.93000000","0.00000000"],["110764.94000000","0.00000000"],["110765.39000000","0.00000000"],["110765.40000000","0.00000000"],["110765.56000000","0.00000000"],["110766.17000000","0.00000000"],["110766.26000000","0.00000000"],["110766.27000000","0.00000000"],["110766.47000000","0.00000000"],["110766.48000000","0.00000000"],["110766.57000000","0.00000000"],["110766.58000000","0.00000000"],["110766.75000000","0.00000000"],["110766.76000000","0.00000000"],["110767.03000000","0.00000000"],["110767.28000000","0.00000000"],["110767.45000000","0.00000000"],["110767.62000000","0.00000000"],["110767.63000000","0.00000000"],["110767.75000000","0.00000000"],["110767.89000000","0.00000000"],["110767.90000000","0.00000000"],["110768.08000000","0.00000000"],["110768.58000000","0.00000000"],["110768.59000000","0.00000000"],["110768.69000000","0.00000000"],["110768.90000000","0.00000000"],["110769.14000000","0.00000000"],["110769.36000000","0.00000000"],["110769.50000000","0.00000000"],["110769.80000000","0.00000000"],["110769.89000000","0.00000000"],["110769.94000000","0.00000000"],["110769.98000000","0.00000000"],["110769.99000000","0.00000000"],["110770.13000000","0.00000000"],["110770.14000000","0.00000000"],["110770.74000000","0.00000000"],["110770.77000000","0.00000000"],["110770.78000000","0.00000000"],["110770.96000000","0.00000000"],["110770.97000000","0.00000000"],["110771.02000000","0.00000000"],["110771.03000000","0.00000000"],["110771.36000000","0.00000000"],["110772.04000000","0.00000000"],["110772.05000000","0.00000000"],["110772.18000000","0.00000000"],["110772.19000000","0.00000000"],["110773.00000000","0.00000000"],["110773.17000000","0.00000000"],["110773.18000000","2.59400000"],["110773.19000000","0.00080000"],["110773.26000000","0.00010000"],["110773.38000000","0.00010000"],["110773.39000000","0.00015000"],["110773.43000000","0.00010000"],["110773.44000000","0.00015000"],["110774.01000000","0.00000000"],["110774.36000000","0.04204000"],["110774.44000000","0.00000000"],["110774.45000000","0.00005000"],["110774.46000000","0.00005000"],["110774.54000000","0.00000000"],["110774.55000000","0.00000000"],["110774.88000000","0.00010000"],["110774.89000000","0.00010000"],["110775.08000000","0.17409000"],["110775.09000000","0.48010000"],["110775.12000000","0.00000000"],["110775.19000000","0.00000000"],["110775.65000000","0.00000000"],["110775.88000000","0.00000000"],["110775.89000000","0.00000000"],["110775.90000000","0.00000000"],["110776.09000000","0.00000000"],["110776.16000000","0.00005000"],["110776.75000000","0.00000000"],["110776.84000000","0.00000000"],["110776.92000000","0.00000000"],["110776.98000000","0.00000000"],["110777.00000000","0.00000000"],["110777.12000000","0.00000000"],["110777.22000000","0.00000000"],["110777.28000000","0.00913000"],["110777.30000000","0.00000000"],["110777.34000000","0.00000000"],["110777.50000000","0.01364000"],["110777.80000000","0.00005000"],["110777.87000000","0.29756000"],["110778.03000000","0.00000000"],["110778.24000000","0.00000000"],["110778.25000000","0.00005000"],["110778.65000000","0.00005000"],["110778.66000000","0.03492000"],["110778.67000000","0.00000000"],["110778.89000000","0.00069000"],["110779.21000000","0.00000000"],["110779.22000000","0.00005000"],["110779.23000000","0.00000000"],["110779.65000000","0.00000000"],["110779.87000000","0.00000000"],["110779.88000000","0.00000000"],["110780.07000000","0.00332000"],["110780.32000000","0.00000000"],["110780.38000000","0.00000000"],["110780.54000000","0.00000000"],["110780.62000000","0.00000000"],["110780.85000000","0.00000000"],["110780.86000000","0.00000000"],["110781.29000000","0.00000000"],["110781.68000000","0.00000000"],["110781.72000000","0.00000000"],["110782.02000000","0.00000000"],["110782.11000000","0.00000000"],["110782.26000000","0.00005000"],["110782.52000000","0.00000000"],["110782.66000000","0.00010000"],["110782.87000000","0.00000000"],["110783.21000000","0.01810000"],["110783.67000000","0.00000000"],["110783.68000000","0.00000000"],["110783.88000000","0.00000000"],["110784.05000000","0.00000000"],["110784.06000000","0.00000000"],["110784.07000000","0.52422000"],["110784.08000000","0.04005000"],["110784.26000000","0.00149000"],["110784.39000000","0.00000000"],["110784.44000000","0.00000000"],["110784.61000000","0.00000000"],["110784.86000000","0.00000000"],["110785.21000000","0.04061000"],["110785.54000000","0.00305000"],["110785.96000000","0.00000000"],["110786.16000000","0.04713000"],["110786.32000000","0.03958000"],["110786.78000000","0.00000000"],["110786.86000000","0.01810000"],["110786.90000000","0.00000000"],["110786.97000000","0.00000000"],["110786.98000000","0.00305000"],["110787.18000000","0.00000000"],["110787.19000000","0.11520000"],["110787.35000000","0.00072000"],["110787.42000000","0.00000000"],["110787.46000000","0.00000000"],["110787.58000000","0.10780000"],["110787.89000000","0.32458000"],["110788.18000000","0.00000000"],["110788.20000000","0.46824000"],["110788.40000000","0.00000000"],["110788.70000000","0.00000000"],["110788.76000000","0.00000000"],["110789.18000000","0.00000000"],["110789.50000000","0.00000000"],["110789.53000000","0.01769000"],["110789.80000000","0.00150000"],["110790.06000000","0.00000000"],["110790.07000000","0.00000000"],["110790.09000000","0.00007000"],["110791.15000000","0.00000000"],["110791.60000000","0.32457000"],["110792.14000000","0.00000000"],["110792.97000000","0.00000000"],["110793.49000000","0.00450000"],["110793.74000000","0.32457000"],["110794.27000000","0.13527000"],["110796.59000000","0.08567000"],["110797.78000000","0.00000000"],["110798.67000000","0.00000000"],["110799.67000000","0.01964000"],["110800.26000000","0.00901000"],["110800.50000000","0.30431000"],["110802.61000000","0.00000000"],["110804.01000000","0.00000000"],["110806.27000000","0.08567000"],["110806.41000000","0.04509000"],["110807.60000000","0.13527000"],["110811.30000000","0.00000000"],["110811.35000000","0.00000000"],["110816.94000000","0.00000000"],["110816.97000000","0.22546000"],["110817.96000000","0.02800000"],["110818.58000000","0.00000000"],["110819.80000000","0.00000000"],["110820.52000000","0.00000000"],["110824.14000000","0.00000000"],["110825.28000000","0.00005000"],["110825.90000000","0.00000000"],["110827.51000000","0.04433000"],["110827.66000000","0.00000000"],["110829.87000000","0.00000000"],["110838.61000000","0.00617000"],["110840.98000000","1.07206000"],["110841.12000000","3.24539000"],["110841.55000000","0.00634000"],["110842.91000000","0.03150000"],["110844.95000000","0.13522000"],["110846.04000000","0.00000000"],["110846.05000000","0.00000000"],["110846.99000000","0.00000000"],["110847.00000000","0.00000000"],["110847.01000000","0.00000000"],["110847.02000000","0.00000000"],["110847.64000000","3.24539000"],["110849.01000000","0.00000000"],["110850.14000000","0.00000000"],["110850.15000000","0.00000000"],["110854.29000000","3.24539000"],["110855.76000000","0.00000000"],["110859.46000000","0.13527000"],["110864.23000000","0.00000000"],["110865.02000000","0.13527000"],["110873.98000000","0.32138000"],["110874.17000000","0.00000000"],["110875.14000000","0.00000000"],["110875.15000000","0.00000000"],["110876.45000000","0.03538000"],["110877.61000000","0.00000000"],["110880.55000000","0.00000000"],["110887.98000000","0.15449000"],["110915.86000000","0.09641000"],["110922.90000000","0.00000000"],["110927.82000000","0.00000000"],["110927.98000000","0.05510000"],["110931.80000000","0.00000000"],["110932.96000000","0.02710000"],["110936.84000000","0.99074000"],["110961.67000000","0.50486000"],["111026.87000000","0.19272000"],["111043.53000000","0.06646000"],["111060.19000000","0.06646000"],["111074.56000000","0.00010000"],["111083.20000000","0.00000000"],["111085.62000000","0.00000000"],["111246.20000000","0.45000000"],["111260.83000000","0.67153000"],["111275.39000000","0.00000000"],["128001.97000000","0.00040000"]]}
[2025-10-11T22:18:52.331Z] {"e":"depthUpdate","E":1760221132014,"s":"BTCUSDT","U":77926053314,"u":77926054137,"b":[["110773.17000000","3.92136000"],["110771.56000000","0.00000000"],["110771.55000000","0.00000000"],["110770.68000000","0.04105000"],["110770.35000000","0.31187000"],["110770.34000000","0.29763000"],["110770.18000000","0.00000000"],["110770.17000000","0.00000000"],["110770.16000000","0.00000000"],["110769.51000000","0.00005000"],["110768.91000000","0.00010000"],["110768.90000000","0.00005000"],["110768.89000000","0.00000000"],["110767.64000000","0.00000000"],["110767.63000000","0.00000000"],["110767.28000000","0.00010000"],["110767.27000000","0.48947000"],["110766.75000000","0.00000000"],["110766.32000000","0.00000000"],["110766.03000000","0.00000000"],["110766.02000000","0.00000000"],["110764.85000000","0.00010000"],["110764.84000000","0.31051000"],["110764.83000000","0.00005000"],["110764.82000000","0.18038000"],["110764.81000000","0.39307000"],["110764.50000000","0.00000000"],["110764.40000000","0.00005000"],["110764.39000000","0.29765000"],["110763.80000000","0.00000000"],["110763.70000000","0.00000000"],["110762.09000000","0.16087000"],["110760.95000000","0.00000000"],["110760.94000000","0.00542000"],["110760.52000000","0.00000000"],["110760.38000000","0.27450000"],["110760.32000000","0.00000000"],["110759.99000000","0.00000000"],["110759.41000000","0.00000000"],["110759.39000000","0.00000000"],["110759.21000000","0.00000000"],["110759.03000000","0.00000000"],["110758.57000000","0.00070000"],["110758.10000000","0.03970000"],["110758.06000000","0.08567000"],["110757.90000000","0.00000000"],["110757.83000000","0.00073000"],["110757.51000000","0.00000000"],["110757.26000000","0.00010000"],["110757.02000000","0.32467000"],["110756.99000000","0.04045000"],["110755.56000000","0.27829000"],["110754.31000000","0.20208000"],["110754.30000000","0.32468000"],["110750.01000000","0.07200000"],["110748.77000000","0.07200000"],["110745.33000000","0.00000000"],["110745.13000000","0.00000000"],["110745.07000000","0.01964000"],["110743.95000000","0.00000000"],["110743.94000000","0.00000000"],["110743.93000000","0.00000000"],["110743.56000000","0.00000000"],["110742.32000000","0.00000000"],["110740.95000000","0.00005000"],["110739.94000000","0.00000000"],["110739.47000000","0.00000000"],["110737.09000000","0.04000000"],["110734.14000000","0.22546000"],["110733.75000000","0.18031000"],["110733.09000000","0.22546000"],["110733.03000000","0.72067000"],["110731.91000000","0.00000000"],["110731.58000000","0.00009000"],["110722.12000000","0.00000000"],["110716.46000000","0.13544000"],["110704.44000000","1.28760000"],["110697.68000000","0.00000000"],["110690.40000000","0.00000000"],["110688.07000000","0.00000000"],["110687.04000000","3.24539000"],["110684.50000000","0.13527000"],["110683.01000000","0.04397000"],["110683.00000000","0.03277000"],["110676.62000000","0.02888000"],["110675.44000000","0.13527000"],["110668.29000000","0.14816000"],["110666.91000000","0.15676000"],["110661.28000000","0.00000000"],["110659.31000000","0.00000000"],["110656.59000000","0.22546000"],["110654.42000000","0.13544000"],["110628.77000000","0.04197000"],["110627.05000000","0.02527000"],["110621.55000000","0.43851000"],["110620.65000000","0.00000000"],["110551.43000000","0.00000000"],["110543.35000000","0.00588000"],["110538.26000000","0.00000000"],["110524.51000000","4.82750000"],["109913.15000000","0.00036000"],["109621.35000000","0.00214000"],["105369.11000000","0.00000000"],["101905.53000000","0.00000000"],["99695.00000000","0.00251000"],["99687.00000000","0.00000000"],["88618.54000000","0.00022000"],["39878.34000000","0.00016000"]],"a":[["110773.18000000","5.30989000"],["110773.19000000","0.00030000"],["110773.38000000","0.00000000"],["110773.39000000","0.00000000"],["110773.43000000","0.00000000"],["110773.44000000","0.00000000"],["110774.34000000","0.00010000"],["110774.35000000","0.11559000"],["110774.36000000","0.04219000"],["110774.37000000","0.00000000"],["110774.38000000","0.00000000"],["110774.39000000","0.00000000"],["110774.49000000","0.00000000"],["110774.88000000","0.00000000"],["110774.89000000","0.00000000"],["110775.04000000","0.00000000"],["110775.05000000","0.00000000"],["110775.06000000","0.00000000"],["110775.07000000","0.00000000"],["110775.08000000","0.00000000"],["110775.09000000","0.00000000"],["110775.13000000","0.00010000"],["110775.14000000","0.29767000"],["110776.16000000","0.00000000"],["110776.39000000","0.00010000"],["110776.40000000","0.03620000"],["110777.28000000","0.00918000"],["110777.41000000","0.00010000"],["110777.42000000","0.04518000"],["110777.50000000","0.01364000"],["110777.69000000","0.00000000"],["110777.84000000","0.00000000"],["110777.86000000","0.00000000"],["110777.87000000","0.00000000"],["110778.21000000","0.00000000"],["110778.22000000","0.01815000"],["110778.25000000","0.00000000"],["110778.38000000","0.00005000"],["110778.65000000","0.00000000"],["110778.66000000","0.04508000"],["110778.89000000","0.00000000"],["110779.61000000","0.13519000"],["110779.62000000","0.32461000"],["110780.07000000","0.00337000"],["110781.15000000","0.00005000"],["110782.01000000","0.00000000"],["110782.02000000","0.00000000"],["110782.26000000","0.00000000"],["110783.20000000","0.00000000"],["110783.21000000","0.01815000"],["110783.50000000","0.00400000"],["110783.57000000","0.06646000"],["110784.06000000","0.00000000"],["110784.07000000","0.73874000"],["110784.08000000","0.04010000"],["110784.19000000","0.00000000"],["110784.24000000","0.00000000"],["110784.25000000","0.00000000"],["110784.26000000","0.00154000"],["110784.74000000","0.00000000"],["110784.75000000","0.32459000"],["110785.54000000","0.00300000"],["110786.16000000","0.00010000"],["110786.42000000","0.00005000"],["110786.55000000","0.00000000"],["110786.86000000","0.01805000"],["110786.98000000","0.00000000"],["110787.02000000","0.11273000"],["110787.35000000","0.00000000"],["110787.43000000","0.05280000"],["110787.58000000","0.10780000"],["110787.89000000","0.00000000"],["110788.35000000","0.32458000"],["110790.59000000","0.00005000"],["110791.11000000","0.30433000"],["110791.60000000","0.00000000"],["110792.78000000","0.05760000"],["110798.91000000","0.00005000"],["110799.13000000","0.00000000"],["110799.80000000","0.00000000"],["110800.50000000","0.00000000"],["110806.41000000","0.00000000"],["110806.42000000","0.00300000"],["110807.95000000","0.00000000"],["110828.36000000","0.00000000"],["110844.95000000","0.00000000"],["110845.97000000","0.00331000"],["110854.28000000","1.07054000"],["110856.14000000","0.00100000"],["110856.15000000","0.00100000"],["110867.10000000","0.00005000"],["110876.45000000","0.00000000"],["110883.58000000","0.03538000"],["110892.42000000","0.00000000"],["110936.83000000","0.43828000"],["110977.82000000","0.07159000"],["110994.60000000","0.26479000"],["111017.81000000","4.79987000"],["111031.72000000","0.00000000"],["111060.19000000","0.00000000"],["111102.03000000","0.00000000"],["111119.65000000","0.04379000"],["128001.97000000","0.03006000"]]}
[2025-10-11T22:18:53.331Z] {"e":"depthUpdate","E":1760221133014,"s":"BTCUSDT","U":77926054138,"u":77926055306,"b":[["110773.17000000","0.00000000"],["110773.10000000","0.00000000"],["110770.74000000","0.00000000"],["110770.69000000","0.00000000"],["110770.68000000","0.00000000"],["110770.62000000","0.00000000"],["110770.39000000","0.00000000"],["110770.36000000","0.00000000"],["110770.35000000","0.00000000"],["110770.34000000","0.00000000"],["110769.82000000","0.00000000"],["110769.51000000","0.00000000"],["110768.91000000","0.00000000"],["110768.90000000","0.00000000"],["110767.65000000","0.00000000"],["110767.28000000","0.00000000"],["110767.27000000","0.00000000"],["110764.85000000","0.00000000"],["110764.84000000","0.00000000"],["110764.83000000","0.00000000"],["110764.82000000","0.00000000"],["110764.81000000","6.35906000"],["110764.73000000","0.00010000"],["110764.39000000","0.00000000"],["110763.89000000","0.00010000"],["110763.88000000","0.13506000"],["110763.87000000","0.29770000"],["110763.68000000","0.00000000"],["110762.09000000","0.00300000"],["110761.77000000","0.00010000"],["110761.76000000","0.04076000"],["110761.36000000","0.00010000"],["110761.35000000","0.26553000"],["110761.34000000","0.32471000"],["110760.94000000","0.00547000"],["110760.63000000","0.00005000"],["110760.39000000","0.00000000"],["110760.38000000","0.00000000"],["110760.37000000","0.00000000"],["110759.98000000","0.00000000"],["110759.97000000","0.04798000"],["110759.83000000","0.00727000"],["110759.39000000","0.00000000"],["110759.28000000","0.00000000"],["110759.27000000","0.00000000"],["110759.15000000","0.00000000"],["110759.14000000","0.32467000"],["110759.03000000","0.18026000"],["110758.78000000","0.00000000"],["110758.77000000","0.00000000"],["110758.57000000","0.00000000"],["110758.38000000","0.00000000"],["110758.26000000","0.06646000"],["110758.10000000","0.00000000"],["110758.07000000","0.00000000"],["110758.06000000","0.00000000"],["110758.00000000","0.00000000"],["110757.99000000","0.03975000"],["110757.83000000","0.00000000"],["110757.50000000","0.00000000"],["110757.48000000","0.00000000"],["110757.03000000","0.00000000"],["110757.02000000","0.00000000"],["110757.00000000","0.00000000"],["110756.99000000","0.04045000"],["110755.56000000","0.00000000"],["110755.04000000","0.18026000"],["110755.00000000","0.00400000"],["110754.32000000","0.47078000"],["110754.31000000","0.00000000"],["110752.37000000","0.00149000"],["110752.17000000","0.20209000"],["110752.12000000","0.00000000"],["110751.91000000","0.00000000"],["110751.01000000","0.11273000"],["110750.95000000","0.00000000"],["110750.41000000","0.09982000"],["110750.02000000","0.37869000"],["110749.72000000","0.00000000"],["110749.64000000","0.32469000"],["110748.16000000","0.00000000"],["110748.13000000","0.00000000"],["110746.83000000","0.00000000"],["110746.60000000","0.00325000"],["110746.00000000","0.00000000"],["110745.07000000","0.00000000"],["110743.92000000","0.00000000"],["110743.72000000","0.31190000"],["110742.58000000","0.04000000"],["110741.81000000","0.01964000"],["110739.60000000","0.00000000"],["110737.09000000","0.00000000"],["110736.56000000","0.08567000"],["110734.25000000","0.00005000"],["110734.23000000","0.08567000"],["110733.03000000","1.12614000"],["110731.79000000","0.00000000"],["110730.68000000","0.13527000"],["110728.79000000","0.00000000"],["110725.72000000","0.00000000"],["110721.88000000","0.02000000"],["110720.80000000","0.18026000"],["110716.20000000","0.00005000"],["110710.17000000","0.00000000"],["110710.14000000","0.00005000"],["110709.12000000","0.13522000"],["110687.05000000","1.04586000"],["110684.50000000","0.00000000"],["110683.00000000","0.00000000"],["110680.40000000","3.24539000"],["110676.62000000","0.00000000"],["110676.29000000","0.02888000"],["110674.82000000","0.00005000"],["110670.39000000","0.03277000"],["110668.64000000","0.13527000"],["110668.26000000","0.00005000"],["110664.36000000","0.00000000"],["110663.68000000","0.00000000"],["110663.24000000","0.00000000"],["110658.40000000","0.00000000"],["110647.08000000","0.08036000"],["110621.55000000","0.00000000"],["110621.54000000","0.00000000"],["110604.81000000","0.99419000"],["110573.67000000","0.02898000"],["110536.01000000","0.02898000"],["110496.04000000","0.02898000"],["110384.50000000","0.02910000"],["109253.01000000","0.00038000"],["99695.00000000","0.00251000"],["99688.00000000","0.01141000"],["88618.54000000","0.00000000"],["88611.85000000","0.00022000"],["42000.00000000","1.48098000"],["39878.34000000","0.00032000"]],"a":[["110764.82000000","1.01025000"],["110764.83000000","0.00080000"],["110764.90000000","0.00010000"],["110765.15000000","0.00000000"],["110765.58000000","0.00000000"],["110765.59000000","0.00000000"],["110766.84000000","0.00000000"],["110766.92000000","0.00000000"],["110766.93000000","0.00000000"],["110767.59000000","0.00078000"],["110767.64000000","0.00000000"],["110768.67000000","0.00000000"],["110769.05000000","0.00010000"],["110769.06000000","0.11571000"],["110769.07000000","0.00000000"],["110769.08000000","0.00000000"],["110769.09000000","0.00000000"],["110769.50000000","0.00005000"],["110769.55000000","0.00000000"],["110769.56000000","0.00000000"],["110769.67000000","0.04514000"],["110770.34000000","0.00000000"],["110770.35000000","0.00005000"],["110770.40000000","0.00000000"],["110770.47000000","0.01805000"],["110770.58000000","0.00010000"],["110770.59000000","0.00010000"],["110770.66000000","0.00000000"],["110770.67000000","0.00000000"],["110770.68000000","0.00005000"],["110770.69000000","0.00000000"],["110770.74000000","0.00005000"],["110770.75000000","0.00000000"],["110771.00000000","0.00000000"],["110772.23000000","0.00010000"],["110772.24000000","0.00010000"],["110773.10000000","0.45046000"],["110773.11000000","0.00010000"],["110773.12000000","0.00000000"],["110773.15000000","0.00005000"],["110773.16000000","0.87919000"],["110773.17000000","0.00000000"],["110773.18000000","0.78140000"],["110773.19000000","0.00000000"],["110773.26000000","0.00000000"],["110773.94000000","0.00005000"],["110773.95000000","0.00000000"],["110774.34000000","0.00000000"],["110774.35000000","0.00000000"],["110774.36000000","0.00000000"],["110774.94000000","0.00000000"],["110775.04000000","0.00005000"],["110775.13000000","0.00005000"],["110775.14000000","0.00000000"],["110775.54000000","0.00000000"],["110775.90000000","0.45005000"],["110776.33000000","0.00005000"],["110776.39000000","0.00000000"],["110776.40000000","0.00000000"],["110777.28000000","0.00913000"],["110777.29000000","0.00000000"],["110777.41000000","0.00000000"],["110777.42000000","0.00000000"],["110777.50000000","0.01359000"],["110778.22000000","0.00005000"],["110778.38000000","0.00000000"],["110778.45000000","0.00000000"],["110778.49000000","0.00070000"],["110778.50000000","0.00074000"],["110778.55000000","0.00005000"],["110778.58000000","0.00000000"],["110778.65000000","0.00010000"],["110778.66000000","0.04508000"],["110779.20000000","0.04930000"],["110779.22000000","0.08498000"],["110779.59000000","0.20526000"],["110779.60000000","0.00000000"],["110779.61000000","0.00000000"],["110779.62000000","0.00000000"],["110780.07000000","0.00000000"],["110781.43000000","0.11307000"],["110781.72000000","0.00007000"],["110782.36000000","0.32460000"],["110783.08000000","0.00450000"],["110783.09000000","0.00000000"],["110783.10000000","0.01805000"],["110783.21000000","0.01805000"],["110783.50000000","0.00400000"],["110783.57000000","0.00000000"],["110783.98000000","0.04000000"],["110784.06000000","0.18026000"],["110784.07000000","1.64899000"],["110784.08000000","0.00000000"],["110784.26000000","0.00000000"],["110785.90000000","0.00000000"],["110786.04000000","0.00000000"],["110786.05000000","0.00000000"],["110786.16000000","0.00000000"],["110786.56000000","0.00000000"],["110786.86000000","0.00000000"],["110787.01000000","0.00000000"],["110787.02000000","0.00000000"],["110787.58000000","0.00000000"],["110788.35000000","0.00000000"],["110789.25000000","0.13527000"],["110789.28000000","0.13522000"],["110789.39000000","0.30434000"],["110789.80000000","0.00000000"],["110790.09000000","0.00000000"],["110790.19000000","0.32458000"],["110790.92000000","0.13527000"],["110791.11000000","0.00000000"],["110792.53000000","0.08567000"],["110793.19000000","0.11815000"],["110793.49000000","0.00000000"],["110793.74000000","0.00000000"],["110794.10000000","0.32456000"],["110794.27000000","0.00000000"],["110795.00000000","0.00400000"],["110800.51000000","0.00000000"],["110804.37000000","0.22546000"],["110806.27000000","0.00000000"],["110807.60000000","0.00000000"],["110816.97000000","0.00000000"],["110817.91000000","0.00000000"],["110819.71000000","0.00000000"],["110819.78000000","0.13544000"],["110822.84000000","0.03150000"],["110825.28000000","0.00000000"],["110833.28000000","0.00000000"],["110842.91000000","0.00000000"],["110843.35000000","0.13522000"],["110846.45000000","1.25493000"],["110849.45000000","0.13527000"],["110854.28000000","0.00000000"],["110854.29000000","0.00000000"],["110855.58000000","0.13527000"],["110859.46000000","0.00000000"],["110862.22000000","0.00000000"],["110865.02000000","0.00000000"],["110867.10000000","0.00000000"],["110873.54000000","0.00000000"],["110873.78000000","0.00000000"],["110873.98000000","0.14806000"],["110875.05000000","0.00000000"],["110876.54000000","0.00000000"],["110876.90000000","0.00000000"],["110878.71000000","0.28974000"],["110878.72000000","0.22546000"],["110879.49000000","0.13544000"],["110881.78000000","0.18031000"],["110882.12000000","0.22546000"],["110883.58000000","0.00000000"],["110911.35000000","0.18169000"],["110936.83000000","0.00000000"],["110936.84000000","0.99513000"],["110946.81000000","0.12534000"],["111043.53000000","0.06646000"],["111060.19000000","0.06646000"],["111077.67000000","0.00000000"],["111246.20000000","0.45000000"],["111257.19000000","0.67153000"],["111260.83000000","0.00000000"],["128001.97000000","0.03006000"]]}
[2025-10-11T22:18:54.331Z] {"e":"depthUpdate","E":1760221134014,"s":"BTCUSDT","U":77926055307,"u":77926056598,"b":[["110773.07000000","5.98164000"],["110773.00000000","0.00010000"],["110770.86000000","0.00361000"],["110770.74000000","0.00005000"],["110770.73000000","0.00000000"],["110769.28000000","0.00000000"],["110769.20000000","0.00542000"],["110769.05000000","0.00000000"],["110769.04000000","0.00000000"],["110768.43000000","0.00010000"],["110768.42000000","0.09706000"],["110768.41000000","0.32474000"],["110767.58000000","0.00000000"],["110765.49000000","0.05037000"],["110764.90000000","0.32465000"],["110764.89000000","0.00000000"],["110764.85000000","0.00000000"],["110764.83000000","0.27372000"],["110764.82000000","0.81313000"],["110764.81000000","0.75127000"],["110764.73000000","0.00000000"],["110764.64000000","0.00000000"],["110764.63000000","0.06651000"],["110763.89000000","0.00000000"],["110763.88000000","0.00000000"],["110763.87000000","0.00000000"],["110762.09000000","0.00000000"],["110761.77000000","0.00000000"],["110761.76000000","0.00000000"],["110761.36000000","0.00000000"],["110761.35000000","0.26553000"],["110761.34000000","0.32466000"],["110760.94000000","0.00000000"],["110760.63000000","0.00000000"],["110759.97000000","0.00000000"],["110759.83000000","0.00000000"],["110758.88000000","0.00000000"],["110758.67000000","0.09931000"],["110758.27000000","0.00000000"],["110757.77000000","0.01808000"],["110755.05000000","0.20208000"],["110754.32000000","0.19843000"],["110754.30000000","0.00000000"],["110752.37000000","0.00000000"],["110752.17000000","0.00000000"],["110751.01000000","0.00000000"],["110750.41000000","0.00000000"],["110749.64000000","0.00000000"],["110746.74000000","0.13527000"],["110746.60000000","0.00000000"],["110743.72000000","1.25271000"],["110741.81000000","0.00000000"],["110739.84000000","0.04508000"],["110739.52000000","3.24539000"],["110736.60000000","0.01964000"],["110734.72000000","0.00000000"],["110734.67000000","0.24880000"],["110734.14000000","0.00000000"],["110733.75000000","0.00000000"],["110733.72000000","0.22546000"],["110733.09000000","0.00000000"],["110731.58000000","0.00309000"],["110730.68000000","0.00000000"],["110727.07000000","1.16493000"],["110723.95000000","0.13522000"],["110718.30000000","0.00157000"],["110717.81000000","0.00000000"],["110716.46000000","0.00000000"],["110716.20000000","0.00000000"],["110710.14000000","0.00000000"],["110709.12000000","0.00000000"],["110684.09000000","0.00000000"],["110683.85000000","0.13527000"],["110683.74000000","0.00000000"],["110682.01000000","0.02998000"],["110680.40000000","0.00000000"],["110677.81000000","0.61622000"],["110677.75000000","0.00000000"],["110676.29000000","0.00000000"],["110671.72000000","0.00000000"],["110668.64000000","0.00000000"],["110668.26000000","0.00000000"],["110666.91000000","0.08906000"],["110665.70000000","0.02888000"],["110662.91000000","0.22546000"],["110662.49000000","0.00000000"],["110661.91000000","0.03939000"],["110660.60000000","0.00000000"],["110660.11000000","0.00000000"],["110659.25000000","0.13544000"],["110657.97000000","0.18031000"],["110657.17000000","0.00000000"],["110656.59000000","0.00000000"],["110656.22000000","0.00000000"],["110655.77000000","0.00000000"],["110655.36000000","0.00000000"],["110654.42000000","0.00000000"],["110652.88000000","0.00000000"],["110647.08000000","0.04097000"],["110634.54000000","0.02532000"],["110631.54000000","0.02527000"],["110623.06000000","0.02527000"],["110621.61000000","0.16614000"],["110616.73000000","0.99918000"],["110604.81000000","0.00000000"],["110520.74000000","0.00000000"],["110313.66000000","0.00000000"],["109344.06000000","0.00037000"],["99695.00000000","0.00241000"],["99687.00000000","0.00010000"],["88618.46000000","0.00022000"],["88611.86000000","0.00000000"],["88611.85000000","0.00000000"],["39875.33000000","0.00096000"]],"a":[["110764.82000000","0.00000000"],["110764.83000000","0.00000000"],["110764.84000000","0.00000000"],["110764.90000000","0.00000000"],["110767.59000000","0.00000000"],["110768.67000000","0.00000000"],["110768.90000000","0.00000000"],["110769.04000000","0.00000000"],["110769.05000000","0.00000000"],["110769.06000000","0.00000000"],["110769.45000000","0.00000000"],["110769.46000000","0.00000000"],["110769.50000000","0.00000000"],["110769.66000000","0.00000000"],["110769.67000000","0.00000000"],["110770.07000000","0.00000000"],["110770.08000000","0.00000000"],["110770.35000000","0.00000000"],["110770.46000000","0.00000000"],["110770.47000000","0.00000000"],["110770.58000000","0.00000000"],["110770.59000000","0.00000000"],["110770.68000000","0.00000000"],["110770.74000000","0.00000000"],["110770.87000000","0.00000000"],["110770.88000000","0.00000000"],["110772.23000000","0.00000000"],["110772.24000000","0.00000000"],["110772.37000000","0.00000000"],["110772.38000000","0.00000000"],["110773.07000000","0.00000000"],["110773.08000000","3.71073000"],["110773.09000000","0.00100000"],["110773.10000000","0.00018000"],["110773.11000000","0.00000000"],["110773.15000000","0.00000000"],["110773.16000000","0.00010000"],["110773.17000000","0.00000000"],["110773.18000000","0.00000000"],["110773.94000000","0.00000000"],["110774.01000000","0.00000000"],["110774.38000000","0.00000000"],["110774.39000000","0.00000000"],["110774.71000000","0.00010000"],["110774.72000000","0.04744000"],["110774.79000000","0.00000000"],["110774.80000000","0.00000000"],["110774.87000000","0.45046000"],["110774.88000000","0.16549000"],["110774.89000000","0.16005000"],["110774.91000000","0.00000000"],["110775.04000000","0.00000000"],["110775.06000000","0.00000000"],["110775.07000000","0.00010000"],["110775.08000000","0.21140000"],["110775.09000000","0.32005000"],["110775.13000000","0.00000000"],["110775.40000000","0.00000000"],["110775.66000000","0.00000000"],["110775.89000000","0.00000000"],["110775.90000000","0.00000000"],["110775.91000000","0.00000000"],["110776.16000000","0.00005000"],["110776.30000000","0.00000000"],["110776.31000000","0.05038000"],["110776.33000000","0.00000000"],["110776.95000000","0.00542000"],["110777.12000000","0.00000000"],["110777.28000000","0.00913000"],["110777.50000000","0.01364000"],["110778.04000000","0.00000000"],["110778.06000000","0.00722000"],["110778.12000000","0.00000000"],["110778.22000000","0.00000000"],["110778.55000000","0.00000000"],["110778.64000000","0.00000000"],["110778.65000000","0.01128000"],["110778.66000000","0.00000000"],["110779.20000000","0.00000000"],["110779.21000000","0.00000000"],["110779.22000000","0.00000000"],["110779.47000000","0.00000000"],["110779.59000000","0.00000000"],["110780.12000000","0.00000000"],["110780.15000000","0.00000000"],["110781.43000000","0.00034000"],["110781.58000000","0.00000000"],["110781.72000000","0.00000000"],["110782.36000000","0.00000000"],["110783.08000000","0.00005000"],["110783.10000000","0.01810000"],["110783.21000000","0.01810000"],["110783.50000000","0.00000000"],["110783.98000000","0.04010000"],["110784.06000000","0.00000000"],["110784.07000000","0.57108000"],["110784.42000000","0.32459000"],["110784.50000000","0.00005000"],["110784.74000000","0.00000000"],["110784.75000000","0.00000000"],["110785.21000000","0.00000000"],["110785.33000000","0.04110000"],["110785.54000000","0.00305000"],["110786.32000000","0.03968000"],["110786.92000000","0.04503000"],["110786.97000000","0.00000000"],["110786.98000000","0.00305000"],["110787.43000000","0.05285000"],["110787.48000000","0.08981000"],["110787.53000000","0.32458000"],["110788.62000000","0.00450000"],["110788.86000000","0.00332000"],["110789.39000000","0.00000000"],["110789.53000000","0.00000000"],["110789.65000000","0.01803000"],["110789.70000000","0.00149000"],["110789.99000000","0.00007000"],["110790.19000000","0.00000000"],["110790.92000000","0.00000000"],["110791.81000000","0.32457000"],["110792.11000000","0.30433000"],["110792.51000000","0.11273000"],["110793.94000000","0.00000000"],["110794.10000000","0.00000000"],["110794.27000000","0.32456000"],["110801.24000000","0.00000000"],["110804.89000000","0.13527000"],["110805.52000000","1.21231000"],["110806.31000000","0.04509000"],["110822.84000000","0.00000000"],["110825.28000000","0.00005000"],["110834.80000000","0.03150000"],["110836.85000000","0.00225000"],["110845.97000000","0.00000000"],["110852.81000000","0.00331000"],["110854.28000000","1.11092000"],["110854.29000000","3.24539000"],["110860.91000000","0.00000000"],["110875.54000000","0.00000000"],["110883.46000000","0.03538000"],["110936.83000000","0.43911000"],["110936.84000000","0.99351000"],["110947.99000000","0.00090000"],["110967.77000000","0.06117000"],["110971.19000000","0.00000000"],["111119.65000000","0.04297000"],["111126.50000000","0.00082000"],["128001.97000000","0.00040000"]]}
[2025-10-11T22:18:55.331Z] {"e":"depthUpdate","E":1760221135014,"s":"BTCUSDT","U":77926056599,"u":77926057197,"b":[["110773.07000000","2.65758000"],["110773.06000000","0.00060000"],["110771.86000000","0.00010000"],["110771.85000000","0.04431000"],["110770.62000000","0.00005000"],["110770.51000000","0.00000000"],["110770.45000000","0.00000000"],["110770.44000000","0.00000000"],["110769.51000000","0.00000000"],["110769.20000000","0.00547000"],["110768.43000000","0.00000000"],["110768.42000000","0.00000000"],["110768.41000000","0.00000000"],["110767.25000000","0.00010000"],["110767.24000000","0.08903000"],["110767.23000000","0.29769000"],["110765.92000000","0.00000000"],["110765.91000000","0.00000000"],["110765.50000000","0.00010000"],["110765.49000000","0.05042000"],["110764.91000000","0.00000000"],["110764.90000000","0.00000000"],["110764.84000000","0.00010000"],["110764.83000000","0.22909000"],["110764.82000000","0.00599000"],["110764.81000000","0.55352000"],["110764.63000000","0.00000000"],["110763.72000000","0.00000000"],["110761.99000000","0.00300000"],["110761.37000000","0.00000000"],["110761.36000000","0.18040000"],["110761.35000000","0.55521000"],["110761.34000000","0.00000000"],["110759.22000000","0.15782000"],["110759.17000000","0.00068000"],["110759.15000000","0.00000000"],["110759.14000000","0.00000000"],["110759.03000000","0.00000000"],["110758.47000000","0.00072000"],["110757.78000000","0.08567000"],["110757.77000000","0.00000000"],["110755.92000000","0.32468000"],["110755.05000000","0.00000000"],["110755.04000000","0.00000000"],["110754.33000000","0.18026000"],["110754.32000000","0.33031000"],["110752.36000000","0.32469000"],["110752.17000000","0.20209000"],["110744.97000000","0.00000000"],["110744.91000000","0.00000000"],["110743.72000000","0.31190000"],["110742.58000000","0.00000000"],["110741.46000000","0.36069000"],["110739.84000000","0.00000000"],["110739.52000000","0.00000000"],["110737.80000000","0.04000000"],["110736.60000000","0.00000000"],["110734.12000000","0.18031000"],["110733.42000000","0.00000000"],["110732.70000000","0.22546000"],["110731.58000000","0.00009000"],["110722.48000000","1.15102000"],["110715.98000000","0.13544000"],["110687.28000000","0.00325000"],["110680.41000000","1.18787000"],["110680.40000000","3.24763000"],["110672.85000000","0.10843000"],["110672.02000000","0.00000000"],["110668.01000000","0.10193000"],["110665.70000000","0.00000000"],["110664.01000000","0.07195000"],["110662.79000000","0.02888000"],["110660.23000000","0.00000000"],["110659.25000000","0.00000000"],["110658.62000000","0.09819000"],["110656.05000000","0.00167000"],["110655.37000000","0.04197000"],["110653.94000000","0.13544000"],["110652.37000000","0.22546000"],["110649.54000000","0.04197000"],["110637.43000000","0.04197000"],["110631.05000000","0.04197000"],["110630.01000000","0.00160000"],["110627.67000000","0.04197000"],["110624.51000000","0.04197000"],["110621.64000000","0.00000000"],["110569.68000000","0.00090000"],["110552.93000000","0.00000000"],["110519.30000000","0.00064000"],["110502.46000000","0.00000000"],["110369.06000000","0.45000000"],["109435.11000000","0.00037000"],["109105.67000000","0.00000000"],["107000.00000000","46.45804000"],["99695.00000000","0.00251000"],["99687.00000000","0.00000000"],["88618.46000000","0.00022000"],["39878.31000000","0.00032000"]],"a":[["110773.08000000","7.88061000"],["110773.09000000","0.00020000"],["110773.68000000","0.00000000"],["110774.11000000","0.00010000"],["110774.12000000","0.27487000"],["110774.13000000","0.29767000"],["110774.72000000","0.04744000"],["110774.85000000","0.00000000"],["110774.86000000","0.00010000"],["110774.87000000","0.45046000"],["110774.88000000","0.00000000"],["110774.89000000","0.00000000"],["110775.07000000","0.00000000"],["110775.08000000","0.00000000"],["110775.09000000","0.00000000"],["110776.03000000","0.32467000"],["110776.16000000","0.00005000"],["110776.30000000","0.00000000"],["110776.31000000","0.05043000"],["110776.95000000","0.00547000"],["110777.50000000","0.01369000"],["110777.72000000","0.04513000"],["110778.06000000","0.00732000"],["110778.15000000","0.19690000"],["110778.16000000","0.03610000"],["110778.17000000","0.00000000"],["110778.49000000","0.00000000"],["110778.50000000","0.00000000"],["110778.52000000","0.01805000"],["110778.61000000","0.11273000"],["110778.65000000","0.00015000"],["110778.66000000","0.04513000"],["110779.90000000","0.00000000"],["110779.91000000","0.32461000"],["110782.71000000","0.00450000"],["110782.72000000","0.06652000"],["110783.09000000","0.00000000"],["110783.21000000","0.01810000"],["110783.32000000","0.00005000"],["110783.50000000","0.00400000"],["110783.98000000","0.00005000"],["110784.05000000","0.30435000"],["110784.06000000","0.18026000"],["110784.07000000","2.11469000"],["110785.54000000","0.00300000"],["110786.32000000","0.03958000"],["110786.92000000","0.00000000"],["110786.98000000","0.00300000"],["110787.42000000","3.24539000"],["110787.43000000","0.05280000"],["110788.19000000","2.48636000"],["110788.62000000","0.00000000"],["110788.86000000","0.00000000"],["110790.84000000","0.36069000"],["110791.81000000","0.00000000"],["110792.11000000","0.00000000"],["110792.51000000","0.00000000"],["110794.27000000","0.00000000"],["110806.31000000","0.00000000"],["110811.94000000","0.00225000"],["110818.99000000","0.00000000"],["110821.97000000","0.00000000"],["110833.84000000","0.00331000"],["110836.85000000","0.00000000"],["110841.21000000","0.00000000"],["110843.33000000","0.00000000"],["110843.35000000","0.00000000"],["110845.23000000","0.00225000"],["110851.25000000","0.23921000"],["110852.81000000","0.00000000"],["110853.87000000","0.00000000"],["110854.28000000","0.00000000"],["110854.29000000","0.00000000"],["110862.60000000","0.00225000"],["110865.97000000","0.00000000"],["110867.10000000","0.00005000"],["110868.58000000","0.00000000"],["110872.37000000","0.03538000"],["110872.99000000","0.00000000"],["110878.72000000","0.00000000"],["110881.94000000","0.00000000"],["110881.96000000","0.00000000"],["110883.46000000","0.00000000"],["110922.90000000","0.17240000"],["111060.19000000","0.00000000"],["111107.51000000","0.00082000"],["111126.50000000","0.00000000"],["128001.97000000","0.00040000"]]}
[2025-10-11T22:18:56.331Z] {"e":"depthUpdate","E":1760221136014,"s":"BTCUSDT","U":77926057198,"u":77926057528,"b":[["110773.07000000","1.07875000"],["110773.06000000","0.00045000"],["110772.10000000","0.00010000"],["110772.09000000","0.05012000"],["110771.86000000","0.00000000"],["110771.85000000","0.00000000"],["110769.20000000","0.00547000"],["110769.05000000","0.00010000"],["110769.04000000","0.29768000"],["110767.44000000","0.00000000"],["110767.25000000","0.00000000"],["110767.24000000","0.00000000"],["110767.23000000","0.00000000"],["110765.49000000","0.05042000"],["110764.84000000","0.00000000"],["110764.83000000","0.00010000"],["110764.82000000","0.24693000"],["110764.81000000","0.55352000"],["110764.72000000","0.00005000"],["110764.19000000","0.00000000"],["110763.67000000","0.00000000"],["110763.20000000","0.00000000"],["110763.19000000","0.32470000"],["110761.36000000","0.00000000"],["110761.35000000","0.23060000"],["110759.24000000","0.00000000"],["110759.23000000","0.18040000"],["110759.22000000","0.15782000"],["110758.68000000","0.18026000"],["110758.67000000","0.09931000"],["110758.34000000","0.00000000"],["110758.26000000","0.00000000"],["110755.00000000","0.00000000"],["110754.32000000","0.19843000"],["110752.36000000","0.00000000"],["110752.17000000","0.00000000"],["110751.06000000","0.32469000"],["110750.11000000","0.00325000"],["110750.02000000","0.53236000"],["110749.31000000","0.32470000"],["110748.47000000","0.00000000"],["110748.16000000","0.20209000"],["110737.80000000","0.00000000"],["110726.81000000","0.04000000"],["110668.01000000","0.12720000"],["110665.90000000","0.02888000"],["110662.92000000","0.01715000"],["110662.79000000","0.00000000"],["110658.63000000","0.28514000"],["110654.96000000","0.02527000"],["110641.15000000","0.02527000"],["110636.97000000","0.02527000"],["110632.72000000","0.02527000"],["110629.96000000","0.02527000"],["110621.90000000","0.02527000"],["110494.04000000","0.02898000"],["110431.64000000","0.04397000"],["110108.44000000","0.00019000"],["105000.00000000","233.39354000"],["99695.00000000","0.00251000"],["88618.46000000","0.00022000"]],"a":[["110773.08000000","7.94093000"],["110773.09000000","0.00015000"],["110773.10000000","0.00000000"],["110773.18000000","0.00044000"],["110774.71000000","0.00010000"],["110774.72000000","0.04754000"],["110774.73000000","0.01815000"],["110774.86000000","0.00010000"],["110774.87000000","0.45041000"],["110775.16000000","0.00005000"],["110775.17000000","0.06651000"],["110776.02000000","0.00005000"],["110777.28000000","0.00908000"],["110777.50000000","0.01364000"],["110778.51000000","0.00450000"],["110778.52000000","0.01815000"],["110778.65000000","0.00010000"],["110778.66000000","0.00005000"],["110779.13000000","0.03610000"],["110782.70000000","0.00000000"],["110782.71000000","0.00000000"],["110783.50000000","0.00400000"],["110783.98000000","0.00000000"],["110789.25000000","0.00000000"],["110791.75000000","0.13527000"],["110819.78000000","0.00000000"],["110822.06000000","0.13544000"],["110827.40000000","0.00331000"],["110833.84000000","0.00000000"],["110849.45000000","0.00000000"],["110850.14000000","0.13527000"],["110850.53000000","0.00000000"],["110869.84000000","0.00005000"],["110872.37000000","0.00000000"],["110873.25000000","0.03538000"],["110878.71000000","0.00000000"],["110879.49000000","0.00000000"],["110880.00000000","0.26291000"],["110882.49000000","0.22546000"],["110884.10000000","0.13544000"],["110915.26000000","0.01715000"],["110954.49000000","0.07576000"],["110972.99000000","0.00000000"],["111043.53000000","0.00000000"],["111101.07000000","0.00082000"],["111107.51000000","0.00000000"],["111231.72000000","0.00000000"],["111246.20000000","0.00000000"],["111257.19000000","0.00000000"],["111276.44000000","0.00046000"],["111304.14000000","0.00000000"],["128001.97000000","0.03006000"]]}
[2025-10-11T22:18:57.330Z] {"e":"depthUpdate","E":1760221137014,"s":"BTCUSDT","U":77926057529,"u":77926057680,"b":[["110773.07000000","1.53079000"],["110773.06000000","0.00050000"],["110769.04000000","0.29768000"],["110767.82000000","0.00005000"],["110766.98000000","0.01811000"],["110764.82000000","0.24688000"],["110764.81000000","0.55005000"],["110761.62000000","0.00005000"],["110761.36000000","0.00000000"],["110761.35000000","0.39927000"],["110759.69000000","0.18035000"],["110759.68000000","0.32467000"],["110759.23000000","0.00000000"],["110757.43000000","0.00000000"],["110756.00000000","0.00070000"],["110750.02000000","0.38693000"],["110749.31000000","0.00000000"],["110742.29000000","0.00901000"],["110687.86000000","0.00032000"],["110666.91000000","0.18206000"],["110629.48000000","0.02527000"],["110621.36000000","0.02532000"],["110612.00000000","0.69354000"],["110548.67000000","0.00587000"],["110543.35000000","0.00000000"],["110473.07000000","0.00000000"],["110108.44000000","0.00000000"],["108000.00000000","77.46935000"],["106891.29000000","0.00000000"],["106342.85000000","0.04470000"],["105414.97000000","0.00000000"],["105400.58000000","0.00058000"],["101911.23000000","0.00010000"],["99695.00000000","0.00251000"],["88618.46000000","0.00022000"],["39878.31000000","0.00048000"],["33000.00000000","3.75190000"]],"a":[["110773.08000000","7.78504000"],["110773.09000000","0.00025000"],["110773.24000000","0.00913000"],["110773.45000000","0.00010000"],["110773.46000000","0.01364000"],["110774.46000000","0.00000000"],["110774.72000000","0.04754000"],["110774.73000000","0.00000000"],["110774.75000000","0.01810000"],["110774.87000000","0.45041000"],["110775.16000000","0.00000000"],["110776.02000000","0.00000000"],["110776.31000000","0.05038000"],["110776.95000000","0.00542000"],["110777.28000000","0.00005000"],["110778.16000000","0.03610000"],["110778.51000000","0.00000000"],["110778.52000000","0.01810000"],["110779.13000000","0.03615000"],["110779.90000000","0.00450000"],["110783.10000000","0.01810000"],["110783.21000000","0.00000000"],["110784.05000000","0.00000000"],["110787.18000000","0.30434000"],["111276.44000000","0.00000000"],["111304.14000000","0.00046000"],["117527.03000000","0.04246000"],["118133.15000000","0.00000000"],["128001.97000000","0.03006000"]]}
[2025-10-11T22:18:58.331Z] {"e":"depthUpdate","E":1760221138014,"s":"BTCUSDT","U":77926057681,"u":77926058101,"b":[["110773.07000000","4.38799000"],["110773.06000000","0.00005000"],["110772.09000000","0.05012000"],["110771.47000000","0.19413000"],["110771.46000000","0.29768000"],["110770.21000000","0.32463000"],["110769.20000000","0.00547000"],["110769.06000000","0.18034000"],["110769.05000000","0.00010000"],["110769.04000000","0.00000000"],["110768.93000000","0.06646000"],["110767.50000000","0.00400000"],["110767.33000000","0.00000000"],["110767.32000000","0.32469000"],["110766.98000000","0.01811000"],["110765.50000000","0.00000000"],["110765.49000000","0.05037000"],["110765.22000000","0.00000000"],["110764.83000000","0.00000000"],["110764.82000000","0.45573000"],["110764.81000000","0.59514000"],["110763.19000000","0.32465000"],["110762.61000000","0.00000000"],["110762.09000000","0.18026000"],["110761.35000000","0.39927000"],["110760.56000000","0.06646000"],["110759.69000000","0.00000000"],["110759.22000000","0.11273000"],["110757.99000000","0.04143000"],["110757.78000000","0.00000000"],["110757.43000000","0.01822000"],["110757.41000000","0.00000000"],["110757.00000000","0.00000000"],["110756.99000000","0.00000000"],["110756.88000000","0.04143000"],["110756.00000000","0.00470000"],["110755.92000000","0.00000000"],["110752.88000000","0.08567000"],["110751.06000000","0.00000000"],["110749.90000000","0.08567000"],["110748.16000000","0.00000000"],["110747.84000000","0.00000000"],["110740.40000000","3.24539000"],["110739.81000000","0.04000000"],["110736.56000000","0.00000000"],["110734.23000000","0.00000000"],["110726.81000000","0.00000000"],["110701.25000000","0.02888000"],["110688.66000000","0.03277000"],["110687.04000000","0.00000000"],["110683.43000000","0.00000000"],["110680.40000000","0.00224000"],["110672.95000000","0.01412000"],["110670.39000000","0.00000000"],["110665.90000000","0.00000000"],["110494.04000000","0.00000000"],["110411.13000000","0.00000000"],["110200.00000000","3.25996000"],["109526.17000000","0.00042000"],["101911.23000000","0.00000000"],["99695.00000000","0.00251000"],["97336.44000000","0.00048000"],["88618.46000000","0.00022000"],["39878.31000000","0.00080000"]],"a":[["110773.08000000","3.21822000"],["110773.09000000","0.00045000"],["110773.46000000","0.01364000"],["110774.02000000","0.00000000"],["110774.03000000","0.00000000"],["110774.12000000","0.15105000"],["110774.13000000","0.00010000"],["110774.29000000","0.16000000"],["110774.72000000","0.00020000"],["110774.75000000","0.00000000"],["110774.77000000","0.00000000"],["110774.86000000","0.00000000"],["110774.87000000","0.00000000"],["110775.09000000","0.32000000"],["110775.17000000","0.00000000"],["110775.19000000","0.04000000"],["110775.32000000","0.00005000"],["110775.33000000","0.00005000"],["110776.03000000","0.00000000"],["110776.31000000","0.05043000"],["110776.95000000","0.00547000"],["110777.50000000","0.01369000"],["110777.72000000","0.00000000"],["110778.16000000","0.00000000"],["110778.52000000","0.00010000"],["110778.61000000","0.00000000"],["110778.66000000","0.00000000"],["110779.13000000","0.03620000"],["110779.26000000","0.00000000"],["110779.39000000","0.00000000"],["110779.90000000","0.00000000"],["110779.91000000","0.00000000"],["110780.77000000","0.04000000"],["110780.87000000","0.00000000"],["110781.38000000","0.00000000"],["110782.71000000","0.00000000"],["110782.72000000","0.00006000"],["110784.06000000","0.00000000"],["110784.07000000","1.24977000"],["110784.15000000","0.00000000"],["110784.42000000","0.00000000"],["110784.98000000","0.00000000"],["110785.33000000","0.00000000"],["110786.31000000","0.00000000"],["110786.32000000","0.00000000"],["110787.18000000","0.00000000"],["110787.22000000","0.03964000"],["110787.42000000","0.00000000"],["110787.53000000","0.00000000"],["110788.15000000","0.00450000"],["110788.33000000","0.04052000"],["110788.68000000","0.00000000"],["110789.27000000","0.86838000"],["110789.65000000","0.00000000"],["110790.84000000","0.00000000"],["110790.88000000","0.00000000"],["110790.89000000","0.00000000"],["110790.90000000","0.00000000"],["110792.53000000","0.00000000"],["110793.49000000","0.00000000"],["110793.50000000","0.00000000"],["110793.93000000","0.32456000"],["110794.72000000","0.00000000"],["110794.96000000","0.00000000"],["110795.52000000","0.00000000"],["110796.56000000","0.30432000"],["110800.76000000","0.36069000"],["110808.73000000","0.08567000"],["110826.52000000","0.01412000"],["110851.25000000","1.20718000"],["110851.71000000","0.13522000"],["110854.29000000","3.24539000"],["110860.94000000","3.24539000"],["110873.25000000","0.00000000"],["110883.43000000","0.03538000"],["111043.53000000","0.06646000"],["111060.19000000","0.06646000"],["111231.72000000","0.00000000"],["111235.12000000","0.45000000"],["128001.97000000","0.03006000"]]}
[2025-10-11T22:25:24.306Z] {"e":"depthUpdate","E":1760221524014,"s":"BTCUSDT","U":77926413904,"u":77926414144,"b":[["110819.99000000","10.48012000"],["110819.23000000","0.00000000"],["110819.22000000","0.54368000"],["110819.21000000","0.29755000"],["110819.20000000","0.36936000"],["110818.01000000","0.00000000"],["110807.95000000","0.00005000"],["110805.72000000","0.00088000"],["110805.63000000","0.36050000"],["110805.15000000","0.00000000"],["110804.84000000","0.00009000"],["110788.20000000","1.38890000"],["110787.83000000","0.22572000"],["110785.96000000","0.00000000"],["110784.74000000","0.00000000"],["110782.28000000","1.22489000"],["110777.80000000","0.00000000"],["110772.85000000","0.13537000"],["110756.22000000","0.00451000"],["110752.00000000","0.00120000"],["110750.00000000","0.00120000"],["110748.00000000","0.00120000"],["110747.20000000","0.25333000"],["110746.00000000","0.00120000"],["110744.00000000","0.00120000"],["110742.12000000","0.13543000"],["110742.00000000","0.00120000"],["110740.00000000","0.00120000"],["110739.95000000","0.00000000"],["110738.00000000","0.00120000"],["110737.38000000","0.13543000"],["110729.57000000","0.00000000"],["110727.28000000","0.00224000"],["110727.27000000","0.00000000"],["110721.10000000","0.00225000"],["110712.01000000","0.04002000"],["110711.85000000","0.00000000"],["110711.34000000","0.00000000"],["110711.06000000","0.00000000"],["110710.94000000","0.18057000"],["110710.79000000","0.13537000"],["110710.25000000","0.22572000"],["110705.82000000","0.00000000"],["110703.32000000","0.00167000"],["110703.31000000","0.38368000"],["110696.01000000","0.03998000"],["110692.09000000","0.56280000"],["110688.03000000","0.00000000"],["110677.01000000","0.73894000"],["110675.15000000","0.20389000"],["110670.68000000","0.35579000"],["110667.19000000","0.13496000"],["110654.34000000","0.07995000"],["110633.13000000","0.10524000"],["110616.30000000","0.00090000"],["110610.07000000","0.00090000"],["110592.21000000","0.00066000"],["110579.70000000","0.00000000"],["110577.27000000","0.00000000"],["110572.58000000","0.00000000"],["110546.96000000","0.02298000"],["110155.08000000","0.00000000"],["109539.68000000","0.90310000"],["99738.00000000","0.00010000"],["99737.00000000","0.00000000"],["88656.00000000","0.00038000"]],"a":[["110820.00000000","0.64351000"],["110820.01000000","0.00090000"],["110820.08000000","0.00010000"],["110820.55000000","0.00000000"],["110821.40000000","0.00000000"],["110821.75000000","0.00000000"],["110822.77000000","0.00005000"],["110823.08000000","0.00551000"],["110823.36000000","0.00010000"],["110823.37000000","0.01366000"],["110823.38000000","0.03167000"],["110824.19000000","0.00727000"],["110826.00000000","0.00142000"],["110826.70000000","0.00000000"],["110826.71000000","0.00000000"],["110826.72000000","0.00000000"],["110827.00000000","0.00000000"],["110827.17000000","0.00010000"],["110827.23000000","0.02005000"],["110827.43000000","0.00000000"],["110830.00000000","0.00137000"],["110830.93000000","0.00005000"],["110832.93000000","0.00000000"],["110835.02000000","0.04508000"],["110839.80000000","0.29739000"],["110840.13000000","0.00000000"],["110842.16000000","0.00000000"],["110842.41000000","0.04122000"],["110842.55000000","0.00000000"],["110842.56000000","0.00000000"],["110843.52000000","0.04067000"],["110843.99000000","0.00450000"],["110846.37000000","0.01964000"],["110847.38000000","0.32441000"],["110847.99000000","0.00000000"],["110848.85000000","0.00005000"],["110849.50000000","0.00000000"],["110850.91000000","0.00000000"],["110851.50000000","0.00005000"],["110855.80000000","0.36050000"],["110856.55000000","0.00000000"],["110860.35000000","0.32437000"],["110861.19000000","0.00000000"],["110865.86000000","0.00000000"],["110865.87000000","0.00000000"],["110866.72000000","0.13543000"],["110867.94000000","1.19886000"],["110882.13000000","0.00000000"],["110884.09000000","0.10991000"],["110891.18000000","0.00000000"],["110891.99000000","0.00225000"],["110901.98000000","0.00000000"],["110902.49000000","0.00000000"],["110902.50000000","0.00000000"],["110903.98000000","0.00224000"],["110903.99000000","0.00000000"],["110904.36000000","0.00005000"],["110904.48000000","1.38170000"],["110905.97000000","0.00000000"],["110909.94000000","0.00224000"],["110924.97000000","0.06059000"],["110982.80000000","0.13374000"],["110990.96000000","0.01020000"],["110999.98000000","0.00000000"],["111001.92000000","0.00000000"],["111003.19000000","0.00090000"],["111005.79000000","0.00000000"],["111014.35000000","0.00090000"],["111021.44000000","0.00090000"],["111054.33000000","0.08196000"],["111055.97000000","0.08196000"],["111057.66000000","0.08196000"],["111059.86000000","0.08196000"],["111061.93000000","0.08203000"],["111063.99000000","0.08196000"],["111080.96000000","0.02644000"],["111141.80000000","0.00005000"],["111168.64000000","0.04298000"],["111177.47000000","0.07396000"],["111216.86000000","0.03009000"],["128001.97000000","0.03006000"]]}
