[2025-10-27T18:48:35.152Z] {"e":"depthUpdate","E":1761590915014,"s":"BTCUSDT","U":79129618816,"u":79129619714,"b":[["115478.77000000","8.53752000"],["115478.76000000","0.00017000"],["115478.59000000","0.00010000"],["115478.58000000","0.03916000"],["115478.14000000","0.00010000"],["115478.13000000","0.30446000"],["115478.12000000","0.17314000"],["115477.32000000","0.00000000"],["115477.31000000","0.00000000"],["115477.30000000","0.00010000"],["115477.29000000","0.41586000"],["115476.97000000","0.00010000"],["115476.96000000","0.17304000"],["115476.54000000","0.00005000"],["115476.17000000","0.04404000"],["115475.63000000","0.00000000"],["115475.62000000","0.00000000"],["115475.61000000","0.00000000"],["115475.39000000","0.00005000"],["115475.05000000","0.00000000"],["115475.04000000","0.00000000"],["115474.14000000","0.10891000"],["115474.13000000","0.25648000"],["115474.09000000","0.00000000"],["115473.04000000","0.00000000"],["115472.75000000","0.00000000"],["115472.74000000","0.00005000"],["115472.73000000","0.01753000"],["115471.99000000","0.00000000"],["115471.98000000","0.08819000"],["115469.36000000","0.00000000"],["115468.30000000","0.16900000"],["115467.24000000","0.00000000"],["115467.22000000","0.06554000"],["115465.60000000","0.00330000"],["115463.18000000","0.00000000"],["115463.04000000","0.00259000"],["115462.92000000","1.04069000"],["115462.66000000","0.00009000"],["115462.45000000","0.00018000"],["115462.02000000","0.00009000"],["115461.94000000","0.00000000"],["115461.76000000","0.00009000"],["115461.63000000","0.00000000"],["115461.26000000","0.00000000"],["115461.05000000","0.00000000"],["115460.62000000","0.00000000"],["115460.54000000","0.00005000"],["115460.36000000","0.00000000"],["115460.20000000","0.00005000"],["115460.00000000","0.00005000"],["115459.39000000","0.00041000"],["115458.22000000","0.08657000"],["115458.10000000","0.03000000"],["115457.04000000","0.04000000"],["115457.02000000","0.00006000"],["115456.96000000","0.31744000"],["115456.93000000","0.03000000"],["115456.85000000","0.03000000"],["115456.01000000","0.00000000"],["115455.79000000","0.03000000"],["115455.67000000","0.00300000"],["115454.55000000","0.03000000"],["115454.37000000","0.14725000"],["115454.36000000","0.00005000"],["115453.46000000","0.03000000"],["115452.91000000","0.03000000"],["115452.79000000","0.00005000"],["115452.34000000","0.00000000"],["115452.32000000","0.00000000"],["115452.30000000","0.03000000"],["115452.25000000","0.31181000"],["115451.15000000","0.03000000"],["115451.10000000","0.03000000"],["115451.02000000","0.93958000"],["115450.34000000","0.00583000"],["115449.42000000","0.08717000"],["115447.90000000","0.27163000"],["115447.32000000","0.03681000"],["115445.44000000","0.00000000"],["115442.79000000","0.07000000"],["115437.69000000","0.43314000"],["115436.36000000","0.00693000"],["115436.01000000","0.00000000"],["115434.64000000","0.00000000"],["115432.03000000","0.00000000"],["115431.49000000","0.00000000"],["115428.46000000","0.20898000"],["115426.81000000","0.00086000"],["115426.15000000","0.00000000"],["115424.82000000","0.00000000"],["115423.20000000","0.00000000"],["115422.15000000","0.00000000"],["115419.59000000","0.04298000"],["115415.59000000","0.00000000"],["115413.27000000","0.00000000"],["115411.57000000","0.00000000"],["115410.43000000","0.31500000"],["115408.91000000","0.00000000"],["115407.95000000","0.25985000"],["115405.04000000","0.01299000"],["115404.17000000","0.00000000"],["115401.31000000","0.00000000"],["115399.02000000","0.00000000"],["115396.17000000","0.00000000"],["115393.13000000","0.00000000"],["115391.13000000","0.03025000"],["115390.90000000","0.00000000"],["115390.28000000","0.46857000"],["115380.53000000","0.00000000"],["115377.66000000","0.43314000"],["115377.11000000","0.00000000"],["115376.87000000","0.16378000"],["115376.40000000","0.00000000"],["115371.28000000","0.00000000"],["115363.70000000","0.02813000"],["115351.88000000","0.02868000"],["115351.87000000","0.00000000"],["115347.67000000","0.21373000"],["115347.37000000","0.00000000"],["115346.22000000","0.00000000"],["115346.01000000","0.04597000"],["115345.81000000","0.00000000"],["115344.01000000","0.13793000"],["115343.92000000","0.00000000"],["115343.11000000","0.04597000"],["115343.10000000","0.00000000"],["115341.85000000","0.00000000"],["115340.78000000","0.04597000"],["115340.77000000","0.00000000"],["115339.04000000","0.04597000"],["115337.90000000","0.04597000"],["115337.87000000","0.00000000"],["115336.02000000","0.15174000"],["115335.82000000","0.00000000"],["115330.01000000","0.09194000"],["115329.25000000","0.45023000"],["115328.59000000","0.04597000"],["115326.09000000","0.04597000"],["115326.07000000","0.00000000"],["115325.01000000","0.09693000"],["115323.73000000","0.09659000"],["115322.65000000","0.04597000"],["115320.57000000","0.04597000"],["115318.19000000","0.04597000"],["115316.14000000","0.04597000"],["115314.88000000","0.00000000"],["115312.97000000","0.04597000"],["115310.50000000","0.04597000"],["115309.22000000","0.04597000"],["115309.11000000","0.04597000"],["115307.59000000","0.04597000"],["115306.26000000","0.04597000"],["115305.75000000","0.04597000"],["115304.76000000","0.04597000"],["115302.72000000","0.04597000"],["115300.82000000","0.04597000"],["115262.17000000","0.00307000"],["115254.14000000","0.00000000"],["115197.37000000","0.02098000"],["115187.67000000","0.02103000"],["115180.89000000","0.02098000"],["115180.43000000","0.02498000"],["115178.77000000","0.00000000"],["115158.21000000","0.02398000"],["115154.57000000","0.02398000"],["115152.70000000","0.02398000"],["115151.43000000","0.02166000"],["115125.87000000","0.03098000"],["115124.08000000","0.03098000"],["115121.76000000","0.03098000"],["115120.95000000","0.03098000"],["115120.66000000","0.03098000"],["115120.42000000","0.03098000"],["115044.88000000","0.03298000"],["115043.52000000","0.03298000"],["115037.49000000","0.03298000"],["115036.48000000","0.03298000"],["115033.47000000","0.03298000"],["115031.84000000","0.03298000"],["115031.30000000","0.03298000"],["115030.76000000","0.03298000"],["115027.36000000","0.03298000"],["115026.82000000","0.03298000"],["115015.42000000","0.03298000"],["115014.78000000","0.03298000"],["115013.58000000","0.03298000"],["113746.58000000","0.00413000"],["106212.08000000","0.00000000"],["103930.00000000","0.00020000"],["103921.00000000","0.00000000"],["92383.02000000","0.00021000"],["92383.00000000","0.00000000"],["42000.00000000","1.36531000"]],"a":[["115478.78000000","1.37324000"],["115478.79000000","0.00045000"],["115479.01000000","0.00017000"],["115479.48000000","0.17880000"],["115480.00000000","0.01897000"],["115480.98000000","0.00000000"],["115480.99000000","0.00000000"],["115481.08000000","0.00000000"],["115481.09000000","0.00000000"],["115481.54000000","0.00010000"],["115481.55000000","0.03924000"],["115482.00000000","0.00160000"],["115482.53000000","0.00000000"],["115482.54000000","0.00005000"],["115484.00000000","0.00170000"],["115484.10000000","0.00010000"],["115484.11000000","0.28584000"],["115484.16000000","0.00005000"],["115484.55000000","0.00005000"],["115484.56000000","0.21662000"],["115484.57000000","0.00150000"],["115484.98000000","0.00000000"],["115484.99000000","0.02010000"],["115485.61000000","0.00005000"],["115485.62000000","0.01778000"],["115485.69000000","0.00000000"],["115486.14000000","0.00250000"],["115486.76000000","0.00056000"],["115486.79000000","0.00000000"],["115487.13000000","0.00000000"],["115487.33000000","0.00000000"],["115487.34000000","0.03008000"],["115488.00000000","0.00165000"],["115488.09000000","0.04005000"],["115488.81000000","1.10717000"],["115488.82000000","2.47832000"],["115488.83000000","0.00000000"],["115488.84000000","0.54080000"],["115488.85000000","0.08658000"],["115488.90000000","0.04592000"],["115489.00000000","0.00000000"],["115489.01000000","0.00000000"],["115489.05000000","0.04000000"],["115489.15000000","0.04399000"],["115489.26000000","0.00150000"],["115490.96000000","0.00000000"],["115491.33000000","0.03300000"],["115491.54000000","0.00000000"],["115492.46000000","0.03000000"],["115492.57000000","0.03900000"],["115492.80000000","0.24000000"],["115492.87000000","0.14725000"],["115493.62000000","0.04200000"],["115494.87000000","0.03900000"],["115494.95000000","0.00005000"],["115495.81000000","0.00000000"],["115495.91000000","0.03000000"],["115496.53000000","0.03600000"],["115496.60000000","0.00000000"],["115497.06000000","0.10029000"],["115497.70000000","0.00000000"],["115498.17000000","0.00995000"],["115498.20000000","0.03000000"],["115500.40000000","0.00000000"],["115501.88000000","0.00300000"],["115502.61000000","0.00000000"],["115502.70000000","0.25985000"],["115502.84000000","0.00000000"],["115503.48000000","0.00000000"],["115504.04000000","0.14719000"],["115504.80000000","0.25975000"],["115507.59000000","0.00583000"],["115507.78000000","0.14725000"],["115508.07000000","0.00000000"],["115508.14000000","0.00000000"],["115508.76000000","0.05074000"],["115508.94000000","0.00995000"],["115509.20000000","0.00000000"],["115509.30000000","0.00000000"],["115509.33000000","0.00000000"],["115510.89000000","0.00000000"],["115511.62000000","0.00000000"],["115512.65000000","0.00000000"],["115513.26000000","0.00000000"],["115513.43000000","0.00300000"],["115513.81000000","0.00000000"],["115514.54000000","0.00000000"],["115514.95000000","0.00000000"],["115514.96000000","0.00000000"],["115515.74000000","0.00000000"],["115515.85000000","0.31163000"],["115516.16000000","0.00000000"],["115517.23000000","0.00000000"],["115517.99000000","0.04496000"],["115518.33000000","0.03298000"],["115518.34000000","0.57178000"],["115518.66000000","0.43314000"],["115519.19000000","0.00086000"],["115519.55000000","0.00000000"],["115519.63000000","0.06535000"],["115528.08000000","0.00000000"],["115528.09000000","0.00000000"],["115529.64000000","0.03234000"],["115530.29000000","0.31160000"],["115530.74000000","0.00086000"],["115535.16000000","0.00000000"],["115535.19000000","0.03446000"],["115536.81000000","0.00000000"],["115543.57000000","0.02259000"],["115544.42000000","0.42172000"],["115548.64000000","0.25985000"],["115549.91000000","0.46792000"],["115552.36000000","0.00000000"],["115553.64000000","0.01960000"],["115555.43000000","0.00000000"],["115558.68000000","0.00000000"],["115561.08000000","0.03000000"],["115561.26000000","0.04200000"],["115565.24000000","0.02338000"],["115565.85000000","0.03300000"],["115566.98000000","0.03000000"],["115567.07000000","0.04500000"],["115567.11000000","0.03900000"],["115569.40000000","0.03900000"],["115570.42000000","0.00000000"],["115571.03000000","0.03600000"],["115571.14000000","0.00000000"],["115571.58000000","0.03000000"],["115572.73000000","0.03000000"],["115572.74000000","0.03000000"],["115576.30000000","0.43314000"],["115577.84000000","0.00005000"],["115584.51000000","0.00005000"],["115586.04000000","0.00000000"],["115589.81000000","0.00000000"],["115596.65000000","0.00005000"],["115610.00000000","0.00086000"],["115613.07000000","0.00345000"],["115643.90000000","0.04597000"],["115646.00000000","0.04597000"],["115646.87000000","0.04597000"],["115648.25000000","0.04597000"],["115649.02000000","0.10638000"],["115649.09000000","0.04597000"],["115650.79000000","0.04597000"],["115650.92000000","0.04597000"],["115652.03000000","0.04597000"],["115676.04000000","0.00000000"],["115696.74000000","0.00000000"],["115754.66000000","0.00000000"],["115762.73000000","0.00311000"],["115785.84000000","0.02498000"],["115786.32000000","0.02498000"],["115786.94000000","0.02498000"],["115796.80000000","0.02098000"],["115835.12000000","0.02398000"],["115835.52000000","0.02398000"],["115836.23000000","0.02398000"],["115837.91000000","0.02398000"],["115839.17000000","0.02398000"],["115840.68000000","0.02398000"],["115842.14000000","0.02398000"],["115843.15000000","0.02398000"],["115857.55000000","0.00000000"],["115883.32000000","0.03098000"],["115883.87000000","0.03098000"],["115884.78000000","0.03098000"],["115886.00000000","0.03150000"],["115888.21000000","0.03098000"],["115889.06000000","0.03098000"],["115889.89000000","0.03098000"],["115890.19000000","0.03098000"],["115890.83000000","0.03098000"],["115891.82000000","0.03098000"],["115892.99000000","0.03098000"],["115914.58000000","0.03298000"],["115915.70000000","0.03298000"],["115916.37000000","0.03298000"],["115916.63000000","0.03298000"],["115917.29000000","0.03298000"],["115918.00000000","0.03298000"],["115918.74000000","0.03298000"],["115919.18000000","0.03298000"],["115919.86000000","0.03298000"],["115920.12000000","0.03316000"],["115920.72000000","0.03298000"],["115921.26000000","0.03298000"],["115943.29000000","0.02498000"],["115944.94000000","0.02534000"],["115946.03000000","0.02498000"],["115946.96000000","0.02498000"],["115947.80000000","0.02498000"],["115948.50000000","0.02498000"],["115949.92000000","0.02498000"],["116022.03000000","0.00000000"],["116030.10000000","0.00088000"],["116239.20000000","0.00000000"],["116640.00000000","0.00282000"],["117210.97000000","0.00100000"]]}
[2025-10-27T18:48:36.189Z] {"e":"depthUpdate","E":1761590916014,"s":"BTCUSDT","U":79129619715,"u":79129620172,"b":[["115478.77000000","8.23971000"],["115478.70000000","0.00009000"],["115478.12000000","0.17314000"],["115477.62000000","0.00100000"],["115477.29000000","0.41581000"],["115476.17000000","0.04404000"],["115475.89000000","0.00191000"],["115474.16000000","0.00346000"],["115474.14000000","0.10896000"],["115474.13000000","0.24954000"],["115472.74000000","0.00000000"],["115472.73000000","0.01753000"],["115472.16000000","0.00694000"],["115471.85000000","0.00520000"],["115468.30000000","0.29359000"],["115467.39000000","0.00100000"],["115467.22000000","0.38054000"],["115465.65000000","0.00000000"],["115463.50000000","0.27707000"],["115460.10000000","0.00005000"],["115458.22000000","0.00000000"],["115456.96000000","0.00000000"],["115451.52000000","0.00000000"],["115450.93000000","0.00000000"],["115450.34000000","0.00000000"],["115450.25000000","0.00583000"],["115450.00000000","0.00120000"],["115448.00000000","2.47952000"],["115446.27000000","0.05723000"],["115446.00000000","0.00120000"],["115445.02000000","0.00000000"],["115444.13000000","0.00008000"],["115444.00000000","0.00120000"],["115442.00000000","0.00120000"],["115440.98000000","0.00000000"],["115440.00000000","0.00125000"],["115439.68000000","0.00173000"],["115438.09000000","0.00000000"],["115438.00000000","0.00120000"],["115436.36000000","0.00000000"],["115436.00000000","0.00120000"],["115434.00000000","0.00120000"],["115432.82000000","0.00000000"],["115432.00000000","0.00120000"],["115430.58000000","0.00000000"],["115430.00000000","0.00120000"],["115428.00000000","0.00120000"],["115426.00000000","0.00120000"],["115424.00000000","0.00120000"],["115422.00000000","0.00120000"],["115420.00000000","0.00120000"],["115411.21000000","0.00000000"],["115409.48000000","0.00008000"],["115405.05000000","0.00008000"],["115399.27000000","0.01299000"],["115397.67000000","0.03025000"],["115395.94000000","0.00000000"],["115393.39000000","0.00008000"],["115393.35000000","0.03000000"],["115391.13000000","0.00000000"],["115380.01000000","0.00000000"],["115374.84000000","0.00008000"],["115368.01000000","0.00000000"],["115361.30000000","0.00000000"],["115356.02000000","0.00214000"],["115354.96000000","0.00000000"],["115346.02000000","0.00182000"],["115340.20000000","0.00008000"],["115332.27000000","0.00000000"],["115326.66000000","0.00000000"],["115321.47000000","0.00000000"],["115319.04000000","0.06000000"],["115305.55000000","0.00008000"],["115294.94000000","0.00193000"],["115292.02000000","0.00000000"],["115284.09000000","0.00000000"],["115279.20000000","0.00000000"],["115252.84000000","0.01356000"],["115250.00000000","0.16810000"],["115242.02000000","0.00086000"],["115236.37000000","0.00000000"],["115217.24000000","0.00005000"],["115211.42000000","0.00000000"],["115179.93000000","0.02498000"],["115179.59000000","0.02498000"],["115179.52000000","0.00077000"],["115178.79000000","0.02498000"],["115178.29000000","0.02498000"],["115177.90000000","0.02498000"],["115176.83000000","0.02498000"],["115176.66000000","0.02498000"],["115176.16000000","0.02503000"],["115160.88000000","0.00000000"],["115000.00000000","5.20455000"],["114750.00000000","0.47905000"],["114500.00000000","7.44772000"],["114250.00000000","0.29261000"],["114000.00000000","23.21293000"],["113750.00000000","0.44261000"],["113746.58000000","0.00413000"],["113500.00000000","5.97098000"],["113250.00000000","0.37916000"],["113000.00000000","33.87302000"],["112750.00000000","0.32973000"],["112500.00000000","13.22916000"],["112250.00000000","0.43889000"],["112000.00000000","17.07433000"],["111750.00000000","0.27240000"],["111500.00000000","7.82216000"],["111250.00000000","0.46311000"],["111000.00000000","10.82378000"],["110750.00000000","0.27344000"],["110500.00000000","7.30251000"],["110250.00000000","1.73517000"],["110000.00000000","54.94270000"],["109750.00000000","0.43394000"],["109500.00000000","6.81979000"],["109250.00000000","0.26592000"],["109000.00000000","14.89849000"],["108750.00000000","0.83127000"],["108500.00000000","8.87996000"],["108250.00000000","0.82798000"],["108000.00000000","42.94297000"],["107750.00000000","0.31118000"],["107500.00000000","8.86733000"],["107250.00000000","0.29722000"],["107000.00000000","22.59597000"],["106750.00000000","0.54117000"],["106500.00000000","17.95929000"],["106250.00000000","1.40182000"],["106000.00000000","39.49176000"],["105750.00000000","0.92082000"],["105500.00000000","5.35964000"],["105250.00000000","0.77555000"],["105000.00000000","130.01163000"],["103930.00000000","0.00010000"],["92383.02000000","0.00021000"],["41572.36000000","0.00015000"]],"a":[["115478.78000000","0.95474000"],["115478.79000000","0.00060000"],["115478.86000000","0.00009000"],["115479.48000000","0.03313000"],["115479.93000000","0.00010000"],["115479.94000000","0.03952000"],["115480.00000000","0.01897000"],["115480.98000000","0.00010000"],["115480.99000000","0.02010000"],["115481.55000000","0.03924000"],["115481.66000000","0.00191000"],["115484.00000000","0.00165000"],["115484.10000000","0.00000000"],["115484.11000000","0.00000000"],["115484.55000000","0.00000000"],["115484.56000000","0.00000000"],["115484.98000000","0.00000000"],["115484.99000000","0.00005000"],["115485.61000000","0.00005000"],["115485.62000000","0.01783000"],["115485.70000000","0.00524000"],["115486.14000000","0.00255000"],["115486.76000000","0.00072000"],["115486.77000000","0.00000000"],["115486.78000000","0.28579000"],["115486.79000000","0.04005000"],["115486.99000000","0.00000000"],["115487.33000000","0.00000000"],["115487.34000000","0.03003000"],["115487.45000000","0.21657000"],["115488.00000000","0.00160000"],["115488.09000000","0.00000000"],["115488.50000000","0.00000000"],["115488.59000000","0.00381000"],["115488.90000000","0.00000000"],["115490.29000000","0.04592000"],["115490.32000000","0.00693000"],["115492.80000000","0.00000000"],["115494.50000000","0.24000000"],["115500.48000000","0.00000000"],["115500.50000000","0.06100000"],["115503.55000000","0.00005000"],["115507.59000000","0.00000000"],["115508.21000000","0.00583000"],["115509.61000000","0.03683000"],["115513.42000000","0.00008000"],["115514.78000000","0.05224000"],["115515.85000000","0.00000000"],["115519.62000000","0.02498000"],["115535.12000000","0.00000000"],["115535.54000000","0.31158000"],["115542.83000000","0.00000000"],["115543.50000000","0.26118000"],["115548.07000000","0.00008000"],["115569.76000000","0.00000000"],["115570.32000000","0.03400000"],["115570.42000000","0.03000000"],["115577.83000000","0.02500000"],["115580.46000000","0.00005000"],["115582.71000000","0.00008000"],["115600.69000000","0.00005000"],["115604.40000000","0.00000000"],["115617.35000000","0.00008000"],["115620.92000000","0.06000000"],["115639.04000000","0.00000000"],["115652.00000000","0.00008000"],["115750.00000000","0.17929000"],["115782.54000000","0.02498000"],["115783.18000000","0.02498000"],["115783.46000000","0.02498000"],["115783.85000000","0.02498000"],["115783.99000000","0.02498000"],["115784.01000000","0.02498000"],["115784.13000000","0.02498000"],["115784.24000000","0.02498000"],["115784.50000000","0.02498000"],["115784.62000000","0.02498000"],["115784.80000000","0.02498000"],["115822.84000000","0.01731000"],["115878.02000000","0.37961000"],["115947.85000000","0.02498000"],["116000.00000000","19.40324000"],["116243.87000000","0.00034000"],["116250.00000000","0.33821000"],["116500.00000000","37.01297000"],["116750.00000000","0.52466000"],["116869.75000000","0.00173000"],["117000.00000000","54.89966000"],["117210.97000000","0.00100000"],["117250.00000000","0.63916000"],["117500.00000000","32.69844000"],["117750.00000000","0.25702000"],["118000.00000000","78.05997000"],["118250.00000000","0.24685000"],["118500.00000000","18.69788000"],["118750.00000000","0.62762000"],["119000.00000000","26.90858000"],["119250.00000000","0.23270000"],["119500.00000000","7.54740000"],["119750.00000000","0.20076000"],["120000.00000000","179.69518000"],["120250.00000000","0.22604000"],["120500.00000000","5.55199000"],["120750.00000000","0.75564000"],["121000.00000000","45.65140000"],["121250.00000000","0.74479000"],["121500.00000000","5.25152000"],["121750.00000000","0.76255000"],["122000.00000000","65.95049000"],["122250.00000000","1.21674000"],["122500.00000000","6.72065000"],["122750.00000000","0.18710000"],["123000.00000000","38.00030000"],["123250.00000000","0.33050000"],["123500.00000000","10.82633000"],["123750.00000000","0.35414000"],["124000.00000000","59.32742000"],["124250.00000000","0.35140000"],["124500.00000000","19.31440000"],["124750.00000000","0.43446000"],["125000.00000000","214.37877000"]]}
[2025-10-27T18:48:37.147Z] {"e":"depthUpdate","E":1761590917014,"s":"BTCUSDT","U":79129620173,"u":79129620440,"b":[["115478.77000000","8.23701000"],["115478.76000000","0.00062000"],["115478.13000000","0.30431000"],["115477.62000000","0.00095000"],["115459.18000000","0.00005000"],["115459.00000000","0.97854000"],["115457.09000000","0.07000000"],["115453.28000000","0.00005000"],["115452.07000000","0.00865000"],["115451.02000000","0.00000000"],["115450.25000000","0.00000000"],["115449.41000000","0.00583000"],["115442.79000000","0.00000000"],["115410.00000000","0.00140000"],["115408.00000000","0.00140000"],["115406.00000000","0.00140000"],["115404.00000000","0.00140000"],["115402.00000000","0.02478000"],["115400.00000000","0.00145000"],["115398.00000000","0.00140000"],["115396.00000000","0.00140000"],["115394.00000000","0.00140000"],["115321.80000000","0.00007000"],["115277.23000000","0.00307000"],["115262.17000000","0.00000000"],["115238.99000000","4.62738000"],["115092.59000000","0.04144000"],["115088.39000000","0.00000000"],["113926.70000000","0.00008000"],["113870.99000000","0.00000000"],["113746.58000000","0.00413000"],["113641.40000000","0.00087000"],["103930.00000000","0.00010000"],["92383.02000000","0.00021000"],["42000.00000000","1.36431000"],["41607.79000000","0.00030000"],["41585.55000000","0.00000000"],["41584.70000000","0.00015000"],["41583.41000000","0.00000000"],["41578.58000000","0.00120000"],["41574.56000000","0.00015000"],["41573.06000000","0.00000000"],["41569.19000000","0.00015000"],["41561.02000000","0.00015000"],["41530.78000000","0.00030000"],["41522.33000000","0.00000000"],["41519.18000000","0.00015000"],["41517.87000000","0.00000000"],["41515.92000000","0.00015000"],["41515.50000000","0.00000000"],["41514.84000000","0.00030000"],["41513.86000000","0.00000000"],["41509.16000000","0.00000000"],["41495.12000000","0.00060000"],["41490.55000000","0.00030000"],["33000.00000000","3.79030000"]],"a":[["115478.78000000","0.80876000"],["115478.79000000","0.00055000"],["115479.42000000","0.00058000"],["115479.47000000","0.00000000"],["115479.48000000","0.00000000"],["115479.93000000","0.00000000"],["115479.94000000","0.00000000"],["115480.00000000","0.01907000"],["115480.58000000","0.00010000"],["115480.59000000","0.04151000"],["115480.60000000","0.03992000"],["115480.98000000","0.00000000"],["115480.99000000","0.00000000"],["115481.55000000","0.03929000"],["115482.55000000","0.00305000"],["115483.78000000","0.00000000"],["115483.79000000","0.00000000"],["115485.61000000","0.00010000"],["115485.70000000","0.00524000"],["115486.14000000","0.00255000"],["115486.76000000","0.00616000"],["115486.78000000","0.28579000"],["115486.79000000","0.00000000"],["115487.34000000","0.03008000"],["115488.00000000","0.00165000"],["115488.81000000","0.36944000"],["115488.82000000","0.00000000"],["115492.40000000","0.06000000"],["115558.75000000","0.13137000"],["115584.76000000","0.00005000"],["115602.46000000","0.00005000"],["115762.73000000","0.00000000"],["115777.85000000","0.00311000"],["115858.22000000","0.02498000"],["115859.36000000","0.02498000"],["115860.62000000","0.02498000"],["115861.69000000","0.02498000"],["115878.02000000","0.37961000"],["116030.10000000","0.00006000"],["116045.24000000","0.00082000"],["117210.97000000","0.00100000"]]}
[2025-10-27T18:48:38.151Z] {"e":"depthUpdate","E":1761590918014,"s":"BTCUSDT","U":79129620441,"u":79129620860,"b":[["115478.77000000","8.21471000"],["115478.76000000","0.00057000"],["115478.59000000","0.00000000"],["115478.58000000","0.03826000"],["115478.13000000","0.30431000"],["115477.62000000","0.00095000"],["115476.96000000","0.17304000"],["115476.18000000","0.00000000"],["115474.14000000","0.10409000"],["115474.13000000","0.00000000"],["115473.83000000","0.24954000"],["115473.77000000","0.00699000"],["115472.73000000","0.01748000"],["115472.16000000","0.00000000"],["115471.98000000","0.08819000"],["115467.26000000","0.00005000"],["115463.22000000","0.00005000"],["115457.04000000","0.00000000"],["115454.07000000","0.04000000"],["115452.25000000","0.00000000"],["115449.42000000","0.09300000"],["115449.41000000","0.00000000"],["115432.67000000","0.31186000"],["115416.94000000","0.03025000"],["115397.67000000","0.00000000"],["115337.00000000","0.00243000"],["115321.80000000","0.00012000"],["115311.68000000","0.00000000"],["115285.95000000","0.00307000"],["115277.23000000","0.00000000"],["115151.29000000","0.00025000"],["115077.38000000","0.00000000"],["114503.68000000","0.01620000"],["113746.58000000","0.00413000"],["103930.00000000","0.00010000"],["92383.02000000","0.00021000"],["92383.00000000","0.00000000"],["60000.00000000","57.97732000"],["41572.36000000","0.00030000"]],"a":[["115478.78000000","0.87503000"],["115478.79000000","0.00065000"],["115478.94000000","0.00000000"],["115478.95000000","0.00020000"],["115479.42000000","0.00043000"],["115480.00000000","0.01897000"],["115480.59000000","0.10596000"],["115480.60000000","0.00000000"],["115480.93000000","0.00010000"],["115480.94000000","0.03900000"],["115480.99000000","0.00000000"],["115481.54000000","0.00000000"],["115481.55000000","0.00005000"],["115483.68000000","0.00000000"],["115483.69000000","0.00000000"],["115484.57000000","0.00155000"],["115485.48000000","0.00010000"],["115485.49000000","0.02010000"],["115485.61000000","0.00010000"],["115485.62000000","0.01783000"],["115485.70000000","0.00524000"],["115486.14000000","0.00005000"],["115486.50000000","0.28617000"],["115486.76000000","0.00601000"],["115486.77000000","0.00000000"],["115486.78000000","0.00000000"],["115487.45000000","0.21657000"],["115488.00000000","0.00165000"],["115488.01000000","0.00000000"],["115488.79000000","1.10924000"],["115488.80000000","2.47837000"],["115488.81000000","0.00000000"],["115490.29000000","0.00000000"],["115490.72000000","0.04592000"],["115492.33000000","0.25975000"],["115492.40000000","0.00000000"],["115492.50000000","0.04000000"],["115493.22000000","0.00000000"],["115494.80000000","0.00005000"],["115497.06000000","0.03000000"],["115499.02000000","0.00865000"],["115504.80000000","0.00000000"],["115509.24000000","0.00250000"],["115512.95000000","0.00000000"],["115515.61000000","0.00000000"],["115519.63000000","0.00000000"],["115520.37000000","0.06402000"],["115528.85000000","0.54080000"],["115535.54000000","0.00000000"],["115535.82000000","0.31158000"],["115540.20000000","0.25975000"],["115548.43000000","0.00000000"],["115555.81000000","0.14358000"],["115558.75000000","0.00000000"],["115562.86000000","0.00000000"],["115575.82000000","0.00243000"],["115591.68000000","0.00005000"],["115693.51000000","0.01645000"],["115696.74000000","0.01356000"],["115699.17000000","0.01645000"],["115702.33000000","0.00000000"],["115762.00000000","0.00000000"],["115777.85000000","0.00000000"],["115784.75000000","0.02498000"],["115786.61000000","0.00311000"],["115796.80000000","0.00000000"],["115797.38000000","0.02298000"],["115853.27000000","0.02498000"],["115854.04000000","0.02498000"],["115854.95000000","0.02498000"],["115855.30000000","0.02498000"],["115855.67000000","0.02498000"],["115856.74000000","0.02498000"],["115857.45000000","0.00000000"],["115857.60000000","0.02498000"],["115890.74000000","0.03098000"],["116045.24000000","0.00000000"],["116054.01000000","0.00082000"],["116629.79000000","0.00246000"],["117210.97000000","0.00100000"]]}
[2025-10-27T18:48:39.151Z] {"e":"depthUpdate","E":1761590919014,"s":"BTCUSDT","U":79129620861,"u":79129621002,"b":[["115478.77000000","8.23176000"],["115478.58000000","0.03831000"],["115476.90000000","0.00250000"],["115476.17000000","0.04404000"],["115475.28000000","0.00699000"],["115473.83000000","0.24954000"],["115473.77000000","0.00000000"],["115471.30000000","0.00005000"],["115465.84000000","0.00005000"],["115455.14000000","0.00005000"],["115453.80000000","0.00000000"],["115452.55000000","0.31181000"],["115434.92000000","0.33256000"],["115432.67000000","0.00000000"],["115406.07000000","0.00000000"],["115383.40000000","0.02930000"],["115383.33000000","0.02813000"],["115377.16000000","0.00005000"],["115363.70000000","0.00000000"],["113746.58000000","0.00413000"],["103930.00000000","0.00010000"],["92383.02000000","0.00021000"]],"a":[["115478.78000000","0.54354000"],["115478.79000000","0.00065000"],["115478.95000000","0.00000000"],["115479.42000000","0.00058000"],["115480.59000000","0.00015000"],["115480.93000000","0.00000000"],["115480.94000000","0.00000000"],["115481.40000000","0.00000000"],["115481.43000000","0.03839000"],["115485.61000000","0.00015000"],["115485.62000000","0.01788000"],["115486.00000000","0.00160000"],["115486.49000000","0.00005000"],["115486.50000000","0.28617000"],["115486.76000000","0.00000000"],["115487.45000000","0.21662000"],["115488.00000000","0.00165000"],["115488.79000000","0.19432000"],["115488.80000000","0.00005000"],["115488.84000000","0.00000000"],["115488.85000000","0.00000000"],["115490.72000000","0.00000000"],["115493.23000000","0.02599000"],["115493.45000000","0.00000000"],["115496.11000000","0.13250000"],["115497.93000000","0.00000000"],["115499.02000000","0.00000000"],["115512.10000000","0.00005000"],["115533.99000000","0.00000000"],["115565.29000000","0.00000000"],["115565.30000000","0.00000000"],["115668.73000000","0.00000000"],["115673.34000000","0.00000000"],["115685.40000000","0.01645000"],["115688.96000000","0.01645000"],["115693.08000000","0.01645000"],["115696.98000000","0.00000000"],["115697.38000000","0.00000000"],["115698.07000000","0.01645000"],["115700.46000000","0.00000000"],["115700.47000000","0.00000000"],["115700.48000000","0.00000000"],["115857.31000000","0.00000000"],["115878.02000000","0.00000000"],["115885.63000000","0.37961000"],["115891.57000000","0.03098000"],["117210.97000000","0.00100000"]]}
[2025-10-27T18:48:40.151Z] {"e":"depthUpdate","E":1761590920014,"s":"BTCUSDT","U":79129621003,"u":79129621335,"b":[["115478.77000000","8.22388000"],["115478.76000000","0.00057000"],["115478.59000000","0.00010000"],["115469.74000000","0.00100000"],["115467.39000000","0.00000000"],["115465.60000000","0.00000000"],["115465.23000000","0.00330000"],["115465.04000000","0.00009000"],["115464.67000000","0.00009000"],["115464.45000000","0.00018000"],["115464.38000000","0.01325000"],["115464.03000000","0.00009000"],["115463.76000000","0.00009000"],["115463.04000000","0.00250000"],["115462.66000000","0.00000000"],["115462.45000000","0.00000000"],["115462.02000000","0.00000000"],["115461.76000000","0.00000000"],["115451.10000000","0.03005000"],["115449.42000000","0.08717000"],["115449.37000000","0.00583000"],["115416.94000000","0.00000000"],["115394.08000000","0.03025000"],["115383.33000000","0.00000000"],["115368.22000000","0.02813000"],["114503.68000000","0.01369000"],["113746.58000000","0.00413000"],["103930.00000000","0.00010000"],["92383.02000000","0.00021000"]],"a":[["115478.78000000","1.15847000"],["115478.79000000","0.00055000"],["115479.42000000","0.00058000"],["115479.43000000","0.00010000"],["115479.44000000","0.03904000"],["115480.00000000","0.01892000"],["115480.58000000","0.00000000"],["115480.59000000","0.00000000"],["115481.15000000","0.00036000"],["115481.42000000","0.00000000"],["115481.43000000","0.00000000"],["115481.50000000","0.00000000"],["115481.51000000","0.00000000"],["115482.00000000","0.00160000"],["115482.15000000","0.00000000"],["115482.16000000","0.00000000"],["115484.57000000","0.00155000"],["115484.99000000","0.00000000"],["115485.47000000","0.00010000"],["115485.48000000","0.09911000"],["115485.49000000","0.00000000"],["115485.61000000","0.00005000"],["115485.62000000","0.00005000"],["115485.70000000","0.00524000"],["115486.00000000","0.00165000"],["115486.14000000","0.00000000"],["115486.21000000","0.00010000"],["115486.22000000","0.01718000"],["115486.49000000","0.00010000"],["115486.50000000","0.28617000"],["115487.33000000","0.00000000"],["115488.59000000","0.00386000"],["115488.79000000","0.19432000"],["115488.85000000","0.08658000"],["115489.05000000","0.04000000"],["115489.15000000","0.04399000"],["115489.19000000","0.02000000"],["115489.69000000","0.04592000"],["115490.23000000","0.00597000"],["115490.43000000","0.00000000"],["115491.72000000","0.00000000"],["115493.23000000","0.00000000"],["115493.27000000","0.00000000"],["115493.55000000","0.00000000"],["115494.38000000","0.02599000"],["115496.11000000","0.00000000"],["115499.30000000","0.00000000"],["115500.29000000","0.00000000"],["115504.38000000","0.00100000"],["115520.37000000","0.00000000"],["115531.26000000","0.01645000"],["115559.01000000","0.00000000"],["115565.65000000","0.00000000"],["115565.66000000","0.00000000"],["115570.32000000","0.00000000"],["115577.83000000","0.00000000"],["115697.85000000","0.01645000"],["115855.91000000","0.00000000"],["115856.61000000","0.00000000"],["115857.22000000","0.00000000"],["115882.91000000","0.00000000"],["115883.66000000","0.00000000"],["115884.59000000","0.00000000"],["115888.27000000","0.03098000"],["115889.34000000","0.03098000"],["115890.23000000","0.03098000"],["115916.17000000","0.03298000"],["115917.44000000","0.03298000"],["115918.77000000","0.03298000"],["116629.79000000","0.00000000"],["117210.97000000","0.00100000"]]}
[2025-10-27T18:48:41.159Z] {"e":"depthUpdate","E":1761590921014,"s":"BTCUSDT","U":79129621336,"u":79129621552,"b":[["115478.77000000","8.22116000"],["115478.76000000","0.00052000"],["115476.90000000","0.00000000"],["115476.17000000","0.04404000"],["115475.28000000","0.00000000"],["115474.14000000","0.10649000"],["115473.83000000","0.00000000"],["115472.73000000","0.01753000"],["115471.98000000","0.08824000"],["115471.59000000","0.00000000"],["115471.57000000","0.25643000"],["115470.58000000","0.00005000"],["115461.88000000","0.97704000"],["115459.00000000","0.00000000"],["115453.80000000","0.00250000"],["115450.56000000","0.00583000"],["115449.41000000","0.00000000"],["115449.37000000","0.00000000"],["115424.82000000","0.08662000"],["115380.62000000","0.00000000"],["113746.58000000","0.00413000"],["111984.74000000","0.02167000"],["111981.06000000","0.00000000"],["103930.00000000","0.00010000"],["92383.02000000","0.00021000"],["92383.00000000","0.00000000"],["41572.36000000","0.00045000"],["33000.00000000","3.79030000"]],"a":[["115478.78000000","0.92176000"],["115478.79000000","0.00055000"],["115479.42000000","0.00058000"],["115479.43000000","0.00000000"],["115479.44000000","0.00000000"],["115480.00000000","0.01897000"],["115481.15000000","0.00041000"],["115481.43000000","0.00010000"],["115481.44000000","0.03896000"],["115486.50000000","0.28617000"],["115487.33000000","0.00000000"],["115487.34000000","0.03013000"],["115487.45000000","0.00000000"],["115487.76000000","0.00000000"],["115487.78000000","0.04597000"],["115488.59000000","0.00381000"],["115488.76000000","1.21452000"],["115488.77000000","2.47840000"],["115488.78000000","0.54080000"],["115488.79000000","0.00000000"],["115488.85000000","0.08658000"],["115489.69000000","0.00000000"],["115489.74000000","0.00000000"],["115490.23000000","0.00101000"],["115493.22000000","0.21657000"],["115494.38000000","0.00000000"],["115494.39000000","0.02599000"],["115500.68000000","0.00865000"],["115515.77000000","0.31163000"],["115519.02000000","0.00005000"],["115521.02000000","0.00000000"],["115525.26000000","0.02498000"],["115535.82000000","0.00000000"],["115566.07000000","0.00100000"],["115566.08000000","0.00100000"],["115571.27000000","0.03400000"],["115856.59000000","0.02498000"],["115857.22000000","0.02498000"],["115858.10000000","0.02498000"],["115858.58000000","0.02498000"],["115859.70000000","0.02498000"],["115860.87000000","0.02498000"],["115861.86000000","0.02498000"],["117210.97000000","0.00100000"],["124927.42000000","0.00007000"]]}
[2025-10-27T18:48:42.153Z] {"e":"depthUpdate","E":1761590922014,"s":"BTCUSDT","U":79129621553,"u":79129621750,"b":[["115478.77000000","8.21701000"],["115478.76000000","0.00047000"],["115467.12000000","0.00005000"],["115454.81000000","0.08658000"],["115450.56000000","0.00000000"],["115449.46000000","0.00583000"],["115384.08000000","0.00000000"],["113746.58000000","0.00413000"],["106212.08000000","0.00000000"],["103930.00000000","0.00010000"],["92383.02000000","0.00021000"]],"a":[["115478.78000000","1.18151000"],["115478.79000000","0.00055000"],["115479.42000000","0.00058000"],["115479.97000000","0.00000000"],["115479.98000000","0.00000000"],["115480.00000000","0.01907000"],["115480.05000000","0.00010000"],["115480.06000000","0.03403000"],["115480.07000000","0.03812000"],["115481.15000000","0.00036000"],["115481.44000000","0.03896000"],["115484.57000000","0.00150000"],["115485.47000000","0.00000000"],["115485.48000000","0.00000000"],["115486.22000000","0.01713000"],["115486.49000000","0.00000000"],["115486.50000000","0.00038000"],["115486.75000000","0.28579000"],["115487.34000000","0.03008000"],["115487.78000000","0.00000000"],["115488.00000000","0.00170000"],["115488.49000000","0.04597000"],["115488.59000000","0.00381000"],["115488.76000000","1.21447000"],["115488.77000000","2.47840000"],["115489.24000000","0.00000000"],["115490.95000000","0.00000000"],["115492.33000000","0.00000000"],["115496.37000000","0.07029000"],["115503.24000000","0.00000000"],["115504.03000000","0.16996000"],["115515.77000000","0.00000000"],["115516.04000000","0.31163000"],["115521.03000000","0.06535000"],["115525.94000000","0.00005000"],["115533.92000000","0.25975000"],["115534.50000000","0.00000000"],["115540.20000000","0.00000000"],["115552.10000000","0.01356000"],["115566.07000000","0.00000000"],["115566.09000000","0.00100000"],["115827.52000000","0.00000000"],["115881.82000000","0.37961000"],["115885.63000000","0.00000000"],["115901.39000000","0.00684000"],["117210.97000000","0.00100000"],["117278.81000000","0.00000000"]]}
[2025-10-27T18:48:43.148Z] {"e":"depthUpdate","E":1761590923014,"s":"BTCUSDT","U":79129621751,"u":79129621996,"b":[["115478.77000000","8.12704000"],["115478.76000000","0.00062000"],["115478.69000000","0.00000000"],["115478.59000000","0.00000000"],["115478.58000000","0.00000000"],["115478.13000000","0.12752000"],["115478.12000000","0.00000000"],["115477.62000000","0.00100000"],["115477.29000000","0.41586000"],["115476.97000000","0.00000000"],["115476.96000000","0.00000000"],["115476.65000000","0.00000000"],["115476.64000000","0.00000000"],["115476.18000000","0.00010000"],["115476.17000000","0.04404000"],["115474.57000000","0.00000000"],["115474.56000000","0.00000000"],["115474.15000000","0.00010000"],["115474.14000000","0.19845000"],["115472.97000000","0.00005000"],["115472.96000000","0.17322000"],["115472.73000000","0.00000000"],["115472.06000000","0.17322000"],["115471.98000000","0.08824000"],["115471.90000000","0.01724000"],["115471.63000000","0.25643000"],["115471.57000000","0.00000000"],["115470.22000000","0.02599000"],["115468.30000000","1.10006000"],["115467.23000000","2.47832000"],["115464.38000000","0.00000000"],["115449.96000000","0.00000000"],["115449.70000000","0.00583000"],["115449.46000000","0.00000000"],["115435.74000000","0.00000000"],["115396.18000000","0.01356000"],["115394.08000000","0.00000000"],["115384.08000000","0.00005000"],["115378.81000000","0.00000000"],["115378.64000000","0.03025000"],["115368.72000000","0.00000000"],["115359.22000000","0.09147000"],["115359.21000000","0.00000000"],["115239.03000000","4.89196000"],["115238.99000000","0.00000000"],["113746.58000000","0.00413000"],["103930.00000000","0.00010000"],["92383.02000000","0.00021000"]],"a":[["115478.78000000","2.29709000"],["115478.79000000","0.00055000"],["115479.15000000","0.00000000"],["115480.00000000","0.01902000"],["115480.06000000","0.10476000"],["115480.07000000","0.03812000"],["115481.43000000","0.00000000"],["115481.44000000","0.00000000"],["115484.11000000","0.00010000"],["115484.12000000","0.28579000"],["115486.21000000","0.00000000"],["115486.22000000","0.01713000"],["115486.74000000","0.00000000"],["115486.75000000","0.00000000"],["115487.33000000","0.00005000"],["115488.49000000","0.04602000"],["115488.50000000","0.06105000"],["115488.76000000","1.21447000"],["115489.18000000","0.00000000"],["115490.23000000","0.00583000"],["115495.32000000","0.06748000"],["115515.47000000","0.25975000"],["115525.25000000","0.02498000"],["115527.04000000","0.00000000"],["115532.86000000","0.00005000"],["115533.92000000","0.00000000"],["115535.27000000","0.25975000"],["115562.55000000","0.25975000"],["115573.15000000","0.00000000"],["115878.02000000","0.37961000"],["115881.82000000","0.00000000"],["115946.28000000","0.02498000"],["117210.97000000","0.00100000"],["117934.85000000","0.00021000"],["123000.00000000","38.02531000"]]}
[2025-10-27T18:48:44.147Z] {"e":"depthUpdate","E":1761590924014,"s":"BTCUSDT","U":79129621997,"u":79129622343,"b":[["115478.77000000","8.12424000"],["115478.76000000","0.00052000"],["115478.49000000","0.00025000"],["115478.13000000","0.12737000"],["115478.08000000","0.03915000"],["115477.29000000","0.41581000"],["115477.20000000","0.00010000"],["115477.19000000","0.03939000"],["115476.71000000","0.00000000"],["115476.70000000","0.00000000"],["115476.17000000","0.04404000"],["115475.56000000","0.17317000"],["115474.15000000","0.00000000"],["115472.97000000","0.00000000"],["115472.96000000","0.17322000"],["115472.06000000","0.00000000"],["115471.90000000","0.01724000"],["115471.85000000","0.00520000"],["115467.24000000","0.54080000"],["115461.88000000","0.00000000"],["115458.14000000","0.31179000"],["115456.57000000","0.95050000"],["115454.81000000","0.00000000"],["115452.52000000","0.08658000"],["115450.06000000","0.00583000"],["115449.70000000","0.00000000"],["115435.63000000","0.00000000"],["115413.03000000","0.00000000"],["115411.98000000","0.25985000"],["115407.95000000","0.00000000"],["115379.50000000","0.00000000"],["115364.74000000","0.18705000"],["115361.38000000","0.00000000"],["115360.90000000","0.00000000"],["115360.50000000","0.00000000"],["115359.02000000","0.00000000"],["115336.02000000","0.00000000"],["115334.32000000","0.00000000"],["113746.58000000","0.00413000"],["112640.00000000","0.00092000"],["103930.00000000","0.00010000"],["92383.02000000","0.00021000"],["92383.00000000","0.00000000"]],"a":[["115478.78000000","1.16359000"],["115478.79000000","0.00050000"],["115479.42000000","0.00058000"],["115479.98000000","0.00010000"],["115479.99000000","0.02246000"],["115480.00000000","0.01887000"],["115480.05000000","0.00000000"],["115480.06000000","0.00000000"],["115480.07000000","0.00000000"],["115482.00000000","0.00165000"],["115482.12000000","0.00000000"],["115482.34000000","0.00010000"],["115482.35000000","0.00005000"],["115484.11000000","0.00000000"],["115484.12000000","0.00000000"],["115484.53000000","0.28574000"],["115485.70000000","0.00524000"],["115486.00000000","0.00165000"],["115486.14000000","0.00255000"],["115486.22000000","0.00000000"],["115486.51000000","0.00000000"],["115486.62000000","0.00000000"],["115486.63000000","0.00000000"],["115486.69000000","0.00010000"],["115486.70000000","0.01772000"],["115487.00000000","0.06105000"],["115487.01000000","0.00005000"],["115487.02000000","0.00005000"],["115487.33000000","0.00005000"],["115487.34000000","0.03008000"],["115488.00000000","0.00165000"],["115488.49000000","0.00000000"],["115488.50000000","0.00000000"],["115488.59000000","0.00381000"],["115488.75000000","0.00000000"],["115488.76000000","1.21452000"],["115488.77000000","2.47845000"],["115488.78000000","0.54080000"],["115488.85000000","0.08658000"],["115488.86000000","0.04592000"],["115489.23000000","0.00000000"],["115490.23000000","0.00115000"],["115490.87000000","0.00000000"],["115492.01000000","0.00000000"],["115492.51000000","0.00000000"],["115493.84000000","0.00000000"],["115493.85000000","0.00000000"],["115493.86000000","0.07029000"],["115496.37000000","0.00000000"],["115502.78000000","0.34651000"],["115509.24000000","0.00000000"],["115513.43000000","0.26275000"],["115526.34000000","0.00000000"],["115535.27000000","0.00000000"],["115560.29000000","0.13238000"],["115561.31000000","0.34651000"],["115566.30000000","0.00000000"],["115578.76000000","0.02500000"],["115878.02000000","0.37961000"],["117210.97000000","0.00100000"],["119000.00000000","26.95947000"]]}
[2025-10-27T18:48:45.146Z] {"e":"depthUpdate","E":1761590925014,"s":"BTCUSDT","U":79129622344,"u":79129622805,"b":[["115478.77000000","7.84551000"],["115478.76000000","0.00062000"],["115478.50000000","0.00000000"],["115478.49000000","0.00000000"],["115478.13000000","0.10347000"],["115478.09000000","0.00000000"],["115478.08000000","0.00000000"],["115477.62000000","0.00110000"],["115477.29000000","0.32767000"],["115477.20000000","0.00000000"],["115477.19000000","0.00000000"],["115476.80000000","0.00010000"],["115476.79000000","0.00010000"],["115476.17000000","0.04414000"],["115475.95000000","0.00000000"],["115475.89000000","0.00201000"],["115475.67000000","0.00005000"],["115475.66000000","0.04565000"],["115475.56000000","0.00000000"],["115474.75000000","0.00000000"],["115474.16000000","0.00346000"],["115474.15000000","0.00005000"],["115474.14000000","0.14597000"],["115473.78000000","0.00000000"],["115473.77000000","0.00005000"],["115473.26000000","0.17323000"],["115472.28000000","0.00255000"],["115471.98000000","0.08829000"],["115471.90000000","0.00000000"],["115471.85000000","0.00530000"],["115471.63000000","0.00000000"],["115471.44000000","0.01694000"],["115470.22000000","0.00000000"],["115470.16000000","0.02604000"],["115469.74000000","0.00105000"],["115469.01000000","0.25643000"],["115469.00000000","0.00437000"],["115467.66000000","0.00255000"],["115467.24000000","0.00000000"],["115465.23000000","0.00335000"],["115465.00000000","0.06000000"],["115463.66000000","0.00005000"],["115458.14000000","0.00000000"],["115456.71000000","0.31179000"],["115454.07000000","0.00000000"],["115452.55000000","0.00000000"],["115452.07000000","0.00000000"],["115451.58000000","0.31181000"],["115450.06000000","0.00000000"],["115450.02000000","0.04000000"],["115449.69000000","0.00000000"],["115449.32000000","0.00583000"],["115440.16000000","0.00000000"],["115439.16000000","0.00865000"],["115434.32000000","0.00000000"],["115391.00000000","0.00000000"],["115387.54000000","0.00000000"],["115336.30000000","0.10322000"],["115239.03000000","0.00000000"],["115015.15000000","0.02498000"],["115014.42000000","0.02498000"],["113746.58000000","0.00413000"],["111984.74000000","0.00000000"],["111977.37000000","0.02167000"],["103930.00000000","0.00010000"],["92383.02000000","0.00021000"],["42000.00000000","1.36531000"]],"a":[["115478.78000000","3.64898000"],["115478.79000000","0.00060000"],["115479.31000000","0.00010000"],["115479.32000000","0.03989000"],["115479.42000000","0.00043000"],["115479.99000000","0.18645000"],["115480.00000000","0.01887000"],["115481.10000000","0.00010000"],["115481.11000000","0.29228000"],["115482.00000000","0.00160000"],["115482.21000000","0.00000000"],["115482.34000000","0.00000000"],["115482.35000000","0.00000000"],["115484.00000000","0.00165000"],["115484.19000000","0.00010000"],["115484.20000000","0.28579000"],["115484.44000000","0.00000000"],["115484.45000000","0.00000000"],["115484.52000000","0.00000000"],["115484.53000000","0.00000000"],["115485.70000000","0.00524000"],["115486.14000000","0.00260000"],["115486.31000000","0.00000000"],["115486.32000000","0.04597000"],["115486.69000000","0.00000000"],["115486.70000000","0.01777000"],["115486.88000000","0.00000000"],["115486.99000000","0.00000000"],["115487.00000000","0.06110000"],["115487.01000000","0.00000000"],["115487.02000000","0.00000000"],["115487.33000000","0.00000000"],["115487.34000000","0.03003000"],["115488.59000000","0.00381000"],["115488.76000000","1.21447000"],["115488.77000000","2.47840000"],["115488.85000000","0.08658000"],["115488.86000000","0.00000000"],["115489.05000000","0.00000000"],["115490.23000000","0.00128000"],["115491.10000000","0.25985000"],["115492.38000000","0.00000000"],["115492.44000000","0.03000000"],["115492.59000000","0.00000000"],["115500.68000000","0.00000000"],["115502.55000000","0.00000000"],["115502.70000000","0.00000000"],["115507.36000000","0.04665000"],["115508.76000000","0.00000000"],["115511.12000000","0.57008000"],["115511.13000000","0.31165000"],["115512.50000000","0.06100000"],["115512.80000000","0.00000000"],["115513.43000000","0.26275000"],["115516.10000000","0.00865000"],["115518.66000000","0.00000000"],["115521.03000000","0.00000000"],["115522.51000000","0.33510000"],["115524.25000000","0.31161000"],["115525.61000000","0.00000000"],["115530.29000000","0.00000000"],["115537.43000000","0.25985000"],["115548.64000000","0.00000000"],["115555.81000000","0.24062000"],["115557.05000000","0.00000000"],["115557.18000000","0.00000000"],["115557.26000000","0.00000000"],["115557.79000000","0.43314000"],["115558.20000000","0.43307000"],["115560.29000000","0.00000000"],["115569.98000000","0.03292000"],["115572.62000000","0.00000000"],["115576.30000000","0.00000000"],["117210.97000000","0.00100000"]]}
[2025-10-27T18:48:46.146Z] {"e":"depthUpdate","E":1761590926014,"s":"BTCUSDT","U":79129622806,"u":79129623000,"b":[["115478.77000000","7.86196000"],["115478.76000000","0.00062000"],["115478.61000000","0.00010000"],["115478.60000000","0.03928000"],["115478.13000000","0.10332000"],["115477.62000000","0.00110000"],["115477.54000000","0.00010000"],["115477.53000000","0.04570000"],["115477.29000000","0.32762000"],["115476.80000000","0.00000000"],["115476.79000000","0.00000000"],["115476.17000000","0.04409000"],["115475.89000000","0.00196000"],["115475.67000000","0.00000000"],["115475.66000000","0.00000000"],["115474.16000000","0.00346000"],["115474.15000000","0.00000000"],["115471.85000000","0.00530000"],["115469.00000000","0.00442000"],["115468.96000000","0.00381000"],["115467.23000000","2.48525000"],["115446.75000000","0.00000000"],["115443.29000000","0.00000000"],["115439.16000000","0.00000000"],["115415.47000000","0.00865000"],["115391.00000000","0.00005000"],["115263.88000000","0.01356000"],["115252.84000000","0.00000000"],["115234.25000000","4.82871000"],["113746.58000000","0.00413000"],["103930.00000000","0.00010000"],["92383.02000000","0.00021000"]],"a":[["115478.78000000","3.04275000"],["115478.79000000","0.00065000"],["115479.32000000","0.03994000"],["115479.42000000","0.00043000"],["115479.93000000","0.00100000"],["115479.99000000","0.18640000"],["115481.11000000","0.29233000"],["115481.66000000","0.00191000"],["115482.55000000","0.00310000"],["115483.39000000","0.00346000"],["115485.70000000","0.00524000"],["115488.59000000","0.00381000"],["115490.32000000","0.00693000"],["115491.66000000","0.00069000"],["115494.39000000","0.02599000"],["115502.86000000","0.00000000"],["115504.04000000","0.58033000"],["115516.10000000","0.00000000"],["115521.15000000","0.06576000"],["115555.81000000","0.40330000"],["115557.09000000","0.43307000"],["115558.20000000","0.00000000"],["115878.02000000","0.37961000"],["117210.97000000","0.00100000"]]}
[2025-10-27T18:48:47.149Z] {"e":"depthUpdate","E":1761590927014,"s":"BTCUSDT","U":79129623001,"u":79129623132,"b":[["115478.77000000","7.82670000"],["115463.76000000","0.09098000"],["115462.28000000","0.00500000"],["113746.58000000","0.00413000"],["106212.08000000","0.00010000"],["103930.00000000","0.00010000"],["92383.02000000","0.00021000"],["92383.00000000","0.00000000"],["42000.00000000","1.36431000"],["41642.84000000","0.00015000"],["41630.96000000","0.00000000"],["41623.20000000","0.00045000"],["41602.16000000","0.00360000"],["41599.20000000","0.00015000"],["41589.37000000","0.00015000"],["41588.64000000","0.00105000"],["41579.13000000","0.00210000"],["41530.78000000","0.00000000"],["41528.46000000","0.00000000"],["41526.42000000","0.00000000"],["41515.92000000","0.00000000"],["41514.84000000","0.00015000"],["41511.59000000","0.00000000"],["41495.12000000","0.00000000"],["41492.71000000","0.00000000"],["41490.55000000","0.00000000"],["41482.25000000","0.00000000"],["33000.00000000","3.79030000"]],"a":[["115478.78000000","2.89881000"],["115479.32000000","0.03999000"],["115490.23000000","0.00557000"],["115492.31000000","0.00000000"],["115493.79000000","0.08889000"],["115494.39000000","0.00000000"],["115513.43000000","0.69582000"],["115539.80000000","0.00865000"],["115557.09000000","0.00000000"],["115557.10000000","0.00000000"],["115569.98000000","0.06751000"],["115594.66000000","0.00173000"],["115878.02000000","0.37961000"],["117210.97000000","0.00100000"]]}
[2025-10-27T18:48:48.178Z] {"e":"depthUpdate","E":1761590928014,"s":"BTCUSDT","U":79129623133,"u":79129623218,"b":[["115478.77000000","7.82573000"],["115478.76000000","0.00067000"],["115476.17000000","0.04409000"],["115474.14000000","0.00000000"],["115473.27000000","0.21984000"],["115470.56000000","0.25643000"],["115469.74000000","0.00100000"],["115469.01000000","0.00000000"],["115469.00000000","0.00010000"],["115467.66000000","0.00260000"],["115467.24000000","0.00432000"],["115462.93000000","0.15809000"],["115462.01000000","0.00500000"],["115458.84000000","0.00000000"],["115457.10000000","0.04329000"],["115456.53000000","0.00000000"],["115447.90000000","0.25985000"],["115415.47000000","0.00000000"],["115230.01000000","0.00073000"],["115200.01000000","0.00000000"],["113746.58000000","0.00413000"],["106212.08000000","0.00000000"],["103930.00000000","0.00010000"],["92383.02000000","0.00021000"],["60000.00000000","57.97732000"]],"a":[["115478.78000000","3.67413000"],["115490.23000000","0.00545000"],["115494.39000000","0.00000000"],["115494.40000000","0.02599000"],["115495.37000000","0.00432000"],["115499.48000000","0.00000000"],["115499.99000000","0.17308000"],["115502.78000000","0.00000000"],["115504.03000000","0.00000000"],["115513.43000000","0.69582000"],["115523.99000000","0.00000000"],["115525.24000000","0.00008000"],["115535.77000000","0.42465000"],["115536.93000000","0.00008000"],["115539.80000000","0.00000000"],["115545.99000000","0.00000000"],["115547.99000000","0.00215000"],["115555.81000000","0.00000000"],["115557.13000000","0.06447000"],["115557.34000000","0.34651000"],["115557.35000000","0.00000000"],["115557.79000000","0.00000000"],["115561.31000000","0.00000000"],["115649.99000000","0.00000000"],["115651.38000000","0.00086000"],["115661.24000000","0.00000000"],["115662.64000000","0.00086000"],["115878.02000000","0.37961000"],["117210.97000000","0.00100000"]]}
[2025-10-27T18:48:49.148Z] {"e":"depthUpdate","E":1761590929014,"s":"BTCUSDT","U":79129623219,"u":79129623344,"b":[["115478.77000000","7.84935000"],["115478.76000000","0.00062000"],["115478.13000000","0.10332000"],["115477.62000000","0.00105000"],["115477.54000000","0.00000000"],["115477.53000000","0.00000000"],["115476.17000000","0.04414000"],["115473.28000000","0.00005000"],["115471.85000000","0.00530000"],["115471.44000000","0.01699000"],["115470.56000000","0.24949000"],["115470.55000000","0.00694000"],["115470.16000000","0.00005000"],["115463.76000000","0.09029000"],["115456.62000000","0.95634000"],["115456.57000000","0.00000000"],["115454.97000000","0.00865000"],["115178.77000000","0.00000000"],["113746.58000000","0.00413000"],["111984.74000000","0.02167000"],["111977.37000000","0.00000000"],["103930.89000000","0.00138000"],["103930.00000000","0.00010000"],["92383.02000000","0.00021000"]],"a":[["115478.78000000","2.39472000"],["115486.70000000","0.01772000"],["115487.00000000","0.00005000"],["115490.23000000","0.00152000"],["115491.27000000","0.07029000"],["115491.91000000","0.00069000"],["115491.93000000","0.00000000"],["115493.79000000","0.08935000"],["115493.86000000","0.00000000"],["115494.40000000","0.00000000"],["115494.66000000","0.00432000"],["115495.37000000","0.00000000"],["115495.84000000","0.00000000"],["115496.52000000","0.00432000"],["115499.99000000","0.00312000"],["115501.97000000","0.16996000"],["115501.98000000","0.34651000"],["115502.76000000","0.43307000"],["115503.94000000","0.43314000"],["115504.04000000","0.14719000"],["115513.43000000","0.26275000"],["115536.93000000","0.00056000"],["115536.94000000","0.00009000"],["115557.11000000","0.00000000"],["115557.13000000","0.32848000"],["115557.86000000","0.00000000"],["115557.91000000","0.00000000"],["115559.03000000","0.43314000"],["115560.39000000","0.13242000"],["115560.51000000","0.43307000"],["115566.04000000","0.00100000"],["115566.05000000","0.00100000"],["115566.08000000","0.00000000"],["115566.09000000","0.00000000"],["115625.21000000","0.00000000"],["115652.02000000","0.00019000"],["115652.16000000","0.00000000"],["115653.38000000","0.02078000"],["117210.97000000","0.00100000"]]}
[2025-10-27T18:48:50.147Z] {"e":"depthUpdate","E":1761590930014,"s":"BTCUSDT","U":79129623345,"u":79129623414,"b":[["115478.77000000","7.78458000"],["115465.00000000","0.06005000"],["115464.99000000","0.02599000"],["115463.76000000","0.09495000"],["115178.77000000","0.00000000"],["113746.58000000","0.00413000"],["103930.89000000","0.00119000"],["103930.00000000","0.00010000"],["99999.00000000","8.26486000"],["92383.02000000","0.00021000"],["92383.00000000","0.00000000"]],"a":[["115478.78000000","2.82690000"],["115485.70000000","0.00524000"],["115486.14000000","0.00255000"],["115486.32000000","0.00000000"],["115486.33000000","0.04592000"],["115487.34000000","0.03008000"],["115488.00000000","0.06265000"],["115488.77000000","2.47840000"],["115491.88000000","0.00069000"],["115491.91000000","0.00000000"],["115493.79000000","0.08638000"],["115499.66000000","0.02599000"],["115500.32000000","0.00865000"],["115502.76000000","0.00000000"],["115513.43000000","0.26275000"],["115557.27000000","0.00000000"],["115557.49000000","0.43307000"],["115560.51000000","0.00000000"],["115566.04000000","0.00000000"],["115566.06000000","0.00100000"],["117210.97000000","0.00100000"]]}
[2025-10-27T18:48:51.151Z] {"e":"depthUpdate","E":1761590931014,"s":"BTCUSDT","U":79129623415,"u":79129623515,"b":[["115478.77000000","7.78754000"],["115476.17000000","0.04414000"],["115475.89000000","0.00201000"],["115475.67000000","0.00005000"],["115475.66000000","0.04565000"],["115473.27000000","0.19693000"],["115471.85000000","0.00525000"],["115471.44000000","0.01699000"],["115470.56000000","0.00000000"],["115470.55000000","0.00000000"],["115470.36000000","0.24949000"],["115470.35000000","0.00694000"],["115465.23000000","0.00330000"],["115465.00000000","0.06000000"],["115463.77000000","0.15809000"],["115462.93000000","0.00000000"],["115454.97000000","0.00000000"],["115453.68000000","0.00000000"],["115453.67000000","0.00000000"],["115453.64000000","0.00000000"],["115453.63000000","0.08658000"],["115453.22000000","0.00865000"],["115452.52000000","0.00000000"],["115442.31000000","0.01732000"],["115358.71000000","0.09389000"],["113746.58000000","0.00413000"],["103930.00000000","0.00010000"],["92383.02000000","0.00021000"],["50000.00000000","39.61417000"],["41572.36000000","0.00060000"]],"a":[["115478.78000000","3.81554000"],["115485.70000000","0.00524000"],["115486.14000000","0.00260000"],["115486.33000000","0.04597000"],["115490.23000000","0.00534000"],["115491.88000000","0.00000000"],["115500.32000000","0.00000000"],["115501.98000000","0.00000000"],["115503.94000000","0.00000000"],["115513.43000000","1.12896000"],["115521.15000000","0.00000000"],["115556.95000000","0.00000000"],["115557.00000000","0.34651000"],["115557.13000000","0.00000000"],["115557.34000000","0.00000000"],["115557.49000000","0.00000000"],["115559.03000000","0.00000000"],["115560.39000000","0.00000000"],["115878.02000000","0.37961000"],["117210.97000000","0.00100000"]]}
[2025-10-27T18:48:52.148Z] {"e":"depthUpdate","E":1761590932015,"s":"BTCUSDT","U":79129623516,"u":79129623627,"b":[["115478.77000000","7.78406000"],["115471.44000000","0.01694000"],["115470.36000000","0.25634000"],["115470.35000000","0.00000000"],["115467.66000000","0.00255000"],["115467.24000000","0.00000000"],["115467.23000000","2.48957000"],["115465.24000000","0.00000000"],["115465.23000000","0.00335000"],["115465.00000000","0.06005000"],["115460.33000000","0.95518000"],["115456.62000000","0.00000000"],["115453.22000000","0.00000000"],["115422.04000000","0.00000000"],["115397.00000000","0.00216000"],["115368.22000000","0.00000000"],["115358.71000000","0.00000000"],["115358.41000000","0.00000000"],["115358.37000000","0.00000000"],["115358.36000000","0.00000000"],["115358.34000000","0.02339000"],["115358.24000000","0.00000000"],["115179.54000000","0.00000000"],["115179.53000000","0.00000000"],["115179.52000000","0.00000000"],["115156.56000000","0.21786000"],["115156.55000000","0.00000000"],["115156.54000000","0.00000000"],["113746.58000000","0.00413000"],["103930.01000000","0.00000000"],["103930.00000000","0.00010000"],["92383.02000000","0.00021000"],["33000.01000000","0.00000000"],["33000.00000000","3.79030000"]],"a":[["115478.78000000","3.03589000"],["115478.79000000","0.00065000"],["115481.11000000","0.29233000"],["115482.01000000","0.00005000"],["115482.02000000","0.28580000"],["115484.19000000","0.00000000"],["115484.20000000","0.00000000"],["115488.00000000","0.06265000"],["115490.23000000","0.00524000"],["115491.27000000","0.00000000"],["115491.32000000","0.00000000"],["115491.43000000","0.00006000"],["115491.44000000","0.07029000"],["115501.68000000","0.43314000"],["115502.73000000","0.34651000"],["115506.52000000","0.31166000"],["115513.43000000","0.26275000"],["115517.33000000","0.00000000"],["115521.36000000","0.06643000"],["115524.25000000","0.00000000"],["115556.93000000","0.00000000"],["115556.97000000","0.00000000"],["115556.99000000","0.16792000"],["115558.61000000","0.43307000"],["115571.24000000","0.03400000"],["115571.27000000","0.00000000"],["115878.02000000","0.37961000"],["117210.97000000","0.00100000"]]}
[2025-10-27T18:48:53.260Z] {"e":"depthUpdate","E":1761590933014,"s":"BTCUSDT","U":79129623628,"u":79129623713,"b":[["115478.77000000","7.82973000"],["115478.23000000","0.00000000"],["115475.66000000","0.00005000"],["115461.31000000","0.31178000"],["115454.17000000","0.00865000"],["115440.62000000","0.00000000"],["115406.60000000","0.00000000"],["115396.18000000","0.00000000"],["115365.67000000","0.01356000"],["115343.10000000","0.00243000"],["115337.00000000","0.00000000"],["114777.27000000","0.00000000"],["113746.58000000","0.00413000"],["106212.08000000","0.00010000"],["103930.00000000","0.00010000"],["92383.02000000","0.00021000"],["92383.00000000","0.00000000"]],"a":[["115478.78000000","3.03516000"],["115478.79000000","0.00060000"],["115479.31000000","0.00000000"],["115479.32000000","0.00025000"],["115482.01000000","0.00010000"],["115482.02000000","0.28585000"],["115486.32000000","0.00005000"],["115488.00000000","0.00165000"],["115491.44000000","0.00000000"],["115491.45000000","0.00000000"],["115491.46000000","0.00000000"],["115491.47000000","0.00000000"],["115491.48000000","0.00000000"],["115491.49000000","0.00000000"],["115491.50000000","0.07034000"],["115513.43000000","0.26275000"],["115544.43000000","0.00000000"],["115556.94000000","0.00000000"],["115556.99000000","0.40502000"],["115557.53000000","0.43314000"],["115557.78000000","0.43307000"],["115558.61000000","0.00000000"],["115559.13000000","0.00000000"],["115572.55000000","0.18703000"],["115575.82000000","0.00243000"],["115795.44000000","0.00000000"],["115796.56000000","0.02298000"],["115878.02000000","0.37961000"],["117210.97000000","0.00100000"]]}
[2025-10-27T18:48:54.182Z] {"e":"depthUpdate","E":1761590934014,"s":"BTCUSDT","U":79129623714,"u":79129624312,"b":[["115478.77000000","7.82766000"],["115478.76000000","0.00052000"],["115476.17000000","0.04414000"],["115475.89000000","0.00196000"],["115475.67000000","0.00000000"],["115475.66000000","0.00000000"],["115474.16000000","0.00346000"],["115473.75000000","0.00000000"],["115473.74000000","0.00000000"],["115473.70000000","0.25639000"],["115473.27000000","0.17283000"],["115472.96000000","0.17322000"],["115472.56000000","0.00000000"],["115471.98000000","0.08829000"],["115471.85000000","0.00525000"],["115471.44000000","0.01699000"],["115470.37000000","0.00432000"],["115470.36000000","0.00000000"],["115468.49000000","0.00006000"],["115467.66000000","0.00255000"],["115467.24000000","0.54080000"],["115467.23000000","2.48525000"],["115465.54000000","0.00000000"],["115465.23000000","0.00000000"],["115465.00000000","0.06005000"],["115464.77000000","0.00325000"],["115463.50000000","0.00000000"],["115462.93000000","0.00000000"],["115461.45000000","0.00150000"],["115460.33000000","1.21503000"],["115458.67000000","0.04329000"],["115458.66000000","0.25975000"],["115458.11000000","0.00000000"],["115457.69000000","0.00000000"],["115457.10000000","0.00000000"],["115456.64000000","0.04271000"],["115455.25000000","0.43314000"],["115454.59000000","0.00000000"],["115447.90000000","0.00000000"],["115446.99000000","0.00000000"],["115444.12000000","0.00000000"],["115444.07000000","0.25975000"],["115437.69000000","0.00000000"],["115413.68000000","0.25985000"],["115411.98000000","0.00000000"],["115410.25000000","0.25975000"],["115407.30000000","0.00000000"],["115400.54000000","0.00000000"],["115400.45000000","0.00000000"],["115400.44000000","0.00000000"],["115399.19000000","0.43307000"],["115398.67000000","0.25975000"],["115395.97000000","0.00000000"],["115390.29000000","0.00000000"],["115377.66000000","0.00000000"],["115363.35000000","0.02813000"],["115362.18000000","0.00000000"],["115361.99000000","0.00000000"],["115360.78000000","0.00000000"],["115359.87000000","0.00000000"],["115234.25000000","0.00000000"],["113875.87000000","0.00326000"],["113746.58000000","0.00413000"],["111984.74000000","0.00000000"],["111977.37000000","0.02167000"],["106212.08000000","0.00000000"],["103930.00000000","0.00010000"],["92383.02000000","0.00021000"]],"a":[["115478.78000000","1.34161000"],["115478.79000000","0.00055000"],["115479.31000000","0.00000000"],["115479.32000000","0.00000000"],["115479.42000000","0.00058000"],["115479.51000000","0.00010000"],["115479.52000000","0.10787000"],["115479.53000000","0.00000000"],["115479.54000000","0.00000000"],["115479.93000000","0.00100000"],["115479.98000000","0.00000000"],["115479.99000000","0.00010000"],["115480.00000000","0.01887000"],["115481.09000000","0.00000000"],["115481.10000000","0.00000000"],["115481.11000000","0.00000000"],["115482.00000000","0.00165000"],["115482.01000000","0.00000000"],["115482.02000000","0.00000000"],["115482.39000000","0.00010000"],["115482.40000000","0.03849000"],["115484.28000000","0.00000000"],["115484.45000000","0.00010000"],["115484.46000000","0.28584000"],["115485.70000000","0.00524000"],["115486.00000000","0.00160000"],["115486.14000000","0.00005000"],["115486.32000000","0.00000000"],["115486.33000000","0.00000000"],["115486.69000000","0.00000000"],["115486.70000000","0.00000000"],["115486.78000000","0.00000000"],["115486.79000000","0.01697000"],["115487.33000000","0.00010000"],["115487.34000000","0.03008000"],["115487.77000000","0.00000000"],["115487.78000000","0.00000000"],["115488.00000000","0.00165000"],["115488.75000000","0.00000000"],["115488.76000000","1.21447000"],["115488.77000000","2.47840000"],["115488.84000000","0.00000000"],["115489.86000000","0.25975000"],["115490.23000000","0.00514000"],["115491.12000000","0.29220000"],["115491.41000000","0.04532000"],["115491.50000000","0.00005000"],["115491.85000000","0.00069000"],["115492.06000000","0.00000000"],["115492.14000000","0.00000000"],["115492.65000000","0.00000000"],["115493.76000000","0.00000000"],["115493.77000000","0.07029000"],["115496.52000000","0.00000000"],["115497.99000000","0.00000000"],["115499.65000000","0.00432000"],["115499.66000000","0.00000000"],["115499.67000000","0.02599000"],["115499.88000000","0.00865000"],["115501.97000000","0.00000000"],["115503.07000000","0.43307000"],["115504.89000000","0.16996000"],["115506.52000000","0.00000000"],["115509.24000000","0.00250000"],["115511.56000000","0.12126000"],["115523.20000000","0.31161000"],["115527.77000000","0.00000000"],["115543.31000000","0.00400000"],["115552.10000000","0.01356000"],["115589.97000000","0.00000000"],["115590.54000000","0.00499000"],["117210.97000000","0.00100000"]]}
[2025-10-27T18:48:55.205Z] {"e":"depthUpdate","E":1761590935014,"s":"BTCUSDT","U":79129624313,"u":79129624617,"b":[["115478.77000000","6.55469000"],["115478.76000000","0.00042000"],["115478.61000000","0.00000000"],["115478.60000000","0.00020000"],["115476.58000000","0.04910000"],["115476.17000000","0.04414000"],["115474.33000000","0.00000000"],["115473.71000000","0.00000000"],["115473.70000000","0.00000000"],["115473.28000000","0.00010000"],["115473.27000000","0.17293000"],["115472.88000000","0.00000000"],["115471.98000000","0.00010000"],["115471.85000000","0.00530000"],["115471.44000000","0.00000000"],["115470.71000000","0.00000000"],["115470.37000000","0.00000000"],["115469.74000000","0.00105000"],["115468.97000000","0.00000000"],["115467.66000000","0.00255000"],["115467.25000000","0.00000000"],["115466.49000000","0.82860000"],["115465.01000000","0.00432000"],["115465.00000000","0.06000000"],["115461.31000000","0.00000000"],["115458.67000000","0.00000000"],["115456.71000000","0.00000000"],["115456.00000000","0.04329000"],["115455.70000000","0.08658000"],["115453.63000000","0.00000000"],["115443.32000000","0.31183000"],["115439.96000000","0.31184000"],["115397.87000000","0.00000000"],["115395.48000000","0.43314000"],["115382.32000000","1.08889000"],["115378.64000000","0.00000000"],["115360.05000000","0.00000000"],["115359.48000000","0.00000000"],["115243.85000000","4.88622000"],["113746.58000000","0.00413000"],["103930.00000000","0.00010000"],["92383.02000000","0.00021000"],["42000.00000000","1.36531000"]],"a":[["115478.78000000","4.86167000"],["115478.79000000","0.00070000"],["115478.95000000","0.00000000"],["115479.17000000","0.00000000"],["115479.40000000","0.00010000"],["115479.41000000","0.25921000"],["115479.42000000","0.50053000"],["115479.51000000","0.00000000"],["115479.52000000","0.00005000"],["115479.57000000","0.00010000"],["115479.58000000","0.03819000"],["115479.85000000","0.28575000"],["115479.93000000","0.00095000"],["115479.99000000","0.00000000"],["115480.00000000","0.01892000"],["115480.11000000","0.00000000"],["115480.33000000","0.00000000"],["115480.34000000","0.00000000"],["115481.28000000","0.00010000"],["115481.29000000","0.00005000"],["115481.34000000","0.00005000"],["115481.35000000","0.00005000"],["115482.00000000","0.00160000"],["115482.05000000","0.00005000"],["115482.39000000","0.00000000"],["115482.40000000","0.00000000"],["115484.45000000","0.00000000"],["115484.46000000","0.00000000"],["115485.70000000","0.00524000"],["115486.00000000","0.00165000"],["115486.14000000","0.00255000"],["115486.31000000","0.04537000"],["115486.79000000","0.01692000"],["115487.33000000","0.00000000"],["115487.34000000","0.02998000"],["115488.00000000","0.06260000"],["115488.75000000","0.00000000"],["115488.78000000","0.54080000"],["115488.85000000","0.08658000"],["115489.86000000","0.00000000"],["115490.23000000","0.00000000"],["115491.12000000","0.00000000"],["115491.41000000","0.00000000"],["115491.85000000","0.00000000"],["115495.37000000","0.00432000"],["115499.65000000","0.00000000"],["115503.07000000","0.00000000"],["115506.08000000","0.04370000"],["115506.23000000","0.31166000"],["115507.36000000","0.00000000"],["115509.24000000","0.00000000"],["115511.12000000","0.00000000"],["115513.43000000","0.43607000"],["115523.20000000","0.00000000"],["115534.12000000","0.57944000"],["115534.13000000","0.25978000"],["115535.77000000","0.04284000"],["115557.00000000","0.00000000"],["115557.02000000","0.00000000"],["115557.53000000","0.00000000"],["115557.78000000","0.00000000"],["115560.62000000","0.13215000"],["115569.98000000","0.11892000"],["115878.02000000","0.37961000"],["116337.03000000","0.00000000"],["116371.59000000","0.00008000"],["117210.97000000","0.00100000"]]}
[2025-10-27T18:48:56.230Z] {"e":"depthUpdate","E":1761590936014,"s":"BTCUSDT","U":79129624618,"u":79129624819,"b":[["115478.77000000","6.26312000"],["115478.76000000","0.00062000"],["115478.60000000","0.00000000"],["115478.13000000","0.10347000"],["115477.62000000","0.00110000"],["115477.29000000","0.28695000"],["115476.59000000","0.00010000"],["115476.58000000","0.04920000"],["115476.17000000","0.04414000"],["115475.89000000","0.00201000"],["115474.34000000","0.00005000"],["115474.33000000","0.03821000"],["115474.16000000","0.00346000"],["115473.28000000","0.00005000"],["115473.27000000","0.17429000"],["115472.96000000","0.17322000"],["115472.28000000","0.00250000"],["115471.98000000","0.00005000"],["115471.85000000","0.00530000"],["115471.47000000","0.24942000"],["115471.46000000","0.00697000"],["115470.55000000","0.01734000"],["115469.74000000","0.00100000"],["115468.30000000","1.10006000"],["115467.66000000","0.00250000"],["115465.00000000","0.06000000"],["115464.99000000","0.00000000"],["115464.98000000","0.02599000"],["115463.77000000","0.00000000"],["115460.34000000","0.15809000"],["115456.28000000","0.31180000"],["115455.70000000","0.00000000"],["115454.11000000","0.00000000"],["115454.10000000","0.00000000"],["115452.89000000","0.00000000"],["115452.88000000","0.08658000"],["115439.96000000","0.00000000"],["115382.32000000","1.05864000"],["115374.29000000","0.03025000"],["115270.50000000","0.01356000"],["115263.88000000","0.00000000"],["113746.58000000","0.00413000"],["103930.00000000","0.00010000"],["92383.02000000","0.00021000"],["92383.00000000","0.00000000"]],"a":[["115478.78000000","4.76233000"],["115478.79000000","0.00060000"],["115479.52000000","0.00000000"],["115479.58000000","0.03824000"],["115479.84000000","0.00010000"],["115479.85000000","0.28585000"],["115480.00000000","0.01887000"],["115481.28000000","0.00000000"],["115481.29000000","0.00000000"],["115481.34000000","0.00000000"],["115481.35000000","0.00000000"],["115481.51000000","0.04023000"],["115482.05000000","0.00000000"],["115486.00000000","0.00170000"],["115486.79000000","0.01697000"],["115487.34000000","0.03003000"],["115487.99000000","0.00005000"],["115488.00000000","0.06265000"],["115490.23000000","0.00182000"],["115491.66000000","0.00000000"],["115492.07000000","0.25985000"],["115501.68000000","0.00000000"],["115502.73000000","0.00000000"],["115503.63000000","0.00005000"],["115513.43000000","0.86921000"],["115529.74000000","0.00000000"],["115538.53000000","0.25985000"],["115556.97000000","0.00000000"],["115556.99000000","0.00000000"],["115557.14000000","0.12032000"],["115557.16000000","0.00000000"],["115557.86000000","0.00000000"],["115566.05000000","0.00000000"],["115566.06000000","0.00000000"],["115567.53000000","0.00100000"],["115567.54000000","0.00100000"],["115571.24000000","0.00000000"],["115573.19000000","0.03400000"],["115578.76000000","0.00000000"],["115580.71000000","0.02500000"],["117210.97000000","0.00100000"]]}
[2025-10-27T18:48:57.146Z] {"e":"depthUpdate","E":1761590937014,"s":"BTCUSDT","U":79129624820,"u":79129624912,"b":[["115478.77000000","6.47428000"],["115478.76000000","0.00067000"],["115473.27000000","0.17429000"],["115473.26000000","0.00000000"],["115472.96000000","0.17322000"],["115472.71000000","0.17324000"],["115471.47000000","0.24942000"],["115455.68000000","0.00761000"],["115323.73000000","0.06760000"],["115321.46000000","0.00000000"],["115243.85000000","0.00000000"],["115234.45000000","4.69621000"],["115156.57000000","0.00077000"],["115156.56000000","0.21709000"],["113746.58000000","0.00413000"],["103930.00000000","0.00010000"],["92383.03000000","0.00000000"],["92383.02000000","0.00021000"],["50000.00000000","39.61327000"],["42000.00000000","1.36431000"],["33000.00000000","3.79030000"]],"a":[["115478.78000000","4.65285000"],["115490.23000000","0.00504000"],["115500.52000000","0.00000000"],["115511.12000000","0.65803000"],["115513.43000000","1.21572000"],["115517.66000000","0.31162000"],["115521.36000000","0.00000000"],["115521.46000000","0.00000000"],["115521.48000000","0.06507000"],["115556.91000000","0.00000000"],["115556.98000000","0.00000000"],["115557.02000000","0.00000000"],["115557.08000000","0.00005000"],["115557.09000000","0.00000000"],["115557.14000000","0.02338000"],["115560.62000000","0.00000000"],["115874.21000000","0.37961000"],["115878.02000000","0.00000000"],["117210.97000000","0.00100000"]]}
[2025-10-27T18:48:58.163Z] {"e":"depthUpdate","E":1761590938014,"s":"BTCUSDT","U":79129624913,"u":79129625037,"b":[["115478.77000000","6.60058000"],["115478.76000000","0.00062000"],["115478.26000000","0.00000000"],["115478.25000000","0.00000000"],["115478.13000000","0.10347000"],["115477.29000000","0.28695000"],["115476.17000000","0.04414000"],["115475.89000000","0.00196000"],["115474.34000000","0.00000000"],["115474.33000000","0.00000000"],["115473.28000000","0.00005000"],["115471.47000000","0.24947000"],["115468.30000000","0.60189000"],["115467.66000000","0.00260000"],["115467.24000000","0.00000000"],["115467.23000000","0.00693000"],["115465.01000000","0.00437000"],["115455.68000000","0.01490000"],["115283.98000000","0.02078000"],["115257.25000000","0.00000000"],["115156.57000000","0.00000000"],["114486.97000000","0.00251000"],["113746.59000000","0.00077000"],["113746.58000000","0.00413000"],["111984.75000000","0.02167000"],["111977.37000000","0.00000000"],["109214.41000000","0.00190000"],["103930.00000000","0.00010000"],["92383.02000000","0.00021000"],["60000.00000000","57.97732000"],["50000.00000000","39.61267000"]],"a":[["115478.78000000","4.68478000"],["115490.23000000","0.00192000"],["115513.43000000","0.86921000"],["115556.90000000","0.00000000"],["115557.04000000","0.34651000"],["115557.34000000","0.00000000"],["115566.53000000","0.00100000"],["115566.54000000","0.00100000"],["115567.53000000","0.00000000"],["115567.54000000","0.00000000"],["116612.76000000","0.00246000"],["117210.97000000","0.00100000"]]}
[2025-10-27T18:48:59.150Z] {"e":"depthUpdate","E":1761590939014,"s":"BTCUSDT","U":79129625038,"u":79129625186,"b":[["115478.77000000","6.60057000"],["115478.76000000","0.00057000"],["115478.72000000","0.00000000"],["115477.62000000","0.00105000"],["115477.29000000","0.28695000"],["115476.59000000","0.00000000"],["115476.58000000","0.00000000"],["115475.93000000","0.04910000"],["115474.16000000","0.00351000"],["115473.28000000","0.00010000"],["115473.27000000","0.17434000"],["115472.97000000","0.00005000"],["115472.71000000","0.17324000"],["115472.39000000","0.00697000"],["115471.85000000","0.00525000"],["115471.47000000","0.24947000"],["115471.46000000","0.00005000"],["115465.01000000","0.00437000"],["115461.45000000","0.15959000"],["115460.34000000","0.00000000"],["115460.33000000","0.25985000"],["115456.52000000","0.95809000"],["115455.68000000","0.01570000"],["115285.95000000","0.00000000"],["115277.20000000","0.00307000"],["114486.98000000","0.00077000"],["113746.59000000","0.00000000"],["113746.58000000","0.00413000"],["106240.48000000","0.00000000"],["103930.00000000","0.00010000"],["92383.02000000","0.00021000"],["92383.00000000","0.00000000"]],"a":[["115478.78000000","4.64517000"],["115478.79000000","0.00065000"],["115479.58000000","0.03824000"],["115479.77000000","0.28575000"],["115479.84000000","0.00000000"],["115479.85000000","0.00000000"],["115480.00000000","0.01892000"],["115481.50000000","0.00010000"],["115481.51000000","0.04023000"],["115482.05000000","0.00005000"],["115482.06000000","0.00005000"],["115484.57000000","0.00155000"],["115485.29000000","0.04537000"],["115485.70000000","0.00524000"],["115486.00000000","0.00165000"],["115486.31000000","0.00000000"],["115487.34000000","0.02998000"],["115488.00000000","0.06260000"],["115489.60000000","0.00000000"],["115490.23000000","0.00495000"],["115493.77000000","0.00000000"],["115499.99000000","0.17308000"],["115501.84000000","0.31166000"],["115504.89000000","0.00000000"],["115511.12000000","0.39946000"],["115513.43000000","0.43607000"],["115517.66000000","0.00000000"],["115556.91000000","0.00000000"],["115556.93000000","0.00000000"],["115556.97000000","0.00000000"],["115557.03000000","0.29721000"],["115557.08000000","0.43319000"],["115566.05000000","0.00100000"],["115566.06000000","0.00100000"],["115566.53000000","0.00000000"],["115566.54000000","0.00000000"],["115571.24000000","0.03400000"],["115573.19000000","0.00000000"],["115777.82000000","0.00311000"],["115786.61000000","0.00000000"],["116045.21000000","0.00082000"],["116054.01000000","0.00000000"],["117210.97000000","0.00100000"]]}
[2025-10-27T18:49:00.193Z] {"e":"depthUpdate","E":1761590940014,"s":"BTCUSDT","U":79129625187,"u":79129625341,"b":[["115478.77000000","6.59603000"],["115478.76000000","0.00062000"],["115478.72000000","0.00000000"],["115478.71000000","0.00000000"],["115478.13000000","0.10347000"],["115477.29000000","0.28695000"],["115476.17000000","0.04419000"],["115475.94000000","0.00010000"],["115475.93000000","0.04920000"],["115473.28000000","0.00005000"],["115473.27000000","0.17429000"],["115472.97000000","0.00000000"],["115471.85000000","0.00520000"],["115471.47000000","0.24942000"],["115467.66000000","0.00255000"],["115467.23000000","0.00698000"],["115465.01000000","0.00432000"],["115454.17000000","0.00000000"],["115439.90000000","0.00865000"],["115270.50000000","0.00000000"],["115256.29000000","0.01356000"],["114487.00000000","0.00077000"],["114486.99000000","0.00000000"],["114486.98000000","0.00000000"],["114486.97000000","0.00000000"],["113746.59000000","0.00000000"],["113746.58000000","0.00413000"],["103930.00000000","0.00010000"],["92383.02000000","0.00021000"]],"a":[["115478.78000000","4.69436000"],["115478.79000000","0.00065000"],["115479.58000000","0.03824000"],["115479.76000000","0.00010000"],["115479.77000000","0.28585000"],["115480.00000000","0.01887000"],["115481.50000000","0.00000000"],["115481.51000000","0.04023000"],["115482.05000000","0.00000000"],["115482.06000000","0.00000000"],["115487.34000000","0.03003000"],["115488.00000000","0.06265000"],["115492.30000000","0.07029000"],["115499.88000000","0.00000000"],["115501.84000000","0.00000000"],["115513.43000000","0.43607000"],["115515.45000000","0.00865000"],["115518.53000000","0.31162000"],["115557.01000000","0.00000000"],["115557.03000000","0.16792000"],["115557.08000000","0.00005000"],["115557.19000000","0.43314000"],["115560.74000000","0.12684000"],["115566.05000000","0.00000000"],["115566.06000000","0.00000000"],["115566.53000000","0.00100000"],["115566.54000000","0.00100000"],["115571.24000000","0.00000000"],["115572.19000000","0.00000000"],["115573.19000000","0.03400000"],["115740.19000000","0.00000000"],["115863.10000000","0.00000000"],["116612.76000000","0.00000000"],["117210.97000000","0.00100000"]]}
[2025-10-27T18:49:01.148Z] {"e":"depthUpdate","E":1761590941014,"s":"BTCUSDT","U":79129625342,"u":79129625538,"b":[["115478.77000000","5.92308000"],["115478.76000000","0.00887000"],["115478.13000000","0.15342000"],["115477.62000000","0.00105000"],["115477.49000000","0.00000000"],["115477.29000000","0.28695000"],["115476.66000000","0.00000000"],["115476.65000000","0.00000000"],["115475.93000000","0.00005000"],["115475.89000000","0.00201000"],["115475.50000000","0.00000000"],["115475.49000000","0.00000000"],["115474.51000000","0.00005000"],["115474.50000000","0.00005000"],["115474.35000000","0.00000000"],["115474.16000000","0.00351000"],["115473.28000000","0.00000000"],["115473.27000000","0.14597000"],["115473.07000000","0.08659000"],["115472.71000000","0.17319000"],["115472.39000000","0.00000000"],["115472.14000000","0.04910000"],["115471.47000000","0.00000000"],["115471.46000000","0.00000000"],["115471.06000000","0.24942000"],["115470.55000000","0.00000000"],["115470.30000000","0.00000000"],["115467.23000000","0.00698000"],["115463.55000000","0.00000000"],["115461.37000000","0.00000000"],["115456.28000000","0.00000000"],["115439.90000000","0.00000000"],["115439.07000000","0.31183000"],["115434.74000000","0.00000000"],["115425.01000000","0.00000000"],["115424.48000000","0.00000000"],["115421.98000000","0.31700000"],["115413.40000000","0.00865000"],["115394.96000000","0.03025000"],["115374.29000000","0.00000000"],["114487.03000000","0.00000000"],["114487.02000000","0.00000000"],["114487.01000000","0.00000000"],["114487.00000000","0.00000000"],["113746.59000000","0.00077000"],["113746.58000000","0.00413000"],["103930.00000000","0.00010000"],["92383.02000000","0.00021000"],["33000.00000000","3.79030000"]],"a":[["115478.78000000","4.77233000"],["115479.42000000","0.50015000"],["115481.15000000","0.00000000"],["115482.02000000","0.04532000"],["115485.01000000","0.00038000"],["115485.29000000","0.00005000"],["115485.32000000","0.00036000"],["115485.65000000","0.00000000"],["115486.50000000","0.00000000"],["115490.01000000","0.00000000"],["115490.09000000","0.00000000"],["115490.23000000","0.00200000"],["115490.86000000","0.00038000"],["115490.99000000","0.00032000"],["115495.12000000","0.00035000"],["115495.19000000","0.00000000"],["115495.25000000","0.00000000"],["115495.77000000","0.00033000"],["115499.03000000","0.00033000"],["115500.02000000","0.00000000"],["115500.30000000","0.00000000"],["115500.93000000","0.31167000"],["115501.33000000","0.00037000"],["115504.89000000","0.04121000"],["115505.96000000","0.00032000"],["115506.08000000","0.00000000"],["115506.73000000","0.00035000"],["115511.12000000","0.60696000"],["115513.43000000","1.21572000"],["115515.00000000","0.00000000"],["115515.45000000","0.00000000"],["115518.53000000","0.00000000"],["115557.03000000","0.16792000"],["115557.04000000","0.00000000"],["115557.19000000","0.00000000"],["115566.53000000","0.00000000"],["115566.54000000","0.00000000"],["117210.97000000","0.00100000"]]}
[2025-10-27T18:49:02.151Z] {"e":"depthUpdate","E":1761590942014,"s":"BTCUSDT","U":79129625539,"u":79129625859,"b":[["115478.77000000","5.99982000"],["115478.76000000","0.00892000"],["115478.13000000","0.12515000"],["115477.62000000","0.00110000"],["115477.29000000","0.28695000"],["115476.80000000","0.00010000"],["115476.79000000","0.00005000"],["115476.68000000","0.03839000"],["115476.17000000","0.04414000"],["115475.94000000","0.00000000"],["115475.93000000","0.00000000"],["115475.89000000","0.00201000"],["115474.89000000","0.00010000"],["115474.88000000","0.15123000"],["115474.87000000","0.04920000"],["115474.51000000","0.00000000"],["115474.50000000","0.03938000"],["115474.21000000","0.00000000"],["115474.16000000","0.00351000"],["115473.43000000","0.08664000"],["115473.28000000","0.00000000"],["115473.27000000","0.00000000"],["115473.08000000","0.00000000"],["115473.07000000","0.00000000"],["115473.05000000","0.17318000"],["115472.96000000","0.00000000"],["115472.71000000","0.00000000"],["115472.28000000","0.00255000"],["115472.27000000","0.08659000"],["115472.14000000","0.00000000"],["115471.85000000","0.00525000"],["115471.06000000","0.00000000"],["115470.30000000","0.01747000"],["115469.74000000","0.00105000"],["115469.34000000","0.00692000"],["115469.31000000","0.24942000"],["115468.30000000","0.44048000"],["115468.29000000","0.00000000"],["115468.28000000","0.00000000"],["115467.23000000","0.00693000"],["115465.01000000","0.00432000"],["115465.00000000","0.06000000"],["115464.98000000","0.02599000"],["115462.92000000","0.42145000"],["115460.07000000","0.00000000"],["115459.06000000","0.54080000"],["115456.52000000","0.00000000"],["115455.68000000","0.01597000"],["115452.88000000","0.00000000"],["115450.78000000","0.00000000"],["115450.77000000","0.08659000"],["115363.35000000","0.00000000"],["115312.51000000","0.07019000"],["113746.58000000","0.00413000"],["111984.75000000","0.00000000"],["111977.37000000","0.02168000"],["103930.00000000","0.00010000"],["92383.02000000","0.00021000"],["92383.00000000","0.00000000"]],"a":[["115478.78000000","4.69806000"],["115478.79000000","0.00065000"],["115481.51000000","0.04023000"],["115482.00000000","0.00160000"],["115482.02000000","0.00000000"],["115484.57000000","0.00155000"],["115484.90000000","0.04537000"],["115485.29000000","0.00000000"],["115487.34000000","0.03003000"],["115490.23000000","0.00479000"],["115491.82000000","0.14721000"],["115500.93000000","0.00000000"],["115513.43000000","0.43607000"],["115518.62000000","0.31162000"],["115541.95000000","0.00865000"],["115556.87000000","0.00000000"],["115556.90000000","0.00000000"],["115556.95000000","0.00000000"],["115557.03000000","0.00000000"],["115557.04000000","0.34651000"],["115557.14000000","0.11874000"],["115557.62000000","0.00000000"],["115566.05000000","0.00100000"],["115566.06000000","0.00100000"],["115610.91000000","0.06000000"],["115870.41000000","0.37961000"],["115874.21000000","0.00000000"],["117210.97000000","0.00100000"]]}
[2025-10-27T18:49:03.148Z] {"e":"depthUpdate","E":1761590943014,"s":"BTCUSDT","U":79129625860,"u":79129626050,"b":[["115478.77000000","6.09514000"],["115478.76000000","0.00897000"],["115478.07000000","0.00000000"],["115477.62000000","0.00110000"],["115477.29000000","0.28690000"],["115476.80000000","0.00000000"],["115476.79000000","0.00000000"],["115476.69000000","0.00010000"],["115476.68000000","0.03810000"],["115474.88000000","0.24780000"],["115474.87000000","0.04915000"],["115474.50000000","0.00000000"],["115473.43000000","0.08664000"],["115473.25000000","0.17323000"],["115473.05000000","0.17318000"],["115469.74000000","0.00100000"],["115469.34000000","0.00000000"],["115469.31000000","0.00000000"],["115468.96000000","0.00386000"],["115468.62000000","0.00000000"],["115467.23000000","0.00693000"],["115463.77000000","0.15809000"],["115461.45000000","0.00150000"],["115456.41000000","0.96380000"],["115456.17000000","0.00000000"],["115455.01000000","0.00865000"],["115450.77000000","0.00000000"],["115439.07000000","0.00000000"],["115438.54000000","0.31184000"],["115434.75000000","0.01566000"],["115413.40000000","0.00000000"],["115394.96000000","0.00000000"],["115388.30000000","0.01356000"],["115381.21000000","0.03025000"],["115365.67000000","0.00000000"],["115305.76000000","0.16802000"],["115234.45000000","0.00000000"],["113746.58000000","0.00413000"],["103930.00000000","0.00010000"],["92383.02000000","0.00021000"]],"a":[["115478.78000000","2.68933000"],["115478.79000000","0.00070000"],["115479.77000000","0.00010000"],["115480.00000000","0.01887000"],["115480.72000000","0.00005000"],["115480.73000000","0.29228000"],["115482.11000000","0.28574000"],["115486.79000000","0.01692000"],["115487.99000000","0.00000000"],["115490.23000000","0.00000000"],["115502.32000000","0.43307000"],["115503.43000000","0.43314000"],["115504.13000000","0.34651000"],["115506.23000000","0.00000000"],["115511.12000000","0.39946000"],["115513.43000000","0.00300000"],["115522.50000000","0.33315000"],["115523.53000000","0.00000000"],["115524.04000000","0.31161000"],["115530.66000000","0.33250000"],["115541.95000000","0.00000000"],["115557.03000000","0.00000000"],["115557.13000000","0.43314000"],["115557.14000000","0.02338000"],["115557.21000000","0.00000000"],["115560.07000000","0.45550000"],["115571.24000000","0.03400000"],["115573.19000000","0.00000000"],["115870.41000000","0.37961000"],["116964.00000000","2.65066000"],["117210.97000000","0.00100000"]]}
[2025-10-27T18:49:04.216Z] {"e":"depthUpdate","E":1761590944014,"s":"BTCUSDT","U":79129626051,"u":79129626268,"b":[["115478.77000000","6.19661000"],["115478.76000000","0.00922000"],["115478.75000000","0.05030000"],["115478.70000000","0.05019000"],["115478.57000000","0.00010000"],["115478.56000000","0.03824000"],["115478.32000000","0.00000000"],["115478.13000000","0.12495000"],["115477.62000000","0.00105000"],["115477.29000000","0.28685000"],["115476.68000000","0.03810000"],["115476.17000000","0.04409000"],["115475.89000000","0.00196000"],["115474.89000000","0.00000000"],["115474.88000000","0.17521000"],["115474.87000000","0.00000000"],["115473.43000000","0.08659000"],["115473.25000000","0.17318000"],["115471.11000000","0.25634000"],["115469.92000000","0.00000000"],["115468.96000000","0.00381000"],["115468.58000000","0.00000000"],["115467.23000000","0.00693000"],["115462.58000000","0.54580000"],["115461.99000000","0.00000000"],["115451.20000000","0.00000000"],["115451.17000000","0.08659000"],["115444.07000000","0.00000000"],["115444.04000000","0.25978000"],["115421.98000000","0.31518000"],["115400.22000000","0.25978000"],["115398.67000000","0.00000000"],["115300.01000000","0.16618000"],["115232.91000000","4.84569000"],["115178.77000000","0.00000000"],["113746.58000000","0.00413000"],["106240.48000000","0.00010000"],["103930.00000000","0.00010000"],["92383.02000000","0.00021000"],["41572.36000000","0.00075000"]],"a":[["115478.78000000","2.04987000"],["115478.79000000","0.00065000"],["115479.58000000","0.03819000"],["115479.76000000","0.00000000"],["115479.77000000","0.00000000"],["115480.00000000","0.01887000"],["115480.72000000","0.00000000"],["115480.73000000","0.00000000"],["115481.50000000","0.00010000"],["115481.51000000","0.04023000"],["115482.10000000","0.00005000"],["115482.11000000","0.28579000"],["115483.12000000","0.29227000"],["115484.57000000","0.00150000"],["115484.90000000","0.00000000"],["115486.79000000","0.01697000"],["115488.00000000","0.00165000"],["115489.04000000","0.04532000"],["115490.23000000","0.00230000"],["115491.16000000","0.00000000"],["115491.52000000","0.00069000"],["115491.56000000","0.00000000"],["115500.31000000","0.00865000"],["115522.50000000","0.48842000"],["115527.67000000","0.00000000"],["115533.94000000","0.25978000"],["115534.13000000","0.00000000"],["115536.92000000","0.00048000"],["115536.93000000","0.00008000"],["115552.10000000","0.01356000"],["115557.03000000","0.46435000"],["115652.01000000","0.00019000"],["115652.02000000","0.00000000"],["117210.97000000","0.00100000"]]}
[2025-10-27T18:49:05.156Z] {"e":"depthUpdate","E":1761590945014,"s":"BTCUSDT","U":79129626269,"u":79129627186,"b":[["115478.77000000","6.45857000"],["115478.76000000","0.00867000"],["115478.75000000","0.05035000"],["115478.70000000","0.05024000"],["115478.57000000","0.00000000"],["115478.14000000","0.00000000"],["115478.13000000","0.19273000"],["115477.62000000","0.00110000"],["115477.30000000","0.00000000"],["115477.00000000","0.04000000"],["115476.90000000","0.00250000"],["115476.69000000","0.00000000"],["115476.68000000","0.03815000"],["115476.34000000","0.24947000"],["115476.32000000","0.00702000"],["115476.22000000","0.06748000"],["115476.18000000","0.00000000"],["115476.17000000","0.04404000"],["115475.97000000","0.00100000"],["115474.88000000","1.02606000"],["115474.16000000","0.00356000"],["115473.83000000","0.00000000"],["115473.48000000","0.00100000"],["115473.27000000","2.47832000"],["115473.26000000","0.54080000"],["115472.29000000","0.00000000"],["115471.59000000","0.00000000"],["115471.11000000","0.00000000"],["115470.64000000","0.00009000"],["115470.27000000","0.00009000"],["115470.16000000","0.00000000"],["115470.10000000","0.21657000"],["115470.05000000","0.00018000"],["115469.74000000","0.00005000"],["115469.63000000","0.00009000"],["115469.36000000","0.00009000"],["115468.97000000","0.00432000"],["115468.30000000","1.33013000"],["115468.24000000","0.00000000"],["115467.87000000","0.00000000"],["115467.66000000","0.00250000"],["115467.65000000","0.00000000"],["115467.23000000","2.48525000"],["115467.00000000","0.25985000"],["115466.96000000","0.00000000"],["115466.73000000","0.25985000"],["115466.50000000","0.54080000"],["115466.06000000","0.00000000"],["115465.04000000","0.00000000"],["115465.01000000","0.00000000"],["115464.98000000","0.00000000"],["115464.90000000","0.02599000"],["115464.77000000","0.00000000"],["115464.67000000","0.00000000"],["115464.45000000","0.00000000"],["115464.04000000","0.04772000"],["115464.03000000","0.00000000"],["115463.93000000","0.00000000"],["115463.76000000","0.09486000"],["115462.92000000","1.45656000"],["115462.91000000","0.09158000"],["115462.46000000","0.00000000"],["115462.41000000","0.00000000"],["115462.24000000","0.07000000"],["115462.00000000","0.00000000"],["115461.70000000","0.31177000"],["115461.53000000","0.04000000"],["115461.44000000","0.00000000"],["115461.41000000","2.47832000"],["115460.54000000","0.00000000"],["115460.33000000","0.00000000"],["115459.93000000","0.06000000"],["115459.85000000","0.00000000"],["115458.38000000","0.00583000"],["115458.35000000","0.00000000"],["115458.24000000","0.34651000"],["115457.09000000","0.00000000"],["115456.94000000","0.00000000"],["115456.80000000","0.31179000"],["115456.64000000","0.00000000"],["115455.68000000","0.00000000"],["115455.63000000","0.43314000"],["115455.28000000","0.43307000"],["115455.25000000","0.00000000"],["115454.45000000","0.14725000"],["115454.41000000","0.00000000"],["115454.28000000","0.00000000"],["115453.80000000","0.00000000"],["115451.17000000","0.00000000"],["115450.02000000","0.00000000"],["115449.32000000","0.00000000"],["115448.12000000","0.24000000"],["115444.13000000","0.46119000"],["115444.12000000","0.51963000"],["115444.04000000","0.00000000"],["115443.87000000","0.00000000"],["115443.55000000","0.00000000"],["115443.32000000","0.00000000"],["115442.87000000","0.00000000"],["115438.54000000","0.00000000"],["115436.54000000","0.14735000"],["115434.61000000","0.00000000"],["115428.69000000","0.00000000"],["115423.11000000","0.03025000"],["115422.25000000","0.00000000"],["115420.80000000","0.25985000"],["115418.09000000","0.25699000"],["115413.86000000","0.00000000"],["115413.68000000","0.00000000"],["115412.15000000","0.02243000"],["115409.22000000","0.00000000"],["115402.63000000","0.00000000"],["115401.76000000","0.00000000"],["115400.73000000","0.00000000"],["115400.38000000","0.00000000"],["115400.22000000","0.00000000"],["115400.06000000","0.00000000"],["115399.81000000","0.00000000"],["115399.78000000","0.00000000"],["115399.75000000","0.00000000"],["115399.19000000","0.00000000"],["115397.88000000","0.00000000"],["115397.53000000","0.43307000"],["115396.27000000","0.34651000"],["115396.10000000","0.00000000"],["115395.48000000","0.00000000"],["115395.42000000","0.02813000"],["115391.61000000","0.13080000"],["115383.31000000","0.00000000"],["115382.23000000","0.00000000"],["115381.21000000","0.00000000"],["115377.02000000","0.46862000"],["115376.87000000","0.05649000"],["115376.86000000","0.00000000"],["115370.77000000","0.00000000"],["115370.76000000","0.00000000"],["115363.94000000","0.00000000"],["115363.84000000","0.00000000"],["115363.06000000","0.07511000"],["115360.67000000","0.00000000"],["115360.11000000","0.00000000"],["115357.34000000","0.09389000"],["115356.05000000","0.00051000"],["115341.73000000","0.00173000"],["115338.63000000","0.04597000"],["115327.74000000","0.00000000"],["115323.73000000","0.04517000"],["115323.72000000","0.00000000"],["115316.22000000","0.00000000"],["115243.03000000","0.00000000"],["115193.07000000","0.02498000"],["115178.77000000","0.00000000"],["115178.27000000","0.00000000"],["115176.55000000","0.00077000"],["115176.54000000","0.00250000"],["115150.91000000","0.02398000"],["115148.69000000","0.02398000"],["115136.78000000","0.03098000"],["115136.51000000","0.03098000"],["115136.35000000","0.03098000"],["115100.53000000","0.00000000"],["115049.89000000","0.00000000"],["115049.79000000","0.00000000"],["115043.99000000","0.00000000"],["115043.73000000","0.00000000"],["115042.50000000","0.00000000"],["115033.80000000","0.03298000"],["115033.26000000","0.03298000"],["115031.59000000","0.03298000"],["115031.05000000","0.03298000"],["115029.97000000","0.03298000"],["115017.03000000","0.00000000"],["114940.78000000","0.00000000"],["114938.46000000","0.00000000"],["114937.60000000","0.00000000"],["114937.50000000","0.00005000"],["114937.45000000","0.00000000"],["114936.73000000","0.00000000"],["114934.84000000","0.00000000"],["114933.60000000","0.00000000"],["113746.59000000","0.00000000"],["113746.58000000","0.00413000"],["106240.48000000","0.00000000"],["103930.00000000","0.00010000"],["92383.02000000","0.00021000"],["92383.00000000","0.00000000"],["42000.00000000","1.36531000"]],"a":[["115478.78000000","0.33907000"],["115478.79000000","0.00085000"],["115478.80000000","0.00000000"],["115479.17000000","0.00000000"],["115479.40000000","0.00000000"],["115479.41000000","0.00030000"],["115479.42000000","0.50015000"],["115479.57000000","0.00000000"],["115479.58000000","0.00000000"],["115479.93000000","0.00100000"],["115480.00000000","0.01887000"],["115481.14000000","0.00000000"],["115481.38000000","0.00000000"],["115481.50000000","0.00000000"],["115481.51000000","0.00000000"],["115482.10000000","0.00000000"],["115482.11000000","0.00000000"],["115482.37000000","0.00000000"],["115482.80000000","0.00000000"],["115483.06000000","0.00000000"],["115483.12000000","0.00000000"],["115484.55000000","0.00000000"],["115484.56000000","0.00000000"],["115485.68000000","0.00000000"],["115485.69000000","0.00000000"],["115485.70000000","0.00524000"],["115486.00000000","0.00160000"],["115486.14000000","0.00000000"],["115486.24000000","0.00000000"],["115486.37000000","0.00010000"],["115486.38000000","0.03993000"],["115486.79000000","0.00000000"],["115487.33000000","0.00010000"],["115487.34000000","0.03013000"],["115488.00000000","0.00165000"],["115488.59000000","0.06386000"],["115488.75000000","0.00000000"],["115488.76000000","0.00000000"],["115488.77000000","0.00008000"],["115488.78000000","0.00000000"],["115488.85000000","0.00000000"],["115488.97000000","0.00000000"],["115489.04000000","0.00000000"],["115489.09000000","0.00000000"],["115489.15000000","0.00000000"],["115489.19000000","0.00000000"],["115489.26000000","0.00155000"],["115489.69000000","0.00000000"],["115489.70000000","0.00000000"],["115489.89000000","0.00000000"],["115490.00000000","0.00165000"],["115490.23000000","0.00000000"],["115490.32000000","0.00698000"],["115490.65000000","0.00000000"],["115490.69000000","0.00000000"],["115490.76000000","0.00000000"],["115491.10000000","0.00000000"],["115491.17000000","0.00010000"],["115491.18000000","0.20221000"],["115491.19000000","0.28572000"],["115491.33000000","0.03300000"],["115491.34000000","0.00005000"],["115491.72000000","0.00070000"],["115491.82000000","0.00000000"],["115492.07000000","0.00000000"],["115492.23000000","0.00100000"],["115492.30000000","0.00000000"],["115492.50000000","0.00000000"],["115492.61000000","0.00000000"],["115492.87000000","0.00000000"],["115493.20000000","0.36887000"],["115493.21000000","0.00000000"],["115493.22000000","0.00000000"],["115493.62000000","0.00000000"],["115493.70000000","0.00000000"],["115494.08000000","0.00000000"],["115494.42000000","0.00070000"],["115494.47000000","0.04398000"],["115494.50000000","0.00000000"],["115494.65000000","0.00000000"],["115494.87000000","0.00000000"],["115495.10000000","0.00000000"],["115495.22000000","0.00000000"],["115495.32000000","0.00000000"],["115495.37000000","0.00000000"],["115495.54000000","0.00338000"],["115495.90000000","0.00000000"],["115496.11000000","0.08659000"],["115496.50000000","0.00000000"],["115496.62000000","0.00000000"],["115497.04000000","0.54080000"],["115497.05000000","0.29217000"],["115497.20000000","0.00000000"],["115497.71000000","0.04000000"],["115497.99000000","0.00000000"],["115498.31000000","0.14725000"],["115498.88000000","0.04532000"],["115499.67000000","0.00000000"],["115499.68000000","0.00000000"],["115499.99000000","0.00312000"],["115500.20000000","0.24000000"],["115500.31000000","0.00000000"],["115500.50000000","0.00000000"],["115500.72000000","0.63785000"],["115500.73000000","0.00000000"],["115500.98000000","0.00432000"],["115500.99000000","0.54080000"],["115501.00000000","0.00000000"],["115501.01000000","0.00000000"],["115501.45000000","0.00000000"],["115501.55000000","0.25978000"],["115501.82000000","0.00248000"],["115501.94000000","0.00000000"],["115501.99000000","0.00000000"],["115502.38000000","0.00000000"],["115503.07000000","0.00000000"],["115503.08000000","0.00000000"],["115503.22000000","0.07029000"],["115503.74000000","0.25985000"],["115504.38000000","0.00000000"],["115504.87000000","1.27830000"],["115504.88000000","0.71076000"],["115504.89000000","2.77938000"],["115504.90000000","0.00000000"],["115505.04000000","0.00000000"],["115505.63000000","0.00000000"],["115505.92000000","0.00865000"],["115506.79000000","0.00000000"],["115506.80000000","0.00000000"],["115508.21000000","0.00000000"],["115508.83000000","0.00100000"],["115509.24000000","0.00250000"],["115509.34000000","0.54080000"],["115509.69000000","0.00000000"],["115511.00000000","0.00000000"],["115511.01000000","1.00227000"],["115511.02000000","2.47832000"],["115511.12000000","0.00000000"],["115511.13000000","0.00000000"],["115513.42000000","0.04342000"],["115513.86000000","0.00250000"],["115516.04000000","0.00000000"],["115518.57000000","0.31162000"],["115518.62000000","0.00000000"],["115518.82000000","0.14721000"],["115520.22000000","0.00000000"],["115521.48000000","0.00000000"],["115523.51000000","0.00000000"],["115523.91000000","0.00000000"],["115525.01000000","0.00000000"],["115525.58000000","0.00000000"],["115525.96000000","0.00000000"],["115526.30000000","0.00000000"],["115526.41000000","0.00000000"],["115526.49000000","0.00449000"],["115527.11000000","0.00012000"],["115527.12000000","0.20189000"],["115528.81000000","0.31159000"],["115529.64000000","0.00000000"],["115532.99000000","0.31158000"],["115535.19000000","0.00000000"],["115536.35000000","0.46797000"],["115536.90000000","0.00048000"],["115536.91000000","0.00000000"],["115536.92000000","0.00000000"],["115538.53000000","0.00000000"],["115543.31000000","0.00000000"],["115543.35000000","0.03234000"],["115544.36000000","0.00500000"],["115551.09000000","0.25985000"],["115552.37000000","0.03446000"],["115559.87000000","0.54080000"],["115560.74000000","0.00000000"],["115564.47000000","0.00000000"],["115564.49000000","0.54080000"],["115564.84000000","0.00000000"],["115566.05000000","0.00000000"],["115566.06000000","0.00000000"],["115567.47000000","0.00000000"],["115567.54000000","0.00000000"],["115567.55000000","0.00000000"],["115568.54000000","0.00000000"],["115568.55000000","0.00000000"],["115570.29000000","0.00000000"],["115571.24000000","0.00000000"],["115573.19000000","0.00000000"],["115574.19000000","0.00000000"],["115575.14000000","0.00000000"],["115576.14000000","0.03400000"],["115579.17000000","0.00432000"],["115580.71000000","0.00000000"],["115581.71000000","0.00000000"],["115582.66000000","0.00000000"],["115583.66000000","0.02500000"],["115592.85000000","0.00000000"],["115595.85000000","0.00000000"],["115597.44000000","0.00000000"],["115598.41000000","0.00000000"],["115600.22000000","0.00000000"],["115601.36000000","0.00000000"],["115608.48000000","2.47832000"],["115619.97000000","0.99058000"],["115619.98000000","2.47832000"],["115619.99000000","0.00000000"],["115633.25000000","0.04597000"],["115634.94000000","0.04597000"],["115638.39000000","0.04597000"],["115640.44000000","0.04597000"],["115641.72000000","0.04597000"],["115643.44000000","0.04597000"],["115644.71000000","0.04597000"],["115651.99000000","0.00019000"],["115652.00000000","0.00008000"],["115652.01000000","0.00000000"],["115691.99000000","0.00000000"],["115702.26000000","0.00000000"],["115758.10000000","0.00000000"],["115760.69000000","0.00000000"],["115761.94000000","0.00000000"],["115767.30000000","0.00000000"],["115770.03000000","0.02298000"],["115771.31000000","0.00000000"],["115773.14000000","0.00000000"],["115773.67000000","0.00000000"],["115776.04000000","0.00000000"],["115776.95000000","0.00000000"],["115777.07000000","0.02298000"],["115777.43000000","0.00000000"],["115782.34000000","0.02498000"],["115782.94000000","0.02498000"],["115783.29000000","0.02298000"],["115786.67000000","0.02298000"],["115789.60000000","0.02298000"],["115793.26000000","0.02298000"],["115793.60000000","0.02498000"],["115796.11000000","0.02298000"],["115799.78000000","0.02298000"],["115806.25000000","0.02298000"],["115814.09000000","0.00000000"],["115815.06000000","0.00000000"],["115815.62000000","0.00000000"],["115816.64000000","0.00000000"],["115817.23000000","0.00000000"],["115840.08000000","0.02398000"],["115840.74000000","0.02398000"],["115841.55000000","0.02398000"],["115850.56000000","0.02398000"],["115851.33000000","0.02398000"],["115869.60000000","0.00000000"],["115869.95000000","0.00000000"],["115870.41000000","0.00000000"],["115881.82000000","0.37961000"],["115885.60000000","0.00000000"],["115902.80000000","0.03098000"],["115904.27000000","0.03098000"],["115918.49000000","0.03298000"],["115923.47000000","0.00000000"],["115925.73000000","0.00000000"],["115926.46000000","0.00000000"],["115928.97000000","0.00000000"],["115954.37000000","0.02498000"],["117210.97000000","0.00100000"]]}
[2025-10-27T18:49:06.162Z] {"e":"depthUpdate","E":1761590946014,"s":"BTCUSDT","U":79129627187,"u":79129627366,"b":[["115478.77000000","6.48774000"],["115478.56000000","0.03829000"],["115478.36000000","0.00005000"],["115477.62000000","0.00115000"],["115477.29000000","0.28685000"],["115477.00000000","0.04005000"],["115476.68000000","0.03810000"],["115476.34000000","0.00000000"],["115476.32000000","0.00005000"],["115472.26000000","0.03463000"],["115469.00000000","0.00005000"],["115465.72000000","0.04357000"],["115464.04000000","0.00000000"],["115462.91000000","0.00500000"],["115462.43000000","0.00865000"],["115458.98000000","0.08658000"],["115458.38000000","0.00000000"],["115455.68000000","0.04329000"],["115455.01000000","0.00000000"],["115450.84000000","0.00583000"],["115444.13000000","0.00008000"],["115444.12000000","0.25985000"],["115430.31000000","0.06494000"],["115400.56000000","0.00000000"],["115397.53000000","0.00000000"],["115397.19000000","0.00000000"],["115386.93000000","0.86661000"],["115319.14000000","0.06000000"],["115300.00000000","0.50185000"],["115290.08000000","0.00000000"],["115246.85000000","4.81838000"],["115232.91000000","0.00000000"],["115201.19000000","0.00000000"],["115200.00000000","0.13267000"],["115022.04000000","0.02498000"],["113746.58000000","0.00413000"],["113131.19000000","0.00000000"],["111992.12000000","0.02167000"],["111977.37000000","0.00000000"],["103930.00000000","0.00010000"],["92383.02000000","0.00021000"]],"a":[["115478.78000000","0.22313000"],["115478.79000000","0.00080000"],["115478.86000000","0.00009000"],["115479.07000000","0.00000000"],["115487.34000000","0.03013000"],["115488.58000000","0.00010000"],["115488.59000000","0.00391000"],["115490.32000000","0.00693000"],["115490.69000000","0.00000000"],["115491.18000000","0.00000000"],["115491.19000000","0.00000000"],["115491.35000000","0.00000000"],["115491.61000000","0.29219000"],["115493.20000000","0.00000000"],["115493.76000000","0.00000000"],["115497.05000000","0.00000000"],["115498.46000000","0.00000000"],["115499.40000000","0.00000000"],["115499.43000000","0.07029000"],["115500.10000000","0.06000000"],["115500.72000000","0.00000000"],["115501.82000000","0.00260000"],["115501.88000000","0.21957000"],["115503.18000000","0.00000000"],["115503.22000000","0.00000000"],["115503.29000000","0.00000000"],["115503.53000000","0.04200000"],["115504.78000000","0.03900000"],["115509.33000000","0.00000000"],["115513.42000000","0.00008000"],["115518.57000000","0.00000000"],["115526.83000000","0.00000000"],["115527.23000000","0.00000000"],["115537.22000000","0.31157000"],["115544.36000000","0.00000000"],["115546.54000000","0.00450000"],["115552.10000000","0.00000000"],["115566.14000000","0.01356000"],["115566.89000000","0.13012000"],["115568.05000000","0.00000000"],["115568.06000000","0.00000000"],["115590.15000000","0.00000000"],["115598.29000000","0.00000000"],["115821.46000000","0.00000000"],["115822.78000000","0.00000000"],["115849.22000000","0.02398000"],["115881.82000000","0.00000000"],["115889.43000000","0.37961000"],["115971.49000000","0.31500000"],["117210.97000000","0.00100000"],["120000.00000000","179.73764000"]]}
[2025-10-27T18:49:07.173Z] {"e":"depthUpdate","E":1761590947014,"s":"BTCUSDT","U":79129627367,"u":79129632675,"b":[["115500.28000000","8.94988000"],["115500.27000000","0.15821000"],["115500.26000000","0.00017000"],["115500.20000000","0.00000000"],["115500.19000000","0.00000000"],["115500.18000000","0.00000000"],["115500.09000000","0.00000000"],["115500.08000000","0.00000000"],["115500.01000000","0.21110000"],["115500.00000000","0.28590000"],["115499.99000000","0.08898000"],["115499.98000000","0.00000000"],["115499.97000000","0.00000000"],["115499.21000000","0.01775000"],["115498.97000000","0.00000000"],["115498.88000000","0.00000000"],["115498.87000000","0.00000000"],["115498.33000000","0.00005000"],["115498.32000000","0.00000000"],["115498.30000000","0.00000000"],["115498.23000000","0.00000000"],["115498.20000000","0.00000000"],["115498.19000000","0.00000000"],["115498.16000000","0.00000000"],["115498.09000000","0.00005000"],["115497.83000000","0.00000000"],["115497.82000000","0.00000000"],["115497.70000000","0.00000000"],["115497.11000000","0.04413000"],["115497.05000000","0.00000000"],["115497.04000000","0.00000000"],["115497.03000000","0.00000000"],["115496.87000000","0.00000000"],["115496.76000000","0.06753000"],["115496.62000000","0.00000000"],["115496.54000000","0.00000000"],["115496.53000000","0.00000000"],["115496.52000000","0.00000000"],["115496.42000000","0.00000000"],["115496.10000000","0.00000000"],["115495.90000000","0.00000000"],["115495.84000000","0.00000000"],["115495.64000000","0.00005000"],["115495.53000000","0.00000000"],["115495.38000000","0.00255000"],["115495.37000000","0.00000000"],["115495.18000000","0.00005000"],["115495.14000000","0.00000000"],["115495.12000000","0.00000000"],["115495.11000000","0.00000000"],["115494.65000000","0.00000000"],["115494.61000000","0.00000000"],["115494.46000000","0.00000000"],["115494.36000000","0.00000000"],["115493.99000000","0.00000000"],["115493.78000000","0.00000000"],["115493.14000000","0.25639000"],["115492.56000000","0.00000000"],["115492.55000000","0.00437000"],["115492.54000000","0.00000000"],["115492.52000000","0.00010000"],["115492.51000000","0.03460000"],["115492.48000000","0.00000000"],["115492.46000000","0.00000000"],["115492.45000000","0.00000000"],["115492.43000000","0.00000000"],["115492.42000000","0.00000000"],["115492.32000000","0.00005000"],["115492.22000000","0.00000000"],["115491.99000000","0.00000000"],["115491.60000000","0.00000000"],["115491.42000000","0.00000000"],["115491.38000000","0.00000000"],["115491.33000000","1.55462000"],["115491.32000000","0.00000000"],["115491.16000000","0.00000000"],["115490.85000000","0.00000000"],["115490.76000000","0.00250000"],["115490.31000000","0.00000000"],["115490.07000000","0.00000000"],["115489.99000000","0.00000000"],["115489.35000000","0.00000000"],["115489.25000000","0.00000000"],["115488.79000000","0.00000000"],["115488.78000000","2.47832000"],["115488.77000000","0.54080000"],["115488.76000000","0.57478000"],["115488.63000000","0.21657000"],["115488.61000000","0.00000000"],["115488.59000000","0.08824000"],["115488.58000000","1.87856000"],["115488.57000000","0.00000000"],["115488.38000000","0.00500000"],["115488.25000000","0.00009000"],["115488.02000000","0.00000000"],["115487.99000000","0.00510000"],["115487.88000000","0.00009000"],["115487.87000000","0.00000000"],["115487.66000000","0.00018000"],["115487.45000000","0.00000000"],["115487.35000000","0.09159000"],["115487.33000000","0.00000000"],["115487.32000000","0.00000000"],["115487.24000000","0.00009000"],["115486.99000000","0.00000000"],["115486.97000000","0.00009000"],["115486.55000000","0.00005000"],["115486.54000000","0.00000000"],["115486.45000000","0.00000000"],["115486.42000000","0.00000000"],["115486.40000000","0.00000000"],["115486.38000000","0.00000000"],["115486.37000000","0.00000000"],["115486.36000000","0.00000000"],["115486.35000000","0.00005000"],["115486.14000000","0.00750000"],["115486.13000000","0.00000000"],["115486.00000000","0.58564000"],["115485.99000000","0.25985000"],["115485.85000000","0.00009000"],["115485.72000000","0.00000000"],["115485.70000000","0.00000000"],["115485.69000000","0.00000000"],["115485.61000000","0.00000000"],["115485.60000000","0.00000000"],["115485.22000000","0.00000000"],["115485.20000000","0.00000000"],["115485.19000000","0.00000000"],["115485.10000000","0.00042000"],["115484.69000000","0.00000000"],["115484.67000000","0.00000000"],["115484.66000000","0.00005000"],["115484.59000000","0.00000000"],["115484.58000000","0.00000000"],["115484.57000000","0.15806000"],["115484.56000000","0.04000000"],["115484.41000000","0.00000000"],["115484.15000000","0.00000000"],["115484.02000000","0.00000000"],["115484.00000000","0.54080000"],["115483.99000000","0.04000000"],["115483.41000000","0.00000000"],["115483.39000000","0.00000000"],["115483.38000000","0.04000000"],["115483.35000000","0.00000000"],["115483.30000000","0.00000000"],["115483.21000000","0.04024000"],["115482.98000000","0.00000000"],["115482.76000000","0.00000000"],["115482.67000000","0.00107000"],["115482.65000000","0.00086000"],["115482.58000000","0.60537000"],["115482.57000000","0.00000000"],["115482.55000000","0.00000000"],["115482.54000000","0.03995000"],["115482.53000000","0.00000000"],["115482.35000000","0.00000000"],["115482.34000000","0.00000000"],["115482.30000000","0.07000000"],["115482.07000000","0.00000000"],["115482.02000000","0.00000000"],["115482.00000000","0.26991000"],["115481.99000000","0.03995000"],["115481.65000000","0.00000000"],["115481.54000000","0.00000000"],["115481.52000000","0.00250000"],["115481.51000000","0.00000000"],["115481.28000000","0.00000000"],["115481.27000000","0.00000000"],["115481.13000000","0.04977000"],["115481.06000000","0.00000000"],["115480.95000000","0.00000000"],["115480.78000000","0.00005000"],["115480.77000000","0.00000000"],["115480.66000000","0.00041000"],["115480.63000000","0.00000000"],["115480.49000000","0.00000000"],["115480.40000000","0.00100000"],["115480.37000000","0.00865000"],["115480.07000000","0.00009000"],["115480.02000000","0.00000000"],["115480.01000000","0.98434000"],["115480.00000000","0.54085000"],["115479.99000000","0.00000000"],["115479.98000000","0.00000000"],["115479.95000000","0.00000000"],["115479.94000000","0.00000000"],["115479.92000000","0.03995000"],["115479.65000000","0.00000000"],["115479.58000000","0.14725000"],["115479.44000000","0.00000000"],["115479.43000000","0.00000000"],["115479.42000000","2.47832000"],["115479.41000000","0.21311000"],["115479.40000000","0.00000000"],["115479.07000000","0.03000000"],["115479.03000000","0.03000000"],["115479.01000000","0.00000000"],["115479.00000000","0.00000000"],["115478.99000000","0.00000000"],["115478.85000000","0.00000000"],["115478.80000000","0.00000000"],["115478.78000000","0.00000000"],["115478.77000000","0.04013000"],["115478.76000000","0.00795000"],["115478.75000000","0.00000000"],["115478.70000000","0.00000000"],["115478.56000000","0.00000000"],["115478.50000000","0.00000000"],["115478.36000000","0.00000000"],["115478.14000000","0.00000000"],["115478.13000000","0.00000000"],["115478.09000000","0.00000000"],["115477.94000000","0.03000000"],["115477.93000000","0.03600000"],["115477.88000000","0.03000000"],["115477.87000000","0.00007000"],["115477.85000000","0.03000000"],["115477.70000000","0.00000000"],["115477.62000000","0.00095000"],["115477.32000000","0.00005000"],["115477.29000000","0.00000000"],["115477.05000000","0.04000000"],["115477.01000000","0.00000000"],["115477.00000000","0.00000000"],["115476.87000000","0.00000000"],["115476.85000000","0.00000000"],["115476.68000000","0.00000000"],["115476.54000000","0.00000000"],["115476.48000000","0.14726000"],["115476.32000000","0.00000000"],["115476.22000000","0.00000000"],["115476.17000000","0.00000000"],["115475.97000000","0.00000000"],["115475.89000000","0.00191000"],["115475.39000000","0.00000000"],["115475.34000000","0.00005000"],["115474.89000000","0.22087000"],["115474.86000000","0.00000000"],["115474.70000000","0.00000000"],["115474.62000000","0.00000000"],["115474.52000000","0.00000000"],["115474.28000000","0.00005000"],["115474.16000000","0.00355000"],["115474.11000000","0.31174000"],["115474.04000000","0.00005000"],["115473.90000000","0.03000000"],["115473.85000000","0.00583000"],["115473.77000000","0.00000000"],["115473.64000000","0.00000000"],["115473.48000000","0.00000000"],["115473.43000000","0.00000000"],["115473.05000000","0.00000000"],["115473.02000000","0.00693000"],["115472.70000000","0.00000000"],["115472.54000000","0.00000000"],["115472.50000000","0.00000000"],["115472.28000000","0.00000000"],["115472.27000000","0.00000000"],["115472.26000000","0.00000000"],["115472.17000000","0.03300000"],["115472.09000000","0.25978000"],["115472.07000000","0.03000000"],["115471.98000000","0.00000000"],["115471.85000000","0.00520000"],["115471.83000000","0.00000000"],["115471.58000000","0.00005000"],["115471.53000000","0.30000000"],["115471.42000000","0.00000000"],["115471.26000000","0.00000000"],["115470.85000000","0.08717000"],["115470.79000000","0.00000000"],["115470.64000000","0.00000000"],["115470.41000000","0.00000000"],["115470.30000000","0.00000000"],["115470.27000000","0.00000000"],["115470.18000000","0.00000000"],["115470.10000000","0.00000000"],["115470.05000000","0.00000000"],["115469.74000000","0.00000000"],["115469.63000000","0.00000000"],["115469.53000000","0.00000000"],["115469.36000000","0.00000000"],["115469.00000000","0.00000000"],["115468.97000000","0.00041000"],["115468.95000000","0.00009000"],["115468.30000000","1.64189000"],["115467.95000000","0.00000000"],["115467.66000000","0.00000000"],["115467.28000000","0.04597000"],["115467.27000000","0.03000000"],["115467.00000000","0.00000000"],["115466.73000000","0.00000000"],["115466.49000000","0.00000000"],["115466.06000000","0.00086000"],["115466.04000000","0.03000000"],["115465.74000000","0.00000000"],["115465.72000000","0.00000000"],["115465.42000000","0.93143000"],["115463.77000000","0.00000000"],["115463.76000000","0.00000000"],["115463.30000000","0.00447000"],["115463.04000000","0.00000000"],["115462.91000000","0.00000000"],["115462.88000000","0.00021000"],["115462.87000000","0.00000000"],["115462.61000000","0.00276000"],["115462.58000000","0.54080000"],["115462.43000000","0.00000000"],["115462.28000000","0.00000000"],["115462.24000000","0.00000000"],["115462.01000000","0.00000000"],["115461.62000000","0.05727000"],["115461.53000000","0.00000000"],["115461.45000000","0.00000000"],["115461.20000000","0.24740000"],["115461.19000000","0.00000000"],["115461.14000000","0.50270000"],["115460.28000000","0.14721000"],["115460.07000000","0.00012000"],["115459.97000000","0.00000000"],["115459.93000000","0.00000000"],["115459.75000000","0.14721000"],["115459.55000000","0.00086000"],["115459.39000000","0.00000000"],["115458.98000000","0.00000000"],["115458.78000000","0.03683000"],["115458.42000000","0.00000000"],["115458.24000000","0.00000000"],["115458.14000000","0.17689000"],["115458.10000000","0.00000000"],["115457.90000000","0.00000000"],["115456.93000000","0.00000000"],["115456.85000000","0.00000000"],["115456.74000000","0.00000000"],["115456.41000000","0.00000000"],["115456.01000000","0.02298000"],["115455.79000000","0.00000000"],["115455.68000000","0.00000000"],["115455.63000000","0.00000000"],["115455.28000000","0.00000000"],["115454.55000000","0.00000000"],["115454.37000000","0.00000000"],["115452.92000000","0.08795000"],["115452.91000000","0.00000000"],["115452.79000000","0.00000000"],["115451.58000000","0.00000000"],["115451.10000000","0.00005000"],["115450.84000000","0.00000000"],["115450.18000000","0.08000000"],["115449.93000000","0.00000000"],["115449.50000000","0.00000000"],["115449.42000000","0.00000000"],["115448.49000000","0.77880000"],["115448.45000000","0.00000000"],["115448.12000000","0.00000000"],["115447.91000000","0.00000000"],["115447.86000000","0.00000000"],["115446.67000000","0.02498000"],["115446.27000000","0.00000000"],["115444.14000000","0.18968000"],["115444.13000000","0.04341000"],["115444.12000000","0.00000000"],["115443.51000000","0.00000000"],["115442.97000000","0.00086000"],["115442.11000000","0.00000000"],["115440.44000000","0.00000000"],["115440.39000000","0.00000000"],["115439.80000000","0.00000000"],["115439.69000000","0.00000000"],["115439.00000000","0.00000000"],["115438.63000000","0.04206000"],["115438.23000000","0.00000000"],["115437.72000000","0.25985000"],["115436.68000000","0.00000000"],["115436.03000000","0.01299000"],["115435.30000000","0.25985000"],["115434.62000000","0.00000000"],["115433.58000000","0.00000000"],["115433.32000000","0.00000000"],["115432.01000000","0.02424000"],["115432.00000000","0.00140000"],["115431.89000000","1.13480000"],["115431.88000000","0.00000000"],["115431.74000000","0.00000000"],["115431.34000000","0.00000000"],["115430.25000000","0.01299000"],["115430.00000000","0.00140000"],["115429.67000000","0.04848000"],["115429.63000000","0.22837000"],["115429.22000000","0.00000000"],["115428.85000000","0.00000000"],["115428.00000000","0.00140000"],["115427.82000000","0.00000000"],["115427.74000000","0.00629000"],["115426.81000000","0.00000000"],["115426.00000000","0.00140000"],["115425.53000000","0.00617000"],["115425.43000000","0.00000000"],["115424.83000000","0.02424000"],["115424.01000000","0.02424000"],["115424.00000000","0.00140000"],["115423.12000000","0.02424000"],["115423.11000000","0.00000000"],["115423.08000000","0.00000000"],["115422.72000000","0.02158000"],["115422.59000000","0.00000000"],["115422.26000000","0.00005000"],["115422.02000000","1.14077000"],["115421.21000000","0.03025000"],["115420.80000000","0.00000000"],["115419.59000000","0.00000000"],["115419.11000000","0.00000000"],["115418.24000000","0.25978000"],["115417.31000000","0.00618000"],["115416.65000000","0.35717000"],["115416.56000000","0.06949000"],["115415.22000000","0.43312000"],["115415.01000000","0.02813000"],["115414.40000000","0.00000000"],["115412.14000000","0.00380000"],["115412.00000000","0.00140000"],["115411.66000000","0.34651000"],["115411.38000000","1.16040000"],["115410.25000000","0.00000000"],["115410.00000000","0.00160000"],["115408.48000000","0.00008000"],["115408.47000000","0.00000000"],["115408.00000000","0.00160000"],["115407.52000000","0.00000000"],["115407.24000000","0.05063000"],["115406.34000000","0.02995000"],["115406.00000000","0.00160000"],["115405.85000000","0.46850000"],["115405.59000000","1.18047000"],["115405.32000000","0.00000000"],["115405.05000000","0.00000000"],["115405.04000000","0.00000000"],["115404.34000000","0.00000000"],["115404.02000000","0.00000000"],["115404.00000000","0.00160000"],["115402.19000000","0.02198000"],["115402.00000000","0.02498000"],["115401.85000000","0.00000000"],["115400.82000000","0.00000000"],["115400.00000000","0.00165000"],["115399.61000000","0.94575000"],["115399.27000000","0.00000000"],["115398.00000000","0.00160000"],["115397.01000000","0.00008000"],["115396.27000000","0.00000000"],["115396.00000000","0.00160000"],["115395.42000000","0.00000000"],["115394.59000000","0.46855000"],["115394.41000000","0.00000000"],["115394.00000000","0.00160000"],["115393.39000000","0.00000000"],["115393.38000000","1.29712000"],["115393.35000000","0.00000000"],["115392.09000000","0.00000000"],["115392.02000000","0.02454000"],["115391.02000000","0.04024000"],["115391.00000000","0.00114000"],["115390.50000000","0.00005000"],["115390.28000000","0.00000000"],["115389.77000000","0.09389000"],["115386.94000000","0.30522000"],["115386.79000000","0.00000000"],["115384.90000000","0.00000000"],["115383.57000000","0.00000000"],["115383.40000000","0.02498000"],["115382.32000000","0.00000000"],["115381.80000000","0.12037000"],["115377.63000000","0.00000000"],["115377.02000000","0.00000000"],["115376.87000000","0.00000000"],["115375.94000000","0.04086000"],["115375.93000000","0.00000000"],["115372.32000000","0.00000000"],["115371.39000000","0.00000000"],["115369.45000000","0.00000000"],["115368.78000000","0.00000000"],["115368.33000000","0.00000000"],["115367.03000000","0.16252000"],["115364.30000000","0.00000000"],["115363.84000000","0.31362000"],["115362.24000000","0.00000000"],["115362.01000000","0.00000000"],["115361.35000000","0.00000000"],["115360.89000000","0.00216000"],["115359.23000000","0.00000000"],["115359.22000000","0.00000000"],["115358.54000000","0.00000000"],["115358.34000000","0.10059000"],["115358.29000000","0.00000000"],["115356.02000000","0.00000000"],["115354.74000000","0.00000000"],["115354.16000000","0.00000000"],["115354.00000000","0.00160000"],["115351.88000000","0.00000000"],["115350.02000000","0.01484000"],["115350.01000000","0.04779000"],["115349.93000000","0.00000000"],["115347.67000000","0.00000000"],["115346.79000000","0.21080000"],["115346.02000000","0.00000000"],["115342.56000000","0.00000000"],["115342.01000000","0.09194000"],["115340.48000000","0.71339000"],["115336.30000000","0.00000000"],["115335.64000000","0.00000000"],["115332.70000000","0.08692000"],["115329.25000000","0.52252000"],["115328.72000000","0.00000000"],["115324.10000000","0.00897000"],["115323.73000000","0.00000000"],["115323.51000000","0.00000000"],["115322.01000000","0.00000000"],["115320.00000000","0.00583000"],["115319.39000000","0.00307000"],["115319.00000000","0.00000000"],["115315.06000000","0.00000000"],["115312.51000000","0.00000000"],["115310.17000000","0.00000000"],["115307.91000000","0.00000000"],["115305.76000000","0.00000000"],["115305.15000000","0.00000000"],["115303.45000000","0.25337000"],["115300.01000000","0.00000000"],["115297.95000000","0.00000000"],["115296.01000000","0.00074000"],["115290.78000000","0.00000000"],["115290.56000000","0.02298000"],["115277.20000000","0.00000000"],["115275.74000000","0.00000000"],["115263.25000000","0.01213000"],["115262.28000000","0.00000000"],["115257.20000000","0.00000000"],["115246.06000000","0.97195000"],["115245.77000000","0.00000000"],["115235.67000000","0.00000000"],["115233.76000000","0.00000000"],["115226.08000000","0.21922000"],["115220.44000000","0.00000000"],["115202.37000000","0.04996000"],["115202.36000000","0.09992000"],["115197.08000000","0.01731000"],["115196.57000000","0.00000000"],["115196.49000000","0.00000000"],["115196.38000000","0.07494000"],["115196.20000000","0.01731000"],["115191.16000000","0.01731000"],["115189.12000000","0.00007000"],["115187.97000000","0.01731000"],["115184.95000000","0.02299000"],["115180.53000000","0.02298000"],["115178.40000000","0.00000000"],["115163.93000000","0.01660000"],["115163.19000000","0.02338000"],["115156.07000000","0.00000000"],["115153.55000000","0.02399000"],["115153.26000000","0.02399000"],["115152.93000000","0.02399000"],["115152.18000000","0.02399000"],["115151.77000000","0.03098000"],["115151.50000000","0.03098000"],["115151.24000000","0.03098000"],["115151.07000000","0.03098000"],["115150.91000000","0.04797000"],["115150.76000000","0.03098000"],["115150.30000000","0.00000000"],["115150.15000000","0.03098000"],["115149.75000000","0.03098000"],["115149.67000000","0.02399000"],["115149.37000000","0.02399000"],["115148.76000000","0.02399000"],["115147.40000000","0.00000000"],["115147.38000000","0.02398000"],["115147.05000000","0.02414000"],["115144.08000000","0.02337000"],["115143.23000000","0.03098000"],["115143.22000000","0.02337000"],["115142.96000000","0.03098000"],["115142.79000000","0.03213000"],["115142.44000000","0.02337000"],["115142.41000000","0.01645000"],["115141.91000000","0.00000000"],["115140.32000000","0.02338000"],["115138.70000000","0.02338000"],["115136.44000000","0.02338000"],["115134.88000000","0.02338000"],["115133.32000000","0.02338000"],["115132.54000000","0.02338000"],["115131.87000000","0.02338000"],["115131.32000000","0.02338000"],["115130.10000000","0.00000000"],["115123.93000000","0.00000000"],["115109.65000000","0.00000000"],["115109.63000000","0.00000000"],["115107.60000000","0.00000000"],["115106.53000000","0.00000000"],["115105.52000000","0.00000000"],["115105.26000000","0.00000000"],["115103.24000000","0.00000000"],["115102.62000000","0.00000000"],["115101.17000000","0.00000000"],["115099.44000000","0.02338000"],["115087.74000000","0.00000000"],["115087.34000000","0.00000000"],["115086.82000000","0.00000000"],["115084.78000000","0.00000000"],["115083.01000000","0.00000000"],["115080.06000000","0.00000000"],["115078.24000000","0.02337000"],["115075.85000000","0.02337000"],["115074.56000000","0.02337000"],["115073.40000000","0.02337000"],["115072.39000000","0.02337000"],["115069.51000000","0.02338000"],["115068.55000000","0.00000000"],["115065.57000000","0.02338000"],["115063.02000000","0.02338000"],["115057.56000000","0.00000000"],["115057.54000000","0.00000000"],["115056.86000000","0.00000000"],["115056.59000000","0.00000000"],["115056.46000000","0.00000000"],["115055.80000000","0.00000000"],["115055.75000000","0.00000000"],["115055.70000000","0.00000000"],["115054.30000000","0.00000000"],["115053.53000000","0.00000000"],["115053.16000000","0.00000000"],["115052.40000000","0.00000000"],["115052.27000000","0.00000000"],["115051.59000000","0.00000000"],["115051.33000000","0.00000000"],["115050.64000000","0.00000000"],["115050.53000000","0.00000000"],["115050.17000000","0.00000000"],["115049.61000000","0.00000000"],["115048.86000000","0.00000000"],["115048.02000000","0.00000000"],["115045.03000000","0.03298000"],["115044.90000000","0.03298000"],["115044.36000000","0.03298000"],["115043.73000000","0.03298000"],["115043.48000000","0.00000000"],["115043.18000000","0.03298000"],["115043.12000000","0.00000000"],["115041.33000000","0.00000000"],["115040.10000000","0.02498000"],["115040.05000000","0.00000000"],["115039.42000000","0.02498000"],["115039.32000000","0.00000000"],["115037.21000000","0.03298000"],["115036.56000000","0.03298000"],["115036.16000000","0.00000000"],["115033.66000000","0.00000000"],["115032.88000000","0.00026000"],["115032.09000000","0.00000000"],["115031.23000000","0.00000000"],["115030.37000000","0.00000000"],["115029.92000000","0.00000000"],["115029.59000000","0.00000000"],["115028.20000000","0.00000000"],["115018.95000000","0.00000000"],["115013.17000000","0.00000000"],["115001.62000000","0.00118000"],["114990.07000000","0.00000000"],["114974.10000000","0.00000000"],["114974.09000000","0.00000000"],["114969.76000000","0.00000000"],["114967.01000000","0.00000000"],["114964.27000000","0.00000000"],["114962.36000000","0.00000000"],["114961.02000000","0.00000000"],["114960.76000000","0.00000000"],["114959.90000000","0.00000000"],["114950.81000000","0.00000000"],["114949.90000000","0.00000000"],["114949.32000000","0.00000000"],["114948.83000000","0.00000000"],["114948.80000000","0.00000000"],["114943.82000000","0.00000000"],["114942.85000000","0.00049000"],["114940.92000000","0.00000000"],["114940.69000000","0.00000000"],["114940.02000000","0.00000000"],["114939.23000000","0.00000000"],["114939.07000000","0.00000000"],["114902.60000000","0.00000000"],["114500.00000000","7.40542000"],["113767.76000000","0.00100000"],["113746.58000000","0.00313000"],["113169.19000000","0.00721000"],["103950.00000000","0.00705000"],["103930.00000000","0.00000000"],["92400.23000000","0.00021000"],["92400.22000000","0.00000000"],["92383.02000000","0.00000000"],["42000.00000000","1.36431000"],["33000.00000000","3.79030000"]],"a":[["115478.78000000","0.00000000"],["115478.79000000","0.00000000"],["115478.86000000","0.00000000"],["115479.01000000","0.00000000"],["115479.41000000","0.00000000"],["115479.42000000","0.00000000"],["115479.43000000","0.00000000"],["115479.93000000","0.00000000"],["115479.95000000","0.00000000"],["115479.99000000","0.00000000"],["115480.00000000","0.00000000"],["115480.78000000","0.00000000"],["115480.96000000","0.00000000"],["115481.52000000","0.00000000"],["115481.55000000","0.00000000"],["115481.66000000","0.00000000"],["115482.00000000","0.00000000"],["115482.01000000","0.00000000"],["115482.54000000","0.00000000"],["115482.55000000","0.00000000"],["115483.39000000","0.00000000"],["115483.40000000","0.00000000"],["115483.42000000","0.00000000"],["115484.00000000","0.00000000"],["115484.16000000","0.00000000"],["115484.42000000","0.00000000"],["115484.57000000","0.00000000"],["115485.01000000","0.00000000"],["115485.20000000","0.00000000"],["115485.21000000","0.00000000"],["115485.32000000","0.00000000"],["115485.61000000","0.00000000"],["115485.62000000","0.00000000"],["115485.70000000","0.00000000"],["115485.71000000","0.00000000"],["115486.00000000","0.00000000"],["115486.37000000","0.00000000"],["115486.38000000","0.00000000"],["115486.43000000","0.00000000"],["115486.55000000","0.00000000"],["115487.00000000","0.00000000"],["115487.33000000","0.00000000"],["115487.34000000","0.00000000"],["115487.46000000","0.00000000"],["115487.88000000","0.00000000"],["115488.00000000","0.00000000"],["115488.58000000","0.00000000"],["115488.59000000","0.00000000"],["115488.60000000","0.00000000"],["115488.77000000","0.00000000"],["115488.80000000","0.00000000"],["115489.26000000","0.00000000"],["115489.36000000","0.00000000"],["115490.00000000","0.00000000"],["115490.32000000","0.00000000"],["115490.86000000","0.00000000"],["115490.99000000","0.00000000"],["115491.17000000","0.00000000"],["115491.32000000","0.00000000"],["115491.33000000","0.00000000"],["115491.34000000","0.00000000"],["115491.38000000","0.00000000"],["115491.39000000","0.00000000"],["115491.43000000","0.00000000"],["115491.50000000","0.00000000"],["115491.52000000","0.00000000"],["115491.54000000","0.00000000"],["115491.60000000","0.00000000"],["115491.61000000","0.00000000"],["115491.72000000","0.00000000"],["115491.77000000","0.00000000"],["115492.00000000","0.00000000"],["115492.21000000","0.00000000"],["115492.23000000","0.00000000"],["115492.32000000","0.00000000"],["115492.43000000","0.00000000"],["115492.44000000","0.00000000"],["115492.45000000","0.00000000"],["115492.46000000","0.00000000"],["115492.55000000","0.00000000"],["115492.57000000","0.00000000"],["115493.79000000","0.00000000"],["115494.00000000","0.00000000"],["115494.42000000","0.00000000"],["115494.47000000","0.00000000"],["115494.54000000","0.00000000"],["115494.62000000","0.00000000"],["115494.66000000","0.00000000"],["115494.80000000","0.00000000"],["115494.95000000","0.00000000"],["115495.12000000","0.00000000"],["115495.38000000","0.00000000"],["115495.54000000","0.00000000"],["115495.77000000","0.00000000"],["115495.85000000","0.00000000"],["115495.91000000","0.00000000"],["115496.00000000","0.00000000"],["115496.11000000","0.00000000"],["115496.42000000","0.00000000"],["115496.53000000","0.00000000"],["115497.04000000","0.00000000"],["115497.06000000","0.00000000"],["115497.25000000","0.00000000"],["115497.48000000","0.00000000"],["115497.71000000","0.00000000"],["115497.83000000","0.00000000"],["115498.00000000","0.00000000"],["115498.09000000","0.00000000"],["115498.17000000","0.00000000"],["115498.20000000","0.00000000"],["115498.21000000","0.00000000"],["115498.26000000","0.00000000"],["115498.31000000","0.00000000"],["115498.56000000","0.00000000"],["115498.88000000","0.00000000"],["115499.03000000","0.00000000"],["115499.43000000","0.00000000"],["115499.59000000","0.00000000"],["115499.77000000","0.00000000"],["115499.86000000","0.00000000"],["115499.98000000","0.00000000"],["115499.99000000","0.00000000"],["115500.00000000","0.00000000"],["115500.01000000","0.00000000"],["115500.09000000","0.00000000"],["115500.10000000","0.00000000"],["115500.19000000","0.00000000"],["115500.20000000","0.00000000"],["115500.21000000","0.00000000"],["115500.28000000","0.00000000"],["115500.29000000","1.12355000"],["115500.30000000","0.00165000"],["115500.49000000","0.00000000"],["115500.52000000","0.00017000"],["115500.71000000","0.00000000"],["115500.72000000","0.00000000"],["115500.81000000","0.00000000"],["115500.98000000","0.00000000"],["115500.99000000","0.00000000"],["115501.33000000","0.00057000"],["115501.39000000","0.00000000"],["115501.40000000","0.00000000"],["115501.54000000","0.00000000"],["115501.55000000","0.00000000"],["115501.76000000","0.00005000"],["115501.82000000","0.00010000"],["115501.87000000","0.00000000"],["115501.88000000","0.00305000"],["115502.00000000","0.00165000"],["115502.11000000","0.00000000"],["115502.25000000","0.00000000"],["115502.32000000","0.00000000"],["115502.36000000","0.00000000"],["115502.37000000","0.00000000"],["115502.38000000","0.00000000"],["115502.40000000","0.00000000"],["115502.41000000","0.00000000"],["115502.61000000","0.00000000"],["115502.71000000","0.00021000"],["115502.72000000","0.00000000"],["115502.73000000","0.00000000"],["115502.77000000","0.00000000"],["115502.87000000","0.00000000"],["115502.90000000","0.00000000"],["115503.17000000","0.00000000"],["115503.28000000","0.00000000"],["115503.31000000","0.00000000"],["115503.43000000","0.00000000"],["115503.53000000","0.00005000"],["115503.55000000","0.00000000"],["115503.60000000","0.00000000"],["115503.70000000","0.00000000"],["115503.73000000","0.00000000"],["115503.74000000","0.00000000"],["115503.80000000","0.00000000"],["115504.00000000","0.00160000"],["115504.03000000","0.00000000"],["115504.04000000","0.00000000"],["115504.08000000","0.00000000"],["115504.12000000","0.00000000"],["115504.13000000","0.00000000"],["115504.62000000","0.00000000"],["115504.78000000","0.00000000"],["115504.86000000","0.00000000"],["115504.87000000","0.00000000"],["115504.88000000","0.00000000"],["115504.89000000","0.00000000"],["115504.96000000","0.00000000"],["115505.10000000","0.00000000"],["115505.20000000","0.00000000"],["115505.30000000","0.00005000"],["115505.44000000","0.00000000"],["115505.69000000","0.00000000"],["115505.77000000","0.00000000"],["115505.89000000","0.00000000"],["115505.90000000","0.00000000"],["115505.91000000","0.00150000"],["115505.92000000","0.00005000"],["115506.00000000","0.00170000"],["115506.12000000","0.00010000"],["115506.13000000","0.03988000"],["115506.16000000","0.00000000"],["115506.21000000","0.00000000"],["115506.60000000","0.00000000"],["115506.70000000","0.00000000"],["115507.53000000","0.00000000"],["115507.78000000","0.00000000"],["115507.79000000","0.00000000"],["115507.80000000","0.00000000"],["115508.00000000","0.00165000"],["115508.21000000","0.00000000"],["115508.71000000","0.00000000"],["115508.82000000","0.00000000"],["115508.83000000","0.00000000"],["115508.94000000","0.00000000"],["115509.00000000","0.00000000"],["115509.08000000","0.00000000"],["115509.24000000","0.00005000"],["115509.34000000","0.00000000"],["115509.46000000","0.00010000"],["115509.47000000","0.08550000"],["115509.48000000","0.28577000"],["115509.61000000","0.00005000"],["115509.65000000","0.00000000"],["115509.80000000","0.00000000"],["115509.81000000","0.02010000"],["115509.96000000","0.00000000"],["115510.00000000","0.00165000"],["115510.18000000","0.00033000"],["115510.45000000","0.00000000"],["115510.86000000","0.00000000"],["115510.87000000","0.00000000"],["115510.88000000","0.00044000"],["115510.89000000","0.29220000"],["115511.00000000","0.00005000"],["115511.01000000","0.44331000"],["115511.02000000","0.00000000"],["115511.51000000","0.00000000"],["115511.52000000","0.04408000"],["115511.53000000","0.00155000"],["115511.56000000","0.12131000"],["115511.81000000","0.04010000"],["115511.84000000","0.40159000"],["115512.00000000","0.00174000"],["115512.26000000","0.00000000"],["115512.34000000","0.00000000"],["115512.49000000","0.00000000"],["115512.50000000","0.00000000"],["115512.71000000","0.04000000"],["115512.81000000","0.00000000"],["115512.98000000","0.00000000"],["115513.41000000","0.00276000"],["115513.42000000","0.04342000"],["115513.59000000","0.00000000"],["115513.70000000","0.00000000"],["115513.71000000","0.08000000"],["115513.76000000","0.14725000"],["115513.97000000","0.00069000"],["115514.36000000","0.00069000"],["115514.44000000","0.00034000"],["115514.78000000","0.00000000"],["115514.91000000","0.16000000"],["115514.99000000","0.00070000"],["115515.01000000","0.07396000"],["115515.21000000","0.00000000"],["115515.46000000","0.00000000"],["115515.53000000","0.00332000"],["115515.73000000","1.12677000"],["115515.87000000","0.25978000"],["115515.93000000","0.00037000"],["115516.09000000","0.00000000"],["115516.25000000","0.25985000"],["115516.36000000","0.00000000"],["115516.37000000","0.00000000"],["115516.38000000","0.00000000"],["115517.35000000","0.03300000"],["115517.42000000","0.25985000"],["115517.47000000","0.03900000"],["115517.61000000","0.21657000"],["115517.99000000","0.00000000"],["115518.33000000","0.00000000"],["115518.34000000","0.54080000"],["115518.48000000","0.00250000"],["115518.52000000","0.03000000"],["115518.62000000","0.03900000"],["115518.63000000","0.04500000"],["115518.65000000","0.04757000"],["115519.19000000","0.00000000"],["115519.62000000","0.00000000"],["115519.68000000","0.04200000"],["115519.90000000","0.00995000"],["115520.20000000","0.00039000"],["115520.68000000","0.00000000"],["115520.69000000","0.00000000"],["115520.92000000","0.03900000"],["115521.43000000","0.00037000"],["115522.49000000","0.00000000"],["115522.50000000","0.33315000"],["115522.51000000","0.18784000"],["115522.58000000","0.03600000"],["115523.03000000","0.00000000"],["115523.10000000","0.00250000"],["115523.41000000","0.00000000"],["115523.54000000","0.00000000"],["115524.04000000","0.00000000"],["115524.30000000","0.03000000"],["115525.24000000","0.00000000"],["115525.25000000","0.00000000"],["115525.26000000","0.17428000"],["115525.29000000","0.00000000"],["115525.36000000","0.00000000"],["115525.72000000","0.00032000"],["115525.97000000","0.00005000"],["115527.12000000","0.00000000"],["115527.18000000","0.43307000"],["115527.53000000","0.00000000"],["115527.72000000","0.00250000"],["115527.83000000","0.00000000"],["115527.89000000","0.14726000"],["115527.99000000","0.00000000"],["115528.07000000","0.00000000"],["115528.43000000","0.00000000"],["115528.52000000","0.43314000"],["115528.59000000","0.00000000"],["115528.81000000","0.00000000"],["115528.84000000","0.00000000"],["115529.23000000","0.00000000"],["115529.74000000","0.00583000"],["115529.89000000","0.04328000"],["115530.07000000","0.00000000"],["115530.65000000","0.00000000"],["115530.80000000","0.00995000"],["115531.09000000","0.00000000"],["115531.26000000","0.00000000"],["115531.27000000","0.00145000"],["115531.67000000","0.00000000"],["115531.99000000","0.00000000"],["115532.34000000","0.06998000"],["115532.36000000","0.00000000"],["115532.60000000","0.00000000"],["115532.62000000","0.34651000"],["115532.99000000","0.00000000"],["115533.12000000","0.00000000"],["115533.41000000","0.00274000"],["115533.87000000","0.00000000"],["115534.12000000","0.42371000"],["115535.76000000","0.00000000"],["115535.77000000","0.00000000"],["115535.99000000","0.00000000"],["115536.12000000","0.00000000"],["115536.34000000","0.00000000"],["115536.35000000","0.00000000"],["115536.51000000","0.00000000"],["115536.85000000","0.00000000"],["115536.89000000","0.00000000"],["115536.93000000","0.00000000"],["115536.95000000","0.00000000"],["115537.02000000","0.14719000"],["115537.22000000","0.00000000"],["115537.33000000","0.14725000"],["115537.43000000","0.00000000"],["115537.55000000","0.00000000"],["115538.08000000","0.00000000"],["115538.18000000","0.00000000"],["115538.21000000","0.00000000"],["115538.31000000","0.00000000"],["115538.48000000","0.00005000"],["115538.89000000","0.02849000"],["115538.99000000","0.02995000"],["115539.06000000","0.00173000"],["115539.34000000","0.00000000"],["115539.66000000","0.00000000"],["115539.78000000","0.00005000"],["115539.99000000","0.02338000"],["115540.01000000","0.25144000"],["115540.09000000","0.00000000"],["115540.38000000","0.25122000"],["115540.41000000","0.00000000"],["115540.46000000","0.25140000"],["115540.47000000","0.00000000"],["115540.49000000","0.00000000"],["115540.50000000","0.00000000"],["115541.20000000","0.00000000"],["115541.21000000","0.00000000"],["115541.66000000","0.14768000"],["115541.98000000","0.00126000"],["115542.14000000","0.00000000"],["115542.64000000","0.00000000"],["115543.09000000","0.02298000"],["115543.10000000","0.31155000"],["115543.35000000","0.00000000"],["115543.74000000","0.06612000"],["115543.98000000","0.08000000"],["115544.25000000","0.00005000"],["115544.41000000","0.03298000"],["115544.42000000","0.25351000"],["115544.71000000","0.20251000"],["115544.73000000","0.00000000"],["115545.74000000","0.07994000"],["115545.75000000","0.03683000"],["115546.53000000","0.00008000"],["115546.54000000","0.00000000"],["115546.84000000","0.00000000"],["115547.04000000","0.31154000"],["115547.75000000","0.00126000"],["115547.99000000","0.00000000"],["115549.19000000","0.00000000"],["115549.91000000","0.00000000"],["115550.02000000","0.00005000"],["115550.52000000","0.00000000"],["115550.53000000","0.00000000"],["115550.68000000","0.00000000"],["115551.09000000","0.00000000"],["115552.37000000","0.00000000"],["115552.93000000","0.01731000"],["115553.32000000","0.01645000"],["115553.33000000","0.00000000"],["115553.64000000","0.00000000"],["115553.95000000","0.46790000"],["115553.99000000","0.01731000"],["115555.61000000","0.02337000"],["115555.79000000","0.00005000"],["115555.82000000","0.00000000"],["115556.48000000","0.00000000"],["115557.02000000","0.00216000"],["115557.04000000","0.00000000"],["115557.13000000","0.00000000"],["115557.14000000","0.00000000"],["115557.52000000","0.14726000"],["115557.98000000","0.00008000"],["115557.99000000","0.00000000"],["115558.98000000","0.08000000"],["115561.44000000","0.00000000"],["115562.14000000","0.00360000"],["115563.02000000","0.00625000"],["115563.62000000","0.25985000"],["115565.03000000","0.03446000"],["115565.15000000","0.00619000"],["115565.24000000","0.00000000"],["115565.26000000","0.46786000"],["115565.99000000","0.00000000"],["115566.14000000","0.00000000"],["115566.88000000","0.00216000"],["115566.89000000","0.00000000"],["115568.43000000","0.00616000"],["115569.72000000","0.00000000"],["115569.98000000","0.26403000"],["115569.99000000","0.00000000"],["115570.09000000","0.04809000"],["115571.42000000","0.54080000"],["115571.44000000","0.03234000"],["115571.72000000","0.00006000"],["115571.99000000","0.00000000"],["115572.65000000","0.00000000"],["115575.63000000","0.00000000"],["115575.99000000","0.00000000"],["115576.04000000","0.54080000"],["115576.12000000","0.00000000"],["115576.14000000","0.00000000"],["115576.19000000","0.00000000"],["115576.83000000","0.00000000"],["115577.19000000","0.00000000"],["115577.24000000","0.00000000"],["115577.58000000","0.00000000"],["115579.17000000","0.00000000"],["115579.24000000","0.00000000"],["115579.56000000","0.14227000"],["115579.74000000","0.00000000"],["115580.24000000","0.00000000"],["115581.17000000","0.00000000"],["115581.29000000","0.00000000"],["115581.66000000","0.02177000"],["115582.07000000","0.06917000"],["115582.12000000","0.00000000"],["115583.19000000","0.00006000"],["115583.66000000","0.00000000"],["115584.63000000","0.00000000"],["115584.64000000","0.00000000"],["115584.75000000","0.00000000"],["115585.99000000","0.04848000"],["115586.05000000","0.03000000"],["115587.10000000","1.01219000"],["115587.59000000","0.77004000"],["115589.84000000","0.00000000"],["115589.98000000","0.03000000"],["115590.15000000","0.04200000"],["115590.54000000","0.00000000"],["115590.55000000","0.44365000"],["115590.69000000","0.43314000"],["115591.32000000","0.00432000"],["115591.98000000","0.04848000"],["115593.23000000","0.34651000"],["115594.74000000","0.00000000"],["115594.81000000","0.03900000"],["115595.71000000","0.02424000"],["115595.87000000","0.03000000"],["115595.90000000","0.00864000"],["115595.97000000","0.04500000"],["115596.00000000","0.04060000"],["115596.71000000","0.00432000"],["115596.91000000","0.02424000"],["115597.09000000","0.00000000"],["115598.29000000","0.03900000"],["115598.35000000","0.00499000"],["115598.36000000","0.00000000"],["115598.68000000","0.04013000"],["115598.69000000","0.00111000"],["115599.76000000","0.02454000"],["115599.93000000","0.03600000"],["115599.99000000","0.04848000"],["115600.00000000","0.06383000"],["115600.55000000","0.00000000"],["115601.63000000","0.03000000"],["115602.04000000","0.00499000"],["115602.93000000","0.00000000"],["115603.90000000","0.02424000"],["115604.84000000","0.09668000"],["115605.50000000","0.00000000"],["115606.26000000","0.00000000"],["115608.04000000","0.79570000"],["115608.05000000","0.00000000"],["115609.79000000","0.00000000"],["115609.80000000","0.02424000"],["115610.00000000","0.00000000"],["115612.67000000","0.00000000"],["115613.07000000","0.00844000"],["115613.53000000","0.28351000"],["115613.95000000","0.00000000"],["115614.53000000","0.00000000"],["115614.72000000","0.05192000"],["115614.73000000","0.00000000"],["115615.71000000","0.00000000"],["115616.96000000","0.00000000"],["115617.13000000","0.00000000"],["115617.52000000","0.00000000"],["115617.96000000","0.00000000"],["115619.10000000","0.00000000"],["115620.00000000","0.01830000"],["115620.08000000","0.00000000"],["115621.49000000","0.00000000"],["115623.10000000","0.00000000"],["115624.55000000","0.00000000"],["115631.45000000","0.97119000"],["115631.53000000","2.47832000"],["115635.57000000","0.24034000"],["115638.84000000","0.07511000"],["115640.00000000","0.00119000"],["115644.45000000","0.14946000"],["115646.67000000","0.16280000"],["115647.27000000","0.09389000"],["115651.38000000","0.00000000"],["115654.66000000","0.04597000"],["115654.89000000","0.04597000"],["115655.68000000","0.00000000"],["115655.92000000","0.14925000"],["115655.93000000","0.04597000"],["115655.96000000","0.04597000"],["115656.45000000","0.00000000"],["115657.07000000","0.04597000"],["115658.95000000","0.04597000"],["115661.00000000","0.04597000"],["115661.39000000","0.08591000"],["115661.48000000","0.04597000"],["115662.64000000","0.00000000"],["115663.05000000","0.04598000"],["115664.30000000","0.04597000"],["115664.59000000","0.09196000"],["115665.40000000","0.04597000"],["115666.38000000","0.00086000"],["115666.51000000","0.09158000"],["115666.52000000","0.04597000"],["115666.65000000","0.00000000"],["115666.86000000","0.00000000"],["115668.08000000","0.04597000"],["115668.33000000","0.04597000"],["115669.35000000","0.04597000"],["115670.12000000","0.04597000"],["115671.21000000","0.04597000"],["115671.68000000","0.04597000"],["115672.91000000","0.04597000"],["115674.19000000","0.00086000"],["115676.96000000","0.00000000"],["115677.04000000","0.00000000"],["115688.16000000","0.00000000"],["115690.00000000","0.02466000"],["115690.01000000","0.00000000"],["115691.26000000","0.00000000"],["115693.84000000","0.00000000"],["115695.31000000","0.00000000"],["115696.74000000","0.00000000"],["115698.54000000","0.00005000"],["115699.17000000","0.00000000"],["115699.96000000","0.00000000"],["115700.04000000","0.02599000"],["115701.45000000","0.00000000"],["115710.96000000","0.01361000"],["115724.95000000","0.05195000"],["115726.26000000","0.02597000"],["115726.80000000","0.00865000"],["115728.89000000","0.01731000"],["115730.25000000","0.01731000"],["115733.64000000","0.02597000"],["115737.89000000","0.01731000"],["115745.74000000","0.00000000"],["115758.39000000","0.00000000"],["115764.81000000","0.00000000"],["115772.71000000","0.00000000"],["115776.86000000","0.86369000"],["115777.82000000","0.00000000"],["115780.86000000","0.00000000"],["115780.89000000","0.01731000"],["115783.18000000","0.00000000"],["115783.46000000","0.00000000"],["115783.65000000","0.01731000"],["115783.85000000","0.00000000"],["115783.99000000","0.00000000"],["115784.01000000","0.00000000"],["115784.13000000","0.00000000"],["115784.24000000","0.00000000"],["115784.50000000","0.00000000"],["115784.62000000","0.00000000"],["115784.75000000","0.00000000"],["115784.79000000","0.00000000"],["115784.80000000","0.00000000"],["115785.84000000","0.00000000"],["115786.32000000","0.00000000"],["115789.91000000","0.00000000"],["115795.01000000","0.02498000"],["115796.91000000","0.00000000"],["115799.32000000","0.01731000"],["115800.24000000","0.00000000"],["115800.32000000","0.00000000"],["115801.39000000","0.02498000"],["115802.28000000","0.02498000"],["115802.67000000","0.02498000"],["115803.36000000","0.02498000"],["115803.66000000","0.02538000"],["115804.07000000","0.02498000"],["115804.97000000","0.02498000"],["115805.28000000","0.02498000"],["115805.35000000","0.02498000"],["115805.66000000","0.02498000"],["115806.07000000","0.00000000"],["115806.54000000","0.02498000"],["115806.59000000","0.00000000"],["115806.78000000","0.01731000"],["115806.94000000","0.02498000"],["115807.75000000","0.00000000"],["115808.63000000","0.00000000"],["115809.07000000","0.02507000"],["115809.08000000","0.00000000"],["115811.35000000","0.00007000"],["115815.70000000","0.00000000"],["115815.72000000","0.00009000"],["115815.79000000","0.01731000"],["115816.55000000","0.00000000"],["115818.92000000","0.02298000"],["115820.05000000","0.00000000"],["115820.20000000","0.00311000"],["115821.49000000","0.00009000"],["115822.16000000","0.01731000"],["115822.79000000","0.00000000"],["115823.48000000","0.02298000"],["115827.44000000","0.00009000"],["115830.11000000","0.01731000"],["115831.51000000","0.00000000"],["115831.67000000","0.00000000"],["115833.21000000","0.00009000"],["115835.08000000","0.01731000"],["115835.11000000","0.01731000"],["115836.28000000","0.00000000"],["115837.22000000","0.01645000"],["115838.91000000","0.00000000"],["115839.17000000","0.00000000"],["115839.77000000","0.00009000"],["115840.64000000","0.00000000"],["115840.68000000","0.00000000"],["115840.74000000","0.00000000"],["115841.55000000","0.00000000"],["115842.14000000","0.00000000"],["115843.15000000","0.00000000"],["115843.60000000","0.00009000"],["115845.54000000","0.00000000"],["115846.25000000","0.01645000"],["115848.48000000","0.01645000"],["115848.50000000","0.01645000"],["115849.22000000","0.04796000"],["115849.37000000","0.00000000"],["115854.04000000","0.00000000"],["115854.95000000","0.00000000"],["115855.30000000","0.00000000"],["115855.67000000","0.00000000"],["115856.00000000","0.01731000"],["115856.59000000","0.00000000"],["115856.74000000","0.00000000"],["115857.22000000","0.00000000"],["115857.60000000","0.00000000"],["115858.22000000","0.00000000"],["115858.58000000","0.00000000"],["115859.36000000","0.00000000"],["115859.70000000","0.00000000"],["115860.87000000","0.00000000"],["115861.69000000","0.00000000"],["115861.86000000","0.00000000"],["115863.83000000","0.02398000"],["115863.85000000","0.02398000"],["115864.14000000","0.02398000"],["115864.45000000","0.02398000"],["115864.54000000","0.00000000"],["115864.86000000","0.02398000"],["115865.08000000","0.00000000"],["115865.62000000","0.00000000"],["115865.83000000","0.00000000"],["115866.10000000","0.02398000"],["115866.34000000","0.02338000"],["115867.20000000","0.00000000"],["115868.30000000","0.00000000"],["115869.13000000","0.00000000"],["115869.45000000","0.00000000"],["115871.04000000","0.02338000"],["115873.66000000","0.00000000"],["115876.96000000","0.02337000"],["115877.39000000","0.00000000"],["115877.42000000","0.00000000"],["115878.32000000","0.00000000"],["115879.10000000","0.02337000"],["115884.43000000","0.00000000"],["115885.03000000","0.00000000"],["115892.97000000","0.00000000"],["115893.59000000","0.00000000"],["115893.65000000","0.00000000"],["115895.89000000","0.00000000"],["115896.68000000","0.00000000"],["115897.45000000","0.00000000"],["115897.77000000","0.03098000"],["115897.86000000","0.00000000"],["115898.50000000","0.00000000"],["115898.73000000","0.00000000"],["115898.75000000","0.03098000"],["115898.79000000","0.03098000"],["115899.48000000","0.00000000"],["115899.54000000","0.03098000"],["115899.69000000","0.03098000"],["115899.98000000","0.03115000"],["115900.17000000","0.03098000"],["115909.25000000","0.02378000"],["115911.30000000","0.04676000"],["115912.31000000","0.04676000"],["115913.81000000","0.03098000"],["115923.27000000","0.02337000"],["115926.18000000","0.03298000"],["115927.26000000","0.03298000"],["115927.36000000","0.03298000"],["115927.85000000","0.00000000"],["115928.38000000","0.00000000"],["115928.47000000","0.00000000"],["115929.01000000","0.03298000"],["115929.07000000","0.03298000"],["115929.46000000","0.03298000"],["115929.51000000","0.03298000"],["115929.75000000","0.00000000"],["115932.37000000","1.19998000"],["115934.75000000","0.03298000"],["115935.87000000","0.03298000"],["115937.37000000","0.03298000"],["115947.85000000","0.00000000"],["115948.50000000","0.00000000"],["116023.55000000","0.00000000"],["116045.21000000","0.00000000"],["116057.40000000","0.00005000"],["116087.63000000","0.00082000"],["116089.02000000","0.54998000"],["116425.77000000","0.00000000"],["117210.97000000","0.00000000"],["117232.80000000","0.00113000"]]}
[2025-10-27T18:49:08.151Z] {"e":"depthUpdate","E":1761590948014,"s":"BTCUSDT","U":79129632676,"u":79129633067,"b":[["115500.28000000","9.06653000"],["115500.27000000","0.08928000"],["115499.99000000","0.08903000"],["115499.98000000","0.00250000"],["115499.21000000","0.01775000"],["115498.44000000","0.24947000"],["115496.76000000","0.06753000"],["115496.21000000","0.00692000"],["115495.38000000","0.00260000"],["115493.95000000","0.00261000"],["115493.43000000","0.00100000"],["115493.14000000","0.00000000"],["115490.76000000","0.00260000"],["115488.73000000","0.12492000"],["115488.72000000","0.00300000"],["115488.61000000","0.08657000"],["115488.58000000","1.61871000"],["115486.14000000","0.00755000"],["115486.00000000","0.86437000"],["115484.82000000","0.98798000"],["115484.66000000","0.00000000"],["115484.56000000","0.03995000"],["115483.99000000","0.03995000"],["115483.38000000","0.03995000"],["115483.21000000","0.00000000"],["115480.96000000","0.00005000"],["115480.37000000","0.00000000"],["115480.01000000","1.42104000"],["115479.96000000","0.00006000"],["115479.41000000","0.03995000"],["115478.77000000","1.05937000"],["115478.44000000","0.25985000"],["115477.68000000","0.00865000"],["115476.90000000","0.00000000"],["115476.81000000","0.03000000"],["115475.58000000","0.03000000"],["115474.48000000","0.03000000"],["115473.85000000","0.00000000"],["115473.33000000","0.03000000"],["115473.25000000","0.00000000"],["115472.19000000","0.03000000"],["115472.00000000","0.00120000"],["115470.93000000","0.00583000"],["115470.83000000","0.00000000"],["115470.00000000","0.00120000"],["115469.14000000","0.00005000"],["115468.00000000","0.00120000"],["115467.27000000","0.00000000"],["115467.22000000","0.31800000"],["115466.04000000","0.00000000"],["115466.00000000","0.00120000"],["115465.63000000","0.00008000"],["115465.42000000","0.00000000"],["115464.00000000","0.00120000"],["115462.00000000","0.00120000"],["115461.01000000","0.33250000"],["115460.00000000","0.00125000"],["115458.00000000","0.00120000"],["115456.00000000","0.04449000"],["115454.00000000","0.00120000"],["115453.46000000","0.00000000"],["115452.30000000","0.00000000"],["115452.00000000","0.00120000"],["115451.15000000","0.00000000"],["115451.14000000","0.00000000"],["115450.68000000","0.00000000"],["115447.61000000","0.00000000"],["115447.25000000","0.00000000"],["115447.04000000","0.06632000"],["115444.13000000","0.00000000"],["115439.50000000","0.03025000"],["115436.35000000","0.31500000"],["115434.92000000","0.00000000"],["115430.98000000","0.00008000"],["115430.31000000","0.00000000"],["115426.01000000","0.00008000"],["115422.00000000","0.00140000"],["115421.21000000","0.00000000"],["115420.00000000","0.00140000"],["115418.00000000","0.00140000"],["115416.65000000","0.57873000"],["115416.00000000","0.00140000"],["115414.30000000","0.00008000"],["115414.01000000","0.43314000"],["115414.00000000","0.00140000"],["115412.00000000","0.00160000"],["115409.48000000","0.00000000"],["115408.48000000","0.00000000"],["115405.81000000","0.03000000"],["115398.78000000","0.03000000"],["115397.01000000","0.00000000"],["115397.00000000","0.00000000"],["115396.33000000","0.00008000"],["115389.71000000","0.00000000"],["115386.25000000","0.00000000"],["115385.08000000","0.00000000"],["115378.01000000","0.00214000"],["115374.84000000","0.00000000"],["115367.04000000","0.00182000"],["115361.68000000","0.00008000"],["115361.24000000","0.00243000"],["115360.89000000","0.00000000"],["115350.01000000","0.04597000"],["115344.01000000","0.19793000"],["115343.10000000","0.00000000"],["115340.48000000","0.00000000"],["115340.20000000","0.00000000"],["115332.45000000","0.00307000"],["115329.25000000","0.00000000"],["115327.03000000","0.00008000"],["115319.39000000","0.00000000"],["115311.44000000","0.01645000"],["115305.55000000","0.00000000"],["115305.30000000","0.01645000"],["115294.07000000","0.00000000"],["115173.79000000","0.01731000"],["113767.77000000","0.00100000"],["113767.76000000","0.00000000"],["103950.00000000","0.00705000"],["92400.23000000","0.00021000"],["92383.00000000","0.00000000"],["60000.00000000","57.97732000"]],"a":[["115500.29000000","0.42040000"],["115500.30000000","0.00205000"],["115501.33000000","0.00057000"],["115501.82000000","0.00005000"],["115501.88000000","0.00000000"],["115503.04000000","0.00000000"],["115503.20000000","0.00000000"],["115504.00000000","0.00170000"],["115505.25000000","0.00010000"],["115505.26000000","0.03808000"],["115506.00000000","0.00165000"],["115506.12000000","0.00000000"],["115506.13000000","0.00000000"],["115509.24000000","0.00000000"],["115509.47000000","0.08555000"],["115509.48000000","0.28577000"],["115509.65000000","0.01733000"],["115509.80000000","0.00000000"],["115509.81000000","0.00000000"],["115510.88000000","0.00034000"],["115510.89000000","0.00000000"],["115511.00000000","0.00010000"],["115511.51000000","0.00005000"],["115511.53000000","0.00150000"],["115511.56000000","0.12131000"],["115511.81000000","0.00005000"],["115511.84000000","0.40164000"],["115512.00000000","0.00174000"],["115512.71000000","0.04005000"],["115512.96000000","0.02730000"],["115513.41000000","0.00288000"],["115513.42000000","0.00000000"],["115514.31000000","0.06000000"],["115514.90000000","0.29212000"],["115514.91000000","0.00000000"],["115517.31000000","0.00000000"],["115517.61000000","0.21743000"],["115517.62000000","0.00151000"],["115519.61000000","0.16000000"],["115521.99000000","0.03000000"],["115523.14000000","0.03000000"],["115523.40000000","0.00300000"],["115524.29000000","0.03000000"],["115526.49000000","0.00000000"],["115527.11000000","0.00000000"],["115534.94000000","0.00008000"],["115534.95000000","0.00300000"],["115539.00000000","0.05502000"],["115540.71000000","0.00086000"],["115541.53000000","0.00000000"],["115542.69000000","0.00000000"],["115543.74000000","0.00000000"],["115543.84000000","0.00000000"],["115544.42000000","0.35032000"],["115544.90000000","0.00000000"],["115545.03000000","0.00448000"],["115545.26000000","0.06503000"],["115545.64000000","0.00012000"],["115548.07000000","0.00000000"],["115549.99000000","0.01645000"],["115550.35000000","0.31153000"],["115552.26000000","0.00086000"],["115560.07000000","0.43307000"],["115565.03000000","0.00000000"],["115565.76000000","0.25985000"],["115569.59000000","0.00008000"],["115575.82000000","0.00243000"],["115578.83000000","0.01959000"],["115580.41000000","0.03446000"],["115582.71000000","0.00000000"],["115584.34000000","0.13238000"],["115589.05000000","0.00000000"],["115589.06000000","0.00000000"],["115591.25000000","0.02204000"],["115594.24000000","0.00000000"],["115594.74000000","0.03300000"],["115595.19000000","0.00000000"],["115599.32000000","0.00000000"],["115600.48000000","0.00000000"],["115601.63000000","0.06000000"],["115604.24000000","0.00008000"],["115605.52000000","0.00005000"],["115612.83000000","0.00005000"],["115617.35000000","0.00000000"],["115620.00000000","0.01830000"],["115620.92000000","0.06005000"],["115638.89000000","0.00008000"],["115652.00000000","0.00000000"],["115666.38000000","0.00000000"],["115673.54000000","0.00013000"],["115684.26000000","0.00086000"],["115710.96000000","0.00005000"],["115716.68000000","0.01645000"],["115721.77000000","0.01645000"],["115820.20000000","0.00000000"],["115833.31000000","0.00311000"],["115849.55000000","0.00000000"],["115849.60000000","0.00000000"],["115934.75000000","0.14121000"],["115935.08000000","0.17637000"],["116087.63000000","0.00000000"],["116504.72000000","0.54000000"],["117232.80000000","0.00113000"]]}
[2025-10-27T18:49:09.152Z] {"e":"depthUpdate","E":1761590949015,"s":"BTCUSDT","U":79129633068,"u":79129633336,"b":[["115500.28000000","9.23964000"],["115499.21000000","0.01775000"],["115499.12000000","0.17319000"],["115496.76000000","0.06758000"],["115496.21000000","0.00692000"],["115493.95000000","0.00266000"],["115492.51000000","0.03455000"],["115491.34000000","0.00005000"],["115487.35000000","0.00500000"],["115486.14000000","0.00250000"],["115485.15000000","0.97631000"],["115484.82000000","0.00000000"],["115483.43000000","0.00005000"],["115483.06000000","0.00005000"],["115482.58000000","0.63537000"],["115481.34000000","0.03000000"],["115478.77000000","1.05943000"],["115476.81000000","0.00000000"],["115475.58000000","0.00000000"],["115394.46000000","0.00000000"],["115386.24000000","0.03000000"],["115385.07000000","0.03000000"],["115360.00000000","0.01898000"],["115338.33000000","0.00307000"],["115332.45000000","0.00000000"],["115267.55000000","4.79583000"],["115246.85000000","0.00000000"],["115173.87000000","0.01731000"],["113767.77000000","0.00100000"],["103950.00000000","0.00705000"],["92400.23000000","0.00021000"]],"a":[["115500.29000000","0.00493000"],["115500.30000000","0.00185000"],["115502.00000000","0.00165000"],["115502.44000000","0.00000000"],["115502.45000000","0.00000000"],["115504.00000000","0.00165000"],["115504.62000000","0.00000000"],["115505.25000000","0.00000000"],["115505.26000000","0.00000000"],["115506.00000000","0.00170000"],["115506.13000000","0.00010000"],["115506.14000000","0.08617000"],["115506.15000000","0.00000000"],["115508.00000000","0.00165000"],["115509.09000000","0.00010000"],["115509.10000000","0.28578000"],["115509.46000000","0.00000000"],["115509.47000000","0.00000000"],["115509.48000000","0.00000000"],["115509.65000000","0.00000000"],["115509.76000000","0.01734000"],["115511.01000000","0.44336000"],["115511.51000000","0.00010000"],["115511.52000000","0.04413000"],["115511.55000000","0.00005000"],["115512.71000000","0.04000000"],["115512.96000000","0.02725000"],["115513.41000000","0.00397000"],["115518.65000000","0.00000000"],["115521.90000000","0.00000000"],["115521.91000000","0.02598000"],["115522.75000000","0.04757000"],["115523.01000000","0.00865000"],["115528.08000000","0.00100000"],["115534.73000000","0.05228000"],["115536.87000000","0.00000000"],["115556.38000000","0.31152000"],["115584.34000000","0.00000000"],["115591.06000000","0.00100000"],["115591.07000000","0.00100000"],["115599.32000000","0.03000000"],["115600.48000000","0.03000000"],["115604.66000000","0.02500000"],["115612.44000000","0.00005000"],["115622.57000000","0.00005000"],["115630.00000000","0.00186000"],["115815.79000000","0.00000000"],["115819.66000000","0.01731000"],["115822.16000000","0.00000000"],["115822.84000000","0.00000000"],["115824.45000000","0.00009000"],["115826.16000000","0.01731000"],["115833.31000000","0.00000000"],["115834.76000000","0.01731000"],["115839.22000000","0.00317000"],["115843.02000000","0.00000000"],["115843.39000000","0.01731000"],["115843.60000000","0.00000000"],["115889.43000000","0.00000000"],["115900.85000000","0.37961000"],["115971.00000000","0.12811000"],["115971.74000000","0.02498000"],["117232.80000000","0.00113000"]]}
[2025-10-27T18:49:10.146Z] {"e":"depthUpdate","E":1761590950014,"s":"BTCUSDT","U":79129633337,"u":79129633852,"b":[["115500.28000000","8.73009000"],["115500.27000000","0.05142000"],["115500.02000000","0.00010000"],["115500.01000000","0.22117000"],["115500.00000000","0.28590000"],["115499.99000000","0.00074000"],["115499.98000000","0.00255000"],["115499.96000000","0.00010000"],["115499.95000000","0.05015000"],["115499.91000000","0.00005000"],["115499.90000000","0.05010000"],["115499.26000000","0.03977000"],["115499.21000000","0.00005000"],["115499.12000000","0.00000000"],["115498.44000000","0.00000000"],["115497.65000000","0.17319000"],["115497.11000000","0.04408000"],["115496.86000000","0.00000000"],["115496.76000000","0.00000000"],["115496.21000000","0.00005000"],["115495.86000000","0.08667000"],["115495.83000000","0.01703000"],["115495.42000000","0.00000000"],["115495.38000000","0.00260000"],["115495.18000000","0.00000000"],["115494.22000000","0.24942000"],["115493.96000000","0.00000000"],["115493.43000000","0.00105000"],["115492.55000000","0.00005000"],["115492.52000000","0.00442000"],["115492.51000000","0.03455000"],["115491.51000000","0.00005000"],["115491.33000000","0.85507000"],["115488.79000000","0.00000000"],["115488.78000000","0.00000000"],["115488.77000000","0.54080000"],["115487.99000000","0.00505000"],["115487.47000000","0.00005000"],["115487.35000000","0.00500000"],["115486.02000000","2.47832000"],["115486.01000000","0.15806000"],["115485.10000000","0.00000000"],["115484.57000000","0.00000000"],["115484.00000000","0.00000000"],["115483.50000000","0.54080000"],["115483.39000000","0.00000000"],["115480.02000000","0.04328000"],["115479.06000000","0.00519000"],["115478.77000000","1.05857000"],["115474.11000000","0.00000000"],["115471.25000000","0.00583000"],["115470.93000000","0.00000000"],["115461.11000000","0.00173000"],["115456.00000000","0.00120000"],["115452.41000000","0.31180000"],["115439.50000000","0.00000000"],["115426.06000000","0.03025000"],["115415.01000000","0.00000000"],["115398.57000000","0.02813000"],["115360.47000000","0.00000000"],["115345.70000000","0.00346000"],["115317.48000000","0.00000000"],["115316.15000000","0.00192000"],["115294.94000000","0.00000000"],["115275.01000000","0.01356000"],["115263.52000000","0.00086000"],["115256.29000000","0.00000000"],["115252.01000000","0.00073000"],["115242.02000000","0.00000000"],["115230.01000000","0.00000000"],["115200.98000000","0.00077000"],["115176.55000000","0.00000000"],["113767.77000000","0.00100000"],["112006.86000000","0.02165000"],["111992.12000000","0.00000000"],["106240.48000000","0.00000000"],["103950.00000000","0.00705000"],["92400.23000000","0.00021000"]],"a":[["115500.29000000","0.81141000"],["115500.30000000","0.00160000"],["115501.30000000","0.00010000"],["115501.31000000","0.09066000"],["115501.32000000","0.00005000"],["115501.33000000","0.00042000"],["115502.00000000","0.00160000"],["115502.79000000","0.00010000"],["115502.80000000","0.28579000"],["115504.00000000","0.00165000"],["115505.36000000","0.00010000"],["115505.37000000","0.00000000"],["115506.00000000","0.00165000"],["115506.13000000","0.00000000"],["115506.14000000","0.00000000"],["115506.37000000","0.00000000"],["115506.38000000","0.00000000"],["115509.08000000","0.00000000"],["115509.09000000","0.00000000"],["115509.10000000","0.00000000"],["115510.00000000","0.00160000"],["115511.01000000","0.44331000"],["115511.51000000","0.00000000"],["115511.52000000","0.00005000"],["115511.55000000","0.00010000"],["115511.83000000","0.00005000"],["115512.71000000","0.04000000"],["115512.96000000","0.02725000"],["115513.41000000","0.00662000"],["115513.71000000","0.00000000"],["115514.91000000","0.08000000"],["115515.47000000","0.30732000"],["115516.90000000","0.04398000"],["115519.05000000","0.00000000"],["115521.90000000","0.00432000"],["115522.75000000","0.00000000"],["115525.26000000","0.00000000"],["115527.17000000","0.16996000"],["115529.89000000","0.00000000"],["115530.79000000","0.00000000"],["115531.81000000","0.00380000"],["115531.82000000","0.31158000"],["115532.61000000","0.00000000"],["115536.71000000","0.04556000"],["115536.90000000","0.00000000"],["115537.45000000","0.31157000"],["115539.00000000","0.00000000"],["115550.35000000","0.00000000"],["115552.92000000","0.01731000"],["115553.05000000","0.03234000"],["115556.38000000","0.00000000"],["115556.54000000","0.03446000"],["115557.99000000","0.00048000"],["115566.88000000","0.00000000"],["115569.39000000","0.00215000"],["115571.44000000","0.00000000"],["115580.41000000","0.00000000"],["115591.06000000","0.00000000"],["115591.07000000","0.00000000"],["115591.65000000","0.00100000"],["115591.66000000","0.00100000"],["115593.99000000","0.00000000"],["115597.13000000","0.03400000"],["115600.00000000","0.06393000"],["115604.66000000","0.00000000"],["115613.07000000","0.03268000"],["115651.99000000","0.00000000"],["115673.53000000","0.00019000"],["115735.35000000","0.00000000"],["115800.00000000","3.38561000"],["115834.61000000","0.01731000"],["115836.11000000","0.00009000"],["115839.77000000","0.00000000"],["115842.88000000","0.01736000"],["115876.45000000","0.02498000"],["115877.23000000","0.02498000"],["115878.32000000","0.02498000"],["115878.88000000","0.02498000"],["115880.02000000","0.02498000"],["115880.55000000","0.02498000"],["115881.46000000","0.02498000"],["115881.95000000","0.02498000"],["115882.49000000","0.02498000"],["115883.53000000","0.02498000"],["115884.72000000","0.02498000"],["115885.85000000","0.02498000"],["115971.34000000","0.02498000"],["117232.80000000","0.00113000"]]}
[2025-10-27T18:49:11.161Z] {"e":"depthUpdate","E":1761590951014,"s":"BTCUSDT","U":79129633853,"u":79129634355,"b":[["115500.28000000","4.40723000"],["115500.27000000","0.05117000"],["115500.20000000","0.00009000"],["115500.01000000","0.13169000"],["115500.00000000","0.00005000"],["115499.99000000","0.00069000"],["115499.98000000","0.00005000"],["115499.95000000","0.05020000"],["115499.91000000","0.00010000"],["115499.90000000","0.05010000"],["115499.26000000","0.00000000"],["115498.33000000","0.00000000"],["115498.25000000","0.00000000"],["115497.89000000","0.00000000"],["115497.88000000","0.00000000"],["115497.65000000","0.00000000"],["115497.31000000","0.00005000"],["115497.30000000","0.28575000"],["115497.19000000","0.00000000"],["115497.12000000","0.00005000"],["115497.11000000","0.04408000"],["115496.98000000","0.00000000"],["115496.46000000","0.00000000"],["115496.21000000","0.00000000"],["115495.86000000","0.00000000"],["115495.83000000","0.00000000"],["115495.64000000","0.00000000"],["115495.38000000","0.00260000"],["115494.22000000","0.00000000"],["115494.20000000","0.00000000"],["115494.18000000","0.00000000"],["115493.95000000","0.00261000"],["115493.52000000","0.00000000"],["115493.43000000","0.00005000"],["115493.17000000","0.00000000"],["115493.01000000","0.04566000"],["115492.95000000","0.03818000"],["115492.52000000","0.00005000"],["115492.51000000","0.03465000"],["115492.13000000","0.08662000"],["115491.33000000","0.54783000"],["115491.21000000","0.00100000"],["115490.77000000","0.00000000"],["115488.78000000","0.00000000"],["115488.77000000","0.00000000"],["115488.73000000","0.12577000"],["115488.63000000","0.00000000"],["115488.61000000","0.08657000"],["115488.59000000","0.00005000"],["115488.58000000","1.00921000"],["115488.57000000","0.00000000"],["115488.47000000","0.00000000"],["115488.38000000","0.02257000"],["115487.99000000","0.00510000"],["115487.88000000","0.00014000"],["115487.49000000","0.00692000"],["115487.45000000","0.24942000"],["115487.35000000","0.00500000"],["115486.78000000","0.00330000"],["115486.15000000","0.00000000"],["115486.04000000","0.54080000"],["115486.03000000","0.85679000"],["115486.02000000","0.00000000"],["115486.01000000","0.00000000"],["115486.00000000","0.00000000"],["115484.57000000","0.00432000"],["115483.50000000","0.00000000"],["115482.95000000","0.21657000"],["115481.14000000","0.15806000"],["115480.02000000","0.00000000"],["115479.39000000","0.00005000"],["115476.83000000","0.00250000"],["115474.90000000","0.04328000"],["115468.30000000","1.33013000"],["115467.44000000","0.31176000"],["115467.34000000","0.00000000"],["115465.43000000","0.34651000"],["115458.66000000","0.00000000"],["115455.66000000","0.31500000"],["115447.26000000","0.00000000"],["115446.85000000","0.00000000"],["115439.68000000","0.00000000"],["115428.46000000","0.31189000"],["115426.06000000","0.00000000"],["115424.27000000","0.25978000"],["115412.52000000","0.03025000"],["115411.66000000","0.00000000"],["115407.67000000","0.34651000"],["115398.57000000","0.00000000"],["115397.92000000","0.00000000"],["115267.55000000","0.00000000"],["115238.96000000","0.00557000"],["115207.88000000","0.00000000"],["113767.77000000","0.00100000"],["103950.00000000","0.00705000"],["92400.23000000","0.00021000"],["92400.00000000","0.09106000"]],"a":[["115500.29000000","4.84194000"],["115500.30000000","0.00155000"],["115500.37000000","0.00009000"],["115501.31000000","0.01273000"],["115501.32000000","0.00000000"],["115502.00000000","0.00170000"],["115502.40000000","0.00010000"],["115502.41000000","0.03895000"],["115502.79000000","0.00000000"],["115502.80000000","0.00000000"],["115504.00000000","0.00160000"],["115505.27000000","0.00005000"],["115505.36000000","0.00000000"],["115506.00000000","0.00175000"],["115506.04000000","0.00010000"],["115506.05000000","0.02670000"],["115506.06000000","0.08669000"],["115506.20000000","0.00000000"],["115508.00000000","0.00170000"],["115509.24000000","0.00250000"],["115509.75000000","0.00010000"],["115509.76000000","0.01729000"],["115510.00000000","0.00165000"],["115511.00000000","0.06110000"],["115511.01000000","0.44331000"],["115511.37000000","0.04762000"],["115511.55000000","0.00000000"],["115511.81000000","0.00000000"],["115511.83000000","0.00000000"],["115511.84000000","0.31500000"],["115512.00000000","0.00169000"],["115512.71000000","0.00000000"],["115512.96000000","0.02725000"],["115513.41000000","0.00088000"],["115513.50000000","0.06000000"],["115513.69000000","0.00000000"],["115513.75000000","0.54080000"],["115514.30000000","0.00432000"],["115514.90000000","0.00000000"],["115514.99000000","0.00000000"],["115515.47000000","0.25975000"],["115515.53000000","0.00000000"],["115515.87000000","0.00000000"],["115515.95000000","0.06748000"],["115519.60000000","0.16996000"],["115521.90000000","0.00000000"],["115525.00000000","0.06138000"],["115527.17000000","0.00000000"],["115527.18000000","0.00000000"],["115528.16000000","0.05407000"],["115529.73000000","0.00000000"],["115530.37000000","0.00000000"],["115531.40000000","0.31159000"],["115531.81000000","0.00000000"],["115531.82000000","0.00000000"],["115532.34000000","0.06748000"],["115532.62000000","0.00000000"],["115533.94000000","0.00000000"],["115534.12000000","0.66903000"],["115534.32000000","0.00000000"],["115534.95000000","1.04236000"],["115536.71000000","0.00000000"],["115537.00000000","0.06100000"],["115540.30000000","0.17676000"],["115545.26000000","0.00000000"],["115545.32000000","0.06596000"],["115546.70000000","0.00005000"],["115551.62000000","0.00000000"],["115557.03000000","0.00000000"],["115560.07000000","0.00000000"],["115578.50000000","0.00000000"],["115584.34000000","0.00000000"],["115590.55000000","0.28559000"],["115590.69000000","0.00000000"],["115593.23000000","0.00000000"],["115597.13000000","0.00000000"],["115597.15000000","0.03400000"],["115604.66000000","0.02500000"],["115628.04000000","0.01210000"],["115665.70000000","0.00000000"],["115720.68000000","0.01356000"],["115882.92000000","0.02498000"],["115883.99000000","0.02498000"],["115885.06000000","0.02498000"],["115897.04000000","0.37961000"],["115900.85000000","0.00000000"],["115968.67000000","0.02505000"],["117232.80000000","0.00113000"]]}
[2025-10-27T18:49:12.146Z] {"e":"depthUpdate","E":1761590952014,"s":"BTCUSDT","U":79129634356,"u":79129634664,"b":[["115500.28000000","4.40468000"],["115500.27000000","0.01108000"],["115500.16000000","0.00010000"],["115500.15000000","0.08423000"],["115500.14000000","0.00000000"],["115500.02000000","0.00000000"],["115500.01000000","0.00000000"],["115499.95000000","0.05020000"],["115499.91000000","0.00010000"],["115499.90000000","0.05010000"],["115499.13000000","0.00095000"],["115498.33000000","0.00005000"],["115498.16000000","0.00005000"],["115497.47000000","0.00000000"],["115497.40000000","0.00191000"],["115497.31000000","0.00000000"],["115497.30000000","0.00000000"],["115497.19000000","0.00005000"],["115497.12000000","0.00005000"],["115497.11000000","0.04418000"],["115496.68000000","0.00000000"],["115495.92000000","0.03817000"],["115495.66000000","0.00346000"],["115495.64000000","0.00000000"],["115495.31000000","0.00000000"],["115494.15000000","0.00000000"],["115493.95000000","0.00266000"],["115493.35000000","0.00524000"],["115493.01000000","0.04561000"],["115492.95000000","0.00000000"],["115492.52000000","0.00000000"],["115492.51000000","0.03465000"],["115488.44000000","0.24942000"],["115488.38000000","0.02262000"],["115487.99000000","0.00500000"],["115487.96000000","0.00692000"],["115487.63000000","0.00000000"],["115487.49000000","0.00000000"],["115487.45000000","0.00000000"],["115486.03000000","0.56665000"],["115485.15000000","0.00000000"],["115478.77000000","1.05874000"],["115475.89000000","0.00000000"],["115473.28000000","0.98258000"],["115471.85000000","0.00000000"],["115471.25000000","0.00000000"],["115471.22000000","0.00583000"],["115470.81000000","0.08657000"],["115468.96000000","0.00000000"],["115467.44000000","0.00000000"],["115467.23000000","2.47832000"],["115448.36000000","0.31181000"],["115412.52000000","0.00000000"],["115397.92000000","0.00005000"],["115397.83000000","0.03025000"],["115360.88000000","0.00000000"],["115338.33000000","0.00000000"],["115321.76000000","0.00307000"],["115255.26000000","4.84025000"],["115038.04000000","0.02498000"],["113992.98000000","0.00000000"],["113767.77000000","0.00100000"],["103950.00000000","0.00705000"],["92400.23000000","0.00021000"],["33000.00000000","3.79030000"]],"a":[["115500.29000000","4.84150000"],["115500.30000000","0.00165000"],["115501.31000000","0.02382000"],["115501.33000000","0.00042000"],["115501.43000000","0.00010000"],["115501.44000000","0.04040000"],["115502.00000000","0.00165000"],["115502.41000000","0.03900000"],["115503.17000000","0.00191000"],["115505.27000000","0.00000000"],["115506.06000000","0.08669000"],["115507.21000000","0.00524000"],["115509.75000000","0.00000000"],["115510.00000000","0.00170000"],["115510.10000000","0.00381000"],["115511.37000000","0.04757000"],["115511.56000000","0.12126000"],["115511.84000000","0.32193000"],["115512.37000000","0.07028000"],["115513.41000000","0.00582000"],["115513.65000000","0.00000000"],["115513.67000000","0.00000000"],["115528.52000000","0.00000000"],["115534.95000000","1.04236000"],["115552.68000000","0.01356000"],["115553.62000000","0.00005000"],["115578.40000000","0.00000000"],["115578.41000000","0.00000000"],["115578.75000000","0.00000000"],["115579.22000000","0.00000000"],["115579.45000000","0.00000000"],["115579.62000000","0.06748000"],["115822.57000000","0.00311000"],["115839.22000000","0.00006000"],["117232.80000000","0.00113000"],["155000.00000000","11.99629800"]]}
[2025-10-27T18:49:13.146Z] {"e":"depthUpdate","E":1761590953014,"s":"BTCUSDT","U":79129634665,"u":79129635222,"b":[["115500.28000000","1.00080000"],["115500.27000000","0.01118000"],["115500.16000000","0.00000000"],["115500.15000000","0.00000000"],["115499.99000000","0.00084000"],["115499.97000000","0.00010000"],["115499.96000000","0.13164000"],["115499.90000000","0.05010000"],["115498.73000000","0.00017000"],["115497.47000000","0.00000000"],["115497.46000000","0.00000000"],["115497.12000000","0.00010000"],["115497.11000000","0.04408000"],["115496.17000000","0.28571000"],["115495.92000000","0.00000000"],["115495.83000000","0.00000000"],["115495.38000000","0.00005000"],["115494.83000000","0.00000000"],["115494.60000000","0.00000000"],["115494.05000000","0.00000000"],["115493.98000000","0.00000000"],["115493.64000000","0.00005000"],["115493.43000000","0.00000000"],["115493.35000000","0.00524000"],["115493.02000000","0.00000000"],["115493.01000000","0.00000000"],["115492.97000000","0.00000000"],["115492.82000000","0.00000000"],["115492.51000000","0.03460000"],["115492.13000000","0.00005000"],["115491.33000000","0.20743000"],["115491.21000000","0.00100000"],["115491.13000000","0.03923000"],["115491.11000000","0.00000000"],["115490.76000000","0.00005000"],["115490.70000000","0.00000000"],["115489.53000000","0.00000000"],["115489.46000000","0.00000000"],["115488.76000000","0.31500000"],["115488.72000000","0.00300000"],["115488.61000000","0.00000000"],["115488.59000000","0.00000000"],["115488.58000000","0.13800000"],["115488.44000000","0.00000000"],["115488.38000000","0.00005000"],["115488.30000000","0.08663000"],["115488.07000000","0.00000000"],["115487.99000000","0.00000000"],["115487.96000000","0.00000000"],["115487.35000000","0.00000000"],["115487.16000000","0.00070000"],["115487.09000000","0.04556000"],["115486.83000000","0.00000000"],["115486.04000000","0.00000000"],["115486.03000000","0.13160000"],["115485.99000000","0.00000000"],["115484.57000000","0.00000000"],["115484.56000000","0.00000000"],["115484.42000000","0.00005000"],["115484.40000000","0.00000000"],["115484.00000000","0.00692000"],["115483.99000000","0.24942000"],["115483.38000000","0.00000000"],["115483.37000000","0.00000000"],["115482.95000000","0.00000000"],["115482.68000000","0.00000000"],["115482.58000000","0.03000000"],["115482.54000000","0.00000000"],["115482.00000000","0.00000000"],["115481.99000000","0.00000000"],["115481.14000000","0.00000000"],["115480.41000000","0.00000000"],["115480.01000000","0.63640000"],["115480.00000000","0.00005000"],["115479.75000000","0.00000000"],["115479.58000000","0.00000000"],["115479.42000000","0.00000000"],["115478.78000000","0.54080000"],["115478.45000000","0.00432000"],["115477.17000000","0.21657000"],["115477.06000000","0.00000000"],["115477.05000000","0.00000000"],["115474.90000000","0.00000000"],["115474.88000000","1.43209000"],["115473.29000000","0.15808000"],["115472.95000000","0.25985000"],["115472.20000000","0.00250000"],["115472.18000000","0.00000000"],["115471.22000000","0.00000000"],["115471.20000000","0.00000000"],["115470.99000000","0.00583000"],["115470.85000000","0.08717000"],["115470.84000000","0.00000000"],["115470.81000000","0.00000000"],["115470.29000000","0.00000000"],["115468.43000000","0.14725000"],["115468.31000000","0.04328000"],["115468.30000000","1.76327000"],["115468.02000000","0.00000000"],["115467.80000000","0.00000000"],["115467.57000000","0.00250000"],["115467.14000000","0.00000000"],["115466.95000000","0.43307000"],["115466.62000000","0.08657000"],["115466.19000000","0.04000000"],["115466.08000000","0.00000000"],["115462.12000000","0.31177000"],["115461.70000000","0.00000000"],["115461.62000000","0.00000000"],["115455.68000000","0.08659000"],["115455.05000000","0.25978000"],["115448.36000000","0.00000000"],["115448.22000000","0.05727000"],["115448.11000000","0.31181000"],["115447.84000000","0.00000000"],["115426.37000000","0.00561000"],["115416.65000000","0.35717000"],["115415.22000000","0.00005000"],["115412.14000000","0.00000000"],["115411.87000000","0.01356000"],["115409.19000000","0.43307000"],["115404.84000000","0.00000000"],["115401.38000000","0.00000000"],["115390.31000000","0.00000000"],["115388.30000000","0.00000000"],["115340.48000000","0.14416000"],["115316.16000000","0.00000000"],["115316.15000000","0.00192000"],["115200.99000000","0.00000000"],["115200.98000000","0.00077000"],["114784.35000000","0.00021000"],["113767.77000000","0.00100000"],["103950.00000000","0.00705000"],["92400.23000000","0.00021000"],["41580.10000000","0.00015000"]],"a":[["115500.29000000","5.67618000"],["115500.30000000","0.04524000"],["115501.31000000","0.06642000"],["115501.44000000","0.04045000"],["115502.09000000","0.00010000"],["115502.10000000","0.14730000"],["115502.41000000","0.03895000"],["115502.68000000","0.00000000"],["115504.00000000","0.00170000"],["115504.61000000","0.00250000"],["115505.15000000","0.00000000"],["115505.16000000","0.06758000"],["115505.17000000","0.00000000"],["115505.27000000","0.00005000"],["115505.57000000","0.00000000"],["115505.59000000","0.04762000"],["115506.03000000","2.75428000"],["115506.04000000","0.54085000"],["115506.05000000","0.00005000"],["115506.06000000","0.08664000"],["115506.07000000","0.21657000"],["115507.14000000","0.00000000"],["115507.21000000","0.00524000"],["115507.65000000","0.07028000"],["115509.24000000","0.00250000"],["115509.45000000","0.00000000"],["115509.76000000","0.01724000"],["115510.00000000","0.00165000"],["115510.10000000","0.00381000"],["115510.27000000","0.54080000"],["115510.62000000","0.00000000"],["115510.68000000","0.00000000"],["115510.99000000","0.00432000"],["115511.00000000","0.06100000"],["115511.01000000","1.12892000"],["115511.37000000","0.00000000"],["115511.52000000","0.00000000"],["115512.37000000","0.00000000"],["115512.57000000","2.47832000"],["115512.64000000","0.00000000"],["115513.41000000","0.00000000"],["115513.65000000","0.00000000"],["115513.66000000","0.00000000"],["115513.76000000","0.00000000"],["115513.97000000","0.00000000"],["115514.30000000","0.00000000"],["115514.36000000","0.00000000"],["115516.25000000","0.00000000"],["115517.42000000","0.00000000"],["115517.61000000","0.00086000"],["115522.20000000","0.05174000"],["115525.53000000","0.00000000"],["115525.86000000","0.00000000"],["115526.07000000","0.31160000"],["115527.72000000","0.00000000"],["115528.16000000","0.00000000"],["115530.66000000","0.00000000"],["115534.73000000","0.00000000"],["115534.95000000","1.47550000"],["115541.37000000","0.02498000"],["115544.42000000","0.35032000"],["115546.53000000","0.00000000"],["115547.04000000","0.00000000"],["115547.74000000","0.00008000"],["115554.40000000","0.33247000"],["115555.87000000","0.25985000"],["115556.48000000","0.25985000"],["115557.39000000","0.00000000"],["115557.51000000","0.25732000"],["115558.85000000","0.00000000"],["115562.55000000","0.00000000"],["115563.62000000","0.00000000"],["115565.76000000","0.00000000"],["115574.20000000","0.00561000"],["115893.24000000","0.37961000"],["115897.04000000","0.00000000"],["117232.80000000","0.00113000"]]}
[2025-10-27T18:49:14.252Z] {"e":"depthUpdate","E":1761590954014,"s":"BTCUSDT","U":79129635223,"u":79129635471,"b":[["115500.28000000","1.44657000"],["115500.27000000","0.01133000"],["115499.90000000","0.05005000"],["115499.12000000","0.00000000"],["115499.11000000","0.00000000"],["115498.63000000","0.00000000"],["115498.62000000","0.00000000"],["115497.12000000","0.00005000"],["115497.11000000","0.04408000"],["115497.05000000","0.00000000"],["115496.19000000","0.00000000"],["115496.17000000","0.00000000"],["115495.83000000","0.28576000"],["115495.66000000","0.00346000"],["115495.55000000","0.00000000"],["115493.64000000","0.00000000"],["115493.35000000","0.00529000"],["115493.02000000","0.00005000"],["115492.51000000","0.03460000"],["115492.08000000","0.17316000"],["115491.33000000","0.20738000"],["115491.21000000","0.00105000"],["115491.17000000","0.04561000"],["115491.13000000","0.00005000"],["115490.92000000","0.17316000"],["115490.72000000","0.00250000"],["115490.46000000","0.08658000"],["115488.80000000","0.00005000"],["115488.72000000","0.00305000"],["115488.38000000","0.00005000"],["115488.30000000","0.08658000"],["115487.09000000","0.00000000"],["115484.00000000","0.00000000"],["115483.79000000","0.00692000"],["115480.01000000","1.41036000"],["115479.08000000","2.47832000"],["115468.74000000","0.00000000"],["115467.85000000","0.00000000"],["115467.57000000","0.00000000"],["115466.62000000","0.00000000"],["115466.31000000","0.00000000"],["115466.30000000","0.08657000"],["115449.50000000","0.00000000"],["115448.74000000","0.31181000"],["115448.11000000","0.00000000"],["115340.48000000","0.69494000"],["115255.26000000","0.00000000"],["115252.26000000","4.79576000"],["115179.10000000","0.00000000"],["115164.44000000","0.02298000"],["113767.77000000","0.00100000"],["109000.00000000","14.88938000"],["92400.23000000","0.00021000"],["92400.00000000","0.09106000"]],"a":[["115500.29000000","5.44120000"],["115500.30000000","0.04519000"],["115502.41000000","0.03895000"],["115504.00000000","0.00165000"],["115504.61000000","0.00255000"],["115505.16000000","0.00000000"],["115505.59000000","0.00000000"],["115505.82000000","0.06753000"],["115506.00000000","0.00170000"],["115506.02000000","1.09817000"],["115506.03000000","2.47837000"],["115506.04000000","0.54085000"],["115506.05000000","0.00000000"],["115506.06000000","0.08664000"],["115508.66000000","0.00042000"],["115509.24000000","0.00255000"],["115509.51000000","0.04757000"],["115510.00000000","0.00160000"],["115512.29000000","0.25985000"],["115513.66000000","0.00042000"],["115515.47000000","0.00000000"],["115518.59000000","0.05228000"],["115526.07000000","0.00000000"],["115526.11000000","0.31160000"],["115534.39000000","0.03234000"],["115534.95000000","1.73528000"],["115544.72000000","0.00000000"],["115545.32000000","0.00000000"],["115545.45000000","0.06534000"],["115553.05000000","0.00000000"],["115555.87000000","0.00000000"],["115557.98000000","0.00000000"],["115558.50000000","0.25985000"],["115558.97000000","0.00008000"],["115579.01000000","0.23348000"],["115579.02000000","0.00000000"],["115579.56000000","0.00000000"],["115584.69000000","0.12725000"],["115610.91000000","0.00000000"],["117232.80000000","0.00113000"],["120696.56000000","0.00280000"]]}
