[2025-10-27T18:47:59.191Z] {"e":"depthUpdate","E":1761590879014,"s":"BTCUSDT","U":79129602609,"u":79129602915,"b":[["115434.75000000","6.35351000"],["115434.74000000","0.00843000"],["115432.96000000","0.00010000"],["115425.66000000","0.00005000"],["115419.73000000","0.03000000"],["115418.61000000","0.03000000"],["115418.60000000","0.03600000"],["115418.48000000","0.03000000"],["115417.42000000","0.03000000"],["115416.17000000","0.03000000"],["115415.14000000","0.03000000"],["115414.54000000","0.03000000"],["115414.50000000","0.00866000"],["115413.97000000","0.03000000"],["115413.76000000","0.04000000"],["115412.73000000","0.03000000"],["115411.63000000","0.43314000"],["115411.50000000","0.00000000"],["115411.02000000","0.43307000"],["115410.86000000","0.00000000"],["115407.83000000","0.00000000"],["115406.58000000","0.00000000"],["115404.81000000","0.00000000"],["115403.69000000","0.00000000"],["115403.59000000","0.00000000"],["115402.42000000","0.00000000"],["115402.21000000","0.00000000"],["115400.11000000","0.00000000"],["115399.66000000","0.25975000"],["115399.61000000","1.27081000"],["115398.89000000","0.00000000"],["115398.60000000","0.00000000"],["115397.76000000","0.00000000"],["115397.72000000","0.00000000"],["115396.58000000","0.00000000"],["115396.57000000","0.00000000"],["115383.93000000","0.06300000"],["115356.15000000","0.00000000"],["115356.11000000","0.00000000"],["115356.03000000","0.00000000"],["115354.96000000","0.03000000"],["115354.00000000","0.28633000"],["115353.90000000","0.43314000"],["115353.29000000","0.43307000"],["115344.45000000","0.00360000"],["115324.56000000","2.47832000"],["115310.16000000","0.00000000"],["115308.99000000","0.00000000"],["115295.68000000","0.00000000"],["114423.10000000","0.00251000"],["113703.22000000","0.00100000"],["103891.00000000","0.05717000"],["103890.00000000","0.08110000"],["92348.00000000","0.00000000"],["92347.80000000","0.00021000"]],"a":[["115434.76000000","1.21530000"],["115434.77000000","0.04406000"],["115434.84000000","0.00009000"],["115436.97000000","0.03876000"],["115437.47000000","0.00000000"],["115437.50000000","0.00000000"],["115437.51000000","0.00009000"],["115437.53000000","0.00000000"],["115437.55000000","0.00000000"],["115438.00000000","0.00125000"],["115438.46000000","0.00000000"],["115438.47000000","0.00000000"],["115438.48000000","0.00000000"],["115439.30000000","0.00160000"],["115439.38000000","0.00000000"],["115439.98000000","0.00010000"],["115439.99000000","0.01900000"],["115440.11000000","0.04416000"],["115440.38000000","0.28585000"],["115440.58000000","0.00000000"],["115440.68000000","0.00000000"],["115441.51000000","0.00005000"],["115442.00000000","0.00125000"],["115442.82000000","0.00005000"],["115443.86000000","0.00703000"],["115444.07000000","0.02000000"],["115445.08000000","0.08663000"],["115445.47000000","0.01716000"],["115446.80000000","0.00000000"],["115446.83000000","0.00000000"],["115446.84000000","0.00000000"],["115447.92000000","1.00357000"],["115448.57000000","0.54080000"],["115448.58000000","2.47832000"],["115462.37000000","0.00583000"],["115462.88000000","0.00000000"],["115463.62000000","0.00000000"],["115478.03000000","0.00000000"],["115479.52000000","0.17686000"],["115480.95000000","0.00443000"],["115481.71000000","0.00020000"],["115491.41000000","0.03234000"],["115517.82000000","0.00000000"],["115523.20000000","0.00100000"],["115523.21000000","0.00100000"],["115541.00000000","0.00000000"],["115573.46000000","0.04895000"],["115573.59000000","0.07511000"],["115764.20000000","0.00000000"],["115766.53000000","0.00009000"],["115772.30000000","0.00009000"],["115778.92000000","0.00000000"],["115790.79000000","0.01732000"],["115791.25000000","0.00000000"],["115800.28000000","0.02398000"],["115812.65000000","0.02338000"],["115828.55000000","0.00000000"],["115839.96000000","0.37961000"],["116547.71000000","0.00246000"],["117166.29000000","0.00100000"]]}
[2025-10-27T18:48:00.155Z] {"e":"depthUpdate","E":1761590880014,"s":"BTCUSDT","U":79129602916,"u":79129603138,"b":[["115434.75000000","6.30039000"],["115434.74000000","0.00853000"],["115432.95000000","0.24964000"],["115432.87000000","0.17329000"],["115432.06000000","0.04767000"],["115431.94000000","0.00699000"],["115428.98000000","0.00006000"],["115428.46000000","0.13284000"],["115428.03000000","0.06748000"],["115416.65000000","0.55719000"],["115413.76000000","0.00000000"],["115410.26000000","0.04000000"],["115401.09000000","0.00000000"],["115400.97000000","0.93637000"],["115389.71000000","0.03600000"],["115388.53000000","0.03000000"],["115387.28000000","0.03000000"],["115386.25000000","0.03000000"],["115385.08000000","0.03000000"],["115326.08000000","0.03000000"],["115325.74000000","0.00000000"],["115322.99000000","0.00000000"],["115319.87000000","0.02813000"],["115315.05000000","0.00000000"],["115311.88000000","0.00000000"],["115310.16000000","0.00000000"],["115308.99000000","0.00000000"],["115306.95000000","0.00000000"],["115306.94000000","0.00000000"],["115284.09000000","0.06000000"],["115254.63000000","0.00000000"],["114423.10000000","0.00000000"],["113703.22000000","0.00100000"],["103890.00000000","0.08110000"],["92347.80000000","0.00021000"]],"a":[["115434.76000000","1.47156000"],["115434.77000000","0.04411000"],["115436.00000000","0.00140000"],["115436.96000000","0.00000000"],["115436.97000000","0.00000000"],["115436.98000000","0.00000000"],["115437.51000000","0.00000000"],["115438.00000000","0.00125000"],["115439.99000000","0.10194000"],["115440.11000000","0.04421000"],["115440.37000000","0.00005000"],["115440.38000000","0.28590000"],["115441.51000000","0.00000000"],["115441.52000000","0.09913000"],["115441.68000000","0.00525000"],["115442.00000000","0.00125000"],["115442.82000000","0.00000000"],["115443.86000000","0.00666000"],["115444.07000000","0.02000000"],["115445.55000000","0.00000000"],["115446.30000000","0.00848000"],["115446.95000000","0.00000000"],["115446.96000000","0.02600000"],["115447.25000000","0.04611000"],["115447.85000000","0.00070000"],["115447.90000000","0.00000000"],["115448.34000000","0.00000000"],["115450.61000000","0.00000000"],["115451.38000000","0.00000000"],["115457.01000000","0.00866000"],["115462.37000000","0.00000000"],["115464.19000000","0.00583000"],["115490.29000000","0.25975000"],["115490.85000000","0.00000000"],["115517.92000000","0.13194000"],["115523.20000000","0.00000000"],["115523.21000000","0.00000000"],["115527.31000000","0.00000000"],["115528.26000000","0.03400000"],["115534.86000000","0.00000000"],["115535.80000000","0.02500000"],["115772.30000000","0.00000000"],["115836.16000000","0.37961000"],["115839.96000000","0.00000000"],["116547.71000000","0.00000000"],["117166.29000000","0.00100000"]]}
[2025-10-27T18:48:01.238Z] {"e":"depthUpdate","E":1761590881014,"s":"BTCUSDT","U":79129603139,"u":79129603338,"b":[["115434.75000000","6.23889000"],["115434.74000000","0.00858000"],["115433.82000000","0.16575000"],["115433.81000000","0.00000000"],["115433.59000000","0.17339000"],["115433.53000000","0.03852000"],["115432.95000000","0.24964000"],["115432.88000000","0.00000000"],["115431.34000000","0.04406000"],["115416.43000000","0.00000000"],["115415.61000000","0.31190000"],["115415.49000000","0.00000000"],["115414.50000000","0.00000000"],["115398.30000000","0.01733000"],["115397.21000000","0.00000000"],["115370.07000000","0.00866000"],["114500.00000000","7.44825000"],["113703.22000000","0.00100000"],["106188.23000000","0.00059000"],["103891.00000000","0.05717000"],["103890.00000000","0.08110000"],["92347.80000000","0.00021000"]],"a":[["115434.76000000","1.47190000"],["115434.77000000","0.04416000"],["115436.00000000","0.00145000"],["115436.99000000","0.00010000"],["115437.00000000","0.10178000"],["115437.01000000","0.00000000"],["115437.27000000","0.00000000"],["115437.53000000","0.00005000"],["115437.64000000","0.00211000"],["115437.65000000","0.03851000"],["115438.00000000","0.00120000"],["115439.30000000","0.00155000"],["115439.56000000","0.00010000"],["115439.57000000","0.28595000"],["115439.98000000","0.00000000"],["115439.99000000","0.00000000"],["115440.00000000","0.01868000"],["115440.11000000","0.04416000"],["115440.37000000","0.00000000"],["115440.38000000","0.00000000"],["115441.51000000","0.00000000"],["115441.68000000","0.00525000"],["115442.00000000","0.00120000"],["115443.86000000","0.00077000"],["115444.07000000","0.02005000"],["115444.56000000","0.00260000"],["115446.30000000","0.00843000"],["115447.85000000","0.00000000"],["115457.01000000","0.00000000"],["115464.66000000","2.47832000"],["115467.66000000","0.00000000"],["115480.83000000","0.20184000"],["115482.27000000","0.31172000"],["115483.69000000","0.00000000"],["115700.00000000","0.13454000"],["117166.29000000","0.00100000"]]}
[2025-10-27T18:48:02.166Z] {"e":"depthUpdate","E":1761590882014,"s":"BTCUSDT","U":79129603339,"u":79129603674,"b":[["115434.75000000","6.29273000"],["115434.74000000","0.00863000"],["115434.71000000","0.00010000"],["115434.70000000","0.05030000"],["115433.82000000","0.16560000"],["115433.59000000","0.17334000"],["115433.54000000","0.00000000"],["115433.53000000","0.00000000"],["115432.96000000","0.00000000"],["115432.95000000","0.00005000"],["115432.88000000","0.00010000"],["115432.87000000","0.17334000"],["115432.55000000","0.00010000"],["115432.54000000","0.03811000"],["115432.07000000","0.00000000"],["115432.06000000","0.00000000"],["115431.95000000","0.04767000"],["115431.94000000","0.00000000"],["115431.35000000","0.00000000"],["115431.34000000","0.04406000"],["115429.71000000","0.24954000"],["115429.68000000","0.00694000"],["115428.46000000","0.13284000"],["115428.40000000","0.00000000"],["115428.03000000","0.00000000"],["115427.95000000","0.01708000"],["115422.00000000","0.96951000"],["115421.99000000","0.54080000"],["115415.00000000","0.00866000"],["115411.67000000","0.08661000"],["115383.83000000","0.04222000"],["115375.42000000","0.17580000"],["115370.07000000","0.00000000"],["115326.38000000","0.01356000"],["115285.80000000","0.00000000"],["113980.00000000","0.00102000"],["113703.22000000","0.00100000"],["106188.23000000","0.00049000"],["103890.00000000","0.08110000"],["92348.00000000","0.00000000"],["92347.80000000","0.00021000"],["33000.00000000","3.79030000"]],"a":[["115434.76000000","2.57149000"],["115434.77000000","0.04421000"],["115434.85000000","0.00000000"],["115434.86000000","0.00020000"],["115435.00000000","0.00169000"],["115436.00000000","0.00125000"],["115436.28000000","0.00010000"],["115436.29000000","0.20476000"],["115436.30000000","0.29243000"],["115436.99000000","0.00000000"],["115437.00000000","0.00000000"],["115437.53000000","0.00000000"],["115437.64000000","0.00191000"],["115437.65000000","0.00000000"],["115439.57000000","0.28595000"],["115440.10000000","0.00005000"],["115441.68000000","0.00525000"],["115442.00000000","0.00125000"],["115443.86000000","0.00700000"],["115443.97000000","0.00000000"],["115446.00000000","0.00130000"],["115446.25000000","0.04611000"],["115447.25000000","0.00000000"],["115447.37000000","0.00000000"],["115453.22000000","0.07031000"],["115455.90000000","0.00000000"],["115458.08000000","0.47458000"],["115461.90000000","0.00000000"],["115463.84000000","0.00583000"],["115464.19000000","0.00000000"],["115464.80000000","0.31177000"],["115469.40000000","0.00300000"],["115482.27000000","0.00000000"],["115490.27000000","0.01356000"],["115510.96000000","0.20526000"],["115513.21000000","0.00000000"],["115513.30000000","0.43307000"],["115513.38000000","0.00000000"],["115513.58000000","0.00000000"],["115514.76000000","0.43314000"],["115519.44000000","0.00000000"],["115523.56000000","0.00100000"],["115523.57000000","0.00100000"],["115530.31000000","0.18710000"],["115551.56000000","0.11135000"],["115551.57000000","0.00000000"],["115832.35000000","0.37961000"],["115836.16000000","0.00000000"],["117166.29000000","0.00100000"]]}
[2025-10-27T18:48:03.185Z] {"e":"depthUpdate","E":1761590883014,"s":"BTCUSDT","U":79129603675,"u":79129604097,"b":[["115434.75000000","8.37541000"],["115434.74000000","0.00838000"],["115434.71000000","0.00000000"],["115434.03000000","0.25643000"],["115433.83000000","0.00000000"],["115433.60000000","0.00100000"],["115432.88000000","0.00000000"],["115432.55000000","0.00000000"],["115432.54000000","0.03811000"],["115431.95000000","0.00000000"],["115431.34000000","0.04406000"],["115430.08000000","0.00005000"],["115429.71000000","0.00005000"],["115429.68000000","0.00000000"],["115428.04000000","0.06748000"],["115425.57000000","0.54080000"],["115423.20000000","0.00300000"],["115422.83000000","0.00000000"],["115422.62000000","0.00000000"],["115422.19000000","0.00000000"],["115422.02000000","1.58016000"],["115422.01000000","2.47832000"],["115422.00000000","0.00000000"],["115421.98000000","0.90538000"],["115421.93000000","0.00000000"],["115420.57000000","0.31189000"],["115420.51000000","0.25975000"],["115419.41000000","0.08661000"],["115416.98000000","0.05165000"],["115416.00000000","0.00000000"],["115415.00000000","0.00000000"],["115414.72000000","0.14725000"],["115414.53000000","0.00000000"],["115413.92000000","0.00000000"],["115412.49000000","0.00000000"],["115411.67000000","0.00000000"],["115408.69000000","0.00000000"],["115403.23000000","0.00000000"],["115400.97000000","0.00000000"],["115400.80000000","0.97306000"],["115400.12000000","0.04341000"],["115400.11000000","0.34651000"],["115399.19000000","0.00000000"],["115383.83000000","0.00000000"],["115379.44000000","0.25986000"],["115378.43000000","0.25979000"],["115377.03000000","0.04313000"],["115373.94000000","0.25975000"],["115372.17000000","0.25630000"],["115371.09000000","0.00000000"],["115369.96000000","0.00000000"],["115369.07000000","0.03025000"],["115362.51000000","0.00000000"],["115359.49000000","0.02813000"],["115356.18000000","0.00000000"],["115355.99000000","0.00000000"],["115355.87000000","0.00000000"],["115354.00000000","0.02658000"],["115353.90000000","0.00000000"],["115353.29000000","0.00000000"],["115350.22000000","0.00000000"],["115349.55000000","0.00000000"],["115340.91000000","0.46336000"],["115331.16000000","0.00000000"],["115329.78000000","0.00000000"],["115319.87000000","0.00000000"],["115179.58000000","0.02198000"],["115066.08000000","0.00000000"],["113703.22000000","0.00100000"],["112500.00000000","13.22969000"],["103891.00000000","0.05717000"],["103890.00000000","0.08110000"],["92347.80000000","0.00021000"]],"a":[["115434.76000000","0.30390000"],["115434.77000000","0.04411000"],["115434.86000000","0.00000000"],["115435.00000000","0.00184000"],["115435.24000000","0.00005000"],["115436.00000000","0.00125000"],["115436.28000000","0.00000000"],["115436.29000000","0.00000000"],["115436.30000000","0.00000000"],["115436.68000000","0.00000000"],["115437.64000000","0.00196000"],["115439.11000000","0.00000000"],["115439.56000000","0.00000000"],["115439.57000000","0.00000000"],["115439.99000000","0.00010000"],["115440.00000000","0.01873000"],["115440.10000000","0.00010000"],["115440.11000000","0.00020000"],["115440.97000000","0.00010000"],["115440.98000000","0.00010000"],["115441.51000000","0.00000000"],["115441.52000000","0.00005000"],["115441.68000000","0.00525000"],["115441.93000000","0.00000000"],["115441.96000000","0.00000000"],["115442.00000000","0.00120000"],["115442.14000000","0.00000000"],["115443.86000000","0.00005000"],["115444.07000000","0.00005000"],["115444.29000000","0.28589000"],["115444.56000000","0.00010000"],["115444.78000000","0.04015000"],["115445.08000000","0.00005000"],["115445.47000000","0.00000000"],["115446.00000000","0.00125000"],["115446.23000000","0.00087000"],["115446.25000000","0.00000000"],["115446.65000000","0.00000000"],["115446.96000000","0.00000000"],["115446.97000000","0.00000000"],["115447.03000000","0.00000000"],["115447.56000000","0.00000000"],["115447.57000000","0.00000000"],["115447.77000000","0.00000000"],["115447.79000000","0.00070000"],["115447.81000000","0.00136000"],["115447.82000000","0.00000000"],["115447.86000000","0.02600000"],["115447.92000000","0.27429000"],["115448.57000000","0.00000000"],["115448.58000000","0.00000000"],["115449.18000000","0.00000000"],["115449.51000000","0.00000000"],["115449.67000000","0.02000000"],["115450.57000000","0.29228000"],["115450.58000000","0.25975000"],["115452.08000000","0.30465000"],["115452.64000000","0.00000000"],["115453.22000000","0.00000000"],["115453.39000000","0.00000000"],["115454.36000000","0.46866000"],["115454.43000000","0.55379000"],["115455.47000000","0.00000000"],["115456.53000000","0.00000000"],["115458.05000000","2.47832000"],["115458.06000000","0.43314000"],["115458.42000000","0.43557000"],["115460.02000000","0.04611000"],["115462.64000000","0.00000000"],["115463.78000000","0.00017000"],["115463.84000000","0.00000000"],["115464.80000000","0.00000000"],["115467.66000000","0.00250000"],["115469.39000000","0.04342000"],["115475.95000000","0.00000000"],["115476.90000000","0.00250000"],["115478.79000000","0.00000000"],["115479.29000000","0.00000000"],["115479.33000000","0.00000000"],["115480.06000000","0.06603000"],["115481.72000000","0.00000000"],["115482.01000000","0.31173000"],["115482.43000000","0.00000000"],["115496.83000000","0.03446000"],["115510.96000000","0.43759000"],["115517.92000000","0.00000000"],["115518.58000000","0.00000000"],["115523.56000000","0.00000000"],["115523.57000000","0.00000000"],["115528.26000000","0.00000000"],["115529.21000000","0.00000000"],["115529.26000000","0.03400000"],["115535.80000000","0.00000000"],["115536.75000000","0.00000000"],["115536.80000000","0.02500000"],["115731.53000000","0.00000000"],["115758.06000000","0.02198000"],["115784.57000000","0.00000000"],["115788.38000000","0.00000000"],["115814.18000000","0.02338000"],["115816.26000000","0.02338000"],["115832.35000000","0.00000000"],["115839.96000000","0.37961000"],["117166.29000000","0.00100000"]]}
[2025-10-27T18:48:04.209Z] {"e":"depthUpdate","E":1761590884014,"s":"BTCUSDT","U":79129604098,"u":79129605791,"b":[["115439.99000000","9.61099000"],["115439.98000000","0.00017000"],["115439.95000000","0.05025000"],["115439.94000000","0.00270000"],["115439.92000000","0.00009000"],["115439.90000000","0.05010000"],["115439.29000000","0.00000000"],["115437.99000000","0.00000000"],["115437.66000000","0.00000000"],["115437.63000000","0.00000000"],["115437.14000000","0.00000000"],["115436.73000000","0.00000000"],["115436.02000000","1.47394000"],["115436.01000000","2.47842000"],["115436.00000000","0.00005000"],["115435.99000000","0.77700000"],["115435.97000000","0.00000000"],["115435.49000000","0.00006000"],["115435.32000000","0.00250000"],["115435.02000000","0.00000000"],["115435.00000000","0.00000000"],["115434.99000000","0.00000000"],["115434.79000000","0.00000000"],["115434.78000000","0.00000000"],["115434.77000000","0.54085000"],["115434.76000000","0.00000000"],["115434.75000000","0.53525000"],["115434.74000000","0.00801000"],["115434.70000000","0.00000000"],["115434.67000000","0.00000000"],["115434.03000000","0.00000000"],["115433.82000000","0.00000000"],["115433.60000000","0.00095000"],["115433.59000000","0.17329000"],["115433.51000000","0.00009000"],["115433.14000000","0.00009000"],["115432.95000000","0.00000000"],["115432.92000000","0.00018000"],["115432.87000000","0.00000000"],["115432.54000000","0.03806000"],["115432.50000000","0.00009000"],["115432.23000000","0.00009000"],["115431.81000000","0.00000000"],["115431.34000000","0.00000000"],["115431.25000000","0.00100000"],["115431.07000000","0.00000000"],["115430.98000000","0.00000000"],["115430.90000000","0.00005000"],["115430.82000000","0.00000000"],["115430.71000000","0.00433000"],["115430.69000000","0.00000000"],["115430.19000000","0.00100000"],["115430.08000000","0.00000000"],["115430.07000000","0.00042000"],["115429.71000000","0.00000000"],["115429.67000000","0.90125000"],["115429.66000000","2.47832000"],["115429.65000000","0.54080000"],["115429.12000000","0.00000000"],["115429.06000000","0.00005000"],["115428.98000000","0.00000000"],["115428.46000000","0.18340000"],["115428.45000000","0.00130000"],["115428.24000000","0.00000000"],["115427.99000000","0.00000000"],["115427.80000000","0.00000000"],["115427.58000000","0.07000000"],["115427.03000000","0.00000000"],["115426.09000000","0.00000000"],["115425.97000000","0.00000000"],["115425.95000000","0.00000000"],["115425.94000000","0.00000000"],["115425.59000000","0.00000000"],["115425.57000000","0.54089000"],["115424.95000000","0.00000000"],["115424.91000000","0.00000000"],["115424.53000000","0.00000000"],["115424.33000000","0.00000000"],["115424.32000000","0.00000000"],["115423.99000000","0.00000000"],["115423.89000000","0.00000000"],["115423.82000000","0.08660000"],["115423.63000000","0.00000000"],["115422.84000000","0.00000000"],["115422.34000000","0.00866000"],["115421.98000000","0.42902000"],["115421.80000000","0.05414000"],["115420.23000000","0.00000000"],["115419.83000000","0.00000000"],["115419.41000000","0.00000000"],["115417.28000000","0.00000000"],["115416.98000000","0.00000000"],["115416.84000000","0.00000000"],["115416.21000000","0.00000000"],["115415.64000000","0.34651000"],["115415.63000000","0.08718000"],["115412.22000000","0.00000000"],["115411.68000000","0.04331000"],["115411.63000000","0.00000000"],["115411.14000000","0.00092000"],["115411.02000000","0.00000000"],["115408.91000000","0.00005000"],["115405.35000000","0.00300000"],["115400.96000000","0.52144000"],["115400.11000000","0.17698000"],["115399.66000000","0.00000000"],["115397.52000000","0.00000000"],["115396.96000000","0.00005000"],["115395.72000000","0.00000000"],["115391.74000000","0.00000000"],["115389.04000000","0.00000000"],["115388.05000000","0.00086000"],["115387.59000000","0.00000000"],["115386.21000000","0.04174000"],["115384.57000000","0.25986000"],["115384.39000000","0.00000000"],["115383.24000000","0.25979000"],["115381.59000000","0.00036000"],["115381.54000000","0.00000000"],["115381.24000000","0.22884000"],["115379.44000000","0.00000000"],["115379.32000000","0.00000000"],["115378.43000000","0.00000000"],["115378.15000000","0.00000000"],["115377.03000000","0.00000000"],["115375.86000000","0.00000000"],["115375.42000000","0.35076000"],["115370.94000000","0.00000000"],["115369.90000000","0.00634000"],["115369.07000000","0.00000000"],["115365.01000000","0.23552000"],["115364.53000000","0.00000000"],["115363.32000000","0.00000000"],["115361.90000000","0.00631000"],["115361.42000000","0.00000000"],["115361.37000000","0.25975000"],["115361.24000000","0.00000000"],["115360.90000000","0.46869000"],["115359.49000000","0.00000000"],["115359.24000000","0.00000000"],["115357.91000000","0.34651000"],["115357.83000000","0.00000000"],["115354.11000000","0.00000000"],["115353.73000000","0.02813000"],["115353.57000000","0.03025000"],["115347.67000000","0.00000000"],["115345.00000000","0.00000000"],["115340.91000000","0.00000000"],["115340.90000000","0.00000000"],["115340.77000000","0.03000000"],["115340.47000000","0.86698000"],["115339.70000000","0.03960000"],["115339.58000000","0.02432000"],["115336.83000000","0.00111000"],["115336.71000000","0.00000000"],["115336.12000000","0.31280000"],["115330.50000000","0.33726000"],["115329.03000000","0.00000000"],["115324.57000000","0.00000000"],["115323.72000000","0.07511000"],["115319.00000000","0.00000000"],["115317.71000000","0.00000000"],["115317.53000000","0.00000000"],["115314.63000000","0.00000000"],["115313.02000000","0.00000000"],["115313.01000000","0.00000000"],["115311.18000000","0.00000000"],["115305.15000000","0.02339000"],["115304.55000000","0.00000000"],["115301.46000000","0.00000000"],["115295.66000000","0.00000000"],["115293.15000000","0.78537000"],["115281.31000000","0.00000000"],["115155.63000000","0.00000000"],["115134.75000000","0.00000000"],["115095.21000000","0.02252000"],["115088.70000000","0.00000000"],["114990.07000000","0.31500000"],["114978.52000000","0.00000000"],["114955.54000000","0.00000000"],["114800.00000000","0.68195000"],["113708.39000000","0.00100000"],["113703.22000000","0.00000000"],["113145.34000000","0.00000000"],["113131.19000000","0.00441000"],["111947.87000000","0.02176000"],["111944.19000000","0.00000000"],["103895.00000000","0.00010000"],["103890.00000000","0.08100000"],["92352.00000000","0.00021000"],["92347.80000000","0.00000000"]],"a":[["115434.76000000","0.00000000"],["115434.77000000","0.00000000"],["115434.84000000","0.00000000"],["115434.96000000","0.00000000"],["115435.00000000","0.00000000"],["115435.24000000","0.00000000"],["115435.98000000","0.00000000"],["115436.00000000","0.00000000"],["115436.01000000","0.00000000"],["115436.38000000","0.00000000"],["115436.74000000","0.00000000"],["115437.15000000","0.00000000"],["115437.35000000","0.00000000"],["115437.64000000","0.00000000"],["115437.87000000","0.00000000"],["115438.00000000","0.00000000"],["115439.25000000","0.00000000"],["115439.30000000","0.00000000"],["115439.44000000","0.00000000"],["115439.99000000","0.00000000"],["115440.00000000","0.31888000"],["115440.01000000","0.00095000"],["115440.08000000","0.00009000"],["115440.10000000","0.00000000"],["115440.11000000","0.00005000"],["115440.21000000","0.00017000"],["115440.95000000","0.00054000"],["115440.97000000","0.00005000"],["115440.98000000","0.00000000"],["115441.46000000","0.00042000"],["115441.52000000","0.00000000"],["115441.53000000","0.00000000"],["115441.68000000","0.00530000"],["115442.00000000","0.00120000"],["115442.38000000","0.00000000"],["115442.39000000","0.00000000"],["115442.88000000","0.00000000"],["115443.29000000","0.00000000"],["115443.73000000","0.00000000"],["115444.00000000","0.00120000"],["115444.06000000","0.00000000"],["115444.07000000","0.00000000"],["115444.28000000","0.00000000"],["115444.29000000","0.00000000"],["115444.56000000","0.00005000"],["115444.77000000","0.00000000"],["115444.78000000","0.00005000"],["115445.08000000","0.00000000"],["115445.91000000","0.00000000"],["115446.05000000","0.00000000"],["115446.23000000","0.00000000"],["115446.30000000","0.00853000"],["115446.55000000","0.00000000"],["115447.19000000","0.00390000"],["115447.37000000","0.00010000"],["115447.38000000","0.05365000"],["115447.48000000","0.00000000"],["115447.79000000","0.00000000"],["115447.81000000","0.00141000"],["115447.86000000","0.00000000"],["115447.91000000","0.00010000"],["115447.92000000","0.17637000"],["115447.93000000","0.14729000"],["115448.00000000","0.00125000"],["115448.07000000","0.00000000"],["115448.16000000","0.00000000"],["115448.40000000","0.00005000"],["115448.58000000","0.00000000"],["115448.59000000","0.00100000"],["115448.62000000","0.00000000"],["115449.28000000","0.00330000"],["115449.67000000","0.00000000"],["115449.76000000","0.00010000"],["115449.77000000","0.07540000"],["115450.00000000","0.00125000"],["115450.09000000","0.00000000"],["115450.57000000","0.00005000"],["115450.58000000","0.25980000"],["115450.84000000","0.00000000"],["115450.97000000","0.00000000"],["115451.47000000","0.10000000"],["115452.00000000","0.00120000"],["115452.08000000","0.08808000"],["115452.23000000","0.00000000"],["115452.33000000","0.00000000"],["115452.35000000","0.00000000"],["115452.36000000","0.00000000"],["115452.46000000","0.54191000"],["115452.47000000","0.04000000"],["115452.52000000","0.28582000"],["115452.57000000","0.00000000"],["115452.68000000","0.00000000"],["115452.80000000","0.00000000"],["115452.98000000","0.00000000"],["115453.47000000","0.00000000"],["115453.76000000","0.00000000"],["115453.79000000","0.00000000"],["115453.80000000","0.00000000"],["115453.83000000","0.00000000"],["115454.13000000","0.00087000"],["115454.36000000","0.00005000"],["115454.37000000","0.16000000"],["115454.43000000","0.01299000"],["115454.69000000","0.04401000"],["115454.86000000","0.00000000"],["115454.87000000","0.04000000"],["115454.88000000","0.00000000"],["115454.97000000","0.00000000"],["115455.17000000","0.00000000"],["115455.53000000","0.00000000"],["115456.12000000","0.00000000"],["115456.32000000","0.00000000"],["115456.50000000","0.29227000"],["115456.64000000","0.00000000"],["115457.02000000","0.00006000"],["115457.31000000","0.00086000"],["115457.32000000","0.00150000"],["115457.76000000","0.00000000"],["115457.85000000","0.00300000"],["115458.04000000","0.49311000"],["115458.05000000","0.00000000"],["115458.08000000","0.00000000"],["115458.26000000","0.00000000"],["115458.95000000","0.00000000"],["115459.48000000","0.00000000"],["115459.54000000","0.00000000"],["115459.65000000","0.00000000"],["115459.80000000","0.04611000"],["115459.82000000","0.00000000"],["115460.00000000","0.00125000"],["115460.02000000","0.00000000"],["115460.07000000","0.14725000"],["115460.14000000","0.31500000"],["115461.65000000","0.54080000"],["115461.67000000","0.00000000"],["115463.03000000","0.00433000"],["115463.09000000","0.21657000"],["115463.30000000","0.07031000"],["115463.69000000","0.25979000"],["115463.80000000","0.00000000"],["115463.89000000","0.00000000"],["115464.26000000","0.00009000"],["115464.82000000","0.00100000"],["115465.15000000","0.00000000"],["115465.95000000","0.00000000"],["115466.21000000","0.00000000"],["115466.50000000","0.00000000"],["115467.46000000","0.00000000"],["115468.61000000","0.25986000"],["115469.13000000","0.00005000"],["115469.44000000","0.00583000"],["115469.58000000","0.03000000"],["115469.94000000","0.00000000"],["115471.28000000","0.00000000"],["115471.36000000","0.00000000"],["115471.43000000","0.00000000"],["115472.28000000","0.00250000"],["115472.36000000","0.00000000"],["115472.94000000","0.00011000"],["115473.90000000","0.00000000"],["115473.92000000","0.00000000"],["115475.17000000","0.00000000"],["115475.50000000","0.03000000"],["115475.83000000","0.00000000"],["115475.84000000","0.00000000"],["115476.98000000","0.00000000"],["115477.32000000","2.47837000"],["115477.99000000","0.00000000"],["115478.20000000","0.00000000"],["115478.72000000","0.00011000"],["115480.06000000","0.00000000"],["115480.40000000","0.00086000"],["115480.83000000","0.29969000"],["115481.71000000","0.00012000"],["115483.84000000","0.14725000"],["115485.26000000","0.00274000"],["115486.68000000","0.00008000"],["115486.69000000","0.07094000"],["115486.82000000","0.00000000"],["115487.27000000","0.31171000"],["115487.43000000","0.00000000"],["115487.71000000","0.14630000"],["115488.54000000","0.00000000"],["115489.23000000","0.06343000"],["115489.80000000","0.00000000"],["115490.27000000","0.00000000"],["115491.12000000","0.20117000"],["115491.41000000","0.00000000"],["115491.99000000","0.00000000"],["115492.01000000","0.33263000"],["115492.21000000","0.31170000"],["115492.40000000","0.00048000"],["115492.41000000","0.00000000"],["115492.45000000","0.02849000"],["115492.59000000","0.08643000"],["115493.03000000","0.00000000"],["115493.04000000","0.00000000"],["115494.29000000","0.00000000"],["115495.21000000","0.01645000"],["115495.83000000","0.03464000"],["115495.84000000","0.02338000"],["115496.83000000","0.00000000"],["115497.95000000","0.04207000"],["115500.82000000","0.00000000"],["115500.97000000","0.00000000"],["115501.70000000","0.00000000"],["115501.96000000","0.01356000"],["115503.30000000","0.00000000"],["115504.97000000","0.03234000"],["115508.43000000","0.25950000"],["115509.12000000","0.00215000"],["115509.70000000","0.03446000"],["115512.81000000","0.54080000"],["115514.79000000","0.25986000"],["115515.24000000","0.03681000"],["115515.62000000","0.00633000"],["115518.34000000","0.54080000"],["115520.35000000","0.46804000"],["115523.30000000","0.00000000"],["115525.91000000","0.00000000"],["115526.21000000","0.00000000"],["115526.64000000","0.00000000"],["115527.03000000","0.00000000"],["115527.99000000","0.00000000"],["115528.22000000","0.00100000"],["115528.23000000","0.00100000"],["115529.26000000","0.00000000"],["115529.48000000","0.73129000"],["115531.31000000","0.00000000"],["115532.31000000","0.03400000"],["115533.99000000","0.00000000"],["115536.80000000","0.00000000"],["115537.02000000","0.03900000"],["115537.75000000","0.00000000"],["115538.08000000","0.03300000"],["115538.18000000","0.04500000"],["115539.86000000","0.02500000"],["115541.96000000","0.01732000"],["115543.84000000","0.06000000"],["115546.73000000","0.03952000"],["115547.22000000","0.00110000"],["115547.61000000","0.02418000"],["115551.56000000","0.83689000"],["115552.95000000","2.47832000"],["115555.82000000","0.00499000"],["115555.83000000","0.03346000"],["115555.84000000","0.00000000"],["115557.08000000","0.00005000"],["115557.15000000","0.03000000"],["115559.99000000","0.00499000"],["115560.00000000","0.00165000"],["115560.24000000","0.00005000"],["115561.07000000","0.00000000"],["115607.69000000","0.00019000"],["115607.70000000","0.00086000"],["115680.07000000","0.00000000"],["115701.54000000","0.08643000"],["115717.41000000","0.00000000"],["115720.75000000","0.00000000"],["115732.23000000","0.00000000"],["115732.62000000","0.00000000"],["115733.84000000","0.00000000"],["115734.35000000","0.00000000"],["115736.33000000","0.00000000"],["115736.35000000","0.00000000"],["115744.79000000","0.02498000"],["115745.25000000","0.02498000"],["115745.48000000","0.02498000"],["115748.63000000","0.01645000"],["115751.99000000","0.02498000"],["115752.17000000","0.02498000"],["115752.73000000","0.02498000"],["115753.37000000","0.02498000"],["115753.62000000","0.02198000"],["115753.85000000","0.02498000"],["115755.02000000","0.00000000"],["115759.60000000","0.02198000"],["115764.07000000","0.00000000"],["115771.77000000","0.00009000"],["115776.12000000","0.00000000"],["115776.55000000","0.00000000"],["115776.56000000","0.00000000"],["115777.54000000","0.00000000"],["115780.48000000","0.00000000"],["115781.99000000","0.00000000"],["115783.01000000","0.00000000"],["115783.08000000","0.00000000"],["115784.51000000","0.00000000"],["115788.28000000","0.00000000"],["115790.94000000","0.00000000"],["115796.50000000","0.01819000"],["115797.97000000","0.02398000"],["115798.19000000","0.00000000"],["115798.37000000","0.02398000"],["115798.73000000","0.00000000"],["115799.28000000","0.02398000"],["115800.61000000","0.02398000"],["115802.05000000","0.02398000"],["115803.05000000","0.02398000"],["115803.96000000","0.02398000"],["115804.00000000","0.02398000"],["115806.14000000","0.00000000"],["115816.26000000","0.04676000"],["115819.73000000","0.02338000"],["115819.83000000","0.02338000"],["115820.73000000","0.02338000"],["115824.63000000","0.00000000"],["115827.39000000","0.02498000"],["115827.41000000","0.00000000"],["115827.94000000","0.00000000"],["115828.41000000","0.02498000"],["115828.70000000","0.00000000"],["115829.54000000","0.02498000"],["115830.82000000","0.00000000"],["115832.78000000","0.00000000"],["115844.80000000","0.00000000"],["115845.41000000","0.00000000"],["115845.62000000","0.00000000"],["115846.07000000","0.00000000"],["115848.12000000","0.00000000"],["115851.25000000","0.00000000"],["115852.40000000","0.03198000"],["115857.45000000","0.03198000"],["115857.83000000","0.03198000"],["115858.32000000","0.03198000"],["115862.65000000","0.02252000"],["115867.06000000","0.02252000"],["115874.83000000","0.03198000"],["115876.37000000","0.03198000"],["115877.46000000","0.03198000"],["115878.21000000","0.03275000"],["115879.13000000","0.03198000"],["115879.71000000","0.03198000"],["115886.49000000","0.00000000"],["115887.42000000","0.00000000"],["115891.55000000","0.00000000"],["115897.64000000","0.00000000"],["115908.08000000","0.02498000"],["115908.85000000","0.02498000"],["115915.92000000","0.02498000"],["115915.99000000","0.02498000"],["115936.84000000","0.31500000"],["117166.29000000","0.00000000"],["117171.60000000","0.00100000"],["121443.38000000","0.00000000"]]}
[2025-10-27T18:48:05.155Z] {"e":"depthUpdate","E":1761590885014,"s":"BTCUSDT","U":79129605792,"u":79129606146,"b":[["115439.99000000","9.37065000"],["115439.95000000","0.05030000"],["115439.90000000","0.05015000"],["115438.25000000","0.24949000"],["115436.03000000","0.00438000"],["115436.02000000","0.18812000"],["115436.01000000","0.00000000"],["115435.99000000","0.08405000"],["115434.77000000","0.00000000"],["115434.75000000","0.49593000"],["115433.61000000","0.00000000"],["115433.59000000","0.17329000"],["115432.54000000","0.00000000"],["115431.40000000","0.00005000"],["115430.71000000","0.00000000"],["115430.46000000","0.03005000"],["115429.67000000","0.90130000"],["115429.66000000","2.47832000"],["115429.30000000","0.03000000"],["115428.47000000","0.15814000"],["115428.46000000","0.44618000"],["115427.95000000","0.00000000"],["115426.12000000","0.00005000"],["115425.87000000","0.00866000"],["115425.42000000","0.31188000"],["115424.53000000","0.04330000"],["115424.52000000","0.25986000"],["115423.82000000","0.00000000"],["115423.39000000","0.25979000"],["115422.43000000","0.00000000"],["115422.42000000","0.03000000"],["115422.34000000","0.00000000"],["115421.18000000","0.03000000"],["115417.66000000","0.00000000"],["115417.61000000","0.00000000"],["115417.42000000","0.00000000"],["115416.17000000","0.00000000"],["115413.84000000","0.00000000"],["115405.59000000","1.81481000"],["115405.35000000","0.00300000"],["115403.63000000","0.00000000"],["115400.12000000","0.00008000"],["115392.15000000","0.00000000"],["115392.14000000","0.06583000"],["115372.96000000","0.00000000"],["115372.88000000","0.00000000"],["115366.01000000","0.00008000"],["115363.32000000","0.00005000"],["115361.60000000","0.00000000"],["115361.53000000","0.00000000"],["115361.52000000","0.00000000"],["115361.48000000","0.00000000"],["115361.44000000","0.00000000"],["115361.37000000","0.00000000"],["115361.35000000","0.00000000"],["115361.30000000","0.43307000"],["115361.22000000","0.25975000"],["115361.11000000","0.00000000"],["115361.00000000","0.00000000"],["115359.22000000","0.94299000"],["115354.75000000","0.00008000"],["115353.73000000","0.00000000"],["115353.68000000","0.00000000"],["115353.57000000","0.00000000"],["115348.37000000","0.00000000"],["115340.87000000","0.03025000"],["115337.23000000","0.00000000"],["115327.74000000","0.00052000"],["115326.23000000","0.02813000"],["115319.01000000","0.00216000"],["115319.00000000","0.98720000"],["115316.93000000","0.00000000"],["115316.22000000","0.00173000"],["115313.03000000","0.00000000"],["115306.82000000","0.00182000"],["115305.40000000","0.00000000"],["115302.01000000","0.00000000"],["115256.03000000","0.00193000"],["115250.02000000","0.00000000"],["115191.15000000","0.00073000"],["115186.56000000","0.00000000"],["115139.99000000","0.00000000"],["115138.53000000","0.00077000"],["115132.76000000","0.00000000"],["113708.39000000","0.00100000"],["111000.00000000","10.82431000"],["103896.00000000","0.00000000"],["103895.00000000","0.00010000"],["92352.00000000","0.00021000"],["42000.00000000","1.36531000"]],"a":[["115440.00000000","0.04667000"],["115440.01000000","0.00090000"],["115440.59000000","0.00009000"],["115440.83000000","0.00009000"],["115440.93000000","0.00000000"],["115440.95000000","0.00054000"],["115440.96000000","0.00000000"],["115440.97000000","0.00005000"],["115441.77000000","0.00000000"],["115442.00000000","0.00125000"],["115442.12000000","0.00005000"],["115443.86000000","0.00271000"],["115444.17000000","0.00000000"],["115445.17000000","0.00005000"],["115447.38000000","0.05365000"],["115447.90000000","0.00010000"],["115447.91000000","0.13587000"],["115448.58000000","0.00000000"],["115449.77000000","0.07530000"],["115450.00000000","0.00120000"],["115450.57000000","0.00000000"],["115450.58000000","0.25975000"],["115452.40000000","0.00000000"],["115452.52000000","0.00000000"],["115452.89000000","0.00070000"],["115452.93000000","0.00000000"],["115454.13000000","0.00000000"],["115454.69000000","0.00000000"],["115454.81000000","0.00000000"],["115455.03000000","0.28590000"],["115455.19000000","0.00000000"],["115456.71000000","0.04611000"],["115457.02000000","0.00000000"],["115458.01000000","1.61977000"],["115458.02000000","2.47832000"],["115458.03000000","0.54080000"],["115458.04000000","0.00000000"],["115458.65000000","0.04402000"],["115459.80000000","0.00000000"],["115463.03000000","0.00000000"],["115463.30000000","0.00000000"],["115463.66000000","0.00005000"],["115464.63000000","0.00000000"],["115464.65000000","0.00433000"],["115468.29000000","0.03300000"],["115468.57000000","0.16996000"],["115469.39000000","0.00008000"],["115469.44000000","0.00000000"],["115469.52000000","0.03900000"],["115470.64000000","0.04200000"],["115470.68000000","0.13834000"],["115471.88000000","0.03900000"],["115473.02000000","0.03000000"],["115473.50000000","0.03600000"],["115474.18000000","0.03000000"],["115477.98000000","0.03198000"],["115479.13000000","0.00000000"],["115485.45000000","0.03234000"],["115489.13000000","0.00000000"],["115489.23000000","0.00000000"],["115489.37000000","0.06478000"],["115492.01000000","0.00000000"],["115492.40000000","0.00000000"],["115492.59000000","0.00000000"],["115493.99000000","0.02498000"],["115495.46000000","0.33263000"],["115495.73000000","0.31169000"],["115497.94000000","0.00048000"],["115504.97000000","0.00000000"],["115527.99000000","0.00000000"],["115528.22000000","0.00000000"],["115528.23000000","0.00000000"],["115530.00000000","0.00260000"],["115530.01000000","0.00100000"],["115532.31000000","0.00000000"],["115539.86000000","0.00000000"],["115561.25000000","0.00000000"],["115565.84000000","0.00000000"],["115567.10000000","0.00000000"],["115569.39000000","0.00000000"],["115570.00000000","0.00246000"],["115570.41000000","0.00000000"],["115571.02000000","0.00000000"],["115571.57000000","0.00000000"],["115607.69000000","0.00000000"],["115607.70000000","0.00000000"],["115612.66000000","0.00086000"],["115613.51000000","0.00019000"],["115618.93000000","0.00000000"],["115624.20000000","0.00086000"],["115805.41000000","0.00000000"],["117171.60000000","0.00100000"]]}
[2025-10-27T18:48:06.173Z] {"e":"depthUpdate","E":1761590886014,"s":"BTCUSDT","U":79129606147,"u":79129607432,"b":[["115447.90000000","8.51095000"],["115447.89000000","0.00000000"],["115447.85000000","0.00060000"],["115447.83000000","0.00009000"],["115447.80000000","0.00000000"],["115447.66000000","0.00010000"],["115447.65000000","0.05025000"],["115447.61000000","0.00010000"],["115447.60000000","0.05010000"],["115447.40000000","0.00000000"],["115447.37000000","0.00000000"],["115447.18000000","0.00000000"],["115447.05000000","0.00010000"],["115447.04000000","0.24219000"],["115447.03000000","0.17333000"],["115446.72000000","0.00005000"],["115446.29000000","0.00000000"],["115446.16000000","0.00005000"],["115445.99000000","0.00000000"],["115445.77000000","0.00000000"],["115445.68000000","0.00000000"],["115444.56000000","0.00000000"],["115443.99000000","0.00000000"],["115443.97000000","0.00000000"],["115443.86000000","0.04407000"],["115443.85000000","0.00000000"],["115443.66000000","0.06753000"],["115443.49000000","0.00000000"],["115442.91000000","0.00005000"],["115442.89000000","0.27659000"],["115441.99000000","0.00000000"],["115441.70000000","0.00000000"],["115441.67000000","0.00000000"],["115441.45000000","0.00000000"],["115440.96000000","0.24896000"],["115440.94000000","0.00000000"],["115440.82000000","0.00000000"],["115440.58000000","0.00000000"],["115440.39000000","0.00005000"],["115440.38000000","0.24949000"],["115440.20000000","0.00000000"],["115440.10000000","0.08824000"],["115440.07000000","0.00000000"],["115440.02000000","0.00000000"],["115440.01000000","0.17242000"],["115440.00000000","0.00005000"],["115439.99000000","1.16983000"],["115439.98000000","0.00000000"],["115439.95000000","0.00000000"],["115439.94000000","0.00250000"],["115439.92000000","0.00000000"],["115439.90000000","0.00000000"],["115439.05000000","0.00000000"],["115438.98000000","0.00005000"],["115438.84000000","0.00095000"],["115438.68000000","0.00583000"],["115438.25000000","0.00000000"],["115437.54000000","0.00000000"],["115437.12000000","0.00433000"],["115437.11000000","0.00191000"],["115436.36000000","0.00031000"],["115436.35000000","0.00300000"],["115436.03000000","0.00000000"],["115436.02000000","0.00000000"],["115436.00000000","0.00000000"],["115435.99000000","0.03995000"],["115435.49000000","0.00000000"],["115435.38000000","0.00347000"],["115435.33000000","0.00000000"],["115434.94000000","0.00005000"],["115434.85000000","0.00100000"],["115434.75000000","0.50670000"],["115434.74000000","0.00796000"],["115433.60000000","0.15813000"],["115433.59000000","0.00000000"],["115433.48000000","0.00009000"],["115433.46000000","0.00000000"],["115433.40000000","0.54080000"],["115433.07000000","0.00520000"],["115432.89000000","0.09676000"],["115432.52000000","0.00005000"],["115431.99000000","0.00007000"],["115431.25000000","0.00000000"],["115431.22000000","0.00000000"],["115430.79000000","0.00000000"],["115430.59000000","0.00086000"],["115430.46000000","0.03000000"],["115430.14000000","0.00000000"],["115430.07000000","0.00000000"],["115429.67000000","0.90125000"],["115428.56000000","0.00029000"],["115428.48000000","0.04330000"],["115428.47000000","0.00000000"],["115428.22000000","0.03000000"],["115426.98000000","0.03000000"],["115424.82000000","0.04000000"],["115424.53000000","0.00000000"],["115423.21000000","0.00000000"],["115422.42000000","0.00000000"],["115421.98000000","0.35495000"],["115421.18000000","0.00000000"],["115420.83000000","0.00000000"],["115418.77000000","0.00000000"],["115417.81000000","0.00029000"],["115417.37000000","0.00000000"],["115416.25000000","0.05690000"],["115413.27000000","0.00008000"],["115412.63000000","0.31191000"],["115410.40000000","0.00000000"],["115410.26000000","0.00000000"],["115408.88000000","0.25647000"],["115408.86000000","0.52094000"],["115408.85000000","0.00173000"],["115405.35000000","0.00000000"],["115404.67000000","0.00000000"],["115404.62000000","0.00009000"],["115403.14000000","0.00000000"],["115402.35000000","0.00000000"],["115401.53000000","0.03000000"],["115401.40000000","0.00000000"],["115400.96000000","0.00000000"],["115400.37000000","0.03000000"],["115400.12000000","0.00000000"],["115400.02000000","0.00029000"],["115395.95000000","0.00086000"],["115395.71000000","0.00000000"],["115395.36000000","0.00000000"],["115393.33000000","0.70073000"],["115388.46000000","0.00000000"],["115388.05000000","0.00000000"],["115386.36000000","0.00000000"],["115385.94000000","0.00000000"],["115382.69000000","0.00000000"],["115381.59000000","0.00000000"],["115380.81000000","0.00000000"],["115378.63000000","0.00008000"],["115374.01000000","0.00008000"],["115372.84000000","0.00000000"],["115366.01000000","0.00000000"],["115365.56000000","0.43314000"],["115365.49000000","0.00000000"],["115365.01000000","0.42207000"],["115364.96000000","0.43307000"],["115364.23000000","0.00000000"],["115362.46000000","0.00000000"],["115361.54000000","0.00000000"],["115361.30000000","0.00000000"],["115361.29000000","0.00000000"],["115361.22000000","0.00000000"],["115360.71000000","0.25975000"],["115356.05000000","0.00000000"],["115348.92000000","0.00000000"],["115348.23000000","0.00000000"],["115345.18000000","0.00000000"],["115344.00000000","0.00168000"],["115341.53000000","0.03025000"],["115340.87000000","0.00000000"],["115337.90000000","0.07597000"],["115335.83000000","0.04597000"],["115330.86000000","0.00000000"],["115329.55000000","0.00000000"],["115326.39000000","0.00215000"],["115326.23000000","0.00000000"],["115325.97000000","0.00000000"],["115325.87000000","0.00000000"],["115324.57000000","0.00000000"],["115319.01000000","0.00000000"],["115319.00000000","0.00000000"],["115313.80000000","0.00000000"],["115309.36000000","0.00008000"],["115296.23000000","0.00000000"],["115294.12000000","0.00000000"],["115290.61000000","0.00000000"],["115290.08000000","0.06000000"],["115284.26000000","0.48420000"],["115274.73000000","0.00008000"],["115270.05000000","0.00000000"],["115267.11000000","0.00000000"],["115264.01000000","0.00193000"],["115261.60000000","0.00000000"],["115256.03000000","0.00000000"],["115251.57000000","0.28492000"],["115218.24000000","0.01361000"],["115217.80000000","0.04597000"],["115211.42000000","0.00086000"],["115206.52000000","0.00000000"],["115196.63000000","0.00000000"],["115193.31000000","4.64032000"],["115182.74000000","0.00000000"],["115182.73000000","0.00000000"],["115172.53000000","0.01645000"],["115098.49000000","0.00000000"],["115092.72000000","0.00000000"],["115045.64000000","0.00000000"],["113716.18000000","0.00100000"],["113708.39000000","0.00000000"],["103902.00000000","0.00020000"],["103896.00000000","0.00000000"],["103895.00000000","0.00000000"],["92358.32000000","0.00021000"],["92352.00000000","0.00000000"],["33000.00000000","3.79030000"]],"a":[["115440.00000000","0.00000000"],["115440.01000000","0.00000000"],["115440.08000000","0.00000000"],["115440.11000000","0.00000000"],["115440.21000000","0.00000000"],["115440.39000000","0.00000000"],["115440.59000000","0.00000000"],["115440.83000000","0.00000000"],["115440.95000000","0.00000000"],["115440.97000000","0.00000000"],["115441.05000000","0.00000000"],["115441.46000000","0.00000000"],["115441.68000000","0.00000000"],["115442.00000000","0.00000000"],["115442.12000000","0.00000000"],["115442.90000000","0.00000000"],["115443.01000000","0.00000000"],["115443.86000000","0.00000000"],["115444.00000000","0.00000000"],["115444.56000000","0.00000000"],["115444.57000000","0.00000000"],["115444.59000000","0.00000000"],["115444.78000000","0.00000000"],["115445.17000000","0.00000000"],["115446.00000000","0.00000000"],["115446.16000000","0.00000000"],["115446.29000000","0.00000000"],["115446.30000000","0.00000000"],["115446.36000000","0.00000000"],["115446.73000000","0.00000000"],["115447.05000000","0.00000000"],["115447.19000000","0.00000000"],["115447.37000000","0.00000000"],["115447.38000000","0.00000000"],["115447.81000000","0.00000000"],["115447.90000000","0.00000000"],["115447.91000000","2.42429000"],["115447.92000000","0.04926000"],["115447.93000000","0.14744000"],["115447.99000000","0.00009000"],["115448.00000000","0.00130000"],["115448.40000000","0.00000000"],["115448.57000000","0.00000000"],["115448.59000000","0.00000000"],["115448.75000000","0.00000000"],["115449.06000000","0.00000000"],["115449.16000000","0.00010000"],["115449.17000000","0.03950000"],["115449.26000000","0.00000000"],["115449.28000000","0.00000000"],["115449.76000000","0.00000000"],["115449.77000000","0.00010000"],["115449.81000000","0.00381000"],["115450.00000000","0.00125000"],["115450.13000000","0.00000000"],["115450.57000000","0.00000000"],["115450.58000000","0.00000000"],["115450.77000000","0.00000000"],["115451.09000000","0.00000000"],["115451.21000000","0.00000000"],["115451.34000000","0.00010000"],["115451.35000000","0.00005000"],["115451.46000000","0.00000000"],["115451.47000000","0.00005000"],["115451.54000000","0.00703000"],["115452.00000000","0.00125000"],["115452.05000000","0.00005000"],["115452.07000000","0.00000000"],["115452.08000000","0.00155000"],["115452.17000000","0.00100000"],["115452.37000000","0.00000000"],["115452.43000000","0.00000000"],["115452.45000000","0.00010000"],["115452.46000000","0.34070000"],["115452.47000000","0.00005000"],["115452.83000000","0.00000000"],["115452.84000000","0.14726000"],["115452.89000000","0.00000000"],["115453.00000000","0.00531000"],["115454.00000000","0.00125000"],["115454.01000000","0.00000000"],["115454.07000000","0.00705000"],["115454.30000000","0.00000000"],["115454.34000000","0.00005000"],["115454.37000000","0.00000000"],["115454.43000000","0.01304000"],["115454.44000000","0.00269000"],["115454.80000000","0.01771000"],["115454.86000000","0.00000000"],["115454.87000000","0.04000000"],["115455.03000000","0.00009000"],["115455.10000000","0.00000000"],["115455.11000000","0.34651000"],["115455.57000000","0.00000000"],["115455.58000000","0.00005000"],["115455.59000000","0.00000000"],["115455.61000000","0.28581000"],["115456.00000000","0.00125000"],["115456.62000000","0.00300000"],["115456.71000000","0.00000000"],["115457.31000000","0.00000000"],["115457.32000000","0.00150000"],["115457.85000000","0.00000000"],["115458.06000000","0.43314000"],["115458.64000000","0.02599000"],["115459.46000000","0.08658000"],["115459.71000000","0.00000000"],["115460.53000000","0.00000000"],["115461.17000000","0.00000000"],["115461.20000000","0.00000000"],["115461.78000000","0.04587000"],["115462.14000000","0.25975000"],["115462.92000000","0.08532000"],["115462.98000000","0.30000000"],["115464.65000000","0.00000000"],["115464.94000000","0.00034000"],["115465.23000000","0.00151000"],["115465.25000000","0.00034000"],["115466.31000000","0.00866000"],["115467.25000000","0.01001000"],["115468.56000000","0.00433000"],["115468.57000000","0.00000000"],["115469.39000000","0.00000000"],["115470.30000000","0.00034000"],["115470.56000000","2.47869000"],["115470.68000000","0.08643000"],["115472.91000000","0.00000000"],["115475.16000000","0.00000000"],["115475.98000000","0.16996000"],["115477.74000000","0.00005000"],["115477.86000000","0.04169000"],["115478.00000000","0.01136000"],["115478.77000000","0.01201000"],["115479.52000000","0.00000000"],["115480.68000000","0.00000000"],["115482.01000000","0.00000000"],["115482.45000000","0.31172000"],["115482.54000000","0.00008000"],["115482.55000000","0.00300000"],["115484.43000000","0.05191000"],["115485.45000000","0.00000000"],["115486.68000000","0.00000000"],["115488.61000000","0.08000000"],["115488.76000000","0.00000000"],["115489.37000000","0.00000000"],["115490.29000000","0.00000000"],["115491.34000000","0.00005000"],["115494.64000000","0.00008000"],["115497.94000000","0.00000000"],["115497.95000000","0.03984000"],["115497.96000000","0.00000000"],["115498.09000000","0.00005000"],["115499.68000000","0.00000000"],["115499.86000000","0.00086000"],["115501.75000000","0.03234000"],["115503.61000000","0.08000000"],["115503.83000000","0.00000000"],["115503.86000000","0.00005000"],["115504.02000000","0.00000000"],["115504.89000000","0.00216000"],["115505.20000000","0.00000000"],["115505.99000000","0.00056000"],["115509.12000000","0.00000000"],["115510.96000000","0.65787000"],["115517.18000000","0.00008000"],["115517.43000000","0.00621000"],["115517.99000000","0.00214000"],["115520.79000000","0.00031000"],["115528.41000000","0.00000000"],["115530.00000000","0.00160000"],["115530.01000000","0.00000000"],["115535.21000000","0.00000000"],["115538.31000000","0.03400000"],["115538.65000000","0.00000000"],["115538.95000000","0.07072000"],["115541.42000000","0.00000000"],["115542.76000000","0.00000000"],["115546.72000000","0.02987000"],["115546.97000000","0.00000000"],["115551.81000000","0.00008000"],["115555.82000000","0.02837000"],["115560.00000000","0.01896000"],["115570.54000000","0.00000000"],["115570.85000000","0.00000000"],["115573.28000000","0.00000000"],["115586.45000000","0.00008000"],["115603.31000000","0.08805000"],["115607.91000000","0.00000000"],["115613.51000000","0.00000000"],["115620.90000000","0.00019000"],["115621.08000000","0.00008000"],["115621.98000000","0.00000000"],["115624.20000000","0.00000000"],["115632.87000000","0.00086000"],["115662.48000000","0.01645000"],["115691.77000000","0.08643000"],["115701.54000000","0.00000000"],["115710.73000000","0.00000000"],["115726.67000000","0.86408000"],["115735.91000000","0.00000000"],["115738.76000000","0.00000000"],["115746.90000000","0.01645000"],["115750.83000000","0.00009000"],["115753.71000000","0.02498000"],["115758.67000000","0.00000000"],["115779.68000000","0.00000000"],["115782.68000000","0.00000000"],["115785.46000000","0.01645000"],["115786.52000000","0.00000000"],["115800.95000000","0.01819000"],["115820.18000000","0.02350000"],["115821.97000000","0.02338000"],["115826.88000000","0.00015000"],["115829.66000000","0.02498000"],["115830.65000000","0.00000000"],["115839.96000000","0.00000000"],["115847.57000000","0.37961000"],["115857.55000000","0.03198000"],["115868.30000000","0.02252000"],["117171.60000000","0.00000000"],["117179.63000000","0.00100000"]]}
[2025-10-27T18:48:07.145Z] {"e":"depthUpdate","E":1761590887014,"s":"BTCUSDT","U":79129607433,"u":79129607942,"b":[["115447.90000000","6.40965000"],["115447.89000000","0.00090000"],["115447.82000000","0.00000000"],["115447.65000000","0.05015000"],["115447.60000000","0.05015000"],["115447.24000000","0.00000000"],["115447.23000000","0.00000000"],["115447.04000000","0.24204000"],["115447.03000000","0.00000000"],["115446.74000000","0.00000000"],["115444.60000000","0.00005000"],["115444.59000000","0.03914000"],["115444.56000000","0.00000000"],["115444.55000000","0.00000000"],["115443.87000000","0.00010000"],["115443.86000000","0.04407000"],["115443.66000000","0.00000000"],["115443.55000000","0.00000000"],["115442.92000000","0.00005000"],["115442.91000000","0.00000000"],["115442.90000000","0.00000000"],["115442.89000000","0.27659000"],["115442.83000000","0.17323000"],["115441.67000000","0.17323000"],["115441.46000000","0.04753000"],["115440.96000000","0.24891000"],["115440.43000000","0.00000000"],["115440.39000000","0.00005000"],["115440.38000000","0.00000000"],["115440.10000000","0.08819000"],["115440.01000000","0.24833000"],["115439.99000000","0.00333000"],["115438.68000000","0.00000000"],["115438.01000000","0.24949000"],["115437.81000000","0.00694000"],["115437.56000000","0.01710000"],["115437.12000000","0.00000000"],["115436.35000000","0.31800000"],["115435.99000000","0.00000000"],["115434.75000000","0.29013000"],["115434.08000000","0.00006000"],["115433.60000000","0.00000000"],["115433.41000000","0.00433000"],["115430.58000000","0.21657000"],["115429.68000000","0.15813000"],["115428.48000000","0.00000000"],["115425.78000000","0.31188000"],["115425.42000000","0.00000000"],["115424.82000000","0.00000000"],["115424.53000000","0.00000000"],["115422.34000000","0.04330000"],["115421.92000000","0.00000000"],["115420.00000000","0.00000000"],["115419.03000000","0.00583000"],["115418.82000000","0.04000000"],["115418.51000000","0.00000000"],["115418.50000000","0.00000000"],["115418.46000000","0.00000000"],["115416.65000000","0.86966000"],["115415.43000000","0.43307000"],["115415.17000000","0.43314000"],["115411.68000000","0.00000000"],["115407.42000000","0.00000000"],["115403.22000000","0.25975000"],["115400.80000000","0.00000000"],["115365.56000000","0.00000000"],["115364.96000000","0.00000000"],["115362.02000000","0.00008000"],["115358.97000000","0.43314000"],["115357.70000000","0.43307000"],["115354.75000000","0.00000000"],["115347.67000000","0.95468000"],["115318.50000000","0.00000000"],["115317.35000000","0.00000000"],["115315.20000000","0.00182000"],["115312.51000000","0.04008000"],["115306.82000000","0.00000000"],["113716.18000000","0.00100000"],["111947.87000000","0.00000000"],["111944.18000000","0.02174000"],["106188.23000000","0.00049000"],["103902.00000000","0.00020000"],["92358.32000000","0.00021000"],["42000.00000000","1.36431000"]],"a":[["115447.91000000","4.48306000"],["115447.92000000","0.04916000"],["115447.93000000","0.14744000"],["115448.00000000","0.00125000"],["115448.13000000","0.00017000"],["115448.47000000","0.00000000"],["115448.70000000","0.00000000"],["115448.71000000","0.00000000"],["115449.16000000","0.00000000"],["115449.17000000","0.00000000"],["115449.81000000","0.00386000"],["115450.00000000","0.00120000"],["115450.08000000","0.00000000"],["115450.09000000","0.00000000"],["115450.15000000","0.00005000"],["115450.54000000","0.28583000"],["115450.58000000","0.00000000"],["115450.59000000","0.00000000"],["115451.30000000","0.00005000"],["115451.34000000","0.00000000"],["115451.35000000","0.00000000"],["115451.54000000","0.00703000"],["115452.05000000","0.00000000"],["115452.07000000","0.00010000"],["115452.08000000","0.08818000"],["115452.83000000","0.00005000"],["115452.84000000","0.14726000"],["115452.86000000","0.00005000"],["115453.00000000","0.00536000"],["115453.20000000","0.00000000"],["115453.80000000","0.00250000"],["115454.00000000","0.06230000"],["115454.07000000","0.00700000"],["115454.43000000","0.01304000"],["115454.44000000","0.00264000"],["115454.80000000","0.01709000"],["115454.87000000","0.00000000"],["115455.61000000","0.00000000"],["115455.93000000","0.04587000"],["115456.50000000","0.00000000"],["115456.51000000","0.00000000"],["115456.62000000","0.00305000"],["115458.06000000","0.00000000"],["115458.42000000","0.00250000"],["115458.71000000","0.00000000"],["115459.46000000","0.00000000"],["115460.53000000","0.00005000"],["115461.78000000","0.00000000"],["115461.99000000","0.00433000"],["115468.56000000","0.00000000"],["115468.57000000","0.16996000"],["115470.68000000","0.00000000"],["115474.26000000","0.04416000"],["115475.79000000","0.00000000"],["115475.98000000","0.00000000"],["115476.73000000","0.00583000"],["115476.75000000","0.00000000"],["115476.90000000","0.00000000"],["115477.28000000","0.00000000"],["115477.29000000","0.00000000"],["115477.61000000","0.31174000"],["115477.74000000","0.00000000"],["115477.86000000","0.00000000"],["115478.77000000","0.00000000"],["115480.83000000","0.43284000"],["115481.67000000","0.06988000"],["115482.55000000","1.12896000"],["115482.64000000","0.03234000"],["115487.00000000","0.06100000"],["115490.59000000","0.06538000"],["115491.46000000","0.03446000"],["115494.66000000","0.27250000"],["115495.73000000","0.00000000"],["115501.75000000","0.00000000"],["115502.68000000","0.00000000"],["115509.70000000","0.00000000"],["115510.96000000","0.00000000"],["115512.82000000","0.00000000"],["115513.30000000","0.00000000"],["115514.76000000","0.00000000"],["115526.18000000","0.00000000"],["115526.34000000","0.00000000"],["115538.31000000","0.00000000"],["115538.32000000","0.00000000"],["115538.95000000","0.00000000"],["115539.27000000","0.03400000"],["115545.86000000","0.00000000"],["115570.54000000","0.03218000"],["115572.29000000","0.00005000"],["115612.66000000","0.00000000"],["115620.44000000","0.00086000"],["115730.48000000","0.00000000"],["115753.66000000","0.02498000"],["115800.20000000","0.00000000"],["115801.68000000","0.00000000"],["115803.21000000","0.00000000"],["115839.37000000","0.00000000"],["115843.77000000","0.37961000"],["115847.57000000","0.00000000"],["115857.04000000","0.00037000"],["115896.81000000","0.00000000"],["115953.85000000","0.00007000"],["117179.63000000","0.00100000"]]}
[2025-10-27T18:48:08.150Z] {"e":"depthUpdate","E":1761590888014,"s":"BTCUSDT","U":79129607943,"u":79129608110,"b":[["115447.90000000","6.55188000"],["115447.89000000","0.00085000"],["115447.04000000","0.24204000"],["115446.74000000","0.00000000"],["115446.73000000","0.00000000"],["115446.36000000","0.00000000"],["115446.02000000","0.03923000"],["115445.39000000","0.00010000"],["115445.38000000","0.03935000"],["115444.60000000","0.00000000"],["115444.59000000","0.00000000"],["115443.87000000","0.00005000"],["115442.83000000","0.17328000"],["115441.46000000","0.04748000"],["115439.44000000","0.00005000"],["115425.87000000","0.00000000"],["115423.46000000","0.00866000"],["115419.03000000","0.00000000"],["115418.88000000","0.00583000"],["115418.00000000","0.00120000"],["115416.00000000","0.00120000"],["115414.29000000","0.08663000"],["115414.00000000","0.00120000"],["115412.00000000","0.00120000"],["115410.07000000","0.93300000"],["115410.00000000","0.00120000"],["115408.00000000","0.00120000"],["115405.59000000","1.31082000"],["115366.78000000","0.00000000"],["115336.12000000","0.81018000"],["115311.68000000","0.00243000"],["115298.84000000","0.00000000"],["113716.18000000","0.00100000"],["103903.00000000","0.00000000"],["103902.00000000","0.00020000"],["92358.32000000","0.00021000"],["92352.00000000","0.00000000"],["60000.00000000","57.97732000"]],"a":[["115447.91000000","4.52306000"],["115447.92000000","0.04911000"],["115447.93000000","0.14744000"],["115450.53000000","0.00000000"],["115450.54000000","0.00000000"],["115452.46000000","0.19612000"],["115452.83000000","0.00005000"],["115452.84000000","0.43308000"],["115452.86000000","0.00000000"],["115454.07000000","0.00705000"],["115455.11000000","0.00000000"],["115457.32000000","0.00155000"],["115458.64000000","0.00000000"],["115460.03000000","0.02599000"],["115461.99000000","0.00000000"],["115463.38000000","0.00433000"],["115466.31000000","0.00000000"],["115468.73000000","0.00866000"],["115470.09000000","0.08643000"],["115476.26000000","0.00000000"],["115476.61000000","0.00583000"],["115476.73000000","0.00000000"],["115477.98000000","0.00000000"],["115482.55000000","0.43607000"],["115482.79000000","0.25975000"],["115493.98000000","0.03198000"],["115498.26000000","0.00005000"],["115522.50000000","0.27767000"],["115526.76000000","0.43314000"],["115526.78000000","0.00000000"],["115527.49000000","0.34651000"],["115528.97000000","0.25975000"],["115534.57000000","0.00100000"],["115534.58000000","0.00100000"],["115545.43000000","0.00000000"],["115546.81000000","0.02500000"],["115562.57000000","0.00243000"],["115826.27000000","0.00000000"],["115827.75000000","0.02498000"],["115828.95000000","0.02498000"],["115830.17000000","0.02498000"],["115857.22000000","0.03198000"],["116026.12000000","0.00000000"],["116112.38000000","0.00000000"],["116211.74000000","0.00000000"],["116323.53000000","0.00000000"],["116447.24000000","0.00000000"],["116505.74000000","0.04696000"],["117179.63000000","0.00100000"]]}
[2025-10-27T18:48:09.146Z] {"e":"depthUpdate","E":1761590889014,"s":"BTCUSDT","U":79129608111,"u":79129608248,"b":[["115447.90000000","6.73018000"],["115447.89000000","0.00085000"],["115447.60000000","0.05015000"],["115447.20000000","0.00000000"],["115447.19000000","0.00000000"],["115447.10000000","0.00000000"],["115447.04000000","0.24204000"],["115446.03000000","0.00000000"],["115446.02000000","0.00000000"],["115445.57000000","0.00000000"],["115445.39000000","0.00000000"],["115445.38000000","0.00000000"],["115443.87000000","0.00010000"],["115443.86000000","0.04412000"],["115442.90000000","0.00005000"],["115441.67000000","0.17328000"],["115437.14000000","0.00005000"],["115435.98000000","0.00005000"],["115435.82000000","0.02599000"],["115419.69000000","0.00583000"],["115418.88000000","0.00000000"],["115418.54000000","0.00000000"],["115404.90000000","0.00000000"],["115370.24000000","0.00000000"],["115340.48000000","0.33868000"],["115336.12000000","0.79722000"],["115334.32000000","0.18709000"],["115317.49000000","0.00000000"],["115284.26000000","0.02339000"],["114000.00000000","23.21365000"],["113716.18000000","0.00100000"],["112000.00000000","17.07486000"],["103902.00000000","0.00020000"],["92358.32000000","0.00021000"]],"a":[["115447.91000000","4.47643000"],["115476.61000000","0.00000000"],["115477.29000000","0.00583000"],["115477.67000000","0.00000000"],["115482.55000000","1.21572000"],["115492.44000000","0.03198000"],["115501.96000000","0.00000000"],["115505.18000000","0.00005000"],["115512.80000000","0.31637000"],["115522.50000000","0.18243000"],["115526.35000000","0.00000000"],["115526.49000000","0.00000000"],["115526.76000000","0.00000000"],["115527.49000000","0.00000000"],["115563.23000000","0.00009000"],["115586.47000000","0.00009000"],["115638.73000000","0.00009000"],["115713.69000000","0.00009000"],["115808.70000000","0.00009000"],["115922.11000000","0.00009000"],["115950.00000000","0.06461000"],["117179.63000000","0.00100000"],["118211.31000000","0.18627000"],["118557.67000000","0.18627000"],["118904.03000000","0.18627000"],["119250.39000000","0.18627000"],["119596.75000000","0.18627000"],["119943.11000000","0.18627000"],["120289.47000000","0.18666000"]]}
[2025-10-27T18:48:10.153Z] {"e":"depthUpdate","E":1761590890014,"s":"BTCUSDT","U":79129608249,"u":79129608498,"b":[["115447.90000000","6.88260000"],["115447.89000000","0.00030000"],["115447.04000000","0.24204000"],["115444.52000000","0.00005000"],["115444.51000000","0.04758000"],["115443.86000000","0.04407000"],["115442.90000000","0.00000000"],["115441.67000000","0.17328000"],["115441.46000000","0.00000000"],["115438.02000000","0.00433000"],["115433.41000000","0.00000000"],["115425.56000000","0.05558000"],["115423.20000000","0.00300000"],["115422.09000000","0.00583000"],["115421.80000000","0.00000000"],["115419.69000000","0.00000000"],["115370.24000000","0.00005000"],["115322.60000000","0.09389000"],["115321.55000000","0.00000000"],["115321.32000000","0.00000000"],["115317.48000000","0.00346000"],["115290.88000000","0.00000000"],["113716.18000000","0.00100000"],["103903.00000000","0.00000000"],["103902.00000000","0.00020000"],["92358.32000000","0.00021000"]],"a":[["115447.91000000","2.00334000"],["115447.92000000","0.04931000"],["115447.93000000","0.14749000"],["115448.66000000","0.00000000"],["115450.77000000","0.00000000"],["115451.16000000","0.03953000"],["115451.54000000","0.00708000"],["115451.76000000","0.00010000"],["115451.77000000","0.04010000"],["115452.07000000","0.00000000"],["115452.08000000","0.00155000"],["115452.46000000","0.21471000"],["115452.84000000","0.14726000"],["115453.00000000","0.00531000"],["115453.08000000","0.29234000"],["115453.80000000","0.00000000"],["115454.00000000","0.00120000"],["115454.07000000","0.00000000"],["115454.43000000","0.01309000"],["115454.44000000","0.00259000"],["115454.80000000","0.00000000"],["115455.32000000","0.00000000"],["115455.37000000","0.28581000"],["115455.93000000","0.00000000"],["115457.32000000","0.00150000"],["115457.99000000","0.59770000"],["115458.00000000","0.00120000"],["115458.01000000","0.00000000"],["115458.02000000","0.00000000"],["115458.03000000","0.00000000"],["115458.46000000","0.04587000"],["115459.46000000","0.08658000"],["115460.94000000","0.00069000"],["115462.14000000","0.00000000"],["115463.38000000","0.00000000"],["115465.22000000","0.00000000"],["115467.24000000","0.00433000"],["115468.57000000","0.00000000"],["115470.19000000","0.43314000"],["115470.89000000","0.34651000"],["115471.20000000","0.43307000"],["115471.87000000","0.16996000"],["115476.90000000","0.00250000"],["115477.61000000","0.00000000"],["115480.83000000","0.43284000"],["115482.55000000","0.00300000"],["115482.64000000","0.00000000"],["115489.83000000","0.17684000"],["115495.25000000","0.31169000"],["115495.92000000","0.03234000"],["115504.16000000","0.25975000"],["115522.50000000","0.25181000"],["115526.56000000","0.00000000"],["115526.64000000","0.34651000"],["115526.75000000","0.43307000"],["115526.77000000","0.43314000"],["115529.73000000","0.12811000"],["115759.90000000","0.00000000"],["115798.75000000","0.01732000"],["116052.79000000","0.00009000"],["116199.86000000","0.00009000"],["116362.66000000","0.00009000"],["116439.65000000","0.00009000"],["116825.87000000","0.18627000"],["117172.23000000","0.18627000"],["117179.63000000","0.00100000"],["117518.59000000","0.18627000"],["117864.95000000","0.18627000"]]}
[2025-10-27T18:48:11.151Z] {"e":"depthUpdate","E":1761590891015,"s":"BTCUSDT","U":79129608499,"u":79129608714,"b":[["115447.90000000","6.84069000"],["115447.89000000","0.00045000"],["115446.75000000","0.00095000"],["115445.02000000","0.00191000"],["115444.52000000","0.00010000"],["115443.29000000","0.00347000"],["115442.92000000","0.00000000"],["115441.67000000","0.17328000"],["115440.98000000","0.00520000"],["115440.43000000","0.00025000"],["115438.02000000","0.00000000"],["115438.01000000","0.00000000"],["115437.81000000","0.00000000"],["115437.11000000","0.00000000"],["115435.83000000","0.00433000"],["115434.75000000","0.30579000"],["115433.40000000","0.00000000"],["115433.07000000","0.00000000"],["115431.87000000","0.00000000"],["115427.83000000","0.00000000"],["115422.09000000","0.00000000"],["115418.62000000","0.00583000"],["115414.31000000","0.94382000"],["115410.07000000","0.00000000"],["115324.69000000","0.00000000"],["115324.53000000","0.00000000"],["115324.35000000","0.00000000"],["115322.60000000","0.00000000"],["115094.07000000","0.18627000"],["111955.25000000","0.02174000"],["111944.18000000","0.00000000"],["106000.00000000","39.49229000"],["103902.00000000","0.00020000"],["92358.32000000","0.00021000"],["92358.00000000","0.00000000"]],"a":[["115447.91000000","4.38999000"],["115447.92000000","0.14102000"],["115447.93000000","0.14749000"],["115449.33000000","0.00000000"],["115450.00000000","0.00125000"],["115450.41000000","0.00000000"],["115450.79000000","0.00191000"],["115450.82000000","0.00005000"],["115450.83000000","0.28593000"],["115451.15000000","0.00000000"],["115451.16000000","0.00000000"],["115451.77000000","0.04010000"],["115452.08000000","0.08818000"],["115452.45000000","0.00005000"],["115452.46000000","0.14610000"],["115452.83000000","0.00000000"],["115453.08000000","0.00000000"],["115453.11000000","0.00000000"],["115454.43000000","0.01304000"],["115454.44000000","0.00269000"],["115454.83000000","0.00520000"],["115455.32000000","0.01696000"],["115455.37000000","0.00000000"],["115455.46000000","0.00708000"],["115456.62000000","0.00305000"],["115456.84000000","0.00000000"],["115457.72000000","0.00381000"],["115457.97000000","1.50077000"],["115457.98000000","3.01912000"],["115457.99000000","0.00000000"],["115459.45000000","0.00693000"],["115459.46000000","0.00000000"],["115460.94000000","0.00000000"],["115470.09000000","0.00000000"],["115470.89000000","0.00000000"],["115472.87000000","0.08643000"],["115476.38000000","0.00583000"],["115477.29000000","0.00000000"],["115477.58000000","0.31174000"],["115482.55000000","0.34951000"],["115495.25000000","0.00000000"],["115526.41000000","0.04597000"],["115526.64000000","0.00000000"],["115526.75000000","0.00000000"],["115526.77000000","0.00000000"],["115529.73000000","0.00000000"],["116133.15000000","0.18627000"],["116479.51000000","0.18627000"],["117179.63000000","0.00100000"]]}
[2025-10-27T18:48:12.297Z] {"e":"depthUpdate","E":1761590892014,"s":"BTCUSDT","U":79129608715,"u":79129608909,"b":[["115447.90000000","6.87772000"],["115447.89000000","0.00055000"],["115447.85000000","0.00060000"],["115447.84000000","0.00000000"],["115447.83000000","0.00009000"],["115447.60000000","0.05015000"],["115447.04000000","0.24204000"],["115444.52000000","0.00000000"],["115444.51000000","0.00000000"],["115443.87000000","0.00010000"],["115443.86000000","0.04412000"],["115442.92000000","0.00005000"],["115442.90000000","0.00005000"],["115441.67000000","0.17328000"],["115441.30000000","0.04753000"],["115440.03000000","0.25643000"],["115420.63000000","0.08660000"],["115418.72000000","0.00583000"],["115418.62000000","0.00000000"],["115377.04000000","0.00000000"],["115353.13000000","0.01356000"],["115346.83000000","0.00000000"],["115334.41000000","0.00000000"],["115326.38000000","0.00000000"],["115324.01000000","0.00000000"],["115303.04000000","0.00000000"],["115284.84000000","0.00000000"],["114747.71000000","0.18627000"],["114401.35000000","0.18627000"],["114054.99000000","0.18627000"],["113716.18000000","0.00100000"],["113708.63000000","0.18627000"],["110026.70000000","0.00000000"],["106188.23000000","0.00059000"],["103903.00000000","0.00000000"],["103902.00000000","0.00020000"],["92358.32000000","0.00021000"],["50865.70000000","0.00000000"],["50864.80000000","0.00000000"],["33000.00000000","3.79030000"]],"a":[["115447.91000000","4.38911000"],["115447.92000000","0.04926000"],["115447.93000000","0.14749000"],["115450.82000000","0.00000000"],["115450.83000000","0.00000000"],["115451.77000000","0.04010000"],["115452.00000000","0.00125000"],["115452.06000000","0.00010000"],["115452.07000000","0.19262000"],["115452.08000000","0.08818000"],["115452.17000000","0.00100000"],["115452.45000000","0.00000000"],["115452.46000000","0.00000000"],["115453.00000000","0.00536000"],["115453.11000000","0.28587000"],["115453.80000000","0.00250000"],["115454.00000000","0.06220000"],["115454.83000000","0.00525000"],["115455.29000000","0.04587000"],["115456.62000000","0.00305000"],["115458.46000000","0.00000000"],["115462.18000000","0.07031000"],["115470.19000000","0.00000000"],["115476.90000000","0.00000000"],["115482.55000000","0.26275000"],["115482.79000000","0.00000000"],["115502.16000000","0.01356000"],["115522.50000000","0.32935000"],["115526.34000000","0.00000000"],["115526.37000000","0.34651000"],["115526.67000000","0.43314000"],["115528.73000000","0.25975000"],["115528.97000000","0.00000000"],["117179.63000000","0.00100000"]]}
[2025-10-27T18:48:13.144Z] {"e":"depthUpdate","E":1761590893014,"s":"BTCUSDT","U":79129608910,"u":79129608969,"b":[["115447.90000000","6.83768000"],["115445.71000000","0.00000000"],["115423.46000000","0.00000000"],["115418.72000000","0.00000000"],["115418.63000000","0.00583000"],["115406.64000000","0.00000000"],["115079.39000000","0.01645000"],["115060.80000000","0.02498000"],["115059.82000000","0.02498000"],["114043.17000000","0.00000000"],["113716.18000000","0.00100000"],["113362.27000000","0.18627000"],["113015.91000000","0.18627000"],["112669.55000000","0.18627000"],["112323.19000000","0.18627000"],["106188.23000000","0.00049000"],["103902.00000000","0.00020000"],["92358.32000000","0.00021000"]],"a":[["115447.91000000","4.41448000"],["115468.73000000","0.00000000"],["115476.38000000","0.00000000"],["115476.88000000","0.00583000"],["115478.78000000","0.00000000"],["115482.55000000","0.26275000"],["115485.62000000","0.00000000"],["115492.43000000","0.02507000"],["115526.32000000","0.00000000"],["115526.50000000","0.43314000"],["115526.67000000","0.00000000"],["115800.39000000","0.01645000"],["116300.00000000","3.12791000"],["117179.63000000","0.00100000"]]}
[2025-10-27T18:48:14.144Z] {"e":"depthUpdate","E":1761590894014,"s":"BTCUSDT","U":79129608970,"u":79129609033,"b":[["115447.90000000","6.83766000"],["115447.89000000","0.00060000"],["115447.72000000","0.00000000"],["115447.04000000","0.24204000"],["115443.95000000","0.00005000"],["115443.94000000","0.04005000"],["115443.86000000","0.04407000"],["115442.90000000","0.00000000"],["115425.46000000","0.00866000"],["115420.04000000","0.00583000"],["115418.70000000","0.00000000"],["115418.63000000","0.00000000"],["115408.49000000","0.17697000"],["115403.14000000","0.33260000"],["115400.11000000","0.00000000"],["115390.19000000","0.00000000"],["113716.18000000","0.00100000"],["111976.83000000","0.18627000"],["111630.47000000","0.18627000"],["111284.11000000","0.18627000"],["110937.75000000","0.18627000"],["110021.85000000","0.00090000"],["103903.00000000","0.00000000"],["103902.00000000","0.00020000"],["98000.00000000","96.52772000"],["92358.32000000","0.00021000"],["92358.00000000","0.00000000"]],"a":[["115447.91000000","4.48746000"],["115472.94000000","0.00000000"],["115478.72000000","0.00000000"],["115480.83000000","0.61767000"],["115482.55000000","0.69589000"],["115522.50000000","0.25181000"],["115526.29000000","0.00000000"],["115526.37000000","0.00000000"],["115526.39000000","0.34651000"],["115526.50000000","0.00000000"],["117179.63000000","0.00100000"]]}
[2025-10-27T18:48:15.165Z] {"e":"depthUpdate","E":1761590895014,"s":"BTCUSDT","U":79129609034,"u":79129609169,"b":[["115447.90000000","6.83755000"],["115447.89000000","0.00060000"],["115447.63000000","0.03932000"],["115447.04000000","0.24204000"],["115446.54000000","0.00000000"],["115445.57000000","0.00005000"],["115443.95000000","0.00010000"],["115443.94000000","0.04010000"],["115443.87000000","0.00005000"],["115441.30000000","0.04748000"],["115435.82000000","0.00000000"],["115435.74000000","0.02599000"],["115420.04000000","0.00000000"],["115418.61000000","0.03000000"],["115418.53000000","0.00583000"],["115193.31000000","0.00000000"],["115191.67000000","4.66928000"],["113716.18000000","0.00100000"],["110591.39000000","0.18627000"],["110245.03000000","0.18693000"],["103902.00000000","0.00020000"],["95000.00000000","84.76596000"],["92358.32000000","0.00021000"],["42000.00000000","1.36531000"]],"a":[["115447.91000000","4.05963000"],["115447.92000000","0.04926000"],["115447.93000000","0.14749000"],["115448.10000000","0.03855000"],["115450.72000000","0.00000000"],["115450.73000000","0.00000000"],["115452.00000000","0.00125000"],["115452.07000000","0.16674000"],["115452.08000000","0.00155000"],["115452.83000000","0.00005000"],["115453.00000000","0.00536000"],["115453.08000000","0.28587000"],["115453.11000000","0.00000000"],["115454.00000000","0.06225000"],["115456.62000000","0.00300000"],["115459.46000000","0.08658000"],["115466.81000000","0.00866000"],["115471.20000000","0.00000000"],["115480.83000000","0.43284000"],["115482.55000000","0.26275000"],["115526.32000000","0.43307000"],["115526.39000000","0.00000000"],["115526.78000000","0.43314000"],["115527.46000000","0.34651000"],["115529.84000000","0.12728000"],["115690.11000000","0.08643000"],["115691.77000000","0.00000000"],["117179.63000000","0.00100000"]]}
[2025-10-27T18:48:16.146Z] {"e":"depthUpdate","E":1761590896014,"s":"BTCUSDT","U":79129609170,"u":79129609480,"b":[["115447.90000000","6.69603000"],["115447.89000000","0.00060000"],["115447.65000000","0.05015000"],["115447.64000000","0.00000000"],["115447.63000000","0.00000000"],["115447.60000000","0.05015000"],["115446.81000000","0.00000000"],["115446.75000000","0.00095000"],["115446.63000000","0.00000000"],["115445.57000000","0.00000000"],["115445.02000000","0.00191000"],["115444.54000000","0.00000000"],["115444.45000000","0.00000000"],["115443.94000000","0.04010000"],["115443.87000000","0.00005000"],["115443.29000000","0.00347000"],["115442.92000000","0.00005000"],["115442.89000000","0.27659000"],["115442.83000000","0.00000000"],["115441.30000000","0.04753000"],["115440.98000000","0.00520000"],["115440.47000000","0.17323000"],["115440.03000000","0.00000000"],["115438.84000000","0.00000000"],["115438.14000000","0.00000000"],["115438.09000000","0.00381000"],["115438.03000000","0.24949000"],["115436.36000000","0.00724000"],["115435.38000000","0.00000000"],["115425.46000000","0.00000000"],["115419.58000000","0.00583000"],["115419.45000000","0.00000000"],["115418.98000000","0.00000000"],["115418.53000000","0.00000000"],["115382.34000000","0.00866000"],["115229.55000000","0.01356000"],["115218.24000000","0.00005000"],["114801.00000000","0.00090000"],["114800.00000000","0.68105000"],["113716.18000000","0.00100000"],["111955.25000000","0.00000000"],["111940.50000000","0.02174000"],["103903.00000000","0.00000000"],["103902.00000000","0.00020000"],["92358.32000000","0.00021000"],["41561.25000000","0.00015000"]],"a":[["115447.91000000","4.74330000"],["115447.92000000","0.12903000"],["115447.93000000","0.14749000"],["115448.00000000","0.00130000"],["115448.09000000","0.00010000"],["115448.10000000","0.03916000"],["115448.49000000","0.00000000"],["115448.50000000","0.00000000"],["115449.06000000","0.00095000"],["115449.77000000","0.00005000"],["115449.81000000","0.00000000"],["115450.76000000","0.00005000"],["115450.77000000","0.28593000"],["115450.79000000","0.00191000"],["115450.81000000","0.00000000"],["115450.82000000","0.00000000"],["115451.47000000","0.00000000"],["115451.54000000","0.00005000"],["115451.76000000","0.00000000"],["115451.77000000","0.00000000"],["115452.00000000","0.00130000"],["115452.07000000","0.10637000"],["115452.08000000","0.08818000"],["115452.17000000","0.00105000"],["115452.52000000","0.00347000"],["115452.83000000","0.00000000"],["115453.00000000","0.00536000"],["115453.08000000","0.00000000"],["115454.00000000","0.06225000"],["115454.43000000","0.01304000"],["115454.83000000","0.00525000"],["115456.00000000","0.00125000"],["115456.62000000","0.00300000"],["115457.72000000","0.00381000"],["115459.45000000","0.00693000"],["115459.46000000","0.00000000"],["115466.81000000","0.00000000"],["115472.93000000","0.00000000"],["115476.88000000","0.00000000"],["115477.22000000","0.00583000"],["115480.83000000","0.74694000"],["115482.55000000","1.21572000"],["115489.78000000","0.31170000"],["115492.21000000","0.00000000"],["115522.50000000","0.18243000"],["115526.26000000","0.25975000"],["115526.30000000","0.00000000"],["115526.32000000","0.00000000"],["115526.78000000","0.00000000"],["115527.46000000","0.00000000"],["115528.73000000","0.00000000"],["115534.21000000","0.00100000"],["115534.22000000","0.00100000"],["115534.57000000","0.00000000"],["115534.58000000","0.00000000"],["116500.00000000","37.01850000"],["117179.63000000","0.00100000"]]}
[2025-10-27T18:48:17.146Z] {"e":"depthUpdate","E":1761590897014,"s":"BTCUSDT","U":79129609481,"u":79129609805,"b":[["115447.90000000","7.13909000"],["115447.89000000","0.00035000"],["115447.85000000","0.00060000"],["115447.75000000","0.00000000"],["115447.74000000","0.00000000"],["115447.60000000","0.05015000"],["115447.54000000","0.00005000"],["115447.53000000","0.17333000"],["115447.41000000","0.00000000"],["115447.26000000","0.00000000"],["115447.04000000","0.24204000"],["115446.70000000","0.00000000"],["115446.69000000","0.00000000"],["115444.65000000","0.00000000"],["115443.95000000","0.00005000"],["115443.94000000","0.04005000"],["115443.87000000","0.00000000"],["115441.67000000","0.17328000"],["115441.30000000","0.00000000"],["115440.47000000","0.00000000"],["115439.67000000","0.00694000"],["115438.50000000","0.00100000"],["115437.99000000","0.00000000"],["115434.85000000","0.00000000"],["115433.26000000","0.54080000"],["115430.38000000","0.31187000"],["115424.18000000","0.00866000"],["115419.58000000","0.00000000"],["115419.57000000","0.00583000"],["115412.63000000","0.00000000"],["115382.34000000","0.00000000"],["115360.71000000","0.00000000"],["115332.94000000","0.02813000"],["115322.29000000","0.09389000"],["115320.81000000","0.00000000"],["115191.67000000","0.00000000"],["115191.66000000","4.62930000"],["113716.18000000","0.00100000"],["103902.00000000","0.00020000"],["92358.32000000","0.00021000"],["92358.00000000","0.00000000"],["42000.00000000","1.36431000"],["41561.25000000","0.00045000"],["33000.00000000","3.79030000"]],"a":[["115447.91000000","1.52480000"],["115447.92000000","0.01458000"],["115447.93000000","0.00020000"],["115448.10000000","0.03916000"],["115450.76000000","0.00000000"],["115450.77000000","0.00000000"],["115452.00000000","0.00125000"],["115452.04000000","0.00010000"],["115452.05000000","0.26882000"],["115452.06000000","0.29239000"],["115452.07000000","0.00000000"],["115452.08000000","0.00150000"],["115452.17000000","0.00005000"],["115452.47000000","0.00000000"],["115452.52000000","0.00352000"],["115452.83000000","0.00005000"],["115453.00000000","0.00536000"],["115453.80000000","0.00000000"],["115454.00000000","0.00120000"],["115454.43000000","0.01309000"],["115454.83000000","0.00525000"],["115455.29000000","0.00000000"],["115455.32000000","0.01701000"],["115455.46000000","0.00005000"],["115455.77000000","0.28581000"],["115455.92000000","0.00100000"],["115456.62000000","0.00305000"],["115457.97000000","0.74244000"],["115457.98000000","0.54080000"],["115458.91000000","0.04587000"],["115459.46000000","0.08658000"],["115460.67000000","0.25975000"],["115471.07000000","0.34651000"],["115471.21000000","0.43307000"],["115472.39000000","0.43314000"],["115476.90000000","0.00250000"],["115477.22000000","0.00000000"],["115477.58000000","0.00000000"],["115480.83000000","0.43284000"],["115482.55000000","0.00300000"],["115483.50000000","0.25975000"],["115487.47000000","0.14719000"],["115494.55000000","0.31169000"],["115522.50000000","0.32935000"],["115526.26000000","0.34651000"],["115526.39000000","0.43307000"],["115526.49000000","0.00000000"],["115527.27000000","0.43314000"],["115529.68000000","0.25975000"],["115534.21000000","0.00000000"],["115534.22000000","0.00000000"],["115534.57000000","0.00100000"],["115534.58000000","0.00100000"],["115546.81000000","0.00000000"],["115546.82000000","0.02500000"],["115690.11000000","0.00000000"],["115691.78000000","0.08643000"],["117179.63000000","0.00100000"]]}
[2025-10-27T18:48:18.144Z] {"e":"depthUpdate","E":1761590898014,"s":"BTCUSDT","U":79129609806,"u":79129610020,"b":[["115447.90000000","7.17769000"],["115447.89000000","0.00040000"],["115447.60000000","0.05015000"],["115447.54000000","0.36371000"],["115447.53000000","0.17333000"],["115447.05000000","0.00000000"],["115447.04000000","0.00000000"],["115440.98000000","0.00525000"],["115440.91000000","0.24949000"],["115439.99000000","0.00000000"],["115438.03000000","0.00000000"],["115434.72000000","0.00000000"],["115422.73000000","0.08660000"],["115421.98000000","0.35513000"],["115420.63000000","0.00000000"],["115419.57000000","0.00000000"],["115419.08000000","0.00000000"],["115418.95000000","0.00583000"],["115418.92000000","0.00000000"],["115418.67000000","0.00000000"],["115414.77000000","0.00440000"],["115414.31000000","0.00000000"],["115410.82000000","0.93294000"],["115403.22000000","0.00000000"],["115396.35000000","0.00000000"],["115392.00000000","0.00160000"],["115368.87000000","0.25975000"],["115340.48000000","0.32572000"],["115324.77000000","0.09389000"],["115324.49000000","0.00000000"],["115324.24000000","0.00000000"],["115323.88000000","0.00000000"],["115322.29000000","0.00000000"],["115248.00000000","0.00052000"],["115229.00000000","0.00057000"],["115124.00000000","0.00000000"],["115116.00000000","0.00000000"],["114984.00000000","0.00043000"],["114578.00000000","0.00000000"],["114558.00000000","0.00000000"],["114522.00000000","0.00000000"],["114428.67000000","0.00251000"],["114082.00000000","0.00000000"],["114044.00000000","0.12360000"],["113958.00000000","0.00000000"],["113886.00000000","0.01327000"],["113716.18000000","0.00100000"],["113655.00000000","0.00026000"],["113611.00000000","0.00000000"],["113453.00000000","0.00005000"],["113034.00000000","0.00000000"],["112458.00000000","0.00052000"],["106188.23000000","0.00049000"],["103903.00000000","0.00000000"],["103902.00000000","0.00020000"],["92358.32000000","0.00021000"],["60000.00000000","57.97732000"]],"a":[["115447.91000000","1.52313000"],["115447.92000000","0.00075000"],["115447.93000000","0.00000000"],["115448.00000000","0.00140000"],["115448.09000000","0.00000000"],["115448.10000000","0.00005000"],["115449.06000000","0.00100000"],["115450.00000000","0.00130000"],["115452.83000000","0.00010000"],["115452.84000000","0.14731000"],["115453.00000000","0.00531000"],["115454.43000000","0.01314000"],["115455.32000000","0.01701000"],["115455.46000000","0.00723000"],["115455.76000000","0.00010000"],["115457.98000000","0.00000000"],["115460.03000000","0.00000000"],["115460.09000000","0.00000000"],["115460.10000000","0.02604000"],["115460.87000000","0.00000000"],["115460.92000000","0.00000000"],["115460.94000000","0.00000000"],["115461.18000000","0.00070000"],["115462.14000000","0.00000000"],["115462.18000000","0.00000000"],["115462.20000000","0.00000000"],["115462.31000000","0.07031000"],["115468.11000000","0.00866000"],["115472.87000000","0.00000000"],["115474.41000000","0.08643000"],["115477.33000000","0.00583000"],["115528.86000000","1.10104000"],["115618.00000000","0.00000000"],["115732.00000000","0.00000000"],["115733.95000000","0.00000000"],["115753.59000000","0.02498000"],["115813.00000000","0.00000000"],["115900.00000000","1.00643000"],["115929.00000000","0.00010000"],["116553.39000000","0.00246000"],["116773.00000000","0.00000000"],["116877.00000000","0.00000000"],["116964.00000000","0.00000000"],["117179.63000000","0.00100000"]]}
[2025-10-27T18:48:19.147Z] {"e":"depthUpdate","E":1761590899014,"s":"BTCUSDT","U":79129610021,"u":79129610358,"b":[["115447.90000000","8.06509000"],["115447.89000000","0.00000000"],["115447.65000000","0.05030000"],["115447.54000000","0.36376000"],["115447.53000000","0.17333000"],["115444.56000000","0.00250000"],["115444.23000000","0.06753000"],["115444.20000000","0.24954000"],["115442.90000000","0.00000000"],["115442.89000000","0.27659000"],["115442.66000000","0.00694000"],["115441.67000000","0.17323000"],["115440.98000000","0.00520000"],["115440.91000000","0.00000000"],["115440.11000000","0.00433000"],["115439.67000000","0.00000000"],["115439.42000000","0.00009000"],["115439.04000000","0.00009000"],["115438.83000000","0.00018000"],["115438.40000000","0.00009000"],["115438.14000000","0.00009000"],["115436.13000000","0.00100000"],["115435.83000000","0.00000000"],["115434.82000000","0.00000000"],["115434.75000000","0.30570000"],["115433.51000000","0.00000000"],["115433.48000000","0.07009000"],["115433.14000000","0.00000000"],["115432.92000000","0.00000000"],["115432.89000000","0.09971000"],["115432.50000000","0.00000000"],["115432.23000000","0.00000000"],["115431.29000000","0.00866000"],["115430.19000000","0.00000000"],["115429.26000000","0.06000000"],["115428.30000000","0.00000000"],["115428.29000000","0.00000000"],["115428.28000000","0.00000000"],["115428.27000000","0.08660000"],["115427.58000000","0.00000000"],["115426.81000000","0.04752000"],["115426.12000000","0.00000000"],["115425.56000000","0.00000000"],["115425.32000000","0.14725000"],["115424.18000000","0.00000000"],["115422.73000000","0.00000000"],["115421.46000000","0.00000000"],["115419.42000000","0.00583000"],["115418.95000000","0.00000000"],["115416.65000000","0.55719000"],["115415.43000000","0.00000000"],["115415.17000000","0.00000000"],["115414.72000000","0.00000000"],["115413.26000000","0.25975000"],["115413.16000000","0.24000000"],["115401.76000000","0.14726000"],["115393.13000000","0.04280000"],["115386.21000000","0.00000000"],["115369.42000000","0.43314000"],["115369.12000000","0.43307000"],["115368.87000000","0.00000000"],["115365.61000000","0.00000000"],["115360.67000000","0.12969000"],["115358.97000000","0.00000000"],["115357.70000000","0.00000000"],["115346.38000000","0.46875000"],["115342.01000000","0.04597000"],["115339.59000000","0.04597000"],["115330.50000000","0.00000000"],["115330.49000000","0.00000000"],["115330.09000000","0.00000000"],["115324.77000000","0.00000000"],["115324.27000000","0.09389000"],["115218.63000000","0.09194000"],["115217.80000000","0.00000000"],["115180.16000000","0.02198000"],["115147.90000000","0.00000000"],["115070.40000000","0.00000000"],["114814.41000000","0.35025000"],["114749.82000000","0.00050000"],["113716.18000000","0.00100000"],["103902.00000000","0.00020000"],["92358.32000000","0.00021000"],["41561.25000000","0.00060000"]],"a":[["115447.91000000","0.73398000"],["115447.92000000","0.00075000"],["115452.00000000","0.00130000"],["115452.05000000","0.01954000"],["115452.06000000","0.00000000"],["115452.83000000","0.00000000"],["115452.84000000","0.00000000"],["115454.42000000","0.00010000"],["115455.31000000","0.00010000"],["115455.32000000","0.01691000"],["115455.46000000","0.00005000"],["115455.76000000","0.00000000"],["115455.77000000","0.00000000"],["115457.32000000","0.00155000"],["115457.96000000","0.00010000"],["115458.03000000","0.00000000"],["115458.28000000","0.29228000"],["115458.42000000","0.00337000"],["115458.91000000","0.00000000"],["115460.10000000","0.00005000"],["115460.58000000","0.00069000"],["115461.31000000","0.00324000"],["115461.40000000","0.04587000"],["115462.31000000","0.00000000"],["115462.33000000","0.00000000"],["115462.36000000","0.00000000"],["115462.37000000","0.00000000"],["115462.92000000","0.08368000"],["115462.97000000","0.00000000"],["115462.98000000","0.32599000"],["115464.12000000","0.00000000"],["115464.14000000","0.00000000"],["115464.82000000","0.00000000"],["115465.82000000","0.00000000"],["115467.24000000","0.00000000"],["115467.77000000","0.07031000"],["115468.11000000","0.00000000"],["115470.76000000","0.00100000"],["115471.06000000","0.00433000"],["115476.02000000","0.14721000"],["115477.25000000","0.00583000"],["115477.33000000","0.00000000"],["115489.75000000","0.00000000"],["115490.59000000","0.00000000"],["115494.53000000","0.00000000"],["115502.74000000","0.00000000"],["115505.67000000","0.46810000"],["115509.13000000","0.00000000"],["115516.46000000","0.00617000"],["115529.84000000","0.00000000"],["115529.93000000","0.01960000"],["115530.31000000","0.00000000"],["115533.78000000","0.00000000"],["115535.96000000","0.22008000"],["115535.98000000","0.04597000"],["115544.43000000","0.18708000"],["115546.98000000","0.00000000"],["115607.60000000","0.00864000"],["115630.80000000","0.00000000"],["115653.88000000","0.02600000"],["115728.26000000","0.00000000"],["115729.44000000","0.00000000"],["115752.40000000","0.04996000"],["115752.56000000","0.02498000"],["115786.21000000","0.00000000"],["115799.69000000","0.00000000"],["115805.00000000","0.00007000"],["115807.82000000","0.00019000"],["115812.03000000","0.02398000"],["115823.99000000","0.00000000"],["115824.43000000","0.00000000"],["115824.87000000","0.00000000"],["115825.54000000","0.00000000"],["115831.91000000","0.02498000"],["115833.13000000","0.02498000"],["115834.10000000","0.02498000"],["115843.77000000","0.00000000"],["115851.38000000","0.37961000"],["115854.28000000","0.00000000"],["115854.89000000","0.00000000"],["115855.49000000","0.00139000"],["115855.91000000","0.03198000"],["115856.10000000","0.00000000"],["115856.61000000","0.03198000"],["115857.31000000","0.03198000"],["115857.88000000","0.03198000"],["115882.91000000","0.03198000"],["115883.66000000","0.03198000"],["115884.59000000","0.03198000"],["115885.60000000","0.03198000"],["115887.37000000","0.00000000"],["115888.09000000","0.00000000"],["115888.30000000","0.00000000"],["115888.96000000","0.00000000"],["115889.03000000","0.00000000"],["115891.05000000","0.00000000"],["115893.55000000","0.00000000"],["115910.76000000","0.02498000"],["115911.64000000","0.02498000"],["115912.54000000","0.02498000"],["115914.10000000","0.02513000"],["115914.69000000","0.02498000"],["115915.19000000","0.02498000"],["115915.64000000","0.02498000"],["117179.63000000","0.00100000"]]}
[2025-10-27T18:48:20.205Z] {"e":"depthUpdate","E":1761590900014,"s":"BTCUSDT","U":79129610359,"u":79129610459,"b":[["115447.90000000","8.05921000"],["115434.75000000","0.29384000"],["115432.89000000","0.09740000"],["115431.29000000","0.00000000"],["115428.27000000","0.00000000"],["115428.26000000","0.00000000"],["115428.24000000","0.00000000"],["115428.22000000","0.03000000"],["115428.21000000","0.00000000"],["115428.18000000","0.00000000"],["115428.13000000","0.00000000"],["115428.11000000","0.00000000"],["115428.08000000","0.08660000"],["115413.26000000","0.00000000"],["115401.52000000","0.00866000"],["115377.05000000","0.01300000"],["115371.28000000","0.01300000"],["115369.68000000","0.25975000"],["115369.62000000","0.00000000"],["115368.06000000","0.00000000"],["115362.29000000","0.00000000"],["115324.57000000","0.20777000"],["115147.90000000","0.00000000"],["114428.67000000","0.00000000"],["113716.18000000","0.00100000"],["103903.00000000","0.00000000"],["103902.00000000","0.00020000"],["92358.32000000","0.00021000"],["92358.00000000","0.00000000"],["50000.00000000","39.61327000"]],"a":[["115447.91000000","0.72652000"],["115447.92000000","0.00070000"],["115452.05000000","0.10024000"],["115455.32000000","0.01706000"],["115455.37000000","0.00010000"],["115455.38000000","0.28586000"],["115455.46000000","0.00529000"],["115457.32000000","0.00150000"],["115457.96000000","0.00000000"],["115458.42000000","0.00250000"],["115462.92000000","0.08496000"],["115477.21000000","0.00583000"],["115477.25000000","0.00000000"],["115494.60000000","0.06408000"],["115502.16000000","0.00000000"],["115533.86000000","0.13029000"],["115544.42000000","0.09109000"],["115546.72000000","0.00000000"],["116553.39000000","0.00000000"],["117179.63000000","0.00100000"]]}
[2025-10-27T18:48:21.218Z] {"e":"depthUpdate","E":1761590901014,"s":"BTCUSDT","U":79129610460,"u":79129610630,"b":[["115447.90000000","6.93376000"],["115447.55000000","0.00010000"],["115447.54000000","0.36381000"],["115444.24000000","0.00005000"],["115443.95000000","0.00000000"],["115428.66000000","0.00866000"],["115428.46000000","0.73532000"],["115428.08000000","0.00000000"],["115428.06000000","0.00000000"],["115427.10000000","0.00000000"],["115427.07000000","0.00000000"],["115427.05000000","0.00000000"],["115427.02000000","0.00000000"],["115427.01000000","0.00000000"],["115424.94000000","0.43307000"],["115423.80000000","0.08660000"],["115423.50000000","0.43314000"],["115419.37000000","0.98137000"],["115412.53000000","0.25975000"],["115410.82000000","0.00000000"],["115401.52000000","0.00000000"],["115369.42000000","0.00000000"],["115369.12000000","0.00000000"],["115367.21000000","0.43307000"],["115365.77000000","0.43314000"],["113716.18000000","0.00100000"],["103902.00000000","0.00020000"],["100000.00000000","205.28458000"],["92358.32000000","0.00021000"],["50000.00000000","39.61417000"]],"a":[["115447.91000000","1.58819000"],["115447.92000000","0.00070000"],["115448.00000000","0.00145000"],["115448.47000000","0.00010000"],["115448.48000000","0.01320000"],["115448.49000000","0.00000000"],["115448.50000000","0.00000000"],["115448.82000000","0.00000000"],["115450.00000000","0.00130000"],["115450.36000000","0.00005000"],["115450.37000000","0.03836000"],["115454.42000000","0.00000000"],["115455.32000000","0.01701000"],["115455.46000000","0.00713000"],["115456.62000000","0.00300000"],["115459.46000000","0.08658000"],["115460.58000000","0.00000000"],["115461.31000000","0.00000000"],["115463.27000000","0.00000000"],["115463.31000000","0.21750000"],["115467.77000000","0.00000000"],["115474.41000000","0.00000000"],["115477.89000000","0.31174000"],["115490.34000000","0.08643000"],["115494.55000000","0.00000000"],["115504.16000000","0.00000000"],["115843.77000000","0.37961000"],["115851.38000000","0.00000000"],["117179.63000000","0.00100000"]]}
[2025-10-27T18:48:22.242Z] {"e":"depthUpdate","E":1761590902014,"s":"BTCUSDT","U":79129610631,"u":79129610730,"b":[["115447.90000000","6.93324000"],["115447.89000000","0.00005000"],["115447.85000000","0.04070000"],["115447.53000000","0.17328000"],["115444.24000000","0.00000000"],["115444.20000000","0.24954000"],["115443.94000000","0.00000000"],["115432.90000000","0.28819000"],["115324.30000000","0.09389000"],["115324.27000000","0.00000000"],["115323.94000000","0.00000000"],["115323.92000000","0.00000000"],["115323.89000000","0.00000000"],["114368.53000000","0.00000000"],["113716.18000000","0.00100000"],["111958.93000000","0.02172000"],["111940.50000000","0.00000000"],["103903.00000000","0.00000000"],["103902.00000000","0.00020000"],["92358.32000000","0.00021000"],["41561.25000000","0.00075000"],["33000.00000000","3.79030000"]],"a":[["115447.91000000","1.42186000"],["115447.92000000","0.00065000"],["115448.48000000","0.00015000"],["115448.88000000","0.00000000"],["115450.00000000","0.00125000"],["115450.36000000","0.00000000"],["115450.37000000","0.00000000"],["115454.42000000","0.00010000"],["115455.32000000","0.01706000"],["115460.67000000","0.00000000"],["115463.31000000","0.14719000"],["115463.32000000","0.00000000"],["115463.33000000","0.00000000"],["115463.34000000","0.00000000"],["115463.35000000","0.07031000"],["115475.48000000","0.00866000"],["115477.21000000","0.00000000"],["115477.33000000","0.00000000"],["115477.35000000","0.00583000"],["115504.95000000","0.25975000"],["115528.08000000","0.01356000"],["115566.45000000","0.00000000"],["116302.51000000","0.00000000"],["116337.03000000","0.00008000"],["117179.63000000","0.00100000"],["118000.00000000","78.06050000"]]}
[2025-10-27T18:48:23.144Z] {"e":"depthUpdate","E":1761590903014,"s":"BTCUSDT","U":79129610731,"u":79129610818,"b":[["115447.90000000","6.89382000"],["115447.86000000","0.00010000"],["115444.20000000","0.00005000"],["115442.92000000","0.00000000"],["115442.66000000","0.00000000"],["115369.18000000","0.01356000"],["115353.13000000","0.00000000"],["115324.67000000","0.00000000"],["115324.33000000","0.09389000"],["115324.30000000","0.00000000"],["115311.68000000","0.00243000"],["115210.00000000","0.00241000"],["115149.80000000","0.00452000"],["115127.83000000","0.00000000"],["115068.43000000","0.02498000"],["115067.29000000","0.02498000"],["115065.37000000","0.02498000"],["114900.00000000","0.91176000"],["114686.46000000","0.00021000"],["113716.18000000","0.00100000"],["106212.08000000","0.00010000"],["103902.00000000","0.00020000"],["92358.32000000","0.00021000"],["92358.00000000","0.00000000"]],"a":[["115447.91000000","1.89634000"],["115447.92000000","0.00070000"],["115448.00000000","0.00140000"],["115448.26000000","0.03822000"],["115448.47000000","0.00000000"],["115448.48000000","0.00000000"],["115448.88000000","0.00000000"],["115450.00000000","0.00130000"],["115453.24000000","0.28582000"],["115455.38000000","0.00005000"],["115456.62000000","0.00305000"],["115459.26000000","0.25975000"],["115460.96000000","0.00000000"],["115460.97000000","0.00000000"],["115477.33000000","0.00583000"],["115477.35000000","0.00000000"],["115504.95000000","0.00000000"],["115506.60000000","0.00000000"],["115546.81000000","0.02500000"],["115546.82000000","0.00000000"],["115562.57000000","0.00000000"],["115562.86000000","0.00243000"],["117179.63000000","0.00100000"]]}
[2025-10-27T18:48:24.169Z] {"e":"depthUpdate","E":1761590904014,"s":"BTCUSDT","U":79129610819,"u":79129611096,"b":[["115447.90000000","6.90250000"],["115447.89000000","0.00005000"],["115447.85000000","0.04070000"],["115447.79000000","0.00000000"],["115447.78000000","0.00000000"],["115447.65000000","0.05030000"],["115447.54000000","0.36371000"],["115447.53000000","0.00000000"],["115447.04000000","0.00005000"],["115447.03000000","0.03988000"],["115445.33000000","0.00005000"],["115445.32000000","0.17327000"],["115444.64000000","0.00000000"],["115444.23000000","0.00000000"],["115444.20000000","0.00000000"],["115442.89000000","0.27659000"],["115441.50000000","0.25643000"],["115440.11000000","0.00000000"],["115436.37000000","0.00433000"],["115434.91000000","0.00000000"],["115434.90000000","0.00000000"],["115432.90000000","0.00000000"],["115430.38000000","0.00000000"],["115430.25000000","0.31187000"],["115413.72000000","0.00000000"],["115324.33000000","0.00000000"],["115207.47000000","4.79791000"],["115191.66000000","0.00000000"],["113716.18000000","0.00100000"],["112569.75000000","0.00000000"],["106212.08000000","0.00000000"],["103903.00000000","0.00000000"],["92358.32000000","0.00021000"]],"a":[["115447.91000000","2.00234000"],["115447.92000000","0.00060000"],["115448.00000000","0.00145000"],["115448.10000000","0.00000000"],["115448.24000000","0.00000000"],["115448.25000000","0.00000000"],["115448.26000000","0.00000000"],["115449.06000000","0.00100000"],["115450.00000000","0.00130000"],["115452.05000000","0.10024000"],["115453.00000000","0.00531000"],["115453.23000000","0.00010000"],["115453.24000000","0.28587000"],["115453.99000000","0.00010000"],["115454.00000000","0.06225000"],["115454.42000000","0.00000000"],["115454.43000000","0.01309000"],["115455.31000000","0.00000000"],["115455.32000000","0.01701000"],["115455.37000000","0.00000000"],["115455.38000000","0.00000000"],["115455.46000000","0.00713000"],["115456.62000000","0.00305000"],["115457.18000000","0.00000000"],["115457.19000000","0.00000000"],["115457.32000000","0.00155000"],["115457.96000000","0.00010000"],["115458.91000000","0.04592000"],["115459.26000000","0.00000000"],["115459.32000000","0.00000000"],["115460.83000000","0.00069000"],["115460.99000000","0.00000000"],["115461.18000000","0.00000000"],["115461.40000000","0.00000000"],["115470.61000000","0.43307000"],["115471.21000000","0.00000000"],["115476.55000000","0.00583000"],["115477.33000000","0.00000000"],["115482.55000000","0.00300000"],["115503.36000000","0.25975000"],["115505.65000000","0.00048000"],["115505.66000000","0.00000000"],["115505.99000000","0.00008000"],["115508.21000000","0.00360000"],["115526.39000000","0.00000000"],["115526.40000000","0.43307000"],["115611.13000000","0.00000000"],["115620.89000000","0.00019000"],["115620.90000000","0.00000000"],["115625.21000000","0.02078000"],["115691.78000000","0.00000000"],["115706.66000000","0.08643000"],["117179.63000000","0.00100000"]]}
[2025-10-27T18:48:25.146Z] {"e":"depthUpdate","E":1761590905014,"s":"BTCUSDT","U":79129611097,"u":79129611455,"b":[["115447.90000000","6.38249000"],["115447.89000000","0.00050000"],["115447.65000000","0.05015000"],["115447.54000000","0.36366000"],["115447.04000000","0.00000000"],["115447.03000000","0.00000000"],["115445.33000000","0.00000000"],["115445.32000000","0.00000000"],["115444.83000000","0.00000000"],["115444.82000000","0.00000000"],["115444.56000000","0.00000000"],["115443.87000000","0.00005000"],["115442.89000000","0.27659000"],["115442.42000000","0.00000000"],["115442.40000000","0.04565000"],["115441.97000000","0.03902000"],["115441.67000000","0.00000000"],["115441.58000000","0.00000000"],["115441.50000000","0.00000000"],["115441.45000000","0.23015000"],["115440.48000000","0.17323000"],["115440.46000000","0.00000000"],["115440.45000000","0.00000000"],["115440.42000000","0.17323000"],["115440.01000000","0.18502000"],["115439.32000000","0.00000000"],["115437.85000000","0.25643000"],["115436.37000000","0.00000000"],["115434.75000000","0.02393000"],["115434.42000000","0.00325000"],["115433.49000000","0.00433000"],["115433.26000000","0.00000000"],["115430.25000000","0.00000000"],["115425.78000000","0.00000000"],["115425.15000000","0.31188000"],["115423.80000000","0.00000000"],["115423.14000000","0.00000000"],["115421.98000000","0.35513000"],["115421.93000000","0.00000000"],["115421.46000000","0.00250000"],["115419.37000000","0.00000000"],["115418.69000000","0.08661000"],["115413.25000000","0.00000000"],["115408.86000000","0.83286000"],["115332.94000000","0.00000000"],["115326.09000000","0.05358000"],["115316.25000000","0.00000000"],["115316.03000000","0.09535000"],["115315.32000000","0.00000000"],["115260.00000000","0.00226000"],["113716.18000000","0.00100000"],["103902.00000000","0.00020000"],["92358.32000000","0.00021000"],["42000.00000000","1.36531000"]],"a":[["115447.91000000","4.47092000"],["115447.92000000","0.00060000"],["115448.01000000","0.00000000"],["115450.00000000","0.00135000"],["115450.48000000","0.00010000"],["115450.49000000","0.08614000"],["115450.50000000","0.28593000"],["115452.05000000","0.10024000"],["115452.07000000","0.00010000"],["115452.08000000","0.08818000"],["115453.00000000","0.00541000"],["115453.23000000","0.00000000"],["115453.24000000","0.00000000"],["115453.80000000","0.00250000"],["115453.82000000","0.04597000"],["115453.99000000","0.00005000"],["115454.00000000","0.06225000"],["115455.32000000","0.01696000"],["115455.46000000","0.00713000"],["115456.00000000","0.00125000"],["115456.38000000","0.00000000"],["115457.32000000","0.00150000"],["115457.95000000","1.58330000"],["115457.96000000","3.01912000"],["115457.97000000","0.00000000"],["115458.16000000","0.07031000"],["115458.28000000","0.00000000"],["115458.91000000","0.00000000"],["115459.46000000","0.00000000"],["115460.83000000","0.00000000"],["115461.99000000","0.00433000"],["115463.35000000","0.00000000"],["115463.69000000","0.00000000"],["115470.61000000","0.00000000"],["115471.06000000","0.00000000"],["115471.07000000","0.00000000"],["115472.39000000","0.00000000"],["115472.43000000","0.04552000"],["115473.60000000","0.00000000"],["115474.26000000","0.00000000"],["115476.55000000","0.00000000"],["115476.90000000","0.00000000"],["115477.20000000","0.00583000"],["115480.83000000","0.74694000"],["115481.95000000","0.01298000"],["115482.55000000","1.47547000"],["115483.50000000","0.00000000"],["115487.72000000","0.01298000"],["115489.78000000","0.00000000"],["115490.25000000","0.31170000"],["115490.34000000","0.00000000"],["115499.64000000","0.00000000"],["115503.25000000","0.25979000"],["115522.50000000","0.18243000"],["115526.26000000","0.00000000"],["115526.40000000","0.00000000"],["115527.27000000","0.00000000"],["115529.68000000","0.00000000"],["115534.57000000","0.00000000"],["115534.58000000","0.00000000"],["115535.99000000","0.09294000"],["115536.00000000","0.00260000"],["115539.27000000","0.00000000"],["115541.22000000","0.03400000"],["115546.81000000","0.00000000"],["115548.77000000","0.02500000"],["117179.63000000","0.00100000"]]}
[2025-10-27T18:48:26.146Z] {"e":"depthUpdate","E":1761590906014,"s":"BTCUSDT","U":79129611456,"u":79129611593,"b":[["115447.90000000","6.23608000"],["115447.89000000","0.00045000"],["115447.86000000","0.00000000"],["115447.85000000","0.00060000"],["115443.87000000","0.00010000"],["115443.86000000","0.04412000"],["115442.90000000","0.00005000"],["115441.45000000","0.23020000"],["115434.43000000","0.00433000"],["115433.49000000","0.00000000"],["115425.15000000","0.00000000"],["115424.97000000","0.97293000"],["115424.53000000","0.04330000"],["115422.34000000","0.00000000"],["115408.24000000","0.31192000"],["115326.39000000","0.00000000"],["115326.10000000","0.00215000"],["115236.37000000","0.01356000"],["115229.55000000","0.00000000"],["115200.01000000","0.00073000"],["115191.15000000","0.00000000"],["115147.41000000","0.00077000"],["115138.53000000","0.00000000"],["113716.18000000","0.00100000"],["112561.70000000","0.00088000"],["111958.93000000","0.00000000"],["111947.87000000","0.02172000"],["103902.00000000","0.00020000"],["92358.32000000","0.00021000"],["92358.00000000","0.00000000"]],"a":[["115447.91000000","4.47064000"],["115447.92000000","0.00060000"],["115448.00000000","0.00145000"],["115448.11000000","0.00010000"],["115448.12000000","0.08730000"],["115448.13000000","0.28615000"],["115449.06000000","0.00095000"],["115450.00000000","0.00125000"],["115450.48000000","0.00000000"],["115450.49000000","0.00000000"],["115450.50000000","0.00000000"],["115450.79000000","0.00196000"],["115451.71000000","0.00005000"],["115451.72000000","0.04064000"],["115452.08000000","0.08813000"],["115453.99000000","0.00000000"],["115454.83000000","0.00520000"],["115458.16000000","0.00000000"],["115458.19000000","0.07031000"],["115461.99000000","0.00000000"],["115462.91000000","0.00433000"],["115466.59000000","0.16996000"],["115471.87000000","0.00000000"],["115473.13000000","0.31175000"],["115488.73000000","0.08643000"],["115490.25000000","0.00000000"],["115516.45000000","0.00216000"],["115517.99000000","0.00000000"],["115839.96000000","0.37961000"],["115843.77000000","0.00000000"],["117179.63000000","0.00100000"]]}
[2025-10-27T18:48:27.148Z] {"e":"depthUpdate","E":1761590907014,"s":"BTCUSDT","U":79129611594,"u":79129611727,"b":[["115447.90000000","5.96694000"],["115447.89000000","0.00045000"],["115447.54000000","0.36366000"],["115445.58000000","0.00000000"],["115445.57000000","0.00000000"],["115444.64000000","0.00005000"],["115444.63000000","0.04570000"],["115443.86000000","0.04407000"],["115442.90000000","0.00000000"],["115442.89000000","0.27659000"],["115442.40000000","0.00000000"],["115437.85000000","0.24949000"],["115436.93000000","0.00694000"],["115435.23000000","0.00000000"],["115435.14000000","0.00000000"],["115425.17000000","0.31188000"],["115424.53000000","0.00000000"],["115423.51000000","0.04330000"],["115408.24000000","0.00000000"],["115341.53000000","0.00000000"],["115326.09000000","0.09739000"],["115288.36000000","0.00866000"],["115264.61000000","0.00000000"],["113716.18000000","0.00100000"],["103903.00000000","0.00000000"],["103902.00000000","0.00020000"],["92358.32000000","0.00021000"],["50000.00000000","39.61267000"],["42000.00000000","1.36431000"],["33000.00000000","3.79030000"]],"a":[["115447.91000000","4.24432000"],["115458.19000000","0.00000000"],["115458.20000000","0.00007000"],["115458.24000000","0.00000000"],["115458.27000000","0.00000000"],["115458.31000000","0.00000000"],["115458.34000000","0.00000000"],["115458.38000000","0.00000000"],["115458.45000000","0.00000000"],["115458.56000000","0.00000000"],["115458.60000000","0.00000000"],["115458.63000000","0.07031000"],["115459.04000000","0.06748000"],["115476.80000000","0.00583000"],["115477.20000000","0.00000000"],["115477.25000000","0.00000000"],["115494.60000000","0.00000000"],["115533.86000000","0.00000000"],["117179.63000000","0.00100000"]]}
[2025-10-27T18:48:28.146Z] {"e":"depthUpdate","E":1761590908014,"s":"BTCUSDT","U":79129611728,"u":79129612001,"b":[["115447.90000000","6.39249000"],["115447.89000000","0.00020000"],["115447.65000000","0.05030000"],["115447.54000000","0.36371000"],["115447.23000000","0.00010000"],["115447.22000000","0.03934000"],["115446.60000000","0.04565000"],["115446.48000000","0.17328000"],["115446.12000000","0.03865000"],["115445.57000000","0.00005000"],["115444.64000000","0.00000000"],["115444.63000000","0.00000000"],["115443.87000000","0.00000000"],["115442.89000000","0.27659000"],["115441.97000000","0.00000000"],["115441.45000000","0.23015000"],["115440.98000000","0.00520000"],["115440.48000000","0.00000000"],["115435.33000000","0.00433000"],["115434.43000000","0.00000000"],["115425.33000000","0.04330000"],["115425.23000000","0.31188000"],["115425.17000000","0.00000000"],["115424.82000000","0.04331000"],["115423.51000000","0.00000000"],["115407.97000000","0.00000000"],["115332.57000000","0.03025000"],["115316.03000000","0.00000000"],["113716.18000000","0.00100000"],["103903.11000000","0.00019000"],["103902.00000000","0.00020000"],["92358.32000000","0.00021000"],["60000.00000000","57.97732000"],["41561.25000000","0.00105000"]],"a":[["115447.91000000","3.08264000"],["115447.92000000","0.04406000"],["115448.12000000","0.08725000"],["115448.13000000","0.00022000"],["115449.78000000","0.00010000"],["115449.79000000","0.04010000"],["115450.43000000","0.00010000"],["115450.44000000","0.28588000"],["115451.72000000","0.04059000"],["115452.04000000","0.00005000"],["115452.05000000","0.01949000"],["115452.07000000","0.00000000"],["115452.08000000","0.00150000"],["115453.00000000","0.00536000"],["115453.82000000","0.00000000"],["115454.00000000","0.00120000"],["115454.43000000","0.01309000"],["115454.83000000","0.00525000"],["115456.05000000","0.04592000"],["115456.62000000","0.00300000"],["115458.63000000","0.00000000"],["115458.66000000","0.00000000"],["115458.68000000","0.00000000"],["115458.70000000","0.00000000"],["115458.72000000","0.00000000"],["115458.73000000","0.00000000"],["115458.76000000","0.00000000"],["115458.78000000","0.00000000"],["115458.81000000","0.00000000"],["115459.04000000","0.00000000"],["115459.46000000","0.08658000"],["115459.76000000","0.07031000"],["115459.94000000","0.25979000"],["115462.91000000","0.00000000"],["115463.30000000","0.00000000"],["115464.65000000","0.00433000"],["115466.59000000","0.00000000"],["115468.57000000","0.16996000"],["115473.13000000","0.00000000"],["115476.53000000","0.00000000"],["115476.80000000","0.00000000"],["115477.02000000","0.00583000"],["115480.83000000","0.43284000"],["115482.55000000","0.43607000"],["115482.57000000","0.25975000"],["115489.94000000","0.31170000"],["115494.84000000","0.06473000"],["115522.50000000","0.18243000"],["115526.31000000","0.00000000"],["115526.40000000","0.00000000"],["115526.53000000","0.00000000"],["115526.68000000","0.34651000"],["115527.28000000","0.43314000"],["115528.75000000","0.25975000"],["115539.27000000","0.03400000"],["115541.22000000","0.00000000"],["115546.81000000","0.02500000"],["115548.77000000","0.00000000"],["117001.01000000","0.27758000"],["117179.63000000","0.00100000"]]}
[2025-10-27T18:48:29.149Z] {"e":"depthUpdate","E":1761590909015,"s":"BTCUSDT","U":79129612002,"u":79129612274,"b":[["115447.90000000","6.42722000"],["115447.89000000","0.00015000"],["115447.22000000","0.03934000"],["115446.61000000","0.00000000"],["115446.60000000","0.00000000"],["115446.12000000","0.03870000"],["115444.56000000","0.00250000"],["115441.25000000","0.24949000"],["115441.11000000","0.06748000"],["115440.01000000","0.11325000"],["115439.80000000","0.00694000"],["115438.51000000","0.00433000"],["115437.85000000","0.00000000"],["115436.93000000","0.00000000"],["115435.33000000","0.00000000"],["115434.42000000","0.00000000"],["115433.33000000","0.54080000"],["115429.31000000","0.04330000"],["115428.66000000","0.00000000"],["115425.33000000","0.00000000"],["115423.56000000","0.00000000"],["115421.48000000","0.08660000"],["115421.46000000","0.00000000"],["115418.69000000","0.00000000"],["115413.37000000","0.00000000"],["115412.74000000","0.25975000"],["115412.53000000","0.00000000"],["115369.68000000","0.00000000"],["115369.32000000","0.25975000"],["115333.12000000","0.02813000"],["115324.64000000","0.00000000"],["115324.62000000","0.00000000"],["115324.38000000","0.00000000"],["115324.23000000","0.00000000"],["115322.64000000","0.02069000"],["115063.30000000","0.02498000"],["114921.25000000","0.00000000"],["114000.00000000","23.21346000"],["113716.18000000","0.00100000"],["106212.08000000","0.00010000"],["103903.11000000","0.00000000"],["103903.00000000","0.00000000"],["103902.00000000","0.00020000"],["92358.32000000","0.00021000"],["92358.00000000","0.00000000"]],"a":[["115447.91000000","1.17573000"],["115447.92000000","0.04436000"],["115448.00000000","0.00140000"],["115448.11000000","0.00000000"],["115448.12000000","0.00010000"],["115448.13000000","0.00017000"],["115449.06000000","0.00105000"],["115449.77000000","0.00015000"],["115449.78000000","0.10767000"],["115449.79000000","0.04005000"],["115450.31000000","0.00010000"],["115450.32000000","0.28588000"],["115450.43000000","0.00000000"],["115450.44000000","0.00000000"],["115451.71000000","0.00010000"],["115452.00000000","0.00125000"],["115452.04000000","0.00000000"],["115452.05000000","0.10267000"],["115452.82000000","0.00000000"],["115452.96000000","0.00000000"],["115453.00000000","0.00531000"],["115453.80000000","0.00000000"],["115454.43000000","0.01309000"],["115454.78000000","0.29233000"],["115454.83000000","0.00520000"],["115455.32000000","0.01696000"],["115455.46000000","0.00715000"],["115456.00000000","0.00120000"],["115456.05000000","0.00005000"],["115457.95000000","0.51559000"],["115457.96000000","0.00000000"],["115458.42000000","0.00250000"],["115458.54000000","0.04592000"],["115459.76000000","0.00000000"],["115459.79000000","0.00000000"],["115459.86000000","0.00000000"],["115459.89000000","0.00000000"],["115459.93000000","0.54080000"],["115460.79000000","0.00000000"],["115460.98000000","0.00000000"],["115461.03000000","0.00000000"],["115461.65000000","0.00000000"],["115462.43000000","0.00000000"],["115462.46000000","0.07031000"],["115463.03000000","0.00000000"],["115464.65000000","0.00000000"],["115466.59000000","0.00000000"],["115467.65000000","0.00433000"],["115468.57000000","0.00000000"],["115470.55000000","0.16996000"],["115471.11000000","0.34651000"],["115471.14000000","0.43314000"],["115471.33000000","0.43307000"],["115475.48000000","0.00000000"],["115476.90000000","0.00250000"],["115477.02000000","0.00000000"],["115477.35000000","0.00583000"],["115481.95000000","0.00000000"],["115482.55000000","0.00300000"],["115487.72000000","0.00000000"],["115490.48000000","0.00000000"],["115495.46000000","0.00000000"],["115497.80000000","0.33259000"],["115522.50000000","0.38108000"],["115526.81000000","0.43307000"],["115545.86000000","0.02500000"],["115546.81000000","0.00000000"],["115901.44000000","0.00000000"],["117179.63000000","0.00100000"]]}
[2025-10-27T18:48:30.149Z] {"e":"depthUpdate","E":1761590910014,"s":"BTCUSDT","U":79129612275,"u":79129612534,"b":[["115447.90000000","6.18364000"],["115447.89000000","0.00005000"],["115447.54000000","0.36371000"],["115447.23000000","0.00000000"],["115447.22000000","0.00000000"],["115447.11000000","0.00000000"],["115447.02000000","0.00000000"],["115447.00000000","0.00000000"],["115446.48000000","0.00000000"],["115446.37000000","0.00010000"],["115446.36000000","0.04565000"],["115446.12000000","0.00000000"],["115445.86000000","0.00000000"],["115443.97000000","0.00000000"],["115443.96000000","0.00000000"],["115443.87000000","0.00005000"],["115443.86000000","0.04407000"],["115443.82000000","0.17323000"],["115441.45000000","0.23020000"],["115441.25000000","0.00000000"],["115441.11000000","0.00000000"],["115440.98000000","0.00525000"],["115440.27000000","0.49338000"],["115440.26000000","0.25643000"],["115440.01000000","0.00000000"],["115439.80000000","0.00000000"],["115438.51000000","0.00000000"],["115436.37000000","0.00433000"],["115434.95000000","0.00331000"],["115434.64000000","0.98639000"],["115431.33000000","0.00866000"],["115429.31000000","0.00000000"],["115426.99000000","0.04330000"],["115425.49000000","0.00000000"],["115425.46000000","0.31188000"],["115425.23000000","0.00000000"],["115424.97000000","0.00000000"],["115408.30000000","0.00005000"],["115333.12000000","0.00000000"],["115326.09000000","0.05358000"],["115207.63000000","4.73113000"],["115207.47000000","0.00000000"],["113716.18000000","0.00100000"],["106212.08000000","0.00000000"],["103902.00000000","0.00020000"],["92358.32000000","0.00021000"],["41561.25000000","0.00120000"]],"a":[["115447.91000000","3.54835000"],["115447.92000000","0.04431000"],["115449.06000000","0.00105000"],["115449.76000000","0.00010000"],["115449.77000000","0.10754000"],["115449.78000000","0.00010000"],["115449.79000000","0.04005000"],["115450.20000000","0.00005000"],["115450.21000000","0.28588000"],["115450.31000000","0.00000000"],["115450.32000000","0.00000000"],["115452.00000000","0.00130000"],["115452.04000000","0.00000000"],["115452.05000000","0.05896000"],["115452.08000000","0.08813000"],["115454.43000000","0.01309000"],["115454.78000000","0.00000000"],["115454.83000000","0.00520000"],["115456.00000000","0.00125000"],["115456.49000000","0.04592000"],["115458.54000000","0.00000000"],["115459.46000000","0.00000000"],["115462.46000000","0.00000000"],["115462.49000000","0.00000000"],["115462.51000000","0.07031000"],["115463.60000000","0.00433000"],["115467.65000000","0.00000000"],["115471.11000000","0.00000000"],["115471.14000000","0.00000000"],["115471.33000000","0.00000000"],["115473.50000000","0.03600000"],["115477.13000000","0.00583000"],["115477.35000000","0.00000000"],["115480.83000000","0.74694000"],["115482.55000000","0.43607000"],["115488.73000000","0.00000000"],["115489.94000000","0.00000000"],["115490.00000000","0.31330000"],["115490.52000000","0.08643000"],["115522.50000000","0.32935000"],["115526.15000000","0.00000000"],["115526.19000000","0.00000000"],["115526.38000000","0.25975000"],["115526.68000000","0.00000000"],["115526.81000000","0.00000000"],["115526.89000000","0.34651000"],["115527.28000000","0.00000000"],["115528.08000000","0.00000000"],["115528.75000000","0.00000000"],["115534.09000000","0.12844000"],["115545.23000000","0.00000000"],["115555.62000000","0.00051000"],["115566.71000000","0.00000000"],["115567.17000000","0.00173000"],["115578.26000000","0.00000000"],["115705.94000000","0.08643000"],["115706.66000000","0.00000000"],["117179.63000000","0.00100000"]]}
[2025-10-27T18:48:31.146Z] {"e":"depthUpdate","E":1761590911014,"s":"BTCUSDT","U":79129612535,"u":79129612672,"b":[["115447.90000000","6.40771000"],["115447.89000000","0.00000000"],["115447.57000000","0.00000000"],["115447.54000000","0.36371000"],["115446.37000000","0.00000000"],["115446.36000000","0.00000000"],["115443.86000000","0.04412000"],["115443.82000000","0.17328000"],["115440.26000000","0.00000000"],["115440.04000000","0.00694000"],["115440.02000000","0.24949000"],["115434.95000000","0.00000000"],["115431.33000000","0.00000000"],["115430.19000000","0.31187000"],["115408.86000000","0.52094000"],["115388.92000000","0.00866000"],["113716.18000000","0.00100000"],["111958.93000000","0.02172000"],["111947.87000000","0.00000000"],["103903.00000000","0.00000000"],["103902.00000000","0.00020000"],["92358.32000000","0.00021000"]],"a":[["115447.91000000","1.65416000"],["115447.92000000","0.04431000"],["115449.77000000","0.10759000"],["115449.79000000","0.04010000"],["115450.20000000","0.00000000"],["115450.21000000","0.00000000"],["115451.70000000","0.00010000"],["115451.71000000","0.29249000"],["115452.00000000","0.00125000"],["115452.05000000","0.11090000"],["115452.08000000","0.00150000"],["115452.71000000","0.28587000"],["115456.00000000","0.00125000"],["115456.05000000","0.00000000"],["115456.49000000","0.00000000"],["115456.62000000","0.00305000"],["115457.18000000","0.04592000"],["115459.11000000","0.00000000"],["115459.46000000","0.08658000"],["115460.75000000","0.00069000"],["115463.60000000","0.00000000"],["115465.22000000","0.00000000"],["115467.24000000","0.00433000"],["115471.00000000","0.43307000"],["115471.66000000","0.34651000"],["115471.88000000","0.47214000"],["115477.13000000","0.00000000"],["115477.31000000","0.00583000"],["115480.83000000","0.43284000"],["115482.55000000","0.00300000"],["115517.33000000","0.24252000"],["115526.30000000","0.43314000"],["115527.54000000","0.43307000"],["115538.32000000","0.00000000"],["115539.27000000","0.03400000"],["115545.86000000","0.00000000"],["115546.81000000","0.02500000"],["117179.63000000","0.00100000"]]}
[2025-10-27T18:48:32.146Z] {"e":"depthUpdate","E":1761590912014,"s":"BTCUSDT","U":79129612673,"u":79129612760,"b":[["115447.90000000","6.26246000"],["115445.57000000","0.00000000"],["115436.36000000","0.02724000"],["115435.01000000","0.00000000"],["115435.00000000","0.00000000"],["115434.99000000","0.00000000"],["115432.89000000","0.00000000"],["115430.19000000","0.00000000"],["115413.54000000","0.31191000"],["115388.92000000","0.00000000"],["113716.18000000","0.00100000"],["103902.00000000","0.00020000"],["92358.32000000","0.00021000"],["92358.00000000","0.00000000"],["41561.25000000","0.00135000"],["33000.00000000","3.79030000"]],"a":[["115447.91000000","1.58701000"],["115447.92000000","0.04441000"],["115451.72000000","0.04059000"],["115452.00000000","0.02382000"],["115454.43000000","0.01304000"],["115456.62000000","0.00305000"],["115457.18000000","0.00000000"],["115457.59000000","0.04592000"],["115459.68000000","0.00000000"],["115460.75000000","0.00000000"],["115462.51000000","0.00000000"],["115462.52000000","0.00000000"],["115462.53000000","0.00000000"],["115462.54000000","0.00000000"],["115462.55000000","0.00000000"],["115462.56000000","0.07031000"],["115462.92000000","0.00000000"],["115477.31000000","0.00000000"],["115477.35000000","0.00000000"],["115514.86000000","0.00000000"],["115528.08000000","0.01356000"],["115534.21000000","0.00100000"],["115534.22000000","0.00100000"],["115535.99000000","0.09194000"],["115536.00000000","0.00160000"],["115538.32000000","0.03400000"],["115539.27000000","0.00000000"],["117179.63000000","0.00100000"]]}
[2025-10-27T18:48:33.144Z] {"e":"depthUpdate","E":1761590913014,"s":"BTCUSDT","U":79129612761,"u":79129612884,"b":[["115447.90000000","6.48415000"],["115434.77000000","0.00000000"],["115432.89000000","0.07017000"],["115431.19000000","0.00000000"],["115430.25000000","0.31187000"],["115413.54000000","0.00000000"],["115406.07000000","0.33259000"],["115403.14000000","0.00000000"],["115378.81000000","0.01356000"],["115369.18000000","0.00000000"],["115325.87000000","0.00000000"],["115064.31000000","0.02498000"],["115063.37000000","0.02498000"],["113716.18000000","0.00100000"],["103903.00000000","0.00000000"],["103902.00000000","0.00020000"],["92358.32000000","0.00021000"]],"a":[["115447.91000000","1.69449000"],["115447.92000000","0.04436000"],["115448.12000000","0.00005000"],["115449.77000000","0.01365000"],["115449.78000000","0.00000000"],["115449.79000000","0.00000000"],["115451.70000000","0.00000000"],["115451.71000000","0.00010000"],["115451.72000000","0.04064000"],["115451.99000000","0.00010000"],["115452.00000000","0.02387000"],["115452.04000000","0.00005000"],["115452.05000000","0.19149000"],["115454.43000000","0.01309000"],["115454.55000000","0.29233000"],["115456.62000000","0.00300000"],["115460.49000000","0.00000000"],["115460.51000000","0.00069000"],["115462.56000000","0.00000000"],["115462.57000000","0.00000000"],["115462.58000000","0.00000000"],["115462.59000000","0.00000000"],["115462.60000000","0.00000000"],["115462.61000000","0.07031000"],["115462.92000000","0.10575000"],["115476.88000000","0.00583000"],["115477.21000000","0.00000000"],["115534.21000000","0.00000000"],["115534.22000000","0.00000000"],["115534.25000000","0.00100000"],["115534.26000000","0.00100000"],["117179.63000000","0.00100000"]]}
[2025-10-27T18:48:34.170Z] {"e":"depthUpdate","E":1761590914014,"s":"BTCUSDT","U":79129612885,"u":79129618815,"b":[["115478.77000000","8.57190000"],["115478.02000000","0.00000000"],["115477.99000000","0.00000000"],["115477.49000000","0.00000000"],["115477.32000000","0.00000000"],["115477.31000000","0.91293000"],["115477.30000000","0.00030000"],["115477.29000000","0.49526000"],["115476.89000000","0.00000000"],["115476.33000000","0.00000000"],["115476.32000000","0.00000000"],["115476.09000000","0.00000000"],["115476.01000000","0.00000000"],["115475.99000000","0.00000000"],["115475.81000000","0.00000000"],["115475.63000000","0.00704000"],["115475.61000000","0.24964000"],["115475.49000000","0.00000000"],["115475.44000000","0.00000000"],["115475.32000000","0.00000000"],["115475.01000000","0.00005000"],["115475.00000000","0.00000000"],["115474.92000000","0.00000000"],["115474.82000000","0.00000000"],["115474.63000000","0.00000000"],["115474.17000000","0.00000000"],["115474.03000000","0.00000000"],["115474.00000000","0.00000000"],["115473.99000000","0.00000000"],["115473.59000000","0.00000000"],["115473.49000000","0.00000000"],["115473.18000000","0.00000000"],["115473.04000000","0.06758000"],["115473.01000000","0.00000000"],["115472.74000000","0.09126000"],["115472.73000000","0.01697000"],["115472.70000000","0.00005000"],["115472.42000000","0.00000000"],["115472.28000000","0.00250000"],["115472.27000000","0.00000000"],["115472.26000000","0.00000000"],["115471.99000000","0.00005000"],["115471.98000000","0.08819000"],["115471.97000000","0.00000000"],["115471.88000000","0.00000000"],["115471.87000000","0.00000000"],["115471.65000000","0.00000000"],["115471.43000000","0.00000000"],["115471.27000000","0.00000000"],["115470.99000000","0.00000000"],["115470.75000000","0.00000000"],["115470.63000000","0.00000000"],["115470.55000000","0.00000000"],["115470.29000000","0.00000000"],["115470.02000000","0.00000000"],["115469.99000000","0.00000000"],["115469.79000000","0.00000000"],["115469.66000000","0.00000000"],["115469.57000000","0.00000000"],["115469.51000000","0.00000000"],["115469.40000000","0.00000000"],["115469.39000000","0.00000000"],["115469.36000000","0.04404000"],["115469.24000000","0.00005000"],["115469.23000000","0.00000000"],["115469.12000000","0.00000000"],["115469.00000000","0.00432000"],["115468.99000000","0.00000000"],["115468.61000000","0.00000000"],["115468.48000000","0.00000000"],["115468.46000000","0.00000000"],["115468.43000000","0.00000000"],["115468.42000000","0.00000000"],["115468.31000000","0.00000000"],["115468.30000000","0.16900000"],["115468.29000000","0.00000000"],["115468.28000000","0.00000000"],["115468.27000000","0.00000000"],["115468.02000000","0.00000000"],["115468.00000000","0.00000000"],["115467.99000000","0.00000000"],["115467.68000000","0.00000000"],["115467.66000000","0.00250000"],["115467.65000000","0.00000000"],["115467.25000000","0.00000000"],["115467.24000000","0.00532000"],["115467.17000000","0.00000000"],["115467.11000000","0.00000000"],["115466.84000000","0.00000000"],["115466.76000000","0.00000000"],["115466.59000000","0.00000000"],["115466.58000000","0.00000000"],["115466.40000000","0.00007000"],["115465.99000000","0.00000000"],["115465.83000000","0.00000000"],["115465.74000000","0.00021000"],["115465.72000000","0.00000000"],["115465.65000000","0.00100000"],["115465.63000000","0.00000000"],["115465.32000000","0.00000000"],["115465.25000000","0.00000000"],["115465.24000000","0.00000000"],["115465.23000000","0.00000000"],["115465.22000000","0.00000000"],["115465.00000000","0.06000000"],["115464.93000000","0.00000000"],["115464.82000000","0.00000000"],["115464.52000000","0.00000000"],["115464.41000000","0.00000000"],["115464.25000000","0.00000000"],["115464.09000000","0.00000000"],["115464.02000000","0.00000000"],["115464.00000000","0.00000000"],["115463.99000000","0.00000000"],["115463.96000000","0.00000000"],["115463.77000000","0.00000000"],["115463.76000000","0.00000000"],["115463.75000000","0.00000000"],["115463.65000000","0.00000000"],["115463.60000000","0.00000000"],["115463.55000000","0.54080000"],["115463.54000000","0.06748000"],["115463.47000000","0.00005000"],["115463.46000000","0.00000000"],["115463.38000000","0.00000000"],["115463.30000000","0.00000000"],["115463.21000000","0.00000000"],["115463.20000000","0.00000000"],["115463.18000000","0.08657000"],["115463.04000000","0.00250000"],["115463.01000000","0.00000000"],["115462.98000000","0.00000000"],["115462.97000000","0.00000000"],["115462.94000000","0.00000000"],["115462.92000000","0.28650000"],["115462.91000000","0.00500000"],["115462.86000000","0.00009000"],["115462.28000000","0.11658000"],["115462.01000000","0.04829000"],["115462.00000000","0.00500000"],["115461.99000000","0.00500000"],["115461.63000000","0.00009000"],["115461.54000000","0.00000000"],["115461.45000000","0.00150000"],["115461.44000000","0.21657000"],["115461.37000000","2.47832000"],["115461.26000000","0.00009000"],["115461.06000000","0.00000000"],["115461.05000000","0.00009000"],["115461.00000000","0.00000000"],["115460.95000000","0.00000000"],["115460.79000000","0.00000000"],["115460.71000000","0.00000000"],["115460.62000000","0.00009000"],["115460.54000000","0.00000000"],["115460.36000000","0.00009000"],["115460.07000000","0.54080000"],["115460.06000000","0.00000000"],["115459.99000000","0.00000000"],["115459.97000000","0.00086000"],["115459.90000000","0.00000000"],["115459.63000000","0.00000000"],["115459.45000000","0.00000000"],["115459.44000000","0.00000000"],["115459.26000000","0.00000000"],["115459.16000000","0.00000000"],["115459.12000000","0.00000000"],["115459.05000000","0.00000000"],["115458.84000000","0.15810000"],["115458.83000000","0.00000000"],["115458.64000000","0.00000000"],["115458.62000000","0.00000000"],["115458.53000000","0.00000000"],["115458.42000000","0.00250000"],["115458.35000000","0.00000000"],["115457.99000000","0.00000000"],["115457.95000000","0.00000000"],["115457.90000000","0.03000000"],["115457.71000000","0.00000000"],["115457.70000000","0.00005000"],["115457.69000000","0.25975000"],["115457.51000000","0.00000000"],["115457.45000000","0.00009000"],["115457.34000000","0.00000000"],["115457.32000000","0.00000000"],["115457.31000000","0.00000000"],["115457.23000000","0.00000000"],["115456.74000000","0.03000000"],["115456.73000000","0.00000000"],["115456.61000000","0.03995000"],["115455.99000000","0.03995000"],["115455.64000000","0.00000000"],["115455.59000000","1.16489000"],["115455.58000000","3.01912000"],["115455.57000000","0.00000000"],["115455.54000000","0.00000000"],["115455.53000000","0.00000000"],["115455.44000000","0.00000000"],["115455.43000000","0.03995000"],["115455.42000000","0.00000000"],["115455.35000000","0.00000000"],["115455.34000000","0.00000000"],["115455.32000000","0.00000000"],["115455.22000000","0.00000000"],["115455.12000000","0.00000000"],["115455.09000000","0.00000000"],["115455.02000000","0.00000000"],["115455.01000000","0.00000000"],["115454.99000000","0.00000000"],["115454.93000000","0.00007000"],["115454.92000000","0.00000000"],["115454.83000000","0.00000000"],["115454.82000000","0.03995000"],["115454.67000000","0.00000000"],["115454.65000000","0.00000000"],["115454.64000000","0.00000000"],["115454.59000000","0.04400000"],["115454.45000000","0.00000000"],["115454.43000000","0.00000000"],["115454.42000000","0.00000000"],["115454.41000000","0.25985000"],["115454.35000000","0.00000000"],["115454.33000000","0.00000000"],["115454.31000000","0.00000000"],["115454.26000000","0.00000000"],["115454.24000000","0.00000000"],["115454.23000000","0.03995000"],["115454.22000000","0.00000000"],["115454.10000000","0.00000000"],["115454.07000000","0.00000000"],["115454.05000000","0.00000000"],["115454.02000000","0.00000000"],["115454.00000000","0.00000000"],["115453.99000000","0.00000000"],["115453.92000000","0.00000000"],["115453.80000000","0.00250000"],["115453.56000000","0.00000000"],["115453.55000000","0.26991000"],["115453.54000000","0.03995000"],["115453.27000000","0.00000000"],["115452.99000000","0.00000000"],["115452.82000000","0.00009000"],["115452.51000000","0.00000000"],["115452.34000000","0.04000000"],["115452.32000000","0.31181000"],["115452.07000000","0.00000000"],["115451.99000000","0.00000000"],["115451.98000000","0.00000000"],["115451.93000000","0.00005000"],["115451.92000000","0.00000000"],["115451.74000000","0.00000000"],["115451.56000000","0.00000000"],["115451.21000000","0.03600000"],["115451.14000000","0.03300000"],["115450.96000000","0.00000000"],["115450.88000000","0.00000000"],["115450.78000000","0.00000000"],["115450.68000000","0.00261000"],["115450.57000000","0.00000000"],["115450.37000000","0.00000000"],["115450.14000000","0.00000000"],["115450.04000000","0.00000000"],["115449.99000000","0.00000000"],["115449.93000000","0.00086000"],["115449.81000000","0.00000000"],["115449.77000000","0.00000000"],["115449.76000000","0.00000000"],["115449.37000000","0.00000000"],["115449.18000000","0.00000000"],["115449.10000000","0.00000000"],["115449.09000000","0.54080000"],["115449.05000000","0.00000000"],["115448.83000000","0.00000000"],["115448.62000000","0.00005000"],["115448.56000000","0.00000000"],["115448.55000000","0.00000000"],["115448.49000000","1.11677000"],["115448.48000000","0.00000000"],["115448.46000000","0.00000000"],["115448.45000000","0.03995000"],["115448.17000000","0.00000000"],["115448.12000000","0.30000000"],["115448.11000000","0.00000000"],["115448.02000000","0.00000000"],["115448.00000000","2.47832000"],["115447.99000000","0.00000000"],["115447.98000000","0.00000000"],["115447.94000000","0.00000000"],["115447.92000000","0.00000000"],["115447.91000000","0.03995000"],["115447.90000000","0.33311000"],["115447.86000000","0.00041000"],["115447.85000000","0.00000000"],["115447.83000000","0.00000000"],["115447.69000000","0.00009000"],["115447.66000000","0.00000000"],["115447.65000000","0.00000000"],["115447.61000000","0.00000000"],["115447.60000000","0.00000000"],["115447.55000000","0.00000000"],["115447.54000000","0.00000000"],["115447.11000000","0.00000000"],["115447.06000000","0.00005000"],["115446.99000000","0.25975000"],["115446.72000000","0.00000000"],["115446.67000000","0.31182000"],["115446.36000000","0.00005000"],["115446.35000000","0.06748000"],["115446.02000000","0.00000000"],["115445.55000000","0.00006000"],["115445.04000000","0.00000000"],["115444.56000000","0.00000000"],["115444.52000000","0.00000000"],["115444.22000000","0.00000000"],["115443.87000000","0.35481000"],["115443.86000000","0.00000000"],["115443.82000000","0.00000000"],["115443.51000000","0.00441000"],["115443.46000000","0.00007000"],["115443.02000000","0.00005000"],["115442.90000000","0.00000000"],["115442.89000000","0.00000000"],["115442.88000000","0.00005000"],["115442.87000000","0.43307000"],["115442.81000000","0.54080000"],["115442.14000000","0.00000000"],["115441.45000000","0.00000000"],["115441.41000000","0.00000000"],["115441.39000000","0.00000000"],["115441.35000000","0.00000000"],["115441.04000000","0.00000000"],["115440.98000000","0.00520000"],["115440.96000000","0.00000000"],["115440.72000000","0.00000000"],["115440.62000000","0.31184000"],["115440.49000000","0.00000000"],["115440.44000000","0.00275000"],["115440.42000000","0.00000000"],["115440.27000000","1.39442000"],["115440.12000000","0.00000000"],["115440.10000000","0.00000000"],["115440.04000000","0.00000000"],["115440.02000000","0.00000000"],["115439.94000000","0.00000000"],["115439.82000000","0.00000000"],["115439.80000000","0.00012000"],["115439.69000000","0.51366000"],["115439.57000000","0.00009000"],["115439.49000000","0.06748000"],["115439.42000000","0.00000000"],["115439.04000000","0.00000000"],["115439.00000000","0.00021000"],["115438.83000000","0.00000000"],["115438.50000000","0.00000000"],["115438.40000000","0.00000000"],["115438.23000000","0.25305000"],["115438.21000000","0.00000000"],["115438.14000000","0.00000000"],["115437.97000000","0.00000000"],["115437.85000000","0.00000000"],["115437.56000000","0.00000000"],["115436.99000000","0.54080000"],["115436.92000000","0.00000000"],["115436.68000000","0.00086000"],["115436.54000000","0.00009000"],["115436.38000000","0.00000000"],["115436.37000000","2.47832000"],["115436.36000000","0.02693000"],["115436.32000000","0.00000000"],["115436.13000000","0.00000000"],["115436.01000000","0.03025000"],["115435.76000000","0.00000000"],["115435.63000000","0.31185000"],["115435.32000000","0.00000000"],["115434.71000000","0.03000000"],["115434.61000000","0.34651000"],["115433.56000000","0.03000000"],["115433.49000000","0.00000000"],["115433.48000000","0.03009000"],["115433.32000000","0.14726000"],["115432.89000000","0.00000000"],["115432.85000000","0.00000000"],["115432.82000000","0.05723000"],["115432.68000000","0.00000000"],["115431.88000000","0.17693000"],["115431.74000000","0.22087000"],["115431.49000000","0.14725000"],["115431.34000000","0.14719000"],["115431.16000000","0.00000000"],["115430.89000000","0.00000000"],["115430.70000000","0.00000000"],["115430.59000000","0.00000000"],["115430.58000000","0.00008000"],["115430.37000000","0.00009000"],["115430.25000000","0.00000000"],["115429.76000000","0.00000000"],["115429.68000000","0.00000000"],["115429.66000000","2.47832000"],["115429.51000000","0.03000000"],["115429.26000000","0.00000000"],["115429.14000000","0.00000000"],["115428.69000000","0.14725000"],["115428.56000000","0.00000000"],["115428.46000000","0.28914000"],["115428.45000000","0.00000000"],["115428.16000000","0.00000000"],["115428.01000000","0.00000000"],["115427.68000000","0.03000000"],["115426.99000000","0.00000000"],["115426.81000000","0.00000000"],["115426.70000000","0.00000000"],["115426.08000000","0.00000000"],["115425.46000000","0.00000000"],["115425.32000000","0.00000000"],["115425.01000000","0.00035000"],["115424.94000000","0.00000000"],["115424.52000000","0.00000000"],["115424.48000000","0.00033000"],["115423.50000000","0.00000000"],["115423.39000000","0.00000000"],["115422.87000000","0.00000000"],["115422.59000000","0.03683000"],["115422.33000000","0.00000000"],["115422.18000000","0.14725000"],["115422.15000000","0.02813000"],["115422.03000000","0.02338000"],["115422.02000000","1.11654000"],["115421.98000000","0.31518000"],["115421.48000000","0.00000000"],["115421.29000000","0.08000000"],["115420.57000000","0.00000000"],["115420.51000000","0.00000000"],["115420.17000000","0.00000000"],["115419.73000000","0.00000000"],["115419.42000000","0.00000000"],["115419.11000000","0.14719000"],["115418.82000000","0.00000000"],["115418.61000000","0.00000000"],["115418.48000000","0.00000000"],["115418.47000000","0.00000000"],["115417.87000000","0.00000000"],["115417.81000000","0.00000000"],["115417.73000000","0.00000000"],["115417.44000000","0.00000000"],["115417.31000000","0.00000000"],["115416.65000000","0.29141000"],["115416.25000000","0.00000000"],["115415.64000000","0.00000000"],["115415.63000000","0.00000000"],["115415.61000000","0.00000000"],["115414.77000000","0.00000000"],["115414.54000000","0.00000000"],["115413.86000000","0.25985000"],["115413.27000000","0.04333000"],["115413.26000000","0.00000000"],["115413.16000000","0.00000000"],["115412.74000000","0.00000000"],["115412.73000000","0.00000000"],["115412.15000000","0.08670000"],["115411.57000000","0.00350000"],["115411.54000000","0.00000000"],["115411.14000000","0.00006000"],["115410.71000000","0.00009000"],["115409.35000000","0.00000000"],["115409.17000000","0.00007000"],["115408.88000000","0.00000000"],["115408.86000000","0.00000000"],["115408.85000000","0.00000000"],["115408.49000000","0.00000000"],["115408.47000000","0.00623000"],["115407.52000000","0.00618000"],["115407.50000000","0.00000000"],["115407.30000000","0.25975000"],["115405.77000000","0.00000000"],["115405.58000000","2.47832000"],["115404.72000000","0.28629000"],["115404.36000000","0.00100000"],["115404.02000000","0.23031000"],["115403.93000000","0.00000000"],["115402.87000000","0.00000000"],["115402.48000000","0.00000000"],["115402.00000000","0.02458000"],["115401.85000000","0.02158000"],["115400.82000000","0.00619000"],["115400.71000000","0.00000000"],["115400.07000000","0.00000000"],["115400.00000000","0.00125000"],["115399.20000000","0.00000000"],["115398.74000000","0.00000000"],["115396.10000000","0.25776000"],["115396.01000000","0.02338000"],["115395.97000000","0.25975000"],["115395.95000000","0.00000000"],["115395.94000000","0.00008000"],["115395.27000000","0.02338000"],["115394.42000000","0.02338000"],["115394.23000000","0.00000000"],["115393.38000000","1.37467000"],["115392.14000000","0.00000000"],["115391.88000000","0.00000000"],["115391.03000000","0.00000000"],["115390.90000000","0.00000000"],["115390.43000000","0.00000000"],["115390.29000000","0.43307000"],["115389.32000000","0.00490000"],["115388.31000000","0.00000000"],["115387.35000000","0.00000000"],["115384.90000000","0.67597000"],["115384.89000000","0.00000000"],["115384.69000000","0.00000000"],["115384.57000000","0.00000000"],["115383.79000000","0.00000000"],["115383.59000000","0.00000000"],["115383.24000000","0.00000000"],["115382.32000000","1.05864000"],["115381.86000000","0.00000000"],["115381.24000000","0.00000000"],["115380.93000000","0.00000000"],["115380.01000000","0.00008000"],["115379.49000000","0.00000000"],["115378.68000000","0.00000000"],["115378.63000000","0.00000000"],["115377.17000000","0.00000000"],["115377.16000000","0.00000000"],["115377.05000000","0.00000000"],["115376.86000000","0.34651000"],["115376.40000000","0.20021000"],["115376.39000000","0.00000000"],["115375.42000000","0.00000000"],["115375.41000000","0.00000000"],["115374.92000000","0.00000000"],["115374.01000000","0.00000000"],["115373.94000000","0.00000000"],["115373.70000000","0.00000000"],["115372.32000000","0.05067000"],["115372.17000000","0.00000000"],["115371.40000000","0.00000000"],["115370.78000000","0.00000000"],["115370.77000000","0.76081000"],["115369.90000000","0.00000000"],["115369.45000000","0.02436000"],["115369.32000000","0.00000000"],["115368.78000000","0.00112000"],["115368.72000000","0.09389000"],["115368.33000000","0.04002000"],["115368.01000000","0.00008000"],["115367.21000000","0.00000000"],["115366.75000000","0.00500000"],["115365.77000000","0.00000000"],["115365.01000000","0.00000000"],["115364.30000000","0.02157000"],["115363.97000000","0.00000000"],["115363.85000000","0.00000000"],["115363.84000000","0.47577000"],["115363.83000000","0.86680000"],["115362.93000000","0.00000000"],["115362.02000000","0.00000000"],["115361.90000000","0.00000000"],["115361.30000000","0.00008000"],["115361.27000000","0.00000000"],["115360.99000000","0.00000000"],["115360.90000000","0.00000000"],["115360.11000000","0.46869000"],["115359.23000000","0.06396000"],["115359.22000000","0.83956000"],["115357.91000000","0.00000000"],["115353.14000000","0.00000000"],["115352.60000000","0.00000000"],["115352.30000000","0.00000000"],["115351.88000000","0.03942000"],["115350.19000000","0.00000000"],["115349.93000000","0.09389000"],["115347.83000000","0.00000000"],["115347.67000000","0.95351000"],["115347.66000000","0.00000000"],["115346.38000000","0.00000000"],["115346.09000000","0.00000000"],["115344.45000000","0.00000000"],["115344.00000000","0.00160000"],["115342.05000000","0.00000000"],["115341.28000000","0.00000000"],["115340.48000000","0.71279000"],["115340.00000000","0.00160000"],["115339.70000000","0.00009000"],["115339.58000000","0.00000000"],["115336.83000000","0.00000000"],["115336.78000000","1.28960000"],["115336.29000000","0.08972000"],["115336.12000000","0.00000000"],["115336.11000000","0.00000000"],["115334.47000000","0.00000000"],["115332.87000000","0.00000000"],["115332.57000000","0.00000000"],["115332.27000000","0.00215000"],["115331.25000000","0.00000000"],["115329.64000000","0.00000000"],["115329.25000000","0.24498000"],["115329.24000000","1.15230000"],["115328.76000000","0.00007000"],["115326.66000000","0.00008000"],["115326.10000000","0.00000000"],["115326.09000000","0.00000000"],["115326.08000000","0.00000000"],["115324.57000000","0.00000000"],["115324.56000000","0.00000000"],["115321.87000000","0.00000000"],["115321.47000000","0.00182000"],["115321.44000000","0.00000000"],["115320.00000000","0.00588000"],["115319.00000000","0.88636000"],["115315.20000000","0.00000000"],["115312.51000000","0.00000000"],["115309.85000000","0.00000000"],["115309.36000000","0.00000000"],["115307.96000000","0.00000000"],["115301.04000000","0.00000000"],["115299.74000000","0.00000000"],["115299.09000000","0.00000000"],["115298.04000000","0.00499000"],["115295.66000000","0.00000000"],["115294.07000000","0.06000000"],["115293.15000000","0.00000000"],["115292.20000000","0.00000000"],["115292.19000000","0.00000000"],["115292.02000000","0.00008000"],["115290.78000000","0.08653000"],["115288.12000000","0.00000000"],["115284.26000000","0.00000000"],["115284.25000000","0.00008000"],["115284.22000000","0.00000000"],["115280.00000000","0.01805000"],["115279.20000000","0.00193000"],["115276.82000000","0.16094000"],["115274.73000000","0.00000000"],["115274.55000000","0.00000000"],["115270.05000000","0.00000000"],["115264.01000000","0.00000000"],["115254.15000000","0.00000000"],["115254.14000000","0.00307000"],["115241.44000000","0.00000000"],["115238.60000000","0.00000000"],["115238.04000000","0.00000000"],["115238.02000000","0.00000000"],["115237.81000000","0.00000000"],["115231.07000000","0.00000000"],["115229.85000000","0.00000000"],["115228.95000000","0.00000000"],["115228.69000000","0.00000000"],["115228.30000000","0.00000000"],["115227.76000000","0.00000000"],["115227.49000000","0.00000000"],["115226.66000000","0.00000000"],["115226.61000000","0.00000000"],["115226.39000000","0.00000000"],["115225.02000000","0.00000000"],["115224.79000000","0.00000000"],["115224.77000000","0.00000000"],["115223.31000000","0.00000000"],["115223.28000000","0.00000000"],["115220.46000000","0.00000000"],["115220.44000000","0.97216000"],["115220.41000000","0.00000000"],["115220.30000000","0.00000000"],["115218.63000000","0.00000000"],["115217.24000000","4.61656000"],["115207.63000000","0.00000000"],["115206.93000000","0.00000000"],["115196.57000000","0.19455000"],["115192.34000000","0.00000000"],["115191.84000000","0.01732000"],["115177.66000000","0.00064000"],["115166.09000000","0.00000000"],["115160.88000000","0.00077000"],["115160.21000000","0.02338000"],["115147.90000000","0.00000000"],["115147.41000000","0.00000000"],["115138.52000000","0.00000000"],["115132.75000000","0.00008000"],["115129.59000000","0.00000000"],["115123.82000000","0.00000000"],["115123.09000000","0.03098000"],["115122.48000000","0.03098000"],["115121.47000000","0.03098000"],["115120.93000000","0.03098000"],["115120.50000000","0.03098000"],["115118.05000000","0.00000000"],["115114.59000000","0.00000000"],["115112.83000000","0.00000000"],["115112.81000000","0.02338000"],["115108.82000000","0.00000000"],["115107.61000000","0.00000000"],["115103.05000000","0.00000000"],["115096.28000000","0.02338000"],["115090.50000000","0.00000000"],["115089.75000000","0.00000000"],["115088.51000000","0.00000000"],["115087.80000000","0.00000000"],["115087.58000000","0.00000000"],["115087.00000000","0.00000000"],["115086.84000000","0.00000000"],["115086.73000000","0.00000000"],["115073.16000000","0.00000000"],["115071.74000000","0.00000000"],["115070.47000000","0.00000000"],["115066.35000000","0.00000000"],["115048.72000000","0.00000000"],["115039.22000000","0.00000000"],["115038.32000000","0.00000000"],["115036.53000000","0.00000000"],["115035.39000000","0.00000000"],["115034.60000000","0.00000000"],["115030.25000000","0.00000000"],["115029.26000000","0.00000000"],["115028.54000000","0.00000000"],["115028.32000000","0.00000000"],["115027.50000000","0.00000000"],["115027.40000000","0.00000000"],["115027.07000000","0.00000000"],["115024.80000000","0.00000000"],["114967.13000000","0.00000000"],["114959.88000000","0.00000000"],["114958.82000000","0.00000000"],["114931.88000000","0.00000000"],["114930.95000000","0.00000000"],["114930.43000000","0.00000000"],["114929.87000000","0.00000000"],["114929.38000000","0.00000000"],["114928.13000000","0.00000000"],["114926.27000000","0.00000000"],["114925.04000000","0.00000000"],["114924.90000000","0.00000000"],["114924.23000000","0.00000000"],["114923.94000000","0.00000000"],["114923.72000000","0.00000000"],["114922.65000000","0.00000000"],["114922.55000000","0.00000000"],["114921.86000000","0.00000000"],["114921.27000000","0.00000000"],["114842.91000000","1.13365000"],["114781.75000000","0.00000000"],["114705.60000000","0.00000000"],["113716.18000000","0.00000000"],["111981.06000000","0.02172000"],["111958.93000000","0.00000000"],["103921.00000000","0.00010000"],["103902.00000000","0.00010000"],["92383.02000000","0.00021000"],["92358.32000000","0.00000000"]],"a":[["115447.91000000","0.00000000"],["115447.92000000","0.00000000"],["115447.93000000","0.00000000"],["115447.99000000","0.00000000"],["115448.00000000","0.00000000"],["115448.12000000","0.00000000"],["115448.13000000","0.00000000"],["115449.06000000","0.00000000"],["115449.11000000","0.00000000"],["115449.30000000","0.00000000"],["115449.38000000","0.00000000"],["115449.46000000","0.00000000"],["115449.76000000","0.00000000"],["115449.77000000","0.00000000"],["115449.78000000","0.00000000"],["115449.82000000","0.00000000"],["115450.00000000","0.00000000"],["115450.05000000","0.00000000"],["115450.15000000","0.00000000"],["115450.38000000","0.00000000"],["115450.79000000","0.00000000"],["115451.23000000","0.00000000"],["115451.30000000","0.00000000"],["115451.54000000","0.00000000"],["115451.62000000","0.00000000"],["115451.63000000","0.00000000"],["115451.64000000","0.00000000"],["115451.71000000","0.00000000"],["115451.72000000","0.00000000"],["115451.93000000","0.00000000"],["115451.98000000","0.00000000"],["115451.99000000","0.00000000"],["115452.00000000","0.00000000"],["115452.04000000","0.00000000"],["115452.05000000","0.00000000"],["115452.08000000","0.00000000"],["115452.17000000","0.00000000"],["115452.52000000","0.00000000"],["115452.71000000","0.00000000"],["115453.00000000","0.00000000"],["115453.28000000","0.00000000"],["115454.00000000","0.00000000"],["115454.23000000","0.00000000"],["115454.24000000","0.00000000"],["115454.34000000","0.00000000"],["115454.36000000","0.00000000"],["115454.42000000","0.00000000"],["115454.43000000","0.00000000"],["115454.44000000","0.00000000"],["115454.55000000","0.00000000"],["115454.83000000","0.00000000"],["115454.91000000","0.00000000"],["115455.00000000","0.00000000"],["115455.03000000","0.00000000"],["115455.13000000","0.00000000"],["115455.32000000","0.00000000"],["115455.33000000","0.00000000"],["115455.36000000","0.00000000"],["115455.46000000","0.00000000"],["115455.58000000","0.00000000"],["115455.92000000","0.00000000"],["115456.00000000","0.00000000"],["115456.62000000","0.00000000"],["115456.74000000","0.00000000"],["115457.32000000","0.00000000"],["115457.52000000","0.00000000"],["115457.59000000","0.00000000"],["115457.70000000","0.00000000"],["115457.72000000","0.00000000"],["115457.95000000","0.00000000"],["115458.00000000","0.00000000"],["115458.02000000","0.00000000"],["115458.20000000","0.00000000"],["115458.28000000","0.00000000"],["115458.42000000","0.00000000"],["115458.53000000","0.00000000"],["115458.54000000","0.00000000"],["115458.57000000","0.00000000"],["115458.64000000","0.00000000"],["115458.65000000","0.00000000"],["115458.84000000","0.00000000"],["115459.13000000","0.00000000"],["115459.17000000","0.00000000"],["115459.44000000","0.00000000"],["115459.45000000","0.00000000"],["115459.46000000","0.00000000"],["115459.91000000","0.00000000"],["115459.93000000","0.00000000"],["115459.94000000","0.00000000"],["115460.00000000","0.00000000"],["115460.07000000","0.00000000"],["115460.10000000","0.00000000"],["115460.14000000","0.00000000"],["115460.16000000","0.00000000"],["115460.20000000","0.00000000"],["115460.33000000","0.00000000"],["115460.51000000","0.00000000"],["115460.53000000","0.00000000"],["115460.72000000","0.00000000"],["115460.80000000","0.00000000"],["115460.96000000","0.00000000"],["115461.01000000","0.00000000"],["115461.15000000","0.00000000"],["115461.28000000","0.00000000"],["115461.79000000","0.00000000"],["115462.00000000","0.00000000"],["115462.01000000","0.00000000"],["115462.61000000","0.00000000"],["115462.92000000","0.00000000"],["115462.98000000","0.00000000"],["115463.04000000","0.00000000"],["115463.09000000","0.00000000"],["115463.14000000","0.00000000"],["115463.16000000","0.00000000"],["115463.21000000","0.00000000"],["115463.24000000","0.00000000"],["115463.31000000","0.00000000"],["115463.39000000","0.00000000"],["115463.47000000","0.00000000"],["115463.61000000","0.00000000"],["115463.66000000","0.00000000"],["115463.76000000","0.00000000"],["115463.78000000","0.00000000"],["115463.97000000","0.00000000"],["115464.00000000","0.00000000"],["115464.26000000","0.00000000"],["115464.66000000","0.00000000"],["115464.83000000","0.00000000"],["115464.94000000","0.00000000"],["115465.23000000","0.00000000"],["115465.25000000","0.00000000"],["115465.58000000","0.00000000"],["115465.64000000","0.00000000"],["115465.84000000","0.00000000"],["115466.00000000","0.00000000"],["115466.12000000","0.00000000"],["115466.18000000","0.00000000"],["115466.59000000","0.00000000"],["115466.60000000","0.00000000"],["115466.85000000","0.00000000"],["115467.12000000","0.00000000"],["115467.24000000","0.00000000"],["115467.25000000","0.00000000"],["115467.44000000","0.00000000"],["115467.66000000","0.00000000"],["115467.73000000","0.00000000"],["115467.77000000","0.00000000"],["115468.00000000","0.00000000"],["115468.28000000","0.00000000"],["115468.29000000","0.00000000"],["115468.30000000","0.00000000"],["115468.34000000","0.00000000"],["115468.43000000","0.00000000"],["115468.44000000","0.00000000"],["115468.49000000","0.00000000"],["115468.57000000","0.00000000"],["115468.58000000","0.00000000"],["115468.61000000","0.00000000"],["115468.62000000","0.00000000"],["115468.63000000","0.00000000"],["115469.00000000","0.00000000"],["115469.01000000","0.00000000"],["115469.10000000","0.00000000"],["115469.11000000","0.00000000"],["115469.13000000","0.00000000"],["115469.24000000","0.00000000"],["115469.40000000","0.00000000"],["115469.43000000","0.00000000"],["115469.47000000","0.00000000"],["115469.51000000","0.00000000"],["115469.52000000","0.00000000"],["115469.57000000","0.00000000"],["115469.58000000","0.00000000"],["115469.67000000","0.00000000"],["115469.80000000","0.00000000"],["115470.00000000","0.00000000"],["115470.03000000","0.00000000"],["115470.23000000","0.00000000"],["115470.30000000","0.00000000"],["115470.55000000","0.00000000"],["115470.56000000","0.00000000"],["115470.58000000","0.00000000"],["115470.63000000","0.00000000"],["115470.64000000","0.00000000"],["115470.76000000","0.00000000"],["115471.00000000","0.00000000"],["115471.03000000","0.00000000"],["115471.29000000","0.00000000"],["115471.31000000","0.00000000"],["115471.43000000","0.00000000"],["115471.44000000","0.00000000"],["115471.58000000","0.00000000"],["115471.65000000","0.00000000"],["115471.66000000","0.00000000"],["115471.83000000","0.00000000"],["115471.88000000","0.00000000"],["115471.99000000","0.00000000"],["115472.00000000","0.00000000"],["115472.27000000","0.00000000"],["115472.28000000","0.00000000"],["115472.43000000","0.00000000"],["115472.92000000","0.00000000"],["115473.02000000","0.00000000"],["115473.19000000","0.00000000"],["115473.49000000","0.00000000"],["115473.50000000","0.00000000"],["115473.60000000","0.00000000"],["115473.78000000","0.00000000"],["115473.79000000","0.00000000"],["115473.91000000","0.00000000"],["115474.00000000","0.00000000"],["115474.04000000","0.00000000"],["115474.18000000","0.00000000"],["115474.64000000","0.00000000"],["115474.81000000","0.00000000"],["115474.83000000","0.00000000"],["115474.93000000","0.00000000"],["115475.01000000","0.00000000"],["115475.33000000","0.00000000"],["115475.45000000","0.00000000"],["115475.49000000","0.00000000"],["115475.50000000","0.00000000"],["115475.58000000","0.00000000"],["115475.64000000","0.00000000"],["115475.82000000","0.00000000"],["115475.98000000","0.00000000"],["115475.99000000","0.00000000"],["115476.00000000","0.00000000"],["115476.02000000","0.00000000"],["115476.10000000","0.00000000"],["115476.34000000","0.00000000"],["115476.82000000","0.00000000"],["115476.88000000","0.00000000"],["115476.90000000","0.00000000"],["115477.30000000","0.00000000"],["115477.31000000","0.00000000"],["115477.32000000","0.00000000"],["115477.44000000","0.00000000"],["115477.50000000","0.00000000"],["115477.68000000","0.00000000"],["115477.89000000","0.00000000"],["115477.98000000","0.00000000"],["115477.99000000","0.00000000"],["115478.00000000","0.00000000"],["115478.35000000","0.00000000"],["115478.78000000","0.55966000"],["115478.79000000","0.00115000"],["115478.80000000","0.00000000"],["115479.30000000","0.00000000"],["115479.38000000","0.00000000"],["115479.42000000","0.00058000"],["115479.45000000","0.00000000"],["115479.47000000","0.00010000"],["115479.48000000","0.11262000"],["115479.49000000","0.00000000"],["115479.55000000","0.00000000"],["115479.94000000","0.00000000"],["115479.95000000","0.00005000"],["115479.96000000","0.00000000"],["115479.98000000","0.00000000"],["115479.99000000","0.00010000"],["115480.00000000","0.01892000"],["115480.10000000","0.00000000"],["115480.40000000","0.00000000"],["115480.82000000","0.00000000"],["115480.83000000","0.00000000"],["115480.95000000","0.00000000"],["115480.98000000","0.00010000"],["115480.99000000","0.00010000"],["115481.10000000","0.00000000"],["115481.15000000","0.00036000"],["115481.51000000","0.00000000"],["115481.52000000","0.00005000"],["115481.55000000","0.00000000"],["115481.67000000","0.00000000"],["115481.71000000","0.00000000"],["115482.00000000","0.00165000"],["115482.21000000","0.00000000"],["115482.45000000","0.00000000"],["115482.52000000","0.00000000"],["115482.53000000","0.00010000"],["115482.54000000","0.04344000"],["115482.55000000","0.00305000"],["115482.56000000","0.00000000"],["115482.57000000","0.00000000"],["115482.65000000","0.00000000"],["115483.18000000","0.00000000"],["115483.19000000","0.00000000"],["115483.22000000","0.00000000"],["115483.27000000","0.00000000"],["115483.30000000","0.00000000"],["115483.40000000","0.00000000"],["115483.55000000","0.00000000"],["115483.79000000","0.00000000"],["115483.84000000","0.00000000"],["115484.00000000","0.00160000"],["115484.05000000","0.00000000"],["115484.16000000","0.00000000"],["115484.43000000","0.00000000"],["115484.56000000","0.00005000"],["115484.57000000","0.28729000"],["115484.95000000","0.00000000"],["115484.99000000","0.06000000"],["115485.19000000","0.00000000"],["115485.26000000","0.00000000"],["115485.36000000","0.00000000"],["115485.59000000","0.00000000"],["115485.60000000","0.00000000"],["115485.61000000","0.00005000"],["115485.62000000","0.01773000"],["115485.65000000","0.00032000"],["115485.69000000","0.08000000"],["115486.00000000","0.00165000"],["115486.05000000","0.00000000"],["115486.14000000","0.00250000"],["115486.19000000","0.00000000"],["115486.27000000","0.00000000"],["115486.34000000","0.00000000"],["115486.50000000","0.00038000"],["115486.64000000","0.00000000"],["115486.69000000","0.00000000"],["115486.70000000","0.00000000"],["115486.76000000","0.00681000"],["115487.00000000","0.00005000"],["115487.15000000","0.00000000"],["115487.27000000","0.00000000"],["115487.33000000","0.00000000"],["115487.34000000","0.03008000"],["115487.42000000","0.00000000"],["115487.47000000","0.00000000"],["115487.71000000","0.00000000"],["115488.00000000","0.00170000"],["115488.61000000","0.00000000"],["115488.85000000","0.08663000"],["115489.00000000","0.33578000"],["115489.01000000","0.54085000"],["115489.02000000","0.00000000"],["115489.04000000","0.00000000"],["115489.05000000","0.04005000"],["115489.09000000","0.00000000"],["115489.26000000","0.00155000"],["115489.66000000","0.00000000"],["115489.67000000","0.00000000"],["115489.83000000","0.00000000"],["115490.00000000","0.00160000"],["115490.01000000","0.00033000"],["115490.09000000","0.00035000"],["115490.52000000","0.00000000"],["115490.63000000","0.00000000"],["115490.72000000","0.00000000"],["115490.76000000","0.00250000"],["115490.89000000","0.00000000"],["115491.07000000","0.00000000"],["115491.11000000","0.00000000"],["115491.12000000","0.00000000"],["115491.16000000","0.00000000"],["115491.39000000","0.03900000"],["115491.46000000","0.00000000"],["115491.54000000","0.04592000"],["115492.02000000","0.00000000"],["115492.31000000","0.07827000"],["115492.43000000","0.00009000"],["115492.44000000","0.32219000"],["115492.45000000","0.00000000"],["115492.55000000","0.04500000"],["115492.62000000","0.00000000"],["115492.80000000","0.16000000"],["115493.98000000","0.00000000"],["115493.99000000","0.00000000"],["115494.02000000","0.00000000"],["115494.62000000","0.00150000"],["115494.64000000","0.00000000"],["115494.66000000","0.00259000"],["115494.84000000","0.00000000"],["115495.18000000","0.00000000"],["115495.19000000","0.00037000"],["115495.21000000","0.00000000"],["115495.25000000","0.00033000"],["115495.33000000","0.00000000"],["115495.38000000","0.00250000"],["115495.63000000","0.00000000"],["115495.83000000","0.00000000"],["115495.84000000","0.00000000"],["115495.92000000","0.00000000"],["115496.60000000","0.04399000"],["115497.80000000","0.00000000"],["115497.95000000","0.00000000"],["115497.97000000","0.00000000"],["115497.98000000","0.00000000"],["115497.99000000","0.00000000"],["115498.21000000","0.03000000"],["115499.48000000","0.00432000"],["115499.49000000","0.00000000"],["115499.57000000","0.00000000"],["115499.98000000","0.00000000"],["115500.00000000","0.04642000"],["115500.02000000","0.00035000"],["115500.29000000","0.00100000"],["115500.30000000","0.00032000"],["115500.40000000","0.21657000"],["115500.48000000","0.00008000"],["115500.55000000","0.00000000"],["115500.97000000","0.00000000"],["115500.98000000","0.00000000"],["115501.13000000","0.00000000"],["115501.22000000","0.00000000"],["115501.99000000","0.00000000"],["115502.16000000","0.00000000"],["115502.25000000","0.25683000"],["115502.55000000","0.43307000"],["115502.61000000","0.07028000"],["115502.71000000","0.00021000"],["115502.87000000","0.00000000"],["115503.17000000","0.00000000"],["115503.24000000","0.16996000"],["115503.25000000","0.00000000"],["115503.28000000","0.00005000"],["115503.36000000","0.00000000"],["115503.61000000","0.00000000"],["115503.63000000","0.25990000"],["115503.77000000","0.00000000"],["115503.82000000","0.00000000"],["115503.90000000","0.00000000"],["115504.46000000","0.00000000"],["115504.56000000","0.00000000"],["115504.62000000","0.00250000"],["115504.89000000","0.00000000"],["115505.04000000","0.00445000"],["115505.63000000","0.00012000"],["115505.64000000","0.00000000"],["115505.65000000","0.00000000"],["115505.67000000","0.00000000"],["115505.95000000","0.00000000"],["115505.99000000","0.00000000"],["115506.16000000","0.00086000"],["115506.20000000","0.00000000"],["115506.29000000","0.00000000"],["115506.78000000","0.00000000"],["115507.08000000","0.00000000"],["115507.83000000","0.00000000"],["115508.06000000","0.00000000"],["115508.21000000","0.00000000"],["115508.43000000","0.00000000"],["115508.87000000","0.00000000"],["115508.88000000","0.00000000"],["115509.08000000","0.00009000"],["115509.20000000","0.03300000"],["115509.63000000","0.00005000"],["115509.69000000","0.20264000"],["115509.96000000","0.00018000"],["115509.98000000","0.00000000"],["115509.99000000","0.00000000"],["115511.61000000","0.00000000"],["115511.62000000","0.03900000"],["115511.78000000","0.00000000"],["115511.99000000","0.00000000"],["115512.95000000","0.04329000"],["115513.06000000","0.00000000"],["115513.59000000","0.00272000"],["115514.79000000","0.00000000"],["115514.96000000","0.03000000"],["115515.00000000","0.14721000"],["115515.14000000","0.00000000"],["115515.24000000","0.00000000"],["115515.40000000","0.00005000"],["115515.62000000","0.00000000"],["115515.73000000","1.12695000"],["115515.74000000","0.05107000"],["115515.99000000","0.00000000"],["115516.09000000","0.08000000"],["115516.15000000","0.00000000"],["115516.16000000","0.31163000"],["115516.37000000","0.25801000"],["115516.38000000","0.25726000"],["115516.45000000","0.00000000"],["115516.46000000","0.00000000"],["115516.95000000","0.00000000"],["115517.08000000","0.00000000"],["115517.18000000","0.00000000"],["115517.23000000","0.14725000"],["115517.32000000","0.00000000"],["115517.43000000","0.00000000"],["115517.65000000","0.00000000"],["115518.29000000","0.00000000"],["115518.34000000","0.54080000"],["115518.62000000","0.00000000"],["115518.88000000","0.00000000"],["115519.48000000","0.00000000"],["115519.59000000","0.00000000"],["115519.99000000","0.00000000"],["115520.22000000","0.46804000"],["115520.35000000","0.00000000"],["115520.69000000","0.17679000"],["115520.84000000","0.00000000"],["115521.17000000","0.00005000"],["115521.24000000","0.00000000"],["115521.46000000","0.31162000"],["115521.99000000","0.00000000"],["115522.49000000","0.00000000"],["115522.50000000","0.62374000"],["115523.53000000","0.33259000"],["115523.99000000","0.00008000"],["115524.68000000","0.00000000"],["115525.27000000","0.54080000"],["115525.29000000","0.14779000"],["115525.36000000","0.02849000"],["115525.61000000","0.31161000"],["115526.30000000","0.00000000"],["115526.34000000","0.34651000"],["115526.38000000","0.00000000"],["115526.89000000","0.00000000"],["115526.94000000","0.00005000"],["115527.04000000","0.25975000"],["115527.29000000","0.00000000"],["115527.53000000","0.01645000"],["115527.54000000","0.00000000"],["115527.99000000","0.01732000"],["115528.07000000","0.01732000"],["115528.09000000","0.14719000"],["115528.84000000","0.02338000"],["115528.85000000","0.54080000"],["115528.86000000","1.10104000"],["115529.48000000","0.00000000"],["115529.70000000","0.00000000"],["115529.74000000","0.25985000"],["115529.93000000","0.00000000"],["115531.09000000","0.08000000"],["115531.91000000","0.00000000"],["115531.98000000","0.00000000"],["115531.99000000","0.00000000"],["115532.49000000","0.00000000"],["115532.71000000","0.00005000"],["115533.50000000","0.22087000"],["115533.69000000","0.14726000"],["115533.99000000","0.01645000"],["115534.09000000","0.00000000"],["115534.25000000","0.00000000"],["115534.26000000","0.00000000"],["115534.94000000","0.00000000"],["115535.12000000","0.00008000"],["115535.76000000","0.00000000"],["115535.77000000","0.42473000"],["115535.78000000","0.54080000"],["115535.79000000","0.00000000"],["115535.96000000","0.00000000"],["115535.97000000","0.00000000"],["115535.98000000","0.00000000"],["115535.99000000","0.00000000"],["115536.18000000","0.00000000"],["115536.94000000","0.00057000"],["115537.02000000","0.18619000"],["115537.56000000","0.14725000"],["115537.74000000","0.00000000"],["115538.26000000","0.00000000"],["115538.32000000","0.00000000"],["115539.34000000","0.07084000"],["115539.99000000","0.00000000"],["115541.21000000","0.04814000"],["115541.38000000","0.54080000"],["115541.96000000","0.00000000"],["115542.22000000","0.00000000"],["115542.83000000","0.03683000"],["115543.02000000","0.00000000"],["115543.99000000","0.00000000"],["115544.42000000","0.23831000"],["115544.73000000","0.02161000"],["115545.99000000","0.00216000"],["115546.73000000","0.00000000"],["115546.81000000","0.00000000"],["115546.84000000","0.00624000"],["115547.22000000","0.00000000"],["115547.61000000","0.00000000"],["115547.99000000","0.00000000"],["115548.31000000","0.54080000"],["115548.43000000","0.25975000"],["115549.19000000","0.00620000"],["115549.54000000","0.00000000"],["115550.23000000","0.00000000"],["115550.53000000","0.00620000"],["115551.39000000","0.01800000"],["115551.56000000","1.20379000"],["115551.81000000","0.00000000"],["115552.76000000","0.00000000"],["115552.94000000","0.54080000"],["115553.33000000","1.01287000"],["115554.30000000","0.00000000"],["115554.33000000","0.00000000"],["115555.41000000","0.00000000"],["115555.43000000","0.03446000"],["115555.81000000","0.09122000"],["115555.82000000","0.02338000"],["115555.83000000","0.00000000"],["115556.72000000","0.00000000"],["115557.14000000","0.02338000"],["115557.26000000","0.14726000"],["115557.60000000","0.00000000"],["115557.91000000","0.00000000"],["115557.92000000","0.00000000"],["115557.99000000","0.02338000"],["115558.11000000","0.00000000"],["115559.99000000","0.00000000"],["115560.07000000","0.02243000"],["115561.44000000","0.02338000"],["115562.12000000","0.73876000"],["115562.29000000","1.05984000"],["115562.36000000","0.00000000"],["115562.87000000","0.00000000"],["115564.11000000","0.00000000"],["115564.50000000","2.47832000"],["115564.58000000","0.00000000"],["115565.24000000","0.02338000"],["115565.92000000","0.03900000"],["115565.99000000","0.07014000"],["115566.30000000","0.34651000"],["115567.07000000","0.04500000"],["115567.47000000","0.00433000"],["115569.72000000","0.01296000"],["115569.76000000","0.00008000"],["115569.98000000","0.14972000"],["115569.99000000","0.02338000"],["115570.00000000","0.00160000"],["115570.54000000","0.00000000"],["115570.55000000","0.00000000"],["115570.92000000","0.00005000"],["115571.14000000","0.03234000"],["115571.99000000","0.02338000"],["115572.62000000","0.43307000"],["115572.73000000","0.03000000"],["115572.87000000","0.00000000"],["115573.15000000","0.25975000"],["115573.46000000","0.75752000"],["115573.59000000","0.00000000"],["115573.76000000","0.03681000"],["115573.98000000","0.00000000"],["115575.63000000","0.04002000"],["115575.99000000","0.00499000"],["115576.05000000","2.47832000"],["115576.12000000","0.00112000"],["115576.83000000","0.02436000"],["115577.62000000","0.00000000"],["115578.97000000","0.00000000"],["115579.24000000","0.00499000"],["115579.25000000","0.00000000"],["115579.91000000","0.00000000"],["115579.99000000","0.02338000"],["115580.00000000","0.01890000"],["115580.97000000","0.00000000"],["115581.07000000","0.00000000"],["115582.95000000","0.00000000"],["115586.04000000","0.03000000"],["115586.45000000","0.00000000"],["115587.58000000","0.02338000"],["115587.59000000","1.04272000"],["115587.60000000","2.47832000"],["115589.83000000","0.00000000"],["115590.12000000","0.00000000"],["115590.54000000","0.00000000"],["115591.99000000","0.02338000"],["115595.72000000","0.02338000"],["115596.13000000","0.00000000"],["115596.44000000","0.00100000"],["115596.92000000","2.27066000"],["115596.93000000","2.47832000"],["115596.94000000","0.00000000"],["115603.31000000","0.00000000"],["115604.40000000","0.00008000"],["115606.26000000","0.07511000"],["115613.95000000","0.04597000"],["115614.73000000","0.09389000"],["115617.13000000","0.04597000"],["115617.52000000","0.16340000"],["115619.10000000","0.04597000"],["115619.99000000","0.21712000"],["115620.08000000","0.04597000"],["115620.44000000","0.00000000"],["115620.71000000","0.00000000"],["115620.89000000","0.00000000"],["115621.08000000","0.00000000"],["115621.49000000","0.04597000"],["115623.10000000","0.04597000"],["115624.38000000","0.09389000"],["115624.55000000","0.08728000"],["115626.41000000","0.00000000"],["115629.23000000","0.00000000"],["115632.87000000","0.00000000"],["115633.76000000","0.04597000"],["115636.22000000","0.08733000"],["115638.31000000","0.00000000"],["115639.04000000","0.00008000"],["115646.45000000","0.00000000"],["115646.62000000","0.00000000"],["115647.67000000","0.00000000"],["115649.99000000","0.00086000"],["115650.16000000","0.00000000"],["115651.38000000","0.00000000"],["115652.16000000","0.00019000"],["115652.77000000","0.00000000"],["115653.88000000","0.00000000"],["115656.39000000","0.00000000"],["115656.45000000","0.09927000"],["115658.26000000","0.00000000"],["115661.24000000","0.00086000"],["115661.97000000","0.00000000"],["115662.48000000","0.00000000"],["115666.65000000","0.05528000"],["115668.73000000","0.01645000"],["115668.91000000","0.00000000"],["115673.34000000","0.01645000"],["115674.20000000","0.12123000"],["115674.41000000","0.00007000"],["115676.04000000","0.01356000"],["115676.96000000","0.02599000"],["115677.04000000","0.01645000"],["115682.17000000","0.02016000"],["115684.27000000","0.37808000"],["115690.00000000","0.04466000"],["115692.93000000","0.00000000"],["115695.83000000","0.07484000"],["115696.98000000","0.01645000"],["115697.38000000","0.01645000"],["115700.46000000","0.01645000"],["115700.47000000","0.01645000"],["115700.48000000","0.01645000"],["115701.70000000","0.00000000"],["115705.94000000","0.00000000"],["115707.24000000","0.00000000"],["115709.49000000","0.00000000"],["115711.64000000","0.00000000"],["115731.72000000","0.00000000"],["115732.02000000","0.00000000"],["115732.13000000","0.00000000"],["115733.68000000","0.00000000"],["115734.33000000","0.00000000"],["115734.67000000","0.00000000"],["115735.39000000","0.00000000"],["115735.66000000","0.00000000"],["115738.11000000","0.00000000"],["115741.11000000","0.00000000"],["115744.79000000","0.00000000"],["115745.25000000","0.00000000"],["115745.48000000","0.00000000"],["115746.44000000","0.00000000"],["115746.90000000","0.00000000"],["115747.86000000","0.00000000"],["115748.63000000","0.00000000"],["115749.26000000","0.22443000"],["115749.79000000","0.86391000"],["115751.99000000","0.00000000"],["115752.17000000","0.00000000"],["115752.40000000","0.00000000"],["115752.56000000","0.00000000"],["115752.67000000","0.00005000"],["115752.73000000","0.00000000"],["115753.37000000","0.00000000"],["115753.59000000","0.00000000"],["115753.62000000","0.00000000"],["115753.66000000","0.00000000"],["115753.71000000","0.00000000"],["115753.85000000","0.00000000"],["115754.66000000","0.00311000"],["115758.06000000","0.00000000"],["115758.10000000","0.02498000"],["115758.39000000","0.03464000"],["115758.56000000","0.00000000"],["115758.94000000","0.00000000"],["115759.60000000","0.00000000"],["115759.83000000","0.00000000"],["115760.69000000","0.02498000"],["115761.25000000","0.00000000"],["115761.61000000","0.00000000"],["115761.69000000","0.00000000"],["115761.94000000","0.02498000"],["115762.00000000","0.02498000"],["115762.05000000","0.00000000"],["115762.99000000","0.00000000"],["115764.81000000","0.02498000"],["115767.30000000","0.02099000"],["115770.02000000","0.00000000"],["115771.31000000","0.02098000"],["115772.71000000","0.01732000"],["115773.08000000","0.00000000"],["115773.14000000","0.02099000"],["115773.67000000","0.02099000"],["115775.71000000","0.00000000"],["115775.93000000","0.00009000"],["115776.95000000","0.02099000"],["115777.43000000","0.02098000"],["115779.40000000","0.00009000"],["115779.55000000","0.00000000"],["115781.51000000","0.01732000"],["115781.69000000","0.00000000"],["115782.76000000","0.00000000"],["115783.22000000","0.00000000"],["115784.32000000","0.00000000"],["115784.36000000","0.00000000"],["115784.46000000","0.01732000"],["115784.52000000","0.01731000"],["115784.79000000","0.01731000"],["115784.97000000","0.00000000"],["115785.17000000","0.00009000"],["115785.46000000","0.00000000"],["115785.71000000","0.00000000"],["115787.52000000","0.00000000"],["115787.68000000","0.00000000"],["115789.59000000","0.00009000"],["115789.91000000","0.01732000"],["115790.41000000","0.00000000"],["115790.79000000","0.00000000"],["115792.00000000","0.00000000"],["115792.53000000","0.00000000"],["115795.36000000","0.00009000"],["115796.50000000","0.00000000"],["115796.91000000","0.01732000"],["115796.94000000","0.00000000"],["115797.97000000","0.00000000"],["115798.37000000","0.00000000"],["115798.55000000","0.00000000"],["115798.75000000","0.00000000"],["115799.28000000","0.00000000"],["115799.36000000","0.00000000"],["115799.71000000","0.00009000"],["115800.22000000","0.00000000"],["115800.24000000","0.01732000"],["115800.28000000","0.00000000"],["115800.32000000","0.01732000"],["115800.39000000","0.00000000"],["115800.61000000","0.00000000"],["115800.95000000","0.00000000"],["115802.05000000","0.00000000"],["115803.05000000","0.00000000"],["115803.30000000","0.00009000"],["115803.96000000","0.00000000"],["115804.00000000","0.00000000"],["115805.09000000","0.00000000"],["115806.07000000","0.01732000"],["115806.59000000","0.01732000"],["115808.63000000","0.01732000"],["115808.88000000","0.00000000"],["115809.07000000","0.00009000"],["115809.08000000","0.01645000"],["115809.28000000","0.00000000"],["115809.71000000","0.00000000"],["115809.77000000","0.00000000"],["115809.98000000","0.00000000"],["115810.94000000","0.00000000"],["115811.32000000","0.00000000"],["115812.03000000","0.00000000"],["115812.06000000","0.00000000"],["115812.44000000","0.00000000"],["115812.65000000","0.00000000"],["115813.35000000","0.00000000"],["115814.09000000","0.02398000"],["115814.18000000","0.00000000"],["115815.06000000","0.02398000"],["115815.62000000","0.02398000"],["115815.78000000","0.00000000"],["115816.26000000","0.00000000"],["115816.55000000","0.01645000"],["115816.64000000","0.02398000"],["115816.71000000","0.00000000"],["115817.02000000","0.00000000"],["115817.23000000","0.02398000"],["115817.26000000","0.00000000"],["115817.70000000","0.00030000"],["115817.80000000","0.00000000"],["115818.02000000","0.00000000"],["115818.41000000","0.00023000"],["115819.45000000","0.00006000"],["115819.73000000","0.00000000"],["115819.83000000","0.00000000"],["115819.98000000","0.00000000"],["115820.05000000","0.01645000"],["115820.18000000","0.00012000"],["115820.73000000","0.00000000"],["115820.77000000","0.00000000"],["115821.16000000","0.00000000"],["115821.28000000","0.00000000"],["115821.46000000","0.02398000"],["115821.97000000","0.00000000"],["115822.36000000","0.00000000"],["115822.78000000","0.02398000"],["115822.79000000","0.01645000"],["115822.98000000","0.01732000"],["115823.47000000","0.01731000"],["115827.39000000","0.00000000"],["115827.75000000","0.00000000"],["115828.41000000","0.00000000"],["115828.95000000","0.00000000"],["115829.54000000","0.00000000"],["115829.66000000","0.00000000"],["115830.17000000","0.00000000"],["115830.57000000","0.00000000"],["115830.92000000","0.00000000"],["115831.51000000","0.02338000"],["115831.67000000","0.02338000"],["115831.89000000","0.00000000"],["115831.91000000","0.00000000"],["115832.50000000","0.01732000"],["115833.13000000","0.00000000"],["115833.47000000","0.01650000"],["115834.10000000","0.00000000"],["115835.26000000","0.01645000"],["115836.13000000","0.01732000"],["115836.27000000","0.01731000"],["115836.28000000","0.01731000"],["115837.66000000","0.01645000"],["115838.25000000","0.00000000"],["115838.26000000","0.01645000"],["115838.54000000","0.01645000"],["115839.96000000","0.00000000"],["115840.63000000","0.00000000"],["115840.64000000","0.02338000"],["115841.56000000","0.02338000"],["115841.86000000","0.00000000"],["115842.62000000","0.00000000"],["115842.65000000","0.00000000"],["115843.36000000","0.02338000"],["115843.72000000","0.00019000"],["115843.78000000","0.00000000"],["115844.66000000","0.00000000"],["115845.23000000","0.00000000"],["115845.89000000","0.00000000"],["115846.15000000","0.00413000"],["115848.60000000","0.02338000"],["115849.64000000","0.02338000"],["115851.48000000","0.02338000"],["115852.40000000","0.00000000"],["115852.53000000","0.02338000"],["115852.62000000","0.00000000"],["115853.90000000","0.00000000"],["115855.18000000","0.00000000"],["115855.19000000","0.00007000"],["115855.94000000","0.04676000"],["115856.13000000","0.00000000"],["115856.15000000","0.00000000"],["115857.83000000","0.00000000"],["115857.88000000","0.00000000"],["115858.32000000","0.00000000"],["115858.78000000","0.02338000"],["115860.55000000","0.02338000"],["115860.76000000","0.02338000"],["115861.31000000","0.00000000"],["115862.65000000","0.00000000"],["115864.54000000","0.03098000"],["115865.08000000","0.03098000"],["115865.62000000","0.03098000"],["115865.83000000","0.03098000"],["115867.06000000","0.00000000"],["115867.20000000","0.03098000"],["115867.29000000","0.00000000"],["115867.94000000","0.00000000"],["115868.11000000","0.00000000"],["115868.60000000","0.00000000"],["115868.95000000","0.00000000"],["115869.13000000","0.03098000"],["115869.45000000","0.03098000"],["115869.60000000","0.03098000"],["115870.13000000","0.00000000"],["115870.23000000","0.00000000"],["115870.43000000","0.00000000"],["115870.59000000","0.00000000"],["115870.86000000","0.00000000"],["115871.48000000","0.00000000"],["115871.89000000","0.00000000"],["115872.19000000","0.00000000"],["115872.81000000","0.00000000"],["115873.71000000","0.00000000"],["115874.83000000","0.00000000"],["115876.37000000","0.00000000"],["115877.39000000","0.02338000"],["115877.42000000","0.02338000"],["115877.46000000","0.00000000"],["115878.21000000","0.00077000"],["115878.32000000","0.02338000"],["115879.13000000","0.00000000"],["115879.71000000","0.00000000"],["115885.47000000","0.02338000"],["115888.55000000","0.02338000"],["115889.99000000","0.02338000"],["115891.14000000","0.02338000"],["115892.07000000","0.02338000"],["115892.97000000","0.03298000"],["115893.59000000","0.03298000"],["115893.65000000","0.03298000"],["115894.62000000","0.00000000"],["115895.59000000","0.00000000"],["115895.89000000","0.03298000"],["115896.68000000","0.03298000"],["115896.79000000","0.00000000"],["115897.45000000","0.03298000"],["115897.86000000","0.03298000"],["115898.50000000","0.03298000"],["115903.47000000","0.02338000"],["115905.08000000","0.02338000"],["115906.86000000","0.02338000"],["115908.08000000","0.00000000"],["115908.85000000","0.00000000"],["115910.76000000","0.00000000"],["115911.64000000","0.00000000"],["115912.54000000","0.00000000"],["115914.10000000","0.00015000"],["115914.69000000","0.00000000"],["115915.19000000","0.00000000"],["115915.64000000","0.00000000"],["115915.92000000","0.00000000"],["115915.99000000","0.00000000"],["115923.47000000","0.02498000"],["115925.73000000","0.02498000"],["115926.46000000","0.02498000"],["115927.85000000","0.02498000"],["115928.38000000","0.02498000"],["115948.39000000","0.31500000"],["115959.94000000","0.31500000"],["115963.33000000","0.00000000"],["116022.03000000","0.00082000"],["116046.81000000","0.00100000"],["116123.47000000","0.00000000"],["116239.20000000","0.00034000"],["117179.63000000","0.00000000"],["117209.46000000","0.00000000"]]}
