[2025-10-26T09:48:35.320Z] {"e":"depthUpdate","E":1761472114014,"s":"BTCUSDT","U":79058076076,"u":79058078920,"b":[["112580.10000000","0.00000000"],["112580.09000000","0.00000000"],["112580.03000000","0.00000000"],["112580.00000000","0.00000000"],["112579.80000000","0.00000000"],["112578.98000000","0.00000000"],["112578.75000000","0.00000000"],["112578.35000000","0.00000000"],["112578.34000000","0.00000000"],["112578.04000000","0.00000000"],["112577.99000000","0.00000000"],["112577.62000000","0.00000000"],["112577.29000000","0.00000000"],["112575.89000000","0.00000000"],["112575.88000000","0.00000000"],["112575.64000000","0.00000000"],["112575.60000000","0.00000000"],["112575.03000000","0.00000000"],["112575.02000000","0.00000000"],["112574.47000000","0.00000000"],["112573.72000000","0.00000000"],["112573.35000000","0.00000000"],["112571.80000000","0.00000000"],["112571.79000000","0.00000000"],["112571.66000000","0.00000000"],["112571.65000000","0.00000000"],["112570.94000000","0.00000000"],["112570.91000000","0.00000000"],["112570.78000000","0.00000000"],["112570.69000000","0.00000000"],["112570.68000000","0.00000000"],["112570.67000000","0.00000000"],["112570.25000000","0.00000000"],["112570.16000000","0.00000000"],["112570.01000000","0.00000000"],["112570.00000000","0.00000000"],["112569.87000000","0.00000000"],["112569.65000000","0.00000000"],["112569.60000000","0.00000000"],["112569.12000000","0.00000000"],["112569.11000000","0.00000000"],["112568.84000000","0.00000000"],["112568.55000000","0.00000000"],["112568.24000000","0.00000000"],["112568.10000000","0.00000000"],["112568.00000000","0.00000000"],["112567.71000000","0.00000000"],["112567.29000000","0.00000000"],["112566.86000000","0.00000000"],["112566.82000000","0.00000000"],["112566.70000000","0.00000000"],["112566.31000000","0.00000000"],["112566.03000000","0.00000000"],["112566.00000000","0.00000000"],["112565.49000000","0.00000000"],["112565.46000000","0.00000000"],["112565.34000000","0.00000000"],["112565.32000000","0.00000000"],["112565.09000000","0.00000000"],["112564.69000000","0.00000000"],["112564.68000000","0.00000000"],["112564.25000000","0.00000000"],["112564.24000000","0.00000000"],["112564.00000000","0.00000000"],["112563.92000000","0.00000000"],["112563.72000000","0.00000000"],["112562.52000000","0.00000000"],["112562.46000000","0.00000000"],["112562.37000000","0.00000000"],["112562.00000000","0.00000000"],["112561.83000000","0.00000000"],["112560.58000000","0.00000000"],["112560.09000000","0.00000000"],["112560.00000000","0.00000000"],["112559.76000000","0.00000000"],["112559.20000000","0.00000000"],["112559.04000000","0.00000000"],["112558.43000000","0.00000000"],["112558.41000000","0.00000000"],["112558.32000000","0.00000000"],["112558.00000000","0.00000000"],["112557.58000000","0.00000000"],["112556.53000000","0.00000000"],["112556.29000000","0.00747000"],["112556.28000000","0.00045000"],["112556.23000000","0.00015000"],["112556.22000000","0.04447000"],["112556.20000000","0.00069000"],["112556.12000000","0.00000000"],["112556.11000000","0.00000000"],["112556.07000000","0.00005000"],["112556.00000000","0.00125000"],["112555.95000000","0.00000000"],["112555.66000000","0.00000000"],["112555.63000000","0.00000000"],["112555.62000000","0.00000000"],["112555.57000000","0.00010000"],["112555.51000000","0.00000000"],["112555.12000000","0.00005000"],["112554.65000000","0.00000000"],["112554.64000000","0.00000000"],["112554.63000000","0.00000000"],["112554.29000000","0.00000000"],["112554.21000000","0.00000000"],["112554.18000000","0.00000000"],["112554.13000000","0.00005000"],["112554.00000000","0.00120000"],["112553.74000000","0.00000000"],["112553.71000000","0.00000000"],["112553.39000000","0.00000000"],["112553.38000000","0.00000000"],["112552.77000000","0.00000000"],["112552.76000000","0.00005000"],["112552.19000000","0.00000000"],["112552.00000000","0.00125000"],["112551.96000000","0.00000000"],["112551.75000000","0.00005000"],["112551.70000000","0.00360000"],["112551.69000000","0.00000000"],["112551.68000000","0.00000000"],["112551.56000000","0.00000000"],["112551.51000000","0.00000000"],["112551.50000000","0.00005000"],["112551.13000000","0.00000000"],["112551.12000000","0.00000000"],["112550.98000000","0.00000000"],["112550.32000000","0.00151000"],["112550.21000000","0.00000000"],["112550.20000000","0.00000000"],["112550.00000000","0.00125000"],["112549.73000000","0.00000000"],["112549.32000000","0.00000000"],["112548.92000000","0.00000000"],["112548.60000000","0.00000000"],["112548.39000000","0.00005000"],["112548.35000000","0.00000000"],["112548.34000000","0.00000000"],["112548.03000000","0.00000000"],["112548.00000000","0.00120000"],["112547.87000000","0.00000000"],["112547.74000000","0.00000000"],["112547.38000000","0.00000000"],["112547.36000000","0.00000000"],["112547.32000000","0.00000000"],["112547.26000000","0.00000000"],["112547.20000000","0.00000000"],["112547.16000000","0.00000000"],["112547.06000000","0.00000000"],["112547.05000000","0.00005000"],["112547.02000000","0.00000000"],["112546.92000000","0.00000000"],["112546.51000000","0.00000000"],["112546.39000000","0.00000000"],["112546.33000000","0.00000000"],["112546.32000000","0.00305000"],["112546.09000000","0.00000000"],["112546.00000000","0.00130000"],["112545.81000000","0.00000000"],["112545.58000000","0.00000000"],["112545.56000000","0.00000000"],["112545.29000000","0.00000000"],["112545.26000000","0.00000000"],["112545.22000000","0.00000000"],["112545.04000000","0.00000000"],["112545.03000000","0.00000000"],["112544.94000000","0.00000000"],["112544.69000000","0.00151000"],["112544.66000000","0.00000000"],["112544.65000000","0.00000000"],["112544.56000000","0.00355000"],["112544.50000000","0.00000000"],["112544.16000000","0.00000000"],["112544.00000000","0.00120000"],["112543.99000000","0.20466000"],["112543.90000000","0.00000000"],["112543.43000000","0.00000000"],["112543.41000000","0.00000000"],["112543.39000000","0.00000000"],["112543.02000000","0.00000000"],["112542.73000000","0.00000000"],["112542.68000000","0.00005000"],["112542.54000000","0.00005000"],["112542.53000000","0.00088000"],["112542.52000000","0.00000000"],["112542.35000000","0.00000000"],["112542.32000000","0.00000000"],["112542.00000000","0.00125000"],["112541.67000000","0.28468000"],["112541.66000000","0.10865000"],["112541.63000000","0.00000000"],["112541.58000000","0.00000000"],["112541.42000000","0.00000000"],["112540.35000000","0.00000000"],["112540.13000000","0.00000000"],["112540.00000000","0.00130000"],["112539.63000000","0.00000000"],["112539.41000000","0.00150000"],["112539.40000000","0.00000000"],["112539.37000000","0.00005000"],["112539.26000000","0.00000000"],["112538.51000000","0.00000000"],["112538.03000000","0.00250000"],["112538.00000000","0.00120000"],["112537.75000000","0.00000000"],["112537.58000000","0.00000000"],["112537.11000000","0.00000000"],["112536.78000000","0.00000000"],["112536.54000000","0.00000000"],["112536.00000000","0.00120000"],["112535.90000000","0.25630000"],["112535.89000000","0.03157000"],["112535.88000000","0.04449000"],["112535.75000000","0.00000000"],["112535.70000000","0.04710000"],["112534.93000000","0.00000000"],["112534.00000000","0.00120000"],["112533.93000000","0.00000000"],["112533.77000000","0.09185000"],["112533.52000000","0.00250000"],["112532.94000000","0.00000000"],["112532.90000000","0.00000000"],["112532.73000000","0.00000000"],["112532.64000000","0.00000000"],["112532.50000000","0.00000000"],["112532.41000000","0.00000000"],["112532.39000000","0.00000000"],["112532.37000000","0.00000000"],["112532.25000000","0.25991000"],["112532.24000000","0.05400000"],["112532.23000000","0.00000000"],["112532.00000000","0.00120000"],["112531.99000000","0.00000000"],["112531.65000000","0.44002000"],["112531.64000000","0.46938000"],["112531.63000000","0.00000000"],["112531.18000000","0.00000000"],["112531.08000000","0.00000000"],["112530.51000000","0.00000000"],["112530.40000000","0.00000000"],["112530.00000000","0.00120000"],["112529.97000000","0.00000000"],["112529.96000000","0.00000000"],["112529.87000000","0.00000000"],["112529.72000000","0.00000000"],["112529.37000000","0.00000000"],["112529.15000000","0.00000000"],["112529.01000000","0.00250000"],["112528.95000000","0.00000000"],["112528.21000000","0.02632000"],["112528.20000000","0.46938000"],["112528.00000000","0.00140000"],["112527.79000000","0.00000000"],["112527.22000000","0.00000000"],["112527.04000000","0.00000000"],["112527.00000000","0.00000000"],["112526.58000000","0.00006000"],["112526.51000000","0.00000000"],["112526.32000000","0.00005000"],["112526.18000000","0.85646000"],["112526.17000000","1.70701000"],["112526.16000000","0.00000000"],["112526.15000000","0.00000000"],["112526.00000000","0.00140000"],["112524.71000000","0.00000000"],["112524.69000000","0.00000000"],["112524.67000000","0.00000000"],["112524.57000000","0.00000000"],["112524.50000000","0.00250000"],["112524.41000000","0.29980000"],["112524.37000000","0.00000000"],["112524.00000000","0.00140000"],["112523.92000000","0.00000000"],["112523.56000000","0.00000000"],["112523.55000000","0.00000000"],["112523.49000000","0.46938000"],["112523.23000000","0.00000000"],["112523.12000000","0.00000000"],["112523.07000000","0.21540000"],["112523.01000000","0.00000000"],["112522.94000000","0.00000000"],["112522.61000000","0.00000000"],["112522.54000000","0.00000000"],["112522.52000000","0.00308000"],["112522.25000000","0.00000000"],["112522.07000000","0.00000000"],["112522.03000000","0.00000000"],["112522.02000000","0.00000000"],["112522.00000000","0.00140000"],["112521.78000000","0.00000000"],["112521.56000000","0.00000000"],["112521.27000000","0.00000000"],["112520.84000000","0.00005000"],["112520.48000000","0.93337000"],["112520.47000000","1.70701000"],["112520.46000000","0.00000000"],["112520.45000000","0.00000000"],["112520.35000000","0.00000000"],["112520.02000000","0.00088000"],["112520.00000000","0.00145000"],["112519.75000000","0.00065000"],["112519.31000000","0.00829000"],["112518.82000000","0.00000000"],["112518.18000000","0.00000000"],["112518.16000000","0.15146000"],["112518.00000000","0.00140000"],["112517.77000000","0.00000000"],["112517.57000000","0.00000000"],["112517.29000000","0.00000000"],["112517.02000000","0.00000000"],["112516.83000000","0.03954000"],["112516.09000000","0.00000000"],["112516.00000000","0.00140000"],["112515.61000000","0.00000000"],["112515.54000000","0.00000000"],["112515.48000000","0.00250000"],["112515.46000000","0.00000000"],["112515.41000000","0.00006000"],["112515.36000000","0.00005000"],["112514.95000000","0.97364000"],["112514.77000000","0.30000000"],["112514.69000000","0.00177000"],["112514.60000000","0.15146000"],["112514.00000000","0.00140000"],["112513.64000000","0.00000000"],["112513.63000000","0.04000000"],["112512.98000000","0.00000000"],["112512.97000000","0.00000000"],["112512.84000000","0.00000000"],["112512.82000000","0.01022000"],["112512.75000000","0.00000000"],["112512.55000000","0.00000000"],["112512.00000000","0.00140000"],["112511.53000000","0.00000000"],["112510.77000000","0.01800000"],["112510.41000000","0.03780000"],["112510.40000000","0.00000000"],["112510.12000000","0.00444000"],["112510.05000000","0.00012000"],["112510.00000000","0.00140000"],["112509.88000000","0.00005000"],["112509.53000000","0.00271000"],["112508.40000000","0.22719000"],["112508.00000000","0.00160000"],["112507.60000000","0.00000000"],["112506.01000000","0.00000000"],["112506.00000000","0.00160000"],["112505.94000000","0.00000000"],["112505.65000000","0.00088000"],["112504.40000000","0.00005000"],["112504.00000000","0.00160000"],["112503.22000000","0.00000000"],["112502.81000000","0.95586000"],["112502.01000000","0.00000000"],["112502.00000000","0.00160000"],["112501.74000000","0.00000000"],["112500.93000000","0.35608000"],["112500.22000000","0.00039000"],["112500.00000000","0.02213000"],["112499.94000000","0.00033000"],["112498.19000000","0.15146000"],["112498.00000000","0.00160000"],["112497.84000000","0.19939000"],["112497.45000000","0.00000000"],["112497.36000000","0.15107000"],["112496.39000000","0.00000000"],["112496.00000000","0.00160000"],["112495.58000000","0.08000000"],["112495.57000000","0.00000000"],["112495.56000000","1.70734000"],["112495.32000000","0.00036000"],["112494.65000000","0.00000000"],["112494.20000000","0.26677000"],["112494.00000000","0.00160000"],["112492.35000000","0.00183000"],["112492.00000000","0.00160000"],["112491.56000000","0.00000000"],["112490.19000000","0.00036000"],["112490.04000000","0.46938000"],["112490.00000000","0.00160000"],["112489.94000000","0.00037000"],["112489.90000000","0.00626000"],["112488.93000000","0.00000000"],["112488.84000000","0.34113000"],["112488.77000000","0.00000000"],["112488.76000000","0.00008000"],["112488.40000000","0.31500000"],["112488.31000000","0.00000000"],["112487.10000000","0.97810000"],["112486.72000000","0.00183000"],["112486.25000000","0.00000000"],["112486.03000000","0.00624000"],["112485.57000000","0.00000000"],["112484.85000000","0.00000000"],["112484.19000000","0.46938000"],["112484.18000000","0.00000000"],["112480.90000000","0.00000000"],["112480.79000000","0.00666000"],["112480.05000000","0.00000000"],["112480.00000000","0.00165000"],["112479.70000000","0.00010000"],["112479.21000000","0.00000000"],["112478.78000000","0.00000000"],["112478.71000000","0.02233000"],["112478.39000000","0.24814000"],["112478.10000000","0.46938000"],["112476.88000000","0.00638000"],["112473.32000000","0.00000000"],["112472.29000000","0.26660000"],["112471.84000000","0.46938000"],["112471.14000000","0.26683000"],["112470.34000000","0.26728000"],["112469.26000000","0.00000000"],["112468.89000000","0.00000000"],["112468.38000000","0.22343000"],["112468.09000000","0.00000000"],["112467.27000000","0.00000000"],["112466.20000000","0.00005000"],["112464.53000000","0.00000000"],["112463.92000000","0.02984000"],["112462.15000000","0.02399000"],["112462.01000000","0.00000000"],["112461.75000000","0.02082000"],["112461.61000000","0.00000000"],["112461.60000000","0.00000000"],["112461.59000000","0.00000000"],["112461.08000000","0.00000000"],["112461.06000000","0.00000000"],["112460.01000000","0.00000000"],["112459.94000000","0.00000000"],["112458.01000000","0.00000000"],["112455.85000000","0.36075000"],["112454.99000000","0.00008000"],["112452.76000000","0.36076000"],["112452.12000000","0.00005000"],["112452.08000000","0.44452000"],["112450.54000000","0.19096000"],["112450.03000000","0.00222000"],["112450.02000000","0.00000000"],["112449.16000000","0.26677000"],["112448.18000000","0.00005000"],["112448.09000000","0.44510000"],["112447.18000000","0.00000000"],["112446.06000000","0.00000000"],["112445.00000000","0.00000000"],["112444.64000000","0.35608000"],["112444.01000000","0.00000000"],["112442.97000000","0.05700000"],["112442.31000000","0.02439000"],["112442.27000000","0.04046000"],["112441.15000000","0.30803000"],["112440.97000000","0.02173000"],["112440.00000000","0.01943000"],["112437.62000000","0.00221000"],["112437.61000000","0.05394000"],["112437.38000000","0.00000000"],["112436.83000000","0.00000000"],["112436.18000000","0.03000000"],["112435.62000000","0.00000000"],["112435.36000000","0.00399000"],["112435.35000000","0.19301000"],["112428.94000000","0.07740000"],["112428.64000000","0.07352000"],["112426.81000000","0.03598000"],["112425.83000000","0.00000000"],["112425.61000000","0.00000000"],["112424.63000000","0.05526000"],["112423.85000000","0.03598000"],["112421.22000000","0.00008000"],["112420.95000000","0.03598000"],["112420.90000000","0.03598000"],["112418.01000000","1.24137000"],["112415.39000000","0.00000000"],["112411.23000000","0.00000000"],["112407.75000000","0.00000000"],["112406.34000000","0.00000000"],["112406.18000000","0.00000000"],["112403.60000000","1.11782000"],["112402.72000000","0.00000000"],["112402.34000000","0.00000000"],["112402.33000000","0.00000000"],["112392.47000000","0.09666000"],["112389.90000000","0.00000000"],["112388.64000000","0.00000000"],["112388.63000000","0.00000000"],["112387.46000000","0.00008000"],["112387.39000000","0.00000000"],["112383.86000000","0.00000000"],["112381.43000000","0.00000000"],["112374.40000000","0.14312000"],["112367.91000000","0.08736000"],["112357.55000000","0.01598000"],["112346.28000000","0.06748000"],["112341.43000000","0.00000000"],["112337.29000000","0.00088000"],["112337.28000000","0.00000000"],["112337.27000000","0.00000000"],["112336.85000000","0.26997000"],["112330.66000000","0.00000000"],["112329.42000000","0.06748000"],["112328.59000000","0.00000000"],["112326.84000000","0.00000000"],["112325.42000000","0.00000000"],["112325.35000000","0.00088000"],["112323.15000000","0.00000000"],["112320.01000000","0.01776000"],["112318.94000000","0.01776000"],["112318.19000000","0.00000000"],["112312.57000000","0.06748000"],["112310.74000000","0.99715000"],["112302.57000000","0.89032000"],["112288.10000000","0.00000000"],["112281.12000000","0.89049000"],["112280.10000000","0.00000000"],["112276.60000000","0.00000000"],["112273.92000000","0.00000000"],["112273.20000000","0.00000000"],["112273.07000000","0.00000000"],["112272.25000000","0.00000000"],["112255.23000000","0.00000000"],["112251.44000000","0.00000000"],["112249.99000000","0.02498000"],["112249.93000000","0.00000000"],["112249.57000000","0.02498000"],["112243.73000000","0.00000000"],["112243.46000000","0.00000000"],["112242.53000000","0.00000000"],["112241.88000000","0.00000000"],["112241.25000000","0.00000000"],["112241.17000000","0.00000000"],["112240.95000000","0.00000000"],["112240.63000000","0.00000000"],["112238.31000000","0.02398000"],["112234.63000000","0.00000000"],["112228.56000000","0.00000000"],["112228.20000000","0.00000000"],["112227.52000000","0.00010000"],["112225.10000000","1.24353000"],["112221.94000000","0.02398000"],["112221.90000000","0.00010000"],["112218.57000000","0.03498000"],["112217.62000000","0.03498000"],["112216.92000000","0.00000000"],["112216.60000000","0.03498000"],["112216.38000000","0.03498000"],["112216.28000000","0.00010000"],["112215.79000000","0.02398000"],["112215.69000000","0.03498000"],["112215.57000000","1.12029000"],["112215.38000000","0.03498000"],["112213.24000000","0.00000000"],["112210.66000000","0.00010000"],["112205.04000000","0.00000000"],["112204.19000000","0.00000000"],["112203.68000000","0.00000000"],["112201.61000000","0.00000000"],["112199.42000000","0.00000000"],["112174.38000000","0.01687000"],["112174.35000000","0.01687000"],["112174.25000000","0.01687000"],["112174.07000000","0.02398000"],["112172.50000000","0.02398000"],["112148.29000000","0.02398000"],["112145.98000000","0.00000000"],["112141.35000000","0.00000000"],["112118.78000000","0.02398000"],["112118.69000000","0.02398000"],["112116.64000000","0.02398000"],["112116.50000000","0.02405000"],["112112.13000000","0.00000000"],["112111.50000000","0.00000000"],["112065.83000000","0.03198000"],["112060.89000000","0.03198000"],["111988.86000000","0.27082000"],["111892.05000000","0.00000000"],["110891.39000000","0.00000000"],["110885.11000000","0.00000000"],["110867.94000000","0.00100000"],["108000.00000000","53.87645000"],["101322.00000000","0.00010000"],["90064.09000000","0.00000000"],["90064.08000000","0.00000000"],["90046.07000000","0.00000000"],["90045.04000000","0.00022000"],["78805.54000000","0.00000000"],["78801.60000000","0.00000000"],["78797.66000000","0.00000000"],["60000.00000000","57.64882000"],["56285.65000000","0.00200000"],["56278.15000000","0.00040000"],["56200.00000000","1.11645000"],["56199.00000000","0.00000000"],["56198.78000000","0.00000000"],["56197.78000000","0.00000000"]],"a":[["112556.30000000","8.35078000"],["112556.38000000","0.06040000"],["112556.78000000","0.00293000"],["112556.84000000","0.00000000"],["112557.88000000","0.02335000"],["112558.00000000","0.10020000"],["112558.01000000","0.00000000"],["112558.04000000","0.05710000"],["112558.10000000","0.00000000"],["112558.32000000","0.31015000"],["112558.33000000","0.09471000"],["112559.20000000","0.00005000"],["112559.96000000","0.04961000"],["112559.97000000","0.04095000"],["112560.00000000","0.00005000"],["112560.23000000","1.70701000"],["112560.24000000","0.46943000"],["112560.35000000","0.00000000"],["112560.58000000","0.00255000"],["112560.59000000","0.00000000"],["112561.24000000","0.00000000"],["112561.28000000","0.00000000"],["112561.84000000","0.00000000"],["112562.44000000","0.00000000"],["112562.46000000","0.00000000"],["112562.47000000","0.00005000"],["112563.58000000","0.00444000"],["112563.59000000","0.04000000"],["112563.64000000","0.46938000"],["112563.70000000","0.00000000"],["112563.72000000","0.34290000"],["112563.73000000","0.00005000"],["112564.01000000","0.00000000"],["112564.26000000","0.00000000"],["112564.32000000","0.00000000"],["112564.68000000","0.00005000"],["112564.69000000","0.00000000"],["112564.70000000","0.00000000"],["112565.09000000","0.00260000"],["112565.10000000","0.00000000"],["112565.33000000","0.00000000"],["112565.99000000","1.70701000"],["112566.62000000","0.00005000"],["112566.71000000","0.00000000"],["112566.86000000","0.26991000"],["112566.87000000","0.00000000"],["112567.28000000","0.16000000"],["112567.29000000","0.46938000"],["112567.30000000","0.00000000"],["112567.56000000","0.00331000"],["112567.72000000","0.00200000"],["112568.01000000","0.00000000"],["112568.11000000","0.00000000"],["112568.25000000","0.00000000"],["112568.56000000","0.00000000"],["112568.77000000","0.00000000"],["112568.85000000","0.26677000"],["112568.90000000","0.00000000"],["112568.93000000","0.00000000"],["112569.12000000","0.00000000"],["112569.23000000","0.00161000"],["112569.38000000","0.15146000"],["112569.60000000","0.00255000"],["112569.61000000","0.00000000"],["112569.66000000","0.04000000"],["112569.71000000","0.00000000"],["112569.88000000","0.00000000"],["112570.01000000","0.00000000"],["112570.02000000","0.00000000"],["112570.16000000","0.00005000"],["112570.17000000","0.00000000"],["112570.35000000","0.00010000"],["112570.49000000","0.00005000"],["112570.67000000","0.46938000"],["112570.68000000","2.04045000"],["112570.69000000","0.04005000"],["112570.70000000","0.00000000"],["112570.79000000","0.00000000"],["112570.92000000","0.00005000"],["112570.95000000","0.00000000"],["112571.65000000","0.00000000"],["112571.66000000","1.74701000"],["112571.67000000","0.00000000"],["112571.88000000","0.00005000"],["112572.88000000","0.08010000"],["112572.89000000","0.00000000"],["112572.93000000","0.04839000"],["112573.18000000","0.00239000"],["112573.36000000","0.00000000"],["112573.59000000","0.04095000"],["112573.73000000","0.30991000"],["112573.99000000","0.00000000"],["112574.00000000","0.06100000"],["112574.11000000","0.00250000"],["112574.48000000","0.00000000"],["112574.52000000","0.00005000"],["112574.60000000","0.00000000"],["112574.65000000","0.03867000"],["112574.72000000","0.00007000"],["112574.84000000","0.00000000"],["112574.96000000","0.00000000"],["112575.26000000","0.15094000"],["112575.36000000","0.00000000"],["112575.39000000","0.08000000"],["112575.61000000","0.00000000"],["112575.64000000","0.00005000"],["112575.89000000","0.04000000"],["112575.90000000","0.00000000"],["112576.04000000","0.00000000"],["112576.50000000","0.03005000"],["112576.81000000","0.00000000"],["112576.85000000","0.00000000"],["112577.07000000","0.15146000"],["112577.25000000","0.00000000"],["112577.30000000","0.00000000"],["112577.63000000","0.00000000"],["112577.78000000","0.00010000"],["112577.80000000","0.00000000"],["112577.81000000","0.00000000"],["112577.99000000","0.00000000"],["112578.00000000","0.00000000"],["112578.05000000","0.00000000"],["112578.30000000","0.03770000"],["112578.34000000","0.00000000"],["112578.35000000","2.21639000"],["112578.48000000","0.31973000"],["112578.62000000","0.00250000"],["112578.76000000","0.00000000"],["112578.82000000","0.00300000"],["112578.85000000","0.00000000"],["112578.89000000","0.00000000"],["112578.99000000","0.04000000"],["112579.58000000","0.00000000"],["112579.65000000","0.00000000"],["112579.78000000","0.00000000"],["112579.80000000","0.00000000"],["112579.81000000","0.00000000"],["112580.00000000","0.00005000"],["112580.01000000","0.00000000"],["112580.08000000","0.00000000"],["112580.10000000","0.00000000"],["112580.11000000","0.09998000"],["112580.19000000","0.00000000"],["112580.63000000","0.35608000"],["112581.63000000","0.00005000"],["112581.73000000","0.18782000"],["112581.94000000","0.78438000"],["112581.95000000","0.00000000"],["112581.96000000","0.00000000"],["112582.15000000","0.00000000"],["112582.43000000","0.00006000"],["112582.92000000","0.00195000"],["112583.09000000","0.00000000"],["112583.13000000","0.00000000"],["112583.16000000","0.03000000"],["112583.28000000","0.00000000"],["112583.29000000","0.00000000"],["112583.36000000","0.22719000"],["112583.40000000","0.00010000"],["112583.70000000","0.00450000"],["112584.08000000","0.00271000"],["112584.38000000","0.31971000"],["112584.45000000","0.00012000"],["112584.51000000","0.00000000"],["112584.89000000","0.01256000"],["112584.91000000","0.00000000"],["112584.92000000","0.02898000"],["112585.36000000","0.00000000"],["112585.37000000","0.00000000"],["112585.49000000","0.00000000"],["112585.73000000","0.00000000"],["112585.74000000","1.70701000"],["112585.82000000","0.46938000"],["112585.86000000","0.00007000"],["112586.16000000","0.00000000"],["112586.37000000","0.00000000"],["112586.70000000","0.00000000"],["112586.85000000","0.00000000"],["112586.86000000","0.00533000"],["112586.96000000","0.03553000"],["112587.47000000","0.34113000"],["112587.56000000","0.00088000"],["112587.64000000","0.00000000"],["112587.88000000","0.08000000"],["112587.92000000","0.00000000"],["112587.98000000","0.03598000"],["112588.03000000","0.00000000"],["112588.35000000","0.00010000"],["112588.50000000","0.00000000"],["112590.07000000","0.31978000"],["112590.32000000","0.15133000"],["112590.61000000","0.00000000"],["112590.83000000","0.04000000"],["112591.00000000","0.06100000"],["112591.29000000","0.00000000"],["112591.37000000","0.00300000"],["112591.74000000","0.23721000"],["112591.80000000","0.00000000"],["112591.97000000","0.00000000"],["112592.15000000","0.00000000"],["112592.45000000","0.00800000"],["112592.86000000","0.00000000"],["112593.05000000","0.00000000"],["112593.43000000","0.03000000"],["112593.50000000","0.00000000"],["112594.19000000","0.00000000"],["112595.05000000","0.51866000"],["112596.25000000","0.49323000"],["112596.34000000","0.31968000"],["112596.35000000","0.00000000"],["112596.42000000","0.00000000"],["112596.66000000","0.00000000"],["112597.35000000","1.70701000"],["112597.92000000","0.00177000"],["112597.98000000","0.64111000"],["112598.60000000","0.00000000"],["112598.98000000","0.00000000"],["112599.57000000","0.03000000"],["112600.19000000","0.00000000"],["112600.85000000","0.03460000"],["112601.17000000","0.00000000"],["112601.48000000","0.00000000"],["112601.72000000","0.03000000"],["112601.89000000","0.04091000"],["112603.14000000","0.00000000"],["112603.31000000","0.00000000"],["112603.43000000","0.04450000"],["112603.55000000","0.00005000"],["112603.95000000","0.00000000"],["112604.27000000","0.03553000"],["112605.12000000","0.00000000"],["112605.68000000","0.00000000"],["112606.19000000","0.00000000"],["112606.90000000","0.03082000"],["112607.51000000","0.00000000"],["112607.71000000","0.00000000"],["112607.73000000","0.00000000"],["112608.05000000","0.36026000"],["112609.43000000","0.00000000"],["112610.86000000","0.00000000"],["112611.14000000","0.36025000"],["112611.41000000","0.00000000"],["112611.95000000","0.06808000"],["112612.67000000","0.00000000"],["112613.10000000","0.00000000"],["112613.13000000","0.00000000"],["112613.16000000","0.26728000"],["112613.31000000","0.00000000"],["112613.39000000","0.00000000"],["112613.52000000","0.00000000"],["112613.73000000","0.05400000"],["112613.88000000","0.00000000"],["112613.97000000","0.00000000"],["112614.00000000","0.00160000"],["112614.11000000","0.00000000"],["112614.45000000","0.19918000"],["112614.51000000","0.00000000"],["112614.89000000","0.00000000"],["112615.05000000","0.00000000"],["112615.35000000","0.07247000"],["112615.58000000","0.02173000"],["112615.60000000","0.00000000"],["112615.84000000","0.00000000"],["112615.89000000","0.00000000"],["112616.98000000","0.00619000"],["112617.47000000","0.26660000"],["112618.77000000","0.00000000"],["112619.00000000","0.00000000"],["112619.48000000","0.00000000"],["112619.57000000","0.00000000"],["112620.73000000","0.00000000"],["112620.84000000","0.00000000"],["112621.33000000","0.00000000"],["112621.74000000","0.00000000"],["112622.70000000","0.00000000"],["112623.08000000","0.00000000"],["112623.60000000","0.00000000"],["112623.83000000","0.00008000"],["112623.98000000","0.02233000"],["112624.33000000","0.00624000"],["112624.86000000","0.00000000"],["112624.91000000","0.00000000"],["112624.96000000","0.00000000"],["112626.78000000","0.00659000"],["112627.43000000","0.00624000"],["112627.88000000","0.00000000"],["112630.09000000","0.05385000"],["112630.33000000","0.00000000"],["112630.42000000","0.00007000"],["112630.44000000","0.00000000"],["112633.11000000","0.00000000"],["112635.13000000","0.00000000"],["112635.65000000","0.00000000"],["112635.84000000","0.00000000"],["112635.92000000","0.00000000"],["112636.46000000","0.02487000"],["112636.47000000","0.00000000"],["112636.57000000","0.00000000"],["112636.75000000","0.00000000"],["112636.97000000","0.00000000"],["112637.33000000","0.04435000"],["112637.53000000","0.00221000"],["112637.99000000","0.00000000"],["112638.97000000","0.00000000"],["112641.36000000","0.00005000"],["112641.76000000","0.00000000"],["112643.39000000","0.88763000"],["112643.65000000","0.00000000"],["112643.80000000","0.04057000"],["112643.84000000","0.00109000"],["112645.16000000","0.02416000"],["112645.65000000","0.00000000"],["112646.89000000","0.00000000"],["112647.36000000","0.00000000"],["112647.66000000","0.00000000"],["112648.72000000","0.00000000"],["112648.83000000","0.00000000"],["112650.17000000","0.00000000"],["112650.42000000","0.00000000"],["112652.90000000","0.00000000"],["112653.51000000","0.00000000"],["112653.74000000","0.00000000"],["112654.16000000","0.00000000"],["112655.05000000","0.00000000"],["112657.60000000","0.00008000"],["112659.09000000","0.00000000"],["112659.35000000","0.00000000"],["112659.81000000","0.00000000"],["112660.50000000","0.00005000"],["112661.25000000","0.00000000"],["112664.80000000","0.00000000"],["112665.51000000","0.00000000"],["112666.04000000","0.00000000"],["112666.13000000","0.88745000"],["112666.15000000","0.00000000"],["112666.63000000","0.00000000"],["112666.71000000","0.00000000"],["112666.87000000","0.00000000"],["112668.39000000","0.00000000"],["112669.71000000","0.09675000"],["112671.56000000","0.00000000"],["112672.34000000","0.00000000"],["112675.49000000","0.07740000"],["112676.26000000","0.00000000"],["112677.30000000","0.00000000"],["112678.96000000","0.00000000"],["112681.43000000","0.00000000"],["112686.42000000","0.01776000"],["112690.00000000","0.00274000"],["112691.37000000","0.00008000"],["112693.97000000","0.15917000"],["112702.04000000","0.00000000"],["112714.29000000","0.00000000"],["112714.39000000","0.00000000"],["112714.63000000","0.00000000"],["112715.21000000","0.00000000"],["112719.81000000","0.02398000"],["112722.63000000","0.00000000"],["112725.13000000","0.00008000"],["112727.48000000","0.47523000"],["112737.20000000","0.02676000"],["112738.60000000","0.00000000"],["112748.98000000","0.00000000"],["112750.41000000","0.03846000"],["112757.64000000","0.00000000"],["112780.94000000","0.01687000"],["112785.67000000","0.01391000"],["112826.95000000","0.00000000"],["112836.08000000","0.18241000"],["112844.82000000","0.02398000"],["112848.23000000","0.00000000"],["112859.66000000","0.00000000"],["112866.08000000","0.00000000"],["112874.17000000","0.00000000"],["112895.19000000","0.00006000"],["112905.22000000","1.19998000"],["112921.25000000","0.00684000"],["112945.77000000","0.00000000"],["112946.42000000","0.00008000"],["112952.26000000","0.00007000"],["112953.12000000","0.00000000"],["112958.74000000","0.00000000"],["112963.52000000","0.00000000"],["112964.36000000","0.00000000"],["112967.28000000","0.00000000"],["113025.84000000","0.02598000"],["113134.92000000","0.00000000"],["113554.00000000","0.00000000"],["113592.65000000","0.00000000"],["114244.65000000","0.00100000"],["114268.82000000","0.00000000"],["118001.37000000","0.00000000"],["118018.82000000","0.00000000"],["118097.71000000","0.00000000"],["118102.79000000","0.00000000"],["118189.66000000","0.00030000"],["118199.87000000","0.00010000"]]}
[2025-10-26T09:48:36.136Z] {"e":"depthUpdate","E":1761472115014,"s":"BTCUSDT","U":79058078921,"u":79058079533,"b":[["112556.29000000","1.26936000"],["112556.28000000","0.00040000"],["112556.23000000","0.00010000"],["112556.22000000","0.04447000"],["112555.64000000","0.00000000"],["112555.57000000","0.00000000"],["112554.00000000","0.00125000"],["112546.00000000","0.00135000"],["112545.05000000","0.00010000"],["112545.04000000","0.08952000"],["112545.03000000","0.31510000"],["112544.69000000","0.00151000"],["112544.56000000","0.00000000"],["112544.50000000","0.00007000"],["112544.00000000","0.00135000"],["112543.99000000","0.00000000"],["112542.54000000","0.00255000"],["112542.53000000","0.00098000"],["112542.52000000","0.08895000"],["112542.24000000","0.00005000"],["112542.23000000","0.20510000"],["112542.22000000","0.22260000"],["112542.18000000","0.00355000"],["112542.01000000","0.00000000"],["112542.00000000","0.06220000"],["112541.71000000","0.00000000"],["112541.70000000","0.00000000"],["112541.69000000","0.00000000"],["112541.68000000","0.00000000"],["112541.67000000","0.00000000"],["112541.66000000","0.10860000"],["112541.63000000","0.00000000"],["112541.62000000","0.20466000"],["112540.32000000","0.04710000"],["112540.00000000","0.00125000"],["112538.38000000","0.00000000"],["112537.84000000","0.15892000"],["112537.83000000","0.00000000"],["112537.82000000","0.00000000"],["112535.92000000","0.00000000"],["112535.91000000","0.46938000"],["112535.90000000","0.00000000"],["112535.89000000","0.00000000"],["112535.88000000","0.00000000"],["112535.70000000","0.00000000"],["112535.07000000","0.00000000"],["112534.15000000","0.00000000"],["112533.77000000","0.00300000"],["112532.37000000","0.01777000"],["112532.27000000","1.15403000"],["112532.26000000","1.70701000"],["112532.25000000","0.00000000"],["112531.65000000","0.00000000"],["112530.94000000","0.00005000"],["112530.04000000","0.00000000"],["112528.15000000","0.00000000"],["112528.03000000","0.00000000"],["112528.01000000","0.00000000"],["112527.79000000","0.00000000"],["112527.73000000","0.00000000"],["112527.65000000","0.00000000"],["112526.80000000","0.00000000"],["112526.56000000","0.00000000"],["112525.94000000","0.00000000"],["112525.38000000","0.04351000"],["112525.06000000","0.00000000"],["112525.02000000","0.26660000"],["112524.97000000","0.04179000"],["112524.79000000","0.26728000"],["112524.74000000","0.00000000"],["112523.02000000","0.04500000"],["112522.77000000","0.00000000"],["112522.11000000","0.00000000"],["112522.04000000","0.03900000"],["112522.03000000","0.04200000"],["112521.99000000","0.00000000"],["112521.95000000","0.04500000"],["112520.98000000","0.00000000"],["112520.46000000","0.01768000"],["112520.22000000","0.00000000"],["112519.99000000","0.00000000"],["112519.60000000","0.00000000"],["112519.31000000","0.00000000"],["112518.75000000","0.00000000"],["112518.68000000","0.02666000"],["112518.59000000","0.03600000"],["112517.40000000","0.03000000"],["112516.83000000","0.00000000"],["112516.31000000","0.03000000"],["112516.09000000","0.03000000"],["112515.48000000","0.00000000"],["112513.95000000","0.00009000"],["112513.85000000","0.00009000"],["112513.46000000","0.00000000"],["112513.42000000","0.00000000"],["112512.89000000","0.15120000"],["112512.27000000","0.44510000"],["112509.11000000","0.00009000"],["112509.07000000","0.15105000"],["112507.60000000","0.15133000"],["112507.14000000","0.00009000"],["112499.44000000","0.00009000"],["112489.72000000","0.00000000"],["112487.10000000","0.00000000"],["112486.81000000","0.07207000"],["112483.21000000","0.03778000"],["112481.91000000","0.00000000"],["112481.52000000","0.00000000"],["112479.87000000","0.26660000"],["112478.81000000","0.26728000"],["112476.94000000","0.06743000"],["112472.29000000","0.00000000"],["112470.34000000","0.00000000"],["112463.25000000","0.03000000"],["112462.44000000","0.03600000"],["112462.39000000","0.00089000"],["112459.99000000","0.40466000"],["112459.88000000","0.44452000"],["112455.82000000","0.44510000"],["112452.08000000","0.00000000"],["112450.00000000","0.11160000"],["112448.09000000","0.00000000"],["112442.78000000","0.00000000"],["112441.86000000","0.00000000"],["112441.68000000","0.00000000"],["112441.64000000","0.00000000"],["112440.31000000","0.00005000"],["112438.34000000","0.00000000"],["112437.82000000","0.03900000"],["112437.20000000","0.00000000"],["112436.10000000","0.00000000"],["112435.95000000","0.00000000"],["112430.62000000","0.09666000"],["112428.64000000","0.00000000"],["112409.97000000","0.00020000"],["112392.47000000","0.00000000"],["112390.22000000","0.00000000"],["112378.67000000","0.00304000"],["112373.41000000","0.00000000"],["112372.83000000","0.00000000"],["112256.29000000","0.00000000"],["112225.43000000","0.01688000"],["112207.23000000","0.03397000"],["110867.94000000","0.00100000"],["101322.00000000","0.00000000"],["101300.00000000","1.33203000"],["90045.04000000","0.00022000"]],"a":[["112556.30000000","6.16461000"],["112556.31000000","0.04260000"],["112556.34000000","0.00010000"],["112556.35000000","0.05030000"],["112556.37000000","0.00010000"],["112556.38000000","0.06035000"],["112556.78000000","0.00303000"],["112557.87000000","0.00805000"],["112557.88000000","0.00515000"],["112557.99000000","0.00010000"],["112558.00000000","0.10010000"],["112558.03000000","0.00010000"],["112558.04000000","0.05700000"],["112558.31000000","0.00000000"],["112558.32000000","0.31015000"],["112558.33000000","0.09471000"],["112558.49000000","0.00005000"],["112558.62000000","0.00000000"],["112559.50000000","0.00000000"],["112559.83000000","0.00000000"],["112559.96000000","0.00005000"],["112559.97000000","0.00000000"],["112560.05000000","0.01796000"],["112560.23000000","1.70701000"],["112560.24000000","0.46938000"],["112560.58000000","0.00260000"],["112560.74000000","0.00005000"],["112561.93000000","0.19499000"],["112562.11000000","0.00000000"],["112562.47000000","0.00000000"],["112562.50000000","0.06100000"],["112563.27000000","0.00000000"],["112563.58000000","0.00444000"],["112563.59000000","0.00000000"],["112563.72000000","0.00005000"],["112564.44000000","0.01782000"],["112564.54000000","0.04946000"],["112565.34000000","0.00005000"],["112567.56000000","0.00336000"],["112567.72000000","0.00200000"],["112568.82000000","0.00000000"],["112568.84000000","0.29978000"],["112570.49000000","0.00000000"],["112570.68000000","1.77385000"],["112570.69000000","0.04000000"],["112571.26000000","0.00006000"],["112571.79000000","0.04000000"],["112571.88000000","0.00000000"],["112572.88000000","0.00000000"],["112573.59000000","0.00000000"],["112574.52000000","0.00000000"],["112574.95000000","0.15133000"],["112575.99000000","0.03778000"],["112576.03000000","0.31974000"],["112576.08000000","0.03000000"],["112576.99000000","0.06000000"],["112577.16000000","1.10000000"],["112577.27000000","0.03000000"],["112577.30000000","0.03000000"],["112578.20000000","0.03000000"],["112578.48000000","0.00000000"],["112579.48000000","0.03300000"],["112579.67000000","0.00000000"],["112580.00000000","0.00000000"],["112580.10000000","0.00897000"],["112580.11000000","0.04272000"],["112580.27000000","0.03000000"],["112580.91000000","0.03000000"],["112581.39000000","0.03600000"],["112582.20000000","0.26660000"],["112582.53000000","0.05400000"],["112582.72000000","0.05400000"],["112587.88000000","0.00000000"],["112591.00000000","0.00000000"],["112593.43000000","0.00000000"],["112597.97000000","0.00000000"],["112599.02000000","0.00000000"],["112601.18000000","0.00000000"],["112601.89000000","0.12091000"],["112601.98000000","0.00306000"],["112603.43000000","0.00000000"],["112604.11000000","0.00000000"],["112606.95000000","0.00088000"],["112613.55000000","0.00000000"],["112616.89000000","0.08000000"],["112617.47000000","0.00000000"],["112623.03000000","0.04390000"],["112623.89000000","0.26683000"],["112627.23000000","0.26660000"],["112635.69000000","0.00000000"],["112635.88000000","0.26677000"],["112636.82000000","0.35608000"],["112636.89000000","0.44510000"],["112637.33000000","0.00000000"],["112642.72000000","0.44452000"],["112655.27000000","0.00000000"],["112662.11000000","0.00000000"],["112667.27000000","0.00000000"],["112670.67000000","0.00000000"],["112677.31000000","0.00000000"],["112677.74000000","0.00000000"],["112677.75000000","0.00000000"],["112678.61000000","0.00000000"],["112683.88000000","0.09666000"],["112685.59000000","0.00000000"],["112685.73000000","0.00000000"],["112691.52000000","0.06000000"],["112704.33000000","0.00000000"],["112745.67000000","0.01599000"],["112749.15000000","0.01599000"],["112767.90000000","0.00080000"],["112779.47000000","0.00000000"],["112945.65000000","0.03397000"],["114244.65000000","0.00100000"]]}
[2025-10-26T09:48:37.264Z] {"e":"depthUpdate","E":1761472116014,"s":"BTCUSDT","U":79058079534,"u":79058081143,"b":[["112556.29000000","0.00000000"],["112556.28000000","0.00000000"],["112556.23000000","0.00000000"],["112556.22000000","0.00000000"],["112556.20000000","0.00000000"],["112556.07000000","0.00000000"],["112556.00000000","0.00000000"],["112555.99000000","0.00000000"],["112555.47000000","0.00000000"],["112555.12000000","0.00000000"],["112555.08000000","0.00000000"],["112555.07000000","0.00000000"],["112554.49000000","0.00000000"],["112554.13000000","0.00000000"],["112554.00000000","0.00000000"],["112553.72000000","0.00000000"],["112553.30000000","0.00000000"],["112552.76000000","0.00000000"],["112552.00000000","0.00000000"],["112551.75000000","0.00000000"],["112551.70000000","0.00000000"],["112551.50000000","0.00000000"],["112551.11000000","0.00000000"],["112550.55000000","0.00000000"],["112550.32000000","0.00000000"],["112550.00000000","0.00000000"],["112548.67000000","0.00000000"],["112548.39000000","0.00000000"],["112548.24000000","0.00000000"],["112548.00000000","0.00000000"],["112547.05000000","0.00000000"],["112546.62000000","0.00000000"],["112546.60000000","0.00000000"],["112546.32000000","0.00000000"],["112546.00000000","0.00000000"],["112545.88000000","0.00000000"],["112545.33000000","0.00000000"],["112545.32000000","0.00000000"],["112545.05000000","0.00000000"],["112545.04000000","0.00000000"],["112545.03000000","0.00000000"],["112544.69000000","0.00000000"],["112544.50000000","0.00000000"],["112544.37000000","0.00000000"],["112544.00000000","0.00000000"],["112543.25000000","0.00000000"],["112542.76000000","0.00000000"],["112542.68000000","0.00000000"],["112542.54000000","0.00000000"],["112542.53000000","0.00000000"],["112542.52000000","0.00000000"],["112542.24000000","0.00000000"],["112542.23000000","0.00000000"],["112542.22000000","0.00000000"],["112542.18000000","0.00000000"],["112542.17000000","0.00000000"],["112542.00000000","0.00000000"],["112541.67000000","0.00000000"],["112541.66000000","3.74873000"],["112541.62000000","0.00000000"],["112541.58000000","0.00010000"],["112540.33000000","0.00000000"],["112540.32000000","0.00005000"],["112540.00000000","0.00150000"],["112539.41000000","0.00180000"],["112539.37000000","0.00005000"],["112539.16000000","0.00000000"],["112538.74000000","0.00000000"],["112538.31000000","0.00010000"],["112538.30000000","0.05545000"],["112538.29000000","0.17778000"],["112538.28000000","0.00715000"],["112538.20000000","0.00000000"],["112538.03000000","0.00005000"],["112538.00000000","0.00125000"],["112537.84000000","0.00000000"],["112537.72000000","0.00010000"],["112537.71000000","0.24245000"],["112537.70000000","0.20471000"],["112536.00000000","0.00125000"],["112535.93000000","0.00000000"],["112535.92000000","0.00010000"],["112535.91000000","0.46943000"],["112535.57000000","0.00000000"],["112535.56000000","0.04720000"],["112534.00000000","0.00120000"],["112533.77000000","0.00005000"],["112533.52000000","0.00255000"],["112533.22000000","0.00000000"],["112533.21000000","0.08895000"],["112533.03000000","0.00005000"],["112533.00000000","0.06105000"],["112532.37000000","0.00000000"],["112532.28000000","0.00000000"],["112532.27000000","1.15403000"],["112532.26000000","1.70701000"],["112532.24000000","0.05405000"],["112532.00000000","0.00125000"],["112531.65000000","0.00000000"],["112531.64000000","0.46938000"],["112530.50000000","0.09782000"],["112530.41000000","0.00151000"],["112530.00000000","0.00125000"],["112529.87000000","0.00444000"],["112529.86000000","0.31500000"],["112529.52000000","0.00000000"],["112529.49000000","0.00000000"],["112529.01000000","0.00250000"],["112528.21000000","0.00000000"],["112528.15000000","0.22255000"],["112528.00000000","0.00140000"],["112527.94000000","0.00000000"],["112527.76000000","0.00000000"],["112527.20000000","0.04565000"],["112527.15000000","0.00000000"],["112527.03000000","0.11030000"],["112525.88000000","0.01777000"],["112525.02000000","0.00000000"],["112524.79000000","0.00000000"],["112524.78000000","0.00151000"],["112523.15000000","0.00005000"],["112523.07000000","0.00005000"],["112522.52000000","0.00300000"],["112521.74000000","0.00000000"],["112521.14000000","0.35530000"],["112521.13000000","0.05249000"],["112520.93000000","0.00200000"],["112520.46000000","0.00000000"],["112520.28000000","0.00000000"],["112520.02000000","0.00000000"],["112519.99000000","0.00250000"],["112519.18000000","0.00000000"],["112519.15000000","0.00300000"],["112518.68000000","0.00000000"],["112518.40000000","0.26660000"],["112518.28000000","0.00000000"],["112517.99000000","0.00000000"],["112517.85000000","0.00000000"],["112517.30000000","0.04449000"],["112516.90000000","0.00022000"],["112516.88000000","0.26728000"],["112516.86000000","0.01768000"],["112515.48000000","0.00250000"],["112514.06000000","0.00005000"],["112513.53000000","0.00088000"],["112513.14000000","0.01256000"],["112513.03000000","0.00000000"],["112513.02000000","0.00000000"],["112513.01000000","0.00000000"],["112513.00000000","0.02666000"],["112509.54000000","0.99843000"],["112507.90000000","0.00008000"],["112507.89000000","0.00300000"],["112499.98000000","0.21544000"],["112498.92000000","0.00005000"],["112498.80000000","0.01021000"],["112493.44000000","0.00005000"],["112492.35000000","0.00000000"],["112490.21000000","0.34112000"],["112488.84000000","0.00000000"],["112488.76000000","0.00000000"],["112487.96000000","0.00005000"],["112486.81000000","0.00000000"],["112486.72000000","0.00000000"],["112484.63000000","0.00039000"],["112484.35000000","0.00036000"],["112480.31000000","0.00036000"],["112479.97000000","0.00035000"],["112476.94000000","0.00000000"],["112476.74000000","0.00000000"],["112476.06000000","0.00005000"],["112475.31000000","0.00040000"],["112474.51000000","0.06618000"],["112474.14000000","0.00008000"],["112474.12000000","0.00035000"],["112472.77000000","0.07135000"],["112460.01000000","0.76442000"],["112454.99000000","0.00000000"],["112452.77000000","0.40494000"],["112450.54000000","0.02488000"],["112450.03000000","0.00000000"],["112440.37000000","0.00008000"],["112437.62000000","0.00000000"],["112436.38000000","0.00005000"],["112435.37000000","0.00221000"],["112430.63000000","0.09527000"],["112427.46000000","0.00000000"],["112424.57000000","0.00005000"],["112422.01000000","0.00220000"],["112421.22000000","0.00000000"],["112418.24000000","0.74264000"],["112409.97000000","0.00000000"],["112408.24000000","0.43399000"],["112407.01000000","0.00221000"],["112406.61000000","0.00008000"],["112400.22000000","0.04612000"],["112395.36000000","0.00020000"],["112387.82000000","0.00889000"],["112387.46000000","0.00000000"],["112372.85000000","0.00008000"],["112337.29000000","0.00000000"],["112336.86000000","0.08080000"],["112330.64000000","0.09416000"],["112328.02000000","1.48985000"],["112325.35000000","0.00000000"],["112322.92000000","0.00088000"],["112310.74000000","0.00000000"],["112310.60000000","0.00088000"],["112294.84000000","0.00088000"],["112291.94000000","0.00000000"],["112282.82000000","0.99740000"],["112250.12000000","0.09992000"],["112207.27000000","0.00010000"],["112201.65000000","0.00010000"],["112196.03000000","0.00010000"],["112190.41000000","0.00000000"],["112168.70000000","0.02498000"],["112167.83000000","0.02498000"],["112098.98000000","0.00250000"],["112076.57000000","0.00000000"],["111983.28000000","0.00005000"],["110867.94000000","0.00000000"],["110853.53000000","0.00100000"],["101300.01000000","0.00009000"],["101300.00000000","1.33193000"],["101287.00000000","0.01000000"],["101286.00000000","0.00270000"],["90064.00000000","0.00000000"],["90045.04000000","0.00000000"],["90033.33000000","0.00105000"],["78785.46000000","0.00000000"],["78781.52000000","0.00000000"],["40515.00000000","0.00015000"],["33000.00000000","3.78938000"]],"a":[["112541.67000000","5.27595000"],["112541.69000000","0.00010000"],["112541.70000000","0.05025000"],["112541.74000000","0.00010000"],["112541.75000000","0.05030000"],["112542.01000000","0.00000000"],["112542.17000000","0.00000000"],["112542.18000000","0.00000000"],["112542.54000000","0.00000000"],["112542.76000000","0.00005000"],["112544.01000000","0.00000000"],["112544.33000000","0.00010000"],["112544.34000000","0.03362000"],["112544.35000000","0.04571000"],["112544.70000000","0.00000000"],["112545.74000000","0.00000000"],["112546.01000000","0.00000000"],["112546.07000000","0.00000000"],["112546.08000000","0.00005000"],["112546.33000000","0.00510000"],["112546.53000000","0.00005000"],["112546.54000000","0.20466000"],["112547.24000000","0.00005000"],["112547.29000000","0.00000000"],["112547.30000000","0.08864000"],["112547.81000000","0.00000000"],["112547.82000000","0.00000000"],["112547.84000000","0.06748000"],["112548.01000000","0.00000000"],["112548.24000000","0.00005000"],["112548.38000000","0.00000000"],["112548.40000000","0.00000000"],["112548.67000000","0.00000000"],["112548.68000000","0.08966000"],["112549.46000000","0.00000000"],["112549.79000000","0.00113000"],["112549.81000000","0.00000000"],["112550.01000000","0.00000000"],["112550.11000000","0.00000000"],["112550.12000000","0.00005000"],["112550.33000000","0.00000000"],["112551.56000000","0.00255000"],["112551.71000000","0.00505000"],["112551.87000000","0.00000000"],["112552.01000000","0.00000000"],["112552.93000000","0.00300000"],["112553.72000000","0.00005000"],["112553.98000000","0.00000000"],["112554.00000000","0.00000000"],["112554.01000000","0.32000000"],["112554.50000000","0.10755000"],["112555.06000000","0.00000000"],["112555.08000000","0.00000000"],["112555.09000000","0.12141000"],["112555.13000000","0.00000000"],["112555.48000000","0.04951000"],["112555.72000000","0.00010000"],["112555.74000000","0.10640000"],["112556.00000000","0.00000000"],["112556.01000000","0.00000000"],["112556.07000000","0.00255000"],["112556.20000000","0.00000000"],["112556.21000000","0.00000000"],["112556.23000000","0.00000000"],["112556.27000000","0.00000000"],["112556.29000000","0.00000000"],["112556.30000000","0.01744000"],["112556.31000000","0.00000000"],["112556.34000000","0.00000000"],["112556.35000000","0.00000000"],["112556.37000000","0.00000000"],["112556.38000000","0.06005000"],["112556.78000000","0.00298000"],["112557.86000000","0.00444000"],["112557.87000000","0.00805000"],["112557.88000000","0.00005000"],["112557.95000000","0.01777000"],["112557.99000000","0.00000000"],["112558.00000000","0.00000000"],["112558.03000000","0.00000000"],["112558.04000000","0.05190000"],["112558.32000000","0.26991000"],["112558.33000000","0.00005000"],["112558.49000000","0.00000000"],["112558.55000000","0.00088000"],["112559.67000000","0.00000000"],["112559.76000000","0.00005000"],["112560.58000000","0.00250000"],["112560.72000000","0.00088000"],["112560.74000000","0.00000000"],["112561.34000000","0.00010000"],["112561.58000000","0.00000000"],["112561.93000000","0.00000000"],["112562.13000000","0.00330000"],["112563.58000000","0.00007000"],["112563.72000000","0.00000000"],["112563.73000000","0.00000000"],["112564.44000000","0.00000000"],["112564.54000000","0.00000000"],["112565.09000000","0.00250000"],["112565.79000000","0.00000000"],["112565.98000000","0.17706000"],["112566.62000000","0.00000000"],["112566.96000000","0.00010000"],["112567.42000000","0.00000000"],["112567.56000000","0.00300000"],["112568.85000000","0.00000000"],["112569.23000000","0.00000000"],["112569.60000000","0.00250000"],["112570.68000000","1.32875000"],["112570.77000000","0.04994000"],["112572.93000000","0.00000000"],["112573.18000000","0.00088000"],["112574.11000000","0.00000000"],["112574.65000000","0.00000000"],["112575.43000000","0.00008000"],["112575.61000000","0.00022000"],["112577.09000000","0.04450000"],["112577.65000000","0.44510000"],["112578.62000000","0.00000000"],["112581.05000000","0.00088000"],["112583.35000000","0.00177000"],["112583.36000000","0.65807000"],["112583.41000000","0.21041000"],["112584.53000000","0.01021000"],["112587.67000000","0.99471000"],["112588.69000000","0.31970000"],["112590.07000000","0.31970000"],["112590.69000000","0.26677000"],["112591.37000000","0.00000000"],["112595.85000000","0.19921000"],["112596.24000000","0.31166000"],["112596.25000000","0.45323000"],["112596.34000000","0.00000000"],["112596.99000000","0.00000000"],["112597.92000000","0.00000000"],["112597.98000000","0.00000000"],["112600.00000000","0.22787000"],["112600.66000000","0.00000000"],["112603.04000000","0.00000000"],["112605.62000000","0.03000000"],["112606.95000000","0.00000000"],["112608.50000000","0.00000000"],["112608.52000000","0.00000000"],["112609.20000000","0.00008000"],["112613.16000000","0.00000000"],["112613.45000000","0.00221000"],["112614.45000000","0.00000000"],["112614.81000000","0.26728000"],["112615.17000000","0.26683000"],["112618.73000000","0.00048000"],["112619.22000000","0.26660000"],["112619.62000000","0.00000000"],["112619.98000000","0.03498000"],["112620.00000000","0.28702000"],["112623.02000000","0.00221000"],["112623.41000000","0.00000000"],["112623.83000000","0.00000000"],["112623.89000000","0.00000000"],["112627.23000000","0.00000000"],["112631.41000000","0.00000000"],["112631.63000000","0.35608000"],["112632.57000000","0.26677000"],["112633.93000000","0.44610000"],["112634.01000000","0.44452000"],["112635.18000000","0.00000000"],["112635.33000000","0.00000000"],["112635.41000000","0.00000000"],["112635.69000000","0.00000000"],["112635.72000000","0.00000000"],["112635.78000000","0.00000000"],["112635.85000000","0.00000000"],["112635.88000000","0.00000000"],["112635.92000000","0.00000000"],["112636.82000000","0.00000000"],["112636.89000000","0.00000000"],["112637.09000000","0.00000000"],["112637.21000000","0.00000000"],["112637.53000000","0.00000000"],["112637.59000000","0.00000000"],["112637.60000000","0.00000000"],["112637.70000000","0.00100000"],["112637.71000000","0.00100000"],["112639.11000000","0.00000000"],["112640.00000000","0.37989000"],["112642.72000000","0.00000000"],["112642.96000000","0.00008000"],["112654.37000000","0.03000000"],["112654.62000000","0.00000000"],["112657.60000000","0.00000000"],["112667.99000000","0.00000000"],["112668.78000000","0.00000000"],["112672.73000000","0.00000000"],["112673.39000000","0.00000000"],["112676.72000000","0.00024000"],["112680.23000000","0.00000000"],["112682.62000000","0.00000000"],["112682.63000000","0.00000000"],["112691.37000000","0.00000000"],["112697.84000000","0.47523000"],["112710.48000000","0.00008000"],["112725.13000000","0.00000000"],["112726.55000000","0.00088000"],["112727.48000000","0.00000000"],["112731.59000000","0.00019000"],["112735.38000000","0.00088000"],["112780.60000000","0.00000000"],["112789.87000000","0.00000000"],["112840.38000000","0.00000000"],["112862.95000000","0.00250000"],["112905.73000000","0.02498000"],["112907.86000000","0.02498000"],["112909.29000000","0.02498000"],["112910.51000000","0.02498000"],["112929.76000000","0.00000000"],["112929.77000000","0.31500000"],["112932.05000000","0.00000000"],["112936.87000000","0.00000000"],["112941.01000000","0.00000000"],["112942.49000000","0.00000000"],["112995.38000000","0.02498000"],["113550.42000000","0.04000000"],["113558.00000000","0.10027000"],["114229.80000000","0.00100000"],["114244.65000000","0.00000000"]]}
[2025-10-26T09:48:38.081Z] {"e":"depthUpdate","E":1761472117014,"s":"BTCUSDT","U":79058081144,"u":79058081536,"b":[["112541.66000000","4.21002000"],["112540.00000000","0.00140000"],["112539.44000000","0.00000000"],["112539.43000000","0.00000000"],["112539.42000000","0.00000000"],["112539.41000000","0.00160000"],["112539.33000000","0.00710000"],["112538.85000000","0.00201000"],["112538.31000000","0.00000000"],["112538.30000000","0.00000000"],["112538.29000000","0.00000000"],["112538.28000000","0.00000000"],["112538.03000000","0.00255000"],["112538.00000000","0.00125000"],["112537.71000000","0.20823000"],["112537.70000000","0.00000000"],["112536.92000000","0.20466000"],["112536.28000000","0.00000000"],["112535.92000000","0.00010000"],["112535.57000000","0.00010000"],["112535.56000000","0.04725000"],["112534.91000000","0.00543000"],["112534.01000000","0.00444000"],["112533.52000000","0.00250000"],["112533.21000000","0.00005000"],["112533.00000000","0.06105000"],["112532.27000000","1.15408000"],["112532.26000000","1.70706000"],["112532.24000000","0.05415000"],["112532.10000000","0.00391000"],["112531.64000000","0.46943000"],["112530.50000000","0.09777000"],["112530.41000000","0.00867000"],["112530.00000000","0.06120000"],["112529.87000000","0.00000000"],["112528.15000000","0.00000000"],["112527.20000000","0.00000000"],["112526.19000000","0.35530000"],["112525.88000000","0.00000000"],["112525.85000000","0.00000000"],["112525.82000000","0.00000000"],["112525.80000000","0.00000000"],["112525.78000000","0.01777000"],["112524.67000000","0.04565000"],["112523.23000000","0.06748000"],["112521.14000000","0.00000000"],["112518.02000000","0.00888000"],["112517.30000000","0.00000000"],["112515.48000000","0.00000000"],["112513.51000000","0.01256000"],["112513.14000000","0.00000000"],["112491.02000000","0.00088000"],["112490.21000000","0.00000000"],["112487.38000000","0.34112000"],["112470.00000000","0.36160000"],["112467.86000000","0.00005000"],["112432.70000000","0.00005000"],["112418.84000000","0.00005000"],["112369.95000000","0.13284000"],["112326.00000000","0.00050000"],["112312.57000000","0.00000000"],["112223.24000000","0.00884000"],["112216.46000000","0.01688000"],["112206.85000000","0.01688000"],["111988.87000000","0.00008000"],["110853.53000000","0.00100000"],["101300.01000000","0.00000000"],["101287.00000000","0.01000000"],["101286.00000000","0.00270000"],["90033.33000000","0.00105000"],["40515.00000000","0.00030000"]],"a":[["112541.67000000","1.65423000"],["112541.68000000","0.00090000"],["112541.69000000","0.00776000"],["112541.70000000","0.05020000"],["112541.75000000","0.05015000"],["112542.79000000","0.00098000"],["112543.86000000","0.00005000"],["112544.33000000","0.00000000"],["112544.34000000","0.00010000"],["112544.35000000","0.04571000"],["112544.48000000","0.00201000"],["112544.99000000","0.00005000"],["112546.08000000","0.00000000"],["112546.17000000","0.00360000"],["112546.33000000","0.00005000"],["112546.53000000","0.00000000"],["112546.54000000","0.00000000"],["112547.30000000","0.00000000"],["112547.32000000","0.00010000"],["112547.33000000","0.20466000"],["112547.84000000","0.00000000"],["112548.42000000","0.00533000"],["112548.67000000","0.00010000"],["112549.79000000","0.00400000"],["112551.71000000","0.00510000"],["112553.99000000","0.00000000"],["112554.00000000","0.03342000"],["112554.50000000","0.10750000"],["112555.48000000","0.00010000"],["112555.74000000","0.00000000"],["112555.75000000","0.00711000"],["112556.24000000","0.00005000"],["112556.30000000","0.09892000"],["112556.78000000","0.00005000"],["112557.86000000","0.00000000"],["112557.95000000","0.00000000"],["112558.33000000","0.00000000"],["112559.11000000","0.01777000"],["112559.96000000","0.00000000"],["112560.09000000","0.00006000"],["112560.87000000","0.04946000"],["112562.12000000","0.00444000"],["112562.50000000","0.00000000"],["112564.18000000","0.10640000"],["112564.68000000","0.00010000"],["112565.98000000","0.00000000"],["112570.00000000","0.00120000"],["112570.16000000","0.00005000"],["112570.18000000","0.31975000"],["112570.66000000","0.17706000"],["112572.00000000","0.00120000"],["112574.00000000","0.06220000"],["112576.00000000","0.00120000"],["112577.09000000","0.00000000"],["112578.00000000","0.00120000"],["112580.00000000","0.00120000"],["112582.00000000","0.00120000"],["112582.92000000","0.00000000"],["112584.00000000","0.00120000"],["112586.00000000","0.00120000"],["112586.86000000","0.00000000"],["112588.00000000","0.00120000"],["112589.67000000","0.00000000"],["112590.00000000","0.00120000"],["112590.07000000","0.00000000"],["112591.36000000","0.00000000"],["112591.48000000","0.01688000"],["112591.49000000","0.00000000"],["112592.00000000","0.00120000"],["112594.00000000","0.00120000"],["112596.00000000","0.00120000"],["112618.72000000","0.00048000"],["112618.73000000","0.00000000"],["112637.57000000","0.00000000"],["112637.58000000","0.00000000"],["112637.70000000","0.00000000"],["112637.71000000","0.00000000"],["112637.72000000","0.00000000"],["112637.73000000","0.00010000"],["112637.74000000","0.00000000"],["112686.17000000","0.01688000"],["112704.33000000","0.13368000"],["112723.73000000","0.01698000"],["112731.58000000","0.00019000"],["112731.59000000","0.00000000"],["112837.33000000","0.01688000"],["112848.39000000","0.01688000"],["114229.80000000","0.00100000"]]}
[2025-10-26T09:48:39.104Z] {"e":"depthUpdate","E":1761472118014,"s":"BTCUSDT","U":79058081537,"u":79058081691,"b":[["112541.66000000","3.93830000"],["112539.41000000","0.00165000"],["112539.33000000","0.00715000"],["112537.71000000","0.29760000"],["112536.93000000","0.00010000"],["112536.92000000","0.20476000"],["112536.04000000","0.00010000"],["112536.03000000","0.22265000"],["112535.91000000","0.46948000"],["112535.57000000","0.00000000"],["112535.56000000","0.04725000"],["112534.91000000","0.00543000"],["112533.52000000","0.00255000"],["112533.22000000","0.00005000"],["112533.21000000","0.08895000"],["112533.01000000","0.00000000"],["112532.27000000","1.15403000"],["112532.26000000","1.70701000"],["112532.24000000","0.05410000"],["112531.64000000","0.46938000"],["112530.41000000","0.00862000"],["112509.75000000","0.00005000"],["112509.54000000","0.00005000"],["112480.00000000","0.04165000"],["112474.51000000","0.00000000"],["112474.06000000","0.00000000"],["112473.89000000","0.06580000"],["112469.55000000","0.00000000"],["112407.01000000","0.00221000"],["112369.95000000","0.00000000"],["112328.02000000","0.11491000"],["112325.34000000","0.00000000"],["112300.24000000","4.60868000"],["112294.84000000","0.00088000"],["110853.53000000","0.00100000"],["103545.80000000","0.00010000"],["101287.00000000","0.01000000"],["101286.00000000","0.00270000"],["90033.33000000","0.00105000"],["50000.00000000","39.87929000"],["40515.00000000","0.00045000"],["40498.59000000","0.00030000"],["40447.19000000","0.00075000"],["40437.91000000","0.00000000"]],"a":[["112541.67000000","1.56703000"],["112541.68000000","0.00095000"],["112541.75000000","0.05020000"],["112544.33000000","0.00000000"],["112544.35000000","0.04576000"],["112547.33000000","0.20471000"],["112552.93000000","0.00305000"],["112554.18000000","0.00298000"],["112556.38000000","0.06000000"],["112557.87000000","0.00800000"],["112558.04000000","0.05195000"],["112560.46000000","0.04000000"],["112571.79000000","0.00000000"],["112572.12000000","0.00888000"],["112574.18000000","0.00005000"],["112578.12000000","0.00005000"],["112587.67000000","0.00000000"],["112595.84000000","0.01599000"],["112596.25000000","0.42658000"],["112600.00000000","0.38787000"],["112610.00000000","0.20160000"],["112637.66000000","0.00000000"],["112637.67000000","0.00000000"],["112640.00000000","0.01989000"],["112690.43000000","0.47523000"],["112697.84000000","0.00000000"],["112704.33000000","0.00000000"],["112790.20000000","4.72834000"],["112820.83000000","0.00000000"],["112997.06000000","0.02498000"],["112997.79000000","0.02498000"],["114229.80000000","0.00100000"]]}
[2025-10-26T09:48:40.129Z] {"e":"depthUpdate","E":1761472119014,"s":"BTCUSDT","U":79058081692,"u":79058081808,"b":[["112541.66000000","4.02689000"],["112539.41000000","0.00165000"],["112539.33000000","0.00000000"],["112539.24000000","0.00715000"],["112534.91000000","0.00543000"],["112533.52000000","0.00250000"],["112533.22000000","0.00000000"],["112533.21000000","0.00005000"],["112533.01000000","0.00000000"],["112533.00000000","0.06105000"],["112532.54000000","0.29325000"],["112532.27000000","1.15403000"],["112513.91000000","0.00000000"],["112513.65000000","0.01256000"],["112513.51000000","0.00000000"],["112509.54000000","0.99280000"],["112497.62000000","1.05690000"],["112497.61000000","0.31996000"],["112495.91000000","0.00000000"],["112491.64000000","0.31997000"],["112463.25000000","0.03000000"],["112436.97000000","0.00000000"],["112363.11000000","0.13445000"],["112357.56000000","0.00955000"],["112353.65000000","0.00000000"],["112348.21000000","0.00000000"],["112328.02000000","0.02559000"],["112307.02000000","0.00000000"],["112279.47000000","0.01391000"],["112254.12000000","0.00567000"],["112195.39000000","0.00000000"],["111585.43000000","0.00200000"],["111574.28000000","0.00000000"],["110853.53000000","0.00100000"],["103545.80000000","0.00000000"],["101287.00000000","0.01000000"],["101286.00000000","0.00270000"],["90033.33000000","0.00105000"],["90033.00000000","0.00000000"]],"a":[["112541.67000000","1.56654000"],["112541.68000000","0.00100000"],["112544.35000000","0.04576000"],["112547.32000000","0.00000000"],["112547.33000000","0.00000000"],["112548.68000000","0.08971000"],["112548.97000000","0.00005000"],["112548.98000000","0.20466000"],["112554.00000000","0.03347000"],["112558.04000000","0.05195000"],["112559.02000000","0.01777000"],["112559.11000000","0.00000000"],["112570.24000000","0.00005000"],["112582.06000000","0.00005000"],["112582.47000000","0.98440000"],["112586.96000000","0.00000000"],["112618.72000000","0.00000000"],["112618.73000000","0.00048000"],["112637.98000000","0.00100000"],["112637.99000000","0.00100000"],["112670.25000000","0.00000000"],["112681.52000000","0.00200000"],["112707.52000000","0.13081000"],["112731.58000000","0.00000000"],["112731.59000000","0.00019000"],["112867.71000000","0.02498000"],["112998.07000000","0.02498000"],["114229.80000000","0.00100000"]]}
[2025-10-26T09:48:41.153Z] {"e":"depthUpdate","E":1761472120014,"s":"BTCUSDT","U":79058081809,"u":79058082744,"b":[["112554.00000000","5.38062000"],["112553.99000000","0.00000000"],["112553.92000000","0.00010000"],["112553.72000000","0.00005000"],["112552.92000000","0.00000000"],["112551.70000000","0.00000000"],["112551.33000000","0.04000000"],["112549.78000000","0.00000000"],["112548.97000000","0.00000000"],["112548.96000000","0.00000000"],["112548.67000000","0.00000000"],["112548.41000000","0.00000000"],["112548.39000000","0.00010000"],["112548.38000000","0.03959000"],["112548.37000000","0.08914000"],["112548.24000000","0.00005000"],["112548.23000000","0.00000000"],["112547.29000000","0.00000000"],["112546.32000000","0.00000000"],["112546.16000000","0.00000000"],["112545.76000000","0.00010000"],["112545.75000000","0.04725000"],["112544.47000000","0.00000000"],["112544.34000000","0.00000000"],["112544.33000000","0.00000000"],["112544.32000000","0.00000000"],["112543.78000000","0.00720000"],["112543.23000000","0.20466000"],["112542.78000000","0.00000000"],["112542.76000000","0.00005000"],["112542.75000000","0.00000000"],["112542.74000000","0.00300000"],["112542.54000000","0.00250000"],["112541.74000000","0.00000000"],["112541.69000000","0.49104000"],["112541.68000000","0.00010000"],["112541.67000000","0.47387000"],["112541.66000000","0.42221000"],["112541.58000000","0.00000000"],["112540.68000000","0.00000000"],["112540.10000000","0.00000000"],["112540.00000000","0.00130000"],["112539.95000000","0.00010000"],["112539.61000000","0.00005000"],["112539.60000000","0.05327000"],["112539.41000000","0.00155000"],["112539.24000000","0.00000000"],["112537.72000000","0.00000000"],["112537.71000000","0.30789000"],["112537.12000000","0.00088000"],["112536.93000000","0.00000000"],["112536.92000000","0.00000000"],["112536.04000000","0.00000000"],["112536.03000000","0.22255000"],["112536.00000000","0.00120000"],["112535.99000000","0.00000000"],["112535.92000000","0.35530000"],["112535.91000000","0.46938000"],["112535.57000000","0.00000000"],["112535.56000000","0.00010000"],["112534.91000000","0.00533000"],["112534.01000000","0.00000000"],["112533.00000000","0.06100000"],["112532.54000000","0.00000000"],["112532.27000000","1.15403000"],["112532.24000000","0.05405000"],["112532.00000000","0.00120000"],["112530.51000000","0.26660000"],["112530.50000000","0.09772000"],["112530.41000000","0.00711000"],["112529.75000000","0.01777000"],["112528.76000000","0.26728000"],["112527.82000000","0.04377000"],["112527.03000000","0.00000000"],["112526.69000000","0.00000000"],["112526.19000000","0.00000000"],["112526.11000000","0.00000000"],["112525.91000000","0.15146000"],["112525.83000000","0.26683000"],["112525.78000000","0.00000000"],["112525.77000000","0.04000000"],["112524.97000000","0.00000000"],["112524.78000000","0.00000000"],["112524.54000000","0.00000000"],["112521.13000000","0.00000000"],["112520.24000000","0.04449000"],["112519.99000000","0.00000000"],["112517.45000000","0.44452000"],["112515.60000000","0.00000000"],["112515.09000000","0.00000000"],["112514.90000000","0.00000000"],["112514.60000000","0.00000000"],["112514.51000000","0.00000000"],["112514.06000000","0.00000000"],["112513.65000000","0.00000000"],["112513.63000000","0.00000000"],["112513.19000000","0.00000000"],["112512.32000000","0.21439000"],["112510.96000000","0.31992000"],["112507.89000000","0.00000000"],["112505.88000000","0.26677000"],["112504.40000000","0.31999000"],["112499.98000000","0.00000000"],["112498.23000000","0.07898000"],["112496.35000000","0.00005000"],["112494.84000000","0.00000000"],["112494.20000000","0.00000000"],["112493.44000000","0.00000000"],["112491.02000000","0.00000000"],["112487.96000000","0.00000000"],["112487.87000000","0.00000000"],["112481.36000000","0.00012000"],["112479.87000000","0.00000000"],["112479.70000000","0.26693000"],["112478.81000000","0.00000000"],["112476.25000000","0.00000000"],["112475.73000000","0.00017000"],["112472.90000000","0.00000000"],["112471.14000000","0.00000000"],["112460.66000000","0.44452000"],["112459.88000000","0.00000000"],["112459.57000000","0.00000000"],["112458.98000000","0.26677000"],["112449.16000000","0.00000000"],["112446.55000000","0.00220000"],["112435.38000000","0.00221000"],["112435.37000000","0.00000000"],["112429.34000000","0.02359000"],["112424.63000000","0.09922000"],["112424.57000000","0.00000000"],["112424.03000000","0.09675000"],["112422.01000000","0.00000000"],["112418.84000000","0.00000000"],["112382.08000000","0.05714000"],["112357.56000000","0.00000000"],["112328.02000000","0.11164000"],["112322.93000000","0.00088000"],["112310.60000000","0.00000000"],["112279.47000000","0.00000000"],["112230.85000000","0.00010000"],["112201.65000000","0.00000000"],["112196.03000000","0.00000000"],["112089.43000000","0.02498000"],["112089.06000000","0.02498000"],["112088.70000000","0.02498000"],["111983.28000000","0.00000000"],["110865.69000000","0.00100000"],["110853.53000000","0.00000000"],["101287.00000000","0.01000000"],["101286.00000000","0.00270000"],["90043.20000000","0.00022000"],["90033.33000000","0.00083000"],["78785.46000000","0.00000000"],["42000.00000000","1.40412000"]],"a":[["112541.67000000","0.00000000"],["112541.68000000","0.00000000"],["112541.69000000","0.00000000"],["112541.70000000","0.00000000"],["112541.74000000","0.00000000"],["112541.75000000","0.00000000"],["112542.76000000","0.00000000"],["112542.79000000","0.00000000"],["112543.86000000","0.00000000"],["112544.33000000","0.00000000"],["112544.34000000","0.00000000"],["112544.35000000","0.00000000"],["112544.48000000","0.00000000"],["112544.99000000","0.00000000"],["112546.17000000","0.00000000"],["112546.33000000","0.00000000"],["112547.24000000","0.00000000"],["112548.24000000","0.00000000"],["112548.42000000","0.00000000"],["112548.67000000","0.00000000"],["112548.68000000","0.00000000"],["112548.97000000","0.00000000"],["112548.98000000","0.00000000"],["112549.79000000","0.00000000"],["112550.12000000","0.00000000"],["112551.56000000","0.00000000"],["112551.71000000","0.00000000"],["112552.93000000","0.00000000"],["112553.72000000","0.00000000"],["112554.00000000","0.00000000"],["112554.01000000","3.14046000"],["112554.02000000","0.00060000"],["112554.09000000","0.00010000"],["112554.18000000","0.00323000"],["112554.49000000","0.00010000"],["112554.50000000","0.10765000"],["112555.08000000","0.00000000"],["112555.09000000","0.00000000"],["112555.48000000","0.00005000"],["112555.72000000","0.00000000"],["112555.75000000","0.00716000"],["112556.07000000","0.00005000"],["112556.24000000","0.00000000"],["112556.29000000","0.00000000"],["112556.30000000","0.01038000"],["112556.37000000","0.00010000"],["112556.38000000","0.06010000"],["112556.48000000","0.00010000"],["112556.49000000","0.00005000"],["112556.78000000","0.00000000"],["112557.87000000","0.00000000"],["112558.03000000","0.00010000"],["112558.04000000","0.05190000"],["112558.31000000","0.00000000"],["112558.32000000","0.00000000"],["112558.49000000","0.00005000"],["112558.55000000","0.00000000"],["112559.02000000","0.00000000"],["112559.03000000","0.00000000"],["112559.04000000","0.00005000"],["112559.05000000","0.00000000"],["112559.06000000","0.00000000"],["112559.07000000","0.00000000"],["112559.76000000","0.00022000"],["112560.04000000","0.00005000"],["112560.05000000","0.01801000"],["112560.23000000","0.00000000"],["112560.24000000","0.00000000"],["112560.46000000","0.00000000"],["112560.58000000","0.00250000"],["112560.87000000","0.00000000"],["112561.82000000","0.00000000"],["112562.12000000","0.00000000"],["112562.13000000","0.00005000"],["112562.46000000","0.08864000"],["112563.08000000","0.00000000"],["112563.09000000","0.01777000"],["112563.63000000","0.00000000"],["112564.18000000","0.00000000"],["112564.68000000","0.00005000"],["112565.08000000","0.00005000"],["112565.09000000","0.00255000"],["112565.27000000","0.00156000"],["112565.37000000","0.00000000"],["112565.95000000","0.04951000"],["112567.56000000","0.00305000"],["112567.72000000","0.00205000"],["112568.64000000","0.08897000"],["112569.37000000","0.04000000"],["112569.38000000","0.00000000"],["112569.60000000","0.00250000"],["112569.66000000","0.04000000"],["112570.18000000","0.00000000"],["112570.66000000","0.00000000"],["112570.68000000","0.79464000"],["112570.89000000","0.00151000"],["112570.90000000","0.10640000"],["112573.68000000","0.00010000"],["112573.71000000","0.00444000"],["112573.72000000","0.00000000"],["112576.03000000","0.00000000"],["112577.29000000","0.00000000"],["112577.64000000","0.00017000"],["112578.29000000","0.17706000"],["112578.62000000","0.00250000"],["112580.83000000","0.15146000"],["112581.97000000","0.26728000"],["112582.34000000","0.26683000"],["112583.13000000","0.00250000"],["112584.37000000","0.04441000"],["112584.52000000","0.00000000"],["112585.75000000","0.04450000"],["112587.27000000","0.01332000"],["112587.56000000","0.00000000"],["112587.78000000","0.00300000"],["112589.65000000","0.00000000"],["112590.76000000","0.31969000"],["112593.40000000","0.00088000"],["112593.88000000","0.00005000"],["112595.27000000","0.00000000"],["112596.25000000","0.41326000"],["112597.37000000","0.31968000"],["112597.82000000","0.00005000"],["112600.00000000","0.18787000"],["112600.28000000","0.00000000"],["112601.89000000","0.08000000"],["112603.04000000","0.00005000"],["112604.65000000","0.00088000"],["112608.52000000","0.00005000"],["112610.00000000","0.00160000"],["112613.45000000","0.00000000"],["112613.86000000","0.04091000"],["112614.81000000","0.00000000"],["112615.17000000","0.00000000"],["112615.35000000","0.00000000"],["112618.73000000","0.00000000"],["112620.00000000","0.19702000"],["112623.02000000","0.00000000"],["112625.98000000","0.00221000"],["112627.00000000","0.26733000"],["112627.37000000","0.26683000"],["112630.95000000","0.00048000"],["112634.01000000","0.51758000"],["112635.99000000","0.00220000"],["112637.98000000","0.00000000"],["112637.99000000","0.00000000"],["112640.59000000","0.00000000"],["112640.60000000","0.00000000"],["112690.43000000","0.00000000"],["112697.84000000","0.00000000"],["112726.55000000","0.00000000"],["112735.38000000","0.00000000"],["112738.71000000","0.00098000"],["112747.91000000","0.00088000"],["112933.36000000","0.00062000"],["112998.17000000","0.02498000"],["112999.01000000","0.02498000"],["112999.38000000","0.02498000"],["114229.80000000","0.00000000"],["114242.33000000","0.00100000"]]}
[2025-10-26T09:48:42.048Z] {"e":"depthUpdate","E":1761472121014,"s":"BTCUSDT","U":79058082745,"u":79058083161,"b":[["112554.00000000","5.21100000"],["112553.99000000","0.00010000"],["112552.87000000","0.00005000"],["112551.36000000","0.06521000"],["112551.35000000","0.17776000"],["112551.34000000","0.00020000"],["112551.33000000","0.04010000"],["112549.50000000","0.00005000"],["112548.38000000","0.10696000"],["112548.37000000","0.31169000"],["112547.40000000","0.00710000"],["112547.05000000","0.00250000"],["112546.83000000","0.20466000"],["112545.76000000","0.00005000"],["112545.75000000","0.04720000"],["112545.63000000","0.00000000"],["112545.09000000","0.29317000"],["112543.78000000","0.00010000"],["112543.24000000","0.71909000"],["112543.23000000","0.00005000"],["112542.48000000","0.00000000"],["112541.72000000","0.00000000"],["112541.71000000","0.00000000"],["112541.70000000","0.00000000"],["112541.69000000","0.00000000"],["112541.68000000","0.00000000"],["112541.67000000","0.47382000"],["112541.66000000","0.42216000"],["112539.61000000","0.00000000"],["112539.60000000","0.05289000"],["112539.41000000","0.00155000"],["112539.37000000","0.00005000"],["112539.17000000","0.00000000"],["112538.31000000","0.01783000"],["112537.97000000","0.78269000"],["112537.96000000","1.70701000"],["112537.71000000","0.00000000"],["112536.03000000","0.00000000"],["112535.56000000","0.00005000"],["112534.91000000","0.00538000"],["112533.77000000","0.00000000"],["112533.52000000","0.00250000"],["112533.42000000","0.01777000"],["112533.21000000","0.00000000"],["112533.03000000","0.00000000"],["112532.24000000","0.05400000"],["112531.78000000","0.04881000"],["112529.75000000","0.00000000"],["112529.56000000","0.00000000"],["112528.38000000","0.04320000"],["112527.82000000","0.00000000"],["112526.71000000","0.00000000"],["112526.09000000","0.00000000"],["112525.39000000","0.00000000"],["112525.38000000","0.00000000"],["112525.33000000","0.00000000"],["112524.50000000","0.00000000"],["112524.41000000","0.00000000"],["112520.24000000","0.00000000"],["112520.23000000","0.00008000"],["112518.40000000","0.00000000"],["112516.88000000","0.00000000"],["112516.86000000","0.00000000"],["112509.54000000","0.00005000"],["112507.90000000","0.00000000"],["112486.47000000","0.00008000"],["112483.35000000","0.26660000"],["112481.85000000","0.26728000"],["112474.14000000","0.00000000"],["112472.90000000","0.00005000"],["112452.70000000","0.00008000"],["112440.37000000","0.00000000"],["112418.94000000","0.00008000"],["112406.61000000","0.00000000"],["112403.15000000","0.00355000"],["112385.17000000","0.00008000"],["112372.85000000","0.00000000"],["112328.99000000","0.00000000"],["110865.69000000","0.00100000"],["101298.00000000","0.00010000"],["101286.00000000","0.00260000"],["90043.20000000","0.00022000"]],"a":[["112554.01000000","2.40029000"],["112554.02000000","0.00070000"],["112554.04000000","0.00010000"],["112554.05000000","0.05030000"],["112554.09000000","0.00020000"],["112554.10000000","0.05015000"],["112554.17000000","0.00010000"],["112554.18000000","0.20779000"],["112554.50000000","0.10755000"],["112555.07000000","0.00000000"],["112555.08000000","0.00000000"],["112555.75000000","0.00711000"],["112556.24000000","0.00005000"],["112556.30000000","0.01033000"],["112556.38000000","0.06000000"],["112556.48000000","0.00000000"],["112556.49000000","0.00000000"],["112558.03000000","0.00000000"],["112558.04000000","0.05190000"],["112560.04000000","0.00000000"],["112562.45000000","0.00000000"],["112562.46000000","0.08859000"],["112563.09000000","0.00000000"],["112565.27000000","0.00156000"],["112565.48000000","0.00000000"],["112565.49000000","0.00000000"],["112565.95000000","0.00005000"],["112566.30000000","0.01777000"],["112567.72000000","0.00210000"],["112568.33000000","0.00329000"],["112568.35000000","0.00069000"],["112568.64000000","0.08897000"],["112568.84000000","0.00000000"],["112568.88000000","0.00073000"],["112569.37000000","0.00000000"],["112569.60000000","0.00250000"],["112569.66000000","0.04000000"],["112569.99000000","0.00000000"],["112570.03000000","0.04946000"],["112570.68000000","0.35012000"],["112571.65000000","0.00444000"],["112572.76000000","0.04000000"],["112573.70000000","0.29976000"],["112573.71000000","0.00000000"],["112575.43000000","0.00000000"],["112582.47000000","0.00000000"],["112584.37000000","0.00000000"],["112585.75000000","0.00000000"],["112587.78000000","0.00308000"],["112589.94000000","0.00005000"],["112593.05000000","0.44452000"],["112604.27000000","0.00000000"],["112606.68000000","0.00006000"],["112609.20000000","0.00000000"],["112610.00000000","0.20160000"],["112617.99000000","0.00006000"],["112621.54000000","0.00008000"],["112634.01000000","0.07306000"],["112641.10000000","0.00100000"],["112641.11000000","0.00100000"],["112642.96000000","0.00000000"],["112649.33000000","0.44452000"],["112655.31000000","0.00008000"],["112668.78000000","0.00005000"],["112676.72000000","0.00016000"],["112689.07000000","0.00008000"],["112710.48000000","0.00000000"],["112722.84000000","0.00008000"],["113000.84000000","0.02498000"],["113550.42000000","0.00000000"],["114242.33000000","0.00100000"]]}
[2025-10-26T09:48:43.053Z] {"e":"depthUpdate","E":1761472122014,"s":"BTCUSDT","U":79058083162,"u":79058085613,"b":[["112563.56000000","5.09942000"],["112563.48000000","0.00010000"],["112563.10000000","0.00005000"],["112562.56000000","0.00010000"],["112562.55000000","0.12104000"],["112562.54000000","0.00000000"],["112562.20000000","0.00000000"],["112562.19000000","0.00000000"],["112562.18000000","0.00000000"],["112562.17000000","0.00000000"],["112562.16000000","0.00000000"],["112561.36000000","0.00710000"],["112561.33000000","0.00000000"],["112560.80000000","0.20466000"],["112560.78000000","0.00000000"],["112560.76000000","0.00010000"],["112560.75000000","0.08976000"],["112560.72000000","0.00010000"],["112560.71000000","0.00010000"],["112560.58000000","0.00250000"],["112560.00000000","0.00005000"],["112559.99000000","0.00000000"],["112559.93000000","0.04656000"],["112559.92000000","0.00010000"],["112559.91000000","0.00000000"],["112559.75000000","0.00000000"],["112559.20000000","0.00005000"],["112559.19000000","0.00005000"],["112558.71000000","0.00000000"],["112558.70000000","0.00000000"],["112558.69000000","0.00000000"],["112558.68000000","0.04015000"],["112558.67000000","0.00000000"],["112558.61000000","0.00000000"],["112558.50000000","0.00000000"],["112558.40000000","0.00000000"],["112558.30000000","0.04710000"],["112557.45000000","0.00000000"],["112557.35000000","0.00000000"],["112556.82000000","0.00000000"],["112556.81000000","0.00000000"],["112556.30000000","0.00000000"],["112556.29000000","0.00000000"],["112556.08000000","0.00444000"],["112556.07000000","0.00250000"],["112556.06000000","0.00000000"],["112555.74000000","0.00000000"],["112555.68000000","0.00000000"],["112555.47000000","0.00000000"],["112555.12000000","0.00000000"],["112554.84000000","0.00000000"],["112554.57000000","0.00000000"],["112554.56000000","0.00000000"],["112554.55000000","0.83489000"],["112554.54000000","1.70706000"],["112554.53000000","0.00000000"],["112554.52000000","0.00000000"],["112554.50000000","0.00000000"],["112554.49000000","0.55904000"],["112554.44000000","0.00000000"],["112554.20000000","0.00000000"],["112554.17000000","0.00000000"],["112554.09000000","0.00000000"],["112554.08000000","0.00000000"],["112554.07000000","0.00000000"],["112554.04000000","0.00000000"],["112554.03000000","0.00000000"],["112554.01000000","0.00000000"],["112554.00000000","0.44572000"],["112553.99000000","0.00000000"],["112553.92000000","0.00000000"],["112553.31000000","0.00000000"],["112553.17000000","0.00000000"],["112552.88000000","0.00098000"],["112552.77000000","0.00000000"],["112552.76000000","0.00000000"],["112552.75000000","0.00000000"],["112552.61000000","0.00000000"],["112552.33000000","0.00000000"],["112552.30000000","0.00053000"],["112552.19000000","0.00000000"],["112551.75000000","0.00005000"],["112551.56000000","0.00250000"],["112551.37000000","0.00000000"],["112551.36000000","0.00000000"],["112551.35000000","0.00000000"],["112551.34000000","0.00000000"],["112551.33000000","0.00005000"],["112551.19000000","0.00201000"],["112550.90000000","0.00000000"],["112550.72000000","0.00000000"],["112550.10000000","0.00000000"],["112550.09000000","0.00000000"],["112549.51000000","0.00010000"],["112549.50000000","0.00360000"],["112549.06000000","0.00000000"],["112549.05000000","1.13244000"],["112549.04000000","0.00000000"],["112549.03000000","0.46938000"],["112548.93000000","0.12028000"],["112548.72000000","0.00000000"],["112548.39000000","0.00010000"],["112548.38000000","0.03785000"],["112548.37000000","0.22260000"],["112547.76000000","0.04565000"],["112547.40000000","0.00000000"],["112547.30000000","0.00000000"],["112547.25000000","0.00533000"],["112547.05000000","0.00255000"],["112546.83000000","0.00000000"],["112546.75000000","0.35529000"],["112546.74000000","1.70701000"],["112546.68000000","0.00150000"],["112546.60000000","0.00005000"],["112546.39000000","0.05288000"],["112545.76000000","0.00000000"],["112545.75000000","0.00000000"],["112545.26000000","0.15146000"],["112545.24000000","0.46938000"],["112545.09000000","0.00000000"],["112544.76000000","0.26660000"],["112544.63000000","0.00010000"],["112544.50000000","0.00007000"],["112544.44000000","0.00391000"],["112543.98000000","0.26683000"],["112543.97000000","0.26728000"],["112543.78000000","0.00000000"],["112543.25000000","0.29177000"],["112543.24000000","0.00000000"],["112543.23000000","0.00000000"],["112542.76000000","0.00005000"],["112542.75000000","0.00711000"],["112542.54000000","0.00250000"],["112541.77000000","0.00000000"],["112541.68000000","0.29976000"],["112541.67000000","0.46938000"],["112541.66000000","0.34276000"],["112541.17000000","0.00000000"],["112541.04000000","0.00300000"],["112540.89000000","0.00000000"],["112540.36000000","0.05700000"],["112540.32000000","0.00000000"],["112540.08000000","0.00000000"],["112540.00000000","0.00125000"],["112539.97000000","0.06748000"],["112539.96000000","0.00000000"],["112539.60000000","0.00000000"],["112539.41000000","0.00000000"],["112539.27000000","0.05053000"],["112538.85000000","0.00000000"],["112538.31000000","0.01773000"],["112538.03000000","0.00000000"],["112538.00000000","0.00120000"],["112537.79000000","0.04000000"],["112537.28000000","0.15151000"],["112537.22000000","0.00000000"],["112536.17000000","0.15105000"],["112536.00000000","0.00120000"],["112535.92000000","0.00000000"],["112535.66000000","0.15120000"],["112535.56000000","0.00000000"],["112534.95000000","0.00000000"],["112534.91000000","0.00000000"],["112534.79000000","0.44510000"],["112534.75000000","0.00000000"],["112534.51000000","0.00000000"],["112533.52000000","0.00000000"],["112533.42000000","0.00000000"],["112532.10000000","0.00000000"],["112531.78000000","0.00000000"],["112531.38000000","0.00000000"],["112530.94000000","0.00000000"],["112530.51000000","0.00000000"],["112530.49000000","0.00000000"],["112530.41000000","0.00000000"],["112529.86000000","0.31509000"],["112529.76000000","0.00009000"],["112529.45000000","0.00000000"],["112529.26000000","0.00000000"],["112529.01000000","0.00000000"],["112528.76000000","0.00000000"],["112528.38000000","0.00000000"],["112528.15000000","0.35608000"],["112527.58000000","0.00000000"],["112526.04000000","0.06000000"],["112525.91000000","0.00000000"],["112525.83000000","0.00000000"],["112525.77000000","0.00000000"],["112525.46000000","0.00000000"],["112525.43000000","0.00000000"],["112525.32000000","0.00000000"],["112525.02000000","0.00009000"],["112524.67000000","0.00000000"],["112523.04000000","0.00009000"],["112523.03000000","0.00000000"],["112522.82000000","0.31989000"],["112522.35000000","0.00000000"],["112522.25000000","0.00000000"],["112521.90000000","0.00177000"],["112521.88000000","0.21415000"],["112521.20000000","0.26677000"],["112520.93000000","0.00000000"],["112519.29000000","0.00000000"],["112519.15000000","0.00000000"],["112518.16000000","0.00000000"],["112518.02000000","0.00000000"],["112517.60000000","0.00000000"],["112517.51000000","0.00000000"],["112517.45000000","0.00000000"],["112515.54000000","0.00000000"],["112515.34000000","0.00009000"],["112514.77000000","0.24000000"],["112514.69000000","0.00000000"],["112513.95000000","0.00000000"],["112513.85000000","0.00000000"],["112512.94000000","0.19936000"],["112512.89000000","0.00000000"],["112512.32000000","0.00000000"],["112512.27000000","0.00000000"],["112510.41000000","0.00000000"],["112509.54000000","0.96545000"],["112509.11000000","0.00000000"],["112509.07000000","0.00000000"],["112508.37000000","0.31993000"],["112507.84000000","0.00000000"],["112507.14000000","0.00000000"],["112505.65000000","0.00000000"],["112505.64000000","0.24814000"],["112504.40000000","0.00000000"],["112502.91000000","0.00000000"],["112499.73000000","0.26660000"],["112499.44000000","0.00000000"],["112498.92000000","0.00000000"],["112497.84000000","0.00000000"],["112497.61000000","0.00000000"],["112497.44000000","0.00000000"],["112495.63000000","0.22343000"],["112494.82000000","0.26728000"],["112491.64000000","0.00000000"],["112491.59000000","0.06613000"],["112489.14000000","0.00000000"],["112485.56000000","0.02984000"],["112483.35000000","0.00000000"],["112481.85000000","0.00000000"],["112480.85000000","0.44452000"],["112480.00000000","0.04165000"],["112479.70000000","0.00010000"],["112479.64000000","0.02082000"],["112479.09000000","0.00000000"],["112478.39000000","0.00000000"],["112478.28000000","0.00089000"],["112477.01000000","0.00000000"],["112475.31000000","0.00000000"],["112475.28000000","0.44510000"],["112474.12000000","0.00000000"],["112473.89000000","0.00000000"],["112470.78000000","0.00000000"],["112470.00000000","0.00160000"],["112468.99000000","0.00000000"],["112468.38000000","0.00000000"],["112466.02000000","0.02359000"],["112463.92000000","0.00000000"],["112462.39000000","0.00000000"],["112461.75000000","0.00000000"],["112460.72000000","0.88907000"],["112460.66000000","0.00000000"],["112460.00000000","1.70861000"],["112458.98000000","0.00000000"],["112455.82000000","0.00000000"],["112452.77000000","0.29781000"],["112450.00000000","0.02160000"],["112447.42000000","0.00000000"],["112444.64000000","0.00000000"],["112440.31000000","0.00000000"],["112436.97000000","0.01391000"],["112432.44000000","0.00000000"],["112429.34000000","0.00000000"],["112346.28000000","0.06748000"],["112329.42000000","0.00000000"],["112300.24000000","0.00000000"],["112281.12000000","0.00000000"],["112244.38000000","0.02398000"],["112210.66000000","0.00000000"],["112207.27000000","0.00000000"],["112116.50000000","0.00007000"],["111693.29000000","0.00022000"],["111378.29000000","0.00000000"],["110875.10000000","0.00100000"],["110865.69000000","0.00000000"],["101298.00000000","0.00010000"],["90050.85000000","0.00022000"],["90043.20000000","0.00000000"],["90033.00000000","0.00000000"],["78793.35000000","0.00000000"],["78789.41000000","0.00000000"],["40519.44000000","0.00015000"],["33000.00000000","3.78938000"]],"a":[["112554.01000000","0.00000000"],["112554.02000000","0.00000000"],["112554.04000000","0.00000000"],["112554.05000000","0.00000000"],["112554.09000000","0.00000000"],["112554.10000000","0.00000000"],["112554.17000000","0.00000000"],["112554.18000000","0.00000000"],["112554.49000000","0.00000000"],["112554.50000000","0.00000000"],["112554.53000000","0.00000000"],["112554.54000000","0.00000000"],["112555.13000000","0.00000000"],["112555.29000000","0.00000000"],["112555.48000000","0.00000000"],["112555.75000000","0.00000000"],["112556.07000000","0.00000000"],["112556.24000000","0.00000000"],["112556.30000000","0.00000000"],["112556.37000000","0.00000000"],["112556.38000000","0.00000000"],["112556.82000000","0.00000000"],["112557.36000000","0.00000000"],["112557.88000000","0.00000000"],["112558.04000000","0.00000000"],["112558.49000000","0.00000000"],["112558.51000000","0.00000000"],["112558.68000000","0.00000000"],["112558.69000000","0.00000000"],["112558.70000000","0.00000000"],["112559.04000000","0.00000000"],["112559.20000000","0.00000000"],["112559.76000000","0.00000000"],["112560.00000000","0.00000000"],["112560.01000000","0.00000000"],["112560.05000000","0.00000000"],["112560.09000000","0.00000000"],["112560.58000000","0.00000000"],["112560.72000000","0.00000000"],["112560.76000000","0.00000000"],["112561.05000000","0.00000000"],["112561.06000000","0.00000000"],["112561.34000000","0.00000000"],["112562.13000000","0.00000000"],["112562.17000000","0.00000000"],["112562.18000000","0.00000000"],["112562.19000000","0.00000000"],["112562.20000000","0.00000000"],["112562.46000000","0.00000000"],["112562.77000000","0.00000000"],["112563.57000000","0.05760000"],["112563.58000000","0.00045000"],["112563.64000000","0.00000000"],["112563.65000000","0.00000000"],["112563.86000000","0.00010000"],["112564.09000000","0.00010000"],["112564.10000000","0.29337000"],["112565.00000000","0.00000000"],["112565.08000000","0.00000000"],["112565.09000000","0.00005000"],["112565.26000000","0.00721000"],["112565.27000000","0.00000000"],["112565.95000000","0.00000000"],["112565.96000000","0.00000000"],["112565.97000000","0.00000000"],["112565.99000000","0.00000000"],["112566.30000000","0.00000000"],["112566.86000000","0.00000000"],["112566.94000000","0.00010000"],["112566.95000000","0.30730000"],["112566.96000000","0.00000000"],["112567.27000000","0.00000000"],["112567.28000000","0.00000000"],["112567.29000000","0.00000000"],["112567.56000000","0.00000000"],["112567.72000000","0.00005000"],["112568.33000000","0.00000000"],["112568.35000000","0.00000000"],["112568.37000000","0.00000000"],["112568.59000000","0.00000000"],["112568.63000000","0.00000000"],["112568.64000000","0.00000000"],["112568.69000000","0.00000000"],["112568.87000000","0.00000000"],["112568.88000000","0.00000000"],["112569.30000000","0.04565000"],["112569.60000000","0.00005000"],["112569.66000000","0.00000000"],["112570.00000000","0.00120000"],["112570.03000000","0.00000000"],["112570.35000000","0.00000000"],["112570.67000000","0.00000000"],["112570.68000000","0.00000000"],["112570.69000000","0.00000000"],["112570.76000000","0.00000000"],["112570.77000000","0.00005000"],["112570.89000000","0.00151000"],["112570.90000000","0.00005000"],["112571.07000000","0.00000000"],["112571.65000000","0.00000000"],["112571.66000000","0.00000000"],["112572.00000000","0.00130000"],["112572.03000000","0.00000000"],["112572.12000000","0.00000000"],["112572.46000000","0.00010000"],["112572.47000000","0.00005000"],["112572.76000000","0.00000000"],["112573.18000000","0.00000000"],["112573.28000000","0.00000000"],["112573.65000000","0.00010000"],["112573.66000000","0.05243000"],["112573.70000000","0.00000000"],["112573.73000000","0.00000000"],["112574.00000000","0.00125000"],["112574.11000000","0.00250000"],["112574.58000000","0.00000000"],["112574.72000000","0.00007000"],["112574.83000000","0.00151000"],["112574.95000000","0.00000000"],["112575.26000000","0.00000000"],["112575.38000000","0.00000000"],["112575.39000000","0.00010000"],["112575.57000000","0.00010000"],["112575.58000000","0.08864000"],["112575.76000000","0.01811000"],["112575.77000000","0.00000000"],["112575.78000000","0.00000000"],["112575.89000000","0.00000000"],["112575.99000000","0.00000000"],["112576.00000000","0.00120000"],["112576.08000000","0.00005000"],["112576.49000000","0.00000000"],["112576.50000000","0.03010000"],["112576.53000000","0.00000000"],["112576.99000000","0.00000000"],["112577.16000000","0.00000000"],["112577.27000000","0.00000000"],["112577.30000000","0.00000000"],["112577.48000000","0.02005000"],["112577.65000000","0.00000000"],["112578.00000000","0.00125000"],["112578.04000000","0.00070000"],["112578.08000000","0.04000000"],["112578.19000000","0.46938000"],["112578.20000000","0.07840000"],["112578.28000000","0.24000000"],["112578.29000000","0.00000000"],["112578.30000000","0.00000000"],["112578.35000000","0.00000000"],["112578.60000000","0.00069000"],["112578.82000000","0.00368000"],["112578.83000000","0.00000000"],["112578.99000000","0.00000000"],["112579.19000000","0.00074000"],["112579.47000000","0.00000000"],["112579.48000000","0.00000000"],["112579.73000000","0.00000000"],["112580.00000000","0.00125000"],["112580.10000000","0.01099000"],["112580.11000000","0.00272000"],["112580.27000000","0.00000000"],["112580.45000000","0.00239000"],["112580.62000000","0.00000000"],["112580.63000000","0.00000000"],["112580.68000000","0.04946000"],["112580.83000000","0.00000000"],["112580.86000000","0.00000000"],["112580.91000000","0.00000000"],["112581.05000000","0.00000000"],["112581.39000000","0.00000000"],["112581.64000000","0.00261000"],["112581.68000000","0.00000000"],["112581.73000000","0.00000000"],["112581.89000000","0.00328000"],["112581.93000000","0.46938000"],["112581.94000000","0.31500000"],["112581.97000000","0.00000000"],["112582.20000000","0.00000000"],["112582.34000000","0.00000000"],["112582.53000000","0.00000000"],["112582.72000000","0.00000000"],["112583.35000000","0.00000000"],["112583.36000000","0.22719000"],["112583.41000000","0.00000000"],["112584.38000000","0.00000000"],["112584.53000000","0.00000000"],["112584.86000000","0.00000000"],["112584.89000000","0.00000000"],["112585.73000000","0.00000000"],["112585.81000000","0.29973000"],["112586.81000000","0.00444000"],["112586.82000000","0.00088000"],["112586.83000000","0.10640000"],["112586.92000000","0.00000000"],["112587.27000000","0.00261000"],["112587.47000000","0.00000000"],["112587.64000000","0.00250000"],["112587.76000000","0.04000000"],["112588.02000000","0.01256000"],["112588.69000000","0.00000000"],["112588.71000000","0.00000000"],["112588.72000000","0.96822000"],["112590.31000000","0.00000000"],["112590.32000000","0.00000000"],["112590.76000000","0.00000000"],["112591.47000000","0.00000000"],["112591.48000000","0.00000000"],["112591.56000000","0.00000000"],["112591.74000000","0.00000000"],["112592.15000000","0.00250000"],["112592.34000000","0.34113000"],["112593.40000000","0.00000000"],["112594.41000000","0.17706000"],["112594.42000000","0.15133000"],["112595.36000000","0.00000000"],["112595.84000000","0.00000000"],["112596.28000000","0.15146000"],["112596.66000000","0.00000000"],["112597.28000000","0.03778000"],["112597.34000000","0.00300000"],["112597.37000000","0.00000000"],["112597.58000000","0.31967000"],["112599.05000000","0.26728000"],["112599.39000000","0.26683000"],["112599.99000000","0.04441000"],["112600.49000000","0.03923000"],["112600.85000000","0.00000000"],["112601.17000000","0.00000000"],["112601.23000000","0.26660000"],["112601.75000000","0.15094000"],["112604.65000000","0.32053000"],["112605.22000000","0.35608000"],["112605.25000000","0.21098000"],["112605.26000000","0.42830000"],["112605.30000000","0.44510000"],["112606.44000000","0.01021000"],["112606.68000000","0.00000000"],["112607.03000000","0.18782000"],["112609.03000000","0.01599000"],["112610.00000000","0.00160000"],["112610.91000000","0.03460000"],["112611.01000000","0.31964000"],["112611.08000000","0.00000000"],["112611.34000000","0.00000000"],["112613.79000000","0.00000000"],["112613.86000000","0.00000000"],["112614.00000000","0.00165000"],["112614.22000000","0.00088000"],["112615.81000000","0.00006000"],["112616.13000000","0.03770000"],["112616.98000000","0.00000000"],["112617.04000000","0.23721000"],["112617.99000000","0.00000000"],["112619.22000000","0.00000000"],["112619.48000000","0.00005000"],["112620.00000000","0.19702000"],["112623.03000000","0.00000000"],["112623.05000000","0.15133000"],["112623.97000000","0.00000000"],["112625.98000000","0.00000000"],["112626.54000000","0.00000000"],["112627.00000000","0.00005000"],["112627.36000000","0.00006000"],["112627.37000000","0.00000000"],["112628.15000000","0.00000000"],["112629.04000000","0.00000000"],["112630.40000000","0.01687000"],["112630.95000000","0.00000000"],["112633.08000000","0.01391000"],["112633.93000000","0.00100000"],["112634.84000000","0.00623000"],["112635.98000000","0.00220000"],["112635.99000000","0.00000000"],["112636.15000000","0.00000000"],["112639.24000000","0.04091000"],["112639.99000000","0.00048000"],["112641.10000000","0.00000000"],["112641.11000000","0.00000000"],["112641.43000000","0.00000000"],["112641.44000000","0.00000000"],["112642.09000000","0.04430000"],["112643.39000000","0.00000000"],["112644.08000000","0.26728000"],["112644.42000000","0.26690000"],["112645.15000000","0.00221000"],["112645.85000000","0.00000000"],["112645.86000000","0.00000000"],["112646.26000000","0.26660000"],["112661.58000000","0.51258000"],["112669.71000000","0.00000000"],["112676.67000000","0.00005000"],["112680.61000000","0.00005000"],["112701.48000000","0.09675000"],["112707.52000000","0.00000000"],["112714.01000000","0.00000000"],["112731.59000000","0.00000000"],["112735.12000000","0.00000000"],["112737.20000000","0.00009000"],["112742.95000000","0.00000000"],["112743.76000000","0.01687000"],["112752.62000000","0.00019000"],["112790.20000000","0.00000000"],["112826.11000000","0.88619000"],["112870.75000000","0.01687000"],["112883.69000000","0.00000000"],["112937.30000000","0.00010000"],["112941.03000000","0.31500000"],["112942.92000000","0.00010000"],["112948.54000000","0.00010000"],["112954.16000000","0.00000000"],["112998.97000000","0.02498000"],["112999.34000000","0.02498000"],["113554.22000000","0.04000000"],["114242.33000000","0.00000000"],["114252.03000000","0.00100000"]]}
[2025-10-26T09:48:44.261Z] {"e":"depthUpdate","E":1761472123014,"s":"BTCUSDT","U":79058085614,"u":79058086600,"b":[["112563.57000000","1.57563000"],["112563.56000000","0.00000000"],["112563.54000000","0.00000000"],["112563.53000000","0.00000000"],["112563.10000000","0.00000000"],["112562.56000000","0.00000000"],["112562.55000000","0.00000000"],["112561.87000000","0.00000000"],["112561.36000000","0.00000000"],["112560.81000000","0.00000000"],["112560.80000000","0.00000000"],["112560.76000000","0.00000000"],["112560.75000000","0.00000000"],["112560.72000000","0.00000000"],["112560.71000000","0.00000000"],["112560.58000000","0.00000000"],["112559.94000000","0.00000000"],["112559.93000000","0.00000000"],["112559.92000000","0.00000000"],["112559.82000000","0.00000000"],["112559.43000000","0.00000000"],["112559.42000000","0.00000000"],["112559.27000000","0.00000000"],["112559.26000000","0.00000000"],["112559.19000000","0.00000000"],["112558.69000000","0.00000000"],["112558.68000000","0.00000000"],["112558.50000000","0.00005000"],["112558.30000000","0.00000000"],["112557.94000000","0.00000000"],["112557.93000000","0.00000000"],["112556.08000000","0.00000000"],["112556.07000000","0.00005000"],["112554.55000000","0.00000000"],["112554.54000000","0.00000000"],["112554.49000000","0.00000000"],["112554.39000000","0.00000000"],["112554.33000000","0.00000000"],["112554.32000000","0.00000000"],["112554.00000000","0.00120000"],["112552.89000000","0.00000000"],["112552.87000000","0.00000000"],["112552.31000000","0.25994000"],["112552.30000000","0.08948000"],["112551.94000000","0.00000000"],["112551.75000000","0.00000000"],["112551.58000000","0.00010000"],["112551.57000000","0.00010000"],["112551.56000000","0.00000000"],["112551.37000000","0.20466000"],["112551.19000000","0.00201000"],["112550.94000000","0.00000000"],["112550.86000000","0.29316000"],["112549.51000000","0.00010000"],["112549.50000000","0.00355000"],["112549.31000000","0.00000000"],["112549.06000000","0.00010000"],["112549.05000000","0.58066000"],["112549.04000000","0.00010000"],["112549.03000000","0.46948000"],["112548.94000000","0.00005000"],["112548.93000000","0.12033000"],["112548.90000000","0.00710000"],["112548.38000000","0.03790000"],["112548.37000000","0.22265000"],["112548.23000000","0.00005000"],["112547.81000000","0.00005000"],["112547.76000000","0.04570000"],["112547.05000000","0.00255000"],["112546.75000000","0.00000000"],["112546.74000000","0.00000000"],["112546.68000000","0.00150000"],["112546.39000000","0.00000000"],["112546.01000000","0.00005000"],["112546.00000000","0.00000000"],["112545.27000000","0.04710000"],["112544.76000000","0.00000000"],["112544.65000000","0.04302000"],["112543.98000000","0.00000000"],["112543.97000000","0.00000000"],["112543.25000000","0.40931000"],["112543.02000000","0.00005000"],["112542.55000000","0.00444000"],["112541.67000000","0.49348000"],["112541.22000000","0.00000000"],["112541.21000000","0.03591000"],["112540.83000000","0.00000000"],["112540.56000000","0.05328000"],["112540.19000000","0.04500000"],["112540.00000000","0.00120000"],["112539.97000000","0.00000000"],["112539.37000000","0.00000000"],["112539.27000000","0.00000000"],["112539.25000000","0.03900000"],["112539.12000000","0.04200000"],["112539.08000000","0.04500000"],["112538.31000000","0.00000000"],["112538.18000000","0.03600000"],["112537.79000000","0.00000000"],["112537.75000000","0.00006000"],["112537.09000000","0.01800000"],["112536.83000000","0.03000000"],["112536.76000000","0.00200000"],["112535.83000000","0.03600000"],["112535.33000000","0.03900000"],["112534.88000000","0.00000000"],["112534.80000000","0.35533000"],["112534.68000000","0.03000000"],["112534.50000000","0.04000000"],["112533.65000000","0.03000000"],["112533.56000000","0.03000000"],["112533.52000000","0.00250000"],["112533.37000000","0.03000000"],["112533.00000000","0.00000000"],["112532.84000000","0.00888000"],["112532.54000000","0.26660000"],["112531.50000000","0.44452000"],["112531.49000000","0.26683000"],["112531.15000000","0.26728000"],["112529.01000000","0.00250000"],["112525.76000000","0.00000000"],["112524.81000000","0.00065000"],["112524.50000000","0.00250000"],["112524.40000000","0.00000000"],["112524.18000000","0.00088000"],["112523.02000000","0.00000000"],["112522.82000000","0.00000000"],["112522.11000000","0.00000000"],["112522.04000000","0.00000000"],["112522.03000000","0.00000000"],["112521.95000000","0.00000000"],["112521.90000000","0.21592000"],["112521.88000000","0.00000000"],["112520.79000000","0.00000000"],["112519.75000000","0.00000000"],["112518.59000000","0.00000000"],["112517.40000000","0.00000000"],["112517.04000000","0.00000000"],["112516.86000000","0.31990000"],["112516.82000000","0.00000000"],["112516.31000000","0.00000000"],["112516.09000000","0.00000000"],["112508.37000000","0.00000000"],["112505.88000000","0.00000000"],["112502.63000000","0.31994000"],["112500.93000000","0.00000000"],["112496.17000000","0.31996000"],["112490.88000000","0.26683000"],["112485.56000000","0.00000000"],["112472.09000000","0.26677000"],["112469.85000000","0.00000000"],["112468.12000000","0.02984000"],["112466.62000000","0.35608000"],["112466.02000000","0.00000000"],["112465.41000000","0.00000000"],["112454.20000000","0.00444000"],["112451.19000000","0.02359000"],["112360.00000000","0.00040000"],["112329.42000000","0.06748000"],["112309.76000000","4.86684000"],["112291.98000000","0.01391000"],["111487.83000000","0.00250000"],["110875.11000000","0.00100000"],["110875.10000000","0.00000000"],["101307.00000000","0.00000000"],["101306.00000000","0.00251000"],["101298.00000000","0.00000000"],["90050.86000000","0.00022000"],["90050.85000000","0.00000000"],["60000.00000000","57.64892000"],["42000.00000000","1.40312000"],["40522.89000000","0.00015000"]],"a":[["112563.57000000","0.00000000"],["112563.58000000","3.79854000"],["112563.59000000","0.00070000"],["112563.60000000","0.05030000"],["112563.64000000","0.00010000"],["112563.65000000","0.05020000"],["112563.66000000","0.00010000"],["112563.70000000","0.06748000"],["112563.86000000","0.00000000"],["112564.10000000","0.29322000"],["112565.09000000","0.00255000"],["112565.26000000","0.00721000"],["112565.36000000","0.00000000"],["112565.43000000","0.00000000"],["112565.44000000","0.00005000"],["112565.48000000","0.00010000"],["112565.49000000","0.02676000"],["112566.36000000","0.00005000"],["112566.94000000","0.00000000"],["112566.95000000","0.00000000"],["112567.15000000","0.00005000"],["112567.16000000","0.04946000"],["112567.49000000","0.00005000"],["112567.72000000","0.00000000"],["112568.17000000","0.00000000"],["112568.18000000","0.00000000"],["112568.73000000","0.00716000"],["112569.20000000","0.08859000"],["112569.29000000","0.00000000"],["112569.30000000","0.04570000"],["112569.50000000","0.06753000"],["112569.60000000","0.00255000"],["112570.00000000","0.00125000"],["112570.53000000","0.00200000"],["112571.75000000","0.00000000"],["112572.00000000","0.00140000"],["112572.03000000","0.10640000"],["112572.46000000","0.00000000"],["112572.47000000","0.00000000"],["112573.11000000","0.00005000"],["112573.50000000","0.06100000"],["112573.65000000","0.00000000"],["112573.66000000","0.05238000"],["112574.00000000","0.00130000"],["112575.39000000","0.00005000"],["112575.57000000","0.00000000"],["112575.58000000","0.00005000"],["112576.00000000","0.00120000"],["112576.08000000","0.00000000"],["112576.29000000","0.00000000"],["112576.35000000","0.04000000"],["112576.50000000","0.03005000"],["112576.52000000","0.00161000"],["112577.48000000","0.02000000"],["112578.00000000","0.00120000"],["112578.04000000","0.00000000"],["112578.07000000","1.70701000"],["112578.08000000","0.04000000"],["112578.27000000","0.00444000"],["112578.60000000","0.00000000"],["112578.82000000","0.00300000"],["112579.19000000","0.00000000"],["112579.54000000","0.06748000"],["112580.68000000","0.00000000"],["112581.23000000","0.15146000"],["112581.31000000","0.00000000"],["112581.89000000","0.00000000"],["112584.66000000","0.00000000"],["112585.00000000","0.06100000"],["112585.43000000","0.00000000"],["112586.81000000","0.00000000"],["112586.83000000","0.00000000"],["112587.32000000","0.00000000"],["112587.33000000","0.26728000"],["112587.64000000","0.00000000"],["112587.69000000","0.26683000"],["112587.76000000","0.00000000"],["112587.84000000","0.03000000"],["112588.76000000","0.03000000"],["112588.96000000","0.03000000"],["112588.97000000","0.03000000"],["112589.08000000","0.04803000"],["112589.88000000","0.30660000"],["112589.89000000","0.03000000"],["112590.69000000","0.00000000"],["112590.96000000","0.31969000"],["112591.22000000","0.03300000"],["112591.63000000","0.00000000"],["112592.02000000","0.03000000"],["112592.15000000","0.00000000"],["112592.70000000","0.03000000"],["112593.13000000","0.03600000"],["112593.64000000","0.00000000"],["112594.28000000","0.05400000"],["112594.38000000","0.05400000"],["112595.50000000","0.00000000"],["112596.24000000","0.34613000"],["112596.28000000","0.00000000"],["112596.76000000","0.00000000"],["112597.58000000","0.58644000"],["112599.09000000","0.00000000"],["112599.99000000","0.00000000"],["112600.49000000","0.00000000"],["112601.23000000","0.00000000"],["112601.72000000","0.00000000"],["112602.99000000","0.00000000"],["112605.57000000","0.31965000"],["112605.62000000","0.00000000"],["112605.71000000","0.00000000"],["112607.10000000","0.00000000"],["112608.01000000","0.00000000"],["112611.01000000","0.00000000"],["112611.63000000","0.00000000"],["112613.73000000","0.00000000"],["112614.25000000","0.00000000"],["112620.30000000","0.04096000"],["112632.57000000","0.00000000"],["112633.08000000","0.00000000"],["112634.89000000","0.26660000"],["112639.24000000","0.00000000"],["112639.99000000","0.00000000"],["112642.61000000","0.00000000"],["112643.21000000","0.26677000"],["112644.08000000","0.00000000"],["112644.42000000","0.00007000"],["112646.26000000","0.00000000"],["112655.52000000","0.00000000"],["112656.47000000","0.03400000"],["112662.11000000","0.03000000"],["112667.27000000","0.03000000"],["112670.66000000","0.00000000"],["112672.73000000","0.00005000"],["112677.31000000","0.03000000"],["112677.73000000","0.03000000"],["112677.75000000","0.05400000"],["112678.60000000","0.03300000"],["112680.23000000","0.03000000"],["112682.58000000","0.00000000"],["112685.58000000","0.03000000"],["112686.48000000","0.00000000"],["112688.31000000","0.00000000"],["112689.28000000","0.00000000"],["112693.00000000","0.00005000"],["112700.00000000","0.27842000"],["112716.37000000","0.47523000"],["112719.48000000","0.13064000"],["112752.62000000","0.00000000"],["112805.91000000","4.70393000"],["113000.00000000","27.30672000"],["113011.88000000","0.02498000"],["113012.31000000","0.02498000"],["113012.72000000","0.02498000"],["113558.09000000","0.00246000"],["114252.03000000","0.00000000"],["114252.04000000","0.00100000"]]}
[2025-10-26T09:48:45.157Z] {"e":"depthUpdate","E":1761472124014,"s":"BTCUSDT","U":79058086601,"u":79058087283,"b":[["112563.57000000","1.79940000"],["112558.50000000","0.00000000"],["112557.94000000","0.00000000"],["112557.93000000","0.00000000"],["112556.65000000","0.00005000"],["112556.35000000","0.00000000"],["112554.25000000","0.00000000"],["112554.24000000","0.00000000"],["112554.01000000","0.00014000"],["112554.00000000","0.00120000"],["112553.82000000","0.00000000"],["112552.91000000","0.00000000"],["112552.90000000","0.00000000"],["112552.89000000","0.00000000"],["112552.51000000","0.00000000"],["112552.50000000","0.00000000"],["112552.33000000","0.00000000"],["112552.32000000","0.00000000"],["112552.31000000","0.00010000"],["112552.30000000","0.08948000"],["112552.02000000","0.00005000"],["112551.75000000","0.00715000"],["112551.61000000","0.00000000"],["112551.59000000","0.00010000"],["112551.58000000","0.20176000"],["112551.57000000","0.17776000"],["112551.56000000","0.00250000"],["112551.38000000","0.00000000"],["112551.37000000","0.00000000"],["112551.24000000","0.00000000"],["112551.19000000","0.00206000"],["112551.16000000","0.00010000"],["112551.15000000","0.20476000"],["112550.87000000","0.00000000"],["112550.86000000","0.00010000"],["112550.85000000","0.04715000"],["112550.64000000","0.29321000"],["112549.50000000","0.00355000"],["112549.08000000","0.00000000"],["112549.07000000","0.37694000"],["112549.06000000","0.46943000"],["112549.05000000","0.00000000"],["112549.04000000","0.00000000"],["112549.03000000","0.00000000"],["112548.94000000","0.00000000"],["112548.93000000","0.12028000"],["112548.90000000","0.00000000"],["112548.38000000","0.03780000"],["112548.37000000","0.00005000"],["112548.23000000","0.00000000"],["112547.76000000","0.00000000"],["112547.25000000","0.00533000"],["112546.68000000","0.00145000"],["112546.01000000","0.00000000"],["112545.27000000","0.00000000"],["112545.26000000","0.15146000"],["112545.24000000","0.00000000"],["112545.15000000","0.46938000"],["112544.65000000","0.00005000"],["112544.44000000","0.00401000"],["112544.29000000","0.00000000"],["112543.26000000","0.00444000"],["112543.25000000","0.40931000"],["112542.75000000","0.00711000"],["112542.74000000","0.00300000"],["112542.55000000","0.00000000"],["112542.54000000","0.00250000"],["112541.68000000","0.00000000"],["112541.05000000","0.26820000"],["112540.56000000","0.00000000"],["112539.88000000","0.05339000"],["112538.55000000","0.04302000"],["112538.03000000","0.00250000"],["112537.97000000","1.09310000"],["112537.09000000","0.00000000"],["112536.84000000","0.29977000"],["112536.76000000","0.00000000"],["112536.00000000","0.00120000"],["112535.92000000","0.35528000"],["112535.62000000","0.01773000"],["112534.80000000","0.00005000"],["112534.79000000","0.00000000"],["112534.50000000","0.00000000"],["112532.84000000","0.00000000"],["112531.30000000","0.04000000"],["112530.74000000","0.00200000"],["112529.86000000","0.31500000"],["112529.76000000","0.00000000"],["112529.01000000","0.00000000"],["112526.73000000","0.00888000"],["112525.02000000","0.00000000"],["112524.50000000","0.00000000"],["112523.79000000","0.00000000"],["112523.75000000","0.00009000"],["112523.65000000","0.00009000"],["112523.04000000","0.00000000"],["112518.92000000","0.00009000"],["112517.18000000","0.31990000"],["112516.94000000","0.00009000"],["112516.86000000","0.00000000"],["112516.80000000","0.44510000"],["112515.34000000","0.00000000"],["112515.05000000","0.00000000"],["112513.00000000","0.00000000"],["112509.54000000","0.00005000"],["112509.24000000","0.00009000"],["112506.28000000","0.05700000"],["112503.10000000","0.00000000"],["112502.65000000","0.34113000"],["112501.74000000","0.03900000"],["112501.48000000","0.31995000"],["112499.43000000","0.03000000"],["112496.81000000","0.00010000"],["112496.17000000","0.00000000"],["112487.38000000","0.00000000"],["112484.80000000","0.00010000"],["112484.79000000","0.00383000"],["112480.00000000","0.00165000"],["112479.60000000","0.00000000"],["112478.28000000","0.00000000"],["112477.44000000","0.00000000"],["112472.18000000","0.00089000"],["112470.25000000","0.04500000"],["112465.77000000","0.03000000"],["112451.19000000","0.00000000"],["112448.16000000","0.00449000"],["112442.97000000","0.00000000"],["112437.82000000","0.00000000"],["112429.50000000","0.00221000"],["112407.01000000","0.00000000"],["112317.18000000","0.00088000"],["112294.84000000","0.00000000"],["111487.83000000","0.00000000"],["111260.00000000","0.11147000"],["110875.11000000","0.00100000"],["103545.80000000","0.00010000"],["101307.21000000","0.00019000"],["101307.00000000","0.00000000"],["101306.00000000","0.00251000"],["90050.86000000","0.00022000"],["60000.00000000","57.64882000"],["40522.89000000","0.00060000"]],"a":[["112563.58000000","5.23035000"],["112563.59000000","0.00055000"],["112563.65000000","0.05020000"],["112563.70000000","0.00000000"],["112564.10000000","0.29322000"],["112564.34000000","0.04076000"],["112565.09000000","0.00255000"],["112565.24000000","0.00005000"],["112565.49000000","0.02676000"],["112566.06000000","0.00005000"],["112566.07000000","0.06005000"],["112567.15000000","0.00000000"],["112567.16000000","0.00000000"],["112567.49000000","0.00000000"],["112567.72000000","0.00200000"],["112568.73000000","0.00716000"],["112569.20000000","0.08859000"],["112569.29000000","0.00000000"],["112570.00000000","0.00125000"],["112570.33000000","0.04946000"],["112570.53000000","0.00000000"],["112572.00000000","0.00135000"],["112572.03000000","0.00000000"],["112573.11000000","0.00000000"],["112574.75000000","0.46938000"],["112574.83000000","0.00151000"],["112574.85000000","0.00000000"],["112575.39000000","0.00000000"],["112575.58000000","0.00005000"],["112575.76000000","0.01816000"],["112576.00000000","0.00125000"],["112576.35000000","0.04000000"],["112576.50000000","0.03005000"],["112576.52000000","0.00161000"],["112577.16000000","0.00000000"],["112577.32000000","0.00043000"],["112577.37000000","0.00000000"],["112577.48000000","0.00000000"],["112578.08000000","0.00000000"],["112580.47000000","0.00000000"],["112581.55000000","0.00005000"],["112582.38000000","0.03000000"],["112582.68000000","0.02998000"],["112583.35000000","0.00044000"],["112583.46000000","0.03498000"],["112583.47000000","0.03000000"],["112585.45000000","0.31971000"],["112585.94000000","0.03300000"],["112586.00000000","0.04966000"],["112587.64000000","0.00000000"],["112588.72000000","0.00000000"],["112589.07000000","0.00000000"],["112589.08000000","0.00000000"],["112589.89000000","0.00000000"],["112590.96000000","0.00000000"],["112591.22000000","0.00000000"],["112591.51000000","0.31969000"],["112592.15000000","0.00000000"],["112599.03000000","0.00000000"],["112599.05000000","0.00000000"],["112599.39000000","0.00000000"],["112599.57000000","0.00000000"],["112605.57000000","0.00000000"],["112611.47000000","0.00000000"],["112611.90000000","0.04091000"],["112620.30000000","0.00005000"],["112626.89000000","0.26728000"],["112627.25000000","0.26683000"],["112629.20000000","0.26660000"],["112631.63000000","0.00000000"],["112634.89000000","0.00000000"],["112635.12000000","0.00000000"],["112635.49000000","0.00000000"],["112636.21000000","0.04270000"],["112639.98000000","0.00000000"],["112639.99000000","0.00048000"],["112642.09000000","0.00000000"],["112642.43000000","0.44452000"],["112643.21000000","0.00000000"],["112644.31000000","0.00000000"],["112644.33000000","0.00000000"],["112646.07000000","0.00000000"],["112649.33000000","0.00000000"],["112650.54000000","0.00000000"],["112650.55000000","0.00000000"],["112651.33000000","0.00100000"],["112651.34000000","0.00100000"],["112661.58000000","0.06748000"],["112670.66000000","0.03600000"],["112737.20000000","0.02676000"],["112752.61000000","0.00000000"],["112752.62000000","0.00019000"],["112763.83000000","0.01391000"],["112785.67000000","0.00000000"],["112967.84000000","0.00005000"],["113012.19000000","0.02498000"],["113554.22000000","0.00000000"],["113558.09000000","0.00000000"],["114252.04000000","0.00100000"]]}
[2025-10-27T18:47:35.857Z] Snapshot loaded successfully.
[2025-10-27T18:47:42.252Z] WebSocket connected successfully.
[2025-10-27T18:47:43.159Z] {"e":"depthUpdate","E":1761590863014,"s":"BTCUSDT","U":79129596532,"u":79129596714,"b":[["115421.98000000","3.34381000"],["115421.74000000","0.00000000"],["115421.48000000","0.00000000"],["115414.84000000","0.24943000"],["115406.98000000","0.04321000"],["115405.60000000","0.00433000"],["115404.81000000","0.03000000"],["115403.69000000","0.03000000"],["115403.59000000","0.03000000"],["115403.48000000","0.00000000"],["115399.62000000","0.15818000"],["115399.61000000","1.30081000"],["115399.53000000","0.00866000"],["115397.76000000","0.03000000"],["115393.23000000","0.00000000"],["115392.11000000","0.00000000"],["115392.04000000","0.00000000"],["115388.02000000","0.00000000"],["115386.14000000","0.00000000"],["115380.43000000","0.00000000"],["115348.01000000","0.00008000"],["115336.72000000","0.00008000"],["115330.20000000","0.00000000"],["115330.01000000","0.00000000"],["115329.03000000","0.00433000"],["115320.19000000","0.00000000"],["115314.23000000","0.00000000"],["115300.87000000","0.00216000"],["115295.68000000","0.00000000"],["115293.15000000","0.00000000"],["115288.27000000","0.00000000"],["115288.21000000","0.09389000"],["115288.11000000","0.00000000"],["115288.10000000","0.00000000"],["115288.09000000","0.00000000"],["115288.08000000","0.00000000"],["115287.89000000","0.00000000"],["115185.10000000","0.00086000"],["115170.49000000","0.00073000"],["115156.09000000","0.00000000"],["115156.08000000","0.00000000"],["115088.39000000","0.00025000"],["113690.65000000","0.00100000"],["103878.00000000","0.00030000"],["92337.59000000","0.00021000"]],"a":[["115421.99000000","5.12146000"],["115422.00000000","0.00220000"],["115422.04000000","0.03978000"],["115422.56000000","0.04066000"],["115424.00000000","0.00135000"],["115424.34000000","0.00005000"],["115424.35000000","0.04412000"],["115424.38000000","0.00000000"],["115424.39000000","0.00000000"],["115425.07000000","0.28594000"],["115426.38000000","0.00156000"],["115429.00000000","0.06100000"],["115430.70000000","0.00250000"],["115434.81000000","0.00433000"],["115436.99000000","0.05898000"],["115440.60000000","0.16996000"],["115443.56000000","0.00000000"],["115448.60000000","0.00000000"],["115451.01000000","0.00583000"],["115451.07000000","0.00000000"],["115456.62000000","0.86947000"],["115461.32000000","0.00000000"],["115464.37000000","0.33265000"],["115464.38000000","0.00000000"],["115471.99000000","0.00000000"],["115472.91000000","0.00000000"],["115475.64000000","0.00000000"],["115479.94000000","0.00271000"],["115500.54000000","0.00000000"],["115500.55000000","0.00000000"],["115500.69000000","0.00000000"],["115501.07000000","0.01356000"],["115507.91000000","0.00100000"],["115507.92000000","0.00100000"],["115508.92000000","0.00000000"],["115508.93000000","0.00000000"],["115518.92000000","0.02500000"],["115519.92000000","0.00000000"],["115587.99000000","0.00000000"],["115595.22000000","0.00105000"],["115599.20000000","0.00000000"],["117153.32000000","0.00100000"]]}
[2025-10-27T18:47:44.147Z] {"e":"depthUpdate","E":1761590864014,"s":"BTCUSDT","U":79129596715,"u":79129596845,"b":[["115421.98000000","3.26708000"],["115421.97000000","0.00065000"],["115421.67000000","0.00010000"],["115421.66000000","0.03867000"],["115419.10000000","0.00196000"],["115418.27000000","0.17336000"],["115414.85000000","0.09084000"],["115414.81000000","0.00076000"],["115410.80000000","0.04404000"],["115374.70000000","0.03000000"],["115314.22000000","0.03000000"],["115312.98000000","0.00000000"],["115295.68000000","0.03000000"],["115288.21000000","0.00000000"],["115287.79000000","0.00000000"],["113690.65000000","0.00100000"],["111929.44000000","0.00000000"],["111925.75000000","0.02179000"],["106200.04000000","0.00010000"],["103879.00000000","0.00014000"],["103878.00000000","0.00030000"],["92338.00000000","0.00000000"],["92337.59000000","0.00021000"],["41551.91000000","0.00060000"]],"a":[["115421.99000000","5.11863000"],["115422.00000000","0.00220000"],["115422.04000000","0.03978000"],["115433.60000000","0.06748000"],["115434.84000000","0.00000000"],["115442.21000000","0.00866000"],["115450.90000000","0.00583000"],["115451.01000000","0.00000000"],["115456.62000000","0.00308000"],["115479.93000000","0.00048000"],["115479.94000000","0.00223000"],["115500.51000000","0.00000000"],["115500.58000000","0.00000000"],["115500.62000000","0.00000000"],["115500.64000000","0.43307000"],["115501.00000000","1.03848000"],["115501.13000000","0.43332000"],["115502.40000000","0.34651000"],["115507.91000000","0.00000000"],["115507.93000000","0.00100000"],["115511.35000000","0.03400000"],["115511.38000000","0.00000000"],["115511.39000000","0.00000000"],["115512.38000000","0.00000000"],["115595.21000000","0.00019000"],["115595.22000000","0.00086000"],["115637.35000000","0.01356000"],["115686.99000000","0.00000000"],["115813.33000000","0.37961000"],["117153.32000000","0.00100000"]]}
[2025-10-27T18:47:45.168Z] {"e":"depthUpdate","E":1761590865014,"s":"BTCUSDT","U":79129596846,"u":79129597050,"b":[["115421.98000000","3.24963000"],["115421.97000000","0.00060000"],["115421.67000000","0.00000000"],["115421.66000000","0.00000000"],["115421.48000000","0.00000000"],["115419.10000000","0.00211000"],["115418.27000000","0.17341000"],["115414.85000000","0.09094000"],["115406.99000000","0.00433000"],["115405.60000000","0.00000000"],["115399.53000000","0.00000000"],["115384.15000000","0.96347000"],["115384.14000000","0.00000000"],["115375.93000000","0.03000000"],["115374.80000000","0.03000000"],["115353.05000000","0.00866000"],["115330.20000000","0.12729000"],["115316.94000000","0.00000000"],["115314.22000000","0.00000000"],["115288.52000000","0.00000000"],["115288.50000000","0.00000000"],["115288.34000000","0.00000000"],["115288.33000000","0.00000000"],["115288.32000000","0.00000000"],["115229.49000000","0.01356000"],["115166.28000000","4.69386000"],["115166.25000000","0.00000000"],["115135.65000000","0.00000000"],["114667.89000000","0.00000000"],["114513.25000000","0.00000000"],["113690.65000000","0.00100000"],["111661.59000000","0.00000000"],["109035.78000000","0.00000000"],["106390.58000000","0.00000000"],["106200.04000000","0.00000000"],["103878.00000000","0.00030000"],["92337.59000000","0.00021000"],["42000.00000000","1.36531000"]],"a":[["115421.99000000","4.77014000"],["115422.00000000","0.00220000"],["115422.04000000","0.03978000"],["115422.56000000","0.04066000"],["115424.00000000","0.00135000"],["115424.03000000","0.00010000"],["115424.04000000","0.04412000"],["115424.34000000","0.00000000"],["115424.35000000","0.00000000"],["115425.07000000","0.28594000"],["115426.38000000","0.00156000"],["115429.00000000","0.06100000"],["115430.70000000","0.00250000"],["115434.81000000","0.00000000"],["115435.31000000","0.00433000"],["115442.21000000","0.00000000"],["115444.49000000","0.13537000"],["115445.32000000","0.34651000"],["115446.31000000","0.00000000"],["115450.24000000","0.00583000"],["115450.90000000","0.00000000"],["115456.62000000","0.43615000"],["115464.37000000","0.33265000"],["115500.51000000","0.00000000"],["115500.54000000","0.00000000"],["115500.58000000","0.00000000"],["115500.64000000","0.00000000"],["115501.07000000","0.00000000"],["115501.15000000","0.00000000"],["115507.92000000","0.00000000"],["115507.93000000","0.00000000"],["115508.92000000","0.00100000"],["115508.93000000","0.00100000"],["115511.35000000","0.00000000"],["115512.35000000","0.03400000"],["115518.38000000","0.00000000"],["115518.92000000","0.00000000"],["115519.90000000","0.02500000"],["115564.82000000","0.00000000"],["115637.35000000","0.00000000"],["115664.31000000","0.13537000"],["115665.01000000","0.00000000"],["115745.16000000","0.00000000"],["115813.33000000","0.37961000"],["115952.08000000","0.00000000"],["117153.32000000","0.00100000"],["121072.34000000","0.00000000"],["123512.69000000","0.00000000"],["124147.27000000","0.00000000"]]}
[2025-10-27T18:47:46.149Z] {"e":"depthUpdate","E":1761590866014,"s":"BTCUSDT","U":79129597051,"u":79129597454,"b":[["115421.98000000","3.18044000"],["115421.97000000","0.00065000"],["115421.92000000","0.00000000"],["115420.83000000","0.00115000"],["115420.34000000","0.00005000"],["115419.10000000","0.00000000"],["115418.27000000","0.17341000"],["115418.24000000","0.00010000"],["115418.23000000","0.03825000"],["115417.77000000","0.17331000"],["115417.37000000","0.00347000"],["115415.06000000","0.00525000"],["115414.91000000","0.00000000"],["115414.89000000","0.09860000"],["115414.88000000","0.24943000"],["115414.86000000","0.00000000"],["115414.85000000","0.00000000"],["115414.84000000","0.00000000"],["115414.83000000","0.00372000"],["115412.17000000","0.00381000"],["115412.13000000","0.00000000"],["115412.12000000","0.00000000"],["115411.95000000","0.00000000"],["115410.80000000","0.04409000"],["115410.44000000","0.17562000"],["115408.48000000","0.04628000"],["115407.91000000","0.00000000"],["115406.99000000","0.00000000"],["115405.60000000","0.00433000"],["115400.02000000","0.03000000"],["115370.71000000","0.03000000"],["115353.05000000","0.00000000"],["115309.02000000","0.00000000"],["115289.05000000","0.00000000"],["115288.97000000","0.00000000"],["115288.81000000","0.00000000"],["115288.62000000","0.00000000"],["115288.60000000","0.00000000"],["115288.54000000","0.00000000"],["115288.53000000","0.00000000"],["115229.49000000","0.00000000"],["115190.25000000","0.01356000"],["115182.96000000","0.00009000"],["113690.65000000","0.00100000"],["103879.00000000","0.00014000"],["103878.00000000","0.00030000"],["92337.59000000","0.00021000"]],"a":[["115421.99000000","5.11657000"],["115422.00000000","0.00220000"],["115422.03000000","0.00000000"],["115422.04000000","0.00000000"],["115422.35000000","0.00010000"],["115422.36000000","0.03857000"],["115422.56000000","0.04071000"],["115422.83000000","0.00010000"],["115422.84000000","0.13613000"],["115422.85000000","0.28604000"],["115423.14000000","0.00100000"],["115423.77000000","0.00005000"],["115423.89000000","0.00010000"],["115423.90000000","0.04407000"],["115424.00000000","0.00125000"],["115424.03000000","0.00000000"],["115424.04000000","0.00000000"],["115424.87000000","0.00191000"],["115425.05000000","0.00000000"],["115425.06000000","0.00000000"],["115425.07000000","0.00000000"],["115426.38000000","0.00156000"],["115426.39000000","0.08668000"],["115426.60000000","0.00347000"],["115428.91000000","0.00525000"],["115428.98000000","0.00000000"],["115429.00000000","0.06100000"],["115429.50000000","1.27877000"],["115431.80000000","0.00381000"],["115433.53000000","0.00693000"],["115435.11000000","0.00000000"],["115435.16000000","0.02600000"],["115435.99000000","0.00000000"],["115439.45000000","0.00000000"],["115440.61000000","1.56142000"],["115445.78000000","0.43332000"],["115446.96000000","0.31182000"],["115456.62000000","0.43615000"],["115464.32000000","0.33265000"],["115464.37000000","0.00000000"],["115467.17000000","0.00000000"],["115500.50000000","0.00000000"],["115501.13000000","0.00000000"],["115502.40000000","0.00000000"],["115508.92000000","0.00000000"],["115508.93000000","0.00000000"],["115509.20000000","0.03400000"],["115509.21000000","0.00100000"],["115512.35000000","0.00000000"],["115513.30000000","0.03400000"],["115519.90000000","0.00000000"],["115520.85000000","0.02500000"],["117153.32000000","0.00100000"]]}
[2025-10-27T18:47:47.210Z] {"e":"depthUpdate","E":1761590867014,"s":"BTCUSDT","U":79129597455,"u":79129597628,"b":[["115421.98000000","3.17725000"],["115421.97000000","0.00065000"],["115421.28000000","0.03948000"],["115418.27000000","0.17341000"],["115418.24000000","0.00000000"],["115418.23000000","0.00000000"],["115418.19000000","0.00010000"],["115418.18000000","0.00010000"],["115417.77000000","0.17336000"],["115414.90000000","0.00010000"],["115414.89000000","0.09855000"],["115414.88000000","0.24943000"],["115412.31000000","0.04628000"],["115410.44000000","0.17562000"],["115408.48000000","0.00000000"],["115300.00000000","0.50176000"],["115166.28000000","0.00000000"],["113690.65000000","0.00100000"],["111929.44000000","0.02179000"],["111925.75000000","0.00000000"],["109032.28000000","0.00068000"],["107000.00000000","22.59650000"],["106386.48000000","0.00070000"],["103878.00000000","0.00030000"],["92338.00000000","0.00000000"],["92337.59000000","0.00021000"],["42000.00000000","1.36431000"],["33000.00000000","3.79030000"]],"a":[["115421.99000000","5.37763000"],["115422.00000000","0.00220000"],["115422.36000000","0.03857000"],["115422.56000000","0.04071000"],["115422.84000000","0.13618000"],["115422.85000000","0.28604000"],["115423.14000000","0.00095000"],["115423.76000000","0.00005000"],["115423.77000000","0.00010000"],["115423.89000000","0.00000000"],["115423.90000000","0.00000000"],["115426.08000000","0.00260000"],["115426.14000000","0.04945000"],["115426.38000000","0.00156000"],["115428.67000000","0.00310000"],["115428.91000000","0.00525000"],["115428.99000000","0.00000000"],["115429.00000000","0.06100000"],["115432.27000000","0.00197000"],["115435.64000000","0.01725000"],["115456.28000000","0.31180000"],["115456.62000000","0.43615000"],["115464.32000000","0.00000000"],["115464.34000000","0.00000000"],["115500.34000000","0.25975000"],["115500.41000000","0.00000000"],["115502.45000000","0.00000000"],["115664.31000000","0.00000000"],["115813.33000000","0.37961000"],["117153.32000000","0.00100000"],["121076.74000000","0.00061000"],["123515.53000000","0.00060000"],["124150.07000000","0.00060000"]]}
[2025-10-27T18:47:48.234Z] {"e":"depthUpdate","E":1761590868014,"s":"BTCUSDT","U":79129597629,"u":79129598034,"b":[["115421.98000000","2.53527000"],["115421.97000000","0.00050000"],["115421.66000000","0.00000000"],["115421.65000000","0.00000000"],["115421.64000000","0.00000000"],["115421.29000000","0.00000000"],["115421.28000000","0.00000000"],["115420.83000000","0.00115000"],["115418.29000000","0.00000000"],["115418.28000000","0.00000000"],["115418.27000000","0.00000000"],["115418.19000000","0.00000000"],["115418.18000000","0.00000000"],["115417.78000000","0.00000000"],["115417.77000000","0.00000000"],["115417.65000000","0.00000000"],["115417.40000000","0.00000000"],["115417.39000000","0.00000000"],["115417.38000000","0.00000000"],["115417.37000000","0.00352000"],["115416.55000000","0.00010000"],["115416.54000000","0.18779000"],["115416.53000000","0.17337000"],["115415.38000000","0.00010000"],["115415.37000000","0.17332000"],["115415.06000000","0.00525000"],["115414.90000000","0.00000000"],["115414.89000000","0.00000000"],["115414.88000000","0.00000000"],["115413.85000000","0.00010000"],["115413.84000000","0.25630000"],["115412.32000000","0.00005000"],["115412.31000000","0.04633000"],["115410.44000000","0.17567000"],["115405.60000000","0.00000000"],["115404.82000000","0.00433000"],["115399.37000000","0.00000000"],["115399.19000000","0.31195000"],["115399.10000000","0.00866000"],["115397.50000000","0.00000000"],["115397.48000000","0.00000000"],["115394.43000000","0.08662000"],["115381.79000000","0.31500000"],["115286.97000000","0.00000000"],["115286.09000000","0.00000000"],["115285.88000000","0.00000000"],["115285.80000000","0.00000000"],["115285.56000000","0.00000000"],["115166.28000000","4.79705000"],["115035.05000000","0.02498000"],["115033.37000000","0.02498000"],["115032.06000000","0.02498000"],["114670.49000000","0.00065000"],["114513.25000000","0.00065000"],["113690.65000000","0.00100000"],["111660.07000000","0.00067000"],["103879.78000000","0.00019000"],["103879.00000000","0.00014000"],["103878.00000000","0.00030000"],["92337.59000000","0.00021000"],["60000.00000000","57.97732000"],["41551.91000000","0.00075000"]],"a":[["115421.99000000","5.37758000"],["115422.00000000","0.00220000"],["115422.36000000","0.03857000"],["115422.56000000","0.04071000"],["115422.85000000","0.28599000"],["115423.30000000","0.01699000"],["115423.75000000","0.00005000"],["115423.76000000","0.04407000"],["115423.77000000","0.00005000"],["115426.13000000","0.00005000"],["115428.91000000","0.00525000"],["115429.00000000","0.06100000"],["115432.27000000","0.00206000"],["115433.89000000","0.07033000"],["115435.16000000","0.00000000"],["115435.17000000","0.02600000"],["115435.64000000","0.00000000"],["115438.86000000","0.00000000"],["115445.32000000","0.00000000"],["115445.78000000","0.00000000"],["115447.38000000","0.05350000"],["115448.59000000","0.48732000"],["115456.62000000","0.86947000"],["115464.38000000","0.33265000"],["115500.34000000","0.00000000"],["115500.35000000","0.00000000"],["115500.38000000","0.00000000"],["115500.54000000","0.00000000"],["115500.76000000","0.34651000"],["115500.98000000","0.25975000"],["115509.20000000","0.03300000"],["115509.21000000","0.00000000"],["115509.56000000","0.00100000"],["115509.57000000","0.00100000"],["115513.30000000","0.00000000"],["115514.25000000","0.03400000"],["115520.85000000","0.00000000"],["115521.80000000","0.02500000"],["115637.35000000","0.01356000"],["115664.17000000","0.13537000"],["115955.53000000","0.00064000"],["116300.00000000","3.62791000"],["117153.32000000","0.00100000"]]}
[2025-10-27T18:47:49.156Z] {"e":"depthUpdate","E":1761590869014,"s":"BTCUSDT","U":79129598035,"u":79129598197,"b":[["115421.98000000","2.26876000"],["115421.97000000","0.00060000"],["115420.83000000","0.00115000"],["115417.91000000","0.00010000"],["115417.90000000","0.01292000"],["115417.89000000","0.03975000"],["115417.65000000","0.00005000"],["115417.37000000","0.00347000"],["115416.54000000","0.17251000"],["115415.06000000","0.00525000"],["115413.85000000","0.00000000"],["115413.84000000","0.00000000"],["115412.51000000","0.00000000"],["115412.50000000","0.25630000"],["115412.32000000","0.00000000"],["115410.81000000","0.00000000"],["115410.44000000","0.17562000"],["115399.10000000","0.00000000"],["115397.02000000","0.00866000"],["115384.15000000","0.00000000"],["115287.15000000","0.00000000"],["115286.95000000","0.00000000"],["115286.30000000","0.09389000"],["115286.18000000","0.00000000"],["115121.98000000","0.00000000"],["113690.65000000","0.00100000"],["103879.78000000","0.00000000"],["103878.00000000","0.00030000"],["92337.59000000","0.00021000"]],"a":[["115421.99000000","5.37758000"],["115422.00000000","0.00220000"],["115422.36000000","0.03857000"],["115422.56000000","0.04071000"],["115422.85000000","0.28599000"],["115423.30000000","0.00000000"],["115423.76000000","0.04407000"],["115424.87000000","0.01928000"],["115426.39000000","0.08668000"],["115428.91000000","0.00520000"],["115432.27000000","0.00492000"],["115444.49000000","0.00000000"],["115456.62000000","1.21598000"],["115457.74000000","0.00000000"],["115500.31000000","0.00000000"],["115500.38000000","0.00000000"],["115500.74000000","0.25975000"],["115500.76000000","0.00000000"],["115500.98000000","0.00000000"],["115501.15000000","0.00000000"],["115501.85000000","0.00000000"],["115503.91000000","0.00000000"],["115509.20000000","0.03400000"],["115509.21000000","0.00100000"],["115509.56000000","0.00000000"],["115509.57000000","0.00000000"],["115813.33000000","0.37961000"],["117153.32000000","0.00100000"]]}
[2025-10-27T18:47:50.150Z] {"e":"depthUpdate","E":1761590870014,"s":"BTCUSDT","U":79129598198,"u":79129598377,"b":[["115421.98000000","2.59288000"],["115421.97000000","0.00050000"],["115421.48000000","0.00000000"],["115421.05000000","0.00000000"],["115420.83000000","0.00115000"],["115420.65000000","0.03972000"],["115417.91000000","0.00000000"],["115417.90000000","0.00000000"],["115417.89000000","0.00000000"],["115417.65000000","0.00000000"],["115417.37000000","0.00352000"],["115416.54000000","0.17261000"],["115415.37000000","0.17337000"],["115412.51000000","0.00010000"],["115412.50000000","0.25640000"],["115412.32000000","0.00005000"],["115410.44000000","0.17567000"],["115410.43000000","0.31805000"],["115400.58000000","0.00866000"],["115397.02000000","0.00000000"],["115383.70000000","0.96923000"],["115330.20000000","0.00000000"],["115287.22000000","0.00000000"],["115286.67000000","0.00000000"],["115286.37000000","0.00000000"],["115286.30000000","0.00000000"],["115200.00000000","0.13276000"],["115121.98000000","0.00000000"],["113690.65000000","0.00100000"],["106188.23000000","0.00059000"],["103879.00000000","0.00014000"],["103878.00000000","0.00030000"],["92338.00000000","0.00000000"],["92337.59000000","0.00021000"],["50000.00000000","39.61417000"]],"a":[["115421.99000000","5.11780000"],["115422.00000000","0.00220000"],["115422.36000000","0.03857000"],["115422.84000000","0.13608000"],["115422.85000000","0.00005000"],["115423.75000000","0.00010000"],["115423.76000000","0.04412000"],["115424.86000000","0.00005000"],["115424.87000000","0.01928000"],["115425.10000000","0.28594000"],["115426.13000000","0.00000000"],["115433.89000000","0.00000000"],["115434.91000000","0.00000000"],["115434.92000000","0.00000000"],["115434.93000000","0.07038000"],["115444.33000000","0.13537000"],["115446.96000000","0.00000000"],["115456.51000000","0.25975000"],["115456.62000000","0.43615000"],["115463.64000000","0.31178000"],["115500.52000000","0.34651000"],["115500.59000000","0.43332000"],["115500.74000000","0.00000000"],["115502.68000000","0.25975000"],["117153.32000000","0.00100000"]]}
[2025-10-27T18:47:51.203Z] {"e":"depthUpdate","E":1761590871014,"s":"BTCUSDT","U":79129598378,"u":79129598499,"b":[["115421.98000000","2.28070000"],["115421.97000000","0.00050000"],["115420.83000000","0.00115000"],["115420.67000000","0.00000000"],["115420.66000000","0.00000000"],["115420.65000000","0.03910000"],["115416.54000000","0.17261000"],["115412.50000000","0.25640000"],["115412.32000000","0.00005000"],["115410.43000000","0.31805000"],["115362.00000000","0.34716000"],["115348.12000000","0.00561000"],["115330.09000000","0.12938000"],["115298.00000000","0.00040000"],["113690.65000000","0.00100000"],["106188.23000000","0.00049000"],["103878.00000000","0.00030000"],["92337.59000000","0.00021000"],["33000.00000000","3.79030000"]],"a":[["115421.99000000","5.11742000"],["115422.00000000","0.00220000"],["115422.36000000","0.03857000"],["115434.93000000","0.00005000"],["115434.95000000","0.07033000"],["115438.13000000","0.13537000"],["115441.14000000","0.00866000"],["115444.17000000","0.00000000"],["115456.62000000","0.43615000"],["115495.85000000","0.00561000"],["115500.51000000","0.00000000"],["115500.52000000","0.00000000"],["115500.53000000","0.00000000"],["115500.59000000","0.00000000"],["115500.61000000","0.00000000"],["115500.86000000","0.43332000"],["115501.23000000","0.34651000"],["115526.88000000","0.00000000"],["117153.32000000","0.00100000"]]}
[2025-10-27T18:47:52.228Z] {"e":"depthUpdate","E":1761590872014,"s":"BTCUSDT","U":79129598500,"u":79129599688,"b":[["115421.98000000","6.12888000"],["115421.97000000","0.00000000"],["115421.50000000","0.00158000"],["115421.48000000","0.00008000"],["115421.46000000","0.00270000"],["115420.83000000","0.00100000"],["115420.67000000","0.00000000"],["115420.66000000","0.00000000"],["115420.65000000","0.00000000"],["115419.56000000","0.00000000"],["115419.26000000","0.00000000"],["115419.24000000","0.00000000"],["115418.30000000","0.00000000"],["115418.27000000","0.00000000"],["115417.66000000","0.02140000"],["115417.65000000","0.06758000"],["115417.37000000","0.00347000"],["115416.84000000","0.00250000"],["115416.70000000","0.04411000"],["115416.65000000","0.29689000"],["115416.64000000","0.54085000"],["115416.55000000","0.00000000"],["115416.54000000","0.00000000"],["115416.53000000","0.17332000"],["115416.21000000","0.00021000"],["115416.20000000","0.00000000"],["115415.38000000","0.00000000"],["115415.37000000","0.17332000"],["115415.23000000","0.08661000"],["115415.10000000","0.00009000"],["115415.07000000","0.00433000"],["115415.06000000","0.00525000"],["115414.83000000","0.00040000"],["115414.81000000","0.00000000"],["115414.73000000","0.00009000"],["115414.51000000","0.00018000"],["115414.18000000","0.00005000"],["115414.09000000","0.00009000"],["115413.82000000","0.00009000"],["115413.14000000","0.00005000"],["115412.61000000","0.00000000"],["115412.51000000","0.00000000"],["115412.50000000","0.00000000"],["115412.32000000","0.00000000"],["115412.31000000","0.00000000"],["115411.38000000","1.21310000"],["115411.37000000","2.47832000"],["115411.14000000","0.00006000"],["115411.07000000","0.00100000"],["115410.80000000","0.00000000"],["115410.44000000","0.00693000"],["115410.43000000","0.31800000"],["115410.28000000","0.01741000"],["115409.79000000","0.00000000"],["115409.06000000","0.54101000"],["115409.05000000","0.00007000"],["115408.44000000","0.06753000"],["115408.38000000","0.00000000"],["115408.29000000","0.00000000"],["115408.27000000","0.00000000"],["115407.92000000","0.00000000"],["115407.70000000","0.00000000"],["115407.63000000","0.00000000"],["115407.28000000","0.00000000"],["115407.01000000","0.00000000"],["115406.99000000","0.15817000"],["115405.44000000","0.00000000"],["115404.82000000","0.00000000"],["115403.74000000","0.05712000"],["115403.70000000","0.04331000"],["115403.63000000","0.31194000"],["115403.31000000","0.00000000"],["115403.23000000","0.14725000"],["115402.85000000","0.00000000"],["115402.37000000","0.00000000"],["115402.35000000","0.05690000"],["115402.21000000","0.04000000"],["115402.06000000","0.00000000"],["115401.97000000","0.00000000"],["115400.73000000","0.00000000"],["115400.71000000","0.00000000"],["115400.58000000","0.00000000"],["115400.30000000","0.00000000"],["115400.03000000","0.00000000"],["115399.62000000","0.00000000"],["115398.94000000","0.00000000"],["115398.36000000","0.00000000"],["115396.41000000","0.00000000"],["115394.43000000","0.00000000"],["115394.23000000","0.00005000"],["115393.74000000","0.00000000"],["115393.38000000","1.82187000"],["115393.36000000","0.00000000"],["115393.16000000","0.00000000"],["115390.82000000","0.00000000"],["115388.49000000","0.04331000"],["115388.32000000","0.00000000"],["115388.21000000","0.31198000"],["115387.36000000","0.04333000"],["115387.35000000","0.55645000"],["115385.63000000","0.00000000"],["115383.40000000","0.02498000"],["115382.15000000","0.00000000"],["115380.82000000","0.00000000"],["115379.90000000","0.00000000"],["115379.02000000","0.00000000"],["115375.87000000","0.00000000"],["115372.88000000","0.06427000"],["115369.93000000","0.00000000"],["115367.81000000","0.00000000"],["115366.34000000","0.00000000"],["115366.32000000","0.04281000"],["115366.09000000","0.25975000"],["115364.37000000","0.03025000"],["115362.45000000","0.00000000"],["115360.99000000","0.02158000"],["115359.93000000","0.00000000"],["115359.23000000","0.60476000"],["115356.68000000","0.00000000"],["115354.80000000","0.00000000"],["115354.11000000","0.00628000"],["115353.52000000","0.02813000"],["115352.31000000","0.31374000"],["115350.19000000","0.28462000"],["115347.23000000","0.00000000"],["115345.00000000","0.00623000"],["115343.62000000","0.00000000"],["115343.16000000","0.00000000"],["115343.12000000","0.00000000"],["115342.98000000","0.00000000"],["115341.07000000","0.00000000"],["115340.77000000","0.49877000"],["115336.96000000","0.00000000"],["115336.94000000","0.00000000"],["115334.49000000","0.00000000"],["115334.47000000","0.05050000"],["115334.01000000","0.04597000"],["115332.78000000","0.00000000"],["115332.46000000","0.00000000"],["115332.01000000","0.04597000"],["115329.83000000","0.00000000"],["115328.13000000","0.00000000"],["115325.01000000","0.59176000"],["115323.54000000","0.00000000"],["115323.36000000","0.00000000"],["115319.01000000","0.00000000"],["115306.76000000","0.00000000"],["115297.59000000","0.00000000"],["115295.66000000","0.73073000"],["115292.19000000","1.30569000"],["115290.61000000","0.09389000"],["115285.80000000","0.01356000"],["115278.37000000","0.00000000"],["115278.36000000","0.00000000"],["115247.63000000","0.00000000"],["115216.61000000","0.00000000"],["115216.55000000","0.00000000"],["115179.51000000","0.02198000"],["115106.33000000","0.00000000"],["115066.01000000","0.00000000"],["113690.65000000","0.00100000"],["111933.13000000","0.02179000"],["111929.44000000","0.00000000"],["103878.00000000","0.00030000"],["92337.59000000","0.00021000"]],"a":[["115421.99000000","0.00734000"],["115422.00000000","0.00210000"],["115422.07000000","0.00000000"],["115422.14000000","0.00005000"],["115422.30000000","0.00009000"],["115422.34000000","0.00009000"],["115422.35000000","0.00000000"],["115422.36000000","0.00000000"],["115422.55000000","0.00000000"],["115422.56000000","0.00005000"],["115422.83000000","0.00000000"],["115422.84000000","0.00000000"],["115423.14000000","0.00115000"],["115423.49000000","0.00000000"],["115423.50000000","0.00000000"],["115423.75000000","0.00000000"],["115423.76000000","0.00009000"],["115423.79000000","0.00000000"],["115424.00000000","0.00130000"],["115424.86000000","0.00000000"],["115424.87000000","0.00196000"],["115425.09000000","0.00000000"],["115425.10000000","0.00000000"],["115425.66000000","0.00000000"],["115426.00000000","0.00120000"],["115426.08000000","0.00005000"],["115426.14000000","0.00000000"],["115426.38000000","0.00151000"],["115426.39000000","0.00005000"],["115426.60000000","0.00347000"],["115426.63000000","0.00000000"],["115426.96000000","0.00000000"],["115426.97000000","0.00000000"],["115428.00000000","0.00120000"],["115428.56000000","0.00005000"],["115428.67000000","0.00305000"],["115428.91000000","0.00525000"],["115428.93000000","0.00000000"],["115428.99000000","0.00000000"],["115429.00000000","0.00000000"],["115429.50000000","0.00000000"],["115429.60000000","0.00000000"],["115429.86000000","0.00000000"],["115430.00000000","0.00120000"],["115430.36000000","0.00000000"],["115430.52000000","0.00000000"],["115430.59000000","0.00000000"],["115430.60000000","0.00000000"],["115430.66000000","0.00000000"],["115430.70000000","0.00005000"],["115430.96000000","0.00000000"],["115430.98000000","0.00000000"],["115431.04000000","0.00000000"],["115431.16000000","0.00000000"],["115431.80000000","0.00386000"],["115432.00000000","0.00125000"],["115432.01000000","0.00000000"],["115432.15000000","0.00150000"],["115432.27000000","0.00010000"],["115432.94000000","0.00105000"],["115433.31000000","0.00010000"],["115433.32000000","0.04387000"],["115433.51000000","0.14414000"],["115433.52000000","0.00010000"],["115433.53000000","0.00713000"],["115433.54000000","0.00000000"],["115433.60000000","0.00000000"],["115433.68000000","0.00000000"],["115433.85000000","0.00000000"],["115433.86000000","0.00000000"],["115433.99000000","0.00000000"],["115434.00000000","0.00120000"],["115434.08000000","0.00000000"],["115434.17000000","0.00000000"],["115434.75000000","0.00010000"],["115434.76000000","0.22442000"],["115434.77000000","0.00000000"],["115434.82000000","0.00000000"],["115434.95000000","0.00000000"],["115435.16000000","0.00000000"],["115435.17000000","0.00000000"],["115435.26000000","0.00000000"],["115435.31000000","0.00000000"],["115435.32000000","0.00000000"],["115436.07000000","0.00070000"],["115436.33000000","0.00000000"],["115436.43000000","0.00000000"],["115436.95000000","0.02609000"],["115436.96000000","0.00000000"],["115437.25000000","0.00069000"],["115437.35000000","0.28586000"],["115437.36000000","0.00000000"],["115437.38000000","0.04000000"],["115437.67000000","0.00000000"],["115437.70000000","0.00000000"],["115437.85000000","0.00069000"],["115437.86000000","0.29232000"],["115437.87000000","0.02000000"],["115437.93000000","0.00000000"],["115438.13000000","0.00000000"],["115439.25000000","0.00331000"],["115439.92000000","0.00000000"],["115439.94000000","0.00000000"],["115440.60000000","0.00000000"],["115440.61000000","0.00000000"],["115440.67000000","0.00000000"],["115440.69000000","0.00000000"],["115440.87000000","0.00000000"],["115441.00000000","0.00000000"],["115441.14000000","0.00000000"],["115441.17000000","0.00000000"],["115441.82000000","0.33953000"],["115441.83000000","0.00000000"],["115442.03000000","0.25975000"],["115442.67000000","0.12000000"],["115442.78000000","0.00000000"],["115443.25000000","0.00000000"],["115443.86000000","0.00221000"],["115444.33000000","0.00000000"],["115444.78000000","0.00000000"],["115444.79000000","0.00000000"],["115445.07000000","0.54080000"],["115445.08000000","0.21657000"],["115445.09000000","0.04940000"],["115445.70000000","0.00100000"],["115445.99000000","0.00433000"],["115446.37000000","0.16000000"],["115447.14000000","0.00000000"],["115447.84000000","0.00000000"],["115447.92000000","1.06952000"],["115448.07000000","0.14725000"],["115448.57000000","3.01912000"],["115448.58000000","0.00000000"],["115448.59000000","0.31500000"],["115448.61000000","0.00000000"],["115448.62000000","0.00005000"],["115449.18000000","0.00250000"],["115450.24000000","0.00000000"],["115451.48000000","0.00000000"],["115451.61000000","0.00000000"],["115452.58000000","0.16996000"],["115452.59000000","0.00000000"],["115453.16000000","0.00000000"],["115453.26000000","0.43307000"],["115453.47000000","0.25979000"],["115453.50000000","0.00000000"],["115453.80000000","0.00250000"],["115454.44000000","0.00259000"],["115454.64000000","0.00000000"],["115454.70000000","0.07031000"],["115454.98000000","0.00000000"],["115455.11000000","0.34651000"],["115455.53000000","0.25986000"],["115455.58000000","0.13537000"],["115456.28000000","0.00000000"],["115456.61000000","0.04334000"],["115456.62000000","0.00308000"],["115458.07000000","0.04330000"],["115458.08000000","0.30810000"],["115458.42000000","0.00250000"],["115458.92000000","0.00000000"],["115458.94000000","0.00000000"],["115460.96000000","0.00000000"],["115460.99000000","0.00000000"],["115461.46000000","0.00000000"],["115461.90000000","0.43332000"],["115463.04000000","0.00250000"],["115463.46000000","0.00000000"],["115463.64000000","0.00000000"],["115463.67000000","0.00000000"],["115464.01000000","0.00000000"],["115464.38000000","0.00000000"],["115464.45000000","0.00000000"],["115465.57000000","0.00000000"],["115466.59000000","0.02498000"],["115468.81000000","0.31176000"],["115468.85000000","0.00000000"],["115471.28000000","0.33265000"],["115472.36000000","0.20117000"],["115473.90000000","0.04696000"],["115475.17000000","0.31174000"],["115476.98000000","0.02849000"],["115479.14000000","0.01356000"],["115479.93000000","0.00048000"],["115480.83000000","0.51001000"],["115482.96000000","0.01646000"],["115483.21000000","0.00000000"],["115484.35000000","0.00000000"],["115485.94000000","0.00000000"],["115487.60000000","0.03446000"],["115488.00000000","0.00160000"],["115488.20000000","0.25975000"],["115489.22000000","0.00000000"],["115490.46000000","0.00000000"],["115494.08000000","0.54080000"],["115496.44000000","0.03234000"],["115499.64000000","0.25979000"],["115500.51000000","0.00000000"],["115500.82000000","0.00622000"],["115500.86000000","0.00000000"],["115500.97000000","0.46812000"],["115500.99000000","0.54080000"],["115501.23000000","0.00000000"],["115501.70000000","0.25986000"],["115503.34000000","0.00000000"],["115506.29000000","0.00000000"],["115506.78000000","0.00000000"],["115506.79000000","0.54080000"],["115508.40000000","0.00000000"],["115509.20000000","0.03300000"],["115509.21000000","0.00000000"],["115510.56000000","0.00000000"],["115510.57000000","0.00000000"],["115510.61000000","0.00000000"],["115510.97000000","0.43307000"],["115511.56000000","0.00000000"],["115511.57000000","0.00000000"],["115512.82000000","0.34651000"],["115514.25000000","0.00000000"],["115514.76000000","0.00000000"],["115515.25000000","0.00000000"],["115515.73000000","0.79344000"],["115516.25000000","0.00000000"],["115517.20000000","0.00000000"],["115517.25000000","0.03400000"],["115518.35000000","2.47832000"],["115519.44000000","0.43332000"],["115521.80000000","0.00000000"],["115522.80000000","0.00000000"],["115523.30000000","0.01299000"],["115523.80000000","0.00000000"],["115524.75000000","0.00000000"],["115524.80000000","0.02500000"],["115529.90000000","2.47832000"],["115540.00000000","0.01916000"],["115541.40000000","2.47832000"],["115548.21000000","0.00000000"],["115581.07000000","0.09389000"],["115595.21000000","0.00019000"],["115622.28000000","0.00000000"],["115622.32000000","0.00000000"],["115646.62000000","0.01646000"],["115647.67000000","0.01646000"],["115702.14000000","0.00000000"],["115704.15000000","0.00000000"],["115711.60000000","0.00000000"],["115732.02000000","0.01646000"],["115735.39000000","0.02498000"],["115736.33000000","0.02498000"],["115736.35000000","0.02498000"],["115738.96000000","0.00000000"],["115747.86000000","0.02198000"],["115759.94000000","0.00000000"],["115760.00000000","0.00256000"],["115762.89000000","0.00000000"],["115763.18000000","0.00000000"],["115764.38000000","0.00000000"],["115764.49000000","0.00000000"],["115770.02000000","0.01646000"],["115780.95000000","0.00000000"],["115781.69000000","0.01732000"],["115782.58000000","0.00000000"],["115783.22000000","0.01732000"],["115784.32000000","0.01732000"],["115784.36000000","0.01732000"],["115786.21000000","0.02398000"],["115792.53000000","0.02398000"],["115802.78000000","0.00000000"],["115803.32000000","0.00000000"],["115803.85000000","0.00000000"],["115804.38000000","0.00000000"],["115804.61000000","0.00000000"],["115813.33000000","0.00000000"],["115829.96000000","0.00000000"],["115830.54000000","0.00000000"],["115831.12000000","0.00000000"],["115831.71000000","0.00025000"],["115832.90000000","0.00000000"],["115841.86000000","0.03198000"],["115842.62000000","0.03198000"],["115842.65000000","0.03198000"],["115843.72000000","0.03217000"],["115843.78000000","0.03198000"],["115853.90000000","0.02252000"],["115865.18000000","0.00000000"],["115867.79000000","0.00000000"],["115868.11000000","0.03198000"],["115868.95000000","0.03198000"],["115870.43000000","0.03198000"],["115871.89000000","0.03198000"],["115891.55000000","0.02498000"],["115897.64000000","0.02498000"],["115925.29000000","0.31500000"],["117153.32000000","0.00100000"]]}
[2025-10-27T18:47:53.253Z] {"e":"depthUpdate","E":1761590873014,"s":"BTCUSDT","U":79129599689,"u":79129601468,"b":[["115434.75000000","6.31553000"],["115434.74000000","0.00017000"],["115434.71000000","0.00000000"],["115434.70000000","0.00000000"],["115434.67000000","0.00009000"],["115434.62000000","0.00005000"],["115434.03000000","0.00000000"],["115433.99000000","0.00000000"],["115433.91000000","0.00000000"],["115433.82000000","0.16585000"],["115433.81000000","0.04045000"],["115433.52000000","0.00000000"],["115433.31000000","0.00000000"],["115433.18000000","0.00000000"],["115433.17000000","0.00000000"],["115432.95000000","0.00005000"],["115432.93000000","0.00000000"],["115432.92000000","0.00000000"],["115432.91000000","0.00000000"],["115432.90000000","0.00000000"],["115432.87000000","0.17339000"],["115432.75000000","0.00000000"],["115432.57000000","0.00000000"],["115432.26000000","0.00010000"],["115432.25000000","0.00015000"],["115432.14000000","0.00000000"],["115431.99000000","0.00000000"],["115431.79000000","0.00000000"],["115431.18000000","0.00000000"],["115431.17000000","0.00000000"],["115431.10000000","0.24954000"],["115430.98000000","0.00007000"],["115430.76000000","0.04767000"],["115430.71000000","0.00000000"],["115430.70000000","0.00250000"],["115429.99000000","0.00000000"],["115429.57000000","0.00000000"],["115429.43000000","0.00699000"],["115429.12000000","0.00005000"],["115428.90000000","0.00000000"],["115428.85000000","0.00005000"],["115428.66000000","0.00000000"],["115428.33000000","0.00000000"],["115428.24000000","0.00000000"],["115428.04000000","0.00010000"],["115428.03000000","0.06753000"],["115427.99000000","0.00000000"],["115427.96000000","0.00000000"],["115427.95000000","0.01754000"],["115427.76000000","0.00000000"],["115426.86000000","0.00005000"],["115426.59000000","0.00000000"],["115426.37000000","0.00000000"],["115426.09000000","0.00433000"],["115426.08000000","0.00250000"],["115425.99000000","0.00000000"],["115425.61000000","0.00005000"],["115425.60000000","0.11621000"],["115425.59000000","0.12125000"],["115424.86000000","0.00000000"],["115423.99000000","0.22345000"],["115423.54000000","0.04401000"],["115423.21000000","0.00039000"],["115423.20000000","0.00309000"],["115423.13000000","0.00000000"],["115423.08000000","0.00005000"],["115422.84000000","0.27948000"],["115422.83000000","0.00009000"],["115422.82000000","0.00005000"],["115422.62000000","0.00018000"],["115422.61000000","0.00000000"],["115422.33000000","0.08819000"],["115422.29000000","0.00000000"],["115422.19000000","0.00009000"],["115422.17000000","0.00000000"],["115422.13000000","0.00000000"],["115422.01000000","0.00000000"],["115422.00000000","1.42433000"],["115421.99000000","3.01912000"],["115421.98000000","1.55199000"],["115421.93000000","0.00009000"],["115421.91000000","0.00000000"],["115421.50000000","0.00000000"],["115421.48000000","0.00000000"],["115421.46000000","0.00250000"],["115421.36000000","0.00333000"],["115420.83000000","0.00095000"],["115420.62000000","0.03465000"],["115420.52000000","0.00007000"],["115420.34000000","0.00000000"],["115420.32000000","0.00009000"],["115420.23000000","0.00100000"],["115420.01000000","0.00000000"],["115420.00000000","0.00005000"],["115419.78000000","0.00000000"],["115419.72000000","0.00000000"],["115419.62000000","0.00000000"],["115419.58000000","0.00000000"],["115418.22000000","0.00000000"],["115417.66000000","0.15815000"],["115417.65000000","0.06748000"],["115417.44000000","0.00086000"],["115417.00000000","0.06000000"],["115416.70000000","0.00000000"],["115416.65000000","0.20246000"],["115416.64000000","0.54080000"],["115416.53000000","0.00000000"],["115416.52000000","0.00000000"],["115415.37000000","0.00000000"],["115415.23000000","0.00000000"],["115415.10000000","0.00000000"],["115415.07000000","0.00000000"],["115415.06000000","0.00520000"],["115414.91000000","0.08661000"],["115414.89000000","0.00000000"],["115414.83000000","0.00000000"],["115414.73000000","0.00000000"],["115414.55000000","0.00009000"],["115414.51000000","0.00000000"],["115414.09000000","0.00000000"],["115413.88000000","0.00000000"],["115413.84000000","0.04330000"],["115413.83000000","0.00000000"],["115413.82000000","0.00000000"],["115413.16000000","0.30000000"],["115413.14000000","0.00000000"],["115412.54000000","0.00000000"],["115411.50000000","0.43332000"],["115411.07000000","0.00000000"],["115410.86000000","0.43307000"],["115410.40000000","0.31192000"],["115410.28000000","0.00000000"],["115410.07000000","0.05002000"],["115409.35000000","0.00021000"],["115409.17000000","0.07000000"],["115409.06000000","0.54080000"],["115408.91000000","0.00000000"],["115407.83000000","0.03000000"],["115407.60000000","0.00000000"],["115407.50000000","0.14726000"],["115406.99000000","0.00000000"],["115406.98000000","0.00000000"],["115406.76000000","0.00000000"],["115406.58000000","0.03000000"],["115405.60000000","0.00000000"],["115405.58000000","2.47837000"],["115404.67000000","0.00086000"],["115403.74000000","0.00000000"],["115403.70000000","0.00000000"],["115403.32000000","0.00000000"],["115403.14000000","0.00583000"],["115402.98000000","0.00000000"],["115402.48000000","0.14719000"],["115401.31000000","0.03683000"],["115401.27000000","0.00000000"],["115400.71000000","0.00270000"],["115400.11000000","0.00000000"],["115400.07000000","0.00012000"],["115400.02000000","0.00000000"],["115397.10000000","0.00000000"],["115396.35000000","0.00444000"],["115395.72000000","0.52784000"],["115395.71000000","0.00173000"],["115395.36000000","0.25917000"],["115395.19000000","0.98089000"],["115393.98000000","0.00000000"],["115392.20000000","0.00000000"],["115392.09000000","0.08000000"],["115390.49000000","0.00000000"],["115390.17000000","0.00000000"],["115389.96000000","0.00000000"],["115389.70000000","0.00000000"],["115388.31000000","1.21478000"],["115388.21000000","0.00000000"],["115387.36000000","0.00000000"],["115387.35000000","0.03691000"],["115383.70000000","0.00000000"],["115383.18000000","0.00000000"],["115382.97000000","0.00000000"],["115382.96000000","0.00000000"],["115382.78000000","0.00000000"],["115381.54000000","0.17701000"],["115381.52000000","0.00000000"],["115380.89000000","0.00000000"],["115380.18000000","0.00000000"],["115379.60000000","0.00000000"],["115377.94000000","0.00000000"],["115377.90000000","0.00000000"],["115377.71000000","0.00000000"],["115376.92000000","0.00000000"],["115375.42000000","0.21854000"],["115374.92000000","0.02237000"],["115374.31000000","0.00000000"],["115371.93000000","0.00000000"],["115371.15000000","0.00000000"],["115371.09000000","0.25986000"],["115371.07000000","0.00000000"],["115370.18000000","0.00000000"],["115369.96000000","0.25979000"],["115369.14000000","0.00000000"],["115366.32000000","0.00000000"],["115366.23000000","0.00000000"],["115366.09000000","0.00000000"],["115365.50000000","0.00000000"],["115365.38000000","0.00000000"],["115364.86000000","0.00000000"],["115364.52000000","0.00005000"],["115364.37000000","0.00000000"],["115361.00000000","0.00008000"],["115358.77000000","0.00000000"],["115358.29000000","0.06764000"],["115356.16000000","0.00000000"],["115356.06000000","0.43332000"],["115355.99000000","0.34651000"],["115355.95000000","0.00000000"],["115355.50000000","0.00000000"],["115355.05000000","0.00000000"],["115354.62000000","0.25975000"],["115353.95000000","0.00000000"],["115353.52000000","0.00000000"],["115353.35000000","0.00000000"],["115353.14000000","0.47643000"],["115353.13000000","0.43307000"],["115352.31000000","0.00000000"],["115351.67000000","0.03025000"],["115349.83000000","0.00000000"],["115348.37000000","0.00008000"],["115348.01000000","0.00000000"],["115347.93000000","0.00000000"],["115342.65000000","0.00000000"],["115339.23000000","0.02813000"],["115336.72000000","0.00000000"],["115330.50000000","0.48569000"],["115330.49000000","0.46881000"],["115329.79000000","0.00000000"],["115325.01000000","0.05096000"],["115314.45000000","0.00000000"],["115313.03000000","0.00215000"],["115313.02000000","0.09874000"],["115311.89000000","0.00000000"],["115302.01000000","0.00182000"],["115301.69000000","0.00000000"],["115301.47000000","0.00000000"],["115301.15000000","0.00000000"],["115300.87000000","0.00000000"],["115300.86000000","0.00000000"],["115299.09000000","0.08947000"],["115298.84000000","0.00243000"],["115295.66000000","0.58525000"],["115289.92000000","0.00000000"],["115289.91000000","0.00000000"],["115288.13000000","0.00000000"],["115284.26000000","0.02339000"],["115280.75000000","0.00000000"],["115266.85000000","0.00000000"],["115266.84000000","0.00000000"],["115250.01000000","0.00192000"],["115238.05000000","0.00000000"],["115229.00000000","1.33494000"],["115196.63000000","0.00086000"],["115192.34000000","0.97240000"],["115186.56000000","0.00073000"],["115185.10000000","0.00000000"],["115170.49000000","0.00000000"],["115163.22000000","0.00000000"],["115130.00000000","0.00100000"],["115084.97000000","0.00000000"],["115079.56000000","0.00000000"],["114966.97000000","0.00000000"],["113703.22000000","0.00100000"],["113690.65000000","0.00000000"],["112200.00000000","1.87264000"],["103890.00000000","0.08110000"],["103879.00000000","0.00014000"],["103878.00000000","0.00020000"],["99000.00000000","53.58677000"],["92347.80000000","0.00021000"],["92338.00000000","0.00000000"],["92337.59000000","0.00000000"]],"a":[["115421.99000000","0.00000000"],["115422.00000000","0.00000000"],["115422.14000000","0.00000000"],["115422.18000000","0.00000000"],["115422.30000000","0.00000000"],["115422.34000000","0.00000000"],["115422.56000000","0.00000000"],["115422.62000000","0.00000000"],["115422.85000000","0.00000000"],["115423.08000000","0.00000000"],["115423.14000000","0.00000000"],["115423.76000000","0.00000000"],["115423.77000000","0.00000000"],["115423.84000000","0.00000000"],["115424.00000000","0.00000000"],["115424.87000000","0.00000000"],["115424.91000000","0.00000000"],["115425.60000000","0.00000000"],["115425.85000000","0.00000000"],["115426.00000000","0.00000000"],["115426.08000000","0.00000000"],["115426.26000000","0.00000000"],["115426.38000000","0.00000000"],["115426.39000000","0.00000000"],["115426.60000000","0.00000000"],["115427.55000000","0.00000000"],["115428.00000000","0.00000000"],["115428.56000000","0.00000000"],["115428.67000000","0.00000000"],["115428.85000000","0.00000000"],["115428.91000000","0.00000000"],["115429.06000000","0.00000000"],["115429.89000000","0.00000000"],["115430.00000000","0.00000000"],["115430.70000000","0.00000000"],["115430.89000000","0.00000000"],["115431.18000000","0.00000000"],["115431.40000000","0.00000000"],["115431.55000000","0.00000000"],["115431.80000000","0.00000000"],["115432.00000000","0.00000000"],["115432.15000000","0.00000000"],["115432.27000000","0.00000000"],["115432.52000000","0.00000000"],["115432.57000000","0.00000000"],["115432.58000000","0.00000000"],["115432.59000000","0.00000000"],["115432.94000000","0.00000000"],["115433.30000000","0.00000000"],["115433.31000000","0.00000000"],["115433.32000000","0.00000000"],["115433.50000000","0.00000000"],["115433.51000000","0.00000000"],["115433.52000000","0.00000000"],["115433.53000000","0.00000000"],["115434.00000000","0.00000000"],["115434.07000000","0.00000000"],["115434.62000000","0.00000000"],["115434.71000000","0.00000000"],["115434.75000000","0.00000000"],["115434.76000000","1.60198000"],["115434.77000000","0.00060000"],["115434.78000000","0.00000000"],["115434.84000000","0.00009000"],["115434.93000000","0.00000000"],["115434.96000000","0.00017000"],["115435.23000000","0.00000000"],["115436.00000000","0.00145000"],["115436.07000000","0.00000000"],["115436.34000000","0.00000000"],["115436.53000000","0.00000000"],["115436.67000000","0.00000000"],["115436.68000000","0.00000000"],["115436.95000000","0.00000000"],["115436.98000000","0.00000000"],["115436.99000000","0.00000000"],["115437.05000000","0.00000000"],["115437.14000000","0.00000000"],["115437.15000000","0.00000000"],["115437.25000000","0.00000000"],["115437.27000000","0.00010000"],["115437.28000000","0.02074000"],["115437.29000000","0.00000000"],["115437.30000000","0.00000000"],["115437.31000000","0.00000000"],["115437.35000000","0.00000000"],["115437.37000000","0.00000000"],["115437.38000000","0.00000000"],["115437.44000000","0.00000000"],["115437.85000000","0.00000000"],["115437.86000000","0.00000000"],["115437.87000000","0.00005000"],["115437.88000000","0.00000000"],["115438.00000000","0.00125000"],["115438.37000000","0.00000000"],["115438.57000000","0.00000000"],["115438.67000000","0.00000000"],["115438.87000000","0.00000000"],["115438.97000000","0.00000000"],["115439.25000000","0.00005000"],["115439.30000000","0.00155000"],["115439.76000000","0.00000000"],["115439.78000000","0.00000000"],["115439.99000000","0.00010000"],["115440.00000000","0.01878000"],["115440.10000000","0.00010000"],["115440.11000000","0.04411000"],["115440.17000000","0.00000000"],["115440.56000000","0.00000000"],["115440.92000000","0.00000000"],["115440.93000000","0.00000000"],["115441.04000000","0.00000000"],["115441.05000000","0.00005000"],["115441.16000000","0.00000000"],["115441.17000000","0.00000000"],["115441.52000000","0.00010000"],["115441.53000000","0.16429000"],["115441.81000000","0.00010000"],["115441.82000000","0.21880000"],["115442.00000000","0.00120000"],["115442.02000000","0.00000000"],["115442.03000000","0.25980000"],["115442.11000000","0.28590000"],["115442.12000000","0.00000000"],["115442.15000000","0.00000000"],["115442.18000000","0.00000000"],["115442.20000000","0.00000000"],["115442.57000000","0.00000000"],["115442.67000000","0.00000000"],["115443.26000000","0.00005000"],["115443.32000000","0.00000000"],["115443.85000000","0.00000000"],["115443.86000000","0.00253000"],["115444.00000000","0.00120000"],["115444.07000000","0.14005000"],["115444.12000000","0.00000000"],["115444.51000000","0.00000000"],["115444.56000000","0.00005000"],["115444.78000000","0.04020000"],["115445.06000000","0.04611000"],["115445.07000000","0.00000000"],["115445.08000000","0.08658000"],["115445.09000000","0.00000000"],["115445.70000000","0.00000000"],["115445.99000000","0.00000000"],["115446.00000000","0.00125000"],["115446.12000000","0.00000000"],["115446.30000000","0.00150000"],["115446.61000000","0.00000000"],["115446.62000000","0.00000000"],["115446.64000000","0.02600000"],["115447.37000000","0.29229000"],["115447.84000000","0.00000000"],["115447.85000000","0.00000000"],["115447.87000000","0.00000000"],["115447.96000000","0.00000000"],["115448.06000000","0.00000000"],["115448.11000000","0.00000000"],["115448.23000000","0.00000000"],["115449.19000000","0.00000000"],["115449.28000000","0.00325000"],["115449.77000000","0.07525000"],["115451.42000000","0.00000000"],["115452.08000000","0.21807000"],["115452.58000000","0.00000000"],["115452.68000000","0.03900000"],["115453.76000000","0.06300000"],["115453.83000000","0.04500000"],["115453.87000000","0.00000000"],["115454.34000000","0.00996000"],["115454.35000000","0.00000000"],["115454.38000000","0.07031000"],["115454.70000000","0.00000000"],["115454.86000000","0.00100000"],["115455.58000000","0.00000000"],["115455.94000000","0.00000000"],["115455.99000000","0.00000000"],["115456.61000000","0.00000000"],["115457.34000000","0.00000000"],["115457.47000000","0.00000000"],["115457.52000000","0.00005000"],["115457.85000000","0.00300000"],["115458.06000000","0.00000000"],["115458.07000000","0.00000000"],["115458.08000000","0.47458000"],["115459.33000000","0.00000000"],["115459.48000000","0.00433000"],["115459.49000000","0.00000000"],["115459.54000000","0.06000000"],["115459.65000000","0.03000000"],["115460.16000000","0.00021000"],["115460.53000000","0.00005000"],["115461.79000000","0.13537000"],["115462.15000000","0.00000000"],["115463.61000000","0.00086000"],["115464.17000000","0.00583000"],["115464.48000000","0.00000000"],["115464.63000000","0.16996000"],["115464.64000000","0.00000000"],["115464.65000000","0.00000000"],["115466.59000000","0.00000000"],["115467.66000000","0.00250000"],["115468.57000000","0.04330000"],["115468.81000000","0.00000000"],["115468.82000000","0.00000000"],["115469.40000000","0.00300000"],["115469.71000000","0.00000000"],["115469.94000000","0.31176000"],["115470.39000000","0.00000000"],["115471.97000000","0.00000000"],["115472.64000000","0.00000000"],["115473.70000000","0.00000000"],["115473.78000000","0.26565000"],["115473.79000000","0.26398000"],["115474.00000000","0.00140000"],["115474.69000000","0.00000000"],["115475.83000000","0.02398000"],["115475.87000000","0.00000000"],["115477.67000000","0.03198000"],["115477.98000000","0.05696000"],["115478.46000000","0.06632000"],["115479.13000000","0.31173000"],["115479.93000000","0.00000000"],["115479.94000000","0.00000000"],["115480.78000000","0.00005000"],["115480.83000000","0.28815000"],["115481.71000000","0.00008000"],["115482.97000000","0.00000000"],["115483.26000000","0.00000000"],["115483.69000000","0.31172000"],["115486.55000000","0.00005000"],["115486.70000000","0.00086000"],["115487.60000000","0.00000000"],["115487.61000000","0.00000000"],["115487.66000000","0.00000000"],["115488.20000000","0.00000000"],["115489.05000000","0.00000000"],["115489.75000000","0.46816000"],["115491.34000000","0.00000000"],["115491.99000000","0.00216000"],["115492.32000000","0.00005000"],["115492.41000000","0.00048000"],["115492.42000000","0.00000000"],["115493.03000000","0.00008000"],["115497.94000000","0.00000000"],["115500.72000000","0.03446000"],["115501.38000000","0.00000000"],["115502.74000000","0.00630000"],["115503.30000000","0.00216000"],["115503.83000000","0.00617000"],["115510.96000000","0.32151000"],["115511.37000000","0.00000000"],["115511.62000000","0.08696000"],["115513.22000000","0.00000000"],["115514.91000000","0.00000000"],["115515.73000000","1.15015000"],["115517.25000000","0.00000000"],["115519.20000000","0.00000000"],["115519.59000000","1.00548000"],["115520.79000000","0.07145000"],["115521.20000000","0.00100000"],["115521.21000000","0.00100000"],["115522.35000000","0.00000000"],["115522.50000000","0.18243000"],["115523.35000000","0.00000000"],["115524.68000000","0.02237000"],["115524.80000000","0.00000000"],["115525.31000000","0.03400000"],["115525.41000000","0.00000000"],["115526.64000000","0.00433000"],["115526.75000000","0.00000000"],["115528.86000000","0.79454000"],["115529.90000000","2.47832000"],["115530.61000000","0.00000000"],["115530.90000000","0.00000000"],["115532.85000000","0.02500000"],["115537.02000000","0.03900000"],["115538.08000000","0.00000000"],["115538.18000000","0.04500000"],["115539.99000000","0.02339000"],["115541.39000000","1.03077000"],["115541.41000000","0.00000000"],["115543.84000000","0.06000000"],["115545.43000000","0.00243000"],["115545.67000000","0.00000000"],["115546.97000000","0.01053000"],["115548.76000000","0.00000000"],["115549.98000000","0.00000000"],["115549.99000000","0.00000000"],["115552.76000000","0.04664000"],["115553.55000000","0.00000000"],["115553.99000000","0.00000000"],["115555.66000000","0.00000000"],["115557.14000000","0.00000000"],["115557.15000000","0.00000000"],["115560.00000000","0.00251000"],["115561.07000000","0.00000000"],["115579.56000000","0.24334000"],["115581.17000000","0.23970000"],["115592.85000000","0.04597000"],["115595.21000000","0.00000000"],["115595.22000000","0.00000000"],["115595.85000000","0.04597000"],["115596.13000000","0.04597000"],["115597.44000000","0.04597000"],["115598.41000000","0.04597000"],["115600.22000000","0.04597000"],["115601.36000000","0.04597000"],["115607.70000000","0.00105000"],["115607.71000000","0.00000000"],["115607.72000000","0.00000000"],["115618.93000000","0.00086000"],["115620.35000000","0.00000000"],["115630.80000000","0.02600000"],["115652.77000000","0.01646000"],["115680.16000000","0.00000000"],["115701.58000000","0.00000000"],["115711.46000000","0.00000000"],["115711.52000000","0.00000000"],["115734.33000000","0.01646000"],["115736.87000000","0.00000000"],["115741.11000000","0.01645000"],["115746.44000000","0.02198000"],["115752.67000000","0.02203000"],["115755.81000000","0.00000000"],["115757.34000000","0.00000000"],["115760.76000000","0.00009000"],["115764.20000000","0.01732000"],["115766.53000000","0.00009000"],["115772.14000000","0.00000000"],["115772.96000000","0.00000000"],["115775.71000000","0.01646000"],["115787.52000000","0.01732000"],["115787.68000000","0.01732000"],["115788.29000000","0.00000000"],["115790.41000000","0.04071000"],["115791.47000000","0.00000000"],["115796.94000000","0.02398000"],["115798.55000000","0.02398000"],["115805.59000000","0.00000000"],["115809.71000000","0.02338000"],["115809.82000000","0.00000000"],["115812.54000000","0.00000000"],["115813.91000000","0.00000000"],["115814.14000000","0.00000000"],["115819.54000000","0.00000000"],["115830.85000000","0.00000000"],["115831.60000000","0.00000000"],["115831.96000000","0.00000000"],["115832.74000000","0.00000000"],["115832.84000000","0.00000000"],["115836.92000000","0.00000000"],["115838.33000000","0.00000000"],["115840.18000000","0.00000000"],["115840.63000000","0.03198000"],["115840.77000000","0.00000000"],["115841.35000000","0.00000000"],["115844.66000000","0.03198000"],["115845.23000000","0.03198000"],["115845.89000000","0.03198000"],["115846.15000000","0.03611000"],["115852.62000000","0.02252000"],["115855.18000000","0.02252000"],["115856.13000000","0.02252000"],["115867.29000000","0.03198000"],["115867.94000000","0.03198000"],["115870.13000000","0.03198000"],["115870.86000000","0.03198000"],["115871.48000000","0.03198000"],["115872.19000000","0.03198000"],["115872.81000000","0.03198000"],["115873.71000000","0.03198000"],["115999.66000000","0.00005000"],["117153.32000000","0.00000000"],["117166.29000000","0.00100000"],["125075.02000000","0.00000000"]]}
[2025-10-27T18:47:54.378Z] {"e":"depthUpdate","E":1761590874014,"s":"BTCUSDT","U":79129601469,"u":79129601742,"b":[["115434.75000000","6.31154000"],["115433.83000000","0.00010000"],["115433.81000000","0.04045000"],["115433.60000000","0.00010000"],["115433.59000000","0.17339000"],["115432.88000000","0.00010000"],["115432.87000000","0.17339000"],["115432.26000000","0.00000000"],["115432.25000000","0.00000000"],["115431.81000000","0.00005000"],["115431.35000000","0.00005000"],["115431.34000000","0.04406000"],["115431.11000000","0.00000000"],["115431.10000000","0.00000000"],["115430.77000000","0.00000000"],["115430.76000000","0.04767000"],["115429.43000000","0.00000000"],["115428.04000000","0.00000000"],["115427.95000000","0.01713000"],["115425.61000000","0.00000000"],["115425.60000000","0.11626000"],["115423.54000000","0.00000000"],["115421.98000000","1.51184000"],["115420.62000000","0.00000000"],["115419.92000000","0.00005000"],["115418.78000000","0.00005000"],["115418.68000000","0.00005000"],["115417.28000000","0.07000000"],["115414.96000000","0.00866000"],["115414.91000000","0.00000000"],["115409.17000000","0.00000000"],["115408.69000000","0.25975000"],["115400.12000000","0.00008000"],["115398.90000000","0.04331000"],["115398.60000000","0.25975000"],["115397.27000000","0.00000000"],["115390.19000000","0.33265000"],["115387.35000000","0.03683000"],["115377.04000000","0.00020000"],["115365.49000000","0.00008000"],["115365.01000000","0.37994000"],["115362.51000000","0.25975000"],["115354.62000000","0.00000000"],["115352.73000000","0.00000000"],["115352.42000000","0.25975000"],["115351.67000000","0.00000000"],["115347.88000000","0.00000000"],["115339.23000000","0.00000000"],["115338.33000000","0.03025000"],["115330.86000000","0.00008000"],["115325.74000000","0.02813000"],["115318.10000000","0.00000000"],["115311.88000000","0.03000000"],["115296.23000000","0.00008000"],["115295.93000000","0.00000000"],["115283.47000000","0.00000000"],["115274.55000000","0.06000000"],["115266.74000000","0.00000000"],["115261.60000000","0.00008000"],["115251.13000000","0.00000000"],["115250.02000000","0.00192000"],["115250.01000000","0.00000000"],["115248.85000000","0.00000000"],["115132.76000000","0.00077000"],["115118.28000000","0.00000000"],["115000.00000000","5.20508000"],["113703.22000000","0.00100000"],["103890.00000000","0.08110000"],["92347.80000000","0.00021000"]],"a":[["115434.76000000","1.78386000"],["115434.77000000","0.04391000"],["115436.00000000","0.00150000"],["115436.38000000","0.00005000"],["115437.14000000","0.03129000"],["115437.15000000","0.03835000"],["115437.28000000","0.00015000"],["115438.00000000","0.00120000"],["115438.28000000","0.00000000"],["115440.00000000","0.01873000"],["115440.11000000","0.04406000"],["115441.52000000","0.00000000"],["115441.53000000","0.16424000"],["115441.81000000","0.00000000"],["115441.82000000","0.21880000"],["115442.00000000","0.00125000"],["115442.03000000","0.00000000"],["115443.26000000","0.00000000"],["115443.86000000","0.00268000"],["115444.56000000","0.00255000"],["115444.78000000","0.04015000"],["115445.06000000","0.04611000"],["115446.30000000","0.00155000"],["115446.58000000","0.25975000"],["115446.64000000","0.00000000"],["115446.65000000","0.00000000"],["115446.69000000","0.02600000"],["115452.57000000","0.03300000"],["115453.79000000","0.03900000"],["115454.88000000","0.04200000"],["115456.12000000","0.03900000"],["115456.62000000","0.00300000"],["115457.76000000","0.03600000"],["115461.73000000","0.13240000"],["115461.79000000","0.00000000"],["115464.17000000","0.00000000"],["115464.19000000","0.00583000"],["115467.66000000","0.00000000"],["115469.39000000","0.00008000"],["115469.82000000","0.00000000"],["115471.07000000","0.00000000"],["115474.61000000","0.00000000"],["115475.00000000","0.00000000"],["115475.85000000","0.00000000"],["115482.43000000","0.03446000"],["115490.44000000","0.00000000"],["115491.24000000","0.00000000"],["115500.72000000","0.00000000"],["115504.02000000","0.00008000"],["115521.20000000","0.00000000"],["115521.22000000","0.00100000"],["115525.87000000","0.00000000"],["115532.36000000","0.00000000"],["115536.95000000","0.03300000"],["115537.02000000","0.00000000"],["115538.18000000","0.00000000"],["115538.21000000","0.03900000"],["115538.65000000","0.00008000"],["115540.50000000","0.03900000"],["115542.14000000","0.03600000"],["115543.84000000","0.00000000"],["115560.50000000","0.00000000"],["115562.23000000","0.00005000"],["115573.28000000","0.00008000"],["115595.12000000","0.00000000"],["115607.91000000","0.00008000"],["115832.35000000","0.37961000"],["117166.29000000","0.00100000"]]}
[2025-10-27T18:47:55.197Z] {"e":"depthUpdate","E":1761590875014,"s":"BTCUSDT","U":79129601743,"u":79129601883,"b":[["115434.75000000","6.30329000"],["115430.76000000","0.04767000"],["115429.58000000","0.00000000"],["115429.56000000","0.00000000"],["115427.95000000","0.01713000"],["115425.60000000","0.11626000"],["115422.14000000","0.00005000"],["115421.98000000","1.51175000"],["115415.30000000","0.00000000"],["115414.96000000","0.00000000"],["115413.97000000","0.00000000"],["115413.92000000","0.00000000"],["115413.89000000","0.00000000"],["115413.87000000","0.00000000"],["115413.86000000","0.08661000"],["115338.33000000","0.00000000"],["115325.27000000","0.03025000"],["113703.22000000","0.00100000"],["103891.00000000","0.05717000"],["103890.00000000","0.08110000"],["92347.80000000","0.00021000"],["42000.00000000","1.36531000"]],"a":[["115434.76000000","1.65787000"],["115434.77000000","0.04391000"],["115436.00000000","0.00150000"],["115437.13000000","0.00010000"],["115437.14000000","0.03144000"],["115437.15000000","0.03835000"],["115437.27000000","0.00000000"],["115437.28000000","0.00000000"],["115437.53000000","0.00005000"],["115441.82000000","0.31436000"],["115442.00000000","0.00125000"],["115443.86000000","0.00273000"],["115444.00000000","0.00125000"],["115445.05000000","0.54080000"],["115446.30000000","0.00155000"],["115446.58000000","0.00000000"],["115446.69000000","0.00000000"],["115446.71000000","0.02600000"],["115453.26000000","0.00000000"],["115456.59000000","0.00000000"],["115458.08000000","0.90765000"],["115478.03000000","0.03234000"],["115478.46000000","0.00000000"],["115478.57000000","0.06367000"],["115479.14000000","0.00000000"],["115490.75000000","0.01356000"],["115490.85000000","0.25975000"],["115496.44000000","0.00000000"],["115510.96000000","0.30829000"],["115510.97000000","0.00000000"],["115513.38000000","0.43307000"],["115521.21000000","0.00000000"],["115521.22000000","0.00000000"],["115525.31000000","0.00000000"],["115526.25000000","0.03400000"],["115532.36000000","0.04200000"],["115532.85000000","0.00000000"],["115533.80000000","0.02500000"],["115552.15000000","0.00005000"],["115637.35000000","0.00000000"],["115652.08000000","0.00000000"],["115687.38000000","0.00000000"],["115828.55000000","0.37961000"],["115832.35000000","0.00000000"],["117166.29000000","0.00100000"],["123613.51000000","0.00014000"]]}
[2025-10-27T18:47:56.221Z] {"e":"depthUpdate","E":1761590876014,"s":"BTCUSDT","U":79129601884,"u":79129602032,"b":[["115434.75000000","6.30296000"],["115434.74000000","0.00082000"],["115433.81000000","0.04030000"],["115433.60000000","0.00110000"],["115433.59000000","0.17334000"],["115432.87000000","0.17334000"],["115431.87000000","0.00191000"],["115430.76000000","0.04767000"],["115430.14000000","0.00347000"],["115428.46000000","0.20790000"],["115428.45000000","0.25648000"],["115427.95000000","0.01708000"],["115427.83000000","0.00520000"],["115425.60000000","0.00005000"],["115415.06000000","0.00000000"],["115414.25000000","0.00866000"],["115413.86000000","0.00000000"],["115413.85000000","0.00000000"],["115413.84000000","0.04330000"],["115413.83000000","0.00000000"],["115413.82000000","0.00000000"],["115413.81000000","0.00000000"],["115413.80000000","0.08661000"],["115412.17000000","0.00000000"],["115410.44000000","0.00000000"],["115401.09000000","0.93545000"],["115395.19000000","0.00000000"],["115206.52000000","0.01356000"],["115190.25000000","0.00000000"],["115166.28000000","0.00000000"],["114500.00000000","7.94916000"],["114400.00000000","3.75768000"],["113703.22000000","0.00100000"],["106188.23000000","0.00049000"],["103890.00000000","0.08110000"],["92347.80000000","0.00021000"],["92338.00000000","0.00000000"],["50000.00000000","39.61297000"],["33000.00000000","3.79030000"]],"a":[["115434.76000000","1.65599000"],["115434.77000000","0.04401000"],["115435.72000000","0.00000000"],["115437.15000000","0.03840000"],["115437.64000000","0.00191000"],["115440.11000000","0.04411000"],["115441.53000000","0.16424000"],["115441.68000000","0.00525000"],["115443.86000000","0.00278000"],["115444.07000000","0.14000000"],["115444.56000000","0.00260000"],["115444.57000000","0.00381000"],["115446.30000000","0.00843000"],["115459.85000000","0.13240000"],["115461.73000000","0.00000000"],["115464.15000000","0.00583000"],["115464.19000000","0.00000000"],["115478.57000000","0.00000000"],["115478.78000000","0.02498000"],["115478.79000000","0.06591000"],["115490.75000000","0.00000000"],["115517.82000000","0.12946000"],["115521.56000000","0.00100000"],["115521.57000000","0.00100000"],["115526.25000000","0.00000000"],["115526.26000000","0.03400000"],["115533.80000000","0.00000000"],["115533.81000000","0.02500000"],["115535.22000000","0.00000000"],["115664.17000000","0.00000000"],["115815.78000000","0.02498000"],["115816.71000000","0.02498000"],["115817.80000000","0.02498000"],["117166.29000000","0.00100000"]]}
[2025-10-27T18:47:57.245Z] {"e":"depthUpdate","E":1761590877014,"s":"BTCUSDT","U":79129602033,"u":79129602139,"b":[["115434.75000000","6.30162000"],["115428.46000000","0.19245000"],["115428.45000000","0.00000000"],["115428.39000000","0.25648000"],["115427.95000000","0.01708000"],["115421.39000000","0.00324000"],["115421.36000000","0.00000000"],["115415.22000000","0.00005000"],["115413.80000000","0.00000000"],["115413.79000000","0.00000000"],["115413.78000000","0.00000000"],["115413.73000000","0.00000000"],["115413.72000000","0.00000000"],["115413.64000000","0.00000000"],["115413.63000000","0.08661000"],["115406.00000000","0.00120000"],["115404.00000000","0.00120000"],["115402.00000000","0.00120000"],["115400.00000000","0.00130000"],["115398.00000000","0.00120000"],["115396.00000000","0.00120000"],["115394.00000000","0.00120000"],["115348.12000000","0.00000000"],["115234.71000000","0.00010000"],["115182.73000000","4.79501000"],["113703.22000000","0.00100000"],["111944.19000000","0.02176000"],["111933.13000000","0.00000000"],["103891.00000000","0.05717000"],["103890.00000000","0.08110000"],["92347.80000000","0.00021000"],["50000.00000000","39.61267000"],["42000.00000000","1.36431000"]],"a":[["115434.76000000","1.51350000"],["115435.98000000","0.00005000"],["115436.00000000","0.00145000"],["115437.13000000","0.03233000"],["115437.14000000","0.03986000"],["115437.15000000","0.00005000"],["115437.64000000","0.00196000"],["115440.11000000","0.04416000"],["115441.52000000","0.00005000"],["115441.53000000","0.16478000"],["115443.86000000","0.00427000"],["115444.07000000","0.14005000"],["115446.00000000","0.00120000"],["115457.62000000","0.00866000"],["115500.00000000","0.04392000"],["115611.13000000","0.02079000"],["115633.15000000","0.00000000"],["115680.75000000","0.13240000"],["115828.55000000","0.37961000"],["117166.29000000","0.00100000"]]}
[2025-10-27T18:47:58.167Z] {"e":"depthUpdate","E":1761590878014,"s":"BTCUSDT","U":79129602140,"u":79129602608,"b":[["115434.75000000","7.60177000"],["115434.74000000","0.00838000"],["115433.59000000","0.17334000"],["115433.58000000","0.00000000"],["115432.95000000","0.25658000"],["115432.87000000","0.17329000"],["115431.35000000","0.00000000"],["115431.34000000","0.04406000"],["115430.76000000","0.00000000"],["115429.56000000","0.00000000"],["115428.46000000","0.13289000"],["115428.39000000","0.00000000"],["115428.03000000","0.06753000"],["115422.61000000","0.00006000"],["115421.39000000","0.00000000"],["115418.77000000","0.03000000"],["115417.61000000","0.03000000"],["115416.65000000","0.37138000"],["115416.43000000","0.08661000"],["115415.49000000","0.31191000"],["115414.25000000","0.00000000"],["115413.63000000","0.00000000"],["115412.82000000","0.06300000"],["115412.49000000","0.04521000"],["115410.07000000","0.00000000"],["115403.47000000","0.00000000"],["115402.32000000","0.00000000"],["115395.51000000","0.00000000"],["115394.40000000","0.00000000"],["115392.00000000","0.34716000"],["115363.97000000","0.00618000"],["115362.00000000","0.00160000"],["115360.88000000","0.00561000"],["115356.06000000","0.00000000"],["115353.14000000","0.33643000"],["115353.13000000","0.00000000"],["115352.42000000","0.00000000"],["115348.36000000","0.00000000"],["115344.37000000","0.00000000"],["115331.16000000","0.03025000"],["115325.27000000","0.00000000"],["113703.22000000","0.00100000"],["103890.00000000","0.08110000"],["92347.80000000","0.00021000"],["60000.00000000","57.97732000"]],"a":[["115434.76000000","0.17554000"],["115434.77000000","0.04416000"],["115434.84000000","0.00000000"],["115436.00000000","0.00140000"],["115436.98000000","0.00000000"],["115437.09000000","0.00000000"],["115437.12000000","0.00000000"],["115437.13000000","0.00000000"],["115437.14000000","0.00000000"],["115437.50000000","0.00009000"],["115437.64000000","0.00196000"],["115438.00000000","0.00130000"],["115438.09000000","0.00000000"],["115438.47000000","0.03124000"],["115438.48000000","0.03958000"],["115439.30000000","0.00160000"],["115439.78000000","0.00000000"],["115439.79000000","0.00000000"],["115439.98000000","0.00010000"],["115439.99000000","0.00015000"],["115440.00000000","0.01873000"],["115440.11000000","0.04411000"],["115441.51000000","0.00000000"],["115441.52000000","0.18430000"],["115441.53000000","0.14730000"],["115441.66000000","0.00000000"],["115441.67000000","0.00000000"],["115441.68000000","0.00525000"],["115441.82000000","0.00000000"],["115442.11000000","0.00000000"],["115442.82000000","0.28590000"],["115443.86000000","0.00291000"],["115444.00000000","0.00125000"],["115444.07000000","0.02000000"],["115444.56000000","0.00010000"],["115444.78000000","0.04010000"],["115445.05000000","0.00000000"],["115445.06000000","0.00000000"],["115446.00000000","0.00125000"],["115446.37000000","0.00000000"],["115446.71000000","0.00000000"],["115446.72000000","0.00000000"],["115446.79000000","0.00000000"],["115446.80000000","0.02600000"],["115447.92000000","1.06952000"],["115448.34000000","0.00069000"],["115450.61000000","0.04611000"],["115451.38000000","0.25975000"],["115452.47000000","0.28000000"],["115454.38000000","0.00000000"],["115454.74000000","0.00000000"],["115455.90000000","0.07031000"],["115457.62000000","0.00000000"],["115459.85000000","0.00000000"],["115462.26000000","0.00000000"],["115464.15000000","0.00000000"],["115467.66000000","0.00250000"],["115468.57000000","0.00000000"],["115470.68000000","0.05191000"],["115482.96000000","0.00000000"],["115489.66000000","0.01645000"],["115497.95000000","0.00000000"],["115521.56000000","0.00000000"],["115521.57000000","0.00000000"],["115521.58000000","0.00000000"],["115526.26000000","0.00000000"],["115526.31000000","0.00000000"],["115527.31000000","0.03400000"],["115533.81000000","0.00000000"],["115533.86000000","0.00000000"],["115534.86000000","0.02500000"],["115543.99000000","0.02338000"],["115553.64000000","0.00000000"],["115582.95000000","0.16123000"],["115620.68000000","0.00000000"],["115621.45000000","0.00000000"],["115646.45000000","0.01645000"],["115650.16000000","0.01645000"],["115656.39000000","0.01356000"],["115680.75000000","0.00000000"],["115709.49000000","0.01645000"],["115734.67000000","0.01645000"],["115737.51000000","0.00000000"],["115757.24000000","0.00009000"],["115757.87000000","0.00000000"],["115766.53000000","0.00000000"],["115773.08000000","0.01645000"],["115779.65000000","0.00000000"],["115779.66000000","0.00000000"],["115785.71000000","0.01732000"],["115788.40000000","0.00000000"],["115799.36000000","0.02398000"],["115800.22000000","0.02398000"],["115809.77000000","0.02338000"],["115822.78000000","0.00000000"],["115856.15000000","0.02252000"],["117166.29000000","0.00100000"]]}
