[2025-10-26T09:47:37.017Z] Snapshot loaded successfully.
[2025-10-26T09:47:40.439Z] WebSocket connected successfully.
[2025-10-26T09:47:41.155Z] {"e":"depthUpdate","E":1761472060014,"s":"BTCUSDT","U":79058028554,"u":79058028931,"b":[["112496.07000000","1.42205000"],["112496.06000000","0.00085000"],["112495.45000000","0.03150000"],["112493.26000000","0.00201000"],["112491.01000000","0.56873000"],["112490.45000000","0.00000000"],["112490.44000000","0.00000000"],["112489.69000000","0.00000000"],["112489.68000000","0.00000000"],["112489.54000000","0.00000000"],["112489.53000000","0.00000000"],["112489.33000000","0.00538000"],["112488.17000000","0.00000000"],["112488.16000000","0.00000000"],["112487.04000000","0.00000000"],["112487.03000000","0.00000000"],["112486.79000000","0.00000000"],["112486.78000000","0.00000000"],["112486.69000000","0.00010000"],["112486.68000000","0.15308000"],["112486.67000000","0.00000000"],["112486.43000000","0.00010000"],["112486.42000000","0.29337000"],["112486.39000000","0.00000000"],["112486.38000000","0.00000000"],["112485.60000000","0.00000000"],["112485.39000000","0.00005000"],["112485.38000000","0.09029000"],["112485.25000000","0.08892000"],["112484.82000000","0.22255000"],["112484.52000000","0.04578000"],["112484.50000000","0.06010000"],["112484.12000000","0.08887000"],["112484.04000000","0.00000000"],["112483.84000000","0.04904000"],["112483.17000000","0.00000000"],["112483.13000000","0.00000000"],["112482.89000000","0.00000000"],["112482.84000000","0.00000000"],["112479.75000000","0.00300000"],["112479.67000000","0.00005000"],["112476.84000000","0.04376000"],["112476.00000000","0.06100000"],["112473.57000000","0.31500000"],["112469.87000000","0.00000000"],["112469.55000000","0.00005000"],["112469.25000000","0.00000000"],["112465.22000000","0.00000000"],["112456.05000000","0.00005000"],["112446.75000000","0.95924000"],["112445.57000000","0.00000000"],["112445.30000000","0.34138000"],["112440.55000000","0.34766000"],["112439.51000000","0.00000000"],["112400.00000000","0.00175000"],["112362.35000000","0.00000000"],["112359.00000000","0.00000000"],["112358.31000000","0.09675000"],["112350.97000000","0.00000000"],["112324.45000000","0.00304000"],["112307.50000000","0.00000000"],["110808.62000000","0.00100000"],["101246.00000000","0.00010000"],["89996.86000000","0.00022000"],["42000.00000000","1.40412000"]],"a":[["112496.08000000","2.93509000"],["112496.25000000","0.29335000"],["112497.93000000","0.00010000"],["112497.94000000","0.04578000"],["112498.45000000","0.00000000"],["112498.46000000","0.00000000"],["112501.12000000","0.00005000"],["112501.13000000","0.08971000"],["112502.20000000","0.00510000"],["112505.30000000","0.00040000"],["112505.41000000","0.00010000"],["112506.00000000","0.00170000"],["112507.32000000","0.00716000"],["112507.33000000","0.00000000"],["112507.90000000","0.00156000"],["112509.01000000","0.00161000"],["112512.96000000","0.10640000"],["112515.84000000","0.00044000"],["112521.67000000","0.00000000"],["112523.15000000","0.00005000"],["112523.65000000","0.01256000"],["112523.96000000","0.00000000"],["112524.48000000","0.00000000"],["112524.63000000","0.00000000"],["112525.27000000","0.00000000"],["112529.83000000","1.06795000"],["112530.67000000","0.00000000"],["112537.25000000","0.00000000"],["112538.04000000","0.00000000"],["112539.43000000","0.03460000"],["112547.65000000","0.00306000"],["112550.00000000","0.07877000"],["112550.88000000","0.04091000"],["112560.00000000","0.38061000"],["112565.51000000","0.00000000"],["112570.00000000","0.09160000"],["112574.84000000","0.00000000"],["112574.91000000","0.00000000"],["112575.18000000","0.35608000"],["112575.41000000","0.00005000"],["112575.48000000","0.71187000"],["112579.84000000","0.04416000"],["112581.11000000","0.44452000"],["112943.93000000","0.02598000"],["112945.41000000","0.02598000"],["112946.09000000","0.02598000"],["114183.53000000","0.00100000"]]}
[2025-10-26T09:47:42.055Z] {"e":"depthUpdate","E":1761472061014,"s":"BTCUSDT","U":79058028932,"u":79058029513,"b":[["112496.07000000","3.12843000"],["112496.06000000","0.00055000"],["112495.47000000","0.00010000"],["112495.46000000","0.09801000"],["112495.45000000","0.03145000"],["112494.95000000","0.00108000"],["112494.51000000","0.20484000"],["112494.50000000","0.00010000"],["112494.49000000","0.29335000"],["112493.60000000","0.00356000"],["112493.19000000","0.05209000"],["112491.52000000","0.00000000"],["112491.51000000","0.00000000"],["112491.23000000","0.01802000"],["112491.03000000","0.00010000"],["112491.02000000","0.25472000"],["112491.01000000","0.56868000"],["112491.00000000","0.00255000"],["112490.63000000","0.00005000"],["112489.33000000","0.00543000"],["112489.08000000","0.00000000"],["112488.95000000","0.00000000"],["112488.94000000","0.00000000"],["112488.92000000","0.00000000"],["112488.91000000","0.00000000"],["112487.90000000","0.00000000"],["112487.89000000","0.08897000"],["112486.77000000","0.00000000"],["112486.76000000","0.08897000"],["112486.75000000","0.00000000"],["112486.69000000","0.00000000"],["112486.68000000","0.44265000"],["112486.50000000","0.00255000"],["112486.43000000","0.00000000"],["112486.42000000","0.00000000"],["112486.40000000","0.46938000"],["112485.39000000","0.00000000"],["112485.38000000","0.00118000"],["112485.32000000","0.00000000"],["112485.25000000","0.00000000"],["112484.82000000","0.31500000"],["112484.52000000","0.04573000"],["112484.50000000","0.06000000"],["112484.12000000","0.00000000"],["112483.84000000","0.00000000"],["112483.61000000","0.00005000"],["112483.44000000","0.00000000"],["112483.15000000","0.00000000"],["112482.94000000","0.46938000"],["112482.79000000","0.00000000"],["112482.75000000","0.00000000"],["112482.33000000","0.00000000"],["112482.28000000","0.00000000"],["112482.00000000","0.22510000"],["112481.74000000","0.00000000"],["112481.46000000","0.67637000"],["112481.45000000","0.10397000"],["112480.90000000","0.00128000"],["112479.77000000","0.00300000"],["112478.08000000","1.70701000"],["112475.35000000","0.03681000"],["112474.16000000","0.00000000"],["112472.19000000","0.06748000"],["112471.81000000","0.00000000"],["112471.19000000","0.00000000"],["112470.38000000","0.00000000"],["112468.92000000","0.27939000"],["112466.97000000","0.04200000"],["112466.26000000","0.32005000"],["112464.00000000","0.00120000"],["112460.51000000","0.32006000"],["112452.12000000","0.00005000"],["112449.95000000","0.30694000"],["112448.75000000","0.02598000"],["112448.48000000","0.02984000"],["112442.97000000","0.00000000"],["112440.55000000","0.00000000"],["112440.54000000","0.00000000"],["112417.50000000","0.02488000"],["112417.19000000","0.00000000"],["112411.79000000","0.02359000"],["112397.40000000","0.00000000"],["112390.58000000","0.00000000"],["112340.22000000","0.00177000"],["112332.23000000","0.00304000"],["112328.99000000","0.00355000"],["112324.45000000","0.00000000"],["112312.01000000","0.00000000"],["112297.27000000","0.00000000"],["112214.10000000","0.00000000"],["112201.23000000","0.00000000"],["112188.95000000","0.00000000"],["112144.38000000","0.00000000"],["112129.74000000","0.00464000"],["112048.50000000","0.00000000"],["111921.08000000","0.00008000"],["110808.62000000","0.00100000"],["110095.45000000","0.00000000"],["101246.00000000","0.00010000"],["89996.86000000","0.00022000"]],"a":[["112496.08000000","1.00234000"],["112496.09000000","0.00040000"],["112496.23000000","0.00000000"],["112496.24000000","0.00000000"],["112496.25000000","0.00000000"],["112496.84000000","0.00000000"],["112496.88000000","0.00277000"],["112496.98000000","0.00000000"],["112497.94000000","0.04578000"],["112498.27000000","0.00000000"],["112499.85000000","0.00000000"],["112499.99000000","0.00010000"],["112500.00000000","0.50010000"],["112501.12000000","0.00010000"],["112501.95000000","0.00000000"],["112502.00000000","0.00000000"],["112502.20000000","0.00005000"],["112502.25000000","0.00000000"],["112502.27000000","0.00037000"],["112502.28000000","0.00005000"],["112504.17000000","0.00010000"],["112504.18000000","0.03791000"],["112504.39000000","0.00000000"],["112505.40000000","0.00000000"],["112505.41000000","0.00005000"],["112505.42000000","0.00010000"],["112505.50000000","0.00000000"],["112505.55000000","0.00005000"],["112505.66000000","0.02000000"],["112505.88000000","0.00000000"],["112509.72000000","0.00039000"],["112510.99000000","0.00000000"],["112514.66000000","0.00000000"],["112514.99000000","0.00444000"],["112516.65000000","0.00000000"],["112517.06000000","0.00450000"],["112519.08000000","0.00000000"],["112521.12000000","0.00000000"],["112522.39000000","0.00000000"],["112523.22000000","0.00000000"],["112523.65000000","0.00000000"],["112524.41000000","0.00000000"],["112524.56000000","0.00000000"],["112524.75000000","0.00000000"],["112524.99000000","0.00000000"],["112525.91000000","0.00000000"],["112526.81000000","0.00000000"],["112527.00000000","0.00250000"],["112527.99000000","0.00000000"],["112528.26000000","0.26728000"],["112529.25000000","0.02598000"],["112529.26000000","0.00000000"],["112529.85000000","0.00005000"],["112530.09000000","0.04480000"],["112530.88000000","0.00000000"],["112531.65000000","0.00000000"],["112531.98000000","0.00000000"],["112532.61000000","0.00000000"],["112532.94000000","0.26730000"],["112533.35000000","0.00000000"],["112533.71000000","0.00000000"],["112536.37000000","0.00000000"],["112539.43000000","0.00000000"],["112540.25000000","0.00006000"],["112546.57000000","0.31982000"],["112547.34000000","0.02488000"],["112547.65000000","0.00000000"],["112549.35000000","0.02488000"],["112550.00000000","0.03877000"],["112551.64000000","0.02488000"],["112553.06000000","0.00000000"],["112554.50000000","0.02488000"],["112555.45000000","0.00306000"],["112557.14000000","0.00000000"],["112557.88000000","0.02488000"],["112560.00000000","0.02061000"],["112561.99000000","0.02488000"],["112562.06000000","0.00000000"],["112563.68000000","0.02488000"],["112564.08000000","0.00000000"],["112570.00000000","0.00160000"],["112571.89000000","0.02488000"],["112573.26000000","0.26728000"],["112575.18000000","0.00000000"],["112575.48000000","0.00000000"],["112576.51000000","0.26677000"],["112576.98000000","0.35608000"],["112577.05000000","0.44510000"],["112577.94000000","0.26730000"],["112579.83000000","0.02488000"],["112584.55000000","0.00000000"],["112584.56000000","0.00000000"],["112589.59000000","0.03460000"],["112590.67000000","0.00000000"],["112645.97000000","0.00000000"],["112651.89000000","0.69990000"],["112654.21000000","0.13511000"],["112682.60000000","0.00000000"],["112688.20000000","0.01600000"],["112695.68000000","0.00000000"],["112702.33000000","0.01777000"],["112707.43000000","0.00000000"],["112717.01000000","0.01777000"],["112718.97000000","0.00000000"],["112721.99000000","0.00000000"],["112728.77000000","0.01777000"],["112740.26000000","0.01777000"],["112742.70000000","0.00000000"],["112743.74000000","0.01777000"],["112744.29000000","0.00000000"],["112756.26000000","0.00000000"],["112761.56000000","0.00000000"],["112763.31000000","0.00010000"],["112764.84000000","0.01866000"],["112767.35000000","0.01866000"],["112769.00000000","0.00080000"],["112775.46000000","0.00000000"],["112775.99000000","0.00000000"],["112776.39000000","0.00000000"],["112786.40000000","0.00000000"],["112791.28000000","0.00000000"],["112795.32000000","0.00000000"],["112798.72000000","0.00000000"],["112798.73000000","0.01688000"],["112799.80000000","0.00000000"],["112806.03000000","0.02400000"],["112808.81000000","0.01688000"],["112810.59000000","0.00024000"],["112812.23000000","0.00000000"],["112813.70000000","0.01688000"],["112813.87000000","0.00000000"],["112814.09000000","0.02400000"],["112817.93000000","0.01688000"],["112818.02000000","0.00000000"],["112821.75000000","0.01688000"],["112828.82000000","0.02400000"],["112832.04000000","0.00000000"],["112842.17000000","0.02400000"],["112842.53000000","0.02400000"],["112842.92000000","0.00000000"],["112844.18000000","0.02400000"],["112846.08000000","0.02400000"],["112847.48000000","0.02400000"],["112850.47000000","0.02818000"],["112852.72000000","0.00000000"],["112854.94000000","0.00000000"],["112856.07000000","0.02400000"],["112856.34000000","0.00000000"],["112858.31000000","0.00000000"],["112866.35000000","0.02400000"],["112876.39000000","0.02400000"],["112881.86000000","0.02400000"],["112883.74000000","0.02400000"],["112946.24000000","0.02598000"],["112997.26000000","0.31500000"],["113000.00000000","27.30763000"],["114183.53000000","0.00100000"]]}
[2025-10-26T09:47:43.062Z] {"e":"depthUpdate","E":1761472062014,"s":"BTCUSDT","U":79058029514,"u":79058030324,"b":[["112496.07000000","3.10049000"],["112496.06000000","0.00000000"],["112496.01000000","0.00185000"],["112495.50000000","0.00275000"],["112495.47000000","0.00010000"],["112495.46000000","0.09826000"],["112495.45000000","0.03140000"],["112494.95000000","0.00098000"],["112494.52000000","0.00000000"],["112494.51000000","0.00000000"],["112494.50000000","0.00010000"],["112494.49000000","0.29340000"],["112494.21000000","0.08887000"],["112493.60000000","0.00000000"],["112493.39000000","0.00000000"],["112493.38000000","0.00000000"],["112493.26000000","0.00196000"],["112493.20000000","0.00000000"],["112493.19000000","0.00000000"],["112493.04000000","0.00000000"],["112491.60000000","0.00000000"],["112491.59000000","0.00000000"],["112491.58000000","0.00000000"],["112491.23000000","0.00005000"],["112491.05000000","0.00010000"],["112491.04000000","0.44209000"],["112491.03000000","0.00000000"],["112491.02000000","0.00005000"],["112491.01000000","0.56868000"],["112491.00000000","0.00260000"],["112490.69000000","0.46943000"],["112490.63000000","0.00000000"],["112490.44000000","0.22260000"],["112489.33000000","0.00000000"],["112488.99000000","0.05099000"],["112487.89000000","0.00005000"],["112487.54000000","0.00005000"],["112486.77000000","0.00444000"],["112486.76000000","0.08902000"],["112486.68000000","0.89925000"],["112486.51000000","0.00391000"],["112486.50000000","0.00260000"],["112485.79000000","0.29991000"],["112485.78000000","0.06753000"],["112485.45000000","0.01753000"],["112485.38000000","0.00123000"],["112485.21000000","0.00200000"],["112484.83000000","0.00000000"],["112484.50000000","0.06010000"],["112483.80000000","1.70701000"],["112483.35000000","0.04372000"],["112483.21000000","0.26730000"],["112482.00000000","0.00250000"],["112481.93000000","0.04000000"],["112481.64000000","0.00005000"],["112481.46000000","0.95281000"],["112481.45000000","0.10392000"],["112480.90000000","0.00128000"],["112480.65000000","0.00000000"],["112480.55000000","0.00000000"],["112480.38000000","0.15146000"],["112480.18000000","0.26683000"],["112479.77000000","0.00300000"],["112479.52000000","0.04150000"],["112479.30000000","0.26728000"],["112479.18000000","0.00000000"],["112478.81000000","0.00000000"],["112477.93000000","0.00000000"],["112477.87000000","0.15120000"],["112477.32000000","0.00888000"],["112476.84000000","0.00000000"],["112476.16000000","0.00000000"],["112475.83000000","0.00000000"],["112475.82000000","0.00000000"],["112475.81000000","0.00000000"],["112475.35000000","0.00000000"],["112474.81000000","0.00000000"],["112474.41000000","0.01256000"],["112473.00000000","0.00000000"],["112472.80000000","0.03300000"],["112472.13000000","0.00009000"],["112472.06000000","0.00000000"],["112472.03000000","0.00009000"],["112471.87000000","0.00000000"],["112470.08000000","0.00000000"],["112469.14000000","0.24000000"],["112469.08000000","0.00000000"],["112468.94000000","0.00000000"],["112468.92000000","0.00000000"],["112468.84000000","0.00000000"],["112467.89000000","0.00000000"],["112467.80000000","0.15133000"],["112467.30000000","0.00009000"],["112466.44000000","0.02000000"],["112466.14000000","0.04000000"],["112466.01000000","0.00000000"],["112465.32000000","0.00009000"],["112465.07000000","0.15157000"],["112463.83000000","0.00000000"],["112463.73000000","0.00000000"],["112461.12000000","0.26677000"],["112459.08000000","0.00000000"],["112459.00000000","0.00000000"],["112457.63000000","0.00009000"],["112457.02000000","0.00000000"],["112454.79000000","0.00000000"],["112454.17000000","0.00000000"],["112452.69000000","0.32009000"],["112449.73000000","0.03778000"],["112449.33000000","0.00000000"],["112449.10000000","0.00000000"],["112448.48000000","0.00000000"],["112447.14000000","0.00000000"],["112446.53000000","0.00000000"],["112443.65000000","0.24681000"],["112437.58000000","0.26730000"],["112435.84000000","0.00000000"],["112435.51000000","0.26683000"],["112435.31000000","0.02984000"],["112433.90000000","0.26728000"],["112433.57000000","0.02224000"],["112432.44000000","0.00005000"],["112430.00000000","0.00140000"],["112426.36000000","0.22209000"],["112426.07000000","0.00000000"],["112425.24000000","0.00000000"],["112424.63000000","0.80195000"],["112422.58000000","0.00000000"],["112420.61000000","0.00707000"],["112420.57000000","0.00000000"],["112420.00000000","0.00140000"],["112417.78000000","0.00000000"],["112416.12000000","0.26677000"],["112415.82000000","0.00000000"],["112415.73000000","0.44452000"],["112414.01000000","0.13292000"],["112413.71000000","0.00000000"],["112413.51000000","0.55293000"],["112413.50000000","0.00000000"],["112412.31000000","0.03598000"],["112410.01000000","0.03598000"],["112408.40000000","0.00000000"],["112408.23000000","0.03598000"],["112408.12000000","0.00000000"],["112408.04000000","0.36090000"],["112405.30000000","0.00000000"],["112404.28000000","0.36091000"],["112403.75000000","0.00000000"],["112402.84000000","0.00000000"],["112393.17000000","0.00000000"],["112389.63000000","0.00000000"],["112379.74000000","0.00000000"],["112359.00000000","0.00005000"],["112340.02000000","0.02409000"],["112336.56000000","0.00005000"],["112336.55000000","0.00020000"],["112330.97000000","0.06748000"],["112314.12000000","0.00000000"],["112309.90000000","0.00000000"],["112308.04000000","0.03598000"],["112307.81000000","0.00000000"],["112307.35000000","0.00000000"],["112306.02000000","0.00000000"],["112306.01000000","0.00000000"],["112249.26000000","4.63410000"],["112243.33000000","0.00567000"],["112243.32000000","0.00000000"],["112227.01000000","0.00000000"],["112208.60000000","0.02598000"],["112207.44000000","0.01688000"],["112193.29000000","0.00000000"],["112185.03000000","0.03298000"],["112184.09000000","0.02398000"],["112183.22000000","0.03298000"],["112181.10000000","0.03298000"],["112179.81000000","0.03298000"],["112178.51000000","0.03298000"],["112109.70000000","0.00000000"],["112086.83000000","0.00000000"],["112079.67000000","0.00000000"],["112079.26000000","0.00000000"],["112078.49000000","0.00000000"],["112075.54000000","0.00000000"],["112075.23000000","0.00000000"],["112070.58000000","0.00000000"],["112038.27000000","0.02998000"],["112036.40000000","0.00000000"],["112035.04000000","0.00000000"],["112034.69000000","0.00490000"],["112034.02000000","0.00000000"],["112033.25000000","0.00000000"],["112032.38000000","0.00000000"],["112031.28000000","0.00000000"],["111941.77000000","0.00000000"],["111939.22000000","0.00000000"],["111923.90000000","0.00000000"],["111921.08000000","0.00000000"],["111920.79000000","0.00000000"],["110808.62000000","0.00100000"],["103435.13000000","0.00010000"],["101246.46000000","0.00000000"],["101246.00000000","0.00010000"],["89997.00000000","0.00100000"],["89996.86000000","0.00022000"],["89978.86000000","0.00000000"],["40498.59000000","0.00045000"],["33000.01000000","0.00000000"],["33000.00000000","3.78938000"],["32993.41000000","0.00029000"]],"a":[["112496.08000000","0.64551000"],["112496.09000000","0.00030000"],["112496.16000000","0.00010000"],["112496.88000000","0.00000000"],["112497.20000000","0.00098000"],["112497.64000000","0.00000000"],["112497.69000000","0.00000000"],["112497.93000000","0.00000000"],["112497.94000000","0.00000000"],["112498.75000000","0.00000000"],["112498.89000000","0.00201000"],["112499.77000000","0.00010000"],["112499.78000000","0.29334000"],["112500.00000000","0.50010000"],["112500.04000000","0.00000000"],["112500.05000000","0.00000000"],["112500.57000000","0.00356000"],["112501.12000000","0.00000000"],["112501.13000000","0.00005000"],["112501.70000000","0.00156000"],["112502.05000000","0.00010000"],["112502.06000000","0.04578000"],["112502.20000000","0.00000000"],["112502.29000000","0.00000000"],["112502.30000000","0.00000000"],["112502.65000000","0.00000000"],["112502.82000000","0.00538000"],["112503.23000000","0.00010000"],["112503.24000000","0.05299000"],["112504.13000000","0.00000000"],["112504.17000000","0.00000000"],["112504.18000000","0.03781000"],["112504.50000000","0.00000000"],["112505.09000000","0.00121000"],["112505.55000000","0.00000000"],["112505.56000000","0.00000000"],["112505.64000000","0.00391000"],["112505.66000000","0.00000000"],["112506.00000000","0.00160000"],["112507.15000000","0.00000000"],["112507.16000000","0.00000000"],["112507.32000000","0.00005000"],["112507.51000000","0.00000000"],["112508.00000000","0.00170000"],["112508.05000000","0.00000000"],["112508.06000000","0.00000000"],["112508.61000000","0.01882000"],["112508.62000000","0.03005000"],["112509.01000000","0.00000000"],["112509.74000000","0.00000000"],["112509.91000000","0.00000000"],["112509.99000000","0.00069000"],["112510.46000000","0.00010000"],["112511.26000000","0.00072000"],["112511.29000000","0.00000000"],["112511.32000000","0.20484000"],["112511.41000000","0.40039000"],["112511.45000000","0.00329000"],["112511.48000000","0.00000000"],["112511.96000000","0.30696000"],["112512.96000000","0.00000000"],["112513.54000000","0.00000000"],["112513.85000000","0.00000000"],["112513.99000000","1.70701000"],["112514.99000000","0.00000000"],["112515.16000000","0.00000000"],["112515.84000000","0.00000000"],["112517.02000000","0.00000000"],["112518.20000000","0.00000000"],["112518.58000000","0.10640000"],["112518.84000000","0.00444000"],["112518.96000000","0.00200000"],["112519.59000000","0.00000000"],["112519.66000000","1.70701000"],["112520.32000000","0.04000000"],["112520.92000000","0.00000000"],["112521.82000000","0.00000000"],["112522.18000000","0.00000000"],["112522.50000000","0.00250000"],["112524.83000000","0.00000000"],["112525.95000000","0.15146000"],["112528.24000000","0.17706000"],["112528.25000000","0.29989000"],["112529.16000000","0.00888000"],["112530.09000000","0.00000000"],["112531.02000000","0.04480000"],["112531.50000000","0.26683000"],["112532.56000000","0.31986000"],["112533.13000000","0.00000000"],["112536.32000000","0.00000000"],["112536.55000000","0.00005000"],["112539.19000000","0.00000000"],["112539.63000000","0.15094000"],["112539.99000000","0.00000000"],["112541.99000000","0.00000000"],["112544.83000000","0.00000000"],["112544.90000000","0.03770000"],["112546.99000000","0.18645000"],["112547.99000000","0.00000000"],["112548.36000000","0.01866000"],["112548.37000000","0.00000000"],["112550.88000000","0.00000000"],["112551.07000000","0.00000000"],["112551.44000000","0.31981000"],["112555.98000000","0.00000000"],["112559.50000000","0.36041000"],["112563.26000000","0.36040000"],["112564.41000000","0.00000000"],["112565.39000000","0.00616000"],["112567.44000000","0.02488000"],["112567.47000000","0.06748000"],["112567.94000000","0.04091000"],["112571.40000000","0.02488000"],["112576.50000000","0.26683000"],["112577.52000000","0.02488000"],["112579.84000000","0.00000000"],["112581.10000000","0.46938000"],["112584.26000000","0.02488000"],["112586.06000000","0.03600000"],["112586.07000000","0.00000000"],["112588.75000000","0.03460000"],["112588.91000000","0.00000000"],["112589.59000000","0.00000000"],["112590.73000000","0.00000000"],["112591.68000000","0.00000000"],["112591.73000000","0.00000000"],["112592.68000000","0.00000000"],["112592.73000000","0.00000000"],["112592.78000000","0.03400000"],["112594.97000000","0.04386000"],["112602.68000000","0.00000000"],["112621.02000000","0.00000000"],["112631.24000000","1.70701000"],["112640.13000000","0.01866000"],["112640.47000000","0.08604000"],["112654.21000000","0.00000000"],["112660.79000000","0.47523000"],["112665.24000000","0.00000000"],["112684.98000000","0.01866000"],["112738.90000000","0.00000000"],["112751.26000000","0.00000000"],["112751.46000000","4.85258000"],["112771.90000000","0.01866000"],["112773.95000000","0.24292000"],["112774.99000000","0.00000000"],["112777.70000000","0.01866000"],["112779.17000000","0.00000000"],["112790.89000000","0.01866000"],["112797.94000000","0.02598000"],["112803.53000000","0.01866000"],["112824.36000000","0.00000000"],["112825.42000000","0.00000000"],["112853.05000000","0.02400000"],["112855.10000000","0.02400000"],["112860.43000000","0.00000000"],["112860.54000000","0.00000000"],["112870.46000000","0.02498000"],["112875.74000000","0.00000000"],["112876.91000000","0.00000000"],["112877.62000000","0.00000000"],["112888.83000000","0.02699000"],["112891.36000000","0.02411000"],["112902.14000000","0.03298000"],["112903.80000000","0.03298000"],["112905.08000000","0.03298000"],["114183.53000000","0.00100000"]]}
[2025-10-26T09:47:44.122Z] {"e":"depthUpdate","E":1761472063014,"s":"BTCUSDT","U":79058030325,"u":79058031199,"b":[["112496.07000000","3.69783000"],["112496.06000000","0.00045000"],["112496.01000000","0.00185000"],["112495.50000000","0.00000000"],["112495.47000000","0.00010000"],["112495.46000000","0.07253000"],["112495.45000000","0.03145000"],["112494.95000000","0.00098000"],["112494.82000000","0.00000000"],["112494.81000000","0.00000000"],["112494.50000000","0.00000000"],["112494.49000000","0.00000000"],["112494.22000000","0.00005000"],["112494.21000000","0.00000000"],["112493.95000000","0.00000000"],["112493.94000000","0.00000000"],["112493.77000000","0.08887000"],["112493.58000000","0.00000000"],["112493.56000000","0.00717000"],["112493.26000000","0.00196000"],["112493.07000000","0.00010000"],["112493.06000000","0.20494000"],["112492.94000000","0.00000000"],["112492.93000000","0.00000000"],["112492.66000000","0.00005000"],["112492.29000000","0.00010000"],["112492.28000000","0.22522000"],["112492.27000000","0.00000000"],["112491.61000000","0.00010000"],["112491.60000000","0.04578000"],["112491.36000000","0.00000000"],["112491.23000000","0.00000000"],["112491.05000000","0.00000000"],["112491.04000000","0.00000000"],["112491.03000000","0.00000000"],["112491.02000000","0.29336000"],["112491.01000000","0.56868000"],["112491.00000000","0.00005000"],["112490.78000000","0.00000000"],["112490.69000000","0.00000000"],["112490.44000000","0.00000000"],["112488.99000000","0.00000000"],["112488.91000000","0.00000000"],["112486.77000000","0.00000000"],["112486.76000000","0.08902000"],["112486.68000000","0.44265000"],["112486.50000000","0.00255000"],["112486.40000000","0.46938000"],["112485.79000000","0.00000000"],["112485.78000000","0.00000000"],["112485.45000000","0.00000000"],["112485.44000000","0.00000000"],["112485.38000000","0.00113000"],["112485.21000000","0.00000000"],["112484.92000000","0.00000000"],["112484.82000000","0.53755000"],["112484.52000000","0.00000000"],["112484.50000000","0.06010000"],["112484.01000000","0.00000000"],["112483.80000000","0.00000000"],["112483.65000000","0.05301000"],["112483.35000000","0.04387000"],["112483.21000000","0.00000000"],["112482.45000000","0.00200000"],["112482.18000000","0.00000000"],["112482.01000000","0.00444000"],["112482.00000000","0.00255000"],["112481.93000000","0.00000000"],["112481.74000000","0.00000000"],["112481.45000000","0.10397000"],["112480.90000000","0.00128000"],["112480.53000000","0.00000000"],["112480.39000000","0.29993000"],["112480.18000000","0.00000000"],["112479.54000000","0.01735000"],["112479.30000000","0.00000000"],["112478.03000000","0.04000000"],["112477.32000000","0.00000000"],["112474.60000000","0.00888000"],["112474.41000000","0.00000000"],["112473.00000000","0.00250000"],["112472.13000000","0.00000000"],["112472.03000000","0.00000000"],["112471.47000000","0.03000000"],["112471.10000000","0.26730000"],["112469.43000000","0.00009000"],["112469.33000000","0.00009000"],["112469.14000000","0.00000000"],["112468.50000000","0.00250000"],["112468.17000000","0.01256000"],["112468.04000000","0.00000000"],["112467.30000000","0.00000000"],["112467.29000000","0.26683000"],["112467.00000000","0.26728000"],["112466.26000000","0.00000000"],["112466.14000000","0.00000000"],["112465.32000000","0.00000000"],["112464.73000000","0.00000000"],["112464.60000000","0.00009000"],["112464.45000000","1.26504000"],["112464.44000000","0.12000000"],["112462.85000000","0.00005000"],["112462.62000000","0.00009000"],["112462.34000000","0.16000000"],["112460.01000000","0.00000000"],["112457.63000000","0.00000000"],["112454.93000000","0.00009000"],["112454.38000000","0.00177000"],["112452.70000000","0.47194000"],["112452.34000000","0.34136000"],["112449.95000000","0.00000000"],["112447.26000000","0.32010000"],["112445.30000000","0.00000000"],["112443.66000000","0.03300000"],["112435.31000000","0.00000000"],["112424.22000000","0.02984000"],["112420.61000000","0.00618000"],["112417.91000000","0.00089000"],["112411.79000000","0.00000000"],["112406.28000000","0.66310000"],["112396.48000000","0.02359000"],["112386.89000000","0.00000000"],["112378.85000000","0.00360000"],["112373.46000000","0.00000000"],["112372.18000000","0.00000000"],["112369.95000000","0.00005000"],["112369.05000000","0.00000000"],["112365.70000000","0.00010000"],["112347.16000000","0.06000000"],["112332.23000000","0.00000000"],["112326.37000000","0.00304000"],["112317.40000000","0.00000000"],["112314.12000000","0.06748000"],["112310.59000000","0.19018000"],["112250.00000000","0.16658000"],["112122.67000000","0.02498000"],["112122.13000000","0.02498000"],["112121.82000000","0.02498000"],["112120.65000000","0.02498000"],["112118.64000000","0.02498000"],["112118.28000000","0.02498000"],["112117.82000000","0.02498000"],["112115.96000000","0.02504000"],["112114.97000000","0.02498000"],["112114.11000000","0.02498000"],["111920.92000000","0.00000000"],["111918.06000000","0.00000000"],["111445.75000000","0.00250000"],["111423.46000000","0.00089000"],["110808.62000000","0.00100000"],["103435.13000000","0.00000000"],["101246.46000000","0.00019000"],["101246.00000000","0.00010000"],["101225.75000000","0.00000000"],["89996.86000000","0.00022000"],["60000.01000000","0.04846000"],["60000.00000000","57.64892000"],["42000.00000000","1.40312000"],["32993.41000000","0.00000000"]],"a":[["112496.08000000","1.55149000"],["112496.09000000","0.00005000"],["112496.14000000","0.00010000"],["112496.15000000","0.29335000"],["112496.57000000","0.00000000"],["112496.58000000","0.00000000"],["112497.08000000","0.00000000"],["112497.09000000","0.00000000"],["112499.76000000","0.00010000"],["112499.77000000","0.19380000"],["112499.78000000","0.00000000"],["112500.00000000","0.50010000"],["112500.57000000","0.00361000"],["112501.46000000","0.01809000"],["112501.70000000","0.00161000"],["112501.99000000","0.00000000"],["112502.00000000","0.00000000"],["112502.04000000","0.00356000"],["112502.05000000","0.00010000"],["112502.06000000","0.04573000"],["112502.53000000","0.00000000"],["112502.55000000","0.00000000"],["112502.56000000","0.00000000"],["112502.59000000","0.00005000"],["112502.60000000","0.20484000"],["112503.05000000","0.00020000"],["112503.23000000","0.00000000"],["112503.24000000","0.05222000"],["112503.50000000","0.00000000"],["112504.17000000","0.00000000"],["112504.18000000","0.03796000"],["112504.50000000","0.00255000"],["112504.52000000","0.10640000"],["112505.42000000","0.00000000"],["112506.00000000","0.00165000"],["112507.65000000","0.01981000"],["112507.66000000","0.00000000"],["112508.00000000","0.00165000"],["112508.61000000","0.00000000"],["112508.62000000","0.03000000"],["112511.32000000","0.00000000"],["112512.27000000","0.06748000"],["112513.50000000","0.06350000"],["112513.93000000","0.46938000"],["112513.94000000","0.00000000"],["112516.20000000","0.00200000"],["112518.47000000","0.00000000"],["112518.58000000","0.00000000"],["112518.96000000","0.00000000"],["112519.04000000","0.26683000"],["112519.97000000","0.00000000"],["112523.91000000","0.00000000"],["112525.40000000","0.04480000"],["112525.43000000","0.00000000"],["112527.00000000","0.00000000"],["112527.21000000","0.31987000"],["112530.50000000","0.00000000"],["112531.02000000","0.00000000"],["112531.50000000","0.00000000"],["112537.79000000","0.00000000"],["112544.37000000","0.00360000"],["112546.17000000","0.00000000"],["112548.34000000","0.00000000"],["112549.59000000","0.00306000"],["112551.44000000","0.00000000"],["112555.45000000","0.00000000"],["112559.02000000","0.03460000"],["112561.51000000","0.04091000"],["112567.94000000","0.00000000"],["112569.03000000","0.26730000"],["112569.62000000","0.26683000"],["112570.09000000","0.00000000"],["112576.50000000","0.00000000"],["112577.94000000","0.00000000"],["112585.90000000","0.00100000"],["112585.91000000","0.00122000"],["112588.75000000","0.00000000"],["112763.14000000","0.00080000"],["112769.00000000","0.00000000"],["112997.26000000","0.00000000"],["113515.24000000","0.00246000"],["114183.53000000","0.00100000"],["114601.21000000","0.01386000"]]}
[2025-10-26T09:47:45.059Z] {"e":"depthUpdate","E":1761472064014,"s":"BTCUSDT","U":79058031200,"u":79058031358,"b":[["112496.07000000","3.67254000"],["112496.06000000","0.00225000"],["112495.45000000","0.03145000"],["112493.78000000","0.00000000"],["112493.77000000","0.00000000"],["112493.26000000","0.00196000"],["112493.06000000","0.20494000"],["112492.98000000","0.00000000"],["112492.97000000","0.00000000"],["112492.28000000","0.22522000"],["112491.61000000","0.00005000"],["112490.65000000","0.08888000"],["112487.22000000","0.00005000"],["112486.76000000","0.08902000"],["112485.38000000","0.09024000"],["112484.50000000","0.06010000"],["112483.65000000","0.00000000"],["112481.45000000","0.10397000"],["112479.54000000","0.00000000"],["112479.52000000","0.04150000"],["112479.35000000","0.01746000"],["112456.15000000","0.00005000"],["112442.37000000","0.03000000"],["112439.51000000","0.30189000"],["112389.15000000","0.00000000"],["112384.36000000","0.00000000"],["112372.40000000","0.00000000"],["112285.25000000","0.01392000"],["112266.13000000","0.00000000"],["111917.25000000","0.00008000"],["111445.75000000","0.00000000"],["110808.62000000","0.00100000"],["110000.00000000","17.38267000"],["101246.46000000","0.00000000"],["101246.00000000","0.00010000"],["89996.86000000","0.00022000"],["60000.01000000","0.04830000"],["60000.00000000","57.64882000"]],"a":[["112496.08000000","1.63193000"],["112501.42000000","0.00010000"],["112504.18000000","0.03786000"],["112504.50000000","0.00260000"],["112504.51000000","0.02208000"],["112504.52000000","0.00000000"],["112506.00000000","0.00160000"],["112507.65000000","0.00000000"],["112508.00000000","0.00160000"],["112509.01000000","0.00161000"],["112512.96000000","0.10640000"],["112543.25000000","0.00005000"],["112560.00000000","0.42061000"],["112585.90000000","0.00000000"],["112585.91000000","0.00122000"],["112585.92000000","0.00100000"],["112653.38000000","0.47523000"],["112660.79000000","0.00000000"],["113515.24000000","0.00000000"],["114183.53000000","0.00100000"]]}
[2025-10-26T09:47:46.066Z] {"e":"depthUpdate","E":1761472065014,"s":"BTCUSDT","U":79058031359,"u":79058031997,"b":[["112503.23000000","4.70124000"],["112503.22000000","0.00045000"],["112502.81000000","0.00000000"],["112502.08000000","0.00000000"],["112502.06000000","0.20014000"],["112502.05000000","0.00030000"],["112501.80000000","0.00010000"],["112501.69000000","0.00000000"],["112501.30000000","0.04899000"],["112500.56000000","0.00000000"],["112499.99000000","0.00000000"],["112499.79000000","0.00000000"],["112499.76000000","0.00030000"],["112499.47000000","0.31500000"],["112498.92000000","0.00005000"],["112498.88000000","0.00000000"],["112497.19000000","0.00000000"],["112497.18000000","0.20484000"],["112496.92000000","0.00000000"],["112496.71000000","0.08888000"],["112496.15000000","0.00000000"],["112496.14000000","0.00000000"],["112496.13000000","0.00000000"],["112496.10000000","0.00000000"],["112496.08000000","0.51998000"],["112496.07000000","0.22688000"],["112496.06000000","0.00180000"],["112496.01000000","0.00160000"],["112496.00000000","0.00000000"],["112495.47000000","0.00000000"],["112495.46000000","0.12109000"],["112495.45000000","0.03130000"],["112493.56000000","0.00000000"],["112493.50000000","0.00000000"],["112493.49000000","0.00005000"],["112493.44000000","0.00005000"],["112493.07000000","0.00000000"],["112493.06000000","0.00005000"],["112492.29000000","0.00000000"],["112492.28000000","0.22517000"],["112491.98000000","0.00048000"],["112491.61000000","0.00000000"],["112491.60000000","0.04583000"],["112491.02000000","0.00000000"],["112491.01000000","0.56863000"],["112491.00000000","0.00255000"],["112490.65000000","0.08888000"],["112490.41000000","0.46938000"],["112488.60000000","0.08083000"],["112487.74000000","0.00010000"],["112486.76000000","0.00010000"],["112486.36000000","0.00088000"],["112485.38000000","0.00113000"],["112484.50000000","0.06005000"],["112484.18000000","1.70701000"],["112483.65000000","0.05115000"],["112483.43000000","0.01778000"],["112483.35000000","0.00015000"],["112482.41000000","0.26730000"],["112482.00000000","0.00250000"],["112481.90000000","0.00006000"],["112481.45000000","0.00000000"],["112478.92000000","0.04326000"],["112478.67000000","0.26683000"],["112478.37000000","0.26728000"],["112477.88000000","0.00000000"],["112468.50000000","0.00000000"],["112467.09000000","0.32005000"],["112460.52000000","0.00000000"],["112460.18000000","0.21958000"],["112447.26000000","0.00000000"],["112445.45000000","0.00000000"],["112444.12000000","0.00000000"],["112440.00000000","0.09525000"],["112437.58000000","0.00000000"],["112435.51000000","0.00000000"],["112433.90000000","0.00000000"],["112430.00000000","0.16140000"],["112428.62000000","0.28520000"],["112424.22000000","0.00000000"],["112417.49000000","0.00000000"],["112407.74000000","0.02984000"],["112369.95000000","0.00000000"],["112303.33000000","0.02133000"],["112285.25000000","0.00000000"],["112254.50000000","0.00000000"],["111917.25000000","0.00000000"],["110808.62000000","0.00000000"],["110786.46000000","0.00008000"],["110000.00000000","17.38539000"],["101246.00000000","0.00010000"],["101225.75000000","0.00000000"],["89997.00000000","0.00100000"],["89996.86000000","0.00022000"]],"a":[["112496.08000000","0.00000000"],["112496.09000000","0.00000000"],["112496.14000000","0.00000000"],["112496.15000000","0.00000000"],["112496.16000000","0.00000000"],["112497.20000000","0.00000000"],["112498.38000000","0.00000000"],["112498.89000000","0.00000000"],["112498.90000000","0.00000000"],["112498.91000000","0.00000000"],["112498.92000000","0.00000000"],["112499.74000000","0.00000000"],["112499.75000000","0.00000000"],["112499.76000000","0.00000000"],["112499.77000000","0.00000000"],["112499.99000000","0.00000000"],["112500.00000000","0.00000000"],["112500.57000000","0.00000000"],["112501.13000000","0.00000000"],["112501.42000000","0.00000000"],["112501.46000000","0.00000000"],["112501.70000000","0.00000000"],["112502.04000000","0.00000000"],["112502.05000000","0.00000000"],["112502.06000000","0.00000000"],["112502.27000000","0.00000000"],["112502.28000000","0.00000000"],["112502.59000000","0.00000000"],["112502.60000000","0.00000000"],["112502.82000000","0.00000000"],["112503.05000000","0.00000000"],["112503.23000000","0.00000000"],["112503.24000000","1.26161000"],["112503.25000000","0.00025000"],["112503.28000000","0.00005000"],["112504.17000000","0.00010000"],["112504.18000000","0.00015000"],["112504.37000000","0.00000000"],["112504.50000000","0.00020000"],["112504.51000000","0.00005000"],["112504.92000000","0.00010000"],["112504.93000000","0.00005000"],["112505.06000000","0.00000000"],["112505.64000000","0.00396000"],["112505.83000000","0.04059000"],["112505.92000000","0.00010000"],["112505.93000000","0.00000000"],["112506.00000000","0.00165000"],["112507.06000000","0.01756000"],["112507.08000000","0.00009000"],["112507.22000000","0.00000000"],["112507.32000000","0.00000000"],["112507.90000000","0.00156000"],["112508.00000000","0.00165000"],["112508.61000000","0.00005000"],["112508.62000000","0.03005000"],["112509.00000000","0.00255000"],["112509.01000000","0.00005000"],["112509.84000000","0.03005000"],["112510.00000000","0.00165000"],["112510.70000000","0.00005000"],["112511.12000000","0.03005000"],["112511.30000000","0.03005000"],["112511.43000000","0.00427000"],["112511.45000000","0.00334000"],["112511.91000000","0.02672000"],["112512.27000000","0.00000000"],["112512.95000000","0.00000000"],["112512.96000000","0.00000000"],["112513.50000000","0.00250000"],["112513.93000000","0.00000000"],["112515.51000000","0.00000000"],["112515.52000000","0.00000000"],["112516.17000000","0.00161000"],["112517.17000000","0.00000000"],["112517.87000000","0.10064000"],["112519.04000000","0.00000000"],["112520.12000000","0.00151000"],["112525.40000000","0.00000000"],["112527.21000000","0.00000000"],["112531.50000000","0.00250000"],["112546.35000000","0.31982000"],["112549.95000000","0.00005000"],["112553.72000000","0.00005000"],["112553.86000000","0.00088000"],["112559.20000000","0.00005000"],["112569.62000000","0.00000000"],["112580.00000000","0.10937000"],["112617.53000000","0.00000000"],["112653.38000000","0.00000000"],["112654.21000000","0.13145000"],["112701.61000000","0.01392000"],["112716.50000000","0.00000000"],["114183.53000000","0.00000000"],["140000.00000000","94.78124000"]]}
[2025-10-26T09:47:47.142Z] {"e":"depthUpdate","E":1761472066014,"s":"BTCUSDT","U":79058031998,"u":79058032896,"b":[["112503.23000000","4.79145000"],["112503.22000000","0.00075000"],["112503.16000000","0.00010000"],["112502.07000000","0.00010000"],["112502.06000000","0.00030000"],["112502.05000000","0.00000000"],["112501.80000000","0.00000000"],["112501.31000000","0.00000000"],["112501.30000000","0.00005000"],["112501.12000000","0.00005000"],["112500.13000000","0.00005000"],["112500.00000000","0.00010000"],["112499.91000000","0.00712000"],["112499.76000000","0.00000000"],["112499.58000000","0.00000000"],["112499.57000000","0.00000000"],["112499.48000000","0.00000000"],["112499.47000000","0.00000000"],["112499.37000000","0.00000000"],["112499.34000000","0.20484000"],["112497.75000000","0.00005000"],["112497.19000000","0.00000000"],["112497.18000000","0.00000000"],["112497.06000000","0.00170000"],["112497.05000000","0.00010000"],["112497.04000000","0.19042000"],["112497.03000000","0.00000000"],["112496.72000000","0.00010000"],["112496.71000000","0.08898000"],["112496.64000000","0.00000000"],["112496.35000000","0.00005000"],["112496.08000000","0.00010000"],["112496.07000000","0.21635000"],["112496.06000000","0.00180000"],["112496.01000000","0.00000000"],["112495.50000000","0.00250000"],["112495.46000000","0.00005000"],["112495.45000000","0.03130000"],["112494.38000000","0.00000000"],["112493.95000000","0.29335000"],["112493.49000000","0.00000000"],["112493.26000000","0.00201000"],["112493.25000000","0.00000000"],["112493.06000000","0.00000000"],["112492.97000000","0.00000000"],["112492.28000000","0.34643000"],["112491.97000000","0.00300000"],["112491.60000000","0.04588000"],["112491.31000000","0.00000000"],["112491.22000000","0.00000000"],["112491.01000000","0.56868000"],["112491.00000000","0.00255000"],["112490.98000000","0.00000000"],["112490.70000000","0.05297000"],["112490.65000000","0.08893000"],["112490.06000000","0.00074000"],["112488.85000000","0.00000000"],["112488.84000000","0.00000000"],["112488.75000000","0.00005000"],["112488.70000000","0.00007000"],["112488.60000000","0.08083000"],["112488.42000000","0.00000000"],["112487.89000000","0.00000000"],["112486.98000000","0.00000000"],["112486.84000000","0.01777000"],["112486.76000000","0.00005000"],["112486.68000000","1.01727000"],["112486.51000000","0.00396000"],["112486.50000000","0.00250000"],["112486.35000000","0.00000000"],["112486.22000000","0.01747000"],["112485.38000000","0.00108000"],["112484.50000000","0.06000000"],["112483.65000000","0.00000000"],["112483.43000000","0.00000000"],["112483.35000000","0.00000000"],["112479.75000000","0.00000000"],["112479.35000000","0.00000000"],["112475.10000000","0.01256000"],["112473.00000000","0.00000000"],["112471.10000000","0.00000000"],["112469.48000000","0.00008000"],["112468.17000000","0.00000000"],["112467.29000000","0.00000000"],["112467.00000000","0.00000000"],["112461.56000000","0.00177000"],["112461.09000000","0.00000000"],["112457.27000000","0.00000000"],["112454.38000000","0.00000000"],["112447.08000000","0.00000000"],["112446.98000000","0.00020000"],["112440.00000000","0.05525000"],["112439.51000000","0.22210000"],["112436.54000000","0.26730000"],["112435.73000000","0.00008000"],["112435.37000000","0.02984000"],["112433.55000000","0.26683000"],["112433.06000000","0.26728000"],["112430.00000000","0.00140000"],["112425.87000000","0.00000000"],["112423.53000000","0.00000000"],["112423.51000000","0.00000000"],["112407.74000000","0.00000000"],["112405.90000000","0.00000000"],["112401.98000000","0.00008000"],["112400.00000000","0.02175000"],["112389.78000000","0.00000000"],["112384.03000000","0.07740000"],["112378.17000000","0.00000000"],["112368.23000000","0.00008000"],["112356.03000000","0.00000000"],["112355.05000000","0.00000000"],["112346.04000000","0.00000000"],["112334.48000000","0.00008000"],["112322.28000000","0.00000000"],["112286.94000000","0.01599000"],["112283.37000000","0.01599000"],["112256.54000000","0.00567000"],["112250.00000000","0.17103000"],["112249.26000000","0.00000000"],["112243.33000000","0.00000000"],["112156.62000000","0.00000000"],["110815.68000000","0.00100000"],["101252.00000000","0.00010000"],["101246.00000000","0.00000000"],["90002.59000000","0.00022000"],["89996.86000000","0.00000000"],["40501.16000000","0.00015000"],["33000.00000000","3.78938000"]],"a":[["112503.24000000","2.29959000"],["112503.25000000","0.04320000"],["112503.28000000","0.00000000"],["112503.32000000","0.00010000"],["112504.00000000","0.00160000"],["112504.17000000","0.00000000"],["112504.18000000","0.00000000"],["112504.50000000","0.00005000"],["112504.51000000","0.00000000"],["112504.92000000","0.00000000"],["112504.93000000","0.00000000"],["112504.98000000","0.00000000"],["112504.99000000","0.00000000"],["112505.64000000","0.00391000"],["112505.82000000","0.00000000"],["112505.83000000","0.00000000"],["112505.92000000","0.00000000"],["112506.00000000","0.00170000"],["112507.05000000","0.00010000"],["112507.06000000","0.01766000"],["112507.07000000","0.00000000"],["112507.08000000","0.00000000"],["112507.41000000","0.00356000"],["112507.58000000","0.00000000"],["112507.63000000","0.00000000"],["112507.64000000","0.00000000"],["112508.00000000","0.00170000"],["112508.12000000","0.00010000"],["112508.13000000","0.08021000"],["112508.14000000","0.20489000"],["112508.58000000","0.00000000"],["112508.61000000","0.00010000"],["112508.62000000","0.03005000"],["112509.00000000","0.00250000"],["112509.83000000","0.00000000"],["112509.84000000","0.03005000"],["112509.99000000","0.00000000"],["112510.00000000","0.00165000"],["112510.24000000","0.04577000"],["112511.00000000","0.06100000"],["112511.11000000","0.00005000"],["112511.26000000","0.00000000"],["112511.41000000","0.27663000"],["112511.43000000","0.00427000"],["112511.45000000","0.00000000"],["112511.91000000","0.02672000"],["112512.00000000","0.00160000"],["112512.47000000","0.00000000"],["112513.32000000","0.06748000"],["112513.51000000","0.00000000"],["112513.99000000","1.70701000"],["112514.50000000","0.31500000"],["112516.77000000","0.00000000"],["112517.15000000","0.00000000"],["112518.41000000","0.00000000"],["112518.84000000","0.00000000"],["112519.03000000","0.00000000"],["112519.04000000","0.00000000"],["112519.05000000","0.01777000"],["112519.60000000","0.00000000"],["112519.61000000","0.00000000"],["112519.65000000","0.46938000"],["112520.12000000","0.10791000"],["112523.37000000","0.00000000"],["112523.68000000","0.00444000"],["112524.50000000","0.06100000"],["112524.78000000","0.00000000"],["112527.07000000","0.31987000"],["112527.99000000","0.00022000"],["112529.01000000","0.00250000"],["112530.05000000","0.04763000"],["112531.50000000","0.00000000"],["112531.70000000","0.26683000"],["112531.87000000","0.04480000"],["112532.85000000","0.00000000"],["112535.23000000","0.00000000"],["112536.37000000","0.00000000"],["112536.99000000","0.00008000"],["112537.00000000","0.00300000"],["112537.51000000","0.00000000"],["112538.88000000","0.00000000"],["112546.57000000","0.00000000"],["112550.41000000","0.00000000"],["112558.52000000","0.00616000"],["112559.02000000","0.00000000"],["112560.00000000","0.02061000"],["112561.51000000","0.00000000"],["112570.74000000","0.00008000"],["112571.90000000","0.00094000"],["112573.04000000","0.00000000"],["112574.50000000","0.04091000"],["112576.71000000","0.26683000"],["112580.00000000","0.01937000"],["112585.91000000","0.00022000"],["112585.92000000","0.00000000"],["112586.19000000","0.03460000"],["112592.18000000","0.00000000"],["112592.27000000","0.00000000"],["112592.78000000","0.00000000"],["112594.64000000","0.00000000"],["112596.59000000","0.03400000"],["112602.60000000","0.00000000"],["112604.49000000","0.00008000"],["112613.60000000","0.00005000"],["112621.47000000","0.00005000"],["112624.39000000","0.00005000"],["112626.02000000","0.00000000"],["112637.04000000","0.00000000"],["112638.24000000","0.00008000"],["112654.21000000","0.00000000"],["112659.77000000","0.00000000"],["112660.79000000","0.47523000"],["112671.99000000","0.00008000"],["112694.21000000","0.01599000"],["112697.68000000","0.01611000"],["112701.36000000","0.01599000"],["112751.46000000","0.00000000"],["113050.00000000","0.23344000"],["113497.09000000","0.00000000"],["114000.00000000","98.52119000"],["114190.79000000","0.00100000"]]}
[2025-10-26T09:47:48.324Z] {"e":"depthUpdate","E":1761472067014,"s":"BTCUSDT","U":79058032897,"u":79058033263,"b":[["112503.23000000","3.07544000"],["112503.22000000","0.00090000"],["112502.11000000","0.00118000"],["112502.07000000","0.00000000"],["112502.06000000","0.00000000"],["112501.30000000","0.00000000"],["112500.42000000","0.00206000"],["112500.13000000","0.00000000"],["112499.91000000","0.00015000"],["112499.36000000","0.00010000"],["112499.35000000","0.06255000"],["112499.34000000","0.20494000"],["112498.73000000","0.00356000"],["112498.49000000","0.00712000"],["112497.76000000","0.00165000"],["112497.06000000","0.00000000"],["112497.04000000","0.07737000"],["112496.72000000","0.00000000"],["112496.71000000","0.00005000"],["112496.48000000","0.00538000"],["112496.44000000","0.00000000"],["112496.43000000","0.00000000"],["112496.08000000","0.00010000"],["112496.07000000","0.21532000"],["112496.06000000","0.00005000"],["112495.46000000","0.00005000"],["112495.45000000","0.03135000"],["112494.95000000","0.00000000"],["112493.99000000","0.08892000"],["112493.95000000","0.00000000"],["112492.51000000","0.29336000"],["112492.28000000","0.34638000"],["112491.60000000","0.04583000"],["112491.48000000","0.00005000"],["112491.01000000","0.56863000"],["112491.00000000","0.00250000"],["112490.70000000","0.00000000"],["112490.17000000","0.00000000"],["112490.04000000","0.00069000"],["112488.60000000","0.08088000"],["112488.17000000","0.05087000"],["112486.84000000","0.00000000"],["112486.81000000","0.01777000"],["112486.76000000","0.00000000"],["112486.51000000","0.00000000"],["112486.22000000","0.00000000"],["112483.74000000","0.01733000"],["112473.58000000","0.04444000"],["112467.09000000","0.00000000"],["112450.00000000","0.02120000"],["112447.04000000","0.32010000"],["112446.75000000","0.00000000"],["112435.37000000","0.00000000"],["112421.58000000","0.02984000"],["112410.00000000","0.09160000"],["112405.90000000","0.00005000"],["112360.00000000","0.02034000"],["112248.51000000","4.63060000"],["112214.16000000","0.00000000"],["111923.87000000","0.00000000"],["110815.68000000","0.00100000"],["110786.46000000","0.00000000"],["101252.00000000","0.00010000"],["101231.75000000","0.00009000"],["90002.59000000","0.00022000"]],"a":[["112503.24000000","2.72783000"],["112503.25000000","0.04320000"],["112505.64000000","0.00396000"],["112505.81000000","0.00000000"],["112506.00000000","0.00175000"],["112506.35000000","0.00010000"],["112506.36000000","0.08657000"],["112506.37000000","0.00005000"],["112507.06000000","0.01761000"],["112507.41000000","0.00000000"],["112508.00000000","0.00165000"],["112508.12000000","0.00000000"],["112508.13000000","0.00000000"],["112508.14000000","0.00000000"],["112508.62000000","0.03005000"],["112509.83000000","0.00000000"],["112509.84000000","0.03010000"],["112509.99000000","0.00533000"],["112511.91000000","0.02667000"],["112512.80000000","0.00391000"],["112514.49000000","0.00711000"],["112525.07000000","0.00000000"],["112526.52000000","0.04168000"],["112527.96000000","0.00000000"],["112530.05000000","0.00000000"],["112531.67000000","0.00000000"],["112560.00000000","0.42061000"],["112568.40000000","0.03460000"],["112576.51000000","0.00000000"],["112580.00000000","0.10937000"],["112583.91000000","0.26677000"],["112586.19000000","0.00000000"],["112590.40000000","0.00100000"],["112590.41000000","0.00100000"],["112743.36000000","4.73723000"],["112908.89000000","0.00005000"],["113500.00000000","18.33589000"],["114190.79000000","0.00100000"]]}
[2025-10-26T09:47:49.241Z] {"e":"depthUpdate","E":1761472068014,"s":"BTCUSDT","U":79058033264,"u":79058033497,"b":[["112503.23000000","3.03510000"],["112503.22000000","0.00090000"],["112500.42000000","0.00206000"],["112499.91000000","0.00005000"],["112499.64000000","0.00000000"],["112499.35000000","0.06260000"],["112499.34000000","0.20494000"],["112498.73000000","0.00361000"],["112498.49000000","0.00717000"],["112497.76000000","0.00160000"],["112497.04000000","0.12002000"],["112497.00000000","0.00000000"],["112496.99000000","0.00000000"],["112496.07000000","0.21532000"],["112495.46000000","0.00005000"],["112495.45000000","0.03135000"],["112495.42000000","0.00005000"],["112494.98000000","0.00000000"],["112493.99000000","0.08897000"],["112493.74000000","0.08892000"],["112493.00000000","0.00005000"],["112492.51000000","0.00000000"],["112492.29000000","0.29331000"],["112491.60000000","0.04578000"],["112490.65000000","0.00005000"],["112488.60000000","0.08083000"],["112488.17000000","0.05089000"],["112486.81000000","0.00000000"],["112486.13000000","0.01777000"],["112455.94000000","0.94383000"],["112440.00000000","0.09525000"],["112430.00000000","0.36140000"],["112429.48000000","0.00000000"],["112409.25000000","0.00000000"],["112295.35000000","0.01392000"],["111922.88000000","0.00008000"],["111921.93000000","0.00000000"],["111300.00000000","1.98414000"],["110815.68000000","0.00100000"],["103502.98000000","0.00010000"],["101252.00000000","0.00010000"],["101231.75000000","0.00000000"],["90002.59000000","0.00022000"],["89997.00000000","0.00100000"],["40501.16000000","0.00030000"]],"a":[["112503.24000000","1.91901000"],["112503.25000000","0.04320000"],["112504.00000000","0.00160000"],["112504.74000000","0.00000000"],["112504.91000000","0.00356000"],["112505.09000000","0.00126000"],["112505.28000000","0.00010000"],["112505.29000000","0.02709000"],["112505.30000000","0.00040000"],["112505.45000000","0.20484000"],["112505.64000000","0.00391000"],["112506.00000000","0.00170000"],["112506.34000000","0.00000000"],["112506.35000000","0.00000000"],["112506.36000000","0.00000000"],["112506.37000000","0.00000000"],["112508.62000000","0.03010000"],["112509.83000000","0.00005000"],["112511.91000000","0.02672000"],["112512.00000000","0.00160000"],["112525.73000000","0.12133000"],["112532.09000000","0.96112000"],["112556.65000000","0.00005000"],["112647.69000000","0.00000000"],["112648.53000000","0.01850000"],["112657.08000000","0.47523000"],["112660.79000000","0.00000000"],["112704.01000000","0.00000000"],["112704.86000000","0.01855000"],["112760.34000000","0.00000000"],["112761.18000000","0.01850000"],["112801.00000000","0.00000000"],["112859.66000000","0.00684000"],["114190.79000000","0.00100000"]]}
[2025-10-26T09:48:05.752Z] Snapshot loaded successfully.
[2025-10-26T09:48:09.008Z] WebSocket connected successfully.
[2025-10-26T09:48:09.055Z] {"e":"depthUpdate","E":1761472088014,"s":"BTCUSDT","U":79058049260,"u":79058051414,"b":[["112541.12000000","6.20838000"],["112541.04000000","0.00010000"],["112540.17000000","0.00000000"],["112540.05000000","0.00000000"],["112540.01000000","0.00000000"],["112540.00000000","0.00005000"],["112539.99000000","0.00000000"],["112539.22000000","0.00000000"],["112538.40000000","0.00000000"],["112538.37000000","0.00000000"],["112538.30000000","1.51255000"],["112538.29000000","0.52695000"],["112538.25000000","0.00000000"],["112538.24000000","0.00000000"],["112538.20000000","0.00000000"],["112538.12000000","0.00000000"],["112537.99000000","0.00000000"],["112537.93000000","0.00000000"],["112537.76000000","0.11516000"],["112537.75000000","0.29349000"],["112537.64000000","0.00000000"],["112537.31000000","0.00000000"],["112537.28000000","0.00005000"],["112537.27000000","0.00000000"],["112537.13000000","0.00000000"],["112536.71000000","0.00000000"],["112536.14000000","0.00000000"],["112536.13000000","0.00015000"],["112536.02000000","0.00000000"],["112536.00000000","0.00005000"],["112535.99000000","0.00000000"],["112535.34000000","0.00000000"],["112535.33000000","0.00000000"],["112534.93000000","0.00000000"],["112533.99000000","0.00000000"],["112533.90000000","0.00000000"],["112533.52000000","0.00260000"],["112532.98000000","0.00000000"],["112532.97000000","0.00010000"],["112532.96000000","0.46948000"],["112532.95000000","0.00015000"],["112532.94000000","0.00000000"],["112532.92000000","0.00000000"],["112532.91000000","0.00005000"],["112532.88000000","0.00000000"],["112532.49000000","0.00000000"],["112532.30000000","0.00010000"],["112531.99000000","0.00000000"],["112531.85000000","0.00000000"],["112531.80000000","0.00005000"],["112531.79000000","0.00000000"],["112531.71000000","0.00000000"],["112531.70000000","0.00000000"],["112531.54000000","0.04569000"],["112531.43000000","0.00000000"],["112530.81000000","0.00000000"],["112530.79000000","0.00000000"],["112530.11000000","0.00000000"],["112529.99000000","0.00000000"],["112529.96000000","0.00000000"],["112529.87000000","0.00044000"],["112529.85000000","0.23854000"],["112529.84000000","0.22260000"],["112529.52000000","0.00000000"],["112529.22000000","0.00000000"],["112529.03000000","0.00000000"],["112529.02000000","0.00444000"],["112529.01000000","0.00250000"],["112528.96000000","0.00000000"],["112528.78000000","0.00000000"],["112528.75000000","0.00000000"],["112528.51000000","0.00000000"],["112527.99000000","0.00000000"],["112527.83000000","0.00000000"],["112527.81000000","0.00000000"],["112527.80000000","0.55909000"],["112527.73000000","0.00000000"],["112527.49000000","0.00000000"],["112527.42000000","0.00000000"],["112527.41000000","0.00000000"],["112527.40000000","0.00000000"],["112527.39000000","0.04005000"],["112527.23000000","0.00000000"],["112527.16000000","0.00000000"],["112527.15000000","0.00332000"],["112527.08000000","0.00000000"],["112527.07000000","0.00010000"],["112527.04000000","0.00000000"],["112527.03000000","0.00300000"],["112527.02000000","0.00000000"],["112527.01000000","0.00000000"],["112526.49000000","0.10782000"],["112526.39000000","0.00000000"],["112526.03000000","0.00098000"],["112525.87000000","0.00000000"],["112525.24000000","0.00000000"],["112525.21000000","0.00000000"],["112525.14000000","0.00000000"],["112524.96000000","0.00326000"],["112524.92000000","0.00000000"],["112524.75000000","0.00000000"],["112524.51000000","0.16636000"],["112524.23000000","0.00010000"],["112523.62000000","0.00000000"],["112523.61000000","0.02787000"],["112523.56000000","0.46938000"],["112522.98000000","0.00005000"],["112522.67000000","0.00000000"],["112522.65000000","0.00361000"],["112522.41000000","0.00043000"],["112522.18000000","0.00007000"],["112522.17000000","0.00074000"],["112521.66000000","0.00000000"],["112521.23000000","0.00000000"],["112521.17000000","0.00087000"],["112520.43000000","0.93812000"],["112520.40000000","0.00533000"],["112520.25000000","0.00000000"],["112520.12000000","1.70701000"],["112519.99000000","0.00250000"],["112519.80000000","0.00005000"],["112518.90000000","0.00010000"],["112518.71000000","0.00000000"],["112518.33000000","0.00000000"],["112518.32000000","0.00000000"],["112517.79000000","0.00200000"],["112517.30000000","0.03852000"],["112517.18000000","0.00000000"],["112516.08000000","0.00088000"],["112515.90000000","0.00000000"],["112515.48000000","0.00250000"],["112515.42000000","0.26683000"],["112515.41000000","0.00006000"],["112515.12000000","0.00005000"],["112515.11000000","0.26733000"],["112515.00000000","0.00000000"],["112514.50000000","0.04327000"],["112514.46000000","0.00000000"],["112514.22000000","0.15146000"],["112514.19000000","0.00000000"],["112512.97000000","0.06748000"],["112512.69000000","0.00000000"],["112512.67000000","0.00000000"],["112512.44000000","0.00000000"],["112512.36000000","0.00000000"],["112512.08000000","0.00043000"],["112511.53000000","0.00043000"],["112511.27000000","0.00000000"],["112511.12000000","0.00000000"],["112510.97000000","0.00000000"],["112510.92000000","0.00012000"],["112510.53000000","0.00000000"],["112510.41000000","0.05700000"],["112510.04000000","0.00000000"],["112509.63000000","0.01256000"],["112509.14000000","0.00000000"],["112507.42000000","0.00000000"],["112506.73000000","0.00000000"],["112506.46000000","0.00000000"],["112506.42000000","0.31993000"],["112505.19000000","0.00000000"],["112505.14000000","0.00009000"],["112505.04000000","0.00009000"],["112504.65000000","0.04442000"],["112504.59000000","0.15107000"],["112504.17000000","0.44510000"],["112504.06000000","0.00000000"],["112503.76000000","0.00000000"],["112503.22000000","0.35608000"],["112503.04000000","0.00000000"],["112502.94000000","0.00000000"],["112502.73000000","0.00000000"],["112501.96000000","0.06000000"],["112501.59000000","0.00000000"],["112501.54000000","0.03000000"],["112501.44000000","0.00000000"],["112501.34000000","0.00000000"],["112501.16000000","0.00000000"],["112500.94000000","0.00000000"],["112500.91000000","0.31995000"],["112500.40000000","0.00000000"],["112500.31000000","0.00009000"],["112499.70000000","0.03658000"],["112499.46000000","0.00177000"],["112499.45000000","0.00177000"],["112498.33000000","0.00009000"],["112498.25000000","0.00000000"],["112498.21000000","0.00000000"],["112498.00000000","0.00120000"],["112497.47000000","0.26677000"],["112497.19000000","0.00000000"],["112497.14000000","0.00000000"],["112496.62000000","0.21689000"],["112496.61000000","0.00000000"],["112496.23000000","0.00000000"],["112495.14000000","0.00000000"],["112494.86000000","0.00000000"],["112494.63000000","0.00000000"],["112493.40000000","0.00000000"],["112491.66000000","0.00000000"],["112491.31000000","0.00000000"],["112491.30000000","0.00000000"],["112491.29000000","0.00000000"],["112491.20000000","0.00008000"],["112490.64000000","0.00009000"],["112490.30000000","0.00000000"],["112489.51000000","0.05498000"],["112488.54000000","0.00000000"],["112488.31000000","0.00000000"],["112486.94000000","0.00000000"],["112486.16000000","0.00000000"],["112485.49000000","0.00000000"],["112485.39000000","0.00007000"],["112484.23000000","0.00000000"],["112483.83000000","0.00000000"],["112483.28000000","0.00000000"],["112482.48000000","0.00000000"],["112482.32000000","0.00000000"],["112482.30000000","0.26857000"],["112481.97000000","0.00000000"],["112481.96000000","0.00000000"],["112481.71000000","0.00000000"],["112481.11000000","0.00000000"],["112478.80000000","0.02984000"],["112478.60000000","0.00000000"],["112477.00000000","0.00000000"],["112476.84000000","0.00005000"],["112471.55000000","0.00000000"],["112471.52000000","0.00000000"],["112470.27000000","0.26683000"],["112469.98000000","0.26728000"],["112469.69000000","0.02224000"],["112468.29000000","0.00624000"],["112467.18000000","0.00625000"],["112466.68000000","0.00000000"],["112466.19000000","0.00010000"],["112465.07000000","0.00010000"],["112463.71000000","0.00000000"],["112461.70000000","0.00659000"],["112460.04000000","0.02498000"],["112458.48000000","0.00000000"],["112458.19000000","0.00000000"],["112456.25000000","0.02488000"],["112453.59000000","0.00089000"],["112452.75000000","0.00000000"],["112452.71000000","0.26677000"],["112452.48000000","0.44452000"],["112452.35000000","0.00000000"],["112452.28000000","0.00000000"],["112452.03000000","0.00000000"],["112451.50000000","0.00000000"],["112451.49000000","0.00000000"],["112451.29000000","0.00000000"],["112451.12000000","0.02488000"],["112449.94000000","0.00000000"],["112449.89000000","0.00000000"],["112447.32000000","0.44510000"],["112446.15000000","0.00000000"],["112444.79000000","0.35608000"],["112444.01000000","0.00000000"],["112444.00000000","0.00140000"],["112441.14000000","0.36079000"],["112441.03000000","0.08864000"],["112439.51000000","0.00000000"],["112439.40000000","0.00000000"],["112439.05000000","0.00000000"],["112437.22000000","0.36087000"],["112432.40000000","0.00000000"],["112428.38000000","0.01334000"],["112426.00000000","0.00160000"],["112425.60000000","0.04027000"],["112424.81000000","0.00000000"],["112424.63000000","0.00000000"],["112423.90000000","0.00000000"],["112422.45000000","0.00000000"],["112422.38000000","0.07740000"],["112421.37000000","0.00000000"],["112420.38000000","0.00000000"],["112414.76000000","0.03598000"],["112412.77000000","0.00000000"],["112405.18000000","0.00000000"],["112404.90000000","0.00000000"],["112404.32000000","0.00000000"],["112398.84000000","0.00000000"],["112388.82000000","0.12605000"],["112387.50000000","0.07423000"],["112387.49000000","0.00000000"],["112384.03000000","0.00000000"],["112379.12000000","0.03067000"],["112356.01000000","0.00000000"],["112355.47000000","0.00000000"],["112355.08000000","0.00000000"],["112354.53000000","0.00000000"],["112349.29000000","0.11245000"],["112348.07000000","0.00000000"],["112324.74000000","0.01599000"],["112323.43000000","0.03897000"],["112313.22000000","0.00006000"],["112310.66000000","0.00006000"],["112307.69000000","0.00005000"],["112306.60000000","0.00607000"],["112304.78000000","0.00007000"],["112304.12000000","0.00006000"],["112298.98000000","0.00000000"],["112292.40000000","0.00005000"],["112291.28000000","0.00000000"],["112289.15000000","0.00010000"],["112289.14000000","0.01777000"],["112279.46000000","0.99743000"],["112270.97000000","0.21739000"],["112252.15000000","0.00000000"],["112241.80000000","0.00000000"],["112230.40000000","0.00000000"],["112227.99000000","0.00033000"],["112214.80000000","0.01688000"],["112202.65000000","0.00000000"],["112194.33000000","0.00000000"],["112191.94000000","0.00000000"],["112188.70000000","0.00000000"],["112185.36000000","0.01688000"],["112184.50000000","0.00000000"],["112182.87000000","0.02399000"],["112181.99000000","0.02399000"],["112172.22000000","0.02399000"],["112167.56000000","0.22294000"],["112144.41000000","0.02399000"],["112120.12000000","0.00000000"],["112109.48000000","0.00000000"],["112092.49000000","0.00000000"],["112087.18000000","0.00000000"],["112085.54000000","0.00000000"],["112084.58000000","0.00000000"],["112078.50000000","0.00000000"],["112037.65000000","0.03098000"],["112035.85000000","0.03098000"],["112035.10000000","0.03098000"],["112030.97000000","0.00000000"],["111979.60000000","0.00000000"],["111969.85000000","0.00000000"],["111961.73000000","0.00008000"],["111954.93000000","0.00000000"],["111944.17000000","0.00000000"],["111943.11000000","0.00000000"],["111941.70000000","0.00000000"],["111919.33000000","1.16303000"],["111854.71000000","0.00000000"],["111500.01000000","0.00000000"],["111218.87000000","1.07292000"],["111085.64000000","0.00000000"],["110850.21000000","0.00100000"],["110839.24000000","0.00000000"],["109300.00000000","13.94309000"],["108450.00000000","0.05507000"],["101284.00000000","0.00010000"],["101274.00000000","0.00296000"],["98000.00000000","100.04259000"],["90032.90000000","0.00022000"],["90022.24000000","0.00000000"],["90021.72000000","0.00000000"],["90004.24000000","0.00000000"],["78778.64000000","0.00000000"],["78774.70000000","0.00000000"],["78770.76000000","0.00000000"],["40509.78000000","0.00060000"],["40501.68000000","0.00000000"]],"a":[["112527.16000000","0.00000000"],["112527.17000000","0.00000000"],["112527.24000000","0.00000000"],["112527.81000000","0.00000000"],["112527.82000000","0.00000000"],["112528.00000000","0.00000000"],["112528.52000000","0.00000000"],["112528.76000000","0.00000000"],["112528.79000000","0.00000000"],["112528.97000000","0.00000000"],["112529.04000000","0.00000000"],["112529.23000000","0.00000000"],["112529.53000000","0.00000000"],["112529.85000000","0.00000000"],["112529.97000000","0.00000000"],["112530.00000000","0.00000000"],["112530.12000000","0.00000000"],["112530.80000000","0.00000000"],["112531.44000000","0.00000000"],["112531.71000000","0.00000000"],["112531.72000000","0.00000000"],["112531.80000000","0.00000000"],["112531.86000000","0.00000000"],["112532.00000000","0.00000000"],["112532.50000000","0.00000000"],["112532.95000000","0.00000000"],["112532.96000000","0.00000000"],["112532.97000000","0.00000000"],["112533.00000000","0.00000000"],["112533.17000000","0.00000000"],["112533.18000000","0.00000000"],["112533.20000000","0.00000000"],["112533.37000000","0.00000000"],["112533.91000000","0.00000000"],["112533.99000000","0.00000000"],["112534.00000000","0.00000000"],["112534.79000000","0.00000000"],["112534.94000000","0.00000000"],["112535.34000000","0.00000000"],["112535.35000000","0.00000000"],["112535.66000000","0.00000000"],["112535.73000000","0.00000000"],["112535.88000000","0.00000000"],["112535.93000000","0.00000000"],["112536.00000000","0.00000000"],["112536.03000000","0.00000000"],["112536.04000000","0.00000000"],["112536.25000000","0.00000000"],["112536.55000000","0.00000000"],["112536.58000000","0.00000000"],["112536.59000000","0.00000000"],["112536.67000000","0.00000000"],["112536.72000000","0.00000000"],["112537.14000000","0.00000000"],["112537.28000000","0.00000000"],["112537.43000000","0.00000000"],["112537.44000000","0.00000000"],["112537.64000000","0.00000000"],["112537.65000000","0.00000000"],["112537.75000000","0.00000000"],["112537.94000000","0.00000000"],["112538.00000000","0.00000000"],["112538.03000000","0.00000000"],["112538.13000000","0.00000000"],["112538.18000000","0.00000000"],["112538.24000000","0.00000000"],["112538.25000000","0.00000000"],["112538.29000000","0.00000000"],["112538.30000000","0.00000000"],["112538.31000000","0.00000000"],["112538.38000000","0.00000000"],["112538.41000000","0.00000000"],["112538.46000000","0.00000000"],["112539.00000000","0.00000000"],["112539.05000000","0.00000000"],["112539.23000000","0.00000000"],["112539.90000000","0.00000000"],["112539.91000000","0.00000000"],["112539.97000000","0.00000000"],["112539.99000000","0.00000000"],["112540.00000000","0.00000000"],["112540.02000000","0.00000000"],["112540.06000000","0.00000000"],["112540.18000000","0.00000000"],["112540.21000000","0.00000000"],["112540.25000000","0.00000000"],["112540.27000000","0.00000000"],["112540.28000000","0.00000000"],["112540.43000000","0.00000000"],["112540.57000000","0.00000000"],["112540.74000000","0.00000000"],["112540.79000000","0.00000000"],["112540.80000000","0.00000000"],["112540.81000000","0.00000000"],["112540.82000000","0.00000000"],["112540.92000000","0.00000000"],["112540.96000000","0.00000000"],["112540.97000000","0.00000000"],["112541.09000000","0.00000000"],["112541.11000000","0.00000000"],["112541.12000000","0.00000000"],["112541.13000000","0.71394000"],["112541.14000000","0.00055000"],["112541.21000000","0.00010000"],["112541.50000000","0.00000000"],["112541.61000000","0.00005000"],["112541.63000000","0.00000000"],["112541.65000000","0.00000000"],["112541.72000000","0.00010000"],["112541.73000000","0.05204000"],["112541.85000000","0.00000000"],["112541.95000000","0.00005000"],["112542.00000000","0.00175000"],["112542.01000000","0.01810000"],["112542.09000000","0.00010000"],["112542.10000000","0.03010000"],["112542.21000000","0.00000000"],["112542.54000000","0.00000000"],["112542.59000000","0.00000000"],["112542.67000000","0.00000000"],["112542.82000000","0.00010000"],["112542.83000000","0.03010000"],["112542.92000000","0.00000000"],["112543.01000000","0.00000000"],["112543.28000000","0.00000000"],["112543.51000000","0.00000000"],["112543.79000000","0.00005000"],["112543.80000000","0.03005000"],["112543.81000000","0.00000000"],["112544.00000000","0.00165000"],["112544.15000000","0.00000000"],["112544.21000000","0.00000000"],["112544.31000000","0.00000000"],["112544.69000000","0.00305000"],["112544.72000000","0.00000000"],["112544.75000000","0.00000000"],["112544.76000000","0.00000000"],["112544.82000000","0.00000000"],["112545.05000000","0.00005000"],["112545.21000000","0.00005000"],["112545.44000000","0.01815000"],["112545.64000000","0.13731000"],["112545.65000000","0.00000000"],["112545.71000000","0.00000000"],["112546.00000000","0.00165000"],["112546.13000000","0.00000000"],["112546.19000000","0.00000000"],["112546.41000000","0.06000000"],["112546.48000000","0.00000000"],["112546.63000000","0.00059000"],["112547.05000000","0.00010000"],["112547.11000000","0.00000000"],["112547.59000000","0.00005000"],["112547.73000000","0.03000000"],["112547.88000000","0.00000000"],["112547.91000000","0.24000000"],["112547.95000000","0.00005000"],["112548.00000000","0.00165000"],["112548.38000000","0.00000000"],["112548.79000000","0.00000000"],["112548.80000000","0.03005000"],["112548.96000000","0.00000000"],["112548.97000000","0.00000000"],["112548.99000000","0.00005000"],["112549.00000000","0.00000000"],["112549.46000000","0.00000000"],["112549.47000000","0.05405000"],["112549.63000000","0.04100000"],["112549.78000000","0.14067000"],["112549.83000000","0.00000000"],["112549.84000000","0.00151000"],["112549.94000000","0.00000000"],["112549.96000000","0.00000000"],["112550.02000000","0.04000000"],["112551.13000000","0.00070000"],["112551.55000000","0.00200000"],["112552.25000000","0.00059000"],["112552.38000000","0.03000000"],["112552.62000000","0.03000000"],["112552.63000000","0.00070000"],["112552.78000000","0.00000000"],["112552.82000000","0.03000000"],["112553.04000000","0.00078000"],["112553.05000000","0.00000000"],["112553.72000000","0.00005000"],["112553.91000000","0.00000000"],["112553.98000000","0.00035000"],["112553.99000000","0.00000000"],["112554.22000000","0.00038000"],["112555.07000000","0.00000000"],["112555.18000000","0.00151000"],["112555.43000000","0.00089000"],["112555.72000000","0.46938000"],["112555.73000000","0.20484000"],["112555.76000000","0.08307000"],["112555.91000000","0.00607000"],["112557.06000000","0.00000000"],["112557.27000000","0.00000000"],["112557.47000000","0.00000000"],["112557.88000000","0.00000000"],["112558.01000000","0.00151000"],["112558.22000000","1.70701000"],["112558.46000000","0.00000000"],["112559.12000000","0.00039000"],["112559.33000000","0.00444000"],["112559.51000000","0.00033000"],["112559.72000000","0.46938000"],["112559.74000000","0.00000000"],["112559.79000000","0.00000000"],["112559.99000000","0.00000000"],["112560.58000000","0.00250000"],["112560.67000000","0.00000000"],["112560.76000000","0.00000000"],["112561.00000000","0.00000000"],["112561.30000000","0.00000000"],["112561.55000000","0.00000000"],["112561.90000000","0.00000000"],["112562.48000000","0.00888000"],["112563.32000000","0.00000000"],["112563.52000000","0.00000000"],["112563.55000000","0.00000000"],["112563.87000000","0.00038000"],["112563.97000000","0.29979000"],["112564.48000000","0.00033000"],["112564.54000000","0.00000000"],["112564.62000000","0.26728000"],["112565.09000000","0.00250000"],["112565.29000000","0.00000000"],["112566.84000000","0.00000000"],["112566.89000000","0.00000000"],["112567.19000000","0.00088000"],["112567.45000000","0.00000000"],["112567.82000000","0.00000000"],["112568.20000000","0.00000000"],["112568.96000000","0.00000000"],["112569.37000000","0.00000000"],["112569.60000000","0.00250000"],["112569.93000000","0.04442000"],["112571.78000000","0.04480000"],["112572.07000000","0.00300000"],["112574.11000000","0.00000000"],["112574.25000000","0.00000000"],["112575.00000000","0.34607000"],["112577.24000000","0.00000000"],["112578.31000000","0.00000000"],["112579.15000000","0.00000000"],["112579.28000000","0.00000000"],["112580.05000000","0.00000000"],["112580.12000000","0.31972000"],["112580.79000000","0.00000000"],["112581.30000000","0.00056000"],["112581.66000000","0.00000000"],["112581.72000000","0.00000000"],["112582.66000000","0.00000000"],["112582.81000000","0.43378000"],["112583.15000000","0.00000000"],["112583.46000000","0.31971000"],["112583.59000000","0.00088000"],["112586.60000000","0.00005000"],["112587.83000000","0.00000000"],["112589.43000000","0.00064000"],["112592.08000000","0.00005000"],["112592.48000000","0.36039000"],["112593.82000000","0.00000000"],["112595.09000000","0.00000000"],["112595.62000000","0.00000000"],["112596.41000000","0.36030000"],["112597.03000000","0.02935000"],["112597.79000000","0.00000000"],["112598.82000000","0.00005000"],["112603.36000000","0.00000000"],["112604.62000000","0.00000000"],["112605.02000000","0.00000000"],["112605.34000000","0.00000000"],["112605.35000000","0.00000000"],["112607.80000000","0.00648000"],["112609.03000000","0.00618000"],["112609.63000000","0.26728000"],["112610.65000000","0.00221000"],["112613.51000000","0.03460000"],["112617.59000000","0.00000000"],["112619.33000000","0.00000000"],["112619.42000000","0.46938000"],["112619.96000000","0.00221000"],["112620.90000000","0.03000000"],["112623.82000000","0.03000000"],["112624.91000000","0.03954000"],["112625.37000000","0.44510000"],["112625.68000000","0.00000000"],["112625.81000000","0.00110000"],["112626.55000000","0.00000000"],["112626.56000000","0.00000000"],["112627.64000000","0.00000000"],["112636.90000000","0.00000000"],["112637.55000000","0.01258000"],["112638.67000000","0.00000000"],["112639.06000000","0.00000000"],["112640.47000000","0.00000000"],["112643.21000000","0.00000000"],["112646.94000000","0.00000000"],["112647.10000000","0.00005000"],["112647.56000000","0.07345000"],["112649.07000000","0.00005000"],["112659.90000000","0.00000000"],["112664.63000000","0.00000000"],["112670.18000000","0.00000000"],["112673.32000000","0.00000000"],["112677.22000000","0.08687000"],["112679.37000000","0.08868000"],["112679.76000000","0.00000000"],["112680.00000000","0.00078000"],["112683.02000000","0.00000000"],["112684.71000000","0.00000000"],["112689.14000000","0.00000000"],["112694.14000000","0.47523000"],["112695.57000000","0.04346000"],["112697.64000000","0.00000000"],["112704.82000000","0.00000000"],["112705.95000000","0.03847000"],["112716.47000000","0.00006000"],["112723.19000000","0.00088000"],["112734.10000000","0.00088000"],["112757.24000000","0.00000000"],["112758.38000000","0.01777000"],["112758.70000000","0.00000000"],["112761.61000000","0.00000000"],["112761.68000000","0.01392000"],["112770.75000000","0.01777000"],["112782.32000000","0.01777000"],["112783.55000000","0.00000000"],["112785.29000000","0.01777000"],["112791.84000000","0.02398000"],["112805.29000000","0.01688000"],["112806.76000000","0.02398000"],["112807.34000000","0.01688000"],["112807.79000000","0.24292000"],["112812.39000000","0.22307000"],["112814.65000000","0.00000000"],["112822.20000000","0.02398000"],["112828.62000000","0.00000000"],["112829.56000000","0.02398000"],["112833.61000000","0.00000000"],["112837.49000000","0.00000000"],["112839.96000000","0.01599000"],["112848.82000000","0.01688000"],["112849.97000000","0.00005000"],["112850.65000000","0.00000000"],["112853.79000000","0.01688000"],["112857.76000000","0.01688000"],["112861.15000000","0.01688000"],["112869.42000000","0.00000000"],["112870.25000000","0.00000000"],["112871.45000000","0.00000000"],["112875.70000000","0.02398000"],["112877.19000000","0.02398000"],["112901.62000000","0.00000000"],["112902.14000000","0.00000000"],["112902.59000000","0.00000000"],["112903.69000000","0.00000000"],["112903.78000000","0.00000000"],["112903.93000000","0.00000000"],["112904.63000000","0.00000000"],["112905.08000000","0.00000000"],["112906.41000000","0.00010000"],["112912.03000000","0.00010000"],["112917.65000000","0.00010000"],["112923.27000000","0.00000000"],["112928.47000000","0.03298000"],["112929.17000000","0.03298000"],["112929.99000000","0.03298000"],["112930.38000000","0.03298000"],["112930.81000000","0.03298000"],["112931.20000000","0.03298000"],["112932.01000000","0.06596000"],["112981.00000000","0.02639000"],["112986.04000000","0.31500000"],["114215.07000000","0.00000000"]]}
[2025-10-26T09:48:10.127Z] {"e":"depthUpdate","E":1761472089014,"s":"BTCUSDT","U":79058051415,"u":79058052469,"b":[["112541.12000000","4.44434000"],["112538.34000000","0.00000000"],["112538.33000000","0.00000000"],["112538.32000000","0.00000000"],["112538.31000000","0.00000000"],["112538.30000000","0.00000000"],["112538.29000000","0.00005000"],["112538.25000000","0.00005000"],["112538.03000000","0.00270000"],["112537.77000000","0.00000000"],["112537.76000000","0.00000000"],["112537.75000000","0.00000000"],["112537.00000000","0.12612000"],["112536.99000000","0.00030000"],["112536.98000000","0.00010000"],["112536.97000000","0.29339000"],["112536.13000000","0.00005000"],["112536.00000000","0.00005000"],["112534.29000000","0.00000000"],["112534.28000000","0.00000000"],["112534.27000000","0.00000000"],["112533.52000000","0.00260000"],["112532.97000000","0.00000000"],["112532.96000000","0.00000000"],["112532.95000000","0.00005000"],["112532.30000000","0.00000000"],["112531.68000000","0.00000000"],["112531.67000000","0.00000000"],["112531.55000000","0.48564000"],["112531.54000000","0.04584000"],["112531.12000000","0.46943000"],["112530.94000000","0.00000000"],["112529.87000000","0.56912000"],["112529.86000000","0.31505000"],["112529.85000000","0.00000000"],["112529.84000000","0.22260000"],["112529.71000000","0.05136000"],["112529.01000000","0.00260000"],["112528.03000000","0.00326000"],["112528.00000000","0.00000000"],["112527.85000000","0.04000000"],["112527.80000000","0.08961000"],["112527.39000000","0.00000000"],["112527.15000000","0.00020000"],["112527.04000000","0.46938000"],["112527.03000000","0.00305000"],["112526.49000000","0.10782000"],["112524.96000000","0.00321000"],["112524.51000000","0.00000000"],["112524.24000000","0.00088000"],["112523.62000000","0.14988000"],["112523.61000000","0.02782000"],["112522.65000000","0.00356000"],["112522.50000000","0.00005000"],["112521.17000000","0.00000000"],["112520.70000000","0.00005000"],["112520.46000000","0.64098000"],["112520.45000000","1.70701000"],["112520.44000000","0.00000000"],["112520.43000000","0.00000000"],["112520.12000000","0.00000000"],["112519.45000000","0.04288000"],["112519.41000000","0.04073000"],["112517.79000000","0.00000000"],["112517.30000000","0.00000000"],["112517.05000000","0.00000000"],["112515.80000000","0.00005000"],["112515.69000000","0.00000000"],["112515.48000000","0.00000000"],["112515.37000000","0.03780000"],["112514.50000000","0.00000000"],["112513.71000000","0.00000000"],["112513.70000000","0.32688000"],["112512.86000000","0.01256000"],["112511.62000000","0.00000000"],["112511.53000000","0.00000000"],["112510.64000000","0.59598000"],["112510.24000000","0.08700000"],["112509.72000000","0.04500000"],["112509.63000000","0.00000000"],["112509.58000000","0.03900000"],["112509.29000000","0.03600000"],["112509.28000000","0.05400000"],["112507.87000000","0.00000000"],["112507.36000000","0.00008000"],["112507.25000000","0.00009000"],["112507.15000000","0.03009000"],["112506.92000000","0.03600000"],["112506.71000000","0.31993000"],["112506.42000000","0.00000000"],["112505.14000000","0.00000000"],["112505.07000000","0.03000000"],["112505.04000000","0.00000000"],["112504.26000000","0.00053000"],["112504.25000000","0.03000000"],["112503.76000000","0.03000000"],["112502.41000000","0.00009000"],["112501.94000000","0.00000000"],["112500.43000000","0.00009000"],["112500.31000000","0.00000000"],["112499.70000000","0.00005000"],["112498.42000000","0.00000000"],["112498.34000000","0.00271000"],["112498.33000000","0.00000000"],["112497.89000000","1.27617000"],["112495.19000000","0.00012000"],["112495.14000000","0.00000000"],["112495.04000000","0.00000000"],["112494.67000000","0.00000000"],["112494.07000000","0.00000000"],["112493.97000000","0.00000000"],["112493.95000000","0.00000000"],["112493.15000000","0.95639000"],["112492.97000000","0.38591000"],["112492.74000000","0.00009000"],["112491.20000000","0.00000000"],["112490.69000000","0.00000000"],["112490.64000000","0.00000000"],["112489.51000000","0.02498000"],["112488.43000000","0.00000000"],["112488.23000000","0.00000000"],["112487.90000000","0.00000000"],["112486.14000000","0.00000000"],["112483.87000000","0.00000000"],["112480.79000000","0.02984000"],["112480.34000000","0.00000000"],["112479.24000000","0.06623000"],["112478.80000000","0.00000000"],["112476.95000000","0.00000000"],["112473.60000000","0.00008000"],["112472.00000000","0.00140000"],["112470.00000000","0.00140000"],["112468.00000000","0.00140000"],["112466.00000000","0.00140000"],["112464.00000000","0.00140000"],["112462.00000000","0.00140000"],["112461.73000000","0.00000000"],["112460.00000000","1.70841000"],["112459.31000000","0.00000000"],["112457.45000000","0.00000000"],["112455.69000000","0.00089000"],["112453.59000000","0.00000000"],["112453.56000000","0.44452000"],["112452.48000000","0.00000000"],["112452.00000000","0.00160000"],["112443.37000000","0.01334000"],["112441.15000000","0.30404000"],["112441.03000000","0.00000000"],["112439.83000000","0.00008000"],["112437.75000000","0.01334000"],["112428.38000000","0.00000000"],["112426.00000000","0.00165000"],["112424.75000000","0.00000000"],["112423.69000000","0.00000000"],["112420.26000000","0.00000000"],["112410.58000000","0.00007000"],["112406.07000000","0.00008000"],["112405.07000000","0.00000000"],["112390.01000000","0.00000000"],["112389.93000000","0.00000000"],["112383.01000000","0.06000000"],["112373.38000000","0.13670000"],["112372.31000000","0.00008000"],["112367.03000000","0.00000000"],["112360.00000000","0.00249000"],["112356.24000000","0.00937000"],["112356.17000000","0.00000000"],["112345.83000000","0.00005000"],["112340.02000000","0.02409000"],["112337.96000000","0.00000000"],["112300.00000000","12.55883000"],["112278.01000000","0.00000000"],["112042.96000000","0.00250000"],["112031.75000000","0.00000000"],["111965.11000000","0.00000000"],["111961.73000000","0.00000000"],["110853.00000000","0.00100000"],["110850.21000000","0.00000000"],["109801.66000000","0.00421000"],["109572.35000000","0.00000000"],["109300.01000000","0.00000000"],["107056.72000000","0.00000000"],["101287.00000000","0.01000000"],["101286.00000000","0.00270000"],["101284.00000000","0.00000000"],["101266.74000000","0.00009000"],["95225.56000000","0.00000000"],["90033.00000000","0.00000000"],["90032.90000000","0.00022000"]],"a":[["112541.13000000","0.34899000"],["112541.14000000","0.04280000"],["112541.61000000","0.00000000"],["112541.72000000","0.00000000"],["112541.73000000","0.00000000"],["112542.00000000","0.00160000"],["112542.01000000","0.00000000"],["112542.09000000","0.00000000"],["112542.10000000","0.00000000"],["112542.66000000","0.05129000"],["112542.82000000","0.00000000"],["112542.83000000","0.00000000"],["112543.79000000","0.00000000"],["112543.80000000","0.00005000"],["112544.69000000","0.00300000"],["112545.05000000","0.00000000"],["112545.44000000","0.00000000"],["112545.54000000","0.00000000"],["112545.63000000","0.00010000"],["112545.64000000","0.00000000"],["112545.94000000","0.00000000"],["112545.95000000","0.00000000"],["112546.40000000","0.00010000"],["112546.41000000","0.02005000"],["112546.63000000","0.00059000"],["112546.64000000","0.01808000"],["112547.05000000","0.00000000"],["112547.59000000","0.00000000"],["112547.73000000","0.00000000"],["112547.76000000","0.00000000"],["112547.89000000","0.00010000"],["112547.90000000","0.04000000"],["112547.91000000","0.00000000"],["112548.00000000","0.00160000"],["112548.80000000","0.00000000"],["112548.99000000","0.00000000"],["112549.38000000","0.00000000"],["112549.47000000","0.00005000"],["112549.62000000","0.00005000"],["112549.63000000","0.04095000"],["112549.64000000","0.00005000"],["112549.77000000","0.00000000"],["112549.78000000","0.27799000"],["112549.84000000","0.00156000"],["112550.00000000","0.03877000"],["112550.02000000","0.00000000"],["112550.10000000","0.00000000"],["112550.11000000","0.00000000"],["112550.30000000","0.24000000"],["112550.33000000","0.00000000"],["112551.19000000","0.00000000"],["112551.55000000","0.00000000"],["112552.25000000","0.00059000"],["112553.37000000","0.00082000"],["112553.86000000","0.03000000"],["112553.95000000","0.20484000"],["112554.02000000","0.00000000"],["112554.04000000","0.00000000"],["112554.12000000","0.00072000"],["112554.32000000","0.00328000"],["112554.57000000","0.00000000"],["112555.30000000","0.00000000"],["112555.43000000","0.00000000"],["112555.72000000","0.00000000"],["112555.73000000","0.00000000"],["112556.08000000","0.03300000"],["112556.15000000","0.00089000"],["112557.11000000","0.03000000"],["112558.00000000","0.00160000"],["112558.01000000","0.00239000"],["112558.15000000","0.04569000"],["112558.67000000","0.00000000"],["112558.73000000","0.00300000"],["112559.73000000","0.00000000"],["112559.82000000","0.04000000"],["112560.95000000","0.00000000"],["112561.43000000","0.00000000"],["112561.44000000","0.00000000"],["112561.99000000","0.00000000"],["112563.32000000","0.18117000"],["112563.64000000","0.10640000"],["112563.99000000","0.00000000"],["112565.75000000","0.02398000"],["112566.27000000","0.00000000"],["112566.56000000","0.00000000"],["112567.16000000","0.00000000"],["112569.50000000","0.06100000"],["112569.78000000","0.00000000"],["112569.93000000","0.00000000"],["112570.34000000","0.03598000"],["112571.78000000","0.00000000"],["112572.12000000","0.00000000"],["112572.75000000","0.08094000"],["112572.76000000","0.97233000"],["112572.99000000","0.00000000"],["112574.16000000","0.04480000"],["112574.80000000","0.03598000"],["112574.86000000","0.01800000"],["112574.89000000","0.00008000"],["112575.99000000","0.03398000"],["112580.90000000","0.15133000"],["112583.18000000","0.00000000"],["112583.22000000","0.00000000"],["112583.25000000","0.00000000"],["112583.30000000","0.00000000"],["112583.33000000","0.00000000"],["112583.35000000","0.00000000"],["112583.42000000","0.00000000"],["112584.25000000","0.02488000"],["112584.72000000","0.00000000"],["112585.37000000","0.18798000"],["112586.15000000","0.00000000"],["112586.33000000","0.01391000"],["112591.77000000","0.00088000"],["112592.48000000","0.36031000"],["112598.77000000","0.00000000"],["112604.05000000","0.01573000"],["112605.70000000","0.00000000"],["112605.93000000","0.00000000"],["112608.65000000","0.00008000"],["112613.51000000","0.00000000"],["112618.87000000","0.00000000"],["112620.45000000","0.00000000"],["112623.82000000","0.05487000"],["112625.60000000","0.03460000"],["112626.17000000","0.03000000"],["112626.24000000","0.00000000"],["112627.35000000","0.00000000"],["112629.36000000","0.00105000"],["112629.38000000","0.03000000"],["112631.75000000","0.04096000"],["112632.43000000","0.19195000"],["112635.59000000","0.00000000"],["112642.42000000","0.00008000"],["112644.37000000","0.00000000"],["112650.39000000","0.00000000"],["112652.75000000","0.00000000"],["112653.01000000","0.00005000"],["112660.00000000","0.01775000"],["112664.13000000","0.00444000"],["112676.18000000","0.00008000"],["112682.45000000","0.06000000"],["112690.73000000","0.00000000"],["112690.78000000","0.00000000"],["112690.83000000","0.00000000"],["112693.52000000","0.02398000"],["112693.76000000","0.00231000"],["112698.02000000","0.00000000"],["112709.94000000","0.00008000"],["112795.25000000","0.00000000"],["112806.53000000","0.00250000"],["112832.05000000","0.00000000"],["112846.39000000","0.00000000"],["112872.97000000","0.00080000"],["112874.57000000","0.00000000"],["112897.54000000","0.00000000"],["112902.67000000","0.00000000"],["112903.74000000","0.00000000"],["112931.43000000","0.03398000"],["112932.24000000","0.03398000"],["112948.19000000","0.00005000"],["113134.45000000","0.00420000"],["113511.23000000","0.00000000"],["113541.15000000","0.04000000"],["114229.25000000","0.00100000"],["117269.01000000","0.00013000"]]}
[2025-10-26T09:48:11.152Z] {"e":"depthUpdate","E":1761472090014,"s":"BTCUSDT","U":79058052470,"u":79058053892,"b":[["112549.78000000","5.08467000"],["112549.77000000","0.00000000"],["112549.70000000","0.13201000"],["112549.69000000","0.00035000"],["112549.68000000","0.20509000"],["112549.63000000","0.00000000"],["112549.62000000","0.00000000"],["112548.82000000","0.00371000"],["112548.24000000","0.00005000"],["112548.17000000","0.00000000"],["112548.00000000","0.00000000"],["112547.99000000","0.00000000"],["112546.75000000","0.00000000"],["112545.99000000","0.00000000"],["112545.66000000","0.00000000"],["112545.65000000","0.00000000"],["112545.64000000","0.00000000"],["112545.63000000","0.00000000"],["112545.07000000","0.00000000"],["112545.04000000","0.00000000"],["112544.81000000","0.00000000"],["112544.71000000","0.00000000"],["112544.68000000","0.00000000"],["112543.99000000","0.00000000"],["112543.96000000","0.00000000"],["112543.79000000","0.00000000"],["112542.76000000","0.00005000"],["112542.08000000","0.00010000"],["112542.07000000","0.03273000"],["112541.99000000","0.00000000"],["112541.98000000","0.00010000"],["112541.97000000","0.09608000"],["112541.72000000","0.00000000"],["112541.20000000","0.00000000"],["112541.15000000","0.50297000"],["112541.14000000","0.00005000"],["112541.13000000","0.31505000"],["112541.12000000","0.19889000"],["112541.04000000","0.00000000"],["112539.46000000","0.00000000"],["112539.45000000","0.00000000"],["112538.53000000","0.29982000"],["112538.52000000","0.22260000"],["112538.25000000","0.00000000"],["112538.03000000","0.00260000"],["112537.03000000","0.00000000"],["112537.02000000","0.14413000"],["112537.01000000","0.00000000"],["112537.00000000","0.00000000"],["112536.99000000","0.00000000"],["112536.98000000","0.00000000"],["112536.97000000","0.00000000"],["112536.00000000","0.06005000"],["112535.80000000","0.00000000"],["112535.79000000","0.04574000"],["112535.73000000","0.00010000"],["112535.15000000","0.09400000"],["112534.80000000","0.00005000"],["112534.74000000","0.46938000"],["112533.90000000","0.00043000"],["112533.52000000","0.00255000"],["112533.34000000","0.00007000"],["112532.90000000","0.00118000"],["112531.55000000","1.13537000"],["112531.54000000","0.00005000"],["112531.12000000","0.46938000"],["112530.86000000","0.00005000"],["112530.11000000","0.00010000"],["112529.87000000","0.56863000"],["112529.86000000","0.31500000"],["112529.84000000","0.00000000"],["112529.71000000","0.05131000"],["112529.01000000","0.00265000"],["112528.62000000","0.06748000"],["112528.03000000","0.00000000"],["112527.92000000","0.00000000"],["112527.85000000","0.00000000"],["112527.15000000","0.00010000"],["112527.05000000","1.70701000"],["112527.03000000","0.00300000"],["112526.50000000","0.00005000"],["112526.49000000","0.00000000"],["112525.02000000","0.00022000"],["112524.96000000","0.00316000"],["112524.75000000","0.00200000"],["112524.50000000","0.00250000"],["112524.05000000","0.04317000"],["112523.61000000","0.02777000"],["112523.56000000","0.46981000"],["112522.63000000","0.00000000"],["112522.50000000","0.04508000"],["112522.41000000","0.00000000"],["112522.17000000","0.00000000"],["112522.16000000","0.04000000"],["112521.18000000","0.00000000"],["112520.99000000","0.00000000"],["112520.50000000","0.06100000"],["112520.07000000","0.00000000"],["112519.69000000","0.00000000"],["112519.45000000","0.00000000"],["112519.41000000","0.00000000"],["112517.47000000","0.01791000"],["112516.08000000","0.00000000"],["112512.90000000","0.31991000"],["112512.86000000","0.00000000"],["112512.08000000","0.00000000"],["112511.85000000","0.00009000"],["112511.75000000","0.00009000"],["112511.00000000","0.00000000"],["112510.87000000","0.24000000"],["112510.58000000","0.08000000"],["112508.13000000","0.00177000"],["112508.12000000","0.00177000"],["112508.11000000","0.21647000"],["112507.25000000","0.00000000"],["112507.15000000","0.03000000"],["112507.01000000","0.00009000"],["112506.98000000","0.01021000"],["112506.60000000","0.00059000"],["112505.04000000","0.00009000"],["112504.26000000","0.00000000"],["112502.41000000","0.00000000"],["112500.43000000","0.00000000"],["112500.20000000","0.00000000"],["112500.00000000","0.00053000"],["112499.46000000","0.00000000"],["112499.45000000","0.00000000"],["112497.34000000","0.00009000"],["112496.62000000","0.00000000"],["112493.44000000","0.00000000"],["112493.25000000","0.18855000"],["112492.97000000","0.61172000"],["112492.74000000","0.00000000"],["112489.58000000","0.00000000"],["112487.96000000","0.00000000"],["112487.30000000","0.00000000"],["112485.60000000","0.00000000"],["112482.30000000","0.08000000"],["112480.79000000","0.00000000"],["112467.79000000","0.00619000"],["112460.29000000","0.00089000"],["112459.52000000","0.00000000"],["112456.00000000","0.62961000"],["112455.69000000","0.00000000"],["112454.76000000","0.00399000"],["112454.18000000","0.00000000"],["112453.98000000","0.00000000"],["112453.74000000","0.02989000"],["112451.63000000","0.00000000"],["112450.00000000","0.11160000"],["112448.00000000","0.00160000"],["112446.00000000","0.00160000"],["112444.00000000","0.00160000"],["112443.38000000","0.00221000"],["112442.00000000","0.00160000"],["112441.02000000","0.00000000"],["112440.00000000","0.05565000"],["112437.37000000","0.88926000"],["112431.37000000","0.00221000"],["112424.63000000","0.55238000"],["112424.57000000","0.00000000"],["112420.64000000","0.00000000"],["112410.58000000","0.03907000"],["112405.90000000","0.03005000"],["112404.29000000","0.00000000"],["112396.30000000","0.39980000"],["112393.32000000","0.00000000"],["112393.31000000","0.00000000"],["112392.51000000","0.00000000"],["112387.50000000","0.00000000"],["112385.80000000","0.00000000"],["112379.12000000","0.04767000"],["112378.56000000","0.06124000"],["112373.39000000","0.15221000"],["112370.64000000","0.00000000"],["112370.54000000","0.00000000"],["112365.56000000","0.00304000"],["112354.64000000","0.00000000"],["112345.95000000","0.88998000"],["112318.18000000","0.00018000"],["112317.89000000","0.00010000"],["112317.70000000","0.00007000"],["112314.89000000","0.00007000"],["112310.14000000","0.00000000"],["112307.29000000","0.00000000"],["112303.79000000","0.00021000"],["112288.54000000","4.61943000"],["112275.87000000","0.00000000"],["112256.53000000","0.00000000"],["112253.51000000","0.00000000"],["112242.42000000","0.00031000"],["112223.80000000","0.00011000"],["112213.82000000","0.00000000"],["112200.89000000","0.00000000"],["112196.20000000","0.00000000"],["112128.68000000","0.02399000"],["112114.92000000","0.02803000"],["112031.87000000","0.00000000"],["112027.17000000","0.00000000"],["111989.34000000","0.00000000"],["111983.28000000","0.00000000"],["111965.17000000","0.00000000"],["111964.16000000","0.00000000"],["110853.00000000","0.00000000"],["110830.83000000","0.00008000"],["106430.84000000","0.00000000"],["103502.98000000","0.00010000"],["102397.24000000","0.00000000"],["101287.00000000","0.01000000"],["101286.00000000","0.00270000"],["101266.74000000","0.00000000"],["97355.24000000","0.00000000"],["91052.75000000","0.00000000"],["90039.83000000","0.00022000"],["90032.90000000","0.00000000"],["83174.63000000","0.00000000"],["78782.58000000","0.00000000"],["42000.00000000","1.40412000"]],"a":[["112541.13000000","0.00000000"],["112541.14000000","0.00000000"],["112541.21000000","0.00000000"],["112541.30000000","0.00000000"],["112541.95000000","0.00000000"],["112541.98000000","0.00000000"],["112542.00000000","0.00000000"],["112542.07000000","0.00000000"],["112542.65000000","0.00000000"],["112542.66000000","0.00000000"],["112542.76000000","0.00000000"],["112542.80000000","0.00000000"],["112542.81000000","0.00000000"],["112542.87000000","0.00000000"],["112543.02000000","0.00000000"],["112543.07000000","0.00000000"],["112543.25000000","0.00000000"],["112543.80000000","0.00000000"],["112543.97000000","0.00000000"],["112544.00000000","0.00000000"],["112544.30000000","0.00000000"],["112544.69000000","0.00000000"],["112544.81000000","0.00000000"],["112544.82000000","0.00000000"],["112545.21000000","0.00000000"],["112545.43000000","0.00000000"],["112545.45000000","0.00000000"],["112545.63000000","0.00000000"],["112545.72000000","0.00000000"],["112546.00000000","0.00000000"],["112546.40000000","0.00000000"],["112546.41000000","0.00000000"],["112546.60000000","0.00000000"],["112546.61000000","0.00000000"],["112546.63000000","0.00000000"],["112546.64000000","0.00000000"],["112546.99000000","0.00000000"],["112547.01000000","0.00000000"],["112547.02000000","0.00000000"],["112547.08000000","0.00000000"],["112547.87000000","0.00000000"],["112547.89000000","0.00000000"],["112547.90000000","0.00000000"],["112547.95000000","0.00000000"],["112548.00000000","0.00000000"],["112548.18000000","0.00000000"],["112548.24000000","0.00000000"],["112548.60000000","0.00000000"],["112548.92000000","0.00000000"],["112548.94000000","0.00000000"],["112549.47000000","0.00000000"],["112549.62000000","0.00000000"],["112549.63000000","0.00000000"],["112549.64000000","0.00000000"],["112549.77000000","0.00000000"],["112549.78000000","0.00000000"],["112549.79000000","2.26206000"],["112549.80000000","0.00069000"],["112549.84000000","0.00005000"],["112549.87000000","0.00010000"],["112549.92000000","0.00048000"],["112549.99000000","0.00010000"],["112550.00000000","0.03887000"],["112550.29000000","0.00010000"],["112550.30000000","0.24005000"],["112550.46000000","0.00010000"],["112550.54000000","0.00000000"],["112550.89000000","0.00010000"],["112550.90000000","0.06005000"],["112551.13000000","0.00000000"],["112551.19000000","0.00000000"],["112551.20000000","0.00000000"],["112551.42000000","0.00000000"],["112551.56000000","0.00005000"],["112551.64000000","0.00005000"],["112551.71000000","0.01802000"],["112551.92000000","0.00000000"],["112551.96000000","0.00178000"],["112552.00000000","0.00170000"],["112552.29000000","0.04051000"],["112552.38000000","0.00000000"],["112552.62000000","0.03005000"],["112552.63000000","0.00000000"],["112552.82000000","0.03000000"],["112553.79000000","0.00000000"],["112553.83000000","0.00005000"],["112553.86000000","0.03005000"],["112553.95000000","0.00000000"],["112554.00000000","0.00160000"],["112554.09000000","0.00000000"],["112554.12000000","0.00000000"],["112554.32000000","0.00000000"],["112554.48000000","0.00000000"],["112554.58000000","0.00005000"],["112554.75000000","0.00000000"],["112555.00000000","0.02005000"],["112555.18000000","0.00151000"],["112555.36000000","0.00000000"],["112555.43000000","0.00000000"],["112555.76000000","0.00005000"],["112555.91000000","0.00612000"],["112556.00000000","0.00165000"],["112556.07000000","0.00255000"],["112556.08000000","0.03305000"],["112556.15000000","0.00000000"],["112557.72000000","0.00000000"],["112557.90000000","0.03000000"],["112558.00000000","0.06260000"],["112558.01000000","0.00151000"],["112558.83000000","0.05049000"],["112558.87000000","0.00000000"],["112559.00000000","0.00000000"],["112559.12000000","0.20523000"],["112559.33000000","0.00000000"],["112559.35000000","0.00000000"],["112561.42000000","0.00000000"],["112561.45000000","0.00000000"],["112561.91000000","0.00000000"],["112562.48000000","0.00000000"],["112562.97000000","0.03000000"],["112562.98000000","0.00070000"],["112563.02000000","0.00000000"],["112563.32000000","0.00000000"],["112563.97000000","0.00000000"],["112564.26000000","0.00444000"],["112564.42000000","0.09073000"],["112564.66000000","0.05400000"],["112565.77000000","0.00000000"],["112566.39000000","0.00000000"],["112566.67000000","0.00239000"],["112567.19000000","0.00000000"],["112568.38000000","0.00000000"],["112568.64000000","0.00000000"],["112568.76000000","0.00000000"],["112569.01000000","0.00034000"],["112569.04000000","0.00888000"],["112569.15000000","0.00039000"],["112570.35000000","0.00000000"],["112571.39000000","0.29977000"],["112571.99000000","0.15146000"],["112572.73000000","0.26683000"],["112572.79000000","0.00000000"],["112573.86000000","0.00451000"],["112573.99000000","0.26660000"],["112574.26000000","0.00005000"],["112574.54000000","0.00012000"],["112574.55000000","0.00022000"],["112575.64000000","0.00005000"],["112576.45000000","0.00000000"],["112577.53000000","0.00000000"],["112577.90000000","0.00000000"],["112577.92000000","0.00088000"],["112577.95000000","0.00274000"],["112578.48000000","0.01256000"],["112578.62000000","0.00250000"],["112582.57000000","0.03900000"],["112585.67000000","0.00000000"],["112585.70000000","0.00000000"],["112586.03000000","0.00000000"],["112586.06000000","0.03600000"],["112586.11000000","0.00000000"],["112586.16000000","0.00000000"],["112586.21000000","0.00000000"],["112586.24000000","0.00000000"],["112587.87000000","0.18839000"],["112588.03000000","0.03778000"],["112588.65000000","0.31970000"],["112588.84000000","0.00306000"],["112589.33000000","0.00000000"],["112589.40000000","0.00000000"],["112590.34000000","0.00000000"],["112590.86000000","0.00000000"],["112590.92000000","0.00000000"],["112590.96000000","0.00000000"],["112591.47000000","0.21135000"],["112591.77000000","0.00000000"],["112592.06000000","0.04400000"],["112592.59000000","0.01021000"],["112593.13000000","0.11000000"],["112597.56000000","0.00005000"],["112600.43000000","0.00088000"],["112603.04000000","0.00005000"],["112606.92000000","0.00000000"],["112607.28000000","0.00000000"],["112608.03000000","0.00000000"],["112608.13000000","0.08000000"],["112609.98000000","0.00005000"],["112610.00000000","0.20000000"],["112614.96000000","0.01180000"],["112615.55000000","0.00000000"],["112616.37000000","0.01021000"],["112617.75000000","0.26683000"],["112619.01000000","0.26660000"],["112619.98000000","0.00000000"],["112622.54000000","0.03000000"],["112628.86000000","0.26677000"],["112629.17000000","0.03000000"],["112629.32000000","0.03000000"],["112629.35000000","0.00000000"],["112629.36000000","0.00005000"],["112631.90000000","0.05400000"],["112633.91000000","0.03000000"],["112635.16000000","0.00000000"],["112635.17000000","0.00000000"],["112635.62000000","0.00000000"],["112636.13000000","0.00000000"],["112636.62000000","0.00000000"],["112639.15000000","0.00399000"],["112642.94000000","0.00399000"],["112644.53000000","0.03400000"],["112647.56000000","0.00000000"],["112648.99000000","0.07258000"],["112649.15000000","0.40000000"],["112649.52000000","0.00000000"],["112649.53000000","0.00000000"],["112652.70000000","0.00007000"],["112653.80000000","0.00005000"],["112654.26000000","0.00084000"],["112678.55000000","0.00000000"],["112685.65000000","0.00000000"],["112686.05000000","0.00000000"],["112691.03000000","0.00000000"],["112691.72000000","0.01849000"],["112693.18000000","0.00000000"],["112693.71000000","0.00000000"],["112695.57000000","0.00000000"],["112698.42000000","0.00000000"],["112704.63000000","0.00000000"],["112714.72000000","0.00000000"],["112721.83000000","0.02241000"],["112722.19000000","0.01582000"],["112722.58000000","0.00000000"],["112725.51000000","0.00405000"],["112734.11000000","0.00000000"],["112735.08000000","0.00000000"],["112737.20000000","0.02676000"],["112749.48000000","0.00005000"],["112760.75000000","0.03598000"],["112762.19000000","0.03598000"],["112768.10000000","0.00000000"],["112769.77000000","0.00005000"],["112774.11000000","0.00080000"],["112779.72000000","4.88104000"],["112850.47000000","0.00000000"],["112854.62000000","0.00000000"],["112859.71000000","0.00000000"],["112878.11000000","0.02399000"],["112880.23000000","0.02398000"],["112896.34000000","0.02399000"],["112898.69000000","1.19998000"],["112903.40000000","0.00000000"],["112905.86000000","0.00000000"],["112906.77000000","0.00000000"],["112908.16000000","0.00000000"],["112923.52000000","0.00010000"],["112925.56000000","0.02739000"],["112929.14000000","0.00010000"],["112930.17000000","0.03398000"],["112930.81000000","0.06696000"],["112931.63000000","0.03398000"],["112932.44000000","0.03398000"],["112964.13000000","0.00000000"],["112965.10000000","0.00000000"],["113051.06000000","0.00000000"],["113052.57000000","0.00000000"],["113053.79000000","0.00000000"],["113053.86000000","0.00000000"],["113054.55000000","0.00000000"],["113055.21000000","0.00000000"],["113055.25000000","0.00006000"],["113056.05000000","0.00000000"],["113056.70000000","0.00000000"],["113056.88000000","0.00000000"],["113058.16000000","0.00000000"],["113059.09000000","0.00000000"],["113070.69000000","0.03098000"],["113072.17000000","0.03104000"],["113074.09000000","0.03098000"],["113075.57000000","0.03098000"],["113075.98000000","0.02209000"],["113076.93000000","0.03098000"],["113078.22000000","0.03098000"],["113078.91000000","0.03098000"],["113079.47000000","0.03098000"],["113080.04000000","0.03098000"],["113080.60000000","0.03098000"],["113081.16000000","0.03098000"],["113081.73000000","0.03098000"],["113135.04000000","0.54998000"],["114229.25000000","0.00000000"]]}
[2025-10-26T09:48:12.277Z] {"e":"depthUpdate","E":1761472091014,"s":"BTCUSDT","U":79058053893,"u":79058054650,"b":[["112549.78000000","2.27154000"],["112549.77000000","0.00060000"],["112549.76000000","0.00000000"],["112549.75000000","0.00000000"],["112549.74000000","0.00000000"],["112549.73000000","0.00000000"],["112549.72000000","0.00000000"],["112549.71000000","0.00000000"],["112549.70000000","0.00010000"],["112549.69000000","0.00000000"],["112549.68000000","0.00000000"],["112548.82000000","0.00005000"],["112548.39000000","0.00356000"],["112548.37000000","0.00000000"],["112546.84000000","0.00000000"],["112546.29000000","0.00010000"],["112546.28000000","0.20509000"],["112545.81000000","0.00010000"],["112545.80000000","0.04590000"],["112544.01000000","0.00005000"],["112542.07000000","0.03263000"],["112541.98000000","0.00000000"],["112541.97000000","0.00000000"],["112541.22000000","0.00000000"],["112541.16000000","0.00000000"],["112541.15000000","0.00000000"],["112541.14000000","0.00010000"],["112541.13000000","0.12479000"],["112541.12000000","0.19454000"],["112539.37000000","0.00005000"],["112538.80000000","0.00000000"],["112538.68000000","0.00000000"],["112538.54000000","0.00000000"],["112538.53000000","0.00000000"],["112538.52000000","0.22560000"],["112537.05000000","0.00000000"],["112537.02000000","0.00000000"],["112536.68000000","0.00069000"],["112536.64000000","0.00074000"],["112536.01000000","0.00000000"],["112536.00000000","0.06005000"],["112535.79000000","0.04579000"],["112535.59000000","0.25687000"],["112535.58000000","0.00005000"],["112535.16000000","0.00000000"],["112535.15000000","0.09400000"],["112534.74000000","0.46938000"],["112533.90000000","0.00000000"],["112532.91000000","0.00000000"],["112532.90000000","0.00123000"],["112531.56000000","0.00000000"],["112531.55000000","1.13537000"],["112531.54000000","0.00000000"],["112530.94000000","0.00005000"],["112529.71000000","0.05288000"],["112529.02000000","0.00449000"],["112529.01000000","0.00250000"],["112528.62000000","0.00005000"],["112527.80000000","0.08961000"],["112527.15000000","0.00110000"],["112524.98000000","0.28042000"],["112524.97000000","0.29980000"],["112523.62000000","0.00000000"],["112523.56000000","0.46938000"],["112522.50000000","0.04503000"],["112521.52000000","0.01256000"],["112521.35000000","0.00000000"],["112521.17000000","0.00000000"],["112521.10000000","0.00000000"],["112518.62000000","0.04442000"],["112512.90000000","0.00000000"],["112512.00000000","0.00120000"],["112510.00000000","0.00120000"],["112508.00000000","0.00120000"],["112506.71000000","0.00000000"],["112506.53000000","0.31993000"],["112506.00000000","0.00120000"],["112504.00000000","0.00120000"],["112502.00000000","0.00120000"],["112500.00000000","0.00173000"],["112499.66000000","0.31500000"],["112497.85000000","0.98908000"],["112493.51000000","0.00020000"],["112493.15000000","0.00000000"],["112492.93000000","0.31997000"],["112487.64000000","0.00000000"],["112481.73000000","0.02984000"],["112453.74000000","0.00005000"],["112441.15000000","0.53153000"],["112433.21000000","0.06598000"],["112431.42000000","0.00000000"],["112427.45000000","0.03598000"],["112420.01000000","0.10794000"],["112419.31000000","0.70373000"],["112417.83000000","0.01573000"],["112414.86000000","0.03598000"],["112411.62000000","0.07196000"],["112398.00000000","0.00040000"],["112396.00000000","0.00040000"],["112394.00000000","0.00040000"],["112393.58000000","0.02049000"],["112392.00000000","0.00040000"],["112390.00000000","0.00040000"],["112388.00000000","0.00040000"],["112387.19000000","0.00000000"],["112386.00000000","0.00040000"],["112384.73000000","0.00304000"],["112384.00000000","0.00040000"],["112383.71000000","0.06000000"],["112382.00000000","0.00040000"],["112380.00000000","0.00040000"],["112378.00000000","0.00040000"],["112376.00000000","0.00040000"],["112374.00000000","0.00040000"],["112373.27000000","0.00000000"],["112372.00000000","0.00040000"],["112370.00000000","0.00040000"],["112369.03000000","0.00000000"],["112368.00000000","0.00040000"],["112366.00000000","0.00040000"],["112365.56000000","0.00000000"],["112364.00000000","0.00040000"],["112362.00000000","0.00040000"],["112361.70000000","0.06748000"],["112360.00000000","0.00129000"],["112359.30000000","0.09455000"],["112358.07000000","0.00000000"],["112358.00000000","0.00040000"],["112356.00000000","0.00040000"],["112354.00000000","0.00040000"],["112352.00000000","0.00040000"],["112350.00000000","0.02460000"],["112348.00000000","0.00040000"],["112346.00000000","0.00040000"],["112344.00000000","0.00040000"],["112342.00000000","0.00040000"],["112340.00000000","0.00040000"],["112321.02000000","0.02398000"],["112317.34000000","0.00000000"],["112316.42000000","0.00000000"],["112316.23000000","0.00000000"],["112316.01000000","0.00000000"],["112315.06000000","0.00000000"],["112213.80000000","0.00000000"],["112161.11000000","0.00000000"],["112073.61000000","0.00000000"],["112048.97000000","0.03098000"],["112048.22000000","0.03194000"],["111969.30000000","0.00000000"],["111944.54000000","0.00000000"],["111944.39000000","0.00005000"],["110861.53000000","0.00100000"],["110839.36000000","0.00008000"],["110830.83000000","0.00000000"],["107259.94000000","0.00093000"],["103800.00000000","1.00093000"],["103502.98000000","0.00000000"],["103482.28000000","0.00000000"],["101294.00000000","0.00010000"],["101286.00000000","0.00260000"],["101273.74000000","0.00000000"],["90039.83000000","0.00022000"],["33000.01000000","0.00000000"],["33000.00000000","3.78938000"]],"a":[["112549.79000000","3.64696000"],["112549.80000000","0.04491000"],["112550.00000000","0.03892000"],["112550.30000000","0.24010000"],["112550.47000000","0.15151000"],["112550.90000000","0.06010000"],["112551.56000000","0.00255000"],["112551.64000000","0.00000000"],["112551.71000000","0.01761000"],["112551.96000000","0.00000000"],["112555.18000000","0.00156000"],["112555.30000000","0.20484000"],["112555.53000000","0.00000000"],["112555.75000000","0.00607000"],["112556.07000000","0.00255000"],["112556.08000000","0.00000000"],["112556.93000000","0.06753000"],["112557.11000000","0.03005000"],["112557.36000000","0.00000000"],["112557.37000000","0.00000000"],["112557.38000000","0.00000000"],["112557.40000000","0.00000000"],["112557.89000000","0.03600000"],["112558.15000000","0.00000000"],["112558.51000000","0.00200000"],["112558.83000000","0.03000000"],["112559.12000000","0.00039000"],["112559.82000000","0.00000000"],["112562.00000000","0.06229000"],["112562.37000000","0.00000000"],["112562.45000000","0.00000000"],["112562.98000000","0.00000000"],["112563.02000000","0.04000000"],["112563.93000000","0.03000000"],["112565.23000000","0.02049000"],["112570.31000000","0.04480000"],["112570.79000000","1.10000000"],["112572.76000000","0.00000000"],["112573.29000000","0.94060000"],["112573.82000000","0.03746000"],["112574.11000000","0.00000000"],["112574.16000000","0.00000000"],["112574.44000000","0.31974000"],["112578.62000000","0.00000000"],["112581.00000000","0.06100000"],["112581.10000000","0.46938000"],["112582.57000000","0.00000000"],["112583.45000000","0.00005000"],["112583.56000000","0.00300000"],["112588.84000000","0.00000000"],["112590.99000000","0.00000000"],["112591.02000000","0.00000000"],["112591.06000000","0.00000000"],["112591.09000000","0.00000000"],["112591.12000000","0.06734000"],["112595.03000000","0.00000000"],["112600.00000000","0.21303000"],["112603.01000000","0.00006000"],["112603.62000000","0.00000000"],["112605.22000000","0.00000000"],["112607.06000000","0.00000000"],["112608.05000000","0.00306000"],["112610.00000000","0.36000000"],["112614.24000000","0.00006000"],["112618.61000000","0.00633000"],["112620.72000000","0.00627000"],["112623.95000000","0.03460000"],["112625.37000000","0.00000000"],["112625.60000000","0.00000000"],["112625.63000000","0.00927000"],["112627.05000000","0.00000000"],["112628.70000000","0.00000000"],["112628.79000000","0.00000000"],["112628.86000000","0.00000000"],["112628.87000000","0.00000000"],["112628.95000000","0.00000000"],["112628.98000000","0.00000000"],["112629.07000000","0.00000000"],["112629.27000000","0.00000000"],["112629.35000000","0.00000000"],["112629.50000000","0.44510000"],["112629.67000000","0.35608000"],["112631.03000000","0.44452000"],["112636.16000000","0.00000000"],["112636.17000000","0.00000000"],["112649.10000000","0.00000000"],["112664.84000000","0.00005000"],["112673.39000000","0.00005000"],["112690.43000000","0.47523000"],["112694.14000000","0.00000000"],["112698.61000000","0.12982000"],["112730.73000000","0.04374000"],["112861.03000000","0.00000000"],["112880.78000000","0.02398000"],["112927.14000000","0.02812000"],["112988.11000000","0.02598000"],["112988.50000000","0.02598000"],["113541.15000000","0.00000000"],["114238.04000000","0.00112000"]]}
[2025-10-26T09:48:13.095Z] {"e":"depthUpdate","E":1761472092014,"s":"BTCUSDT","U":79058054651,"u":79058055102,"b":[["112549.78000000","2.62314000"],["112549.77000000","0.00070000"],["112548.66000000","0.00118000"],["112548.39000000","0.00371000"],["112548.37000000","0.00005000"],["112546.97000000","0.00201000"],["112546.30000000","0.00010000"],["112546.29000000","0.15412000"],["112546.28000000","0.20494000"],["112545.81000000","0.00000000"],["112545.80000000","0.00005000"],["112545.28000000","0.00360000"],["112545.00000000","0.00005000"],["112544.15000000","0.00010000"],["112544.14000000","0.29327000"],["112544.01000000","0.00000000"],["112543.03000000","0.00538000"],["112542.07000000","0.03273000"],["112541.45000000","0.00005000"],["112541.44000000","0.06238000"],["112541.43000000","0.00000000"],["112541.14000000","0.00000000"],["112541.13000000","0.00000000"],["112541.12000000","0.19454000"],["112540.22000000","0.00396000"],["112539.37000000","0.00000000"],["112538.53000000","0.00721000"],["112538.52000000","0.00300000"],["112536.68000000","0.00000000"],["112536.00000000","0.06005000"],["112535.79000000","0.04574000"],["112535.59000000","0.16936000"],["112535.58000000","0.00000000"],["112533.20000000","0.00005000"],["112532.95000000","0.00000000"],["112532.90000000","0.00118000"],["112532.89000000","0.22255000"],["112529.71000000","0.05288000"],["112529.02000000","0.00444000"],["112529.01000000","0.00250000"],["112528.62000000","0.00000000"],["112527.80000000","0.08961000"],["112527.41000000","0.04443000"],["112526.92000000","0.00005000"],["112526.03000000","0.00000000"],["112525.92000000","0.26660000"],["112524.82000000","0.00000000"],["112524.34000000","0.00000000"],["112524.05000000","0.00000000"],["112523.38000000","0.01256000"],["112522.65000000","0.00000000"],["112522.50000000","0.00000000"],["112521.87000000","0.00000000"],["112521.52000000","0.00000000"],["112521.40000000","0.04423000"],["112520.40000000","0.00000000"],["112516.14000000","0.00000000"],["112516.02000000","0.04449000"],["112512.77000000","0.00000000"],["112512.18000000","0.31992000"],["112510.92000000","0.00000000"],["112492.93000000","0.00000000"],["112467.87000000","0.46938000"],["112425.92000000","0.01391000"],["112414.20000000","0.02049000"],["112393.58000000","0.00000000"],["112392.50000000","0.06000000"],["112388.82000000","0.09327000"],["112387.01000000","0.00000000"],["112338.00000000","0.00040000"],["112336.00000000","0.00040000"],["112334.00000000","0.00040000"],["112332.00000000","0.00040000"],["112330.00000000","0.00040000"],["112328.00000000","0.00040000"],["112326.00000000","0.00139000"],["112324.00000000","0.01906000"],["112322.00000000","0.00040000"],["112320.00000000","0.34492000"],["112318.00000000","0.00040000"],["112317.41000000","0.00000000"],["112316.00000000","0.00040000"],["112314.00000000","0.00040000"],["112312.00000000","0.00040000"],["112310.00000000","0.00040000"],["112308.00000000","0.00040000"],["112306.00000000","0.00040000"],["112304.00000000","0.00040000"],["112302.00000000","0.00040000"],["112300.50000000","0.00567000"],["112300.01000000","0.00000000"],["112300.00000000","12.61763000"],["112277.78000000","0.00000000"],["112222.75000000","0.00000000"],["112168.46000000","0.02498000"],["111422.72000000","0.00022000"],["111400.44000000","0.00008000"],["111011.64000000","0.00000000"],["110861.53000000","0.00100000"],["110839.36000000","0.00000000"],["101294.00000000","0.00010000"],["101273.74000000","0.00000000"],["90039.83000000","0.00022000"],["90033.00000000","0.00000000"],["40517.92000000","0.00015000"]],"a":[["112549.79000000","2.78518000"],["112549.80000000","0.04506000"],["112550.90000000","0.06005000"],["112550.91000000","0.00098000"],["112551.56000000","0.00005000"],["112552.29000000","0.04056000"],["112552.60000000","0.00196000"],["112554.00000000","0.00165000"],["112554.01000000","0.04574000"],["112554.29000000","0.00355000"],["112554.71000000","0.20484000"],["112555.30000000","0.00000000"],["112555.75000000","0.00702000"],["112556.07000000","0.00250000"],["112556.54000000","0.00533000"],["112556.93000000","0.06748000"],["112557.11000000","0.03000000"],["112557.37000000","0.00000000"],["112557.39000000","0.00000000"],["112557.40000000","0.00000000"],["112559.35000000","0.00391000"],["112561.04000000","0.00711000"],["112565.23000000","0.00000000"],["112565.48000000","0.03300000"],["112570.31000000","0.00000000"],["112574.11000000","0.00250000"],["112574.43000000","0.04480000"],["112574.44000000","0.00000000"],["112585.71000000","0.04450000"],["112585.88000000","0.02049000"],["112590.15000000","0.02493000"],["112591.12000000","0.00000000"],["112591.32000000","0.06744000"],["112593.26000000","0.31969000"],["112599.46000000","0.04380000"],["112600.00000000","0.22787000"],["112602.00000000","0.00120000"],["112604.00000000","0.00120000"],["112606.00000000","0.00120000"],["112608.00000000","0.00120000"],["112610.00000000","0.36120000"],["112612.00000000","0.00120000"],["112614.00000000","0.00120000"],["112616.00000000","0.00120000"],["112618.00000000","0.00120000"],["112620.00000000","0.28662000"],["112622.00000000","0.00120000"],["112622.25000000","0.03460000"],["112623.95000000","0.00000000"],["112624.00000000","0.00120000"],["112626.00000000","0.00120000"],["112628.00000000","0.00120000"],["112628.99000000","0.26677000"],["112629.12000000","0.00000000"],["112629.38000000","0.03000000"],["112629.45000000","0.00000000"],["112629.86000000","0.00000000"],["112630.00000000","0.00120000"],["112632.00000000","0.00120000"],["112633.26000000","0.00089000"],["112634.00000000","0.00120000"],["112636.00000000","0.00120000"],["112636.20000000","0.00100000"],["112636.21000000","0.00100000"],["112638.00000000","0.00120000"],["112640.00000000","0.01949000"],["112641.16000000","0.00000000"],["112642.00000000","0.00120000"],["112644.00000000","0.00120000"],["112646.00000000","0.00120000"],["112648.00000000","0.00120000"],["112650.00000000","0.03229000"],["112650.39000000","0.00000000"],["112652.00000000","0.00120000"],["112654.00000000","0.00120000"],["112656.00000000","0.00120000"],["112658.00000000","0.00120000"],["112660.00000000","0.01895000"],["112662.00000000","0.00120000"],["112664.00000000","0.00120000"],["112666.00000000","0.00120000"],["112668.00000000","0.00120000"],["112670.00000000","0.00120000"],["112672.00000000","0.00120000"],["112674.00000000","0.00820000"],["112676.00000000","0.00120000"],["112678.00000000","0.00120000"],["112680.00000000","0.00198000"],["112682.00000000","0.00120000"],["112684.00000000","0.00127000"],["112686.00000000","0.00120000"],["112688.00000000","0.00585000"],["112690.00000000","0.00145000"],["112690.43000000","0.00000000"],["112692.00000000","0.00120000"],["112694.00000000","0.00125000"],["112696.00000000","0.00120000"],["112698.00000000","0.00120000"],["112698.61000000","0.13177000"],["112700.00000000","0.58984000"],["112730.73000000","0.00000000"],["112734.89000000","0.01599000"],["112958.02000000","0.00005000"],["114238.04000000","0.00112000"]]}
[2025-10-26T09:48:14.223Z] {"e":"depthUpdate","E":1761472093014,"s":"BTCUSDT","U":79058055103,"u":79058055656,"b":[["112549.78000000","2.53037000"],["112549.77000000","0.00050000"],["112548.66000000","0.00123000"],["112548.39000000","0.00005000"],["112547.12000000","0.00000000"],["112546.98000000","0.00366000"],["112546.97000000","0.00201000"],["112546.48000000","0.00010000"],["112546.47000000","0.20494000"],["112546.30000000","0.00000000"],["112546.29000000","0.00000000"],["112546.28000000","0.00000000"],["112545.28000000","0.00360000"],["112544.15000000","0.00000000"],["112544.14000000","0.00000000"],["112542.68000000","0.00005000"],["112542.07000000","0.03278000"],["112541.45000000","0.00010000"],["112541.44000000","0.06243000"],["112541.13000000","0.00010000"],["112541.12000000","0.19459000"],["112540.75000000","0.00000000"],["112538.74000000","0.00005000"],["112538.53000000","0.00721000"],["112537.81000000","0.00005000"],["112537.80000000","0.35524000"],["112537.79000000","0.29324000"],["112536.01000000","0.00000000"],["112535.79000000","0.04574000"],["112535.59000000","0.00000000"],["112524.96000000","0.00000000"],["112523.38000000","0.00000000"],["112522.62000000","0.00000000"],["112521.15000000","0.01256000"],["112516.02000000","0.00000000"],["112514.17000000","0.00000000"],["112512.18000000","0.00000000"],["112492.96000000","0.00465000"],["112492.75000000","0.31997000"],["112480.00000000","0.04145000"],["112478.00000000","0.00140000"],["112477.04000000","0.26660000"],["112476.00000000","0.00140000"],["112474.00000000","0.00140000"],["112470.00000000","0.36140000"],["112460.00000000","1.70861000"],["112458.00000000","0.00160000"],["112456.00000000","0.62981000"],["112454.00000000","0.00160000"],["112425.92000000","0.00000000"],["112392.50000000","0.06005000"],["112317.17000000","0.00534000"],["112298.00000000","0.00000000"],["112296.00000000","0.00000000"],["112294.00000000","0.00000000"],["112292.00000000","0.00005000"],["112290.00000000","0.00000000"],["112288.00000000","0.00000000"],["112286.00000000","0.00000000"],["112284.00000000","0.00000000"],["112282.00000000","0.00000000"],["112280.00000000","0.00000000"],["112278.00000000","0.00000000"],["112276.00000000","0.00000000"],["112274.00000000","0.00000000"],["112272.00000000","0.00000000"],["112270.00000000","0.00000000"],["112268.00000000","0.00000000"],["112266.00000000","0.00000000"],["112264.00000000","0.00000000"],["112262.00000000","0.00000000"],["112261.51000000","0.19121000"],["112260.00000000","0.00000000"],["112258.00000000","0.00000000"],["112256.00000000","0.00000000"],["112254.00000000","0.00000000"],["112252.00000000","0.00000000"],["112250.00000000","0.17063000"],["112248.00000000","0.00000000"],["112246.00000000","0.00000000"],["112244.00000000","0.00000000"],["112242.00000000","0.00000000"],["112240.00000000","1.35085000"],["112238.00000000","0.00000000"],["112236.00000000","0.00000000"],["112234.00000000","0.00000000"],["112232.00000000","0.00000000"],["112230.00000000","0.00000000"],["112228.00000000","0.00000000"],["112226.00000000","0.00000000"],["112224.00000000","0.00000000"],["112222.00000000","0.00000000"],["112220.00000000","0.00236000"],["112218.00000000","0.00000000"],["112216.00000000","0.00000000"],["112214.00000000","0.00000000"],["112212.00000000","0.00000000"],["112210.00000000","0.00000000"],["112208.00000000","0.00000000"],["112206.00000000","2.02107000"],["112204.00000000","0.00000000"],["112203.83000000","0.00000000"],["112202.00000000","0.00000000"],["112200.00000000","0.17119000"],["111965.57000000","0.00000000"],["111400.44000000","0.00000000"],["111026.90000000","0.00008000"],["110969.65000000","0.00000000"],["110861.53000000","0.00100000"],["101294.00000000","0.00010000"],["90039.83000000","0.00022000"],["60000.00000000","57.64892000"],["42000.01000000","0.00000000"],["42000.00000000","1.40312000"],["41991.61000000","0.00023000"],["40517.92000000","0.00030000"]],"a":[["112549.79000000","2.66857000"],["112549.80000000","0.04659000"],["112550.00000000","0.03892000"],["112550.29000000","0.00000000"],["112550.30000000","0.00000000"],["112550.37000000","0.00036000"],["112550.90000000","0.06010000"],["112551.64000000","0.00005000"],["112552.82000000","0.03005000"],["112553.60000000","0.08000000"],["112554.71000000","0.00000000"],["112554.80000000","0.16000000"],["112555.15000000","0.20484000"],["112555.29000000","0.00000000"],["112555.91000000","0.00612000"],["112556.00000000","0.00160000"],["112557.40000000","0.00000000"],["112557.41000000","0.00000000"],["112557.48000000","0.00000000"],["112573.82000000","0.35720000"],["112578.43000000","0.01256000"],["112578.48000000","0.00000000"],["112585.71000000","0.00000000"],["112593.26000000","0.00000000"],["112602.00000000","0.00160000"],["112604.00000000","0.00160000"],["112606.00000000","0.00160000"],["112608.00000000","0.00160000"],["112610.00000000","0.36160000"],["112612.00000000","0.00160000"],["112614.00000000","0.00160000"],["112616.00000000","0.00160000"],["112618.00000000","0.00160000"],["112620.00000000","0.28702000"],["112622.00000000","0.00160000"],["112624.00000000","0.00160000"],["112626.00000000","0.00160000"],["112628.00000000","0.00160000"],["112628.59000000","0.00005000"],["112628.61000000","0.00000000"],["112628.67000000","0.00000000"],["112628.99000000","0.00000000"],["112629.50000000","0.00000000"],["112629.54000000","0.35608000"],["112629.60000000","0.44510000"],["112629.67000000","0.00000000"],["112630.00000000","0.00160000"],["112632.00000000","0.00160000"],["112634.00000000","0.00160000"],["112636.00000000","0.00160000"],["112638.00000000","0.00160000"],["112640.00000000","0.01989000"],["112642.00000000","0.00160000"],["112644.00000000","0.00160000"],["112646.00000000","0.00160000"],["112648.00000000","0.00160000"],["112650.00000000","0.03269000"],["112652.00000000","0.00140000"],["112683.00000000","0.00000000"],["112691.72000000","0.00000000"],["112700.00000000","0.56984000"],["112714.40000000","0.01849000"],["112770.76000000","0.90674000"],["114238.04000000","0.00112000"]]}
[2025-10-26T09:48:15.143Z] {"e":"depthUpdate","E":1761472094014,"s":"BTCUSDT","U":79058055657,"u":79058055830,"b":[["112549.78000000","2.53041000"],["112549.77000000","0.00055000"],["112542.07000000","0.03273000"],["112541.44000000","0.16990000"],["112541.12000000","0.09229000"],["112541.11000000","0.09322000"],["112540.38000000","0.00005000"],["112537.81000000","0.00000000"],["112537.80000000","0.30049000"],["112537.79000000","0.00000000"],["112537.68000000","0.29319000"],["112536.00000000","0.06000000"],["112521.42000000","0.00000000"],["112521.29000000","0.00000000"],["112521.21000000","0.00000000"],["112521.15000000","0.00000000"],["112498.63000000","0.98153000"],["112497.85000000","0.00000000"],["112481.73000000","0.00000000"],["112480.00000000","0.00145000"],["112470.00000000","0.16140000"],["112468.46000000","0.02984000"],["112439.40000000","0.00005000"],["112428.62000000","0.00005000"],["112288.54000000","0.00000000"],["112000.00000000","2.26273000"],["110861.53000000","0.00100000"],["110700.01000000","0.00008000"],["110700.00000000","0.19196000"],["109568.00000000","0.00100000"],["101294.00000000","0.00010000"],["90039.83000000","0.00022000"],["60000.00000000","57.64882000"],["41991.61000000","0.00000000"],["40517.92000000","0.00060000"]],"a":[["112549.79000000","2.67268000"],["112557.48000000","0.00000000"],["112573.17000000","0.94334000"],["112573.29000000","0.00000000"],["112578.43000000","0.00000000"],["112578.45000000","0.01256000"],["112596.85000000","0.00005000"],["112628.60000000","0.00000000"],["112628.85000000","0.00000000"],["112629.00000000","0.00000000"],["112629.14000000","0.00000000"],["112629.57000000","0.00000000"],["112652.00000000","0.00160000"],["112654.00000000","0.00160000"],["112656.00000000","0.00160000"],["112658.00000000","0.00160000"],["112660.00000000","0.01935000"],["112662.00000000","0.00160000"],["112664.00000000","0.00160000"],["112666.00000000","0.00160000"],["112668.00000000","0.00160000"],["112668.08000000","0.00000000"],["112670.00000000","0.00160000"],["112672.00000000","0.00160000"],["112674.00000000","0.00860000"],["112676.00000000","0.00160000"],["112678.00000000","0.00160000"],["112680.00000000","0.00238000"],["112682.00000000","0.00160000"],["112684.00000000","0.00167000"],["112686.00000000","0.00160000"],["112688.00000000","0.00625000"],["112690.00000000","0.00185000"],["112692.00000000","0.00160000"],["112694.00000000","0.00165000"],["112694.14000000","0.47523000"],["112696.00000000","0.00160000"],["112698.00000000","0.00160000"],["112700.00000000","0.57024000"],["112708.34000000","0.02132000"],["112779.72000000","0.00000000"],["114238.04000000","0.00112000"],["118000.00000000","54.37967000"]]}
[2025-10-26T09:48:16.048Z] {"e":"depthUpdate","E":1761472095014,"s":"BTCUSDT","U":79058055831,"u":79058056449,"b":[["112549.78000000","3.21561000"],["112549.77000000","0.00055000"],["112549.70000000","0.00010000"],["112549.50000000","0.00000000"],["112548.66000000","0.00118000"],["112546.98000000","0.00000000"],["112546.97000000","0.00206000"],["112546.48000000","0.00000000"],["112546.47000000","0.00000000"],["112546.33000000","0.00000000"],["112545.28000000","0.00370000"],["112544.55000000","0.01379000"],["112544.54000000","0.04585000"],["112543.03000000","0.00538000"],["112542.12000000","0.00010000"],["112542.11000000","0.20494000"],["112542.07000000","0.03278000"],["112541.46000000","0.00000000"],["112541.45000000","0.00000000"],["112541.44000000","0.00005000"],["112541.37000000","0.29318000"],["112541.13000000","0.17779000"],["112541.12000000","0.09234000"],["112541.11000000","0.09322000"],["112540.38000000","0.00000000"],["112538.54000000","0.00000000"],["112538.53000000","0.00771000"],["112538.48000000","0.00000000"],["112538.47000000","0.00005000"],["112538.29000000","0.00000000"],["112538.03000000","0.00255000"],["112537.80000000","0.00000000"],["112537.68000000","0.00000000"],["112537.59000000","0.00000000"],["112536.15000000","0.00000000"],["112536.02000000","0.09596000"],["112536.01000000","0.00005000"],["112536.00000000","0.00000000"],["112535.97000000","0.00000000"],["112535.96000000","0.00000000"],["112535.80000000","0.00000000"],["112535.79000000","0.04574000"],["112535.72000000","0.00000000"],["112535.16000000","0.00000000"],["112535.15000000","0.09400000"],["112534.75000000","0.00000000"],["112534.74000000","0.00000000"],["112533.53000000","0.00000000"],["112533.52000000","0.00255000"],["112532.91000000","0.00000000"],["112532.90000000","0.00118000"],["112532.89000000","0.00000000"],["112532.50000000","0.06000000"],["112532.07000000","0.00000000"],["112531.55000000","0.48554000"],["112529.88000000","0.00000000"],["112529.71000000","0.00000000"],["112529.35000000","0.01777000"],["112529.28000000","0.00000000"],["112529.02000000","0.00000000"],["112527.81000000","0.00444000"],["112527.27000000","0.22255000"],["112527.05000000","0.00000000"],["112526.28000000","0.00005000"],["112525.95000000","0.26808000"],["112525.94000000","0.00000000"],["112525.93000000","0.00000000"],["112525.92000000","0.00000000"],["112525.62000000","0.05109000"],["112524.98000000","0.00000000"],["112522.16000000","0.00000000"],["112521.46000000","0.00000000"],["112521.41000000","0.01256000"],["112521.24000000","0.00000000"],["112520.51000000","0.35534000"],["112518.58000000","0.04000000"],["112515.48000000","0.00000000"],["112514.41000000","0.26660000"],["112507.03000000","0.31993000"],["112506.87000000","0.00000000"],["112506.53000000","0.00000000"],["112501.36000000","0.31995000"],["112500.91000000","0.00000000"],["112488.15000000","0.00000000"],["112487.32000000","0.00000000"],["112482.55000000","0.00010000"],["112471.30000000","0.00010000"],["112471.01000000","0.00383000"],["112470.00000000","0.04140000"],["112468.46000000","0.00000000"],["112466.19000000","0.00000000"],["112460.04000000","0.02488000"],["112460.03000000","0.00000000"],["112459.91000000","0.00000000"],["112459.84000000","0.00283000"],["112450.00000000","0.02160000"],["112448.64000000","0.02984000"],["112431.36000000","0.00000000"],["112428.09000000","0.00000000"],["112414.87000000","0.00220000"],["112384.73000000","0.00000000"],["112378.36000000","0.00304000"],["112330.66000000","0.00088000"],["112318.19000000","0.00088000"],["112306.12000000","0.01391000"],["112303.31000000","0.00088000"],["112290.42000000","4.81860000"],["112274.01000000","0.00000000"],["112262.01000000","0.00000000"],["110861.53000000","0.00100000"],["101294.00000000","0.00010000"],["90040.00000000","0.00025000"],["90039.83000000","0.00022000"],["40517.92000000","0.00075000"]],"a":[["112549.79000000","2.52984000"],["112549.80000000","0.04476000"],["112549.92000000","0.00048000"],["112549.94000000","0.00010000"],["112549.95000000","0.00015000"],["112549.99000000","0.00010000"],["112550.37000000","0.00031000"],["112550.46000000","0.00010000"],["112550.89000000","0.00005000"],["112550.90000000","0.06010000"],["112551.56000000","0.00260000"],["112551.59000000","1.70701000"],["112551.60000000","0.00000000"],["112551.64000000","0.00000000"],["112551.69000000","0.04000000"],["112552.82000000","0.03005000"],["112553.03000000","0.00000000"],["112554.29000000","0.00360000"],["112554.79000000","0.46938000"],["112554.99000000","0.00000000"],["112555.15000000","0.00000000"],["112556.00000000","0.00160000"],["112556.92000000","0.00000000"],["112557.48000000","0.00000000"],["112557.49000000","0.00000000"],["112559.71000000","0.00444000"],["112559.99000000","0.00000000"],["112561.42000000","0.00000000"],["112561.99000000","0.00000000"],["112562.72000000","0.00161000"],["112562.78000000","0.01777000"],["112563.02000000","0.00000000"],["112564.26000000","0.00000000"],["112565.83000000","0.00000000"],["112566.54000000","0.00000000"],["112566.90000000","0.17706000"],["112568.18000000","0.00000000"],["112570.44000000","0.00000000"],["112570.86000000","0.04136000"],["112571.24000000","0.04480000"],["112573.82000000","0.31974000"],["112574.11000000","0.00000000"],["112574.43000000","0.00000000"],["112577.39000000","0.00000000"],["112578.45000000","0.00000000"],["112586.33000000","0.00000000"],["112587.82000000","0.34458000"],["112588.65000000","0.00000000"],["112600.00000000","0.18787000"],["112601.23000000","0.00000000"],["112601.66000000","0.00306000"],["112603.06000000","0.01391000"],["112603.55000000","0.00005000"],["112608.05000000","0.00000000"],["112610.65000000","0.00000000"],["112619.35000000","0.03460000"],["112619.96000000","0.00000000"],["112621.99000000","0.00221000"],["112622.25000000","0.00000000"],["112627.50000000","0.00048000"],["112628.61000000","0.00000000"],["112628.62000000","0.00000000"],["112628.90000000","0.00015000"],["112628.99000000","0.00000000"],["112629.06000000","0.00000000"],["112629.31000000","0.00000000"],["112629.54000000","0.00000000"],["112629.60000000","0.00000000"],["112629.71000000","0.26677000"],["112629.89000000","0.00000000"],["112630.51000000","0.35608000"],["112630.58000000","0.44510000"],["112631.02000000","0.00221000"],["112631.03000000","0.00000000"],["112636.20000000","0.00000000"],["112636.21000000","0.00000000"],["112669.43000000","0.06000000"],["112723.19000000","0.00000000"],["112734.09000000","0.00088000"],["112734.10000000","0.00000000"],["112740.10000000","0.00019000"],["112744.70000000","0.00088000"],["112767.58000000","0.00080000"],["112774.11000000","0.00000000"],["112779.67000000","4.69367000"],["113514.00000000","0.00000000"],["114238.04000000","0.00112000"]]}
[2025-10-26T09:48:17.294Z] {"e":"depthUpdate","E":1761472096014,"s":"BTCUSDT","U":79058056450,"u":79058058074,"b":[["112549.78000000","4.99958000"],["112549.77000000","0.00000000"],["112548.94000000","0.00000000"],["112548.66000000","0.00123000"],["112548.42000000","0.31200000"],["112548.41000000","0.29336000"],["112548.33000000","0.00000000"],["112547.05000000","0.02042000"],["112546.98000000","0.00000000"],["112546.97000000","0.00201000"],["112546.87000000","0.00000000"],["112546.86000000","0.00000000"],["112546.85000000","0.20494000"],["112546.40000000","0.46943000"],["112545.29000000","0.00444000"],["112545.28000000","0.00365000"],["112545.23000000","0.00000000"],["112545.22000000","0.00000000"],["112544.85000000","0.00005000"],["112544.56000000","0.00000000"],["112544.55000000","0.00000000"],["112544.54000000","0.00000000"],["112543.04000000","0.29981000"],["112543.03000000","0.00548000"],["112543.01000000","0.06753000"],["112542.88000000","0.00000000"],["112542.64000000","0.00000000"],["112542.54000000","0.00250000"],["112542.33000000","0.46938000"],["112542.13000000","0.33596000"],["112542.12000000","0.00000000"],["112542.11000000","0.00000000"],["112542.08000000","0.00000000"],["112542.07000000","0.03268000"],["112541.49000000","0.05196000"],["112541.48000000","0.00000000"],["112541.38000000","0.00000000"],["112541.37000000","0.00000000"],["112541.33000000","0.22255000"],["112541.13000000","0.00000000"],["112541.12000000","0.00000000"],["112541.11000000","0.09317000"],["112540.41000000","0.00000000"],["112540.29000000","0.00000000"],["112539.90000000","0.00005000"],["112539.75000000","0.03684000"],["112538.92000000","0.46938000"],["112538.56000000","0.15146000"],["112538.53000000","0.00766000"],["112538.52000000","0.00305000"],["112538.47000000","0.00000000"],["112538.03000000","0.00255000"],["112537.54000000","1.10752000"],["112537.53000000","1.70701000"],["112537.35000000","0.01817000"],["112537.34000000","0.26660000"],["112537.20000000","0.00005000"],["112536.99000000","0.15146000"],["112536.64000000","0.00000000"],["112536.13000000","0.00000000"],["112536.04000000","0.00000000"],["112536.03000000","0.00000000"],["112536.02000000","0.00000000"],["112536.01000000","0.00000000"],["112535.79000000","0.00000000"],["112535.23000000","0.46938000"],["112535.15000000","0.09400000"],["112534.91000000","0.26683000"],["112534.71000000","0.26728000"],["112533.80000000","0.00000000"],["112533.62000000","0.01256000"],["112533.53000000","0.00000000"],["112533.52000000","0.00250000"],["112532.90000000","0.00118000"],["112532.66000000","0.00043000"],["112532.51000000","0.35534000"],["112532.24000000","0.22719000"],["112531.82000000","0.00000000"],["112531.80000000","0.06753000"],["112531.78000000","1.26461000"],["112531.77000000","1.70701000"],["112531.55000000","0.00000000"],["112531.41000000","0.00000000"],["112530.94000000","0.00000000"],["112530.40000000","0.15133000"],["112530.20000000","0.04000000"],["112529.94000000","0.00000000"],["112529.35000000","0.00000000"],["112528.56000000","0.00000000"],["112528.35000000","0.00000000"],["112527.81000000","0.00000000"],["112527.58000000","0.05700000"],["112527.41000000","0.00000000"],["112527.30000000","0.00000000"],["112527.27000000","0.00000000"],["112526.89000000","0.00000000"],["112526.85000000","0.00000000"],["112526.58000000","0.00006000"],["112526.45000000","0.05400000"],["112526.34000000","0.00000000"],["112526.29000000","0.04200000"],["112526.14000000","0.89083000"],["112526.13000000","1.70701000"],["112526.00000000","0.00000000"],["112525.95000000","0.00000000"],["112525.62000000","0.00000000"],["112525.60000000","0.00000000"],["112525.04000000","0.15120000"],["112524.97000000","0.00000000"],["112524.75000000","0.00000000"],["112524.50000000","0.00000000"],["112524.14000000","0.44510000"],["112523.85000000","0.00009000"],["112523.75000000","0.00009000"],["112523.02000000","0.00043000"],["112522.50000000","0.00005000"],["112521.41000000","0.00000000"],["112521.40000000","0.00000000"],["112521.21000000","0.00000000"],["112520.79000000","0.03000000"],["112520.51000000","0.00000000"],["112520.00000000","0.00125000"],["112519.99000000","0.00000000"],["112519.88000000","0.00000000"],["112519.87000000","0.03600000"],["112519.01000000","0.00009000"],["112518.58000000","0.00000000"],["112518.44000000","0.00000000"],["112518.00000000","0.00120000"],["112517.87000000","0.15105000"],["112517.77000000","0.03000000"],["112517.47000000","0.00000000"],["112517.04000000","0.03909000"],["112516.02000000","0.04449000"],["112516.01000000","0.26660000"],["112516.00000000","0.00120000"],["112515.42000000","0.00000000"],["112515.11000000","0.00005000"],["112514.55000000","0.00000000"],["112514.45000000","0.00000000"],["112514.41000000","0.00000000"],["112514.22000000","0.00000000"],["112514.02000000","0.06000000"],["112514.00000000","0.00120000"],["112513.70000000","0.31800000"],["112512.57000000","0.31991000"],["112512.29000000","0.01800000"],["112511.85000000","0.00000000"],["112511.75000000","0.00000000"],["112511.31000000","0.00059000"],["112510.64000000","0.44452000"],["112510.41000000","0.00000000"],["112510.24000000","0.04500000"],["112509.71000000","0.00000000"],["112509.60000000","0.26677000"],["112509.34000000","0.00009000"],["112509.29000000","0.00000000"],["112509.28000000","0.00000000"],["112508.86000000","1.03331000"],["112507.74000000","0.00000000"],["112507.28000000","0.00000000"],["112507.15000000","0.00000000"],["112507.01000000","0.00000000"],["112506.60000000","0.00000000"],["112505.04000000","0.00000000"],["112504.17000000","0.00000000"],["112502.51000000","0.00440000"],["112502.27000000","0.00000000"],["112501.96000000","0.00000000"],["112501.54000000","0.00000000"],["112500.04000000","0.00000000"],["112499.14000000","0.00000000"],["112498.48000000","0.31995000"],["112497.89000000","0.00000000"],["112497.47000000","0.00000000"],["112497.34000000","0.00000000"],["112496.92000000","0.00000000"],["112495.09000000","0.00000000"],["112493.41000000","0.02984000"],["112492.75000000","0.00000000"],["112491.13000000","0.00000000"],["112490.79000000","0.00000000"],["112489.69000000","0.26728000"],["112488.70000000","0.24817000"],["112488.62000000","0.00000000"],["112487.80000000","0.02224000"],["112487.22000000","0.00005000"],["112484.27000000","0.00000000"],["112483.84000000","0.00631000"],["112482.52000000","0.00619000"],["112480.28000000","0.00000000"],["112480.01000000","0.02198000"],["112479.58000000","0.00657000"],["112478.25000000","0.00000000"],["112478.02000000","0.00000000"],["112477.75000000","0.00000000"],["112477.04000000","0.00000000"],["112477.00000000","0.22339000"],["112474.73000000","0.00000000"],["112472.28000000","0.00089000"],["112471.18000000","0.05700000"],["112470.34000000","0.26677000"],["112470.27000000","0.00000000"],["112470.21000000","0.00000000"],["112470.00000000","0.00140000"],["112469.98000000","0.00000000"],["112469.89000000","0.04200000"],["112469.73000000","0.00000000"],["112469.71000000","0.00000000"],["112469.69000000","0.00000000"],["112468.29000000","0.00000000"],["112467.87000000","0.00000000"],["112467.77000000","0.00000000"],["112467.18000000","0.00000000"],["112467.00000000","0.00000000"],["112466.60000000","0.44510000"],["112464.48000000","0.00000000"],["112464.39000000","0.03000000"],["112463.83000000","0.05400000"],["112463.40000000","0.00000000"],["112463.00000000","0.00000000"],["112462.99000000","0.00000000"],["112462.22000000","0.00000000"],["112461.70000000","0.00000000"],["112460.74000000","0.00000000"],["112460.70000000","0.00000000"],["112460.29000000","0.00000000"],["112457.61000000","0.00000000"],["112456.88000000","0.00000000"],["112455.99000000","0.36075000"],["112455.27000000","0.00000000"],["112454.93000000","0.36075000"],["112454.08000000","0.02487000"],["112453.78000000","0.01391000"],["112453.57000000","0.00000000"],["112453.56000000","0.00000000"],["112452.98000000","0.00000000"],["112452.71000000","0.00000000"],["112450.03000000","0.00000000"],["112448.64000000","0.00000000"],["112447.32000000","0.00000000"],["112446.00000000","0.02600000"],["112442.95000000","0.00000000"],["112442.94000000","0.02146000"],["112442.75000000","0.00000000"],["112441.15000000","0.30404000"],["112441.14000000","0.00000000"],["112440.30000000","0.00112000"],["112439.10000000","0.00000000"],["112438.58000000","0.02359000"],["112437.22000000","0.00006000"],["112436.83000000","0.09666000"],["112434.68000000","0.09675000"],["112423.85000000","1.11759000"],["112423.07000000","0.00000000"],["112418.50000000","0.00000000"],["112414.01000000","0.10794000"],["112407.99000000","0.00000000"],["112406.28000000","0.00000000"],["112406.27000000","0.00000000"],["112405.29000000","0.00000000"],["112405.03000000","0.00000000"],["112402.14000000","0.00000000"],["112398.98000000","0.00000000"],["112398.80000000","0.00000000"],["112397.85000000","0.00000000"],["112396.62000000","0.00000000"],["112395.42000000","0.00000000"],["112383.51000000","0.00000000"],["112381.43000000","0.00000000"],["112379.12000000","0.03067000"],["112378.56000000","0.00000000"],["112370.45000000","0.08683000"],["112361.70000000","0.00000000"],["112356.24000000","0.00000000"],["112356.23000000","0.00000000"],["112333.95000000","0.02132000"],["112323.43000000","0.06295000"],["112300.50000000","0.00000000"],["112300.01000000","0.00567000"],["112241.98000000","0.00000000"],["112237.14000000","0.00000000"],["112228.65000000","0.02398000"],["112227.55000000","0.01688000"],["112227.26000000","0.01688000"],["112205.05000000","0.02398000"],["112204.19000000","0.02398000"],["112203.33000000","0.02398000"],["112203.11000000","0.00000000"],["112201.61000000","0.02398000"],["112185.27000000","0.01688000"],["112184.70000000","0.01688000"],["112133.99000000","0.00000000"],["112133.88000000","0.00000000"],["112131.90000000","0.02398000"],["112130.44000000","0.02414000"],["112107.90000000","0.00000000"],["112107.77000000","0.00000000"],["112106.20000000","0.00000000"],["112102.75000000","0.00000000"],["112091.54000000","0.00000000"],["112088.69000000","0.10816000"],["112087.65000000","0.00000000"],["112050.47000000","0.00000000"],["112034.31000000","0.00000000"],["112032.08000000","0.00000000"],["112000.01000000","0.00000000"],["111996.06000000","0.00000000"],["110861.53000000","0.00100000"],["110700.01000000","0.00008000"],["103502.98000000","0.00010000"],["101294.00000000","0.00010000"],["90039.83000000","0.00022000"],["40517.92000000","0.00090000"],["33000.00000000","3.78938000"]],"a":[["112549.79000000","0.00343000"],["112549.80000000","0.04491000"],["112549.92000000","0.00048000"],["112549.94000000","0.00000000"],["112549.95000000","0.00005000"],["112550.00000000","0.03887000"],["112550.35000000","0.00010000"],["112550.37000000","0.00036000"],["112550.46000000","0.00000000"],["112550.47000000","0.00000000"],["112550.53000000","0.00000000"],["112550.54000000","0.00000000"],["112550.55000000","0.00000000"],["112550.57000000","0.00000000"],["112550.58000000","0.00000000"],["112550.89000000","0.00000000"],["112550.90000000","0.00000000"],["112551.05000000","0.00010000"],["112551.25000000","0.00006000"],["112551.56000000","0.00005000"],["112551.58000000","0.00000000"],["112551.59000000","0.00000000"],["112551.64000000","0.00010000"],["112551.69000000","0.00000000"],["112551.71000000","0.00000000"],["112552.00000000","0.00160000"],["112552.25000000","0.00000000"],["112552.28000000","0.00000000"],["112552.29000000","0.00005000"],["112552.44000000","0.00000000"],["112552.62000000","0.00000000"],["112552.82000000","0.00000000"],["112553.21000000","0.00010000"],["112553.22000000","0.29315000"],["112553.59000000","0.00000000"],["112553.60000000","0.00000000"],["112553.72000000","0.00005000"],["112553.83000000","0.00000000"],["112553.86000000","0.00005000"],["112554.00000000","0.00160000"],["112554.01000000","0.00005000"],["112554.04000000","0.01839000"],["112554.29000000","0.00355000"],["112554.76000000","0.00000000"],["112554.78000000","0.00000000"],["112554.79000000","0.00000000"],["112554.80000000","0.00000000"],["112554.85000000","0.00000000"],["112554.90000000","0.00000000"],["112554.99000000","0.00005000"],["112555.18000000","0.00151000"],["112555.19000000","0.00000000"],["112555.75000000","0.00005000"],["112555.76000000","0.00000000"],["112555.91000000","0.00612000"],["112556.00000000","0.00165000"],["112556.07000000","0.00000000"],["112556.18000000","0.00000000"],["112556.54000000","0.00538000"],["112556.74000000","0.00005000"],["112556.90000000","0.00000000"],["112556.93000000","0.00000000"],["112557.11000000","0.00000000"],["112557.22000000","0.05132000"],["112557.49000000","0.00000000"],["112557.89000000","0.00000000"],["112557.90000000","0.00000000"],["112558.00000000","0.00165000"],["112558.01000000","0.00156000"],["112558.22000000","0.00000000"],["112558.51000000","0.00000000"],["112558.70000000","0.00000000"],["112558.83000000","0.00000000"],["112559.71000000","0.00000000"],["112559.72000000","0.00000000"],["112560.09000000","0.00000000"],["112560.58000000","0.00000000"],["112560.61000000","0.00000000"],["112560.80000000","0.00000000"],["112561.01000000","0.00000000"],["112561.20000000","0.00695000"],["112561.38000000","0.00000000"],["112561.50000000","0.01741000"],["112561.70000000","0.00000000"],["112561.90000000","0.28000000"],["112562.00000000","0.00229000"],["112562.11000000","0.00000000"],["112562.24000000","0.00000000"],["112562.44000000","0.00000000"],["112562.78000000","0.00000000"],["112562.85000000","0.00069000"],["112562.86000000","0.00069000"],["112562.91000000","0.02000000"],["112562.97000000","0.00000000"],["112563.32000000","0.00333000"],["112563.64000000","0.00000000"],["112563.93000000","0.00000000"],["112563.98000000","0.00000000"],["112564.01000000","0.00072000"],["112564.26000000","0.00000000"],["112564.27000000","0.00000000"],["112564.30000000","0.00000000"],["112564.38000000","0.00070000"],["112564.40000000","0.00000000"],["112564.62000000","0.00000000"],["112564.66000000","0.00000000"],["112564.68000000","0.00005000"],["112564.93000000","0.00000000"],["112564.95000000","0.02666000"],["112565.09000000","0.00000000"],["112565.48000000","0.00000000"],["112565.70000000","0.00000000"],["112565.74000000","0.00000000"],["112565.75000000","0.00000000"],["112565.76000000","0.00000000"],["112565.99000000","0.04568000"],["112566.16000000","0.00000000"],["112566.90000000","0.00000000"],["112566.91000000","0.00000000"],["112567.47000000","0.00000000"],["112567.98000000","0.00000000"],["112568.30000000","0.04000000"],["112568.75000000","0.00000000"],["112569.02000000","1.70701000"],["112569.03000000","0.00000000"],["112569.04000000","0.00000000"],["112569.10000000","0.00000000"],["112569.20000000","0.00000000"],["112569.22000000","0.00000000"],["112569.49000000","0.00000000"],["112569.50000000","0.00000000"],["112569.94000000","0.00000000"],["112570.34000000","0.00000000"],["112570.59000000","0.00000000"],["112570.60000000","0.00000000"],["112570.78000000","0.00000000"],["112570.79000000","0.00000000"],["112571.24000000","0.00000000"],["112571.26000000","0.00006000"],["112571.39000000","0.00000000"],["112571.40000000","0.00000000"],["112571.74000000","0.00000000"],["112571.95000000","0.00000000"],["112571.99000000","0.00000000"],["112572.30000000","0.00000000"],["112572.36000000","0.00000000"],["112572.66000000","0.03000000"],["112572.73000000","0.00000000"],["112572.75000000","0.00000000"],["112572.78000000","0.00000000"],["112572.93000000","0.00444000"],["112572.94000000","0.00000000"],["112573.17000000","0.00000000"],["112573.38000000","0.03000000"],["112573.42000000","0.00017000"],["112573.51000000","0.00000000"],["112573.55000000","0.00000000"],["112573.61000000","0.00000000"],["112573.65000000","0.00000000"],["112573.81000000","0.00000000"],["112573.82000000","0.00000000"],["112573.99000000","0.00000000"],["112574.11000000","0.00250000"],["112574.80000000","0.00000000"],["112574.95000000","0.00000000"],["112575.00000000","0.00481000"],["112575.52000000","0.00000000"],["112575.64000000","0.00005000"],["112575.92000000","0.03000000"],["112575.98000000","0.00000000"],["112575.99000000","0.00000000"],["112576.42000000","0.03000000"],["112576.44000000","0.00000000"],["112577.36000000","0.00000000"],["112577.51000000","0.00000000"],["112577.91000000","0.02398000"],["112577.93000000","0.10640000"],["112578.23000000","0.00000000"],["112578.48000000","0.00000000"],["112578.62000000","0.00250000"],["112579.55000000","0.29976000"],["112579.56000000","0.00000000"],["112579.57000000","0.00000000"],["112579.58000000","0.00000000"],["112580.12000000","0.00000000"],["112580.40000000","0.00000000"],["112580.89000000","0.17706000"],["112581.11000000","0.00000000"],["112581.71000000","0.00000000"],["112581.99000000","0.02398000"],["112582.04000000","0.03000000"],["112582.09000000","0.00000000"],["112582.62000000","0.22719000"],["112582.68000000","0.00000000"],["112583.13000000","0.00250000"],["112583.46000000","0.00000000"],["112584.01000000","0.26683000"],["112585.49000000","0.03598000"],["112585.86000000","0.04448000"],["112585.87000000","0.00000000"],["112585.98000000","0.15146000"],["112586.06000000","0.00000000"],["112586.16000000","0.04450000"],["112586.54000000","0.03098000"],["112587.19000000","0.31970000"],["112587.28000000","0.00000000"],["112587.64000000","0.00250000"],["112587.82000000","0.05886000"],["112588.11000000","0.26728000"],["112588.38000000","0.02498000"],["112588.81000000","0.03000000"],["112588.88000000","0.00018000"],["112588.89000000","0.15146000"],["112589.57000000","0.04480000"],["112591.32000000","0.00000000"],["112591.53000000","0.26660000"],["112592.15000000","0.00000000"],["112592.47000000","0.00000000"],["112592.48000000","0.00000000"],["112592.66000000","0.00000000"],["112592.71000000","0.00000000"],["112593.15000000","0.37369000"],["112593.27000000","0.15094000"],["112593.54000000","0.46938000"],["112593.55000000","0.26677000"],["112594.05000000","0.35608000"],["112594.34000000","0.00000000"],["112594.46000000","0.00000000"],["112594.65000000","0.44510000"],["112595.47000000","0.00800000"],["112595.63000000","0.00000000"],["112595.81000000","0.44452000"],["112596.19000000","0.96547000"],["112596.41000000","0.00000000"],["112596.66000000","0.00000000"],["112597.03000000","0.00000000"],["112597.78000000","0.02398000"],["112597.79000000","0.00000000"],["112599.46000000","0.00000000"],["112599.65000000","0.00000000"],["112600.22000000","0.23717000"],["112600.61000000","0.00000000"],["112601.12000000","0.00000000"],["112603.01000000","0.00000000"],["112603.06000000","0.00000000"],["112604.05000000","0.00000000"],["112604.17000000","0.00000000"],["112604.51000000","0.00000000"],["112606.73000000","0.34122000"],["112607.80000000","0.00000000"],["112609.03000000","0.00000000"],["112609.63000000","0.00000000"],["112609.74000000","0.02935000"],["112610.00000000","0.00160000"],["112610.21000000","0.36025000"],["112611.29000000","0.36025000"],["112612.77000000","0.00000000"],["112614.24000000","0.00000000"],["112616.10000000","0.02146000"],["112617.75000000","0.00000000"],["112619.01000000","0.00000000"],["112619.35000000","0.00000000"],["112619.97000000","0.00000000"],["112620.00000000","0.19702000"],["112620.66000000","0.00000000"],["112621.97000000","0.00662000"],["112621.99000000","0.00221000"],["112622.74000000","0.01573000"],["112623.24000000","0.00630000"],["112624.91000000","0.00000000"],["112625.80000000","0.00000000"],["112625.81000000","0.00000000"],["112626.13000000","0.00000000"],["112626.18000000","0.46938000"],["112626.23000000","0.00000000"],["112627.50000000","0.00048000"],["112627.87000000","0.04091000"],["112629.03000000","0.26683000"],["112629.16000000","0.04974000"],["112630.41000000","0.49425000"],["112630.58000000","0.00000000"],["112631.01000000","0.00000000"],["112631.02000000","0.00000000"],["112631.23000000","0.00221000"],["112631.75000000","0.00005000"],["112633.13000000","0.26728000"],["112633.26000000","0.00000000"],["112636.55000000","0.26660000"],["112636.90000000","0.46938000"],["112636.91000000","0.00000000"],["112637.54000000","0.04974000"],["112637.60000000","0.00533000"],["112639.05000000","0.04974000"],["112639.06000000","0.03000000"],["112642.45000000","0.00000000"],["112642.97000000","0.00010000"],["112644.53000000","0.00000000"],["112644.58000000","0.00000000"],["112644.59000000","0.00000000"],["112644.64000000","0.00000000"],["112644.79000000","0.00000000"],["112645.52000000","0.03963000"],["112645.64000000","0.00000000"],["112645.69000000","0.00000000"],["112645.71000000","0.02419000"],["112645.74000000","0.00000000"],["112646.05000000","0.00111000"],["112647.69000000","0.00000000"],["112647.89000000","0.00399000"],["112648.69000000","0.03400000"],["112649.10000000","0.03000000"],["112650.40000000","0.00000000"],["112650.47000000","0.00000000"],["112650.74000000","0.03000000"],["112650.93000000","0.44510000"],["112652.02000000","0.03000000"],["112652.09000000","0.44452000"],["112654.37000000","0.00000000"],["112657.52000000","0.03000000"],["112657.58000000","0.00000000"],["112657.96000000","0.00000000"],["112658.12000000","0.03460000"],["112658.36000000","0.00000000"],["112662.11000000","0.00000000"],["112663.84000000","0.00007000"],["112664.13000000","0.00000000"],["112664.31000000","0.00000000"],["112664.82000000","0.00000000"],["112669.89000000","0.00000000"],["112671.93000000","0.00888000"],["112676.07000000","1.70701000"],["112677.04000000","0.00444000"],["112681.24000000","0.00444000"],["112682.13000000","0.09675000"],["112682.39000000","0.07740000"],["112687.33000000","1.70701000"],["112694.14000000","0.00000000"],["112694.47000000","0.16212000"],["112697.62000000","0.00000000"],["112697.63000000","0.02398000"],["112698.61000000","0.00000000"],["112700.28000000","0.00000000"],["112700.61000000","0.00000000"],["112702.41000000","0.00000000"],["112705.25000000","0.00000000"],["112706.76000000","0.00000000"],["112709.17000000","0.00000000"],["112710.37000000","0.00000000"],["112711.95000000","0.02398000"],["112714.09000000","0.00000000"],["112714.27000000","0.00000000"],["112714.40000000","0.00000000"],["112718.84000000","0.00000000"],["112722.00000000","0.00000000"],["112722.22000000","0.00000000"],["112726.74000000","0.01849000"],["112729.57000000","0.02398000"],["112734.09000000","0.00000000"],["112734.84000000","0.00088000"],["112737.72000000","0.01275000"],["112737.84000000","0.00000000"],["112738.91000000","0.00000000"],["112740.10000000","0.00019000"],["112740.14000000","0.00000000"],["112741.24000000","0.00000000"],["112741.42000000","0.00000000"],["112742.24000000","0.00000000"],["112742.81000000","0.00000000"],["112743.35000000","0.00000000"],["112744.68000000","0.00088000"],["112744.69000000","0.00000000"],["112744.70000000","0.00000000"],["112744.71000000","0.00000000"],["112745.67000000","0.00000000"],["112746.93000000","0.00000000"],["112747.58000000","0.00000000"],["112753.83000000","0.00000000"],["112754.55000000","0.00000000"],["112758.85000000","0.00000000"],["112759.67000000","0.00000000"],["112759.81000000","0.00000000"],["112760.95000000","0.00000000"],["112761.68000000","0.00000000"],["112765.32000000","0.00000000"],["112768.29000000","0.00000000"],["112769.23000000","0.00330000"],["112771.13000000","0.03598000"],["112772.30000000","0.03598000"],["112774.43000000","0.03598000"],["112776.59000000","0.03598000"],["112779.84000000","0.03598000"],["112780.99000000","0.03598000"],["112781.08000000","0.03598000"],["112781.86000000","0.03610000"],["112782.14000000","0.03598000"],["112782.21000000","0.03598000"],["112782.75000000","0.03598000"],["112783.53000000","0.03598000"],["112783.57000000","0.03598000"],["112784.22000000","0.00000000"],["112784.31000000","0.01776000"],["112785.41000000","0.03598000"],["112787.88000000","0.03598000"],["112789.96000000","0.00000000"],["112790.26000000","0.00000000"],["112791.67000000","0.00000000"],["112793.02000000","0.00000000"],["112794.33000000","0.00000000"],["112796.38000000","0.00000000"],["112796.48000000","0.01776000"],["112799.02000000","0.00000000"],["112799.45000000","0.01776000"],["112799.58000000","0.00263000"],["112800.10000000","0.00000000"],["112803.24000000","0.00000000"],["112804.42000000","0.00000000"],["112807.00000000","0.16735000"],["112808.28000000","0.00000000"],["112812.09000000","0.00000000"],["112812.72000000","0.00000000"],["112812.93000000","0.00000000"],["112813.11000000","0.02398000"],["112813.53000000","0.00000000"],["112817.20000000","0.00000000"],["112817.72000000","0.88626000"],["112818.56000000","0.01688000"],["112818.67000000","0.00000000"],["112818.85000000","0.00000000"],["112819.79000000","0.03376000"],["112820.60000000","0.00000000"],["112820.75000000","0.00000000"],["112820.78000000","0.00000000"],["112821.22000000","0.00000000"],["112821.28000000","0.00000000"],["112821.29000000","0.00000000"],["112821.33000000","0.00000000"],["112821.84000000","0.03376000"],["112822.09000000","0.01688000"],["112824.72000000","0.24292000"],["112824.92000000","0.00000000"],["112825.03000000","0.02398000"],["112825.68000000","0.00000000"],["112828.11000000","0.02405000"],["112829.23000000","0.09992000"],["112832.10000000","0.02398000"],["112836.77000000","0.00000000"],["112841.37000000","0.00009000"],["112843.00000000","0.00000000"],["112843.45000000","0.02398000"],["112843.73000000","0.02498000"],["112844.04000000","0.02498000"],["112844.39000000","0.02498000"],["112845.37000000","0.02498000"],["112845.61000000","0.00000000"],["112846.08000000","0.02498000"],["112847.07000000","0.02498000"],["112848.12000000","0.02498000"],["112848.27000000","0.04996000"],["112848.61000000","0.02605000"],["112849.24000000","0.02498000"],["112849.97000000","0.02503000"],["112851.15000000","0.02398000"],["112854.42000000","0.01606000"],["112855.59000000","0.00000000"],["112856.97000000","0.00000000"],["112858.29000000","0.00000000"],["112859.08000000","0.00000000"],["112860.43000000","0.00000000"],["112862.35000000","0.01688000"],["112863.92000000","0.00000000"],["112864.45000000","0.00000000"],["112865.53000000","0.00000000"],["112866.63000000","0.00000000"],["112867.33000000","0.00000000"],["112868.08000000","0.00000000"],["112868.26000000","0.01688000"],["112868.38000000","0.00000000"],["112868.59000000","0.00000000"],["112869.04000000","0.00000000"],["112872.27000000","0.01688000"],["112875.27000000","0.00317000"],["112875.66000000","0.01688000"],["112877.20000000","0.00000000"],["112877.40000000","0.00000000"],["112878.11000000","0.00000000"],["112878.23000000","0.02398000"],["112879.32000000","0.00000000"],["112879.61000000","0.02398000"],["112880.92000000","0.02398000"],["112881.48000000","0.02398000"],["112881.99000000","0.02398000"],["112884.44000000","0.00000000"],["112889.45000000","0.00000000"],["112892.32000000","0.02398000"],["112894.08000000","0.02398000"],["112895.94000000","0.02398000"],["112897.04000000","0.02398000"],["112897.62000000","0.02398000"],["112897.71000000","0.02398000"],["112897.75000000","0.02398000"],["112898.43000000","0.02398000"],["112898.54000000","0.02398000"],["112899.28000000","0.02398000"],["112899.72000000","0.02398000"],["112901.23000000","0.02398000"],["112907.70000000","0.00000000"],["112909.71000000","0.00000000"],["112910.62000000","0.02398000"],["112911.07000000","0.02398000"],["112912.12000000","0.00000000"],["112913.04000000","0.00028000"],["112915.45000000","0.00012000"],["112916.58000000","0.00000000"],["112927.40000000","0.00000000"],["112928.47000000","0.00000000"],["112929.99000000","0.00000000"],["112930.17000000","0.00000000"],["112930.38000000","0.00000000"],["112930.81000000","0.00000000"],["112931.20000000","0.00000000"],["112931.43000000","0.00000000"],["112931.63000000","0.00000000"],["112932.01000000","0.00000000"],["112932.24000000","0.00000000"],["112932.42000000","0.02398000"],["112932.44000000","0.00000000"],["112933.83000000","0.02398000"],["112937.31000000","0.02398000"],["112939.47000000","0.02398000"],["112942.71000000","0.03398000"],["112943.96000000","0.02398000"],["112945.36000000","0.04796000"],["112948.39000000","0.03398000"],["112948.80000000","0.03398000"],["112949.80000000","0.03398000"],["112950.33000000","0.03398000"],["112950.83000000","0.03398000"],["112951.31000000","0.03398000"],["112951.82000000","0.03398000"],["112951.84000000","0.03398000"],["112952.57000000","0.03398000"],["112953.80000000","0.03398000"],["112954.46000000","0.03398000"],["112955.50000000","0.03398000"],["112956.43000000","0.03398000"],["112957.42000000","0.03398000"],["112957.94000000","0.03398000"],["112970.36000000","0.00000000"],["112971.07000000","0.00000000"],["112972.34000000","0.00000000"],["112973.21000000","0.00000000"],["112973.97000000","0.00000000"],["112975.00000000","2.04713000"],["112975.54000000","0.00000000"],["112976.63000000","0.00000000"],["112977.86000000","0.00000000"],["112978.64000000","0.00000000"],["112979.62000000","0.00000000"],["113066.43000000","0.00000000"],["113067.08000000","0.00000000"],["113067.67000000","0.00000000"],["113076.93000000","0.00000000"],["113078.52000000","0.00000000"],["113078.91000000","0.00000000"],["113079.47000000","0.00000000"],["113080.04000000","0.00000000"],["113081.16000000","0.00000000"],["113081.73000000","0.00000000"],["113096.21000000","0.03098000"],["113098.61000000","0.03098000"],["113099.82000000","0.03098000"],["113100.53000000","0.03098000"],["113101.37000000","0.03098000"],["113102.83000000","0.03098000"],["113103.91000000","0.03098000"],["113104.55000000","0.03098000"],["113105.26000000","0.03098000"],["113105.91000000","0.03098000"],["113549.16000000","0.00000000"],["113549.35000000","0.00013000"],["113549.92000000","0.04000000"],["113554.00000000","0.10000000"],["114238.04000000","0.00112000"],["115000.00000000","181.27674000"]]}
[2025-10-26T09:48:18.119Z] {"e":"depthUpdate","E":1761472097014,"s":"BTCUSDT","U":79058058075,"u":79058059628,"b":[["112556.22000000","3.53256000"],["112556.14000000","0.00315000"],["112555.99000000","0.00000000"],["112555.90000000","0.00000000"],["112555.31000000","0.00000000"],["112555.30000000","0.00030000"],["112555.10000000","0.00118000"],["112554.99000000","0.00000000"],["112554.68000000","0.00000000"],["112554.64000000","0.00000000"],["112554.28000000","0.00000000"],["112554.03000000","0.00000000"],["112554.02000000","0.00000000"],["112554.00000000","0.00005000"],["112553.99000000","0.00000000"],["112553.97000000","0.00000000"],["112553.85000000","0.00000000"],["112553.72000000","0.00005000"],["112553.71000000","0.00000000"],["112553.67000000","0.00000000"],["112553.41000000","0.00216000"],["112553.36000000","0.00000000"],["112553.29000000","0.00000000"],["112553.28000000","0.04568000"],["112553.26000000","0.00000000"],["112553.25000000","0.00000000"],["112553.24000000","0.00000000"],["112553.23000000","0.00000000"],["112553.22000000","0.00010000"],["112553.21000000","0.04015000"],["112553.20000000","0.00000000"],["112553.14000000","0.00000000"],["112553.06000000","0.00000000"],["112553.05000000","0.00000000"],["112552.59000000","0.00000000"],["112552.56000000","0.00000000"],["112552.55000000","0.00000000"],["112552.28000000","0.00000000"],["112551.99000000","0.00000000"],["112551.75000000","0.00005000"],["112551.72000000","0.00355000"],["112551.64000000","0.00000000"],["112551.58000000","0.00000000"],["112551.56000000","0.00000000"],["112551.04000000","0.00000000"],["112550.53000000","0.00000000"],["112550.49000000","0.00000000"],["112550.36000000","0.00000000"],["112550.34000000","0.00000000"],["112550.02000000","0.00000000"],["112550.01000000","0.00000000"],["112549.99000000","0.00000000"],["112549.98000000","0.00000000"],["112549.91000000","0.00000000"],["112549.86000000","0.00000000"],["112549.85000000","0.09337000"],["112549.84000000","0.17772000"],["112549.83000000","0.00000000"],["112549.80000000","0.00000000"],["112549.79000000","0.00010000"],["112549.78000000","0.12907000"],["112549.70000000","0.00000000"],["112549.47000000","0.00538000"],["112549.43000000","0.00000000"],["112549.42000000","0.00000000"],["112548.82000000","0.00000000"],["112548.66000000","0.00010000"],["112548.52000000","0.00010000"],["112548.51000000","0.02974000"],["112548.42000000","0.00000000"],["112548.41000000","0.00000000"],["112548.37000000","0.00000000"],["112547.05000000","0.00250000"],["112546.97000000","0.00196000"],["112546.85000000","0.00000000"],["112546.62000000","0.00005000"],["112546.60000000","0.00005000"],["112546.40000000","0.00000000"],["112546.28000000","0.00000000"],["112545.29000000","0.00000000"],["112545.28000000","0.00360000"],["112545.19000000","0.00000000"],["112545.00000000","0.00000000"],["112544.97000000","0.09418000"],["112544.96000000","0.31533000"],["112544.85000000","0.00000000"],["112544.50000000","0.00007000"],["112543.04000000","0.00000000"],["112543.03000000","0.00005000"],["112543.02000000","0.00326000"],["112543.01000000","0.00000000"],["112542.54000000","0.00260000"],["112542.50000000","0.06105000"],["112542.33000000","0.00000000"],["112542.17000000","0.00010000"],["112542.14000000","0.46938000"],["112542.13000000","0.33601000"],["112542.07000000","0.00000000"],["112541.86000000","0.00005000"],["112541.59000000","0.09971000"],["112541.49000000","0.00000000"],["112541.44000000","0.00000000"],["112541.15000000","0.00005000"],["112541.11000000","0.09322000"],["112540.90000000","0.01777000"],["112540.50000000","0.00444000"],["112540.49000000","0.00200000"],["112540.22000000","0.00000000"],["112540.10000000","0.00000000"],["112539.34000000","0.00088000"],["112539.16000000","0.00010000"],["112538.92000000","0.00000000"],["112538.63000000","0.46938000"],["112538.56000000","0.00000000"],["112538.53000000","0.00050000"],["112538.52000000","0.00300000"],["112538.03000000","0.00250000"],["112537.55000000","1.70701000"],["112537.54000000","0.41292000"],["112537.53000000","0.00000000"],["112537.35000000","0.00000000"],["112537.34000000","0.00000000"],["112537.20000000","0.00000000"],["112535.15000000","0.00000000"],["112534.91000000","0.00000000"],["112534.89000000","0.04366000"],["112534.71000000","0.00000000"],["112533.62000000","0.00000000"],["112532.90000000","0.00088000"],["112532.70000000","0.00000000"],["112532.66000000","0.00000000"],["112532.52000000","0.29979000"],["112531.86000000","0.00005000"],["112531.80000000","1.25260000"],["112531.79000000","1.70701000"],["112531.78000000","0.00000000"],["112531.77000000","0.00000000"],["112530.94000000","0.00005000"],["112529.19000000","0.00888000"],["112529.01000000","0.00000000"],["112528.66000000","0.15146000"],["112527.74000000","0.00000000"],["112527.63000000","0.00000000"],["112527.61000000","0.00000000"],["112527.39000000","0.04500000"],["112527.29000000","0.04442000"],["112526.47000000","0.03900000"],["112526.25000000","0.04500000"],["112525.34000000","0.03600000"],["112524.72000000","0.00000000"],["112524.50000000","0.00250000"],["112524.24000000","0.00000000"],["112524.13000000","0.03000000"],["112523.86000000","0.44452000"],["112523.02000000","0.00000000"],["112522.95000000","0.03600000"],["112522.45000000","0.00008000"],["112521.81000000","0.03000000"],["112521.57000000","0.26660000"],["112520.97000000","0.26683000"],["112520.71000000","0.03000000"],["112520.68000000","0.26728000"],["112520.56000000","0.03000000"],["112520.50000000","0.00000000"],["112520.46000000","0.96485000"],["112519.87000000","0.00000000"],["112519.42000000","0.00000000"],["112519.29000000","0.00000000"],["112517.77000000","0.00000000"],["112516.02000000","0.00000000"],["112516.01000000","0.00059000"],["112514.59000000","0.00177000"],["112514.58000000","0.21827000"],["112513.82000000","0.00088000"],["112513.70000000","0.63791000"],["112513.66000000","0.00000000"],["112513.51000000","0.34121000"],["112512.79000000","0.00000000"],["112512.57000000","0.00000000"],["112511.55000000","0.00000000"],["112511.54000000","0.00000000"],["112511.31000000","0.00000000"],["112511.17000000","0.95739000"],["112510.64000000","0.00000000"],["112510.24000000","0.00000000"],["112509.72000000","0.00000000"],["112509.58000000","0.00000000"],["112508.13000000","0.00000000"],["112508.12000000","0.00000000"],["112508.11000000","0.00000000"],["112508.01000000","0.02498000"],["112507.36000000","0.00000000"],["112506.92000000","0.00000000"],["112505.07000000","0.00000000"],["112504.25000000","0.00000000"],["112503.82000000","0.19530000"],["112503.76000000","0.00000000"],["112499.75000000","0.31995000"],["112499.28000000","0.00000000"],["112498.92000000","0.00000000"],["112498.63000000","0.00000000"],["112498.48000000","0.00000000"],["112498.23000000","0.05400000"],["112494.05000000","0.00000000"],["112493.41000000","0.00000000"],["112493.25000000","0.00000000"],["112488.69000000","0.00008000"],["112486.39000000","0.00010000"],["112486.13000000","0.26683000"],["112482.55000000","0.00000000"],["112480.89000000","0.02984000"],["112476.91000000","0.00000000"],["112476.54000000","0.26660000"],["112475.24000000","0.00000000"],["112475.00000000","0.00010000"],["112473.60000000","0.00000000"],["112471.82000000","0.00000000"],["112471.30000000","0.00000000"],["112470.99000000","0.04500000"],["112470.07000000","0.03900000"],["112469.85000000","0.04500000"],["112467.81000000","0.44452000"],["112466.55000000","0.03600000"],["112466.03000000","0.03900000"],["112465.41000000","0.03000000"],["112464.30000000","0.03000000"],["112464.16000000","0.03000000"],["112460.01000000","0.63173000"],["112454.92000000","0.00008000"],["112446.10000000","0.00000000"],["112442.58000000","0.00000000"],["112439.83000000","0.00000000"],["112438.58000000","0.00000000"],["112434.32000000","0.00000000"],["112434.10000000","0.00000000"],["112432.44000000","0.00000000"],["112428.62000000","0.00000000"],["112427.61000000","0.00000000"],["112424.63000000","0.83009000"],["112422.01000000","0.00221000"],["112421.15000000","0.00008000"],["112414.87000000","0.00000000"],["112410.58000000","0.00007000"],["112406.86000000","0.00000000"],["112406.13000000","0.00000000"],["112406.07000000","0.00000000"],["112405.90000000","0.00005000"],["112399.67000000","0.00000000"],["112399.20000000","0.00000000"],["112397.99000000","0.06000000"],["112396.86000000","0.06124000"],["112388.82000000","0.00000000"],["112387.40000000","0.00000000"],["112387.39000000","0.00008000"],["112387.24000000","0.00000000"],["112386.61000000","0.00000000"],["112383.51000000","0.15722000"],["112383.39000000","0.00000000"],["112380.00000000","0.06788000"],["112379.12000000","0.00000000"],["112375.52000000","0.00000000"],["112372.31000000","0.00000000"],["112321.30000000","0.00000000"],["112311.93000000","0.00025000"],["112310.07000000","0.00007000"],["112309.60000000","0.00088000"],["112309.59000000","0.00009000"],["112307.00000000","0.67685000"],["112303.31000000","0.00000000"],["112284.99000000","0.00005000"],["112251.18000000","0.00031000"],["112250.08000000","0.00007000"],["112239.20000000","0.00087000"],["112231.83000000","0.00005000"],["112228.56000000","0.02398000"],["112207.17000000","0.00000000"],["112204.15000000","0.00000000"],["112188.05000000","0.00000000"],["112127.41000000","0.00000000"],["112054.16000000","0.00250000"],["112042.96000000","0.00000000"],["112019.87000000","0.00000000"],["112000.01000000","0.00000000"],["111999.08000000","0.00000000"],["110867.87000000","0.00100000"],["110861.53000000","0.00000000"],["110700.01000000","0.00008000"],["103502.98000000","0.00000000"],["101300.00000000","1.33203000"],["101294.00000000","0.00000000"],["90044.98000000","0.00022000"],["90039.83000000","0.00000000"],["78786.52000000","0.00000000"],["40520.24000000","0.00015000"]],"a":[["112549.79000000","0.00000000"],["112549.80000000","0.00000000"],["112549.81000000","0.00000000"],["112549.84000000","0.00000000"],["112549.87000000","0.00000000"],["112549.92000000","0.00000000"],["112549.95000000","0.00000000"],["112549.99000000","0.00000000"],["112550.00000000","0.00000000"],["112550.35000000","0.00000000"],["112550.37000000","0.00000000"],["112550.38000000","0.00000000"],["112550.50000000","0.00000000"],["112550.91000000","0.00000000"],["112551.05000000","0.00000000"],["112551.25000000","0.00000000"],["112551.27000000","0.00000000"],["112551.56000000","0.00000000"],["112551.64000000","0.00000000"],["112551.65000000","0.00000000"],["112551.66000000","0.00000000"],["112552.00000000","0.00000000"],["112552.08000000","0.00000000"],["112552.29000000","0.00000000"],["112552.60000000","0.00000000"],["112552.67000000","0.00000000"],["112553.04000000","0.00000000"],["112553.21000000","0.00000000"],["112553.22000000","0.00000000"],["112553.23000000","0.00000000"],["112553.30000000","0.00000000"],["112553.37000000","0.00000000"],["112553.68000000","0.00000000"],["112553.72000000","0.00000000"],["112553.86000000","0.00000000"],["112553.98000000","0.00000000"],["112554.00000000","0.00000000"],["112554.01000000","0.00000000"],["112554.03000000","0.00000000"],["112554.04000000","0.00000000"],["112554.18000000","0.00000000"],["112554.22000000","0.00000000"],["112554.29000000","0.00000000"],["112554.58000000","0.00000000"],["112554.65000000","0.00000000"],["112554.69000000","0.00000000"],["112554.99000000","0.00000000"],["112555.00000000","0.00000000"],["112555.18000000","0.00000000"],["112555.55000000","0.00000000"],["112555.75000000","0.00000000"],["112555.83000000","0.00000000"],["112555.91000000","0.00000000"],["112556.00000000","0.00000000"],["112556.23000000","2.45046000"],["112556.24000000","0.00020000"],["112556.30000000","0.00010000"],["112556.54000000","0.00005000"],["112556.59000000","0.00005000"],["112557.20000000","0.00010000"],["112557.21000000","0.07302000"],["112557.22000000","0.05147000"],["112557.98000000","0.00010000"],["112557.99000000","0.00010000"],["112558.00000000","0.00170000"],["112558.01000000","0.00156000"],["112558.72000000","0.00000000"],["112558.73000000","0.00305000"],["112559.34000000","0.00893000"],["112559.35000000","0.00396000"],["112559.40000000","0.00000000"],["112559.99000000","0.00010000"],["112560.00000000","0.02076000"],["112560.58000000","0.00250000"],["112561.02000000","0.00005000"],["112561.03000000","0.29980000"],["112561.04000000","0.00716000"],["112561.20000000","0.00700000"],["112561.49000000","0.00000000"],["112561.50000000","0.01746000"],["112561.52000000","0.20484000"],["112561.88000000","0.00000000"],["112561.89000000","0.15522000"],["112561.90000000","0.28000000"],["112562.00000000","0.00229000"],["112562.72000000","0.00005000"],["112562.86000000","0.00000000"],["112562.90000000","0.00000000"],["112562.91000000","0.02005000"],["112562.98000000","0.00533000"],["112563.32000000","0.00005000"],["112564.00000000","0.00165000"],["112564.41000000","0.00000000"],["112564.42000000","0.00000000"],["112564.95000000","0.00000000"],["112565.09000000","0.00250000"],["112565.19000000","0.00000000"],["112565.79000000","0.00391000"],["112565.99000000","0.04568000"],["112566.00000000","0.00160000"],["112566.67000000","0.00151000"],["112567.44000000","0.02666000"],["112567.48000000","0.00711000"],["112568.58000000","0.06748000"],["112568.85000000","0.00000000"],["112569.00000000","0.12100000"],["112569.01000000","0.21075000"],["112569.16000000","0.00161000"],["112569.28000000","0.00000000"],["112570.10000000","0.00151000"],["112570.85000000","0.46938000"],["112570.86000000","0.12858000"],["112570.87000000","0.00000000"],["112572.93000000","0.00000000"],["112573.22000000","0.01777000"],["112573.99000000","0.00036000"],["112574.25000000","0.00200000"],["112574.67000000","0.00037000"],["112574.89000000","0.00000000"],["112575.06000000","0.26728000"],["112575.29000000","0.00444000"],["112577.26000000","0.00000000"],["112578.06000000","0.26660000"],["112579.55000000","0.00000000"],["112580.25000000","0.00033000"],["112580.50000000","0.06100000"],["112580.76000000","0.00000000"],["112580.83000000","0.00033000"],["112581.00000000","0.00000000"],["112581.35000000","0.31972000"],["112581.41000000","0.04480000"],["112582.33000000","0.03000000"],["112583.09000000","0.00000000"],["112583.13000000","0.00000000"],["112583.24000000","0.03000000"],["112583.58000000","0.00000000"],["112583.59000000","0.00000000"],["112584.36000000","0.00088000"],["112584.45000000","0.03000000"],["112585.49000000","0.03598000"],["112585.69000000","0.03300000"],["112585.86000000","0.00007000"],["112585.98000000","0.15753000"],["112586.16000000","0.00000000"],["112587.19000000","0.00000000"],["112587.27000000","0.31970000"],["112587.64000000","0.00000000"],["112587.78000000","0.03600000"],["112588.11000000","0.00000000"],["112588.88000000","0.05418000"],["112589.57000000","0.00000000"],["112589.65000000","0.96562000"],["112590.00000000","0.00168000"],["112591.53000000","0.00000000"],["112592.61000000","0.00088000"],["112593.00000000","0.06100000"],["112593.55000000","0.28453000"],["112594.00000000","0.00160000"],["112594.41000000","0.00000000"],["112596.19000000","0.00000000"],["112598.04000000","0.00062000"],["112598.70000000","0.00000000"],["112600.22000000","0.25405000"],["112600.43000000","0.00000000"],["112600.97000000","0.00000000"],["112603.01000000","0.01688000"],["112603.02000000","0.02488000"],["112603.43000000","0.00000000"],["112603.52000000","0.06579000"],["112603.71000000","0.00000000"],["112605.14000000","0.00000000"],["112605.70000000","0.02398000"],["112606.88000000","0.00088000"],["112608.52000000","0.00005000"],["112608.65000000","0.00000000"],["112610.25000000","0.00005000"],["112613.81000000","0.04326000"],["112617.79000000","0.04091000"],["112620.00000000","0.59702000"],["112621.14000000","0.00005000"],["112621.99000000","0.00000000"],["112622.07000000","0.00000000"],["112623.76000000","0.00008000"],["112624.08000000","0.26728000"],["112625.62000000","0.00221000"],["112626.53000000","0.26660000"],["112627.50000000","0.00000000"],["112627.87000000","0.00000000"],["112629.71000000","0.00000000"],["112630.00000000","0.09160000"],["112631.23000000","0.00000000"],["112633.12000000","0.00048000"],["112633.13000000","0.00000000"],["112634.98000000","0.03460000"],["112636.55000000","0.00000000"],["112636.75000000","0.26677000"],["112637.53000000","0.00221000"],["112638.32000000","0.02569000"],["112640.23000000","0.00000000"],["112642.42000000","0.00000000"],["112644.18000000","0.03600000"],["112644.62000000","0.00000000"],["112644.63000000","0.00000000"],["112648.69000000","0.00000000"],["112649.52000000","0.03000000"],["112649.54000000","0.05400000"],["112650.39000000","0.03300000"],["112650.69000000","0.00000000"],["112657.37000000","0.03000000"],["112657.53000000","0.00008000"],["112658.12000000","0.00000000"],["112660.11000000","0.05400000"],["112667.27000000","0.00000000"],["112672.73000000","0.00005000"],["112676.18000000","0.00000000"],["112677.31000000","0.00000000"],["112691.30000000","0.00008000"],["112709.94000000","0.00000000"],["112711.02000000","0.13009000"],["112725.06000000","0.00008000"],["112738.81000000","0.00006000"],["112806.53000000","0.00000000"],["112817.81000000","0.00250000"],["112821.24000000","0.01599000"],["112829.23000000","0.07494000"],["112833.12000000","0.01599000"],["112844.18000000","0.01599000"],["112852.11000000","0.02498000"],["112855.25000000","0.01599000"],["112935.58000000","0.00010000"],["112941.20000000","0.00000000"],["113008.11000000","0.02598000"],["113075.69000000","0.00000000"],["113105.61000000","0.03098000"],["114238.04000000","0.00012000"],["114244.58000000","0.00100000"],["115454.19000000","0.00480000"]]}
[2025-10-26T09:48:19.053Z] {"e":"depthUpdate","E":1761472098014,"s":"BTCUSDT","U":79058059629,"u":79058060309,"b":[["112556.22000000","4.88253000"],["112556.14000000","0.00335000"],["112555.10000000","0.00108000"],["112553.41000000","0.00206000"],["112553.29000000","0.00000000"],["112553.28000000","0.00000000"],["112553.22000000","0.00000000"],["112553.21000000","0.00000000"],["112552.87000000","0.00005000"],["112551.75000000","0.00000000"],["112551.73000000","0.17767000"],["112551.72000000","0.00365000"],["112551.56000000","0.00000000"],["112550.67000000","0.00010000"],["112550.66000000","0.00010000"],["112550.65000000","0.00010000"],["112550.64000000","0.00010000"],["112550.55000000","0.00005000"],["112549.87000000","0.00000000"],["112549.86000000","0.00000000"],["112549.85000000","0.00000000"],["112549.84000000","0.00000000"],["112549.78000000","0.26837000"],["112549.47000000","0.00543000"],["112549.41000000","0.00000000"],["112548.65000000","0.00010000"],["112548.64000000","0.00010000"],["112548.52000000","0.00005000"],["112548.51000000","0.02974000"],["112548.48000000","0.00000000"],["112547.87000000","0.00000000"],["112547.25000000","0.37243000"],["112547.24000000","0.00000000"],["112545.52000000","0.46943000"],["112545.28000000","0.00355000"],["112544.97000000","0.00000000"],["112544.96000000","0.88396000"],["112544.47000000","0.00000000"],["112543.23000000","0.00000000"],["112543.02000000","0.00000000"],["112542.50000000","0.06100000"],["112542.13000000","0.33596000"],["112541.86000000","0.00000000"],["112541.11000000","0.09322000"],["112540.90000000","0.00000000"],["112540.88000000","0.00000000"],["112540.80000000","0.00005000"],["112540.50000000","0.00449000"],["112538.72000000","0.00000000"],["112537.56000000","0.92247000"],["112537.54000000","0.00000000"],["112537.00000000","0.35530000"],["112534.25000000","0.00000000"],["112534.03000000","0.00000000"],["112532.90000000","0.26748000"],["112532.51000000","0.00000000"],["112530.84000000","0.00000000"],["112530.73000000","0.00000000"],["112530.36000000","0.00000000"],["112529.87000000","0.00000000"],["112529.01000000","0.00000000"],["112528.50000000","0.00000000"],["112527.66000000","0.00000000"],["112527.61000000","0.00000000"],["112526.74000000","0.00000000"],["112524.50000000","0.00250000"],["112521.57000000","0.00000000"],["112520.52000000","0.00000000"],["112518.29000000","0.00059000"],["112516.01000000","0.00000000"],["112513.70000000","0.31800000"],["112513.51000000","0.00000000"],["112513.18000000","0.00000000"],["112500.49000000","0.31995000"],["112499.81000000","0.02984000"],["112499.75000000","0.00000000"],["112495.91000000","0.65909000"],["112495.90000000","0.03000000"],["112487.28000000","0.26660000"],["112480.89000000","0.00000000"],["112476.54000000","0.00000000"],["112460.00000000","1.79861000"],["112450.54000000","0.19096000"],["112446.10000000","0.00005000"],["112438.40000000","0.00005000"],["112437.20000000","0.03000000"],["112435.96000000","0.03000000"],["112422.02000000","0.00221000"],["112422.01000000","0.00000000"],["112414.18000000","0.00000000"],["112405.32000000","0.37855000"],["112379.11000000","0.00000000"],["112351.90000000","0.00607000"],["112321.91000000","0.00000000"],["112309.61000000","0.00088000"],["112309.60000000","0.00000000"],["112306.60000000","0.00000000"],["112279.29000000","0.00014000"],["112000.01000000","0.00000000"],["110867.87000000","0.00100000"],["110700.01000000","0.00008000"],["101300.00000000","1.33203000"],["90044.98000000","0.00022000"],["90040.00000000","0.00025000"]],"a":[["112556.23000000","1.62814000"],["112556.24000000","0.00000000"],["112556.74000000","0.00000000"],["112557.20000000","0.00000000"],["112557.21000000","0.00000000"],["112557.22000000","0.00000000"],["112557.98000000","0.00000000"],["112557.99000000","0.00000000"],["112558.00000000","0.00175000"],["112558.01000000","0.00166000"],["112558.73000000","0.00310000"],["112559.01000000","0.00052000"],["112559.33000000","0.01031000"],["112560.00000000","0.02071000"],["112560.09000000","0.00006000"],["112560.58000000","0.00000000"],["112561.02000000","0.00000000"],["112561.03000000","0.00000000"],["112561.19000000","0.00010000"],["112561.20000000","0.05948000"],["112561.49000000","0.00000000"],["112561.50000000","0.00005000"],["112561.51000000","0.00000000"],["112561.52000000","0.00000000"],["112561.88000000","0.00010000"],["112561.89000000","0.18015000"],["112561.90000000","0.28005000"],["112562.33000000","0.00000000"],["112562.36000000","0.20489000"],["112562.44000000","0.00000000"],["112562.98000000","0.00538000"],["112563.77000000","0.01786000"],["112565.09000000","0.00255000"],["112565.79000000","0.00391000"],["112565.94000000","0.00000000"],["112565.99000000","0.04568000"],["112567.44000000","0.00000000"],["112567.46000000","0.00000000"],["112567.47000000","0.00000000"],["112567.48000000","0.00711000"],["112567.49000000","0.00000000"],["112567.50000000","0.00000000"],["112567.52000000","0.00000000"],["112567.56000000","0.02666000"],["112568.97000000","0.00069000"],["112569.00000000","0.06000000"],["112569.37000000","0.00333000"],["112570.83000000","0.46938000"],["112570.84000000","0.29977000"],["112570.85000000","0.00000000"],["112572.27000000","0.00000000"],["112573.22000000","0.00000000"],["112573.38000000","0.06000000"],["112574.56000000","0.03000000"],["112575.32000000","0.31974000"],["112575.81000000","0.03300000"],["112577.23000000","0.12700000"],["112577.32000000","0.00000000"],["112579.20000000","0.05400000"],["112581.04000000","0.00888000"],["112581.35000000","0.00000000"],["112581.40000000","0.00000000"],["112581.41000000","0.00000000"],["112581.66000000","0.31972000"],["112581.98000000","0.00000000"],["112583.13000000","0.00250000"],["112584.35000000","0.00000000"],["112584.45000000","0.00000000"],["112584.75000000","0.00000000"],["112585.69000000","0.00000000"],["112585.79000000","0.04480000"],["112585.98000000","0.15146000"],["112586.53000000","0.00000000"],["112587.64000000","0.00000000"],["112593.13000000","0.08000000"],["112593.15000000","0.31969000"],["112595.56000000","0.00000000"],["112600.44000000","0.00000000"],["112601.32000000","0.00607000"],["112603.52000000","0.00000000"],["112606.87000000","0.00000000"],["112607.46000000","0.06493000"],["112610.00000000","0.04160000"],["112617.79000000","0.00000000"],["112620.00000000","0.55702000"],["112630.00000000","0.00160000"],["112631.14000000","0.04091000"],["112634.98000000","0.00000000"],["112645.39000000","0.00100000"],["112645.40000000","0.00100000"],["112649.13000000","0.03460000"],["112649.54000000","0.00000000"],["112651.64000000","0.03400000"],["112659.36000000","0.02318000"],["112667.20000000","0.00005000"],["112711.02000000","0.00000000"],["112712.66000000","0.47523000"],["112713.01000000","0.00000000"],["112725.99000000","0.01849000"],["112734.85000000","0.00000000"],["112810.00000000","0.00008000"],["112856.90000000","0.00000000"],["112891.00000000","0.00000000"],["112920.00000000","0.00186000"],["112938.00000000","0.67530000"],["112986.04000000","0.00000000"],["113005.23000000","0.02598000"],["113005.96000000","0.02598000"],["113083.00000000","2.80151000"],["113101.00000000","1.95656000"],["114244.58000000","0.00100000"]]}
