[2025-10-26T09:48:20.054Z] {"e":"depthUpdate","E":1761472099014,"s":"BTCUSDT","U":79058060310,"u":79058061236,"b":[["112556.22000000","0.93225000"],["112556.21000000","0.00080000"],["112556.14000000","0.00335000"],["112555.30000000","0.00010000"],["112555.10000000","0.00108000"],["112553.41000000","0.00206000"],["112553.38000000","0.00000000"],["112553.37000000","0.00000000"],["112553.36000000","0.00000000"],["112551.75000000","0.00000000"],["112551.74000000","0.00000000"],["112551.73000000","0.00000000"],["112551.72000000","0.00355000"],["112550.67000000","0.00000000"],["112550.66000000","0.00000000"],["112550.65000000","0.00000000"],["112550.64000000","0.00000000"],["112549.79000000","0.10244000"],["112549.78000000","0.17952000"],["112549.47000000","0.00543000"],["112549.10000000","0.00010000"],["112549.09000000","0.04585000"],["112548.66000000","0.00005000"],["112548.65000000","0.00000000"],["112548.64000000","0.00000000"],["112548.52000000","0.00010000"],["112548.51000000","0.02979000"],["112548.04000000","0.00000000"],["112548.03000000","0.00000000"],["112547.26000000","0.00000000"],["112547.25000000","0.00000000"],["112547.05000000","0.00000000"],["112546.97000000","0.00196000"],["112546.44000000","0.00000000"],["112546.34000000","0.00010000"],["112546.33000000","0.20494000"],["112545.53000000","0.00000000"],["112545.52000000","0.00000000"],["112545.34000000","0.00005000"],["112545.33000000","0.35259000"],["112545.32000000","0.29322000"],["112545.28000000","0.00360000"],["112545.18000000","0.00000000"],["112545.17000000","0.00000000"],["112544.98000000","0.00000000"],["112544.97000000","0.00000000"],["112544.96000000","0.88396000"],["112544.50000000","0.00000000"],["112544.16000000","0.00000000"],["112544.15000000","0.00000000"],["112543.11000000","0.00000000"],["112543.03000000","0.00000000"],["112542.97000000","0.00000000"],["112542.96000000","0.00401000"],["112542.88000000","0.00000000"],["112542.87000000","0.00000000"],["112542.82000000","0.00000000"],["112542.81000000","0.00000000"],["112542.74000000","0.00000000"],["112542.54000000","0.00005000"],["112542.50000000","0.00000000"],["112542.16000000","0.00000000"],["112542.15000000","0.08890000"],["112542.14000000","0.00000000"],["112542.13000000","0.00000000"],["112541.61000000","0.19473000"],["112541.60000000","0.17768000"],["112541.59000000","0.09971000"],["112541.33000000","0.00000000"],["112541.11000000","0.09322000"],["112540.80000000","0.00000000"],["112540.52000000","0.04573000"],["112540.50000000","0.00000000"],["112540.49000000","0.00000000"],["112540.07000000","0.00000000"],["112539.76000000","0.00000000"],["112539.75000000","0.03684000"],["112539.33000000","0.22255000"],["112538.63000000","0.00000000"],["112537.58000000","0.21869000"],["112537.57000000","0.46938000"],["112537.56000000","0.00000000"],["112537.55000000","0.00000000"],["112537.00000000","0.00000000"],["112536.61000000","0.00200000"],["112535.24000000","0.00000000"],["112535.23000000","0.00000000"],["112534.89000000","0.00000000"],["112532.90000000","0.00088000"],["112532.52000000","0.00000000"],["112532.51000000","0.00444000"],["112532.50000000","0.10388000"],["112532.37000000","0.46938000"],["112532.25000000","0.00000000"],["112531.81000000","1.01531000"],["112531.80000000","1.70706000"],["112531.79000000","0.00000000"],["112531.12000000","0.00000000"],["112530.84000000","0.00000000"],["112530.20000000","0.00000000"],["112529.19000000","0.00000000"],["112529.01000000","0.00250000"],["112528.16000000","0.01256000"],["112528.00000000","0.00120000"],["112527.81000000","0.00000000"],["112527.29000000","0.00000000"],["112527.22000000","0.00000000"],["112527.15000000","0.00010000"],["112526.77000000","0.05311000"],["112526.74000000","0.00000000"],["112526.48000000","0.29980000"],["112526.16000000","1.01418000"],["112526.15000000","1.70701000"],["112526.14000000","0.00000000"],["112526.13000000","0.00000000"],["112526.00000000","0.00120000"],["112525.90000000","0.00000000"],["112525.35000000","0.35531000"],["112524.97000000","0.00888000"],["112524.14000000","0.00000000"],["112524.00000000","0.00120000"],["112523.93000000","0.01739000"],["112523.85000000","0.00000000"],["112523.75000000","0.00000000"],["112522.00000000","0.00120000"],["112519.99000000","0.00250000"],["112519.95000000","0.00009000"],["112519.85000000","0.00009000"],["112519.62000000","0.04000000"],["112519.01000000","0.00000000"],["112518.09000000","0.00000000"],["112517.84000000","0.26660000"],["112517.04000000","0.03900000"],["112516.47000000","0.02666000"],["112515.11000000","0.00014000"],["112513.14000000","0.00009000"],["112512.85000000","0.00000000"],["112512.72000000","0.31991000"],["112512.69000000","0.00000000"],["112509.34000000","0.00000000"],["112506.58000000","0.00000000"],["112505.44000000","0.00009000"],["112504.90000000","0.44510000"],["112500.78000000","0.34120000"],["112500.49000000","0.00000000"],["112500.00000000","0.02173000"],["112499.81000000","0.00000000"],["112498.21000000","0.31996000"],["112493.69000000","0.00000000"],["112493.55000000","0.00000000"],["112490.64000000","0.03600000"],["112490.08000000","0.02984000"],["112487.80000000","0.00000000"],["112483.80000000","0.00000000"],["112474.90000000","0.02224000"],["112472.28000000","0.00000000"],["112470.32000000","0.00000000"],["112468.38000000","0.00089000"],["112460.00000000","1.70861000"],["112456.24000000","0.00000000"],["112443.30000000","0.00444000"],["112422.03000000","0.00000000"],["112422.02000000","0.00000000"],["112422.01000000","0.00221000"],["112413.77000000","0.00000000"],["112388.82000000","0.05747000"],["112363.14000000","0.06748000"],["112309.62000000","0.00000000"],["112309.61000000","0.00000000"],["112309.60000000","0.00088000"],["112296.44000000","4.83284000"],["112290.42000000","0.01778000"],["112256.22000000","0.00000000"],["110867.87000000","0.00100000"],["110500.00000000","3.49141000"],["101300.00000000","1.33203000"],["90044.98000000","0.00022000"],["40520.24000000","0.00045000"]],"a":[["112556.23000000","2.68965000"],["112556.24000000","0.00005000"],["112556.48000000","0.04593000"],["112556.81000000","0.09463000"],["112556.82000000","0.06758000"],["112557.79000000","0.20494000"],["112558.00000000","0.00165000"],["112558.01000000","0.00161000"],["112558.72000000","0.00700000"],["112558.73000000","0.00310000"],["112559.01000000","0.00047000"],["112559.02000000","0.04060000"],["112559.32000000","0.00000000"],["112559.33000000","0.00000000"],["112559.99000000","0.00000000"],["112560.00000000","0.02071000"],["112560.58000000","0.00250000"],["112560.78000000","0.00000000"],["112561.19000000","0.00000000"],["112561.20000000","0.05943000"],["112561.86000000","0.00000000"],["112561.88000000","2.17639000"],["112561.89000000","0.18005000"],["112561.90000000","0.28000000"],["112562.36000000","0.00005000"],["112562.85000000","0.00000000"],["112564.01000000","0.00000000"],["112564.38000000","0.00000000"],["112565.09000000","0.00255000"],["112565.78000000","0.00444000"],["112565.79000000","0.00391000"],["112565.99000000","0.00000000"],["112567.49000000","0.10640000"],["112567.92000000","0.03000000"],["112567.99000000","0.26683000"],["112568.30000000","0.00000000"],["112568.87000000","0.00000000"],["112568.97000000","0.00000000"],["112569.00000000","0.12100000"],["112569.04000000","0.03000000"],["112569.32000000","0.00000000"],["112569.37000000","0.00000000"],["112570.12000000","0.15146000"],["112570.38000000","0.00200000"],["112572.58000000","0.00000000"],["112573.36000000","0.01256000"],["112574.25000000","0.00000000"],["112574.60000000","0.03000000"],["112575.29000000","0.00000000"],["112575.32000000","0.00000000"],["112575.62000000","0.00000000"],["112576.41000000","0.04480000"],["112576.79000000","0.00000000"],["112577.93000000","0.00000000"],["112581.60000000","0.00000000"],["112582.04000000","0.00000000"],["112583.13000000","0.00000000"],["112583.24000000","0.00000000"],["112584.01000000","0.00000000"],["112585.79000000","0.00000000"],["112585.98000000","0.00000000"],["112588.81000000","0.00000000"],["112590.00000000","0.26845000"],["112593.55000000","0.01776000"],["112594.96000000","0.31968000"],["112595.33000000","0.00000000"],["112601.33000000","0.01391000"],["112612.06000000","0.04091000"],["112613.08000000","0.26728000"],["112613.48000000","0.26683000"],["112615.16000000","0.00000000"],["112615.45000000","0.00000000"],["112615.95000000","0.26660000"],["112618.49000000","0.00000000"],["112624.08000000","0.00000000"],["112626.53000000","0.00000000"],["112626.93000000","0.00000000"],["112629.03000000","0.00000000"],["112630.51000000","0.00000000"],["112631.14000000","0.00000000"],["112633.11000000","0.00000000"],["112633.12000000","0.00000000"],["112633.90000000","0.00048000"],["112635.05000000","0.44510000"],["112635.06000000","0.00000000"],["112635.19000000","0.00000000"],["112635.27000000","0.00000000"],["112635.33000000","0.44452000"],["112635.52000000","0.00000000"],["112635.62000000","0.00000000"],["112636.07000000","0.26677000"],["112636.47000000","0.35608000"],["112636.61000000","0.03460000"],["112636.75000000","0.00000000"],["112636.86000000","0.00000000"],["112643.21000000","0.88763000"],["112649.13000000","0.00000000"],["112649.54000000","0.05400000"],["112650.93000000","0.00000000"],["112652.09000000","0.00000000"],["112685.50000000","0.01599000"],["112713.01000000","0.13366000"],["112715.59000000","0.02398000"],["112723.05000000","0.01599000"],["112740.10000000","0.00000000"],["112746.01000000","0.00019000"],["112779.67000000","0.00010000"],["112791.15000000","4.62278000"],["112817.72000000","0.00000000"],["112851.15000000","0.00000000"],["112988.69000000","0.02598000"],["113549.92000000","0.00000000"],["114244.58000000","0.00100000"]]}
[2025-10-26T09:48:21.083Z] {"e":"depthUpdate","E":1761472100014,"s":"BTCUSDT","U":79058061237,"u":79058062136,"b":[["112556.22000000","0.00000000"],["112556.21000000","0.00000000"],["112556.14000000","0.00000000"],["112555.30000000","0.00000000"],["112555.10000000","0.00000000"],["112554.00000000","0.00000000"],["112553.87000000","0.00000000"],["112553.86000000","0.00000000"],["112553.72000000","0.00000000"],["112553.41000000","0.00000000"],["112552.87000000","0.00000000"],["112551.72000000","0.00000000"],["112551.45000000","0.00000000"],["112550.55000000","0.00000000"],["112549.80000000","0.00000000"],["112549.79000000","0.00000000"],["112549.78000000","5.86496000"],["112549.77000000","0.00055000"],["112549.70000000","0.00010000"],["112549.47000000","0.00563000"],["112549.10000000","0.00000000"],["112549.09000000","0.00000000"],["112548.66000000","0.00000000"],["112548.52000000","0.00000000"],["112548.51000000","0.00000000"],["112547.80000000","0.00010000"],["112547.79000000","0.00020000"],["112546.97000000","0.00201000"],["112546.62000000","0.00000000"],["112546.34000000","0.00000000"],["112546.33000000","0.00000000"],["112545.34000000","0.00000000"],["112545.33000000","0.00000000"],["112545.32000000","0.00000000"],["112544.97000000","0.16995000"],["112544.96000000","0.56901000"],["112543.27000000","0.00000000"],["112543.25000000","0.00005000"],["112542.97000000","0.17769000"],["112542.96000000","0.00329000"],["112542.54000000","0.00000000"],["112542.30000000","0.00000000"],["112542.29000000","0.00000000"],["112542.28000000","0.00000000"],["112542.16000000","0.00010000"],["112542.15000000","0.08900000"],["112541.89000000","0.02910000"],["112541.70000000","0.20484000"],["112541.61000000","0.00000000"],["112541.60000000","0.00000000"],["112541.59000000","0.00000000"],["112541.12000000","0.00010000"],["112541.11000000","0.09322000"],["112540.52000000","0.00005000"],["112539.81000000","0.29318000"],["112539.78000000","0.00000000"],["112539.76000000","0.00005000"],["112539.75000000","0.03694000"],["112539.34000000","0.00000000"],["112539.33000000","0.00000000"],["112538.52000000","0.00305000"],["112538.03000000","0.00250000"],["112537.58000000","0.21874000"],["112537.57000000","0.00000000"],["112537.55000000","0.00005000"],["112537.44000000","0.00005000"],["112537.00000000","0.00000000"],["112536.61000000","0.00005000"],["112535.20000000","0.00000000"],["112535.15000000","0.04642000"],["112534.87000000","0.04568000"],["112533.70000000","0.22255000"],["112533.53000000","0.00000000"],["112532.90000000","0.00239000"],["112532.51000000","0.00000000"],["112532.38000000","0.54769000"],["112531.81000000","0.00000000"],["112531.80000000","0.00005000"],["112530.50000000","0.08884000"],["112528.66000000","0.00000000"],["112528.16000000","0.00000000"],["112528.01000000","0.00444000"],["112527.80000000","0.00000000"],["112527.66000000","0.00000000"],["112527.57000000","0.00000000"],["112526.77000000","0.00000000"],["112526.55000000","0.00000000"],["112525.07000000","0.05152000"],["112524.97000000","0.00000000"],["112523.93000000","0.00000000"],["112522.96000000","0.01791000"],["112521.65000000","0.00088000"],["112519.99000000","0.00250000"],["112519.95000000","0.00000000"],["112519.85000000","0.00000000"],["112519.82000000","0.00888000"],["112518.59000000","0.15146000"],["112516.47000000","0.00000000"],["112516.45000000","0.00005000"],["112516.44000000","0.00000000"],["112515.11000000","0.00005000"],["112514.55000000","0.00009000"],["112514.45000000","0.00009000"],["112513.95000000","0.00000000"],["112513.14000000","0.00000000"],["112512.72000000","0.00000000"],["112512.65000000","0.00000000"],["112511.47000000","0.00000000"],["112511.23000000","0.02666000"],["112511.17000000","0.00005000"],["112509.71000000","0.00009000"],["112507.74000000","0.00009000"],["112507.05000000","0.31993000"],["112507.03000000","0.00000000"],["112506.74000000","0.00000000"],["112505.44000000","0.00000000"],["112500.78000000","0.00000000"],["112500.04000000","0.00009000"],["112499.14000000","0.00088000"],["112498.92000000","0.00005000"],["112498.84000000","0.34119000"],["112493.37000000","0.31997000"],["112493.26000000","0.00000000"],["112490.08000000","0.00000000"],["112487.49000000","0.00000000"],["112486.39000000","0.00000000"],["112482.55000000","0.00010000"],["112476.82000000","0.00000000"],["112475.55000000","0.00000000"],["112475.00000000","0.00000000"],["112471.30000000","0.00010000"],["112471.01000000","0.00000000"],["112468.38000000","0.00000000"],["112468.00000000","0.00160000"],["112466.00000000","0.00160000"],["112464.00000000","0.00160000"],["112462.99000000","0.00089000"],["112462.00000000","0.00160000"],["112460.48000000","0.07045000"],["112460.08000000","0.02984000"],["112450.00000000","0.11160000"],["112449.45000000","0.00000000"],["112436.38000000","0.00000000"],["112434.68000000","0.00000000"],["112428.62000000","0.00005000"],["112409.55000000","0.09675000"],["112400.22000000","0.04618000"],["112353.00000000","0.00110000"],["112300.01000000","0.00000000"],["112292.48000000","0.00567000"],["112256.22000000","0.00000000"],["112223.00000000","0.02398000"],["112046.82000000","0.03198000"],["111000.00000000","6.11324000"],["110867.87000000","0.00000000"],["101300.00000000","1.33203000"],["101294.00000000","0.00000000"],["90044.98000000","0.00000000"],["90039.83000000","0.00022000"],["42000.00000000","1.40412000"]],"a":[["112549.79000000","4.12166000"],["112549.80000000","0.00000000"],["112549.87000000","0.00010000"],["112550.56000000","0.00000000"],["112550.59000000","0.00010000"],["112550.60000000","0.09623000"],["112551.45000000","0.00010000"],["112551.46000000","0.08976000"],["112551.73000000","0.00000000"],["112553.42000000","0.00000000"],["112553.72000000","0.00005000"],["112553.86000000","0.00010000"],["112553.87000000","0.00005000"],["112554.01000000","0.00000000"],["112554.18000000","0.00005000"],["112555.11000000","0.00000000"],["112555.29000000","0.00010000"],["112555.30000000","0.04092000"],["112555.31000000","0.00505000"],["112556.07000000","0.00250000"],["112556.15000000","0.00000000"],["112556.21000000","0.00005000"],["112556.22000000","1.79662000"],["112556.23000000","0.89444000"],["112556.24000000","0.00000000"],["112556.30000000","0.00000000"],["112556.48000000","0.04578000"],["112556.81000000","0.00000000"],["112556.82000000","0.06748000"],["112557.79000000","0.00000000"],["112558.42000000","0.00005000"],["112558.73000000","0.00305000"],["112559.02000000","0.00000000"],["112560.00000000","0.02076000"],["112560.57000000","0.00444000"],["112561.20000000","0.05248000"],["112561.89000000","0.02483000"],["112561.90000000","0.00000000"],["112562.00000000","0.00234000"],["112562.72000000","0.00161000"],["112562.85000000","0.00000000"],["112562.91000000","0.00005000"],["112564.00000000","0.00165000"],["112564.42000000","0.05842000"],["112565.09000000","0.00250000"],["112565.78000000","0.00000000"],["112566.67000000","0.00239000"],["112568.17000000","0.03000000"],["112569.16000000","0.00000000"],["112569.88000000","0.00000000"],["112570.10000000","0.00000000"],["112570.38000000","0.00000000"],["112570.86000000","0.04136000"],["112571.15000000","0.04480000"],["112573.36000000","0.00000000"],["112573.48000000","0.02998000"],["112573.57000000","0.03600000"],["112574.26000000","0.03503000"],["112574.71000000","0.05400000"],["112576.26000000","0.31973000"],["112576.41000000","0.00000000"],["112577.54000000","0.06596000"],["112578.27000000","0.44510000"],["112578.62000000","0.00000000"],["112580.18000000","0.44452000"],["112580.53000000","0.00000000"],["112581.04000000","0.00000000"],["112582.09000000","0.03598000"],["112582.33000000","0.00000000"],["112582.81000000","0.00000000"],["112587.78000000","0.00000000"],["112588.88000000","0.00018000"],["112589.42000000","0.31970000"],["112589.65000000","0.00000000"],["112591.41000000","0.43132000"],["112591.46000000","0.01599000"],["112592.61000000","0.00000000"],["112593.15000000","0.00000000"],["112594.05000000","0.00000000"],["112594.65000000","0.00000000"],["112594.96000000","0.00000000"],["112595.81000000","0.00000000"],["112600.43000000","0.00088000"],["112606.88000000","0.00000000"],["112608.52000000","0.00000000"],["112611.68000000","0.03460000"],["112612.53000000","0.26683000"],["112613.08000000","0.00000000"],["112613.48000000","0.00000000"],["112613.58000000","0.26728000"],["112620.00000000","0.64702000"],["112630.32000000","0.26677000"],["112631.77000000","0.35608000"],["112631.84000000","0.00000000"],["112633.52000000","0.00000000"],["112634.55000000","0.44510000"],["112635.04000000","0.00000000"],["112635.05000000","0.00000000"],["112635.10000000","0.00000000"],["112635.33000000","0.00000000"],["112635.49000000","0.00000000"],["112635.56000000","0.00000000"],["112636.07000000","0.00000000"],["112636.46000000","0.44452000"],["112636.47000000","0.00000000"],["112636.61000000","0.00000000"],["112636.90000000","0.46938000"],["112636.97000000","0.00000000"],["112644.18000000","0.00000000"],["112649.46000000","0.00089000"],["112673.39000000","0.00000000"],["112715.73000000","0.02398000"],["112740.93000000","0.01599000"],["112744.41000000","0.01599000"],["112760.95000000","0.01391000"],["112832.64000000","0.02398000"],["112843.45000000","0.00000000"],["113090.00000000","0.03198000"],["113549.16000000","0.00013000"],["113549.35000000","0.00000000"],["113551.02000000","0.04000000"],["114244.58000000","0.00000000"]]}
[2025-10-26T09:48:22.107Z] {"e":"depthUpdate","E":1761472101014,"s":"BTCUSDT","U":79058062137,"u":79058062770,"b":[["112549.78000000","6.83853000"],["112549.77000000","0.00035000"],["112549.47000000","0.00558000"],["112548.37000000","0.00005000"],["112547.80000000","0.00000000"],["112547.79000000","0.00000000"],["112547.05000000","0.00255000"],["112546.97000000","0.00196000"],["112546.82000000","0.20494000"],["112545.60000000","0.00000000"],["112545.33000000","0.37574000"],["112545.32000000","0.29327000"],["112545.28000000","0.00360000"],["112545.00000000","0.00005000"],["112544.98000000","0.00000000"],["112544.97000000","0.00000000"],["112544.96000000","0.56901000"],["112544.16000000","0.00000000"],["112544.15000000","0.22260000"],["112543.40000000","0.38317000"],["112543.39000000","0.46943000"],["112542.98000000","0.00000000"],["112542.97000000","0.00000000"],["112542.96000000","0.00329000"],["112542.54000000","0.00250000"],["112542.40000000","0.00000000"],["112542.17000000","0.00010000"],["112542.16000000","0.00000000"],["112542.15000000","0.00005000"],["112541.89000000","0.02905000"],["112541.71000000","0.00000000"],["112541.70000000","0.00000000"],["112541.12000000","0.00000000"],["112541.11000000","0.09317000"],["112539.81000000","0.00000000"],["112539.76000000","0.00000000"],["112539.75000000","0.03689000"],["112539.26000000","0.46938000"],["112537.58000000","0.21869000"],["112537.55000000","0.00000000"],["112537.10000000","0.00000000"],["112536.55000000","0.00005000"],["112535.75000000","0.46938000"],["112535.15000000","0.04647000"],["112533.70000000","0.00000000"],["112532.96000000","0.01256000"],["112532.50000000","0.12100000"],["112532.41000000","1.53521000"],["112532.40000000","0.00000000"],["112532.39000000","1.70701000"],["112532.38000000","0.00000000"],["112532.19000000","0.06748000"],["112531.45000000","0.00200000"],["112530.27000000","0.15146000"],["112529.50000000","0.26660000"],["112528.86000000","0.04305000"],["112524.50000000","0.00000000"],["112519.99000000","0.00000000"],["112518.59000000","0.00000000"],["112517.84000000","0.00000000"],["112512.68000000","0.31991000"],["112511.23000000","0.00000000"],["112511.17000000","0.02671000"],["112503.89000000","0.94321000"],["112493.37000000","0.00000000"],["112488.00000000","0.00140000"],["112487.80000000","0.02984000"],["112487.28000000","0.00000000"],["112486.00000000","0.00140000"],["112484.00000000","0.00140000"],["112482.00000000","0.00140000"],["112481.23000000","0.26660000"],["112477.44000000","0.00383000"],["112460.08000000","0.00000000"],["112456.15000000","0.00000000"],["112452.80000000","0.00000000"],["112450.00000000","0.02160000"],["112447.24000000","0.02359000"],["112432.44000000","0.00005000"],["112420.60000000","0.09675000"],["112409.55000000","0.00000000"],["112380.01000000","0.00000000"],["112346.28000000","0.04463000"],["111265.93000000","0.00000000"],["110861.53000000","0.00100000"],["101300.00000000","1.33193000"],["101294.00000000","0.00010000"],["90040.00000000","0.00025000"],["90039.83000000","0.00022000"]],"a":[["112549.79000000","0.49792000"],["112550.59000000","0.00000000"],["112550.60000000","0.00005000"],["112551.46000000","0.08996000"],["112553.41000000","0.00000000"],["112553.42000000","0.00000000"],["112553.86000000","0.00000000"],["112553.87000000","0.00000000"],["112555.30000000","0.04112000"],["112555.31000000","0.00000000"],["112555.53000000","0.00000000"],["112555.54000000","0.00000000"],["112555.75000000","0.00000000"],["112556.05000000","0.00010000"],["112556.06000000","0.15380000"],["112556.07000000","0.00005000"],["112556.21000000","0.00010000"],["112556.22000000","0.08986000"],["112556.23000000","0.31463000"],["112556.24000000","0.00005000"],["112556.47000000","0.00000000"],["112556.48000000","0.04573000"],["112556.74000000","0.00007000"],["112556.82000000","0.00000000"],["112558.01000000","0.00161000"],["112558.68000000","0.04005000"],["112558.72000000","0.00000000"],["112559.09000000","0.20484000"],["112559.34000000","0.00898000"],["112559.84000000","0.00005000"],["112560.00000000","0.02071000"],["112560.57000000","0.00000000"],["112561.20000000","0.05948000"],["112561.86000000","0.08411000"],["112561.87000000","0.00000000"],["112561.88000000","0.00000000"],["112561.89000000","0.00000000"],["112562.70000000","0.00070000"],["112562.98000000","0.00538000"],["112563.04000000","0.00072000"],["112563.08000000","0.00325000"],["112563.32000000","0.00000000"],["112564.00000000","0.00160000"],["112564.68000000","0.00010000"],["112565.20000000","0.00000000"],["112565.21000000","0.00200000"],["112565.33000000","0.03000000"],["112566.59000000","0.03300000"],["112567.99000000","0.00000000"],["112568.99000000","0.00444000"],["112569.00000000","0.06000000"],["112570.12000000","0.00000000"],["112570.84000000","0.00000000"],["112571.15000000","0.00000000"],["112571.68000000","0.00888000"],["112574.56000000","0.00000000"],["112575.81000000","0.00000000"],["112575.82000000","0.31974000"],["112576.26000000","0.00000000"],["112576.41000000","0.29976000"],["112576.88000000","0.00000000"],["112577.23000000","0.00000000"],["112578.28000000","0.26683000"],["112578.62000000","0.00250000"],["112578.63000000","0.35608000"],["112580.65000000","0.04480000"],["112581.20000000","0.98101000"],["112581.99000000","0.17544000"],["112611.68000000","0.00000000"],["112612.06000000","0.00000000"],["112612.53000000","0.00000000"],["112620.00000000","0.55702000"],["112620.84000000","0.03460000"],["112623.30000000","0.26691000"],["112623.72000000","0.04091000"],["112627.50000000","0.00048000"],["112633.90000000","0.00000000"],["112642.45000000","0.03600000"],["112705.25000000","0.47523000"],["112712.66000000","0.00000000"],["112740.10000000","0.00019000"],["112746.01000000","0.00000000"],["114238.04000000","0.00112000"]]}
[2025-10-26T09:48:23.050Z] {"e":"depthUpdate","E":1761472102014,"s":"BTCUSDT","U":79058062771,"u":79058063320,"b":[["112549.78000000","6.38950000"],["112549.77000000","0.00229000"],["112549.47000000","0.00000000"],["112548.37000000","0.00000000"],["112547.05000000","0.00000000"],["112546.99000000","0.00010000"],["112546.98000000","0.17787000"],["112546.97000000","0.00201000"],["112546.83000000","0.00000000"],["112546.82000000","0.00000000"],["112545.34000000","0.00000000"],["112545.33000000","0.00000000"],["112545.32000000","0.00000000"],["112545.28000000","0.00365000"],["112544.97000000","0.00010000"],["112544.96000000","0.56901000"],["112544.16000000","0.00000000"],["112544.15000000","0.00000000"],["112543.41000000","0.00010000"],["112543.40000000","0.51629000"],["112543.39000000","0.46948000"],["112543.03000000","0.00538000"],["112542.75000000","0.00005000"],["112542.74000000","0.20489000"],["112542.54000000","0.00255000"],["112542.46000000","0.00000000"],["112542.16000000","0.00000000"],["112542.15000000","0.08895000"],["112541.89000000","0.02905000"],["112541.33000000","0.22260000"],["112541.11000000","0.09322000"],["112540.22000000","0.00391000"],["112539.75000000","0.03694000"],["112539.00000000","0.29319000"],["112538.53000000","0.00761000"],["112538.03000000","0.00255000"],["112536.61000000","0.00000000"],["112536.12000000","0.04567000"],["112535.15000000","0.04642000"],["112534.87000000","0.00000000"],["112532.96000000","0.00000000"],["112526.48000000","0.00000000"],["112524.50000000","0.00250000"],["112521.21000000","0.01256000"],["112520.12000000","0.29982000"],["112512.68000000","0.00000000"],["112498.84000000","0.00000000"],["112497.31000000","0.34118000"],["112494.00000000","0.32117000"],["112487.80000000","0.00000000"],["112474.70000000","0.02984000"],["112452.80000000","0.00005000"],["112447.24000000","0.00000000"],["112439.40000000","0.00005000"],["112380.01000000","0.02288000"],["112320.00000000","0.00045000"],["112230.00000000","0.04851000"],["112222.00000000","0.34447000"],["111596.26000000","0.00000000"],["111000.00000000","6.11234000"],["110861.53000000","0.00100000"],["103545.80000000","0.00000000"],["101294.00000000","0.00010000"],["90039.83000000","0.00022000"],["40517.92000000","0.00105000"],["33000.00000000","3.78938000"]],"a":[["112549.79000000","1.63325000"],["112549.80000000","0.00055000"],["112550.91000000","0.00118000"],["112551.44000000","0.00010000"],["112551.45000000","0.09081000"],["112551.46000000","0.08991000"],["112551.84000000","0.00010000"],["112551.85000000","0.20494000"],["112551.88000000","0.00842000"],["112553.02000000","0.00903000"],["112553.99000000","0.00005000"],["112554.29000000","0.00355000"],["112555.08000000","0.00000000"],["112555.09000000","0.00000000"],["112555.10000000","0.00186000"],["112555.30000000","0.04102000"],["112555.49000000","0.00005000"],["112555.50000000","0.06105000"],["112556.03000000","0.00000000"],["112556.04000000","0.00000000"],["112556.05000000","0.00000000"],["112556.06000000","0.00000000"],["112556.07000000","0.00255000"],["112556.20000000","0.00005000"],["112556.21000000","0.14515000"],["112556.22000000","0.08966000"],["112556.23000000","0.30622000"],["112556.24000000","0.00000000"],["112556.47000000","0.29981000"],["112556.48000000","0.04573000"],["112556.54000000","0.00538000"],["112557.34000000","0.00000000"],["112558.01000000","0.00156000"],["112558.68000000","0.00000000"],["112559.09000000","0.00000000"],["112559.34000000","0.00893000"],["112559.84000000","0.00000000"],["112560.00000000","0.02071000"],["112561.04000000","0.00716000"],["112561.20000000","0.05948000"],["112561.50000000","0.00000000"],["112561.57000000","0.04000000"],["112562.00000000","0.00229000"],["112562.70000000","0.00000000"],["112562.72000000","0.00000000"],["112562.91000000","0.00000000"],["112562.98000000","0.00000000"],["112563.04000000","0.00000000"],["112563.08000000","0.00000000"],["112563.39000000","1.70701000"],["112565.79000000","0.00000000"],["112565.94000000","0.46938000"],["112567.48000000","0.00000000"],["112569.00000000","0.12100000"],["112570.01000000","0.31975000"],["112571.72000000","0.15146000"],["112575.00000000","0.04961000"],["112576.41000000","0.00000000"],["112578.38000000","0.00000000"],["112578.47000000","0.00000000"],["112578.62000000","0.00000000"],["112580.50000000","0.00000000"],["112580.65000000","0.00000000"],["112581.20000000","0.00000000"],["112581.99000000","0.02398000"],["112585.06000000","0.98212000"],["112589.42000000","0.00000000"],["112599.44000000","0.00490000"],["112600.07000000","0.03000000"],["112610.00000000","0.40160000"],["112620.00000000","0.19702000"],["112627.50000000","0.00048000"],["112657.37000000","0.00000000"],["112700.00000000","0.57033000"],["112740.10000000","0.00019000"],["114238.04000000","0.00112000"]]}
[2025-10-26T09:48:24.049Z] {"e":"depthUpdate","E":1761472103014,"s":"BTCUSDT","U":79058063321,"u":79058063441,"b":[["112549.78000000","6.38549000"],["112549.77000000","0.00224000"],["112541.89000000","0.02905000"],["112541.33000000","0.00000000"],["112541.11000000","0.09327000"],["112539.00000000","0.00000000"],["112538.88000000","0.29319000"],["112537.58000000","0.31007000"],["112536.46000000","0.00000000"],["112535.71000000","0.22255000"],["112532.41000000","1.13603000"],["112529.50000000","0.00000000"],["112522.86000000","0.01256000"],["112521.78000000","0.00000000"],["112521.45000000","0.00000000"],["112521.33000000","0.00000000"],["112521.21000000","0.00000000"],["112517.81000000","0.26660000"],["112503.89000000","0.00000000"],["112470.00000000","0.20140000"],["112450.00000000","0.11160000"],["112435.02000000","0.00000000"],["112422.01000000","0.00000000"],["112414.87000000","0.00220000"],["112380.01000000","0.02288000"],["112332.96000000","0.01599000"],["112329.52000000","0.01599000"],["112309.60000000","0.00000000"],["112303.31000000","0.00088000"],["111457.53000000","0.00250000"],["111348.10000000","0.00022000"],["110861.53000000","0.00100000"],["101294.00000000","0.00010000"],["90039.83000000","0.00022000"],["60000.00000000","57.64892000"],["42000.00000000","1.40312000"],["40517.92000000","0.00120000"]],"a":[["112549.79000000","1.46356000"],["112549.80000000","0.00055000"],["112551.25000000","0.00008000"],["112551.46000000","0.08991000"],["112551.84000000","0.00000000"],["112551.85000000","0.00000000"],["112553.02000000","0.00903000"],["112553.57000000","0.00010000"],["112553.58000000","0.20494000"],["112556.47000000","0.00000000"],["112556.54000000","0.00543000"],["112557.43000000","0.06748000"],["112561.19000000","0.29980000"],["112561.57000000","0.04000000"],["112571.32000000","0.00600000"],["112577.42000000","0.00000000"],["112578.47000000","0.00000000"],["112585.06000000","0.00000000"],["112620.00000000","0.19702000"],["112637.21000000","0.00100000"],["112637.22000000","0.00100000"],["112645.39000000","0.00000000"],["112645.40000000","0.00000000"],["112989.49000000","0.02612000"],["113527.23000000","0.00246000"],["114238.04000000","0.00112000"],["114800.00000000","3.60193000"]]}
[2025-10-26T09:48:25.054Z] {"e":"depthUpdate","E":1761472104014,"s":"BTCUSDT","U":79058063442,"u":79058064743,"b":[["112556.20000000","2.96767000"],["112556.19000000","0.00045000"],["112556.14000000","0.00000000"],["112556.13000000","0.00010000"],["112556.09000000","0.00000000"],["112556.06000000","0.00000000"],["112555.58000000","0.00010000"],["112555.57000000","0.04020000"],["112555.52000000","0.00000000"],["112555.50000000","0.00000000"],["112555.49000000","0.00000000"],["112555.36000000","0.00000000"],["112555.33000000","0.00000000"],["112555.31000000","0.00000000"],["112555.30000000","0.00000000"],["112555.29000000","0.00000000"],["112555.09000000","0.00000000"],["112554.28000000","0.00000000"],["112553.72000000","0.00005000"],["112553.57000000","0.00000000"],["112553.01000000","0.00000000"],["112551.87000000","0.00000000"],["112551.78000000","0.17938000"],["112551.77000000","0.00010000"],["112551.76000000","0.00000000"],["112551.75000000","0.00005000"],["112551.56000000","0.00255000"],["112551.45000000","0.00000000"],["112551.44000000","0.00010000"],["112551.43000000","0.00005000"],["112550.90000000","0.00000000"],["112550.59000000","0.00000000"],["112550.58000000","0.00010000"],["112550.57000000","0.08895000"],["112549.86000000","0.00000000"],["112549.81000000","0.00000000"],["112549.79000000","0.00010000"],["112549.78000000","0.11146000"],["112549.77000000","0.00189000"],["112549.70000000","0.00000000"],["112547.99000000","0.20484000"],["112547.94000000","0.00000000"],["112547.93000000","0.00000000"],["112547.88000000","0.00000000"],["112547.87000000","0.26937000"],["112547.86000000","0.02613000"],["112547.05000000","0.00250000"],["112546.99000000","0.00000000"],["112546.98000000","0.00000000"],["112546.97000000","0.00196000"],["112546.62000000","0.00005000"],["112545.28000000","0.00370000"],["112545.00000000","0.06105000"],["112544.97000000","0.00000000"],["112544.96000000","0.56896000"],["112544.94000000","0.31500000"],["112544.50000000","0.00007000"],["112543.87000000","0.00000000"],["112543.44000000","0.00000000"],["112543.41000000","0.17768000"],["112543.40000000","0.44509000"],["112543.39000000","0.46938000"],["112543.03000000","0.00533000"],["112542.96000000","0.00334000"],["112542.75000000","0.00000000"],["112542.74000000","0.00000000"],["112542.55000000","0.00444000"],["112542.54000000","0.00255000"],["112542.15000000","0.00000000"],["112541.89000000","0.00000000"],["112541.57000000","0.07357000"],["112541.51000000","0.00000000"],["112541.34000000","0.00000000"],["112541.15000000","0.00000000"],["112541.11000000","0.00005000"],["112540.52000000","0.00000000"],["112540.22000000","0.00396000"],["112539.76000000","0.29976000"],["112539.75000000","0.03684000"],["112539.32000000","0.00088000"],["112539.31000000","0.22255000"],["112538.88000000","0.00000000"],["112538.53000000","0.00761000"],["112538.52000000","0.00300000"],["112538.03000000","0.00250000"],["112535.71000000","0.00000000"],["112535.15000000","0.00000000"],["112532.90000000","0.00088000"],["112530.50000000","0.09772000"],["112529.94000000","0.26660000"],["112529.85000000","0.00005000"],["112529.01000000","0.00000000"],["112528.01000000","0.00000000"],["112527.75000000","0.00000000"],["112527.64000000","0.00000000"],["112527.55000000","0.01256000"],["112524.50000000","0.00000000"],["112522.86000000","0.00000000"],["112520.50000000","0.00000000"],["112520.12000000","0.00000000"],["112518.25000000","0.31990000"],["112517.81000000","0.00000000"],["112514.61000000","0.21562000"],["112514.58000000","0.00177000"],["112513.82000000","0.00000000"],["112512.48000000","0.31992000"],["112505.56000000","0.00088000"],["112504.38000000","0.96103000"],["112500.57000000","0.00000000"],["112499.14000000","0.00000000"],["112498.92000000","0.00000000"],["112498.21000000","0.00000000"],["112494.00000000","0.00120000"],["112487.73000000","0.02984000"],["112483.07000000","0.26660000"],["112481.23000000","0.00000000"],["112480.00000000","0.00145000"],["112474.70000000","0.00000000"],["112462.85000000","0.00000000"],["112459.50000000","0.00000000"],["112450.16000000","0.02359000"],["112428.62000000","0.00000000"],["112422.01000000","0.00221000"],["112420.60000000","0.00000000"],["112418.14000000","0.09675000"],["112414.87000000","0.00000000"],["112325.00000000","0.34447000"],["112309.60000000","0.00088000"],["112303.31000000","0.00000000"],["112296.89000000","4.73307000"],["112296.44000000","0.00000000"],["112222.00000000","0.00000000"],["112164.29000000","0.66810000"],["111975.44000000","0.00000000"],["111975.16000000","0.00008000"],["111732.00000000","2.04549000"],["111480.00000000","0.00193000"],["111457.53000000","0.00000000"],["110867.85000000","0.00100000"],["110861.53000000","0.00000000"],["110700.01000000","0.00000000"],["103800.00000000","1.00087000"],["101300.01000000","0.00000000"],["101300.00000000","1.33203000"],["101294.00000000","0.00000000"],["90044.96000000","0.00022000"],["90040.00000000","0.00025000"],["90039.83000000","0.00000000"],["60000.01000000","0.04830000"],["60000.00000000","57.64882000"]],"a":[["112549.79000000","0.00000000"],["112549.80000000","0.00000000"],["112549.87000000","0.00000000"],["112550.60000000","0.00000000"],["112550.91000000","0.00000000"],["112551.25000000","0.00000000"],["112551.44000000","0.00000000"],["112551.45000000","0.00000000"],["112551.46000000","0.00000000"],["112551.88000000","0.00000000"],["112553.02000000","0.00000000"],["112553.57000000","0.00000000"],["112553.58000000","0.00000000"],["112553.72000000","0.00000000"],["112553.99000000","0.00000000"],["112554.18000000","0.00000000"],["112554.29000000","0.00000000"],["112555.10000000","0.00000000"],["112555.29000000","0.00000000"],["112555.30000000","0.00000000"],["112555.49000000","0.00000000"],["112555.50000000","0.00000000"],["112556.07000000","0.00000000"],["112556.20000000","0.00000000"],["112556.21000000","1.69661000"],["112556.22000000","0.04465000"],["112556.23000000","0.00005000"],["112556.29000000","0.00010000"],["112556.47000000","0.00010000"],["112556.48000000","0.04603000"],["112556.54000000","0.00553000"],["112556.55000000","0.00000000"],["112556.73000000","0.03480000"],["112557.42000000","0.00000000"],["112557.43000000","0.00000000"],["112557.48000000","0.00000000"],["112557.49000000","0.00000000"],["112558.00000000","0.00170000"],["112558.01000000","0.00156000"],["112558.38000000","0.00000000"],["112558.39000000","0.00000000"],["112558.48000000","0.00000000"],["112558.49000000","0.00000000"],["112559.17000000","0.00000000"],["112559.34000000","0.00898000"],["112559.35000000","0.00401000"],["112559.37000000","0.00000000"],["112559.56000000","0.00000000"],["112559.57000000","0.00000000"],["112559.77000000","0.04409000"],["112559.78000000","0.00010000"],["112559.97000000","0.00010000"],["112559.98000000","0.06753000"],["112559.99000000","0.00005000"],["112560.00000000","0.02071000"],["112560.58000000","0.00000000"],["112561.04000000","0.00721000"],["112561.18000000","0.00000000"],["112561.19000000","0.00000000"],["112561.20000000","0.05948000"],["112561.57000000","0.04005000"],["112561.85000000","0.00000000"],["112561.86000000","0.08416000"],["112562.00000000","0.00234000"],["112563.77000000","0.01791000"],["112564.00000000","0.00160000"],["112564.42000000","0.00005000"],["112565.09000000","0.00255000"],["112565.21000000","0.00205000"],["112565.33000000","0.03000000"],["112565.94000000","0.00000000"],["112566.00000000","0.00160000"],["112566.58000000","0.00000000"],["112566.67000000","0.00151000"],["112570.01000000","0.00000000"],["112570.84000000","0.10691000"],["112571.32000000","0.00000000"],["112571.72000000","0.00000000"],["112572.65000000","0.29976000"],["112573.09000000","0.00151000"],["112575.00000000","0.00481000"],["112576.15000000","0.48335000"],["112578.62000000","0.00250000"],["112580.20000000","0.00000000"],["112580.28000000","0.00000000"],["112581.33000000","0.97238000"],["112582.51000000","0.01256000"],["112582.58000000","0.15146000"],["112583.13000000","0.00000000"],["112584.84000000","0.00000000"],["112585.53000000","0.04480000"],["112587.64000000","0.00250000"],["112589.21000000","0.31970000"],["112606.86000000","0.00088000"],["112608.52000000","0.00005000"],["112620.84000000","0.00000000"],["112623.72000000","0.00000000"],["112627.50000000","0.00000000"],["112630.32000000","0.00000000"],["112633.90000000","0.00048000"],["112635.42000000","0.03460000"],["112636.21000000","0.26677000"],["112637.21000000","0.00000000"],["112637.22000000","0.00000000"],["112637.73000000","0.04101000"],["112640.01000000","0.00000000"],["112640.02000000","0.00000000"],["112641.85000000","0.00000000"],["112641.86000000","0.00000000"],["112642.02000000","0.00000000"],["112642.03000000","0.00000000"],["112655.43000000","0.00000000"],["112673.39000000","0.00005000"],["112688.00000000","0.00360000"],["112705.25000000","0.00000000"],["112740.10000000","0.00000000"],["112746.01000000","0.00019000"],["112791.12000000","4.71697000"],["112791.15000000","0.00000000"],["112974.78000000","0.00000000"],["113527.23000000","0.00000000"],["113551.02000000","0.00000000"],["114238.04000000","0.00012000"],["114244.56000000","0.00100000"],["115000.00000000","181.27453000"]]}
[2025-10-26T09:48:26.048Z] {"e":"depthUpdate","E":1761472105014,"s":"BTCUSDT","U":79058064744,"u":79058065563,"b":[["112556.20000000","3.39339000"],["112556.19000000","0.00005000"],["112555.57000000","0.04030000"],["112551.79000000","0.00000000"],["112551.78000000","0.00000000"],["112551.77000000","0.00000000"],["112551.75000000","0.00000000"],["112551.74000000","0.12176000"],["112551.73000000","0.20486000"],["112551.56000000","0.00250000"],["112551.44000000","0.00000000"],["112551.43000000","0.00000000"],["112550.59000000","0.00000000"],["112550.58000000","0.00015000"],["112550.57000000","0.00010000"],["112550.55000000","0.00005000"],["112549.79000000","0.00000000"],["112549.78000000","0.11146000"],["112548.00000000","0.00000000"],["112547.99000000","0.00000000"],["112547.94000000","0.00000000"],["112547.93000000","0.00000000"],["112547.88000000","0.00000000"],["112547.87000000","0.29260000"],["112547.86000000","0.02613000"],["112547.18000000","0.00000000"],["112547.05000000","0.00250000"],["112546.30000000","0.29322000"],["112545.28000000","0.00370000"],["112545.00000000","0.06105000"],["112544.97000000","0.00000000"],["112544.96000000","0.56891000"],["112544.94000000","0.31500000"],["112543.66000000","0.00000000"],["112543.62000000","0.00000000"],["112543.50000000","0.00000000"],["112543.49000000","0.00000000"],["112543.41000000","0.68115000"],["112543.40000000","0.00000000"],["112543.39000000","0.46938000"],["112542.96000000","0.00329000"],["112542.55000000","0.00000000"],["112540.70000000","0.00000000"],["112539.76000000","0.00000000"],["112539.75000000","0.03689000"],["112538.89000000","0.00000000"],["112538.53000000","0.00761000"],["112538.52000000","0.00300000"],["112538.04000000","0.00444000"],["112535.82000000","0.00000000"],["112535.15000000","0.00000000"],["112534.93000000","0.06748000"],["112533.30000000","0.00000000"],["112532.59000000","0.26683000"],["112532.51000000","0.29978000"],["112532.29000000","0.26728000"],["112532.19000000","0.00000000"],["112531.86000000","0.04005000"],["112531.45000000","0.00000000"],["112529.01000000","0.00000000"],["112525.95000000","0.00888000"],["112524.50000000","0.00000000"],["112520.97000000","0.00000000"],["112520.68000000","0.00000000"],["112519.99000000","0.00000000"],["112519.82000000","0.00000000"],["112519.62000000","0.00000000"],["112518.25000000","0.00000000"],["112518.15000000","0.00000000"],["112518.05000000","0.00000000"],["112517.78000000","0.31990000"],["112514.55000000","0.00000000"],["112514.45000000","0.00000000"],["112513.31000000","0.00000000"],["112511.34000000","0.00000000"],["112509.71000000","0.00000000"],["112507.74000000","0.00000000"],["112503.64000000","0.00000000"],["112500.08000000","0.00000000"],["112500.04000000","0.00000000"],["112495.33000000","0.02984000"],["112489.69000000","0.00000000"],["112487.73000000","0.00000000"],["112486.86000000","0.26683000"],["112486.56000000","0.26728000"],["112486.13000000","0.00000000"],["112475.03000000","0.00000000"],["112470.00000000","0.00140000"],["112466.58000000","0.00000000"],["112464.53000000","0.05397000"],["112462.99000000","0.00000000"],["112459.50000000","0.00005000"],["112450.00000000","0.02160000"],["112428.86000000","0.00000000"],["112425.83000000","0.00380000"],["112420.01000000","0.14391000"],["112417.83000000","0.00000000"],["112337.92000000","0.00000000"],["112330.09000000","0.01391000"],["112329.42000000","0.00000000"],["112328.01000000","0.00000000"],["112306.12000000","0.00000000"],["111975.16000000","0.00000000"],["111241.00000000","0.00273000"],["110867.85000000","0.00100000"],["101300.01000000","0.00009000"],["101300.00000000","1.33203000"],["90044.96000000","0.00022000"]],"a":[["112556.21000000","0.64946000"],["112556.22000000","0.04470000"],["112556.23000000","0.00000000"],["112556.47000000","0.00000000"],["112556.48000000","0.00005000"],["112556.54000000","0.00568000"],["112556.72000000","0.00000000"],["112556.73000000","0.00000000"],["112557.68000000","0.00010000"],["112557.69000000","0.04025000"],["112557.78000000","0.00010000"],["112557.79000000","0.08015000"],["112558.00000000","0.00165000"],["112558.48000000","0.00010000"],["112558.49000000","0.02010000"],["112558.73000000","0.00310000"],["112558.80000000","0.00005000"],["112558.81000000","0.04572000"],["112559.34000000","0.00898000"],["112559.35000000","0.00396000"],["112559.75000000","0.00000000"],["112559.76000000","0.00005000"],["112559.77000000","0.00000000"],["112559.78000000","0.00000000"],["112559.80000000","0.00005000"],["112559.97000000","0.00000000"],["112559.98000000","0.00000000"],["112559.99000000","0.00000000"],["112560.00000000","0.02071000"],["112560.58000000","0.00000000"],["112561.04000000","0.00716000"],["112561.20000000","0.05943000"],["112561.57000000","0.00005000"],["112561.86000000","0.00005000"],["112562.00000000","0.00234000"],["112562.79000000","0.16000000"],["112563.39000000","0.00000000"],["112563.77000000","0.00005000"],["112563.84000000","0.00000000"],["112564.64000000","0.00000000"],["112565.09000000","0.00250000"],["112565.21000000","0.00000000"],["112565.24000000","0.01766000"],["112565.37000000","0.00000000"],["112565.46000000","0.04000000"],["112566.56000000","0.00000000"],["112566.79000000","0.00000000"],["112567.49000000","0.00000000"],["112567.88000000","0.00000000"],["112568.58000000","0.00000000"],["112568.91000000","0.00000000"],["112568.99000000","0.00000000"],["112569.07000000","0.00069000"],["112569.26000000","0.00073000"],["112569.29000000","0.00000000"],["112569.39000000","0.00069000"],["112570.52000000","0.00000000"],["112570.82000000","0.00444000"],["112570.83000000","0.00000000"],["112570.96000000","0.00010000"],["112571.68000000","0.00000000"],["112572.65000000","0.00000000"],["112573.10000000","0.10640000"],["112573.15000000","0.00000000"],["112575.34000000","0.00000000"],["112575.56000000","0.00888000"],["112575.82000000","0.00000000"],["112576.65000000","0.31973000"],["112577.53000000","0.29975000"],["112578.06000000","0.00000000"],["112578.75000000","0.00000000"],["112579.43000000","0.00000000"],["112580.89000000","0.00000000"],["112582.51000000","0.00000000"],["112582.58000000","0.00000000"],["112584.33000000","0.00000000"],["112584.69000000","0.15146000"],["112584.87000000","0.01256000"],["112585.37000000","0.00000000"],["112585.53000000","0.00000000"],["112587.64000000","0.00250000"],["112587.95000000","0.26660000"],["112588.37000000","0.04480000"],["112589.21000000","0.00000000"],["112589.25000000","0.00000000"],["112594.13000000","0.31968000"],["112599.44000000","0.00000000"],["112604.70000000","0.18777000"],["112610.00000000","0.00160000"],["112613.10000000","0.00000000"],["112615.95000000","0.00000000"],["112620.00000000","0.19702000"],["112622.74000000","0.00000000"],["112627.51000000","0.00000000"],["112630.42000000","0.00007000"],["112632.98000000","0.26660000"],["112633.90000000","0.00048000"],["112635.42000000","0.00000000"],["112636.21000000","0.00000000"],["112636.61000000","0.26677000"],["112643.02000000","0.00000000"],["112643.03000000","0.00000000"],["112643.21000000","0.88763000"],["112643.22000000","0.00000000"],["112647.30000000","0.03460000"],["112649.73000000","0.93848000"],["112665.80000000","1.18533000"],["112666.15000000","0.05387000"],["112700.00000000","0.25867000"],["112713.01000000","0.00000000"],["112746.01000000","0.00019000"],["114000.00000000","98.53579000"],["114244.56000000","0.00100000"]]}
[2025-10-26T09:48:27.048Z] {"e":"depthUpdate","E":1761472106014,"s":"BTCUSDT","U":79058065564,"u":79058066177,"b":[["112556.20000000","2.79882000"],["112556.19000000","0.00000000"],["112555.58000000","0.00000000"],["112555.57000000","0.00005000"],["112555.18000000","0.00010000"],["112555.17000000","0.23320000"],["112555.16000000","0.00000000"],["112555.15000000","0.00000000"],["112555.14000000","0.00010000"],["112555.13000000","0.20486000"],["112551.75000000","0.00000000"],["112551.74000000","0.00000000"],["112551.73000000","0.00000000"],["112551.58000000","0.00010000"],["112551.57000000","0.17775000"],["112551.56000000","0.00250000"],["112550.58000000","0.00010000"],["112550.57000000","0.31150000"],["112549.79000000","0.00010000"],["112549.78000000","0.11141000"],["112549.77000000","0.00005000"],["112549.65000000","0.00000000"],["112549.64000000","0.00000000"],["112549.51000000","0.00000000"],["112549.50000000","0.29321000"],["112547.88000000","0.00000000"],["112547.87000000","0.48267000"],["112547.86000000","0.02608000"],["112547.08000000","0.00000000"],["112546.92000000","0.46943000"],["112546.30000000","0.00000000"],["112545.28000000","0.00365000"],["112545.00000000","0.06100000"],["112544.96000000","0.56891000"],["112544.02000000","0.00000000"],["112543.46000000","0.00000000"],["112543.41000000","0.81454000"],["112543.03000000","0.00533000"],["112542.96000000","0.00005000"],["112542.61000000","0.00000000"],["112542.55000000","0.00000000"],["112542.54000000","0.00255000"],["112542.49000000","0.00000000"],["112542.44000000","0.00005000"],["112541.67000000","0.01777000"],["112541.57000000","0.11924000"],["112541.51000000","0.00205000"],["112540.76000000","0.00000000"],["112540.34000000","0.04414000"],["112540.22000000","0.00391000"],["112539.75000000","0.03684000"],["112539.63000000","0.00000000"],["112539.31000000","0.00000000"],["112538.51000000","1.70701000"],["112536.12000000","0.00000000"],["112535.78000000","0.00000000"],["112533.65000000","0.00000000"],["112528.86000000","0.00000000"],["112527.98000000","0.00000000"],["112527.84000000","0.00000000"],["112527.62000000","0.00000000"],["112527.55000000","0.00000000"],["112527.51000000","0.00000000"],["112525.07000000","0.00000000"],["112523.85000000","0.00009000"],["112523.75000000","0.00009000"],["112519.55000000","0.00000000"],["112519.45000000","0.00000000"],["112519.02000000","0.00009000"],["112517.04000000","0.03909000"],["112514.72000000","0.00000000"],["112512.74000000","0.00000000"],["112509.34000000","0.00009000"],["112505.04000000","0.00000000"],["112504.38000000","0.00000000"],["112495.33000000","0.00000000"],["112482.01000000","0.02984000"],["112472.28000000","0.00089000"],["112467.98000000","0.00000000"],["112453.78000000","0.00000000"],["112436.97000000","0.00000000"],["112435.35000000","0.19191000"],["112422.01000000","0.00000000"],["112388.82000000","0.00000000"],["112388.81000000","0.00000000"],["112330.09000000","0.00000000"],["112309.60000000","0.00000000"],["112300.01000000","0.00567000"],["112292.48000000","0.00000000"],["110867.85000000","0.00100000"],["109333.01000000","0.00008000"],["109333.00000000","0.31187000"],["108955.00000000","0.00000000"],["108333.00000000","0.01142000"],["107899.00000000","0.00783000"],["107333.00000000","0.04612000"],["106899.00000000","0.00000000"],["106399.00000000","0.00155000"],["105899.00000000","0.00099000"],["101300.01000000","0.00000000"],["101300.00000000","1.33203000"],["90044.96000000","0.00022000"],["40520.23000000","0.00015000"]],"a":[["112556.21000000","0.93718000"],["112556.22000000","0.04485000"],["112556.54000000","0.00563000"],["112557.68000000","0.00000000"],["112557.69000000","0.00000000"],["112557.78000000","0.00000000"],["112557.79000000","0.00000000"],["112558.00000000","0.00175000"],["112558.01000000","0.00161000"],["112558.48000000","0.00000000"],["112558.49000000","0.00000000"],["112558.80000000","0.00010000"],["112558.81000000","0.04577000"],["112559.34000000","0.00898000"],["112559.80000000","0.00000000"],["112559.99000000","0.00010000"],["112560.00000000","0.02076000"],["112561.04000000","0.00721000"],["112561.20000000","0.00700000"],["112561.57000000","0.00000000"],["112562.00000000","0.00234000"],["112562.39000000","0.00010000"],["112562.40000000","0.05244000"],["112562.77000000","0.00005000"],["112562.78000000","0.03779000"],["112562.79000000","0.30000000"],["112563.24000000","0.00000000"],["112563.31000000","0.00000000"],["112565.09000000","0.00255000"],["112565.24000000","0.00000000"],["112565.33000000","0.00000000"],["112565.46000000","0.04000000"],["112566.59000000","0.00000000"],["112566.67000000","0.01930000"],["112567.56000000","0.00000000"],["112568.58000000","0.06748000"],["112568.78000000","0.00000000"],["112568.80000000","0.02666000"],["112569.00000000","0.12100000"],["112569.36000000","0.00331000"],["112569.55000000","0.00000000"],["112570.83000000","0.46938000"],["112571.16000000","0.00069000"],["112573.10000000","0.00000000"],["112574.45000000","0.01777000"],["112575.06000000","0.00000000"],["112575.28000000","0.00200000"],["112575.35000000","0.00600000"],["112575.39000000","0.03000000"],["112575.56000000","0.00000000"],["112576.65000000","0.00000000"],["112576.67000000","0.03300000"],["112578.28000000","0.00000000"],["112578.73000000","0.10640000"],["112579.86000000","0.00888000"],["112581.33000000","0.00000000"],["112586.53000000","0.26728000"],["112587.87000000","0.00000000"],["112588.72000000","0.26683000"],["112594.63000000","0.31968000"],["112603.62000000","0.00410000"],["112609.03000000","0.00006000"],["112613.58000000","0.00000000"],["112613.81000000","0.00000000"],["112619.98000000","0.00006000"],["112622.38000000","0.04392000"],["112623.30000000","0.00008000"],["112631.56000000","0.26728000"],["112632.97000000","0.00048000"],["112633.75000000","0.26683000"],["112633.90000000","0.00000000"],["112651.64000000","0.00000000"],["112652.42000000","0.03400000"],["112677.30000000","0.00000000"],["112678.59000000","0.00000000"],["112712.66000000","0.47523000"],["112716.20000000","0.13156000"],["112746.01000000","0.00019000"],["112832.64000000","0.00000000"],["112849.61000000","0.02398000"],["113556.53000000","0.04000000"],["114244.56000000","0.00100000"]]}
[2025-10-26T09:48:28.082Z] {"e":"depthUpdate","E":1761472107014,"s":"BTCUSDT","U":79058066178,"u":79058066402,"b":[["112556.20000000","2.73632000"],["112555.17000000","0.23325000"],["112555.14000000","0.00000000"],["112555.13000000","0.00000000"],["112555.08000000","0.00118000"],["112554.00000000","0.00005000"],["112553.25000000","0.00010000"],["112553.24000000","0.20481000"],["112551.75000000","0.00005000"],["112551.70000000","0.00360000"],["112551.57000000","0.17775000"],["112551.56000000","0.00260000"],["112550.57000000","0.08895000"],["112549.51000000","0.00000000"],["112549.50000000","0.00005000"],["112549.45000000","0.00538000"],["112547.86000000","0.02613000"],["112547.75000000","0.00000000"],["112547.02000000","0.29317000"],["112546.92000000","0.46938000"],["112545.28000000","0.00360000"],["112545.00000000","0.06105000"],["112543.10000000","0.01777000"],["112543.03000000","0.00000000"],["112542.54000000","0.00255000"],["112542.44000000","0.00000000"],["112542.13000000","0.22255000"],["112541.67000000","0.00000000"],["112541.51000000","0.00200000"],["112541.11000000","0.00000000"],["112540.22000000","0.00000000"],["112538.72000000","0.05185000"],["112538.53000000","0.00050000"],["112527.97000000","0.00000000"],["112527.60000000","0.01256000"],["112511.68000000","0.98605000"],["112398.99000000","0.06000000"],["110867.85000000","0.00100000"],["103545.80000000","0.00010000"],["101300.00000000","1.33203000"],["90045.00000000","0.03649000"],["90044.96000000","0.00022000"],["33000.00000000","3.78938000"]],"a":[["112556.21000000","0.94500000"],["112556.22000000","0.04485000"],["112556.48000000","0.00000000"],["112556.54000000","0.00005000"],["112558.00000000","0.00185000"],["112558.01000000","0.00166000"],["112558.41000000","0.06540000"],["112558.73000000","0.00315000"],["112560.00000000","0.02076000"],["112561.20000000","0.00700000"],["112561.44000000","0.00010000"],["112561.45000000","0.20476000"],["112562.40000000","0.05239000"],["112562.77000000","0.00000000"],["112562.78000000","0.03774000"],["112562.96000000","0.00533000"],["112565.09000000","0.00255000"],["112565.77000000","0.00391000"],["112567.46000000","0.00711000"],["112569.14000000","0.00161000"],["112574.45000000","0.00000000"],["112574.57000000","0.00000000"],["112574.59000000","0.00000000"],["112576.28000000","0.01777000"],["112583.13000000","0.00250000"],["112584.65000000","0.04480000"],["112587.64000000","0.00000000"],["112588.37000000","0.00000000"],["112589.75000000","0.97599000"],["112603.62000000","0.00000000"],["112603.96000000","0.00450000"],["112630.00000000","0.36160000"],["112640.00000000","0.01989000"],["112645.21000000","0.00100000"],["112645.22000000","0.00100000"],["112779.00000000","0.00026000"],["114244.56000000","0.00100000"]]}
[2025-10-26T09:48:29.070Z] {"e":"depthUpdate","E":1761472108014,"s":"BTCUSDT","U":79058066403,"u":79058066881,"b":[["112556.20000000","4.37509000"],["112556.19000000","0.00010000"],["112555.57000000","0.00000000"],["112555.18000000","0.00000000"],["112555.17000000","0.00000000"],["112555.08000000","0.00118000"],["112553.39000000","0.00010000"],["112553.38000000","0.21174000"],["112553.37000000","0.20486000"],["112553.25000000","0.00000000"],["112553.24000000","0.00000000"],["112552.87000000","0.00005000"],["112551.75000000","0.00000000"],["112551.70000000","0.00360000"],["112551.59000000","0.00000000"],["112551.58000000","0.00000000"],["112551.57000000","0.00000000"],["112551.56000000","0.00010000"],["112550.58000000","0.00010000"],["112550.57000000","0.08895000"],["112550.30000000","0.00010000"],["112550.29000000","0.29326000"],["112549.79000000","0.00010000"],["112549.78000000","0.11141000"],["112549.50000000","0.00000000"],["112547.88000000","0.00000000"],["112547.86000000","0.02613000"],["112547.24000000","0.00000000"],["112547.02000000","0.00000000"],["112546.93000000","0.00000000"],["112546.92000000","0.46943000"],["112545.00000000","0.06100000"],["112544.96000000","0.56891000"],["112544.68000000","0.00000000"],["112544.50000000","0.00007000"],["112543.10000000","0.00000000"],["112542.99000000","0.00000000"],["112542.54000000","0.00255000"],["112541.51000000","0.00210000"],["112540.91000000","0.01777000"],["112540.34000000","0.04414000"],["112539.32000000","0.00088000"],["112538.72000000","0.00000000"],["112535.11000000","0.05225000"],["112531.86000000","0.00005000"],["112529.18000000","0.04000000"],["112529.01000000","0.00250000"],["112522.44000000","0.04449000"],["112518.30000000","0.31990000"],["112517.78000000","0.00000000"],["112512.69000000","0.31991000"],["112512.48000000","0.00000000"],["112499.39000000","0.00000000"],["112482.01000000","0.00000000"],["112480.00000000","0.36145000"],["112467.76000000","0.02984000"],["112450.16000000","0.00000000"],["112443.75000000","0.02359000"],["112383.01000000","0.00000000"],["112296.89000000","0.00000000"],["110867.85000000","0.00100000"],["110000.00000000","17.38689000"],["103545.80000000","0.00000000"],["101300.00000000","1.33203000"],["90044.96000000","0.00022000"],["40520.23000000","0.00030000"]],"a":[["112556.21000000","0.49591000"],["112556.22000000","0.04475000"],["112556.29000000","0.00010000"],["112556.58000000","0.00000000"],["112557.59000000","0.00000000"],["112558.01000000","0.00166000"],["112558.39000000","0.00000000"],["112558.40000000","0.00000000"],["112558.41000000","0.13470000"],["112558.73000000","0.00315000"],["112558.80000000","0.00000000"],["112558.81000000","0.00000000"],["112559.32000000","0.00010000"],["112559.33000000","0.01032000"],["112560.00000000","0.02076000"],["112561.20000000","0.00700000"],["112561.44000000","0.00000000"],["112561.45000000","0.00000000"],["112561.51000000","0.00000000"],["112561.52000000","0.00000000"],["112562.39000000","0.00010000"],["112562.40000000","0.05244000"],["112562.77000000","0.00005000"],["112562.78000000","0.03779000"],["112562.79000000","0.30005000"],["112563.06000000","0.20466000"],["112564.66000000","0.00000000"],["112565.09000000","0.00255000"],["112565.46000000","0.04005000"],["112566.08000000","0.04567000"],["112569.00000000","0.06000000"],["112570.82000000","0.00000000"],["112571.39000000","0.00000000"],["112573.10000000","0.10640000"],["112573.24000000","0.01777000"],["112574.67000000","0.00037000"],["112575.06000000","0.00000000"],["112575.91000000","0.00444000"],["112576.09000000","0.00000000"],["112576.28000000","0.00000000"],["112577.42000000","0.26683000"],["112578.73000000","0.00000000"],["112580.14000000","0.00767000"],["112580.25000000","0.00033000"],["112583.63000000","0.04480000"],["112584.65000000","0.00000000"],["112588.72000000","0.00000000"],["112591.17000000","0.04450000"],["112594.63000000","0.00000000"],["112595.87000000","0.31968000"],["112606.88000000","0.00000000"],["112619.79000000","0.03460000"],["112620.00000000","0.23702000"],["112622.53000000","0.26683000"],["112628.95000000","0.00000000"],["112633.75000000","0.00000000"],["112640.00000000","0.10989000"],["112645.21000000","0.00000000"],["112645.22000000","0.00000000"],["112647.30000000","0.00000000"],["112652.42000000","0.00000000"],["112652.47000000","0.00007000"],["112653.42000000","0.03400000"],["112708.96000000","0.47523000"],["112712.66000000","0.00000000"],["112726.95000000","0.01849000"],["112770.76000000","0.88825000"],["112791.12000000","0.00000000"],["112963.52000000","0.00000000"],["114244.56000000","0.00100000"]]}
[2025-10-26T09:48:30.095Z] {"e":"depthUpdate","E":1761472109014,"s":"BTCUSDT","U":79058066882,"u":79058067771,"b":[["112556.53000000","6.58509000"],["112556.52000000","0.00020000"],["112556.45000000","0.00010000"],["112556.32000000","0.00000000"],["112556.30000000","0.29211000"],["112556.29000000","0.19930000"],["112556.28000000","0.00000000"],["112556.24000000","0.00000000"],["112556.22000000","0.00000000"],["112556.21000000","0.00000000"],["112556.20000000","0.08915000"],["112556.19000000","0.00000000"],["112556.13000000","0.00000000"],["112556.07000000","0.00255000"],["112555.12000000","0.00005000"],["112555.08000000","0.00098000"],["112553.42000000","0.00000000"],["112553.39000000","0.00000000"],["112553.38000000","0.00000000"],["112553.37000000","0.20471000"],["112551.71000000","0.00000000"],["112551.70000000","0.00360000"],["112551.56000000","0.00255000"],["112550.98000000","0.46943000"],["112550.70000000","0.00000000"],["112550.58000000","0.00000000"],["112550.57000000","0.22255000"],["112550.30000000","0.00000000"],["112550.29000000","0.00000000"],["112549.79000000","0.00000000"],["112549.78000000","0.00000000"],["112547.87000000","0.48267000"],["112547.86000000","0.02618000"],["112547.35000000","0.01777000"],["112547.05000000","0.00255000"],["112547.02000000","0.06748000"],["112546.92000000","0.46938000"],["112545.00000000","0.06105000"],["112544.96000000","0.56891000"],["112543.42000000","0.00000000"],["112542.90000000","0.03723000"],["112542.13000000","0.00000000"],["112541.51000000","0.00205000"],["112541.11000000","0.09317000"],["112540.91000000","0.00000000"],["112540.34000000","0.04414000"],["112539.75000000","0.00000000"],["112539.41000000","0.00043000"],["112533.52000000","0.00000000"],["112532.34000000","0.02666000"],["112529.99000000","0.03600000"],["112529.77000000","0.00043000"],["112529.01000000","0.00000000"],["112525.34000000","0.00000000"],["112523.88000000","0.31988000"],["112522.44000000","0.00000000"],["112515.86000000","0.00274000"],["112514.94000000","0.21540000"],["112514.61000000","0.00000000"],["112513.06000000","0.00012000"],["112511.68000000","0.00000000"],["112511.17000000","0.00005000"],["112501.36000000","0.00000000"],["112498.34000000","0.00000000"],["112495.19000000","0.00000000"],["112493.78000000","0.02224000"],["112490.00000000","0.00120000"],["112488.67000000","0.02984000"],["112484.64000000","0.00627000"],["112474.90000000","0.00000000"],["112470.00000000","0.09140000"],["112467.79000000","0.00000000"],["112467.76000000","0.00000000"],["112448.76000000","0.00533000"],["112436.97000000","0.01391000"],["112403.08000000","0.06000000"],["112390.22000000","0.00304000"],["112387.39000000","0.01784000"],["112378.36000000","0.00000000"],["112363.14000000","0.04463000"],["112348.21000000","0.01391000"],["112346.28000000","0.00000000"],["112342.01000000","0.00000000"],["112303.21000000","4.80802000"],["112288.04000000","0.00000000"],["112204.89000000","0.02398000"],["112130.54000000","0.00000000"],["112109.63000000","0.00000000"],["110868.18000000","0.00100000"],["110867.85000000","0.00000000"],["101300.00000000","1.33203000"],["90045.23000000","0.00022000"],["90044.96000000","0.00000000"],["80000.00000000","47.88654000"],["40520.23000000","0.00045000"]],"a":[["112556.21000000","0.00000000"],["112556.22000000","0.00000000"],["112556.29000000","0.00000000"],["112556.54000000","0.05393000"],["112556.55000000","0.00065000"],["112556.72000000","0.00000000"],["112556.74000000","0.00017000"],["112556.95000000","0.00000000"],["112557.19000000","0.00010000"],["112558.00000000","0.00185000"],["112558.01000000","0.00166000"],["112558.02000000","0.00000000"],["112558.07000000","0.00010000"],["112558.40000000","0.00000000"],["112558.41000000","0.00000000"],["112558.73000000","0.00310000"],["112559.01000000","0.00047000"],["112559.32000000","0.00000000"],["112559.33000000","0.00010000"],["112560.00000000","0.02076000"],["112560.09000000","0.00000000"],["112561.20000000","0.00700000"],["112562.00000000","0.00229000"],["112562.39000000","0.00000000"],["112562.40000000","0.00005000"],["112562.77000000","0.00010000"],["112562.78000000","0.03794000"],["112562.79000000","0.30010000"],["112562.96000000","0.00538000"],["112563.06000000","0.00000000"],["112564.00000000","0.00165000"],["112564.42000000","0.00000000"],["112565.09000000","0.00000000"],["112565.14000000","0.00005000"],["112565.15000000","0.05173000"],["112565.46000000","0.00005000"],["112565.55000000","0.00000000"],["112565.77000000","0.00396000"],["112565.95000000","0.00000000"],["112566.00000000","0.00165000"],["112566.08000000","0.04572000"],["112566.67000000","0.00151000"],["112567.92000000","0.00000000"],["112568.17000000","0.00000000"],["112568.35000000","0.04000000"],["112568.58000000","0.00000000"],["112569.01000000","0.00034000"],["112569.02000000","0.00000000"],["112569.04000000","0.00000000"],["112569.43000000","0.01812000"],["112569.48000000","0.00000000"],["112570.18000000","0.20466000"],["112570.83000000","0.00000000"],["112573.24000000","0.00000000"],["112573.25000000","0.00000000"],["112573.32000000","0.00000000"],["112573.39000000","0.00000000"],["112573.45000000","0.00000000"],["112573.57000000","0.00000000"],["112573.82000000","0.00000000"],["112573.88000000","0.00000000"],["112573.95000000","0.00000000"],["112574.59000000","1.70701000"],["112574.60000000","0.00000000"],["112574.64000000","0.00000000"],["112574.71000000","0.00000000"],["112575.30000000","0.00000000"],["112575.49000000","0.00000000"],["112575.55000000","0.00000000"],["112576.15000000","0.00000000"],["112577.42000000","0.00000000"],["112577.52000000","0.46938000"],["112579.42000000","0.00000000"],["112579.48000000","0.00000000"],["112580.89000000","1.70701000"],["112581.09000000","0.46938000"],["112581.10000000","0.00000000"],["112581.66000000","0.00000000"],["112583.63000000","0.00000000"],["112584.25000000","0.00000000"],["112584.87000000","0.00000000"],["112587.65000000","0.00000000"],["112587.82000000","0.03398000"],["112589.52000000","0.26683000"],["112589.75000000","0.00000000"],["112589.99000000","0.00000000"],["112590.15000000","0.00005000"],["112591.17000000","0.00000000"],["112591.73000000","0.04480000"],["112592.15000000","0.00250000"],["112593.12000000","0.00000000"],["112596.91000000","0.00000000"],["112598.87000000","0.00000000"],["112599.99000000","0.00000000"],["112601.33000000","0.00000000"],["112601.66000000","0.00000000"],["112603.02000000","0.00000000"],["112603.96000000","0.00000000"],["112604.70000000","0.19237000"],["112606.08000000","0.15107000"],["112607.46000000","0.00000000"],["112608.23000000","0.00000000"],["112611.99000000","0.02487000"],["112613.55000000","0.00306000"],["112614.24000000","0.02487000"],["112617.24000000","0.02487000"],["112618.61000000","0.00000000"],["112619.41000000","0.02487000"],["112619.79000000","0.00000000"],["112620.00000000","0.39702000"],["112620.89000000","0.02487000"],["112622.38000000","0.00000000"],["112622.53000000","0.00000000"],["112623.07000000","0.00000000"],["112624.00000000","0.02647000"],["112625.63000000","0.00000000"],["112629.24000000","0.02211000"],["112630.00000000","0.20160000"],["112631.23000000","0.02487000"],["112631.90000000","0.06016000"],["112632.75000000","0.03460000"],["112634.55000000","0.71193000"],["112639.04000000","0.02487000"],["112639.74000000","0.00927000"],["112646.21000000","0.00000000"],["112646.22000000","0.00000000"],["112653.42000000","0.00000000"],["112653.47000000","0.03400000"],["112666.66000000","0.00454000"],["112677.09000000","0.00000000"],["112708.96000000","0.00000000"],["112716.20000000","0.00000000"],["112767.58000000","0.00000000"],["112779.47000000","0.00080000"],["112796.87000000","4.80946000"],["112800.00000000","4.06577000"],["112833.15000000","0.02398000"],["112835.01000000","0.00000000"],["112871.64000000","0.00000000"],["112873.44000000","0.00000000"],["112874.36000000","0.00000000"],["112874.77000000","0.00008000"],["112876.19000000","0.00000000"],["112888.67000000","0.00000000"],["112895.66000000","0.00000000"],["112895.80000000","0.00000000"],["112898.96000000","0.00000000"],["112905.18000000","0.02398000"],["112905.70000000","0.00000000"],["112907.37000000","0.02398000"],["112908.26000000","0.00000000"],["112908.29000000","0.02398000"],["112909.20000000","0.02398000"],["112910.12000000","0.02408000"],["112910.71000000","0.00000000"],["112919.16000000","0.02398000"],["112920.48000000","0.00010000"],["112929.45000000","0.02398000"],["112935.58000000","0.00000000"],["112938.75000000","0.02398000"],["112943.23000000","0.02398000"],["112944.64000000","0.02398000"],["112982.07000000","0.10821000"],["113000.00000000","27.30872000"],["113116.25000000","0.00072000"],["114244.56000000","0.00000000"]]}
[2025-10-26T09:48:31.070Z] {"e":"depthUpdate","E":1761472110014,"s":"BTCUSDT","U":79058067772,"u":79058070145,"b":[["112568.34000000","5.52002000"],["112568.28000000","0.00000000"],["112568.26000000","0.00010000"],["112567.99000000","0.00000000"],["112567.85000000","0.00000000"],["112567.84000000","0.00000000"],["112567.11000000","0.27401000"],["112567.10000000","0.29341000"],["112566.66000000","0.00000000"],["112566.37000000","0.00005000"],["112566.20000000","0.00020000"],["112566.08000000","0.00020000"],["112566.07000000","0.00000000"],["112565.99000000","0.00000000"],["112565.76000000","0.00000000"],["112565.45000000","0.00000000"],["112565.15000000","0.00000000"],["112565.14000000","0.00000000"],["112565.13000000","0.00000000"],["112565.09000000","0.00255000"],["112565.00000000","0.00000000"],["112564.97000000","0.00444000"],["112564.96000000","0.00000000"],["112564.93000000","0.00000000"],["112564.68000000","0.00005000"],["112564.67000000","0.00000000"],["112564.47000000","0.00000000"],["112564.45000000","0.00000000"],["112564.09000000","0.00000000"],["112564.00000000","0.04010000"],["112563.99000000","0.00000000"],["112563.86000000","0.00000000"],["112563.76000000","0.00000000"],["112563.72000000","0.46938000"],["112563.37000000","0.00000000"],["112563.34000000","0.00000000"],["112563.00000000","0.00005000"],["112562.95000000","0.00000000"],["112562.80000000","0.00000000"],["112562.78000000","0.14395000"],["112562.77000000","0.00000000"],["112562.76000000","0.00000000"],["112562.39000000","0.00000000"],["112562.37000000","0.00005000"],["112562.36000000","0.00000000"],["112562.35000000","0.00000000"],["112562.09000000","0.00000000"],["112562.02000000","0.00000000"],["112562.00000000","0.00000000"],["112561.99000000","0.00000000"],["112561.85000000","0.00000000"],["112561.58000000","0.00000000"],["112561.39000000","0.00000000"],["112561.34000000","0.00000000"],["112561.31000000","0.00000000"],["112561.22000000","0.04566000"],["112561.19000000","0.00000000"],["112561.03000000","0.00000000"],["112560.58000000","0.00250000"],["112560.43000000","0.00000000"],["112560.36000000","0.00000000"],["112560.09000000","0.00000000"],["112560.00000000","0.02472000"],["112559.99000000","0.00005000"],["112559.98000000","0.00005000"],["112559.81000000","0.00000000"],["112559.75000000","0.00005000"],["112559.58000000","0.00000000"],["112559.50000000","0.00005000"],["112559.34000000","0.02878000"],["112559.33000000","0.02878000"],["112559.32000000","0.02878000"],["112559.20000000","0.00005000"],["112559.19000000","0.02878000"],["112559.11000000","0.00000000"],["112559.04000000","1.12974000"],["112559.03000000","0.00000000"],["112559.01000000","0.00000000"],["112559.00000000","0.04000000"],["112558.78000000","0.00000000"],["112558.72000000","0.00000000"],["112558.43000000","0.00005000"],["112558.41000000","2.17639000"],["112558.10000000","0.00000000"],["112558.02000000","0.00000000"],["112558.01000000","0.00000000"],["112558.00000000","0.00000000"],["112557.99000000","0.04000000"],["112557.64000000","0.00000000"],["112557.52000000","0.00000000"],["112556.99000000","0.00000000"],["112556.90000000","0.00000000"],["112556.73000000","0.00000000"],["112556.64000000","0.00000000"],["112556.58000000","0.00000000"],["112556.56000000","0.00000000"],["112556.55000000","0.00000000"],["112556.54000000","0.29972000"],["112556.53000000","0.35500000"],["112556.52000000","0.00000000"],["112556.45000000","0.00000000"],["112556.30000000","0.00000000"],["112556.29000000","0.19865000"],["112556.22000000","0.04407000"],["112556.20000000","0.00034000"],["112556.07000000","0.00250000"],["112555.98000000","0.00000000"],["112555.76000000","0.00000000"],["112555.66000000","0.00007000"],["112555.28000000","0.00000000"],["112555.12000000","0.00000000"],["112554.29000000","0.00010000"],["112554.00000000","0.00000000"],["112553.71000000","0.16042000"],["112553.37000000","0.00000000"],["112553.30000000","0.00005000"],["112552.93000000","0.00035000"],["112552.87000000","0.00000000"],["112552.71000000","0.00000000"],["112552.19000000","0.03780000"],["112551.56000000","0.00250000"],["112551.49000000","0.00000000"],["112551.47000000","0.00000000"],["112551.46000000","0.00088000"],["112551.45000000","0.00152000"],["112551.22000000","0.00087000"],["112551.13000000","0.71772000"],["112551.12000000","1.70701000"],["112551.11000000","0.00000000"],["112550.98000000","0.46938000"],["112550.57000000","0.22255000"],["112549.77000000","0.00000000"],["112549.45000000","0.00533000"],["112549.32000000","0.01771000"],["112549.20000000","0.04000000"],["112548.69000000","0.26660000"],["112548.67000000","0.00010000"],["112548.63000000","0.00000000"],["112548.57000000","0.00044000"],["112548.39000000","0.00000000"],["112548.03000000","0.15120000"],["112547.90000000","0.00000000"],["112547.87000000","0.69127000"],["112547.86000000","0.00000000"],["112547.35000000","0.00000000"],["112547.20000000","0.15105000"],["112547.05000000","0.00250000"],["112546.57000000","0.26683000"],["112546.28000000","0.26728000"],["112545.80000000","0.00000000"],["112545.28000000","0.00355000"],["112545.00000000","0.06100000"],["112544.96000000","0.56863000"],["112544.70000000","0.15146000"],["112544.55000000","0.04162000"],["112544.16000000","0.15107000"],["112544.00000000","0.00000000"],["112543.88000000","0.00355000"],["112543.02000000","0.00005000"],["112543.01000000","0.00005000"],["112542.96000000","0.00000000"],["112542.90000000","0.00000000"],["112542.81000000","0.00043000"],["112542.54000000","0.00000000"],["112542.35000000","0.30000000"],["112541.76000000","0.00009000"],["112541.66000000","0.00009000"],["112541.58000000","0.00086000"],["112541.57000000","0.00000000"],["112541.51000000","0.00200000"],["112541.11000000","0.09317000"],["112540.34000000","0.00000000"],["112540.06000000","0.01256000"],["112539.43000000","0.00043000"],["112539.41000000","0.00000000"],["112539.40000000","0.08000000"],["112538.53000000","0.00000000"],["112538.04000000","0.00000000"],["112538.03000000","0.00000000"],["112537.75000000","0.00006000"],["112537.58000000","0.44628000"],["112536.92000000","0.00009000"],["112536.78000000","0.15146000"],["112536.48000000","0.31985000"],["112535.11000000","0.00000000"],["112534.94000000","0.00009000"],["112534.57000000","0.04449000"],["112534.05000000","0.00000000"],["112532.90000000","0.03598000"],["112532.51000000","0.00000000"],["112531.08000000","0.35608000"],["112530.87000000","0.31986000"],["112530.27000000","0.00000000"],["112529.77000000","0.00000000"],["112529.73000000","0.03000000"],["112529.18000000","0.00000000"],["112528.95000000","0.00088000"],["112527.60000000","0.00000000"],["112527.55000000","0.44510000"],["112527.24000000","0.00009000"],["112527.05000000","0.26677000"],["112526.76000000","0.00177000"],["112526.75000000","0.21530000"],["112525.04000000","0.00000000"],["112524.48000000","0.00449000"],["112524.13000000","0.00000000"],["112523.85000000","0.00000000"],["112523.75000000","0.00000000"],["112523.41000000","0.00059000"],["112523.15000000","0.00000000"],["112523.14000000","0.31989000"],["112522.96000000","0.00000000"],["112522.07000000","0.03778000"],["112521.56000000","0.24810000"],["112520.58000000","0.00000000"],["112519.02000000","0.00000000"],["112518.30000000","0.00000000"],["112518.29000000","0.00000000"],["112517.87000000","0.00000000"],["112517.04000000","0.03900000"],["112515.80000000","0.00000000"],["112515.37000000","0.00000000"],["112514.94000000","0.00000000"],["112514.59000000","0.00000000"],["112514.58000000","0.00000000"],["112514.02000000","0.00000000"],["112513.52000000","0.02984000"],["112512.69000000","0.00000000"],["112512.68000000","0.93134000"],["112511.53000000","0.22339000"],["112510.87000000","0.00000000"],["112509.88000000","0.00000000"],["112509.34000000","0.00000000"],["112507.05000000","0.00000000"],["112506.98000000","0.07631000"],["112505.56000000","0.00000000"],["112504.90000000","0.00000000"],["112504.59000000","0.00000000"],["112504.40000000","0.00000000"],["112502.51000000","0.00000000"],["112501.22000000","0.00010000"],["112500.91000000","0.00632000"],["112498.90000000","0.00632000"],["112495.50000000","0.00653000"],["112490.18000000","0.00089000"],["112490.01000000","0.00010000"],["112488.70000000","0.00007000"],["112488.67000000","0.00000000"],["112486.86000000","0.00000000"],["112486.73000000","0.86439000"],["112486.56000000","0.00000000"],["112484.55000000","0.00000000"],["112483.84000000","0.00000000"],["112483.07000000","0.00000000"],["112482.55000000","0.00000000"],["112482.52000000","0.00000000"],["112482.30000000","0.00000000"],["112481.46000000","0.44452000"],["112479.71000000","0.00000000"],["112479.68000000","0.02359000"],["112479.58000000","0.00000000"],["112479.24000000","0.00000000"],["112479.16000000","0.00000000"],["112478.30000000","0.44510000"],["112477.12000000","0.36068000"],["112477.00000000","0.00000000"],["112472.28000000","0.00000000"],["112471.30000000","0.00000000"],["112470.34000000","0.00000000"],["112467.81000000","0.00000000"],["112467.40000000","0.01688000"],["112466.60000000","0.00000000"],["112462.15000000","0.02798000"],["112462.01000000","0.00221000"],["112461.59000000","0.88907000"],["112461.48000000","0.00000000"],["112461.08000000","1.24118000"],["112459.94000000","0.09675000"],["112458.01000000","0.00399000"],["112455.99000000","0.00000000"],["112454.93000000","0.00000000"],["112453.74000000","0.00000000"],["112451.10000000","0.03991000"],["112450.54000000","0.22694000"],["112448.77000000","0.00220000"],["112447.18000000","0.06896000"],["112444.79000000","0.00000000"],["112444.01000000","0.03598000"],["112443.75000000","0.00000000"],["112443.38000000","0.00000000"],["112440.31000000","0.00000000"],["112438.40000000","0.00000000"],["112431.37000000","0.00000000"],["112430.60000000","0.00000000"],["112425.60000000","0.00000000"],["112419.31000000","0.06086000"],["112418.26000000","0.00000000"],["112418.14000000","0.00000000"],["112417.48000000","0.08772000"],["112413.51000000","0.00000000"],["112412.60000000","0.00000000"],["112411.56000000","0.00000000"],["112405.90000000","0.00000000"],["112405.32000000","0.00000000"],["112404.94000000","0.00000000"],["112402.34000000","0.08115000"],["112402.33000000","0.05556000"],["112400.22000000","0.00000000"],["112383.71000000","0.00000000"],["112383.51000000","0.00000000"],["112382.94000000","0.00000000"],["112380.01000000","0.00000000"],["112380.00000000","0.04503000"],["112378.85000000","0.00000000"],["112374.39000000","0.16294000"],["112363.14000000","0.06748000"],["112346.26000000","0.00000000"],["112342.68000000","0.00000000"],["112341.43000000","0.02399000"],["112340.02000000","0.00000000"],["112340.01000000","0.00000000"],["112337.86000000","0.00006000"],["112335.67000000","0.00000000"],["112334.01000000","0.00000000"],["112333.35000000","0.00000000"],["112333.34000000","0.00000000"],["112333.33000000","0.00017000"],["112332.46000000","0.00000000"],["112328.59000000","0.02399000"],["112324.29000000","0.00015000"],["112320.35000000","0.00011000"],["112320.00000000","0.00140000"],["112309.85000000","0.00012000"],["112309.44000000","0.99716000"],["112307.02000000","0.00567000"],["112300.30000000","0.20826000"],["112300.01000000","0.00000000"],["112288.10000000","0.03498000"],["112280.00000000","0.00014000"],["112279.46000000","0.00000000"],["112276.35000000","0.00000000"],["112276.34000000","0.00000000"],["112273.03000000","0.00005000"],["112270.97000000","0.00000000"],["112255.23000000","0.01688000"],["112251.44000000","1.11953000"],["112249.93000000","0.02398000"],["112243.46000000","0.02398000"],["112242.53000000","0.03498000"],["112241.88000000","0.03498000"],["112241.25000000","0.03498000"],["112240.95000000","0.03498000"],["112240.63000000","0.03498000"],["112240.00000000","1.35090000"],["112234.63000000","0.02399000"],["112228.20000000","0.02398000"],["112227.93000000","0.00000000"],["112224.84000000","0.00005000"],["112223.00000000","0.00000000"],["112222.78000000","0.00000000"],["112220.94000000","0.00017000"],["112216.92000000","0.01688000"],["112214.27000000","0.02398000"],["112213.52000000","0.00000000"],["112213.24000000","0.01688000"],["112210.29000000","0.00000000"],["112193.00000000","0.00000000"],["112192.91000000","0.00000000"],["112192.90000000","0.00000000"],["112192.23000000","0.00000000"],["112191.70000000","0.00000000"],["112153.17000000","0.00000000"],["112145.63000000","0.00000000"],["112144.76000000","0.00000000"],["112141.35000000","0.03198000"],["112139.08000000","0.00000000"],["112138.34000000","0.00000000"],["112137.89000000","0.02750000"],["112137.73000000","0.00000000"],["112137.59000000","0.00000000"],["112136.32000000","0.00000000"],["112134.43000000","0.00000000"],["112131.29000000","0.00000000"],["112128.17000000","0.00000000"],["112127.43000000","0.00000000"],["112113.48000000","0.00000000"],["112110.68000000","0.00000000"],["112109.92000000","0.00000000"],["112108.74000000","0.00000000"],["112104.18000000","0.00000000"],["112099.09000000","0.17647000"],["112049.43000000","0.00005000"],["112008.82000000","0.00000000"],["112003.46000000","0.00000000"],["111997.61000000","0.00008000"],["111988.67000000","0.00000000"],["111956.48000000","0.31559000"],["111906.19000000","0.32165000"],["111893.48000000","0.00000000"],["111823.00000000","0.00000000"],["111772.11000000","0.00154000"],["110879.81000000","0.00100000"],["110868.18000000","0.00000000"],["109333.01000000","0.00000000"],["101300.00000000","1.33203000"],["90054.68000000","0.00022000"],["90045.23000000","0.00000000"],["90045.00000000","0.03649000"],["78794.40000000","0.00000000"],["78790.46000000","0.00000000"],["56284.17000000","0.00020000"],["56198.78000000","0.00080000"],["42000.00000000","1.40412000"]],"a":[["112556.54000000","0.00000000"],["112556.55000000","0.00000000"],["112556.59000000","0.00000000"],["112556.65000000","0.00000000"],["112556.74000000","0.00000000"],["112557.00000000","0.00000000"],["112557.19000000","0.00000000"],["112557.52000000","0.00000000"],["112557.53000000","0.00000000"],["112558.00000000","0.00000000"],["112558.01000000","0.00000000"],["112558.07000000","0.00000000"],["112558.09000000","0.00000000"],["112558.42000000","0.00000000"],["112558.73000000","0.00000000"],["112559.01000000","0.00000000"],["112559.12000000","0.00000000"],["112559.20000000","0.00000000"],["112559.33000000","0.00000000"],["112559.34000000","0.00000000"],["112559.35000000","0.00000000"],["112559.51000000","0.00000000"],["112559.76000000","0.00000000"],["112559.99000000","0.00000000"],["112560.00000000","0.00000000"],["112560.44000000","0.00000000"],["112561.04000000","0.00000000"],["112561.20000000","0.00000000"],["112561.32000000","0.00000000"],["112561.35000000","0.00000000"],["112561.59000000","0.00000000"],["112561.86000000","0.00000000"],["112562.00000000","0.00000000"],["112562.36000000","0.00000000"],["112562.40000000","0.00000000"],["112562.77000000","0.00000000"],["112562.78000000","0.00000000"],["112562.79000000","0.00000000"],["112562.96000000","0.00000000"],["112563.35000000","0.00000000"],["112563.38000000","0.00000000"],["112563.58000000","0.00000000"],["112563.77000000","0.00000000"],["112563.87000000","0.00000000"],["112564.00000000","0.00000000"],["112564.46000000","0.00000000"],["112564.48000000","0.00000000"],["112564.68000000","0.00000000"],["112564.94000000","0.00000000"],["112565.01000000","0.00000000"],["112565.14000000","0.00000000"],["112565.15000000","0.00000000"],["112565.34000000","0.00000000"],["112565.38000000","0.00000000"],["112565.46000000","0.00000000"],["112565.77000000","0.00000000"],["112566.00000000","0.00000000"],["112566.08000000","0.00000000"],["112566.30000000","0.00000000"],["112566.66000000","0.00000000"],["112566.67000000","0.00000000"],["112566.70000000","0.00000000"],["112567.46000000","0.00000000"],["112567.85000000","0.00000000"],["112568.00000000","0.00000000"],["112568.29000000","0.00000000"],["112568.35000000","0.00489000"],["112568.36000000","0.00065000"],["112568.54000000","0.00013000"],["112568.55000000","0.00024000"],["112568.79000000","0.00005000"],["112568.80000000","0.00020000"],["112568.84000000","0.00010000"],["112568.99000000","0.00000000"],["112569.00000000","0.00000000"],["112569.01000000","0.00044000"],["112569.07000000","0.00000000"],["112569.14000000","0.00000000"],["112569.15000000","0.00044000"],["112569.26000000","0.00000000"],["112569.36000000","0.00000000"],["112569.39000000","0.00000000"],["112569.42000000","0.00000000"],["112569.43000000","0.00000000"],["112569.60000000","0.00005000"],["112570.00000000","0.00160000"],["112570.17000000","0.00000000"],["112570.18000000","0.00000000"],["112570.60000000","0.00000000"],["112570.61000000","0.00000000"],["112570.83000000","0.00000000"],["112570.84000000","0.00000000"],["112570.85000000","0.00000000"],["112570.86000000","0.00000000"],["112570.96000000","0.00000000"],["112571.16000000","0.00000000"],["112571.26000000","0.00000000"],["112571.95000000","0.00221000"],["112572.66000000","0.00000000"],["112573.09000000","0.00000000"],["112573.10000000","0.00000000"],["112573.38000000","0.00000000"],["112573.48000000","0.00000000"],["112573.86000000","0.00000000"],["112574.11000000","0.00000000"],["112574.26000000","0.00005000"],["112574.45000000","0.00000000"],["112574.46000000","0.00000000"],["112574.54000000","0.00000000"],["112574.59000000","0.00000000"],["112574.86000000","0.00000000"],["112574.95000000","0.00000000"],["112575.28000000","0.00000000"],["112575.35000000","0.00000000"],["112575.39000000","0.00000000"],["112575.45000000","0.00151000"],["112575.89000000","0.28799000"],["112575.90000000","0.05175000"],["112575.91000000","0.00000000"],["112575.92000000","0.00000000"],["112576.42000000","0.00000000"],["112576.67000000","0.00000000"],["112577.52000000","0.00000000"],["112577.53000000","0.00000000"],["112577.54000000","0.00000000"],["112577.91000000","0.00000000"],["112577.92000000","0.00000000"],["112577.95000000","0.00000000"],["112578.27000000","0.00000000"],["112578.62000000","0.00000000"],["112578.63000000","0.00000000"],["112578.73000000","0.00000000"],["112579.13000000","0.00711000"],["112579.20000000","0.00000000"],["112579.35000000","0.00000000"],["112579.61000000","0.00152000"],["112579.85000000","0.24807000"],["112579.95000000","0.00000000"],["112580.00000000","0.01942000"],["112580.18000000","0.01811000"],["112580.70000000","0.00000000"],["112580.89000000","0.00000000"],["112580.90000000","0.00000000"],["112581.09000000","0.00000000"],["112581.40000000","0.03000000"],["112581.42000000","0.00069000"],["112581.59000000","0.03000000"],["112581.99000000","0.00000000"],["112582.09000000","0.00000000"],["112582.39000000","0.00000000"],["112582.43000000","0.00006000"],["112582.49000000","0.00000000"],["112582.50000000","0.03000000"],["112582.62000000","0.00000000"],["112582.63000000","0.00070000"],["112582.78000000","0.00000000"],["112582.98000000","0.08291000"],["112583.37000000","0.00073000"],["112583.55000000","0.00000000"],["112584.18000000","1.70701000"],["112584.19000000","0.30000000"],["112584.36000000","0.00000000"],["112584.61000000","0.00000000"],["112584.64000000","0.00009000"],["112584.69000000","0.00000000"],["112584.76000000","0.00070000"],["112585.18000000","0.00039000"],["112585.22000000","0.00000000"],["112585.23000000","0.00088000"],["112585.24000000","0.00151000"],["112585.49000000","0.00000000"],["112585.76000000","0.00331000"],["112585.78000000","0.00039000"],["112585.87000000","0.00000000"],["112586.53000000","0.00000000"],["112586.54000000","0.00000000"],["112586.55000000","0.00000000"],["112586.85000000","0.03600000"],["112587.27000000","0.00000000"],["112587.64000000","0.00250000"],["112587.82000000","0.00000000"],["112587.95000000","0.00000000"],["112588.00000000","0.05760000"],["112588.02000000","0.03000000"],["112588.03000000","0.00000000"],["112588.38000000","0.00000000"],["112588.89000000","0.00000000"],["112589.03000000","0.46938000"],["112589.04000000","0.00000000"],["112589.52000000","0.00000000"],["112589.53000000","0.00000000"],["112589.88000000","0.00033000"],["112589.99000000","1.70701000"],["112590.00000000","0.00168000"],["112590.16000000","0.00000000"],["112590.31000000","0.00300000"],["112590.46000000","0.00037000"],["112591.41000000","0.00000000"],["112591.46000000","0.00000000"],["112591.47000000","0.00000000"],["112591.73000000","0.00000000"],["112591.99000000","0.00444000"],["112592.06000000","0.00000000"],["112592.15000000","0.00250000"],["112592.58000000","0.29971000"],["112592.72000000","0.04042000"],["112593.00000000","0.00000000"],["112593.13000000","0.00000000"],["112593.27000000","0.00000000"],["112593.37000000","0.00447000"],["112593.53000000","0.46938000"],["112593.54000000","0.00000000"],["112593.55000000","0.00000000"],["112594.13000000","0.00000000"],["112594.52000000","0.00024000"],["112595.87000000","0.00000000"],["112596.66000000","0.00250000"],["112596.91000000","0.02398000"],["112597.78000000","0.00000000"],["112597.93000000","0.00272000"],["112600.07000000","0.00000000"],["112600.22000000","0.00000000"],["112601.17000000","0.00250000"],["112601.44000000","0.15146000"],["112601.55000000","0.26728000"],["112601.91000000","0.26683000"],["112602.13000000","0.10640000"],["112603.01000000","0.00000000"],["112603.75000000","0.04480000"],["112604.70000000","0.00000000"],["112605.48000000","0.04450000"],["112605.69000000","0.04896000"],["112605.70000000","0.00000000"],["112605.94000000","0.26660000"],["112606.26000000","0.22719000"],["112606.37000000","0.00000000"],["112606.68000000","0.07772000"],["112606.73000000","0.00000000"],["112606.86000000","0.00000000"],["112607.73000000","0.03198000"],["112607.74000000","0.00282000"],["112607.82000000","0.00000000"],["112608.13000000","0.00000000"],["112608.75000000","0.35608000"],["112608.84000000","0.44510000"],["112609.03000000","0.03498000"],["112609.48000000","0.01800000"],["112609.74000000","0.00000000"],["112609.95000000","0.43060000"],["112610.05000000","0.00000000"],["112610.21000000","0.00000000"],["112610.36000000","0.21056000"],["112610.51000000","0.44452000"],["112610.54000000","0.00064000"],["112611.29000000","0.00000000"],["112611.41000000","0.15094000"],["112612.36000000","0.19410000"],["112613.54000000","0.03376000"],["112614.00000000","0.00165000"],["112615.05000000","0.15133000"],["112615.60000000","0.15146000"],["112615.84000000","0.03778000"],["112616.19000000","0.93744000"],["112616.95000000","0.00005000"],["112618.82000000","0.26677000"],["112619.00000000","0.00088000"],["112619.45000000","0.34116000"],["112619.48000000","0.00005000"],["112619.98000000","0.00000000"],["112620.00000000","0.19702000"],["112620.72000000","0.00000000"],["112620.73000000","0.03770000"],["112620.84000000","0.08000000"],["112621.11000000","0.00063000"],["112621.97000000","0.00000000"],["112623.08000000","0.18777000"],["112623.24000000","0.00000000"],["112623.68000000","0.02935000"],["112623.98000000","0.00000000"],["112624.25000000","0.00000000"],["112624.99000000","0.02398000"],["112625.62000000","0.00000000"],["112630.00000000","0.00160000"],["112630.96000000","0.04224000"],["112631.56000000","0.00000000"],["112631.77000000","0.00000000"],["112631.90000000","0.05400000"],["112632.30000000","0.00005000"],["112632.44000000","0.36018000"],["112632.75000000","0.00000000"],["112632.97000000","0.00000000"],["112632.98000000","0.00000000"],["112633.11000000","0.23717000"],["112634.55000000","0.00000000"],["112634.84000000","0.00000000"],["112634.85000000","0.00000000"],["112635.84000000","0.08000000"],["112636.46000000","0.00000000"],["112636.57000000","0.15133000"],["112636.84000000","0.00621000"],["112637.53000000","0.00000000"],["112637.55000000","0.00000000"],["112637.60000000","0.00000000"],["112637.73000000","0.00010000"],["112639.05000000","0.02487000"],["112639.15000000","0.00000000"],["112639.63000000","0.00630000"],["112639.73000000","0.00000000"],["112640.00000000","0.01989000"],["112640.19000000","0.00664000"],["112642.44000000","0.46938000"],["112642.94000000","0.00000000"],["112643.21000000","0.00000000"],["112645.71000000","0.00000000"],["112646.59000000","0.26728000"],["112646.95000000","0.26683000"],["112647.21000000","0.00000000"],["112647.22000000","0.00000000"],["112647.89000000","0.00000000"],["112648.98000000","0.46938000"],["112648.99000000","0.00000000"],["112649.46000000","0.00000000"],["112649.51000000","0.00000000"],["112650.98000000","0.26660000"],["112653.47000000","0.00000000"],["112653.74000000","0.46938000"],["112654.68000000","0.34960000"],["112655.47000000","0.00000000"],["112656.42000000","0.00000000"],["112657.18000000","0.04091000"],["112657.37000000","0.03000000"],["112657.42000000","0.00000000"],["112658.62000000","0.02487000"],["112658.94000000","0.00533000"],["112660.37000000","0.00000000"],["112660.38000000","0.00000000"],["112661.38000000","0.00000000"],["112661.43000000","0.00000000"],["112662.43000000","0.00000000"],["112663.43000000","0.00000000"],["112663.48000000","0.00000000"],["112664.48000000","0.00000000"],["112665.13000000","0.44510000"],["112665.43000000","0.00000000"],["112665.88000000","0.00000000"],["112666.43000000","0.00000000"],["112666.57000000","0.00399000"],["112666.80000000","0.44452000"],["112667.26000000","0.00000000"],["112667.59000000","0.04680000"],["112667.77000000","0.35608000"],["112669.43000000","0.00000000"],["112670.53000000","0.00399000"],["112670.65000000","0.00000000"],["112671.93000000","0.00000000"],["112672.31000000","0.00399000"],["112673.66000000","0.01258000"],["112674.98000000","0.00007000"],["112677.04000000","0.00000000"],["112678.94000000","0.00000000"],["112679.37000000","0.00000000"],["112680.00000000","0.02013000"],["112681.24000000","0.00000000"],["112681.97000000","0.00000000"],["112682.13000000","0.00000000"],["112683.85000000","0.00000000"],["112684.56000000","0.00000000"],["112685.50000000","0.00000000"],["112685.72000000","0.03000000"],["112688.31000000","0.00000000"],["112693.52000000","0.00000000"],["112697.63000000","0.00000000"],["112698.31000000","0.00006000"],["112698.59000000","1.70701000"],["112699.92000000","0.00444000"],["112700.12000000","0.00532000"],["112700.34000000","0.00444000"],["112700.39000000","0.00444000"],["112702.04000000","0.09666000"],["112710.86000000","0.07262000"],["112711.36000000","0.08830000"],["112714.63000000","0.09675000"],["112715.59000000","0.00000000"],["112715.73000000","0.00000000"],["112721.11000000","0.01848000"],["112721.44000000","0.02398000"],["112723.05000000","0.00000000"],["112725.99000000","0.00000000"],["112726.74000000","0.00000000"],["112726.95000000","0.00000000"],["112729.36000000","0.00000000"],["112734.84000000","0.00000000"],["112734.89000000","0.00000000"],["112737.20000000","0.00009000"],["112740.93000000","0.00000000"],["112744.41000000","0.00000000"],["112744.68000000","0.00000000"],["112745.52000000","0.02398000"],["112746.01000000","0.00000000"],["112747.92000000","0.01695000"],["112749.30000000","0.00000000"],["112749.98000000","0.00006000"],["112751.78000000","0.00000000"],["112751.90000000","0.00000000"],["112752.47000000","0.00000000"],["112752.48000000","0.02398000"],["112752.96000000","0.00000000"],["112753.05000000","0.00000000"],["112753.61000000","0.00000000"],["112754.66000000","0.00000000"],["112754.92000000","0.00000000"],["112755.39000000","0.00000000"],["112756.01000000","0.00000000"],["112756.27000000","0.00000000"],["112756.91000000","0.00000000"],["112757.64000000","0.02666000"],["112757.72000000","0.00000000"],["112757.94000000","0.00000000"],["112758.38000000","0.00000000"],["112758.75000000","0.00000000"],["112760.75000000","0.00000000"],["112762.19000000","0.00000000"],["112763.30000000","0.00000000"],["112770.75000000","0.00000000"],["112771.80000000","0.00005000"],["112777.47000000","0.01848000"],["112778.80000000","0.02398000"],["112782.04000000","0.01776000"],["112782.32000000","0.00000000"],["112783.76000000","0.03598000"],["112784.49000000","0.03598000"],["112785.29000000","0.00000000"],["112785.59000000","0.03598000"],["112786.62000000","0.03598000"],["112787.41000000","0.03598000"],["112788.61000000","0.03611000"],["112789.88000000","0.03598000"],["112791.21000000","0.03937000"],["112791.84000000","0.00000000"],["112792.32000000","0.03598000"],["112793.49000000","0.04000000"],["112794.95000000","0.02890000"],["112795.42000000","0.01776000"],["112798.23000000","0.03598000"],["112799.80000000","0.03598000"],["112801.03000000","0.03598000"],["112801.43000000","0.03598000"],["112802.03000000","0.03598000"],["112802.87000000","0.03608000"],["112805.29000000","0.00000000"],["112805.33000000","0.03598000"],["112806.76000000","0.00000000"],["112807.34000000","0.00000000"],["112807.35000000","0.01776000"],["112808.23000000","0.03598000"],["112808.87000000","0.02398000"],["112810.33000000","0.01776000"],["112818.82000000","0.00000000"],["112819.71000000","0.00000000"],["112820.40000000","0.00000000"],["112822.09000000","0.00000000"],["112822.20000000","0.00000000"],["112823.13000000","0.02398000"],["112825.01000000","0.00000000"],["112825.03000000","0.00000000"],["112826.95000000","0.88619000"],["112829.23000000","0.00000000"],["112829.56000000","0.00000000"],["112830.94000000","0.01688000"],["112832.10000000","0.00000000"],["112832.99000000","0.01688000"],["112833.83000000","0.01848000"],["112837.21000000","0.02398000"],["112839.96000000","0.00000000"],["112841.65000000","0.24292000"],["112843.31000000","0.01688000"],["112848.82000000","0.00000000"],["112850.84000000","0.02398000"],["112853.69000000","0.02498000"],["112853.79000000","0.00000000"],["112854.35000000","0.02498000"],["112854.39000000","0.02498000"],["112854.51000000","0.02506000"],["112854.81000000","0.02498000"],["112854.89000000","0.02498000"],["112856.54000000","0.02416000"],["112857.64000000","0.02398000"],["112857.76000000","0.00000000"],["112861.15000000","0.00000000"],["112871.07000000","0.00000000"],["112874.48000000","0.01688000"],["112875.70000000","0.00000000"],["112877.19000000","0.00000000"],["112878.23000000","0.00000000"],["112879.37000000","0.01726000"],["112879.61000000","0.00000000"],["112880.23000000","0.00000000"],["112880.78000000","0.00000000"],["112880.92000000","0.00000000"],["112881.48000000","0.00000000"],["112881.99000000","0.00000000"],["112883.42000000","0.01688000"],["112886.82000000","0.01688000"],["112890.42000000","0.00000000"],["112891.64000000","0.00000000"],["112892.72000000","0.00000000"],["112893.43000000","0.00000000"],["112894.09000000","0.00000000"],["112898.72000000","0.02398000"],["112899.00000000","0.03692000"],["112899.28000000","0.00000000"],["112899.39000000","0.02398000"],["112899.72000000","0.00000000"],["112900.21000000","0.02398000"],["112901.23000000","0.00000000"],["112901.33000000","0.02398000"],["112903.00000000","0.02398000"],["112904.43000000","0.02403000"],["112905.08000000","0.02398000"],["112905.61000000","0.02398000"],["112906.23000000","0.00000000"],["112910.12000000","0.00010000"],["112910.62000000","0.00000000"],["112911.07000000","0.00000000"],["112920.99000000","0.00000000"],["112921.61000000","0.00000000"],["112922.80000000","0.00000000"],["112924.09000000","0.00000000"],["112924.31000000","0.00000000"],["112925.01000000","0.00000000"],["112925.64000000","0.00034000"],["112925.95000000","0.00000000"],["112926.36000000","0.00000000"],["112926.95000000","0.00000000"],["112927.86000000","0.02398000"],["112929.17000000","0.00000000"],["112929.83000000","0.02398000"],["112930.15000000","0.02398000"],["112930.61000000","0.02398000"],["112931.06000000","0.02398000"],["112931.98000000","0.02398000"],["112932.05000000","0.00010000"],["112936.87000000","0.00010000"],["112942.49000000","0.00010000"],["112945.36000000","0.00000000"],["112948.11000000","0.00010000"],["112951.32000000","0.02961000"],["112953.73000000","0.00000000"],["112953.88000000","0.03498000"],["112954.25000000","0.03498000"],["112954.68000000","0.03498000"],["112955.23000000","0.03498000"],["112956.80000000","0.00000000"],["112957.94000000","0.00000000"],["112957.97000000","0.00000000"],["112958.48000000","0.03498000"],["112959.23000000","0.03506000"],["112960.35000000","0.03503000"],["112961.30000000","0.03498000"],["112962.53000000","0.03498000"],["112963.52000000","0.31500000"],["112965.10000000","0.02398000"],["112966.47000000","0.02398000"],["112976.24000000","0.03498000"],["112978.04000000","0.03498000"],["112979.01000000","0.00000000"],["112979.81000000","0.00000000"],["112979.92000000","0.03498000"],["112980.65000000","0.00000000"],["112981.00000000","0.00041000"],["112988.11000000","0.00000000"],["112988.50000000","0.00000000"],["112988.69000000","0.00000000"],["112989.49000000","0.00014000"],["113070.69000000","0.00000000"],["113072.17000000","0.00006000"],["113074.09000000","0.00000000"],["113074.14000000","0.00000000"],["113074.93000000","0.00000000"],["113075.03000000","0.00000000"],["113075.57000000","0.00000000"],["113075.62000000","0.00000000"],["113075.64000000","0.00000000"],["113075.65000000","0.00000000"],["113077.12000000","0.00338000"],["113078.22000000","0.00000000"],["113080.60000000","0.00000000"],["113099.80000000","0.03198000"],["113101.19000000","0.03198000"],["113102.65000000","0.03198000"],["113104.03000000","0.03198000"],["113105.10000000","0.03198000"],["113105.79000000","0.03198000"],["113106.51000000","0.00000000"],["113107.05000000","0.00000000"],["113107.64000000","0.00000000"],["113108.35000000","0.00000000"],["113109.79000000","0.03198000"],["113121.35000000","0.03198000"],["113125.39000000","0.03198000"],["113126.33000000","0.03216000"],["113126.55000000","0.03198000"],["113127.10000000","0.03198000"],["114244.89000000","0.00172000"]]}
[2025-10-26T09:48:32.063Z] {"e":"depthUpdate","E":1761472111014,"s":"BTCUSDT","U":79058070146,"u":79058073744,"b":[["112596.24000000","1.45627000"],["112596.23000000","0.00000000"],["112596.17000000","0.00010000"],["112593.84000000","0.00000000"],["112593.83000000","0.00005000"],["112593.42000000","0.00000000"],["112593.40000000","0.00000000"],["112593.39000000","0.00000000"],["112593.36000000","0.00000000"],["112593.34000000","0.00000000"],["112593.33000000","0.00000000"],["112592.08000000","0.00005000"],["112591.87000000","0.04710000"],["112590.92000000","0.00000000"],["112590.85000000","0.00000000"],["112590.83000000","0.00000000"],["112590.82000000","0.00000000"],["112590.33000000","0.00000000"],["112590.31000000","0.00000000"],["112590.30000000","0.00000000"],["112589.90000000","0.00000000"],["112589.87000000","0.00000000"],["112589.30000000","0.00000000"],["112587.99000000","0.00000000"],["112587.79000000","0.00010000"],["112587.78000000","0.00030000"],["112587.14000000","0.00000000"],["112586.60000000","0.00005000"],["112585.99000000","0.00000000"],["112585.87000000","0.00010000"],["112585.86000000","0.26627000"],["112585.85000000","0.29321000"],["112585.60000000","0.00000000"],["112585.59000000","0.00000000"],["112585.45000000","0.00000000"],["112585.44000000","0.00000000"],["112585.23000000","0.00000000"],["112585.21000000","0.00000000"],["112585.20000000","0.00000000"],["112584.98000000","0.00305000"],["112584.58000000","0.00010000"],["112584.57000000","0.20471000"],["112584.56000000","0.00000000"],["112584.10000000","0.00010000"],["112584.09000000","0.00005000"],["112583.99000000","0.00000000"],["112583.63000000","0.00000000"],["112583.62000000","0.09613000"],["112583.55000000","0.00000000"],["112583.22000000","0.00000000"],["112583.13000000","0.00000000"],["112582.80000000","0.00000000"],["112582.38000000","0.00000000"],["112582.18000000","0.00010000"],["112582.15000000","0.22255000"],["112581.99000000","0.00000000"],["112581.65000000","0.00000000"],["112581.12000000","0.00005000"],["112580.16000000","0.00000000"],["112580.13000000","0.00000000"],["112580.02000000","0.00000000"],["112580.00000000","0.00005000"],["112579.99000000","0.00000000"],["112579.98000000","0.00000000"],["112579.92000000","0.00000000"],["112579.91000000","0.00088000"],["112579.79000000","0.00000000"],["112579.51000000","0.00000000"],["112579.50000000","0.06015000"],["112579.35000000","0.00037000"],["112579.13000000","0.00000000"],["112579.11000000","0.00000000"],["112578.62000000","0.00250000"],["112578.56000000","0.00000000"],["112578.21000000","0.00000000"],["112578.06000000","0.25239000"],["112578.05000000","0.46943000"],["112578.04000000","0.08966000"],["112578.02000000","0.00000000"],["112578.01000000","0.00000000"],["112578.00000000","0.00000000"],["112577.99000000","0.28609000"],["112577.98000000","0.00007000"],["112577.95000000","0.00000000"],["112577.92000000","0.00000000"],["112577.90000000","0.00000000"],["112576.74000000","0.00000000"],["112576.56000000","0.00010000"],["112576.30000000","0.00000000"],["112576.29000000","0.00000000"],["112576.10000000","0.00000000"],["112575.99000000","0.00000000"],["112575.91000000","0.00000000"],["112575.90000000","0.00000000"],["112575.89000000","0.01332000"],["112575.88000000","0.03888000"],["112575.80000000","0.00000000"],["112575.64000000","0.00005000"],["112574.99000000","0.00000000"],["112574.71000000","0.00000000"],["112574.56000000","0.00000000"],["112574.55000000","0.00005000"],["112574.54000000","0.00000000"],["112574.45000000","0.00000000"],["112574.25000000","0.00005000"],["112574.17000000","0.00000000"],["112574.11000000","0.00260000"],["112573.98000000","0.00000000"],["112573.97000000","0.00000000"],["112573.72000000","0.31800000"],["112572.50000000","0.00000000"],["112572.34000000","0.00000000"],["112572.33000000","0.00005000"],["112571.84000000","0.00000000"],["112571.83000000","0.38457000"],["112571.82000000","0.46938000"],["112571.40000000","0.00000000"],["112570.94000000","0.00010000"],["112570.91000000","0.00005000"],["112570.16000000","0.00005000"],["112570.01000000","0.00444000"],["112570.00000000","0.06110000"],["112569.99000000","0.00000000"],["112569.66000000","0.00000000"],["112569.65000000","0.02597000"],["112569.60000000","0.00255000"],["112569.47000000","0.00000000"],["112569.14000000","0.00000000"],["112569.00000000","0.00000000"],["112568.83000000","0.00000000"],["112568.79000000","0.00000000"],["112568.57000000","0.00000000"],["112568.46000000","0.00000000"],["112568.42000000","0.46938000"],["112568.41000000","0.00000000"],["112568.36000000","0.00000000"],["112568.35000000","0.00000000"],["112568.34000000","0.00000000"],["112568.26000000","0.00000000"],["112568.24000000","0.04566000"],["112568.10000000","0.00088000"],["112567.11000000","0.00000000"],["112567.10000000","0.00000000"],["112566.82000000","0.00007000"],["112566.73000000","0.00000000"],["112566.37000000","0.00000000"],["112566.20000000","0.00000000"],["112566.08000000","0.00000000"],["112565.49000000","0.15146000"],["112565.39000000","0.00000000"],["112565.32000000","0.00010000"],["112565.09000000","0.00250000"],["112564.97000000","0.00000000"],["112564.69000000","0.00005000"],["112564.53000000","0.55288000"],["112564.52000000","1.70701000"],["112564.51000000","0.00000000"],["112564.02000000","0.00000000"],["112564.01000000","0.35527000"],["112564.00000000","0.00000000"],["112563.92000000","0.03773000"],["112563.73000000","0.00000000"],["112563.72000000","0.46938000"],["112563.00000000","0.00000000"],["112562.81000000","0.00000000"],["112562.78000000","0.00000000"],["112562.46000000","0.00300000"],["112562.39000000","0.02665000"],["112562.29000000","0.00000000"],["112562.05000000","0.06748000"],["112561.83000000","0.00010000"],["112561.80000000","0.00000000"],["112561.30000000","0.04395000"],["112561.25000000","0.00000000"],["112561.22000000","0.00000000"],["112560.71000000","0.04000000"],["112560.58000000","0.00000000"],["112560.36000000","0.00000000"],["112560.13000000","0.26660000"],["112560.00000000","0.00005000"],["112559.99000000","0.00000000"],["112559.98000000","0.00000000"],["112559.75000000","0.00000000"],["112559.50000000","0.00000000"],["112559.38000000","0.26683000"],["112559.34000000","0.00000000"],["112559.33000000","0.00000000"],["112559.32000000","0.00000000"],["112559.19000000","0.00000000"],["112559.04000000","1.16071000"],["112559.00000000","0.04088000"],["112558.99000000","0.00000000"],["112558.76000000","0.00000000"],["112558.33000000","0.00000000"],["112558.32000000","0.00010000"],["112557.99000000","0.04000000"],["112557.57000000","0.26728000"],["112557.20000000","0.00000000"],["112557.08000000","0.56994000"],["112556.47000000","0.00000000"],["112556.29000000","0.19865000"],["112556.20000000","0.00059000"],["112556.17000000","0.00009000"],["112556.11000000","0.05700000"],["112556.07000000","0.00250000"],["112556.06000000","0.00009000"],["112555.62000000","0.15146000"],["112555.15000000","0.06000000"],["112554.65000000","0.00177000"],["112554.64000000","0.00177000"],["112554.63000000","0.21569000"],["112554.18000000","0.00005000"],["112553.71000000","0.05255000"],["112553.38000000","0.01021000"],["112552.93000000","0.00000000"],["112551.77000000","0.00000000"],["112551.70000000","0.00355000"],["112551.56000000","0.00000000"],["112551.46000000","0.00000000"],["112551.45000000","0.00000000"],["112551.33000000","0.00009000"],["112551.22000000","0.00000000"],["112551.11000000","0.00022000"],["112550.57000000","0.00000000"],["112550.24000000","0.00000000"],["112550.20000000","0.44510000"],["112549.94000000","0.31981000"],["112549.73000000","0.01256000"],["112549.35000000","0.00009000"],["112549.20000000","0.00000000"],["112549.12000000","0.00000000"],["112548.92000000","0.00006000"],["112548.69000000","0.00000000"],["112548.60000000","0.00005000"],["112548.57000000","0.00000000"],["112548.53000000","0.00000000"],["112548.34000000","0.04500000"],["112548.15000000","0.00000000"],["112547.81000000","0.00005000"],["112547.45000000","0.00000000"],["112547.38000000","0.05400000"],["112547.36000000","0.03900000"],["112547.32000000","0.04200000"],["112547.26000000","0.04500000"],["112547.24000000","0.00000000"],["112547.05000000","0.00000000"],["112546.39000000","0.44452000"],["112546.36000000","0.03600000"],["112546.28000000","0.00000000"],["112545.81000000","0.03000000"],["112545.58000000","0.00088000"],["112545.29000000","0.03498000"],["112545.00000000","0.00000000"],["112544.98000000","0.03000000"],["112544.96000000","0.00000000"],["112544.70000000","0.00000000"],["112544.66000000","0.01800000"],["112544.55000000","0.00000000"],["112543.90000000","0.03600000"],["112543.88000000","0.00000000"],["112543.67000000","0.31983000"],["112543.43000000","0.03900000"],["112543.01000000","0.00000000"],["112542.81000000","0.00000000"],["112542.73000000","0.03000000"],["112542.68000000","0.00447000"],["112542.67000000","0.00000000"],["112542.35000000","0.24000000"],["112541.76000000","0.00000000"],["112541.66000000","0.00000000"],["112541.64000000","0.00009000"],["112541.63000000","0.03000000"],["112541.58000000","0.00000000"],["112541.51000000","0.00000000"],["112541.42000000","0.03000000"],["112540.13000000","0.26677000"],["112540.06000000","0.00000000"],["112540.00000000","0.00000000"],["112539.43000000","0.00000000"],["112539.32000000","0.00000000"],["112538.69000000","0.00065000"],["112538.52000000","0.00000000"],["112537.28000000","0.00000000"],["112536.99000000","0.00000000"],["112536.92000000","0.00000000"],["112536.64000000","0.31985000"],["112536.48000000","0.00000000"],["112536.42000000","0.00000000"],["112536.36000000","0.00000000"],["112535.72000000","0.00000000"],["112534.94000000","0.00000000"],["112534.33000000","0.00000000"],["112534.32000000","0.00000000"],["112534.31000000","0.00000000"],["112533.93000000","0.00000000"],["112533.03000000","0.01021000"],["112532.73000000","0.19424000"],["112532.59000000","0.00000000"],["112532.50000000","0.06000000"],["112532.34000000","0.00000000"],["112532.29000000","0.00000000"],["112532.23000000","0.00271000"],["112531.99000000","0.07174000"],["112531.80000000","0.00000000"],["112531.68000000","0.00005000"],["112531.29000000","0.00000000"],["112531.18000000","0.00012000"],["112530.94000000","0.00000000"],["112530.87000000","0.00000000"],["112530.50000000","1.08662000"],["112530.42000000","0.00000000"],["112529.99000000","0.00000000"],["112529.94000000","0.00000000"],["112529.87000000","0.00010000"],["112529.73000000","0.00000000"],["112528.95000000","0.00000000"],["112528.87000000","0.00000000"],["112528.71000000","0.00000000"],["112527.55000000","0.00000000"],["112527.39000000","0.00000000"],["112527.24000000","0.00000000"],["112527.05000000","0.00000000"],["112527.03000000","0.00000000"],["112526.76000000","0.00000000"],["112526.75000000","0.00000000"],["112526.47000000","0.00000000"],["112526.45000000","0.00000000"],["112526.32000000","0.00000000"],["112526.29000000","0.00000000"],["112526.25000000","0.00000000"],["112526.16000000","0.74824000"],["112526.11000000","0.00000000"],["112525.95000000","0.00000000"],["112525.35000000","0.00000000"],["112525.02000000","0.00000000"],["112524.60000000","0.06740000"],["112524.48000000","0.00000000"],["112523.88000000","0.00000000"],["112523.86000000","0.00000000"],["112523.61000000","0.00000000"],["112523.42000000","0.00000000"],["112523.41000000","0.00000000"],["112523.14000000","0.00000000"],["112522.95000000","0.00000000"],["112522.73000000","0.00000000"],["112522.50000000","0.00000000"],["112521.81000000","0.00000000"],["112521.65000000","0.00000000"],["112520.84000000","0.00000000"],["112520.71000000","0.00000000"],["112520.56000000","0.00000000"],["112519.60000000","0.00020000"],["112519.46000000","0.00000000"],["112518.63000000","0.00010000"],["112517.02000000","0.00632000"],["112516.09000000","0.00627000"],["112515.86000000","0.00000000"],["112515.65000000","0.00000000"],["112515.36000000","0.00000000"],["112515.05000000","0.02984000"],["112513.85000000","0.00000000"],["112513.70000000","0.31500000"],["112513.52000000","0.00000000"],["112513.46000000","0.26728000"],["112513.42000000","0.26660000"],["112513.06000000","0.00000000"],["112512.84000000","0.00653000"],["112512.75000000","0.02224000"],["112512.73000000","0.00000000"],["112512.68000000","0.00000000"],["112512.45000000","0.00000000"],["112512.29000000","0.00000000"],["112510.40000000","0.02186000"],["112509.60000000","0.00000000"],["112509.19000000","0.00000000"],["112506.98000000","0.00000000"],["112504.57000000","0.00089000"],["112503.82000000","0.00000000"],["112501.74000000","0.00623000"],["112501.22000000","0.00000000"],["112500.91000000","0.00000000"],["112498.90000000","0.00000000"],["112498.45000000","0.00000000"],["112497.45000000","0.26677000"],["112497.16000000","0.00100000"],["112495.50000000","0.00000000"],["112495.02000000","0.00000000"],["112494.84000000","0.44452000"],["112493.78000000","0.00000000"],["112493.42000000","0.00000000"],["112493.01000000","0.00000000"],["112492.96000000","0.00000000"],["112492.22000000","0.00000000"],["112491.99000000","0.00000000"],["112491.56000000","0.36063000"],["112490.29000000","0.00000000"],["112490.18000000","0.00000000"],["112490.01000000","0.00000000"],["112489.72000000","0.44510000"],["112488.31000000","0.36064000"],["112486.73000000","0.00000000"],["112486.72000000","0.00000000"],["112484.64000000","0.00000000"],["112484.38000000","0.00000000"],["112484.18000000","0.88889000"],["112484.09000000","0.68898000"],["112484.08000000","0.00000000"],["112482.54000000","0.00000000"],["112481.46000000","0.00000000"],["112480.01000000","0.65533000"],["112479.21000000","0.02187000"],["112478.30000000","0.00000000"],["112477.12000000","0.00000000"],["112476.01000000","0.00220000"],["112475.00000000","0.02487000"],["112473.92000000","0.00000000"],["112473.32000000","0.04034000"],["112471.80000000","0.00000000"],["112467.86000000","0.00000000"],["112467.27000000","0.02452000"],["112461.60000000","1.32495000"],["112461.06000000","0.07740000"],["112460.48000000","0.00000000"],["112460.01000000","0.00110000"],["112459.99000000","0.40461000"],["112457.74000000","0.00000000"],["112452.12000000","0.00000000"],["112451.10000000","0.00000000"],["112448.77000000","0.00000000"],["112448.75000000","0.00000000"],["112448.18000000","0.00000000"],["112447.18000000","0.03598000"],["112446.00000000","0.00160000"],["112443.37000000","0.00000000"],["112443.30000000","0.00000000"],["112442.94000000","0.00000000"],["112440.30000000","0.00000000"],["112440.00000000","0.00165000"],["112438.66000000","0.00000000"],["112437.75000000","0.00000000"],["112437.20000000","0.00000000"],["112435.96000000","0.00000000"],["112435.88000000","0.00000000"],["112427.46000000","0.03257000"],["112424.75000000","0.06000000"],["112424.63000000","0.27771000"],["112424.62000000","0.00000000"],["112422.38000000","0.00000000"],["112419.30000000","0.00000000"],["112419.12000000","0.13664000"],["112418.24000000","0.42663000"],["112414.02000000","0.16380000"],["112408.24000000","0.11502000"],["112407.75000000","0.08747000"],["112397.50000000","0.00000000"],["112388.64000000","0.01077000"],["112388.63000000","0.01776000"],["112383.51000000","0.10212000"],["112381.42000000","0.00000000"],["112380.01000000","0.01407000"],["112373.39000000","0.00000000"],["112373.38000000","0.00000000"],["112370.45000000","0.00000000"],["112363.14000000","0.00000000"],["112354.78000000","0.00000000"],["112347.50000000","0.00000000"],["112343.62000000","0.00000000"],["112341.66000000","0.00018000"],["112339.13000000","0.00010000"],["112338.70000000","0.00510000"],["112337.27000000","0.99691000"],["112332.06000000","0.00019000"],["112325.41000000","0.00010000"],["112315.89000000","0.00016000"],["112309.44000000","0.00000000"],["112304.16000000","0.00007000"],["112298.88000000","0.00000000"],["112297.01000000","0.00006000"],["112294.83000000","0.00064000"],["112292.42000000","0.00007000"],["112290.97000000","0.02227000"],["112288.44000000","0.00000000"],["112286.55000000","0.00005000"],["112285.71000000","0.00024000"],["112276.80000000","0.00000000"],["112276.60000000","1.24640000"],["112271.42000000","0.00044000"],["112269.93000000","0.00008000"],["112261.07000000","0.00042000"],["112256.03000000","0.00027000"],["112250.00000000","0.17099000"],["112247.33000000","0.00000000"],["112244.95000000","0.00005000"],["112243.76000000","0.00009000"],["112243.73000000","0.01687000"],["112242.18000000","0.00010000"],["112241.91000000","0.00019000"],["112241.17000000","0.02398000"],["112239.63000000","0.00000000"],["112238.54000000","0.00005000"],["112238.23000000","0.00009000"],["112237.92000000","0.00061000"],["112237.24000000","0.00010000"],["112237.19000000","0.00000000"],["112236.16000000","0.00000000"],["112235.88000000","0.00005000"],["112235.29000000","0.00110000"],["112234.87000000","0.00090000"],["112234.02000000","0.00000000"],["112233.63000000","0.00008000"],["112231.70000000","0.00006000"],["112229.10000000","0.00027000"],["112228.67000000","0.00000000"],["112228.29000000","0.00005000"],["112228.17000000","0.00094000"],["112227.38000000","0.00022000"],["112225.67000000","0.00000000"],["112222.26000000","0.00008000"],["112221.51000000","0.00000000"],["112217.98000000","0.00000000"],["112217.78000000","0.00464000"],["112217.17000000","0.00000000"],["112212.45000000","0.00000000"],["112165.52000000","0.00000000"],["112149.28000000","0.02751000"],["112148.88000000","0.02903000"],["112145.98000000","0.03198000"],["112129.74000000","0.00000000"],["112128.43000000","0.00000000"],["112076.57000000","0.00250000"],["112059.41000000","0.00000000"],["112058.52000000","0.00000000"],["112054.16000000","0.00000000"],["112053.60000000","0.00000000"],["112042.36000000","0.00000000"],["112038.06000000","0.00000000"],["112035.16000000","0.00000000"],["112034.76000000","0.00000000"],["112031.11000000","0.00000000"],["112028.32000000","0.00000000"],["112018.57000000","0.00000000"],["112011.97000000","0.00000000"],["112011.50000000","0.00000000"],["111999.39000000","0.00000000"],["111997.61000000","0.00000000"],["111856.50000000","0.00000000"],["111832.76000000","0.00000000"],["111787.55000000","0.40310000"],["111632.62000000","0.00000000"],["110907.29000000","0.00302000"],["110879.81000000","0.00000000"],["110620.67000000","0.00000000"],["110061.98000000","0.00000000"],["109503.29000000","0.00114000"],["109258.24000000","0.00000000"],["108944.60000000","0.00000000"],["108385.91000000","0.00000000"],["108143.36000000","0.00009000"],["107827.22000000","0.00000000"],["107268.53000000","0.00122000"],["107028.48000000","0.00000000"],["106709.84000000","0.00000000"],["106151.15000000","0.00000000"],["105913.60000000","0.00000000"],["105592.46000000","0.00000000"],["105033.77000000","0.00131000"],["104798.72000000","0.00000000"],["104475.08000000","0.00000000"],["103916.39000000","0.00000000"],["103683.84000000","0.00000000"],["102568.96000000","0.00000000"],["101336.00000000","0.00996000"],["101317.00000000","0.00030000"],["101315.73000000","0.00009000"],["101300.00000000","1.33193000"],["90077.00000000","0.00133000"],["90060.71000000","0.00000000"],["90054.68000000","0.00000000"],["90042.70000000","0.00000000"],["78814.11000000","0.00000000"],["78810.17000000","0.00000000"],["78806.23000000","0.00000000"],["78802.29000000","0.00000000"],["78798.34000000","0.00000000"],["50000.01000000","0.11364000"],["50000.00000000","39.88049000"],["42000.01000000","0.00000000"],["40534.65000000","0.00015000"]],"a":[["112568.35000000","0.00000000"],["112568.36000000","0.00000000"],["112568.54000000","0.00000000"],["112568.55000000","0.00000000"],["112568.79000000","0.00000000"],["112568.80000000","0.00000000"],["112568.82000000","0.00000000"],["112568.84000000","0.00000000"],["112569.01000000","0.00000000"],["112569.15000000","0.00000000"],["112569.60000000","0.00000000"],["112569.67000000","0.00000000"],["112570.00000000","0.00000000"],["112570.05000000","0.00000000"],["112570.16000000","0.00000000"],["112570.24000000","0.00000000"],["112570.92000000","0.00000000"],["112571.41000000","0.00000000"],["112571.42000000","0.00000000"],["112571.48000000","0.00000000"],["112571.90000000","0.00000000"],["112571.95000000","0.00000000"],["112571.96000000","0.00000000"],["112572.00000000","0.00000000"],["112572.07000000","0.00000000"],["112573.30000000","0.00000000"],["112573.40000000","0.00000000"],["112573.42000000","0.00000000"],["112573.85000000","0.00000000"],["112573.99000000","0.00000000"],["112574.00000000","0.00000000"],["112574.08000000","0.00000000"],["112574.18000000","0.00000000"],["112574.26000000","0.00000000"],["112574.55000000","0.00000000"],["112574.67000000","0.00000000"],["112574.72000000","0.00000000"],["112575.00000000","0.00000000"],["112575.41000000","0.00000000"],["112575.45000000","0.00000000"],["112575.64000000","0.00000000"],["112575.88000000","0.00000000"],["112575.89000000","0.00000000"],["112575.90000000","0.00000000"],["112575.97000000","0.00000000"],["112576.00000000","0.00000000"],["112576.11000000","0.00000000"],["112576.30000000","0.00000000"],["112576.31000000","0.00000000"],["112576.50000000","0.00000000"],["112576.57000000","0.00000000"],["112576.75000000","0.00000000"],["112577.16000000","0.00000000"],["112577.54000000","0.00000000"],["112578.00000000","0.00000000"],["112578.01000000","0.00000000"],["112578.57000000","0.00000000"],["112579.11000000","0.00000000"],["112579.12000000","0.00000000"],["112579.13000000","0.00000000"],["112579.14000000","0.00000000"],["112579.61000000","0.00000000"],["112579.80000000","0.00000000"],["112579.83000000","0.00000000"],["112579.84000000","0.00000000"],["112579.85000000","0.00000000"],["112579.86000000","0.00000000"],["112579.98000000","0.00000000"],["112579.99000000","0.00000000"],["112580.00000000","0.00000000"],["112580.10000000","0.00000000"],["112580.14000000","0.00000000"],["112580.17000000","0.00000000"],["112580.18000000","0.00000000"],["112580.25000000","0.00000000"],["112580.83000000","0.00000000"],["112580.87000000","0.00000000"],["112580.95000000","0.00000000"],["112581.12000000","0.00000000"],["112581.24000000","0.00000000"],["112581.30000000","0.00000000"],["112581.39000000","0.00000000"],["112581.40000000","0.00000000"],["112581.42000000","0.00000000"],["112581.58000000","0.00000000"],["112581.59000000","0.00000000"],["112581.70000000","0.00000000"],["112581.90000000","0.00000000"],["112582.00000000","0.00000000"],["112582.06000000","0.00000000"],["112582.08000000","0.00000000"],["112582.18000000","0.00000000"],["112582.31000000","0.00000000"],["112582.43000000","0.00000000"],["112582.49000000","0.00000000"],["112582.50000000","0.00000000"],["112582.63000000","0.00000000"],["112582.95000000","0.00000000"],["112582.98000000","0.00000000"],["112583.11000000","0.00000000"],["112583.12000000","0.00000000"],["112583.13000000","0.00000000"],["112583.23000000","0.00000000"],["112583.24000000","0.00000000"],["112583.37000000","0.00000000"],["112583.45000000","0.00000000"],["112583.56000000","0.00000000"],["112584.00000000","0.00000000"],["112584.17000000","0.00000000"],["112584.18000000","0.00000000"],["112584.19000000","0.00000000"],["112584.23000000","0.00000000"],["112584.27000000","0.00000000"],["112584.40000000","0.00000000"],["112584.64000000","0.00000000"],["112584.76000000","0.00000000"],["112585.18000000","0.00000000"],["112585.21000000","0.00000000"],["112585.23000000","0.00000000"],["112585.24000000","0.00000000"],["112585.36000000","0.00000000"],["112585.44000000","0.00000000"],["112585.45000000","0.00000000"],["112585.46000000","0.00000000"],["112585.47000000","0.00000000"],["112585.48000000","0.00000000"],["112585.49000000","0.00000000"],["112585.50000000","0.00000000"],["112585.59000000","0.00000000"],["112585.60000000","0.00000000"],["112585.62000000","0.00000000"],["112585.76000000","0.00000000"],["112585.78000000","0.00000000"],["112585.86000000","0.00000000"],["112585.87000000","0.00000000"],["112585.88000000","0.00000000"],["112585.90000000","0.00000000"],["112585.91000000","0.00000000"],["112586.00000000","0.00000000"],["112586.16000000","0.00000000"],["112586.60000000","0.00000000"],["112586.80000000","0.00000000"],["112586.83000000","0.00000000"],["112586.85000000","0.00000000"],["112587.06000000","0.00000000"],["112587.14000000","0.00000000"],["112587.15000000","0.00000000"],["112587.30000000","0.00000000"],["112587.64000000","0.00000000"],["112587.66000000","0.00000000"],["112587.79000000","0.00000000"],["112588.00000000","0.00000000"],["112588.02000000","0.00000000"],["112588.23000000","0.00000000"],["112588.30000000","0.00000000"],["112588.39000000","0.00000000"],["112588.57000000","0.00000000"],["112588.88000000","0.00000000"],["112589.03000000","0.00000000"],["112589.43000000","0.00000000"],["112589.50000000","0.00000000"],["112589.72000000","0.00000000"],["112589.82000000","0.00000000"],["112589.84000000","0.00000000"],["112589.88000000","0.00000000"],["112589.94000000","0.00000000"],["112589.96000000","0.00000000"],["112589.97000000","0.00000000"],["112589.98000000","0.00000000"],["112589.99000000","0.00000000"],["112590.00000000","0.00000000"],["112590.15000000","0.00000000"],["112590.31000000","0.00000000"],["112590.46000000","0.00000000"],["112590.52000000","0.00000000"],["112590.55000000","0.00000000"],["112590.83000000","0.00000000"],["112591.89000000","0.00000000"],["112591.99000000","0.00000000"],["112592.00000000","0.00000000"],["112592.08000000","0.00000000"],["112592.15000000","0.00000000"],["112592.58000000","0.00000000"],["112592.59000000","0.00000000"],["112592.72000000","0.00000000"],["112592.78000000","0.00000000"],["112593.02000000","0.00000000"],["112593.24000000","0.00000000"],["112593.37000000","0.00000000"],["112593.40000000","0.00000000"],["112593.50000000","0.00000000"],["112593.52000000","0.00000000"],["112593.53000000","0.00000000"],["112593.60000000","0.00000000"],["112593.88000000","0.00000000"],["112593.93000000","0.00000000"],["112594.00000000","0.00000000"],["112594.11000000","0.00000000"],["112594.24000000","0.00000000"],["112594.32000000","0.00000000"],["112594.52000000","0.00000000"],["112594.66000000","0.00000000"],["112594.89000000","0.00000000"],["112595.00000000","0.00000000"],["112595.18000000","0.00000000"],["112595.47000000","0.00000000"],["112595.48000000","0.00000000"],["112595.51000000","0.00000000"],["112595.54000000","0.00000000"],["112595.62000000","0.00000000"],["112595.68000000","0.00000000"],["112595.95000000","0.00000000"],["112596.00000000","0.00000000"],["112596.06000000","0.00000000"],["112596.24000000","0.00000000"],["112596.25000000","4.16629000"],["112596.26000000","0.00010000"],["112596.33000000","0.00010000"],["112596.42000000","0.01789000"],["112596.50000000","0.00000000"],["112596.66000000","0.00275000"],["112596.73000000","0.00000000"],["112596.78000000","0.00000000"],["112596.85000000","0.00000000"],["112596.89000000","0.00000000"],["112596.90000000","0.00000000"],["112596.91000000","0.00000000"],["112596.92000000","0.00000000"],["112597.00000000","0.00000000"],["112597.35000000","1.70721000"],["112597.36000000","0.03967000"],["112597.37000000","0.00000000"],["112597.38000000","0.00000000"],["112597.76000000","0.00000000"],["112597.77000000","0.00000000"],["112597.80000000","0.00000000"],["112597.93000000","0.00005000"],["112597.96000000","0.00000000"],["112597.97000000","0.03015000"],["112598.00000000","0.00160000"],["112598.59000000","0.00010000"],["112598.60000000","0.30000000"],["112598.78000000","0.00000000"],["112599.01000000","0.00000000"],["112599.28000000","0.00000000"],["112599.43000000","0.00000000"],["112599.47000000","0.00034000"],["112599.57000000","0.00000000"],["112599.59000000","0.00000000"],["112599.65000000","0.00000000"],["112599.73000000","0.00064000"],["112599.83000000","0.00000000"],["112599.98000000","0.00000000"],["112599.99000000","0.00005000"],["112600.00000000","0.18792000"],["112600.43000000","0.00043000"],["112600.66000000","0.00022000"],["112601.17000000","0.00255000"],["112601.18000000","0.03005000"],["112601.27000000","0.00000000"],["112601.31000000","0.00005000"],["112601.32000000","0.00612000"],["112601.44000000","0.00000000"],["112601.55000000","0.00000000"],["112601.60000000","0.00000000"],["112601.61000000","0.00000000"],["112601.91000000","0.00000000"],["112602.00000000","0.00170000"],["112602.13000000","0.00000000"],["112602.27000000","0.00000000"],["112602.82000000","0.00000000"],["112603.00000000","0.06100000"],["112603.01000000","0.33934000"],["112603.02000000","1.70701000"],["112603.03000000","0.00000000"],["112603.22000000","0.00000000"],["112603.75000000","0.00000000"],["112604.00000000","0.00165000"],["112604.04000000","0.00000000"],["112604.11000000","0.05405000"],["112604.38000000","0.00033000"],["112604.40000000","0.00005000"],["112604.77000000","0.00006000"],["112604.79000000","0.00893000"],["112604.80000000","0.06758000"],["112605.47000000","0.46938000"],["112605.48000000","0.04455000"],["112605.52000000","0.00034000"],["112605.68000000","0.00255000"],["112605.69000000","0.00000000"],["112605.71000000","0.03005000"],["112605.94000000","0.00000000"],["112606.00000000","0.00165000"],["112606.15000000","0.10640000"],["112606.26000000","0.00000000"],["112606.67000000","0.00000000"],["112606.68000000","0.00000000"],["112606.78000000","0.03000000"],["112606.92000000","0.00000000"],["112607.51000000","0.00451000"],["112607.71000000","0.03000000"],["112607.73000000","0.00444000"],["112607.74000000","0.00194000"],["112608.00000000","0.00160000"],["112608.04000000","0.04216000"],["112608.50000000","0.06000000"],["112608.61000000","0.00000000"],["112608.63000000","0.03000000"],["112608.74000000","0.08054000"],["112608.92000000","0.00033000"],["112609.03000000","0.00000000"],["112609.19000000","0.00161000"],["112609.95000000","0.00000000"],["112610.19000000","0.00250000"],["112610.29000000","0.00034000"],["112610.36000000","0.00000000"],["112610.40000000","0.00200000"],["112610.62000000","0.04000000"],["112611.10000000","0.02399000"],["112611.83000000","0.00006000"],["112612.13000000","0.04480000"],["112612.36000000","0.00000000"],["112613.05000000","0.00000000"],["112613.10000000","0.00012000"],["112613.12000000","0.26728000"],["112613.13000000","0.00088000"],["112613.14000000","0.00151000"],["112613.46000000","0.29683000"],["112613.52000000","0.00447000"],["112613.54000000","0.00000000"],["112613.61000000","0.15146000"],["112613.89000000","0.00035000"],["112614.70000000","0.00250000"],["112615.57000000","0.00000000"],["112615.82000000","0.00037000"],["112615.89000000","0.00275000"],["112616.10000000","0.00000000"],["112616.19000000","0.00000000"],["112616.37000000","0.00000000"],["112616.39000000","0.00000000"],["112617.06000000","0.00800000"],["112617.24000000","0.29147000"],["112618.00000000","0.06260000"],["112618.74000000","0.03598000"],["112618.75000000","0.01022000"],["112618.77000000","0.00300000"],["112619.21000000","0.00000000"],["112619.39000000","0.02399000"],["112619.40000000","0.03198000"],["112619.45000000","0.00000000"],["112619.98000000","0.03498000"],["112620.09000000","0.00035000"],["112620.83000000","0.00033000"],["112620.90000000","0.00000000"],["112621.33000000","0.00000000"],["112622.54000000","0.00000000"],["112622.70000000","0.00005000"],["112623.68000000","0.00000000"],["112623.82000000","0.00000000"],["112624.86000000","0.01256000"],["112624.91000000","0.22719000"],["112624.95000000","0.00000000"],["112624.96000000","0.00005000"],["112624.97000000","0.98460000"],["112625.99000000","0.04174000"],["112626.49000000","0.00000000"],["112627.88000000","0.00800000"],["112628.80000000","0.00064000"],["112629.16000000","0.00000000"],["112629.24000000","0.00000000"],["112629.32000000","0.00000000"],["112630.03000000","0.00300000"],["112630.40000000","0.01687000"],["112630.41000000","0.46938000"],["112630.42000000","0.34123000"],["112630.44000000","0.00005000"],["112632.43000000","0.00000000"],["112632.44000000","0.00000000"],["112633.10000000","0.01687000"],["112635.65000000","0.00088000"],["112635.92000000","0.00005000"],["112636.46000000","0.21893000"],["112636.47000000","0.02935000"],["112636.61000000","0.00000000"],["112636.84000000","0.00000000"],["112636.85000000","0.00000000"],["112637.29000000","0.00000000"],["112637.87000000","0.64178000"],["112639.05000000","0.00000000"],["112639.11000000","0.01020000"],["112639.62000000","0.02487000"],["112639.63000000","0.00000000"],["112639.74000000","0.00000000"],["112640.19000000","0.00000000"],["112640.42000000","0.00000000"],["112640.50000000","0.00056000"],["112641.20000000","0.00000000"],["112641.36000000","0.00000000"],["112641.40000000","0.00005000"],["112643.46000000","0.00005000"],["112643.65000000","0.36015000"],["112644.64000000","0.00000000"],["112645.52000000","0.00000000"],["112645.99000000","0.02487000"],["112646.05000000","0.00000000"],["112646.08000000","0.00000000"],["112646.59000000","0.00000000"],["112646.88000000","0.00005000"],["112646.89000000","0.36013000"],["112646.95000000","0.00000000"],["112647.99000000","0.00000000"],["112650.17000000","0.00618000"],["112650.98000000","0.00000000"],["112652.36000000","0.00010000"],["112653.51000000","0.02187000"],["112653.73000000","0.02487000"],["112654.16000000","0.00648000"],["112654.56000000","0.00000000"],["112654.62000000","0.00005000"],["112654.68000000","0.31500000"],["112655.04000000","0.04325000"],["112655.05000000","0.00626000"],["112655.27000000","0.03000000"],["112657.17000000","0.00000000"],["112658.16000000","0.26728000"],["112658.27000000","0.03000000"],["112658.50000000","0.26683000"],["112659.02000000","0.00155000"],["112659.35000000","0.02186000"],["112660.50000000","0.46943000"],["112661.25000000","0.00629000"],["112662.09000000","0.03460000"],["112662.11000000","0.03000000"],["112662.28000000","0.26660000"],["112662.84000000","0.02487000"],["112662.94000000","0.00000000"],["112664.47000000","0.00000000"],["112664.80000000","0.46938000"],["112665.51000000","0.04041000"],["112666.04000000","0.00111000"],["112666.49000000","0.00000000"],["112666.79000000","0.00000000"],["112666.87000000","0.02444000"],["112667.27000000","0.03000000"],["112667.77000000","0.00000000"],["112667.99000000","0.00221000"],["112668.77000000","0.00927000"],["112669.59000000","0.00000000"],["112669.60000000","0.00000000"],["112671.56000000","0.46938000"],["112672.34000000","0.07218000"],["112672.39000000","0.00000000"],["112677.22000000","0.00000000"],["112677.30000000","0.00221000"],["112677.31000000","0.03000000"],["112677.73000000","0.00000000"],["112677.75000000","0.00000000"],["112678.60000000","0.00000000"],["112678.96000000","0.03000000"],["112679.02000000","0.35608000"],["112680.23000000","0.03000000"],["112681.45000000","0.00000000"],["112682.29000000","0.00000000"],["112682.33000000","0.00000000"],["112682.39000000","0.00000000"],["112682.45000000","0.00000000"],["112683.29000000","0.19190000"],["112684.58000000","0.00100000"],["112685.72000000","0.00000000"],["112685.73000000","0.03000000"],["112686.12000000","0.00033000"],["112688.31000000","0.00000000"],["112694.47000000","0.00000000"],["112697.26000000","0.00007000"],["112699.92000000","0.00000000"],["112700.00000000","0.27642000"],["112700.12000000","0.00088000"],["112700.34000000","0.00000000"],["112700.39000000","0.00000000"],["112705.95000000","0.00000000"],["112708.22000000","0.00005000"],["112708.40000000","0.00007000"],["112709.85000000","1.70701000"],["112710.86000000","0.00000000"],["112711.95000000","0.00000000"],["112712.17000000","0.00005000"],["112713.52000000","0.02398000"],["112714.29000000","0.01776000"],["112714.39000000","0.07740000"],["112714.77000000","0.08657000"],["112717.00000000","0.06000000"],["112721.11000000","0.00000000"],["112721.44000000","0.00000000"],["112721.83000000","0.00000000"],["112722.19000000","0.00000000"],["112722.60000000","0.02398000"],["112722.63000000","0.16215000"],["112725.51000000","0.00000000"],["112729.57000000","0.00000000"],["112729.71000000","0.02398000"],["112734.45000000","0.01848000"],["112735.69000000","0.00000000"],["112737.22000000","0.02398000"],["112737.72000000","0.00000000"],["112744.38000000","0.02398000"],["112745.52000000","0.00000000"],["112749.54000000","0.00011000"],["112750.41000000","0.03846000"],["112752.48000000","0.00000000"],["112757.64000000","0.00000000"],["112757.74000000","0.01582000"],["112759.89000000","0.00000000"],["112759.90000000","0.02398000"],["112760.21000000","0.02241000"],["112760.94000000","0.00000000"],["112760.95000000","0.00000000"],["112766.00000000","0.00405000"],["112766.87000000","0.00000000"],["112770.75000000","0.00000000"],["112771.13000000","0.00000000"],["112772.30000000","0.00000000"],["112772.32000000","0.00006000"],["112774.43000000","0.00000000"],["112776.01000000","0.01274000"],["112776.59000000","0.00000000"],["112776.69000000","0.01598000"],["112778.80000000","0.00000000"],["112779.29000000","0.00000000"],["112779.46000000","0.00000000"],["112780.60000000","0.00088000"],["112781.08000000","0.00000000"],["112782.04000000","0.00000000"],["112782.14000000","0.00000000"],["112782.75000000","0.07589000"],["112783.53000000","0.00000000"],["112784.31000000","0.00000000"],["112789.87000000","0.00088000"],["112794.12000000","0.00005000"],["112794.95000000","0.00492000"],["112796.48000000","0.00000000"],["112799.45000000","0.00000000"],["112800.96000000","0.00000000"],["112804.29000000","0.03598000"],["112805.83000000","0.03598000"],["112806.34000000","0.01776000"],["112806.36000000","0.03598000"],["112807.05000000","0.03598000"],["112807.83000000","0.03598000"],["112808.80000000","0.03598000"],["112808.87000000","0.00000000"],["112809.88000000","0.03598000"],["112812.29000000","0.02398000"],["112812.39000000","0.00000000"],["112813.11000000","0.00000000"],["112817.81000000","0.00000000"],["112817.83000000","0.01776000"],["112818.56000000","0.00000000"],["112819.79000000","0.00000000"],["112820.81000000","0.01776000"],["112820.92000000","0.01776000"],["112821.24000000","0.00000000"],["112821.84000000","0.00000000"],["112823.13000000","0.00000000"],["112825.98000000","0.02398000"],["112826.67000000","0.00000000"],["112828.11000000","0.00007000"],["112833.12000000","0.00000000"],["112833.15000000","0.00000000"],["112839.55000000","0.02398000"],["112840.05000000","0.01687000"],["112840.38000000","0.00250000"],["112841.22000000","0.01687000"],["112843.27000000","0.01687000"],["112843.73000000","0.00000000"],["112844.04000000","0.00000000"],["112844.18000000","0.00000000"],["112844.39000000","0.00000000"],["112845.37000000","0.00000000"],["112846.08000000","0.00000000"],["112846.38000000","0.01687000"],["112847.07000000","0.00000000"],["112848.12000000","0.00000000"],["112848.23000000","0.88602000"],["112848.27000000","0.00000000"],["112848.43000000","0.01687000"],["112848.61000000","0.00107000"],["112849.24000000","0.00000000"],["112849.61000000","0.00000000"],["112849.97000000","0.00005000"],["112852.11000000","0.00000000"],["112853.70000000","0.02398000"],["112854.35000000","0.00000000"],["112854.39000000","0.00000000"],["112854.42000000","0.00007000"],["112854.51000000","0.00008000"],["112854.89000000","0.00000000"],["112855.25000000","0.00000000"],["112857.64000000","0.00000000"],["112862.35000000","0.00000000"],["112862.99000000","0.00000000"],["112866.08000000","0.22117000"],["112868.00000000","0.02398000"],["112868.26000000","0.00000000"],["112870.49000000","0.94003000"],["112872.27000000","0.00000000"],["112873.16000000","0.02398000"],["112874.17000000","0.02398000"],["112875.66000000","0.00000000"],["112882.96000000","0.01687000"],["112887.85000000","0.01687000"],["112891.81000000","0.01687000"],["112892.32000000","0.00000000"],["112894.08000000","0.00000000"],["112895.19000000","0.01693000"],["112895.94000000","0.00000000"],["112896.34000000","0.00000000"],["112896.83000000","0.00000000"],["112897.04000000","0.00000000"],["112897.62000000","0.00000000"],["112897.71000000","0.00000000"],["112897.75000000","0.00000000"],["112898.43000000","0.00000000"],["112898.54000000","0.00000000"],["112898.69000000","0.00000000"],["112898.72000000","0.00000000"],["112899.00000000","0.01294000"],["112899.39000000","0.00000000"],["112900.21000000","0.00000000"],["112900.61000000","0.00007000"],["112901.33000000","0.00000000"],["112912.42000000","0.02398000"],["112914.02000000","0.00000000"],["112915.10000000","0.02398000"],["112915.53000000","0.02404000"],["112916.98000000","0.02398000"],["112918.13000000","0.02398000"],["112918.85000000","0.00000000"],["112919.07000000","0.02398000"],["112920.95000000","0.02405000"],["112921.05000000","0.02398000"],["112921.97000000","0.02398000"],["112922.39000000","0.02428000"],["112922.89000000","0.02398000"],["112922.95000000","0.02398000"],["112923.84000000","0.02398000"],["112924.05000000","0.02398000"],["112925.86000000","0.02398000"],["112932.42000000","0.00000000"],["112933.83000000","0.00000000"],["112934.24000000","0.21840000"],["112937.31000000","0.00000000"],["112938.51000000","0.00000000"],["112942.71000000","0.00000000"],["112944.64000000","0.00000000"],["112945.03000000","0.02398000"],["112945.77000000","0.00010000"],["112946.42000000","1.20006000"],["112948.11000000","0.00000000"],["112948.39000000","0.00000000"],["112948.80000000","0.00000000"],["112949.80000000","0.00000000"],["112950.33000000","0.00000000"],["112951.39000000","0.00000000"],["112951.82000000","0.00000000"],["112953.12000000","0.00010000"],["112953.39000000","0.00000000"],["112954.33000000","0.02398000"],["112954.46000000","0.00000000"],["112954.68000000","0.00000000"],["112955.50000000","0.00000000"],["112957.42000000","0.00000000"],["112958.48000000","0.00000000"],["112958.74000000","0.00010000"],["112958.83000000","0.02398000"],["112959.23000000","0.00008000"],["112960.32000000","0.02398000"],["112961.30000000","0.00000000"],["112964.36000000","0.00010000"],["112967.28000000","0.02398000"],["112969.98000000","0.00010000"],["112972.74000000","0.03498000"],["112972.86000000","0.02787000"],["112973.79000000","0.03498000"],["112974.78000000","0.31500000"],["112974.94000000","0.03498000"],["112975.60000000","0.00088000"],["112976.19000000","0.03514000"],["112977.45000000","0.03498000"],["112977.57000000","0.03498000"],["112979.11000000","0.03503000"],["112979.58000000","0.03498000"],["112981.22000000","0.00000000"],["112982.32000000","0.03498000"],["112983.27000000","0.03498000"],["112984.09000000","0.03498000"],["112986.20000000","0.03498000"],["112988.65000000","0.03498000"],["112999.37000000","0.17789000"],["113005.23000000","0.00000000"],["113005.85000000","0.00497000"],["113005.96000000","0.00000000"],["113008.11000000","0.00000000"],["113090.00000000","0.00000000"],["113096.21000000","0.00000000"],["113098.61000000","0.00000000"],["113099.82000000","0.00000000"],["113100.53000000","0.00000000"],["113101.37000000","0.00000000"],["113105.79000000","0.00000000"],["113105.91000000","0.00000000"],["113124.58000000","0.03198000"],["113124.92000000","0.03198000"],["113125.12000000","0.03198000"],["113125.53000000","0.03198000"],["113125.68000000","0.03198000"],["113126.40000000","0.03198000"],["113127.01000000","0.03198000"],["113127.89000000","0.03198000"],["113134.92000000","0.00005000"],["113136.03000000","0.26861000"],["113292.47000000","0.00100000"],["113304.72000000","0.00000000"],["113476.50000000","0.00200000"],["113556.53000000","0.00000000"],["113760.00000000","0.09892000"],["114264.53000000","0.00000000"],["114285.20000000","0.00100000"],["118776.35000000","0.17770000"],["140452.59000000","0.10464000"]]}
[2025-10-26T09:48:33.065Z] {"e":"depthUpdate","E":1761472112014,"s":"BTCUSDT","U":79058073745,"u":79058075408,"b":[["112596.24000000","0.00000000"],["112596.17000000","0.00000000"],["112593.83000000","0.00000000"],["112592.08000000","0.00000000"],["112591.88000000","0.00000000"],["112591.87000000","0.00000000"],["112590.00000000","0.00000000"],["112588.36000000","0.00000000"],["112588.35000000","0.00000000"],["112587.79000000","0.00000000"],["112587.78000000","0.00000000"],["112586.60000000","0.00000000"],["112585.87000000","0.00000000"],["112585.86000000","0.00000000"],["112585.85000000","0.00000000"],["112584.98000000","0.00000000"],["112584.58000000","0.00000000"],["112584.57000000","0.00000000"],["112584.10000000","0.00000000"],["112584.09000000","0.00000000"],["112583.63000000","0.00000000"],["112583.62000000","0.00000000"],["112583.49000000","0.00000000"],["112583.03000000","0.00000000"],["112583.02000000","0.00000000"],["112582.18000000","0.00000000"],["112582.16000000","0.00000000"],["112582.15000000","0.00000000"],["112581.12000000","0.00000000"],["112580.10000000","4.66236000"],["112580.03000000","0.00010000"],["112579.91000000","0.00000000"],["112579.81000000","0.00000000"],["112579.80000000","0.00005000"],["112579.51000000","0.00000000"],["112579.50000000","0.00000000"],["112579.35000000","0.00000000"],["112578.98000000","0.00118000"],["112578.81000000","0.00000000"],["112578.75000000","0.00005000"],["112578.62000000","0.00000000"],["112578.06000000","0.00000000"],["112578.05000000","0.00000000"],["112578.04000000","0.00005000"],["112578.01000000","0.00000000"],["112578.00000000","0.00000000"],["112577.99000000","0.00476000"],["112577.98000000","0.00000000"],["112577.29000000","0.00210000"],["112576.56000000","0.00000000"],["112576.51000000","0.02999000"],["112576.50000000","0.04730000"],["112575.89000000","0.00010000"],["112575.88000000","0.03908000"],["112575.60000000","0.00355000"],["112574.55000000","0.00000000"],["112574.47000000","0.00162000"],["112574.25000000","0.00000000"],["112574.11000000","0.00000000"],["112573.73000000","0.00000000"],["112573.72000000","0.00300000"],["112573.53000000","0.00000000"],["112573.52000000","0.00000000"],["112573.35000000","0.00543000"],["112572.33000000","0.00000000"],["112572.18000000","0.00000000"],["112572.17000000","0.00000000"],["112572.05000000","0.00000000"],["112572.04000000","0.00000000"],["112572.01000000","0.29310000"],["112571.84000000","0.00000000"],["112571.83000000","0.00000000"],["112571.82000000","0.00000000"],["112571.66000000","0.00010000"],["112571.65000000","0.08895000"],["112570.69000000","0.00010000"],["112570.68000000","0.39410000"],["112570.67000000","0.20471000"],["112570.41000000","0.00000000"],["112570.01000000","0.00005000"],["112570.00000000","0.00010000"],["112569.87000000","0.00151000"],["112569.66000000","0.00000000"],["112569.65000000","0.02602000"],["112569.60000000","0.00250000"],["112569.52000000","0.00000000"],["112569.25000000","0.00000000"],["112569.17000000","0.00000000"],["112568.84000000","0.31505000"],["112568.42000000","0.00000000"],["112568.24000000","0.00015000"],["112568.00000000","0.06110000"],["112567.29000000","0.46938000"],["112566.81000000","0.00000000"],["112566.31000000","0.00005000"],["112566.03000000","0.30717000"],["112566.02000000","0.22255000"],["112565.49000000","0.15146000"],["112565.46000000","0.04738000"],["112565.15000000","0.00000000"],["112565.09000000","0.00260000"],["112564.55000000","0.00000000"],["112564.54000000","0.00000000"],["112564.53000000","0.00000000"],["112564.52000000","0.00000000"],["112564.51000000","0.04566000"],["112564.25000000","0.00444000"],["112564.24000000","0.00151000"],["112564.01000000","0.00000000"],["112563.92000000","0.03773000"],["112562.47000000","0.04449000"],["112562.46000000","0.00300000"],["112562.39000000","0.00000000"],["112562.05000000","0.00000000"],["112561.43000000","0.00000000"],["112561.30000000","0.00000000"],["112560.71000000","0.00000000"],["112560.58000000","0.00250000"],["112560.13000000","0.00000000"],["112560.09000000","0.00006000"],["112559.76000000","0.00005000"],["112559.38000000","0.00000000"],["112559.00000000","0.00000000"],["112558.20000000","0.00000000"],["112557.99000000","0.00000000"],["112557.57000000","0.00000000"],["112557.08000000","0.00000000"],["112556.54000000","0.00000000"],["112556.20000000","0.00059000"],["112556.17000000","0.00000000"],["112556.07000000","0.00250000"],["112556.06000000","0.00000000"],["112555.50000000","0.00000000"],["112555.41000000","0.00000000"],["112555.15000000","0.00000000"],["112554.68000000","0.00000000"],["112554.57000000","0.00000000"],["112554.49000000","0.00005000"],["112554.13000000","0.03600000"],["112553.10000000","0.00000000"],["112553.07000000","0.00000000"],["112552.85000000","0.00000000"],["112552.84000000","0.00000000"],["112552.76000000","0.03000000"],["112551.96000000","0.00088000"],["112551.87000000","0.00000000"],["112551.68000000","0.02666000"],["112551.51000000","0.04000000"],["112551.50000000","0.06100000"],["112551.33000000","0.00000000"],["112550.21000000","0.29973000"],["112549.94000000","0.00000000"],["112549.56000000","0.00000000"],["112549.47000000","0.00000000"],["112549.46000000","0.00000000"],["112549.45000000","0.00000000"],["112549.37000000","0.00000000"],["112549.35000000","0.00000000"],["112547.81000000","0.00000000"],["112547.74000000","0.26660000"],["112547.05000000","0.00250000"],["112546.97000000","0.00000000"],["112546.57000000","0.00000000"],["112546.51000000","0.26683000"],["112546.36000000","0.00000000"],["112546.33000000","0.26736000"],["112546.32000000","0.00300000"],["112545.56000000","0.02000000"],["112545.28000000","0.00000000"],["112545.26000000","0.04000000"],["112544.98000000","0.00000000"],["112544.72000000","0.00000000"],["112543.74000000","0.00065000"],["112543.67000000","0.00000000"],["112543.41000000","1.20042000"],["112542.82000000","0.00000000"],["112542.75000000","0.00000000"],["112542.57000000","0.31983000"],["112541.64000000","0.00000000"],["112541.11000000","0.00000000"],["112541.10000000","0.00000000"],["112538.69000000","0.00000000"],["112538.13000000","0.00000000"],["112537.28000000","0.00005000"],["112537.11000000","0.31985000"],["112536.64000000","0.00000000"],["112535.97000000","0.00000000"],["112535.04000000","0.00000000"],["112534.57000000","0.00000000"],["112531.80000000","0.00005000"],["112531.68000000","0.00000000"],["112530.50000000","0.09772000"],["112529.87000000","0.00000000"],["112529.72000000","0.31987000"],["112529.45000000","0.00088000"],["112526.32000000","0.00005000"],["112525.76000000","0.00000000"],["112525.10000000","0.34115000"],["112524.60000000","0.00000000"],["112523.92000000","0.31988000"],["112523.69000000","0.00000000"],["112523.53000000","0.00000000"],["112522.45000000","0.00000000"],["112521.84000000","0.00000000"],["112520.91000000","0.00000000"],["112518.83000000","0.00000000"],["112518.63000000","0.00000000"],["112518.18000000","0.06628000"],["112515.05000000","0.00000000"],["112514.51000000","0.26683000"],["112512.98000000","0.00010000"],["112512.55000000","0.00008000"],["112504.57000000","0.00000000"],["112502.01000000","0.00010000"],["112501.43000000","0.00000000"],["112499.66000000","0.36000000"],["112499.51000000","0.02984000"],["112498.69000000","0.03900000"],["112498.65000000","0.04200000"],["112497.97000000","0.00000000"],["112497.31000000","0.00000000"],["112495.20000000","0.03600000"],["112492.94000000","0.03000000"],["112492.35000000","0.01333000"],["112488.69000000","0.00000000"],["112481.69000000","0.00000000"],["112479.68000000","0.00000000"],["112478.78000000","0.00008000"],["112476.06000000","0.00000000"],["112476.01000000","0.00000000"],["112470.00000000","0.00140000"],["112464.90000000","0.00000000"],["112461.61000000","0.00221000"],["112454.92000000","0.00000000"],["112445.00000000","0.00008000"],["112441.63000000","0.04500000"],["112439.73000000","0.00000000"],["112438.77000000","0.00000000"],["112438.69000000","0.00000000"],["112437.19000000","0.03000000"],["112435.94000000","0.03000000"],["112435.47000000","0.00000000"],["112433.22000000","0.00000000"],["112433.21000000","0.03598000"],["112432.70000000","0.00000000"],["112421.15000000","0.00000000"],["112419.12000000","0.00000000"],["112412.63000000","0.00000000"],["112411.23000000","0.00008000"],["112410.53000000","0.13418000"],["112397.99000000","0.00000000"],["112387.39000000","0.01776000"],["112363.14000000","0.06748000"],["112350.00000000","0.02905000"],["112273.92000000","0.02498000"],["112273.20000000","0.02498000"],["112273.07000000","0.07494000"],["112272.25000000","0.02498000"],["112258.44000000","0.00000000"],["112240.12000000","0.00009000"],["112240.09000000","0.00010000"],["112236.12000000","0.00000000"],["112234.47000000","0.00010000"],["112007.99000000","0.00000000"],["110907.29000000","0.00202000"],["110891.39000000","0.00100000"],["109760.00000000","0.00446000"],["109738.05000000","0.00008000"],["101336.00000000","0.00986000"],["101322.00000000","0.00010000"],["101317.00000000","0.00020000"],["101315.73000000","0.00000000"],["90077.00000000","0.00111000"],["90064.08000000","0.00022000"],["78813.42000000","0.00000000"],["78809.48000000","0.00000000"],["50000.01000000","0.11364000"],["50000.00000000","39.88079000"],["40528.84000000","0.00015000"],["33000.00000000","3.78938000"]],"a":[["112580.11000000","3.29666000"],["112580.12000000","0.00030000"],["112580.19000000","0.00010000"],["112581.12000000","0.00005000"],["112581.69000000","0.03511000"],["112581.70000000","0.20496000"],["112582.08000000","0.00005000"],["112582.13000000","0.00000000"],["112582.14000000","0.00005000"],["112582.15000000","0.00005000"],["112582.16000000","0.00000000"],["112582.19000000","0.00000000"],["112582.43000000","0.00006000"],["112582.92000000","0.00225000"],["112583.02000000","0.00000000"],["112583.03000000","0.00000000"],["112583.28000000","0.00010000"],["112583.29000000","0.04586000"],["112583.50000000","0.00000000"],["112583.62000000","0.00000000"],["112583.63000000","0.00000000"],["112584.10000000","0.00000000"],["112584.57000000","0.00000000"],["112584.91000000","0.00010000"],["112584.92000000","0.03967000"],["112584.93000000","0.00000000"],["112584.99000000","0.00000000"],["112585.36000000","0.00010000"],["112585.37000000","0.06763000"],["112585.73000000","0.00010000"],["112585.74000000","0.08874000"],["112585.86000000","0.00000000"],["112585.87000000","0.00000000"],["112585.88000000","0.00000000"],["112586.19000000","0.00000000"],["112586.60000000","0.00005000"],["112586.61000000","0.00000000"],["112586.86000000","0.00538000"],["112587.64000000","0.00255000"],["112587.66000000","0.00005000"],["112587.79000000","0.00000000"],["112588.21000000","0.00000000"],["112588.36000000","0.00000000"],["112588.37000000","0.00000000"],["112589.05000000","0.00000000"],["112589.06000000","0.00000000"],["112589.67000000","0.00391000"],["112589.87000000","0.00000000"],["112589.88000000","0.04005000"],["112590.01000000","0.00000000"],["112590.31000000","0.00000000"],["112590.60000000","0.00000000"],["112590.61000000","0.00005000"],["112590.62000000","0.00000000"],["112590.82000000","0.00000000"],["112590.83000000","0.04010000"],["112591.00000000","0.06115000"],["112591.36000000","0.00711000"],["112591.37000000","0.00439000"],["112591.64000000","0.49692000"],["112591.65000000","1.70701000"],["112591.88000000","0.00000000"],["112591.89000000","0.00000000"],["112592.08000000","0.00005000"],["112592.09000000","0.00000000"],["112592.15000000","0.00255000"],["112593.05000000","0.00166000"],["112593.24000000","0.00005000"],["112593.34000000","0.00000000"],["112593.47000000","0.00328000"],["112593.60000000","0.00006000"],["112593.84000000","0.00000000"],["112594.16000000","0.00010000"],["112594.19000000","0.10645000"],["112595.05000000","0.46938000"],["112596.18000000","0.00000000"],["112596.23000000","0.00000000"],["112596.24000000","0.00000000"],["112596.25000000","2.47128000"],["112596.26000000","0.00000000"],["112596.33000000","0.00000000"],["112596.35000000","0.04946000"],["112596.42000000","0.02259000"],["112596.66000000","0.00755000"],["112596.99000000","0.00088000"],["112597.00000000","0.00007000"],["112597.34000000","0.00000000"],["112597.35000000","1.71201000"],["112597.36000000","0.03957000"],["112597.82000000","0.04000000"],["112597.93000000","0.00000000"],["112597.97000000","0.03000000"],["112598.00000000","0.00160000"],["112598.59000000","0.46938000"],["112598.60000000","0.30000000"],["112599.56000000","0.00000000"],["112599.73000000","0.00000000"],["112599.78000000","0.00010000"],["112599.99000000","0.00000000"],["112600.00000000","0.18787000"],["112600.19000000","0.26683000"],["112600.43000000","0.00038000"],["112601.17000000","0.49566000"],["112601.18000000","0.03000000"],["112601.31000000","0.00000000"],["112601.32000000","0.00607000"],["112602.00000000","0.00160000"],["112602.06000000","0.46938000"],["112603.31000000","0.15146000"],["112604.00000000","0.00160000"],["112604.11000000","0.05400000"],["112604.79000000","0.00888000"],["112604.80000000","0.06753000"],["112605.12000000","0.26660000"],["112605.48000000","0.00000000"],["112605.68000000","0.00250000"],["112605.71000000","0.03000000"],["112606.00000000","0.00160000"],["112606.15000000","0.00000000"],["112606.19000000","0.04135000"],["112607.10000000","0.03000000"],["112607.51000000","0.00300000"],["112608.01000000","0.03000000"],["112608.04000000","0.00000000"],["112608.74000000","0.00000000"],["112608.75000000","0.00000000"],["112608.84000000","0.00000000"],["112609.19000000","0.00000000"],["112610.19000000","0.00000000"],["112610.40000000","0.00000000"],["112610.49000000","0.03300000"],["112610.51000000","0.00000000"],["112610.62000000","0.00000000"],["112612.13000000","0.00000000"],["112613.12000000","0.00000000"],["112613.14000000","0.00000000"],["112613.46000000","0.03000000"],["112613.61000000","0.00000000"],["112613.73000000","0.05400000"],["112613.88000000","0.00008000"],["112614.70000000","0.00000000"],["112618.00000000","0.00160000"],["112618.82000000","0.00000000"],["112621.32000000","0.00000000"],["112621.74000000","0.43138000"],["112622.07000000","0.00000000"],["112622.19000000","0.00000000"],["112623.60000000","0.21062000"],["112623.76000000","0.00000000"],["112624.97000000","0.00000000"],["112625.06000000","0.04450000"],["112628.15000000","0.01391000"],["112628.22000000","0.02048000"],["112629.17000000","0.00000000"],["112630.03000000","0.00000000"],["112636.75000000","0.03460000"],["112637.87000000","0.00000000"],["112638.97000000","0.04091000"],["112641.40000000","0.00000000"],["112641.76000000","0.06638000"],["112644.09000000","0.00000000"],["112646.88000000","0.00000000"],["112647.66000000","0.00008000"],["112648.72000000","0.04348000"],["112648.83000000","0.26728000"],["112652.14000000","0.00000000"],["112652.36000000","0.00005000"],["112652.58000000","0.00000000"],["112655.04000000","0.00000000"],["112657.18000000","0.00000000"],["112657.53000000","0.00000000"],["112658.16000000","0.00000000"],["112658.50000000","0.00000000"],["112659.16000000","0.00000000"],["112659.56000000","0.00000000"],["112659.75000000","0.00000000"],["112659.80000000","0.00000000"],["112661.10000000","0.00000000"],["112661.30000000","0.26677000"],["112662.09000000","0.00000000"],["112662.28000000","0.00000000"],["112663.66000000","0.00000000"],["112665.13000000","0.00000000"],["112666.63000000","0.35608000"],["112666.71000000","0.44510000"],["112666.80000000","0.00000000"],["112668.39000000","0.44452000"],["112670.67000000","0.03600000"],["112675.08000000","0.00000000"],["112676.27000000","0.00000000"],["112676.40000000","0.00000000"],["112677.74000000","0.03000000"],["112678.61000000","0.03300000"],["112679.02000000","0.00000000"],["112681.43000000","0.00008000"],["112682.62000000","0.00100000"],["112682.63000000","0.00100000"],["112685.59000000","0.03000000"],["112689.28000000","0.03400000"],["112691.30000000","0.00000000"],["112708.22000000","0.00000000"],["112712.17000000","0.00000000"],["112715.21000000","0.00008000"],["112725.06000000","0.00000000"],["112734.45000000","0.00000000"],["112738.60000000","0.47523000"],["112748.98000000","0.00008000"],["112750.41000000","0.17250000"],["112757.64000000","0.02666000"],["112759.10000000","0.01848000"],["112772.84000000","0.01598000"],["112776.33000000","0.01598000"],["112779.81000000","0.01598000"],["112848.17000000","0.01687000"],["112860.48000000","0.01687000"],["112862.84000000","0.07494000"],["112872.32000000","0.01687000"],["112883.69000000","0.01687000"],["112941.60000000","0.10218000"],["112969.98000000","0.00000000"],["112974.78000000","0.00000000"],["112975.60000000","0.00078000"],["113129.50000000","0.00005000"],["113592.65000000","0.04000000"],["114268.82000000","0.00100000"],["114285.20000000","0.00000000"]]}
[2025-10-26T09:48:34.089Z] {"e":"depthUpdate","E":1761472113014,"s":"BTCUSDT","U":79058075409,"u":79058076075,"b":[["112580.10000000","4.65090000"],["112580.09000000","0.00060000"],["112579.65000000","0.00000000"],["112579.64000000","0.00000000"],["112577.99000000","0.00466000"],["112577.62000000","0.00005000"],["112577.29000000","0.00200000"],["112576.52000000","0.00000000"],["112576.51000000","0.00000000"],["112576.50000000","0.00000000"],["112575.89000000","0.00010000"],["112575.88000000","0.03903000"],["112575.60000000","0.00360000"],["112575.03000000","0.00010000"],["112575.02000000","0.04715000"],["112574.55000000","0.00000000"],["112574.54000000","0.00000000"],["112573.35000000","0.00543000"],["112572.02000000","0.00000000"],["112572.01000000","0.00000000"],["112571.87000000","0.00000000"],["112571.86000000","0.00000000"],["112571.80000000","0.00010000"],["112571.79000000","0.29315000"],["112571.65000000","0.08900000"],["112570.78000000","0.00355000"],["112570.69000000","0.00010000"],["112570.68000000","0.45443000"],["112570.25000000","0.00005000"],["112569.65000000","0.02602000"],["112569.60000000","0.00255000"],["112568.87000000","0.00000000"],["112568.84000000","0.88499000"],["112568.55000000","0.04407000"],["112568.24000000","0.00005000"],["112568.00000000","0.06105000"],["112567.71000000","0.00205000"],["112566.86000000","0.00331000"],["112566.70000000","0.00005000"],["112566.02000000","0.00000000"],["112565.34000000","0.00005000"],["112565.09000000","0.00250000"],["112564.51000000","0.00000000"],["112564.25000000","0.00444000"],["112563.41000000","0.00000000"],["112563.34000000","0.00000000"],["112562.52000000","0.04566000"],["112562.47000000","0.00000000"],["112557.58000000","0.22255000"],["112553.74000000","0.00888000"],["112552.76000000","0.07430000"],["112551.56000000","0.00250000"],["112547.16000000","0.00009000"],["112547.06000000","0.00009000"],["112547.05000000","0.00000000"],["112546.09000000","0.00065000"],["112543.74000000","0.00000000"],["112542.57000000","0.00000000"],["112542.32000000","0.00009000"],["112540.35000000","0.00009000"],["112532.64000000","0.00009000"],["112529.96000000","0.96047000"],["112525.76000000","0.03600000"],["112525.10000000","0.00000000"],["112524.40000000","0.03000000"],["112523.94000000","0.00000000"],["112523.89000000","0.00000000"],["112523.01000000","0.34114000"],["112522.94000000","0.31989000"],["112508.00000000","0.00140000"],["112506.00000000","0.00140000"],["112504.00000000","0.00140000"],["112502.00000000","0.00140000"],["112500.00000000","0.02193000"],["112499.51000000","0.00000000"],["112498.45000000","0.04500000"],["112498.00000000","0.00140000"],["112496.00000000","0.00140000"],["112495.57000000","0.00089000"],["112494.00000000","0.00140000"],["112493.98000000","0.03000000"],["112492.66000000","0.03000000"],["112492.00000000","0.00140000"],["112490.00000000","0.00140000"],["112488.00000000","0.00160000"],["112486.72000000","0.01333000"],["112486.52000000","0.00000000"],["112486.00000000","0.00160000"],["112484.00000000","0.00160000"],["112482.00000000","0.00160000"],["112480.00000000","0.45165000"],["112478.00000000","0.00160000"],["112476.00000000","0.00160000"],["112474.00000000","0.00160000"],["112472.00000000","0.00160000"],["112471.80000000","0.00005000"],["112470.00000000","0.00160000"],["112468.09000000","0.02984000"],["112457.38000000","0.02048000"],["112443.66000000","0.00000000"],["112442.37000000","0.00000000"],["112441.63000000","0.00000000"],["112437.19000000","0.00000000"],["112435.94000000","0.00000000"],["112414.20000000","0.00000000"],["112410.53000000","0.00000000"],["112325.34000000","4.64639000"],["112303.21000000","0.00000000"],["112111.50000000","0.02598000"],["112067.15000000","0.03198000"],["111116.56000000","0.00222000"],["110891.40000000","0.00223000"],["110891.39000000","0.00100000"],["110885.11000000","0.00008000"],["110774.96000000","0.00000000"],["110550.50000000","0.00000000"],["109738.05000000","0.00000000"],["103545.80000000","0.00000000"],["101322.00000000","0.00010000"],["90064.08000000","0.00022000"],["90064.00000000","0.00000000"],["90046.07000000","0.00000000"],["60000.00000000","57.64892000"],["42000.00000000","1.40312000"]],"a":[["112580.11000000","3.33895000"],["112580.12000000","0.00000000"],["112581.67000000","0.00000000"],["112581.68000000","0.00000000"],["112581.69000000","0.00000000"],["112581.70000000","0.00000000"],["112581.93000000","0.00000000"],["112581.94000000","0.00030000"],["112581.95000000","0.03542000"],["112581.96000000","0.20486000"],["112582.14000000","0.00000000"],["112582.92000000","0.00210000"],["112583.29000000","0.04576000"],["112584.92000000","0.02908000"],["112585.36000000","0.00705000"],["112585.37000000","0.00005000"],["112585.49000000","0.00005000"],["112585.73000000","0.00005000"],["112585.74000000","0.08879000"],["112586.16000000","0.00711000"],["112586.37000000","0.06753000"],["112586.85000000","0.29978000"],["112586.86000000","0.00538000"],["112589.87000000","0.00000000"],["112589.88000000","0.04000000"],["112590.83000000","0.04005000"],["112591.00000000","0.06110000"],["112591.36000000","0.00711000"],["112593.05000000","0.00171000"],["112593.47000000","0.00000000"],["112593.50000000","0.00325000"],["112596.25000000","2.42127000"],["112596.35000000","0.05446000"],["112596.66000000","0.00750000"],["112597.36000000","0.03952000"],["112597.82000000","0.00000000"],["112600.28000000","0.01332000"],["112601.48000000","0.00200000"],["112601.72000000","0.07000000"],["112602.99000000","0.03300000"],["112603.01000000","0.03966000"],["112608.63000000","0.00000000"],["112609.43000000","0.95737000"],["112610.49000000","0.00000000"],["112611.09000000","0.02498000"],["112617.06000000","0.00000000"],["112617.24000000","0.02487000"],["112625.06000000","0.00000000"],["112640.00000000","0.41989000"],["112647.36000000","0.26683000"],["112650.42000000","0.26660000"],["112658.96000000","0.00000000"],["112659.52000000","0.00000000"],["112659.73000000","0.00000000"],["112659.81000000","0.26677000"],["112661.30000000","0.00000000"],["112677.75000000","0.05400000"],["112777.32000000","0.01598000"],["112781.19000000","0.01598000"],["112796.87000000","0.00000000"],["112820.83000000","4.64167000"],["112861.16000000","0.02498000"],["112861.82000000","0.02498000"],["112862.12000000","0.02498000"],["112862.47000000","0.02498000"],["112862.74000000","0.02498000"],["112862.93000000","0.02498000"],["112863.00000000","0.02498000"],["112863.08000000","0.02498000"],["112863.23000000","0.04996000"],["112866.52000000","0.04996000"],["112867.71000000","0.04996000"],["113124.35000000","0.03198000"],["114268.82000000","0.00100000"]]}
