[2025-10-12T10:57:34.184Z] {"e":"depthUpdate","E":1760266654014,"s":"BTCUSDT","U":77965084516,"u":77965085345,"b":[["111634.99000000","0.00000000"],["111634.98000000","0.00000000"],["111634.60000000","0.25002000"],["111634.59000000","0.00155000"],["111634.58000000","0.00020000"],["111634.53000000","0.00010000"],["111634.01000000","0.00005000"],["111634.00000000","0.00285000"],["111633.90000000","0.00722000"],["111633.89000000","0.00010000"],["111633.83000000","0.00000000"],["111633.79000000","0.00005000"],["111633.69000000","0.00000000"],["111633.61000000","0.00000000"],["111633.20000000","0.00000000"],["111633.17000000","0.00000000"],["111633.11000000","0.00000000"],["111632.78000000","0.01802000"],["111632.77000000","0.00010000"],["111632.38000000","0.00005000"],["111632.22000000","0.00000000"],["111632.00000000","0.00265000"],["111631.56000000","0.00000000"],["111631.27000000","0.00005000"],["111631.12000000","0.00000000"],["111631.11000000","0.00000000"],["111631.10000000","0.00547000"],["111631.04000000","0.00010000"],["111631.03000000","0.04495000"],["111629.19000000","0.00000000"],["111628.87000000","0.01797000"],["111627.76000000","0.00150000"],["111625.28000000","0.00000000"],["111625.27000000","0.00000000"],["111625.26000000","0.00000000"],["111625.25000000","0.00000000"],["111622.59000000","0.00005000"],["111622.58000000","0.20053000"],["111622.57000000","0.14920000"],["111622.56000000","0.00010000"],["111622.50000000","0.00305000"],["111622.40000000","0.00000000"],["111622.39000000","0.29549000"],["111622.21000000","0.03834000"],["111622.20000000","0.00000000"],["111622.19000000","0.00000000"],["111622.17000000","0.04636000"],["111622.00000000","0.00270000"],["111621.76000000","0.00000000"],["111620.25000000","0.00005000"],["111620.01000000","0.00000000"],["111619.95000000","0.00000000"],["111619.89000000","0.00000000"],["111616.50000000","0.00000000"],["111616.33000000","0.02689000"],["111616.32000000","0.00000000"],["111615.90000000","0.00000000"],["111615.63000000","0.00007000"],["111615.18000000","0.17907000"],["111614.80000000","0.00000000"],["111614.40000000","0.00100000"],["111608.97000000","0.00000000"],["111605.13000000","0.00895000"],["111604.62000000","0.00000000"],["111601.10000000","0.00300000"],["111599.25000000","0.15000000"],["111596.24000000","0.00000000"],["111592.73000000","0.05995000"],["111590.18000000","1.29055000"],["111584.49000000","0.00009000"],["111582.27000000","0.00018000"],["111578.85000000","0.00000000"],["111578.74000000","0.00000000"],["111578.73000000","0.06764000"],["111576.69000000","0.00000000"],["111575.67000000","0.00005000"],["111574.10000000","0.00009000"],["111572.87000000","0.30219000"],["111570.20000000","0.00000000"],["111552.06000000","0.13592000"],["111539.66000000","0.00005000"],["111538.77000000","0.00090000"],["111520.67000000","0.02597000"],["111510.30000000","0.22377000"],["111507.55000000","0.02597000"],["111501.40000000","0.00005000"],["111499.03000000","0.11391000"],["111493.59000000","0.26861000"],["111491.77000000","0.02597000"],["111490.38000000","0.00000000"],["111488.58000000","0.02597000"],["111479.98000000","0.02597000"],["111403.09000000","0.00000000"],["111393.29000000","0.00574000"],["111380.14000000","0.02508000"],["111324.91000000","0.00010000"],["111319.33000000","0.00010000"],["111274.29000000","0.05995000"],["110964.80000000","0.00000000"],["109960.47000000","0.00000000"],["109960.08000000","0.00100000"],["108100.00000000","17.51928000"],["100471.00000000","0.01637000"],["100470.00000000","0.00010000"],["89308.00000000","0.00000000"],["89307.68000000","0.00022000"],["60000.00000000","53.14032000"]],"a":[["111634.61000000","6.71234000"],["111634.67000000","0.00000000"],["111634.69000000","0.00010000"],["111634.70000000","0.00080000"],["111634.97000000","0.00000000"],["111634.99000000","0.66876000"],["111635.00000000","0.00100000"],["111635.01000000","0.21511000"],["111635.03000000","0.04017000"],["111635.11000000","0.00000000"],["111635.20000000","0.00000000"],["111635.40000000","0.01349000"],["111636.45000000","0.04017000"],["111637.16000000","0.00000000"],["111637.24000000","0.00363000"],["111637.94000000","0.04662000"],["111638.01000000","0.04007000"],["111638.54000000","0.05866000"],["111638.74000000","0.00187000"],["111639.63000000","0.00005000"],["111640.05000000","0.00000000"],["111641.41000000","0.11931000"],["111642.10000000","0.00005000"],["111642.22000000","0.04119000"],["111642.45000000","0.04800000"],["111644.39000000","0.00006000"],["111644.94000000","0.00087000"],["111645.35000000","0.03588000"],["111645.81000000","0.04800000"],["111645.97000000","0.15000000"],["111645.98000000","1.07194000"],["111646.00000000","0.00000000"],["111646.08000000","0.04800000"],["111646.14000000","0.04800000"],["111646.36000000","0.04800000"],["111646.93000000","0.04800000"],["111647.43000000","0.00000000"],["111648.04000000","0.04800000"],["111648.47000000","0.25599000"],["111649.26000000","0.00000000"],["111650.49000000","0.00000000"],["111650.97000000","0.13426000"],["111653.52000000","0.00012000"],["111654.29000000","0.04000000"],["111654.45000000","0.17428000"],["111655.33000000","0.00000000"],["111655.35000000","0.00000000"],["111658.68000000","0.00000000"],["111659.24000000","0.00000000"],["111659.81000000","0.00000000"],["111660.92000000","0.00000000"],["111663.14000000","0.22377000"],["111667.25000000","0.22377000"],["111668.11000000","0.00300000"],["111671.41000000","0.00000000"],["111674.28000000","0.18374000"],["111674.69000000","0.00000000"],["111675.60000000","0.00000000"],["111678.00000000","0.02498000"],["111679.47000000","0.00000000"],["111680.00000000","0.00200000"],["111681.50000000","0.31330000"],["111682.24000000","0.13433000"],["111684.81000000","0.00259000"],["111693.05000000","0.00625000"],["111698.73000000","0.00894000"],["111712.98000000","0.02175000"],["111714.00000000","0.00260000"],["111725.74000000","0.04800000"],["111730.52000000","0.00000000"],["111741.28000000","0.35405000"],["111741.29000000","0.22377000"],["111741.45000000","0.00000000"],["111741.87000000","0.00000000"],["111742.08000000","0.00000000"],["111745.40000000","0.22377000"],["111747.75000000","0.00000000"],["111753.99000000","0.04097000"],["111763.05000000","0.20354000"],["111882.77000000","0.00083000"],["111883.89000000","0.02508000"],["111884.41000000","0.02508000"],["111886.42000000","0.02508000"],["111891.46000000","0.00000000"],["111911.15000000","0.00000000"],["111959.39000000","0.03997000"],["112221.86000000","0.04796000"],["113309.13000000","0.00100000"],["113309.54000000","0.00000000"]]}
[2025-10-12T10:57:35.183Z] {"e":"depthUpdate","E":1760266655014,"s":"BTCUSDT","U":77965085346,"u":77965085604,"b":[["111634.60000000","0.40352000"],["111634.59000000","0.00155000"],["111628.87000000","0.01802000"],["111622.67000000","0.42533000"],["111622.66000000","0.00005000"],["111622.65000000","0.00005000"],["111622.64000000","0.00000000"],["111622.63000000","0.00000000"],["111622.62000000","0.00000000"],["111622.61000000","0.00000000"],["111622.60000000","0.00000000"],["111622.59000000","0.00000000"],["111622.58000000","0.00000000"],["111622.57000000","0.00000000"],["111622.56000000","0.00005000"],["111622.50000000","0.00310000"],["111622.39000000","0.29549000"],["111622.21000000","0.05622000"],["111622.00000000","0.00270000"],["111620.09000000","0.07631000"],["111619.14000000","0.01804000"],["111604.62000000","0.15000000"],["111601.90000000","0.00005000"],["111599.25000000","0.00000000"],["111590.18000000","0.08694000"],["111473.69000000","0.00000000"],["111380.16000000","0.02508000"],["110985.84000000","0.00000000"],["110979.99000000","0.00135000"],["110978.46000000","0.89110000"],["109960.08000000","0.00100000"],["102722.08000000","0.00010000"],["100594.53000000","0.00000000"],["100470.00000000","0.00010000"],["89324.00000000","0.00000000"],["89307.68000000","0.00022000"],["60000.00000000","53.14022000"],["40188.46000000","0.00015000"]],"a":[["111634.61000000","6.64655000"],["111635.00000000","0.00000000"],["111637.92000000","0.00005000"],["111638.01000000","0.04007000"],["111638.54000000","0.00005000"],["111645.35000000","0.03588000"],["111645.97000000","0.15000000"],["111650.49000000","0.00000000"],["111651.36000000","0.00150000"],["111659.84000000","0.05995000"],["111668.28000000","0.00000000"],["111670.44000000","0.04800000"],["111674.92000000","0.04800000"],["111675.60000000","0.00005000"],["111681.50000000","0.31330000"],["111717.07000000","0.00000000"],["111730.52000000","0.04800000"],["111740.59000000","0.00000000"],["111740.61000000","0.00000000"],["111742.09000000","0.00000000"],["111759.09000000","0.00000000"],["111890.52000000","0.00000000"],["111958.04000000","0.05995000"],["111958.53000000","0.05995000"],["111959.38000000","0.05995000"],["111961.03000000","0.05995000"],["113309.13000000","0.00100000"]]}
[2025-10-12T10:57:36.181Z] {"e":"depthUpdate","E":1760266656014,"s":"BTCUSDT","U":77965085605,"u":77965086667,"b":[["111634.60000000","0.00000000"],["111634.59000000","0.00000000"],["111634.58000000","0.00000000"],["111634.57000000","0.03101000"],["111634.56000000","0.00105000"],["111634.55000000","0.00020000"],["111634.52000000","0.00010000"],["111634.51000000","0.02626000"],["111634.50000000","0.00020000"],["111634.00000000","0.00265000"],["111633.99000000","0.00010000"],["111633.57000000","0.00010000"],["111633.45000000","0.00010000"],["111633.25000000","0.00000000"],["111633.11000000","0.00000000"],["111633.08000000","0.00000000"],["111633.04000000","0.00000000"],["111632.78000000","0.01802000"],["111632.77000000","0.00000000"],["111631.10000000","0.00542000"],["111631.04000000","0.00000000"],["111631.03000000","0.00000000"],["111628.87000000","0.01807000"],["111627.95000000","0.00005000"],["111627.94000000","0.05303000"],["111626.01000000","0.19883000"],["111624.00000000","0.00265000"],["111622.76000000","0.05862000"],["111622.75000000","0.19313000"],["111622.74000000","0.00000000"],["111622.73000000","0.00000000"],["111622.72000000","0.00000000"],["111622.71000000","0.00000000"],["111622.70000000","0.00000000"],["111622.69000000","0.00000000"],["111622.68000000","0.00000000"],["111622.67000000","0.00000000"],["111622.66000000","0.00000000"],["111622.65000000","0.00000000"],["111622.50000000","0.00305000"],["111622.39000000","0.00000000"],["111622.22000000","0.15406000"],["111622.21000000","0.14214000"],["111622.17000000","0.04631000"],["111622.01000000","0.29549000"],["111622.00000000","0.00265000"],["111621.75000000","0.01164000"],["111620.25000000","0.00000000"],["111619.65000000","0.00000000"],["111619.14000000","0.00000000"],["111619.02000000","0.01797000"],["111604.62000000","0.15000000"],["111599.25000000","0.00000000"],["111588.19000000","0.78711000"],["111584.14000000","1.19407000"],["111567.05000000","0.18892000"],["111380.02000000","0.02508000"],["109960.08000000","0.00000000"],["108000.00000000","92.77376000"],["102722.08000000","0.00000000"],["100471.00000000","0.01647000"],["100470.00000000","0.00010000"],["89307.68000000","0.00000000"],["89307.66000000","0.00022000"],["42000.00000000","1.49196000"]],"a":[["111634.58000000","8.08172000"],["111634.59000000","0.00036000"],["111634.60000000","1.10363000"],["111634.61000000","0.27494000"],["111634.66000000","0.00010000"],["111634.69000000","0.00000000"],["111634.97000000","0.00000000"],["111634.99000000","0.00000000"],["111635.00000000","0.00000000"],["111635.01000000","0.21511000"],["111635.02000000","0.85336000"],["111635.03000000","0.04012000"],["111635.72000000","0.30590000"],["111636.45000000","0.04012000"],["111637.94000000","0.04657000"],["111638.01000000","0.04002000"],["111638.25000000","0.00005000"],["111638.74000000","0.00000000"],["111643.34000000","0.04038000"],["111644.18000000","0.05730000"],["111645.35000000","0.03583000"],["111645.97000000","0.00000000"],["111650.49000000","0.15000000"],["111655.50000000","0.00411000"],["111661.48000000","1.22937000"],["111672.56000000","0.00187000"],["111674.25000000","0.18416000"],["111674.26000000","0.00000000"],["111674.27000000","0.00000000"],["111674.28000000","0.00000000"],["111681.50000000","0.00000000"],["111688.67000000","0.00000000"],["111704.00000000","0.00260000"],["111706.00000000","0.00260000"],["111709.48000000","0.13426000"],["111712.74000000","0.00322000"],["111714.50000000","0.00100000"],["111714.51000000","0.00100000"],["111722.66000000","0.00000000"],["111722.67000000","0.00000000"],["111740.70000000","0.00000000"],["111741.18000000","0.17904000"],["111777.66000000","0.02597000"],["111843.79000000","0.08677000"],["111858.27000000","0.08794000"],["111860.03000000","0.08794000"],["111863.35000000","0.08794000"],["111877.08000000","4.72936000"],["111882.77000000","0.00000000"],["111907.91000000","0.00000000"],["111911.20000000","0.00000000"],["111912.70000000","0.00000000"],["112026.07000000","0.00000000"],["112033.44000000","0.55838000"],["113309.10000000","0.00100000"],["113309.13000000","0.00000000"]]}
[2025-10-12T10:57:37.180Z] {"e":"depthUpdate","E":1760266657014,"s":"BTCUSDT","U":77965086668,"u":77965087199,"b":[["111634.57000000","0.00000000"],["111634.56000000","0.17782000"],["111634.55000000","0.00095000"],["111634.54000000","0.00020000"],["111634.53000000","0.00000000"],["111634.00000000","0.00265000"],["111633.99000000","0.00010000"],["111633.89000000","0.00020000"],["111633.86000000","0.00010000"],["111633.85000000","0.00000000"],["111633.83000000","0.00010000"],["111633.57000000","0.00000000"],["111633.49000000","0.00000000"],["111633.45000000","0.00000000"],["111633.04000000","0.00000000"],["111630.53000000","0.00010000"],["111627.94000000","0.05303000"],["111626.04000000","0.00000000"],["111626.03000000","0.00000000"],["111626.02000000","0.19796000"],["111626.01000000","0.00000000"],["111624.00000000","0.00260000"],["111622.76000000","0.00000000"],["111622.75000000","0.00000000"],["111622.53000000","0.00000000"],["111622.52000000","0.04703000"],["111622.51000000","0.15455000"],["111622.50000000","0.00305000"],["111622.22000000","0.15406000"],["111622.17000000","0.04631000"],["111622.00000000","0.00265000"],["111619.02000000","0.00000000"],["111616.33000000","0.00000000"],["111615.90000000","0.00005000"],["111615.42000000","0.02689000"],["111604.62000000","0.15000000"],["111599.25000000","0.00000000"],["111578.01000000","0.00000000"],["111576.10000000","0.30219000"],["111572.87000000","0.00000000"],["111571.20000000","0.00000000"],["111544.01000000","0.00000000"],["111540.01000000","0.00164000"],["111432.31000000","0.00000000"],["111428.25000000","0.00065000"],["111305.01000000","0.03583000"],["111137.52000000","0.00000000"],["109960.05000000","0.00100000"],["107000.00000000","45.28652000"],["100471.00000000","0.01637000"],["100470.00000000","0.00010000"],["89307.66000000","0.00000000"],["89307.65000000","0.00022000"],["40188.44000000","0.00015000"],["33000.00000000","3.87311000"]],"a":[["111634.57000000","7.77721000"],["111634.58000000","0.17914000"],["111634.59000000","0.00345000"],["111634.60000000","0.00010000"],["111634.61000000","0.27388000"],["111634.99000000","0.00000000"],["111635.00000000","0.68324000"],["111635.01000000","0.21511000"],["111635.02000000","0.85336000"],["111635.72000000","0.30590000"],["111636.45000000","0.04012000"],["111638.91000000","0.00542000"],["111639.02000000","0.00100000"],["111639.32000000","0.01344000"],["111639.80000000","0.00000000"],["111641.16000000","0.00363000"],["111641.61000000","0.03583000"],["111644.18000000","0.05725000"],["111644.96000000","0.04800000"],["111645.35000000","0.00000000"],["111645.97000000","0.15000000"],["111650.49000000","0.00000000"],["111672.56000000","0.00000000"],["111674.24000000","0.18416000"],["111674.25000000","0.00000000"],["111681.47000000","0.00000000"],["111682.55000000","0.00187000"],["111709.48000000","0.00000000"],["111709.56000000","0.13426000"],["111711.57000000","0.00000000"],["111741.11000000","0.00000000"],["111741.18000000","0.00000000"],["111751.99000000","0.04097000"],["111843.79000000","0.08594000"],["111853.79000000","0.00083000"],["112033.44000000","0.00000000"],["112221.96000000","0.02398000"],["113309.09000000","0.00100000"],["113309.10000000","0.00000000"]]}
[2025-10-12T10:57:38.181Z] {"e":"depthUpdate","E":1760266658015,"s":"BTCUSDT","U":77965087200,"u":77965087469,"b":[["111634.56000000","0.16175000"],["111634.55000000","0.00110000"],["111633.81000000","0.00010000"],["111627.94000000","0.05303000"],["111627.76000000","0.00155000"],["111626.12000000","0.19388000"],["111626.11000000","0.10689000"],["111626.10000000","0.00000000"],["111626.09000000","0.00000000"],["111626.08000000","0.00000000"],["111626.07000000","0.00000000"],["111626.06000000","0.00000000"],["111626.05000000","0.00000000"],["111626.04000000","0.00000000"],["111626.03000000","0.00000000"],["111626.02000000","0.00000000"],["111624.00000000","0.00260000"],["111622.57000000","0.00000000"],["111622.56000000","0.00005000"],["111622.53000000","0.00000000"],["111622.52000000","0.00000000"],["111622.51000000","0.00000000"],["111622.50000000","0.00300000"],["111622.23000000","0.00000000"],["111622.22000000","0.00000000"],["111615.42000000","0.00000000"],["111615.41000000","0.02689000"],["111604.62000000","0.15000000"],["111599.25000000","0.00000000"],["111598.01000000","0.00000000"],["111582.29000000","0.02687000"],["111542.71000000","0.27742000"],["111539.00000000","0.70054000"],["111407.12000000","0.00000000"],["111375.13000000","0.07520000"],["110964.76000000","0.00000000"],["109960.05000000","0.00000000"],["109960.04000000","0.00100000"],["108100.00000000","17.51946000"],["100470.00000000","0.00010000"],["89307.65000000","0.00022000"],["42000.00000000","1.49096000"],["40188.44000000","0.00030000"]],"a":[["111634.57000000","7.83237000"],["111634.58000000","0.29555000"],["111634.59000000","0.00350000"],["111634.61000000","0.21527000"],["111634.73000000","0.00901000"],["111634.99000000","0.00010000"],["111635.00000000","0.68334000"],["111635.01000000","0.21516000"],["111635.02000000","0.85336000"],["111635.17000000","0.00901000"],["111635.40000000","0.00000000"],["111636.45000000","0.04012000"],["111637.16000000","0.00000000"],["111640.86000000","0.08504000"],["111642.42000000","0.45526000"],["111643.34000000","0.04033000"],["111644.18000000","0.00000000"],["111645.97000000","0.00000000"],["111648.17000000","0.32228000"],["111650.49000000","0.15000000"],["111660.82000000","0.00187000"],["111673.13000000","0.02298000"],["111681.46000000","0.02125000"],["111682.55000000","0.00000000"],["111740.55000000","0.00000000"],["111741.58000000","0.17904000"],["111832.04000000","0.00083000"],["111853.79000000","0.00000000"],["112000.26000000","0.02298000"],["112001.92000000","0.02298000"],["112003.48000000","0.02298000"],["112005.04000000","0.02298000"],["112006.61000000","0.02298000"],["112008.17000000","0.02298000"],["112008.96000000","0.02298000"],["112009.46000000","0.02298000"],["112018.69000000","0.00000000"],["112222.00000000","0.04831000"],["113309.09000000","0.00100000"],["146760.00000000","0.00004000"]]}
[2025-10-12T10:57:39.180Z] {"e":"depthUpdate","E":1760266659014,"s":"BTCUSDT","U":77965087470,"u":77965087730,"b":[["111634.56000000","0.29717000"],["111634.55000000","0.00095000"],["111634.48000000","0.00010000"],["111633.89000000","0.00010000"],["111633.86000000","0.00000000"],["111633.83000000","0.00000000"],["111633.81000000","0.00000000"],["111627.94000000","0.05303000"],["111627.76000000","0.00155000"],["111626.13000000","0.00000000"],["111626.12000000","0.00000000"],["111626.11000000","0.00000000"],["111626.05000000","0.19695000"],["111626.04000000","0.10017000"],["111626.03000000","0.00000000"],["111626.02000000","0.00000000"],["111626.01000000","0.00000000"],["111624.00000000","0.00260000"],["111622.59000000","0.00000000"],["111622.58000000","0.00000000"],["111622.57000000","0.00000000"],["111622.56000000","0.00005000"],["111622.51000000","0.00000000"],["111622.50000000","0.00305000"],["111622.23000000","0.00000000"],["111622.22000000","0.00000000"],["111622.17000000","0.04631000"],["111619.02000000","0.00000000"],["111616.50000000","0.00000000"],["111615.41000000","0.00000000"],["111615.31000000","0.00000000"],["111615.28000000","0.00000000"],["111615.27000000","0.02689000"],["111614.40000000","0.00000000"],["111604.62000000","0.15000000"],["111599.25000000","0.00000000"],["111597.19000000","0.32242000"],["111588.19000000","0.48579000"],["111584.14000000","0.00000000"],["111584.12000000","1.21526000"],["111577.30000000","0.00000000"],["111509.66000000","0.00000000"],["111393.91000000","0.00574000"],["111393.29000000","0.00000000"],["109960.04000000","0.00100000"],["107000.00000000","45.29382000"],["106000.00000000","32.68589000"],["100471.00000000","0.01637000"],["100470.00000000","0.00010000"],["89307.65000000","0.00022000"],["40188.44000000","0.00045000"]],"a":[["111634.57000000","7.62452000"],["111634.60000000","0.00010000"],["111634.99000000","0.00010000"],["111635.00000000","0.68334000"],["111635.01000000","0.21516000"],["111639.24000000","0.00005000"],["111639.32000000","0.01349000"],["111641.16000000","0.00358000"],["111641.61000000","0.00000000"],["111642.45000000","0.04805000"],["111642.84000000","0.03583000"],["111645.97000000","0.15000000"],["111650.49000000","0.00000000"],["111651.16000000","0.13426000"],["111655.35000000","0.00000000"],["111660.82000000","0.00000000"],["111661.48000000","0.00005000"],["111661.87000000","1.22802000"],["111675.10000000","0.00187000"],["111714.39000000","0.00100000"],["111714.40000000","0.00100000"],["111714.50000000","0.00000000"],["111714.51000000","0.00000000"],["111739.99000000","0.04097000"],["111743.11000000","0.04097000"],["111751.98000000","0.04097000"],["111773.59000000","0.00000000"],["111778.39000000","0.02597000"],["111832.04000000","0.00000000"],["111846.33000000","0.00083000"],["112018.69000000","0.00000000"],["112222.03000000","0.02398000"],["113309.09000000","0.00100000"]]}
[2025-10-12T10:57:40.180Z] {"e":"depthUpdate","E":1760266660014,"s":"BTCUSDT","U":77965087731,"u":77965087885,"b":[["111634.56000000","0.14414000"],["111633.76000000","0.00010000"],["111627.94000000","0.05303000"],["111627.76000000","0.00155000"],["111626.11000000","0.19432000"],["111626.10000000","0.10688000"],["111626.09000000","0.00000000"],["111626.08000000","0.00000000"],["111626.07000000","0.00000000"],["111626.06000000","0.00000000"],["111626.05000000","0.00000000"],["111626.04000000","0.00000000"],["111622.56000000","0.00005000"],["111622.23000000","0.00000000"],["111622.22000000","0.00000000"],["111622.17000000","0.04631000"],["111622.00000000","0.00265000"],["111617.43000000","0.00100000"],["111616.50000000","0.00000000"],["109960.04000000","0.00100000"],["105550.00000000","0.06384000"],["100471.10000000","0.00024000"],["100470.00000000","0.00010000"],["100401.37000000","0.00000000"],["89307.65000000","0.00022000"]],"a":[["111634.57000000","7.61391000"],["111640.76000000","0.00000000"],["111657.39000000","0.18877000"],["111658.78000000","0.00187000"],["111665.34000000","0.00000000"],["111672.09000000","0.01402000"],["111675.10000000","0.00000000"],["111681.46000000","0.02125000"],["111714.36000000","0.00100000"],["111714.37000000","0.00100000"],["111714.39000000","0.00000000"],["111714.40000000","0.00000000"],["111741.58000000","0.00000000"],["111741.87000000","0.17904000"],["111754.20000000","0.07200000"],["111830.00000000","0.00183000"],["111846.33000000","0.00000000"],["113309.09000000","0.00100000"]]}
[2025-10-12T10:57:41.181Z] {"e":"depthUpdate","E":1760266661014,"s":"BTCUSDT","U":77965087886,"u":77965088264,"b":[["111634.56000000","0.41562000"],["111634.55000000","0.00110000"],["111634.51000000","0.02636000"],["111634.50000000","0.00020000"],["111634.48000000","0.00010000"],["111634.39000000","0.00010000"],["111634.38000000","0.05341000"],["111634.37000000","0.05683000"],["111634.36000000","0.00010000"],["111633.99000000","0.00000000"],["111633.90000000","0.00722000"],["111633.89000000","0.00000000"],["111633.76000000","0.00000000"],["111632.80000000","0.00000000"],["111632.79000000","0.00010000"],["111630.53000000","0.00010000"],["111630.52000000","0.05256000"],["111630.01000000","0.00000000"],["111628.89000000","0.00000000"],["111628.88000000","0.00000000"],["111628.87000000","0.01797000"],["111628.46000000","0.00000000"],["111627.95000000","0.00000000"],["111627.94000000","0.00000000"],["111627.76000000","0.00150000"],["111627.34000000","0.00000000"],["111626.21000000","0.18993000"],["111626.20000000","0.11952000"],["111626.19000000","0.00000000"],["111626.18000000","0.00000000"],["111626.17000000","0.00000000"],["111626.16000000","0.00000000"],["111626.15000000","0.00000000"],["111626.14000000","0.00000000"],["111626.13000000","0.00000000"],["111626.12000000","0.00000000"],["111626.11000000","0.00000000"],["111626.10000000","0.00000000"],["111625.87000000","0.00005000"],["111624.98000000","0.00000000"],["111624.75000000","0.04115000"],["111624.00000000","0.00260000"],["111623.00000000","0.00000000"],["111622.70000000","0.00000000"],["111622.69000000","0.00000000"],["111622.56000000","0.00005000"],["111622.50000000","0.00305000"],["111622.23000000","0.09386000"],["111622.22000000","0.00000000"],["111622.21000000","0.00000000"],["111622.17000000","0.04636000"],["111622.01000000","0.00000000"],["111620.37000000","0.00005000"],["111620.25000000","0.00005000"],["111620.10000000","0.15528000"],["111619.64000000","0.00100000"],["111619.02000000","0.01762000"],["111617.57000000","0.00000000"],["111617.43000000","0.00000000"],["111616.51000000","0.00000000"],["111616.50000000","0.00000000"],["111616.49000000","0.00000000"],["111616.39000000","0.16317000"],["111616.38000000","0.44436000"],["111615.28000000","0.40306000"],["111613.29000000","0.04000000"],["111610.84000000","0.00000000"],["111610.70000000","0.00000000"],["111606.29000000","0.00000000"],["111606.25000000","0.00000000"],["111606.24000000","0.01390000"],["111592.20000000","0.00000000"],["111588.19000000","0.88269000"],["111585.09000000","0.32246000"],["111579.35000000","0.04415000"],["111578.73000000","0.00000000"],["111578.57000000","0.00000000"],["111578.41000000","0.00000000"],["111578.27000000","0.06832000"],["111575.67000000","0.00000000"],["111572.05000000","0.04283000"],["111567.33000000","0.00000000"],["111552.06000000","0.00000000"],["111550.54000000","0.00000000"],["111391.20000000","0.00000000"],["111376.52000000","0.02597000"],["111149.18000000","0.00000000"],["111145.27000000","0.00000000"],["111131.38000000","0.03734000"],["110466.50000000","0.00239000"],["109960.04000000","0.00100000"],["102722.08000000","0.00000000"],["100471.00000000","0.01637000"],["100470.00000000","0.00010000"],["89307.65000000","0.00022000"]],"a":[["111634.57000000","7.12728000"],["111635.00000000","0.44796000"],["111635.01000000","0.21511000"],["111635.02000000","0.45030000"],["111635.03000000","0.00005000"],["111635.17000000","0.00901000"],["111635.70000000","0.00005000"],["111635.72000000","0.00000000"],["111636.45000000","0.04017000"],["111637.94000000","0.04662000"],["111638.91000000","0.00537000"],["111639.02000000","0.00000000"],["111639.32000000","0.01354000"],["111640.76000000","0.04000000"],["111641.97000000","0.00100000"],["111642.45000000","0.04800000"],["111642.84000000","0.00000000"],["111643.34000000","0.04033000"],["111644.60000000","0.03583000"],["111645.33000000","0.00000000"],["111646.51000000","0.00000000"],["111648.17000000","0.00000000"],["111667.72000000","0.32222000"],["111667.85000000","0.17904000"],["111685.99000000","0.02398000"],["111704.79000000","0.00000000"],["111714.35000000","0.00000000"],["111714.37000000","0.00100000"],["111718.19000000","0.02280000"],["111722.53000000","0.00000000"],["111735.80000000","0.02091000"],["111877.08000000","0.00000000"],["111912.31000000","0.00000000"],["112033.44000000","0.55838000"],["112183.05000000","0.00000000"],["112588.63000000","0.00234000"],["113309.09000000","0.00100000"]]}
[2025-10-12T10:57:42.180Z] {"e":"depthUpdate","E":1760266662014,"s":"BTCUSDT","U":77965088265,"u":77965088573,"b":[["111634.56000000","0.56965000"],["111634.55000000","0.00115000"],["111634.38000000","0.05341000"],["111632.78000000","0.01802000"],["111631.10000000","0.00542000"],["111630.54000000","0.00000000"],["111630.53000000","0.00005000"],["111628.87000000","0.01797000"],["111627.76000000","0.00150000"],["111626.30000000","0.15888000"],["111626.29000000","0.18642000"],["111626.28000000","0.00000000"],["111626.27000000","0.00000000"],["111626.26000000","0.00000000"],["111626.25000000","0.00000000"],["111626.24000000","0.00000000"],["111626.23000000","0.00000000"],["111626.22000000","0.00000000"],["111626.21000000","0.00000000"],["111626.20000000","0.00000000"],["111625.87000000","0.00005000"],["111625.75000000","0.04024000"],["111625.14000000","0.29548000"],["111622.56000000","0.00005000"],["111622.23000000","0.05411000"],["111622.00000000","0.00265000"],["111620.10000000","0.00000000"],["111616.39000000","0.16317000"],["111606.24000000","0.00000000"],["111606.16000000","0.01390000"],["111606.15000000","0.00000000"],["111600.00000000","0.22561000"],["111572.05000000","0.00000000"],["111570.20000000","0.04048000"],["111559.17000000","0.04283000"],["111417.17000000","0.08794000"],["111381.89000000","4.76656000"],["111377.28000000","0.02681000"],["111334.56000000","0.00000000"],["110964.76000000","0.00019000"],["109960.04000000","0.00100000"],["108100.00000000","17.51964000"],["103931.00000000","0.00006000"],["100470.00000000","0.00010000"],["89307.65000000","0.00022000"],["40188.44000000","0.00060000"],["33000.00000000","3.87311000"]],"a":[["111634.57000000","7.12841000"],["111634.58000000","0.30229000"],["111634.59000000","0.00360000"],["111634.60000000","0.27903000"],["111634.61000000","0.21527000"],["111634.73000000","0.00901000"],["111634.99000000","0.00000000"],["111635.00000000","0.00010000"],["111635.01000000","0.21506000"],["111635.02000000","0.00000000"],["111635.17000000","0.00901000"],["111636.45000000","0.00005000"],["111637.93000000","0.00005000"],["111637.94000000","0.04662000"],["111638.01000000","0.00000000"],["111638.76000000","0.00117000"],["111638.91000000","0.00542000"],["111638.92000000","0.00005000"],["111638.93000000","0.27037000"],["111641.40000000","0.25778000"],["111641.73000000","0.02703000"],["111642.18000000","0.40306000"],["111642.19000000","0.35816000"],["111642.20000000","0.00000000"],["111642.21000000","0.00000000"],["111642.22000000","0.04124000"],["111642.42000000","0.05220000"],["111644.60000000","0.00000000"],["111645.96000000","0.15000000"],["111645.97000000","0.00000000"],["111645.98000000","0.73990000"],["111645.99000000","0.00000000"],["111648.03000000","0.32228000"],["111650.03000000","0.00000000"],["111650.49000000","0.00000000"],["111650.51000000","0.95852000"],["111650.52000000","0.00000000"],["111653.34000000","0.00000000"],["111658.80000000","0.00000000"],["111667.72000000","0.00000000"],["111714.36000000","0.00000000"],["111714.37000000","0.00000000"],["111715.36000000","0.00100000"],["111715.37000000","0.00100000"],["111865.39000000","4.74208000"],["111868.52000000","0.08794000"],["112029.75000000","0.55838000"],["112033.44000000","0.00000000"],["113309.09000000","0.00100000"],["116394.39000000","0.00000000"]]}
[2025-10-12T10:57:43.180Z] {"e":"depthUpdate","E":1760266663014,"s":"BTCUSDT","U":77965088574,"u":77965088742,"b":[["111634.56000000","0.56537000"],["111634.55000000","0.00115000"],["111634.51000000","0.02636000"],["111634.50000000","0.00020000"],["111634.40000000","0.00010000"],["111634.39000000","0.08127000"],["111634.38000000","0.00020000"],["111633.99000000","0.00000000"],["111632.78000000","0.01802000"],["111632.00000000","0.00270000"],["111631.87000000","0.00005000"],["111631.86000000","0.04090000"],["111630.53000000","0.00005000"],["111630.52000000","0.05256000"],["111628.88000000","0.00000000"],["111628.87000000","0.01792000"],["111627.76000000","0.00155000"],["111626.31000000","0.00000000"],["111626.30000000","0.11525000"],["111626.29000000","0.00000000"],["111622.50000000","0.00300000"],["111622.23000000","0.05406000"],["111622.17000000","0.04631000"],["111619.64000000","0.00000000"],["111616.39000000","0.00000000"],["111616.16000000","0.00100000"],["111606.16000000","0.00000000"],["111606.11000000","0.00000000"],["111588.19000000","0.88221000"],["111586.21000000","1.21364000"],["111584.12000000","0.00000000"],["111551.80000000","0.13463000"],["111540.18000000","0.00164000"],["111540.01000000","0.00000000"],["111428.26000000","0.00065000"],["111428.25000000","0.00000000"],["111396.11000000","0.00574000"],["111393.91000000","0.00000000"],["110964.76000000","0.00000000"],["110466.50000000","0.00000000"],["109960.04000000","0.00100000"],["109000.00000000","95.75046000"],["100471.00000000","0.01637000"],["100470.00000000","0.00010000"],["89307.65000000","0.00022000"]],"a":[["111634.57000000","7.13113000"],["111637.94000000","0.04667000"],["111638.49000000","0.00100000"],["111641.73000000","0.02698000"],["111641.97000000","0.00000000"],["111644.94000000","0.00043000"],["111650.50000000","1.25396000"],["111661.87000000","0.00000000"],["111662.23000000","1.17223000"],["111718.12000000","0.06016000"],["111748.19000000","0.00000000"],["112029.75000000","0.00000000"],["112588.63000000","0.00000000"],["113309.09000000","0.00100000"],["115822.86000000","0.00021000"]]}
[2025-10-12T10:57:44.180Z] {"e":"depthUpdate","E":1760266664014,"s":"BTCUSDT","U":77965088743,"u":77965088818,"b":[["111634.56000000","0.57125000"],["111634.55000000","0.00115000"],["111634.39000000","0.05325000"],["111632.78000000","0.01802000"],["111632.00000000","0.00265000"],["111631.87000000","0.00000000"],["111631.86000000","0.00000000"],["111628.87000000","0.01797000"],["111626.33000000","0.18467000"],["111626.32000000","0.11525000"],["111626.31000000","0.00000000"],["111626.30000000","0.00000000"],["111625.15000000","0.00000000"],["111622.50000000","0.00305000"],["111616.39000000","0.00000000"],["111606.41000000","0.00000000"],["111606.26000000","0.00000000"],["111606.15000000","0.01390000"],["109960.04000000","0.00100000"],["108100.00000000","17.51982000"],["89307.65000000","0.00022000"],["60000.00000000","53.14032000"],["40188.44000000","0.00075000"]],"a":[["111634.57000000","7.17639000"],["112022.38000000","0.00000000"],["113309.09000000","0.00100000"],["146960.00000000","0.00035000"]]}
[2025-10-12T10:57:45.180Z] {"e":"depthUpdate","E":1760266665014,"s":"BTCUSDT","U":77965088819,"u":77965089113,"b":[["111634.56000000","0.37500000"],["111634.55000000","0.00110000"],["111634.51000000","0.02631000"],["111634.50000000","0.00020000"],["111634.41000000","0.00010000"],["111634.40000000","0.03628000"],["111634.39000000","0.00010000"],["111634.38000000","0.00000000"],["111634.37000000","0.00000000"],["111634.36000000","0.00000000"],["111633.99000000","0.00010000"],["111633.90000000","0.00722000"],["111632.80000000","0.00010000"],["111632.79000000","0.04439000"],["111632.78000000","0.01802000"],["111632.38000000","0.00000000"],["111631.10000000","0.00542000"],["111630.56000000","0.00000000"],["111630.55000000","0.00000000"],["111630.54000000","0.00000000"],["111630.53000000","0.00010000"],["111630.52000000","0.05256000"],["111628.88000000","0.00000000"],["111628.87000000","0.01797000"],["111627.08000000","0.15264000"],["111627.07000000","0.11525000"],["111627.06000000","0.00005000"],["111626.37000000","0.00000000"],["111626.36000000","0.00000000"],["111626.35000000","0.00000000"],["111626.34000000","0.00000000"],["111626.33000000","0.00000000"],["111626.32000000","0.00000000"],["111625.15000000","0.00000000"],["111624.00000000","0.00265000"],["111623.81000000","0.00000000"],["111622.50000000","0.00305000"],["111622.23000000","0.05411000"],["111620.10000000","0.00000000"],["111616.39000000","0.16317000"],["111608.49000000","0.15000000"],["111606.15000000","0.00000000"],["111606.10000000","0.00000000"],["111604.62000000","0.00000000"],["111578.27000000","0.00000000"],["111578.23000000","0.06696000"],["111551.80000000","0.00000000"],["111381.89000000","0.00000000"],["111000.00000000","16.84000000"],["110964.76000000","0.00019000"],["109960.04000000","0.00100000"],["107000.00000000","45.29391000"],["106000.00000000","32.68589000"],["100471.00000000","0.01637000"],["100470.00000000","0.00010000"],["89307.65000000","0.00022000"],["60000.00000000","53.14022000"]],"a":[["111634.57000000","7.17201000"],["111634.61000000","0.21527000"],["111634.73000000","0.00906000"],["111634.98000000","0.00010000"],["111634.99000000","0.06656000"],["111635.01000000","0.21501000"],["111637.93000000","0.00000000"],["111638.92000000","0.00000000"],["111638.93000000","0.27032000"],["111658.78000000","0.00000000"],["111671.15000000","0.00254000"],["111672.09000000","0.00000000"],["111865.39000000","0.00000000"],["112022.38000000","0.55838000"],["113309.09000000","0.00100000"]]}
[2025-10-12T10:57:46.180Z] {"e":"depthUpdate","E":1760266666014,"s":"BTCUSDT","U":77965089114,"u":77965089264,"b":[["111634.56000000","0.29605000"],["111634.55000000","0.00110000"],["111634.51000000","0.02641000"],["111634.50000000","0.07267000"],["111634.49000000","0.00020000"],["111634.48000000","0.02172000"],["111634.47000000","0.00010000"],["111634.41000000","0.00000000"],["111634.40000000","0.00000000"],["111634.39000000","0.00000000"],["111633.99000000","0.00000000"],["111632.78000000","0.01797000"],["111630.53000000","0.00000000"],["111628.87000000","0.01792000"],["111627.09000000","0.20665000"],["111627.07000000","0.00000000"],["111625.15000000","0.15352000"],["111607.24000000","0.00000000"],["111606.58000000","0.01390000"],["111606.15000000","0.00000000"],["111440.23000000","0.00000000"],["111419.58000000","0.02687000"],["111383.16000000","4.82218000"],["111303.66000000","0.00000000"],["110964.76000000","0.00000000"],["109960.04000000","0.00100000"],["106500.00000000","5.34919000"],["102722.08000000","0.00010000"],["100470.00000000","0.00010000"],["89307.65000000","0.00022000"],["42000.00000000","1.49196000"],["40188.44000000","0.00090000"],["33000.00000000","3.87311000"]],"a":[["111634.57000000","7.06058000"],["111634.61000000","0.21506000"],["111705.33000000","2.04838000"],["111806.73000000","0.44887000"],["111813.44000000","0.00083000"],["111830.00000000","0.00100000"],["111861.61000000","0.08894000"],["111864.29000000","0.08894000"],["111865.47000000","4.72584000"],["111866.61000000","0.08894000"],["111868.76000000","0.08894000"],["111916.47000000","0.00000000"],["111918.70000000","0.00000000"],["111920.56000000","0.00000000"],["111921.89000000","0.00000000"],["111963.60000000","0.05995000"],["111964.14000000","0.05995000"],["111969.20000000","0.02687000"],["111971.91000000","0.00000000"],["112022.38000000","0.55838000"],["112025.28000000","0.00000000"],["112029.29000000","0.00000000"],["112080.73000000","0.00000000"],["113309.09000000","0.00100000"]]}
[2025-10-12T10:58:44.216Z] Snapshot loaded successfully.
[2025-10-12T10:58:47.244Z] WebSocket connected successfully.
[2025-10-12T10:58:48.187Z] {"e":"depthUpdate","E":1760266728014,"s":"BTCUSDT","U":77965097071,"u":77965097146,"b":[["111634.54000000","0.48800000"],["111634.53000000","0.00105000"],["111628.42000000","0.01797000"],["111627.76000000","0.00150000"],["111627.73000000","0.02754000"],["111626.87000000","0.00000000"],["111626.55000000","0.00005000"],["111626.27000000","0.00000000"],["111626.24000000","0.29548000"],["111625.81000000","0.00005000"],["111624.00000000","0.00265000"],["111623.60000000","0.03939000"],["111622.48000000","0.04043000"],["111622.17000000","0.04631000"],["111621.39000000","0.00000000"],["111620.32000000","0.00000000"],["111606.58000000","0.01390000"],["111606.50000000","0.00000000"],["111604.20000000","0.00000000"],["111587.16000000","0.32245000"],["110150.00000000","0.02394000"],["109960.02000000","0.00100000"],["106970.40000000","0.00012000"],["103931.00000000","0.00000000"],["102703.80000000","0.00000000"],["100470.00000000","0.00010000"],["89307.64000000","0.00022000"],["42000.00000000","1.49096000"],["40188.44000000","0.00405000"]],"a":[["111634.55000000","7.22078000"],["111635.87000000","0.00005000"],["111636.09000000","0.02689000"],["111640.86000000","0.04000000"],["111642.65000000","0.00000000"],["111648.47000000","0.32227000"],["111649.96000000","0.00000000"],["111664.61000000","0.00000000"],["111715.37000000","0.00000000"],["111715.38000000","0.00000000"],["111716.37000000","0.00100000"],["111716.38000000","0.00100000"],["112085.36000000","0.00000000"],["112134.64000000","0.03672000"],["113309.07000000","0.00100000"]]}
[2025-10-12T10:58:49.185Z] {"e":"depthUpdate","E":1760266729014,"s":"BTCUSDT","U":77965097147,"u":77965097252,"b":[["111634.54000000","1.99378000"],["111634.53000000","0.00105000"],["111634.17000000","0.07479000"],["111634.16000000","0.01354000"],["111634.14000000","0.00000000"],["111634.13000000","0.00000000"],["111633.88000000","0.05195000"],["111632.00000000","0.00270000"],["111631.25000000","0.04089000"],["111627.76000000","0.00150000"],["111627.73000000","0.11151000"],["111624.00000000","0.00260000"],["111623.60000000","0.03955000"],["111620.22000000","0.00000000"],["111619.02000000","0.00000000"],["111618.13000000","0.17907000"],["111615.89000000","0.00100000"],["111612.43000000","0.00000000"],["111609.07000000","0.00447000"],["111606.58000000","0.00000000"],["111606.26000000","0.01390000"],["111603.62000000","0.32240000"],["111587.69000000","0.06017000"],["111587.16000000","0.00000000"],["111585.63000000","0.00000000"],["111583.94000000","0.00000000"],["111570.81000000","0.04283000"],["111392.54000000","0.00000000"],["111390.00000000","4.85547000"],["109960.02000000","0.00100000"],["106000.00000000","32.64502000"],["103000.00000000","75.23204000"],["100471.00000000","0.01637000"],["100470.00000000","0.00010000"],["89307.64000000","0.00022000"]],"a":[["111634.55000000","7.46525000"],["111634.56000000","0.12727000"],["111634.95000000","0.01359000"],["111635.41000000","0.17192000"],["111635.80000000","0.00000000"],["111635.87000000","0.00000000"],["111636.09000000","0.02694000"],["111638.22000000","0.00100000"],["111640.85000000","0.09037000"],["111641.32000000","0.00000000"],["111642.32000000","0.06646000"],["111705.13000000","0.00254000"],["111714.30000000","0.00000000"],["111744.98000000","0.04297000"],["111787.79000000","0.02597000"],["111817.88000000","0.00000000"],["111822.72000000","0.00005000"],["111847.61000000","0.00083000"],["111856.79000000","0.00000000"],["111868.28000000","4.85492000"],["111870.12000000","0.00000000"],["112026.07000000","0.55838000"],["112033.44000000","0.00000000"],["113309.07000000","0.00100000"]]}
[2025-10-12T10:58:50.185Z] {"e":"depthUpdate","E":1760266730014,"s":"BTCUSDT","U":77965097253,"u":77965097294,"b":[["111623.60000000","0.04072000"],["111619.02000000","0.01815000"],["111606.26000000","0.00000000"],["111606.19000000","0.00000000"],["111606.15000000","0.01390000"],["111606.07000000","0.00000000"],["111595.52000000","0.00000000"],["111285.24000000","0.03583000"],["109960.02000000","0.00100000"],["100470.00000000","0.00010000"],["89307.64000000","0.00022000"]],"a":[["111634.55000000","7.46808000"],["111634.58000000","0.01449000"],["111666.93000000","0.00000000"],["111715.37000000","0.00100000"],["111715.38000000","0.00100000"],["111716.37000000","0.00000000"],["111716.38000000","0.00000000"],["111741.98000000","0.00000000"],["111753.17000000","0.01402000"],["111787.82000000","0.02597000"],["111975.31000000","0.05194000"],["111985.22000000","0.03583000"],["112026.07000000","0.00000000"],["113309.07000000","0.00100000"]]}
[2025-10-12T10:58:51.185Z] {"e":"depthUpdate","E":1760266731014,"s":"BTCUSDT","U":77965097295,"u":77965097336,"b":[["111634.54000000","1.99211000"],["111615.89000000","0.00000000"],["111606.15000000","0.00000000"],["111606.08000000","0.01390000"],["111595.04000000","1.18049000"],["111399.28000000","0.00574000"],["111398.70000000","0.00000000"],["110964.74000000","0.00019000"],["110602.79000000","0.00000000"],["109960.02000000","0.00100000"],["100471.00000000","0.01637000"],["100470.00000000","0.00010000"],["89307.64000000","0.00022000"],["33000.00000000","3.87311000"]],"a":[["111634.55000000","7.45577000"],["111634.57000000","0.01740000"],["111638.22000000","0.00000000"],["111641.09000000","0.00100000"],["111648.47000000","0.00000000"],["111664.73000000","0.32223000"],["111665.08000000","1.19434000"],["111694.16000000","0.00254000"],["111705.13000000","0.00000000"],["111836.63000000","0.00083000"],["111847.61000000","0.00000000"],["112029.75000000","0.00000000"],["113309.07000000","0.00100000"],["148960.00000000","0.00206000"]]}
[2025-10-12T10:58:52.185Z] {"e":"depthUpdate","E":1760266732014,"s":"BTCUSDT","U":77965097337,"u":77965097388,"b":[["111634.54000000","1.99220000"],["111623.60000000","0.04130000"],["111621.77000000","0.00000000"],["111620.23000000","0.17906000"],["111620.22000000","0.00000000"],["111618.96000000","0.06897000"],["111618.13000000","0.00000000"],["111612.22000000","0.00447000"],["111610.61000000","0.35812000"],["111609.07000000","0.00000000"],["111608.48000000","0.00000000"],["111606.34000000","0.01390000"],["111606.08000000","0.00000000"],["111516.16000000","0.00000000"],["111516.05000000","0.00223000"],["110964.74000000","0.00019000"],["109960.02000000","0.00100000"],["100470.00000000","0.00010000"],["98200.00000000","3.55420000"],["89308.00000000","0.00000000"],["89307.64000000","0.00022000"],["40188.44000000","0.00420000"]],"a":[["111634.55000000","7.43878000"],["111634.56000000","0.12727000"],["111639.57000000","0.00000000"],["111640.68000000","0.00447000"],["111640.85000000","0.18601000"],["111641.43000000","0.35812000"],["111645.59000000","0.00000000"],["111682.03000000","0.00254000"],["111694.16000000","0.00000000"],["111824.50000000","0.00083000"],["111836.63000000","0.00000000"],["112029.75000000","0.55838000"],["113309.07000000","0.00100000"]]}
[2025-10-12T10:58:53.185Z] {"e":"depthUpdate","E":1760266733014,"s":"BTCUSDT","U":77965097389,"u":77965097449,"b":[["111634.54000000","2.04846000"],["111622.01000000","0.00000000"],["111621.77000000","0.00000000"],["111620.23000000","0.00000000"],["111620.22000000","0.17906000"],["111620.04000000","0.00000000"],["111606.34000000","0.00000000"],["111606.07000000","0.01390000"],["111390.03000000","4.66915000"],["111390.00000000","0.00100000"],["110964.74000000","0.00000000"],["110518.20000000","0.00005000"],["109960.02000000","0.00100000"],["102703.80000000","0.00010000"],["100471.00000000","0.01637000"],["100470.00000000","0.00010000"],["89307.64000000","0.00022000"],["40188.44000000","0.00450000"]],"a":[["111634.55000000","7.02813000"],["111641.43000000","0.00000000"],["111642.32000000","0.00000000"],["111642.41000000","0.35812000"],["111649.07000000","0.00000000"],["111682.03000000","0.00000000"],["111693.79000000","0.00218000"],["111741.98000000","0.01402000"],["111753.17000000","0.00000000"],["111868.22000000","4.77982000"],["111868.28000000","0.00000000"],["113309.07000000","0.00100000"]]}
[2025-10-12T10:58:54.186Z] {"e":"depthUpdate","E":1760266734014,"s":"BTCUSDT","U":77965097450,"u":77965097581,"b":[["111634.54000000","3.13832000"],["111634.53000000","0.00120000"],["111634.39000000","0.00906000"],["111634.17000000","0.17327000"],["111633.88000000","0.05200000"],["111632.75000000","0.03933000"],["111632.38000000","0.00005000"],["111631.63000000","0.03952000"],["111630.65000000","0.00537000"],["111630.62000000","0.29546000"],["111630.52000000","0.05251000"],["111629.53000000","0.00722000"],["111629.17000000","0.06646000"],["111628.42000000","0.06272000"],["111628.35000000","0.00000000"],["111627.73000000","0.07731000"],["111626.24000000","0.00000000"],["111624.59000000","0.00100000"],["111623.61000000","0.17906000"],["111623.60000000","0.00000000"],["111622.50000000","0.01300000"],["111622.48000000","0.00000000"],["111622.17000000","0.00156000"],["111620.22000000","0.00000000"],["111620.03000000","0.07884000"],["111618.96000000","0.06797000"],["111617.00000000","0.00405000"],["111614.43000000","0.00447000"],["111612.22000000","0.00000000"],["111606.17000000","0.01390000"],["111606.07000000","0.00000000"],["111591.90000000","0.32244000"],["111588.96000000","0.00000000"],["111588.78000000","0.04283000"],["111585.44000000","0.30224000"],["111581.20000000","0.00000000"],["111570.81000000","0.00000000"],["111526.31000000","0.00000000"],["111007.97000000","0.00000000"],["109960.02000000","0.00100000"],["106000.00000000","32.64513000"],["102703.80000000","0.00000000"],["100470.00000000","0.00010000"],["89307.64000000","0.00022000"],["60000.00000000","53.14032000"]],"a":[["111634.55000000","6.97656000"],["111640.68000000","0.00000000"],["111640.85000000","0.09037000"],["111640.86000000","0.00000000"],["111641.09000000","0.00000000"],["111641.43000000","0.00000000"],["111642.40000000","0.00447000"],["111642.41000000","0.00000000"],["111644.06000000","0.04000000"],["111645.59000000","0.35812000"],["111646.92000000","0.00100000"],["111649.06000000","0.12206000"],["111652.75000000","0.00000000"],["111652.99000000","0.32226000"],["111669.93000000","0.00000000"],["111693.79000000","0.00000000"],["111700.00000000","0.42341000"],["111704.83000000","0.00218000"],["111715.36000000","0.00000000"],["111715.37000000","0.00000000"],["111715.38000000","0.00000000"],["111716.36000000","0.00100000"],["111716.37000000","0.00100000"],["111767.43000000","0.00000000"],["111771.99000000","0.00000000"],["111773.58000000","0.00000000"],["111787.89000000","0.03134000"],["111819.98000000","0.00000000"],["111824.50000000","0.00000000"],["111832.41000000","0.00000000"],["111833.64000000","0.07521000"],["111835.66000000","0.00083000"],["111840.76000000","0.08694000"],["111970.61000000","0.00000000"],["112026.07000000","0.00000000"],["112029.75000000","0.00000000"],["112083.92000000","0.00000000"],["112133.87000000","0.03762000"],["113309.07000000","0.00100000"]]}
[2025-10-12T10:58:55.185Z] {"e":"depthUpdate","E":1760266735014,"s":"BTCUSDT","U":77965097582,"u":77965097820,"b":[["111634.54000000","3.21387000"],["111634.53000000","0.00115000"],["111634.48000000","0.02177000"],["111634.47000000","0.00010000"],["111634.40000000","0.00000000"],["111634.39000000","0.00010000"],["111634.38000000","0.00906000"],["111634.17000000","0.17322000"],["111634.16000000","0.00010000"],["111634.15000000","0.01354000"],["111633.89000000","0.00000000"],["111633.88000000","0.05200000"],["111632.75000000","0.00000000"],["111632.38000000","0.00000000"],["111632.34000000","0.00000000"],["111632.32000000","0.00000000"],["111632.31000000","0.00358000"],["111632.00000000","0.00265000"],["111631.63000000","0.00000000"],["111631.25000000","0.04094000"],["111630.65000000","0.00000000"],["111630.64000000","0.00542000"],["111630.62000000","0.00000000"],["111630.52000000","0.05256000"],["111630.00000000","0.00359000"],["111629.53000000","0.00005000"],["111629.52000000","0.00722000"],["111629.33000000","0.04054000"],["111628.42000000","0.04485000"],["111628.41000000","0.01792000"],["111628.21000000","0.33594000"],["111627.76000000","0.00155000"],["111626.00000000","0.00265000"],["111625.81000000","0.00000000"],["111623.61000000","0.00000000"],["111622.51000000","0.17906000"],["111614.01000000","0.06720000"],["111606.36000000","0.01390000"],["111606.17000000","0.00000000"],["111604.61000000","0.00000000"],["111604.59000000","0.00000000"],["111604.55000000","0.32000000"],["111520.76000000","0.06720000"],["111517.10000000","0.02997000"],["111007.97000000","0.00000000"],["110484.04000000","0.00006000"],["109960.02000000","0.00100000"],["108348.22000000","0.00006000"],["106888.88000000","0.00423000"],["106000.00000000","32.64502000"],["100471.00000000","0.01637000"],["100470.00000000","0.00010000"],["89307.64000000","0.00022000"],["60000.00000000","53.14022000"],["40188.44000000","0.00480000"]],"a":[["111634.55000000","6.96660000"],["111634.56000000","0.12722000"],["111634.57000000","0.01705000"],["111634.58000000","0.00015000"],["111634.71000000","0.00906000"],["111634.72000000","0.00000000"],["111634.93000000","0.00010000"],["111634.94000000","0.01354000"],["111634.95000000","0.00005000"],["111635.41000000","0.17197000"],["111636.08000000","0.00005000"],["111636.09000000","0.02699000"],["111636.56000000","0.00000000"],["111636.78000000","0.00358000"],["111636.79000000","0.00005000"],["111637.94000000","0.04667000"],["111638.45000000","0.00542000"],["111638.46000000","0.00000000"],["111638.93000000","0.00317000"],["111639.57000000","0.00717000"],["111639.58000000","0.00000000"],["111640.68000000","0.01792000"],["111640.69000000","0.00000000"],["111657.39000000","0.00000000"],["111748.26000000","0.00000000"],["111843.79000000","0.00000000"],["111844.14000000","0.00000000"],["111875.45000000","0.08694000"],["111877.57000000","0.08694000"],["111884.66000000","0.00000000"],["112078.24000000","0.00000000"],["112083.72000000","0.00000000"],["112128.19000000","0.03762000"],["112133.89000000","0.03762000"],["112789.93000000","0.00203000"],["112862.62000000","0.00040000"],["112951.73000000","0.00080000"],["113309.07000000","0.00100000"],["114755.68000000","0.00006000"],["116891.50000000","0.00006000"],["119027.32000000","0.00006000"],["121163.14000000","0.00006000"],["123298.96000000","0.00032000"],["125434.79000000","0.00029000"]]}
[2025-10-12T10:58:56.185Z] {"e":"depthUpdate","E":1760266736014,"s":"BTCUSDT","U":77965097821,"u":77965097905,"b":[["111634.54000000","3.21745000"],["111627.76000000","0.00150000"],["111627.73000000","0.17015000"],["111624.59000000","0.00105000"],["111622.52000000","0.40306000"],["111620.21000000","0.00000000"],["111619.93000000","0.02689000"],["111616.31000000","0.07200000"],["111614.08000000","0.12480000"],["111606.82000000","0.00000000"],["111606.36000000","0.00000000"],["111606.16000000","0.01390000"],["111521.99000000","0.07200000"],["111520.83000000","0.00000000"],["111520.76000000","0.00000000"],["111520.52000000","0.31821000"],["111520.23000000","0.02508000"],["111520.00000000","0.00349000"],["111519.76000000","0.00000000"],["111517.10000000","0.00000000"],["109960.02000000","0.00100000"],["106212.40000000","0.00006000"],["104076.58000000","0.00006000"],["101940.76000000","0.00006000"],["99804.94000000","0.00006000"],["89307.64000000","0.00022000"],["42000.00000000","1.49196000"],["40188.44000000","0.00495000"]],"a":[["111634.55000000","6.98263000"],["111634.56000000","0.12722000"],["111634.57000000","0.01705000"],["111634.71000000","0.00911000"],["111634.87000000","0.00010000"],["111634.88000000","0.02699000"],["111634.95000000","0.00000000"],["111635.41000000","0.17192000"],["111636.08000000","0.00000000"],["111636.09000000","0.00005000"],["111682.06000000","0.00156000"],["111704.83000000","0.00000000"],["111720.43000000","0.00000000"],["111726.86000000","0.00218000"],["111741.98000000","0.01402000"],["111779.11000000","0.00000000"],["111803.57000000","0.00000000"],["111811.90000000","0.00000000"],["111817.87000000","0.00000000"],["111835.66000000","0.00000000"],["111836.29000000","0.08694000"],["111839.20000000","0.08694000"],["111841.00000000","0.08694000"],["111851.27000000","0.00000000"],["111857.70000000","0.00083000"],["111905.30000000","0.02498000"],["113309.07000000","0.00100000"]]}
[2025-10-12T10:58:57.185Z] {"e":"depthUpdate","E":1760266737014,"s":"BTCUSDT","U":77965097906,"u":77965097993,"b":[["111634.54000000","3.21745000"],["111634.53000000","0.00115000"],["111634.38000000","0.00906000"],["111634.17000000","0.19306000"],["111634.16000000","0.00000000"],["111633.89000000","0.00005000"],["111630.64000000","0.00542000"],["111630.55000000","0.29552000"],["111630.52000000","0.05251000"],["111629.33000000","0.03984000"],["111628.41000000","0.01797000"],["111628.21000000","0.04014000"],["111627.70000000","0.00100000"],["111626.00000000","0.00260000"],["111624.59000000","0.00005000"],["111622.68000000","0.00072000"],["111622.49000000","0.00000000"],["111620.72000000","0.04800000"],["111611.26000000","0.00000000"],["111606.25000000","0.01390000"],["111606.22000000","0.00000000"],["111606.16000000","0.00000000"],["111526.43000000","0.00000000"],["111521.99000000","0.00000000"],["111392.60000000","4.76505000"],["111390.03000000","0.00000000"],["111334.54000000","0.00000000"],["111007.97000000","0.00000000"],["109960.02000000","0.00100000"],["100471.00000000","0.01637000"],["100470.00000000","0.00010000"],["100000.00000000","214.22896000"],["97669.12000000","0.00029000"],["89307.64000000","0.00022000"],["33000.00000000","3.87311000"]],"a":[["111634.55000000","6.89351000"],["111639.57000000","0.00722000"],["111640.70000000","0.00000000"],["111640.85000000","0.06005000"],["111641.44000000","0.04074000"],["111646.92000000","0.00000000"],["111650.03000000","0.00100000"],["111663.98000000","0.01402000"],["111665.79000000","0.20530000"],["111741.98000000","0.00000000"],["111779.36000000","0.02597000"],["111788.23000000","0.02597000"],["111865.93000000","0.00000000"],["111868.22000000","0.00000000"],["111870.05000000","4.64294000"],["112075.52000000","0.00000000"],["112080.92000000","0.00000000"],["112086.06000000","0.00000000"],["112122.71000000","0.03672000"],["112128.55000000","0.03672000"],["112134.30000000","0.03672000"],["113309.07000000","0.00100000"]]}
[2025-10-12T10:58:58.186Z] {"e":"depthUpdate","E":1760266738014,"s":"BTCUSDT","U":77965097994,"u":77965098743,"b":[["111634.54000000","3.47607000"],["111634.53000000","0.00550000"],["111634.48000000","0.02177000"],["111634.47000000","0.00010000"],["111634.40000000","0.00000000"],["111634.39000000","0.00000000"],["111634.38000000","0.00906000"],["111634.17000000","0.37155000"],["111634.15000000","0.01359000"],["111634.01000000","0.04485000"],["111633.89000000","0.00000000"],["111633.88000000","0.05200000"],["111633.78000000","0.00005000"],["111632.98000000","0.00000000"],["111632.60000000","0.29551000"],["111632.38000000","0.00005000"],["111632.31000000","0.00358000"],["111632.15000000","0.00000000"],["111631.25000000","0.04089000"],["111630.65000000","0.00000000"],["111630.64000000","0.00542000"],["111630.63000000","0.00000000"],["111630.58000000","0.40306000"],["111630.57000000","0.04809000"],["111630.55000000","0.00000000"],["111629.31000000","0.00005000"],["111629.18000000","0.00000000"],["111629.17000000","0.06651000"],["111628.88000000","0.00100000"],["111628.68000000","0.00044000"],["111628.50000000","0.00400000"],["111628.43000000","0.00000000"],["111628.42000000","0.17915000"],["111628.12000000","0.00005000"],["111627.76000000","0.00150000"],["111627.73000000","0.30684000"],["111627.70000000","0.00000000"],["111627.43000000","0.00043000"],["111627.09000000","0.40306000"],["111626.55000000","0.00000000"],["111626.25000000","0.00000000"],["111626.24000000","0.00000000"],["111626.00000000","0.00260000"],["111625.49000000","0.04000000"],["111624.89000000","0.00000000"],["111624.87000000","0.00000000"],["111624.81000000","0.02688000"],["111624.59000000","0.00000000"],["111623.37000000","0.00300000"],["111622.80000000","0.00000000"],["111622.68000000","0.00000000"],["111622.54000000","0.15000000"],["111622.51000000","0.00000000"],["111622.50000000","0.01000000"],["111622.17000000","0.05436000"],["111622.16000000","0.05760000"],["111621.76000000","0.00000000"],["111621.74000000","0.00000000"],["111621.51000000","0.00000000"],["111621.46000000","0.00000000"],["111620.04000000","0.00000000"],["111619.93000000","0.00000000"],["111619.07000000","0.00000000"],["111618.27000000","0.00447000"],["111618.26000000","0.06240000"],["111616.40000000","0.00000000"],["111615.35000000","0.00000000"],["111615.18000000","0.35810000"],["111614.77000000","0.13426000"],["111614.43000000","0.00000000"],["111614.42000000","0.00000000"],["111613.99000000","0.00000000"],["111613.26000000","0.04415000"],["111612.50000000","0.00000000"],["111610.62000000","1.24028000"],["111610.61000000","1.25396000"],["111610.50000000","0.00000000"],["111610.32000000","0.08504000"],["111610.19000000","0.00000000"],["111608.50000000","0.04283000"],["111608.01000000","0.32239000"],["111606.28000000","0.00000000"],["111606.25000000","0.00000000"],["111606.14000000","0.01390000"],["111605.00000000","0.00400000"],["111603.30000000","0.00000000"],["111602.94000000","0.22377000"],["111602.72000000","0.00000000"],["111601.18000000","0.32241000"],["111599.25000000","0.00000000"],["111599.00000000","0.00000000"],["111597.57000000","0.00000000"],["111595.45000000","0.00000000"],["111595.04000000","0.00000000"],["111594.42000000","0.00000000"],["111593.67000000","0.00000000"],["111593.11000000","0.00000000"],["111593.06000000","1.19195000"],["111591.90000000","0.00000000"],["111590.79000000","0.00009000"],["111590.75000000","0.30215000"],["111589.08000000","0.00000000"],["111588.78000000","0.00000000"],["111588.75000000","0.13436000"],["111588.57000000","0.00018000"],["111588.29000000","0.00000000"],["111587.65000000","0.00000000"],["111586.08000000","0.00000000"],["111585.44000000","0.00007000"],["111584.61000000","0.00000000"],["111583.81000000","0.20545000"],["111580.40000000","0.00009000"],["111577.90000000","0.00000000"],["111572.86000000","0.00000000"],["111568.32000000","0.00000000"],["111567.05000000","0.00000000"],["111552.47000000","0.13426000"],["111551.77000000","0.00000000"],["111551.69000000","0.00000000"],["111550.91000000","0.00000000"],["111549.71000000","0.13426000"],["111545.06000000","0.00090000"],["111544.38000000","0.13426000"],["111542.57000000","0.00000000"],["111541.61000000","0.06646000"],["111540.20000000","0.00164000"],["111540.19000000","0.00000000"],["111528.97000000","0.00000000"],["111528.90000000","0.00000000"],["111528.79000000","0.00000000"],["111528.66000000","0.22377000"],["111528.55000000","0.00000000"],["111528.52000000","0.00000000"],["111528.23000000","0.00000000"],["111527.29000000","0.00000000"],["111527.26000000","0.00000000"],["111526.41000000","0.13436000"],["111525.82000000","0.00000000"],["111525.66000000","0.00000000"],["111525.06000000","0.00000000"],["111524.96000000","0.00000000"],["111428.27000000","0.00065000"],["111428.26000000","0.00000000"],["111367.72000000","0.00467000"],["111359.92000000","0.00000000"],["111007.97000000","0.89110000"],["109960.02000000","0.00100000"],["100470.00000000","0.00010000"],["89307.64000000","0.00022000"],["42000.00000000","1.49096000"]],"a":[["111634.55000000","4.05109000"],["111634.56000000","0.00618000"],["111634.57000000","0.01695000"],["111634.70000000","0.00090000"],["111634.71000000","0.00906000"],["111634.77000000","0.00010000"],["111634.78000000","0.29555000"],["111634.87000000","0.00000000"],["111634.88000000","0.00000000"],["111634.93000000","0.00000000"],["111634.94000000","0.01359000"],["111635.02000000","0.00000000"],["111635.05000000","0.00000000"],["111635.40000000","0.00000000"],["111635.41000000","0.00000000"],["111636.41000000","0.00000000"],["111636.51000000","0.00000000"],["111636.52000000","0.00000000"],["111636.63000000","0.00010000"],["111636.64000000","0.04357000"],["111636.78000000","0.00358000"],["111636.79000000","0.00000000"],["111636.89000000","0.00000000"],["111637.74000000","0.00000000"],["111637.75000000","0.00000000"],["111637.93000000","0.00010000"],["111637.94000000","0.04667000"],["111638.25000000","0.00000000"],["111638.69000000","0.00000000"],["111639.14000000","0.00000000"],["111639.57000000","0.00732000"],["111639.84000000","0.00000000"],["111640.01000000","0.00000000"],["111640.02000000","0.02688000"],["111640.68000000","0.01792000"],["111640.85000000","0.00000000"],["111641.25000000","0.07929000"],["111641.26000000","0.17187000"],["111641.44000000","0.00000000"],["111641.73000000","0.00000000"],["111642.00000000","0.00000000"],["111642.40000000","0.00000000"],["111642.42000000","0.05225000"],["111642.45000000","0.00000000"],["111642.56000000","0.00000000"],["111642.72000000","0.00000000"],["111643.00000000","0.00000000"],["111643.44000000","0.04105000"],["111644.06000000","0.00000000"],["111644.39000000","0.00000000"],["111644.56000000","0.04115000"],["111645.47000000","0.02005000"],["111645.59000000","0.00000000"],["111645.60000000","0.32730000"],["111645.71000000","0.00447000"],["111645.72000000","0.00300000"],["111645.73000000","0.00000000"],["111646.66000000","0.00000000"],["111646.67000000","0.04000000"],["111646.68000000","0.00000000"],["111646.74000000","0.00000000"],["111646.87000000","0.00000000"],["111647.57000000","0.00070000"],["111647.67000000","0.00072000"],["111647.77000000","0.00000000"],["111647.78000000","0.00000000"],["111647.86000000","0.00000000"],["111647.87000000","0.00000000"],["111647.98000000","0.00328000"],["111648.31000000","0.00000000"],["111648.53000000","0.00000000"],["111648.56000000","0.01787000"],["111648.92000000","0.00000000"],["111649.43000000","0.00000000"],["111649.83000000","0.00000000"],["111650.01000000","0.00000000"],["111650.03000000","0.00000000"],["111650.06000000","0.00000000"],["111650.07000000","0.35810000"],["111650.08000000","0.08504000"],["111650.10000000","0.00000000"],["111650.11000000","0.00000000"],["111650.49000000","0.15000000"],["111650.51000000","0.23113000"],["111650.55000000","0.45000000"],["111650.66000000","0.00000000"],["111650.77000000","0.00000000"],["111651.21000000","0.00100000"],["111651.30000000","0.11190000"],["111651.68000000","0.00000000"],["111651.83000000","0.00000000"],["111652.03000000","0.00000000"],["111652.24000000","0.00000000"],["111652.99000000","0.00000000"],["111653.26000000","0.00000000"],["111653.37000000","0.00000000"],["111653.43000000","0.00000000"],["111653.48000000","0.00000000"],["111653.55000000","0.00005000"],["111654.86000000","0.04000000"],["111655.31000000","0.00000000"],["111655.37000000","0.00000000"],["111655.74000000","0.40306000"],["111655.98000000","0.00000000"],["111656.00000000","0.37317000"],["111656.88000000","0.00300000"],["111658.21000000","0.00000000"],["111658.31000000","0.13426000"],["111659.07000000","0.00000000"],["111659.09000000","0.00000000"],["111659.17000000","0.08504000"],["111659.76000000","0.32224000"],["111659.84000000","0.00000000"],["111661.87000000","0.08504000"],["111662.07000000","0.05280000"],["111662.46000000","0.00000000"],["111664.73000000","0.00000000"],["111665.08000000","0.00000000"],["111666.21000000","0.13426000"],["111667.18000000","0.00000000"],["111668.74000000","0.04800000"],["111669.96000000","0.32221000"],["111670.07000000","0.05696000"],["111672.41000000","1.21353000"],["111677.40000000","0.00000000"],["111682.25000000","0.00010000"],["111682.95000000","0.00005000"],["111687.42000000","0.00005000"],["111716.36000000","0.00000000"],["111716.37000000","0.00000000"],["111717.41000000","0.00000000"],["111717.42000000","0.00000000"],["111717.46000000","0.00100000"],["111717.47000000","0.00100000"],["111718.42000000","0.00000000"],["111718.43000000","0.00000000"],["111731.30000000","0.04800000"],["111733.17000000","0.00000000"],["111738.98000000","0.00000000"],["111741.99000000","0.00223000"],["111744.26000000","0.02280000"],["111750.24000000","0.04947000"],["111751.83000000","0.05280000"],["111760.41000000","0.04800000"],["111774.67000000","0.00000000"],["111793.21000000","0.02597000"],["111853.17000000","0.00089000"],["111857.57000000","0.02597000"],["111927.22000000","0.00000000"],["111981.53000000","0.02597000"],["112009.46000000","0.00000000"],["112085.68000000","0.00000000"],["112143.06000000","0.03672000"],["113309.07000000","0.00100000"]]}
[2025-10-12T10:58:59.185Z] {"e":"depthUpdate","E":1760266739014,"s":"BTCUSDT","U":77965098744,"u":77965098858,"b":[["111634.54000000","3.47607000"],["111634.53000000","0.00550000"],["111634.15000000","0.01354000"],["111634.01000000","0.00005000"],["111633.89000000","0.00010000"],["111632.61000000","0.00005000"],["111631.25000000","0.04094000"],["111630.43000000","0.01747000"],["111629.17000000","0.06656000"],["111628.42000000","0.22390000"],["111627.43000000","0.00000000"],["111606.24000000","0.01390000"],["111606.14000000","0.00000000"],["111601.12000000","0.22377000"],["111595.92000000","0.32243000"],["111523.56000000","0.07521000"],["111522.97000000","0.22377000"],["111516.45000000","0.00000000"],["111142.69000000","0.03583000"],["109960.02000000","0.00100000"],["102703.80000000","0.00000000"],["100471.00000000","0.01637000"],["100470.00000000","0.00010000"],["89307.64000000","0.00022000"]],"a":[["111634.55000000","4.05102000"],["111634.56000000","0.00623000"],["111634.57000000","0.01695000"],["111634.71000000","0.00906000"],["111634.76000000","0.00010000"],["111634.77000000","0.12352000"],["111636.64000000","0.04352000"],["111636.81000000","0.00000000"],["111637.93000000","0.00000000"],["111639.57000000","0.00727000"],["111641.25000000","0.09156000"],["111642.72000000","0.00005000"],["111645.60000000","0.25333000"],["111646.64000000","0.00068000"],["111647.57000000","0.00000000"],["111653.25000000","0.06177000"],["111661.95000000","0.04800000"],["111663.08000000","0.04800000"],["111663.14000000","0.06720000"],["111663.15000000","0.04800000"],["111664.19000000","0.07200000"],["111665.38000000","0.07200000"],["111666.95000000","0.04800000"],["111668.63000000","0.04800000"],["111675.42000000","0.32220000"],["111675.72000000","0.00000000"],["111687.20000000","0.00000000"],["111687.42000000","0.00000000"],["111693.99000000","0.02498000"],["111707.67000000","0.00218000"],["111726.86000000","0.00000000"],["111726.90000000","0.04800000"],["111741.20000000","0.04800000"],["111751.98000000","0.04097000"],["111753.02000000","0.00000000"],["111753.67000000","0.00000000"],["111754.20000000","0.00000000"],["111754.86000000","0.00000000"],["111757.48000000","0.00000000"],["111758.64000000","0.04800000"],["111760.41000000","0.00000000"],["111838.51000000","0.00083000"],["111857.70000000","0.00000000"],["111859.07000000","0.02597000"],["111937.36000000","0.02409000"],["112025.32000000","0.02498000"],["112037.91000000","0.03583000"],["112085.65000000","0.00000000"],["112143.09000000","0.03672000"],["113309.07000000","0.00100000"]]}
[2025-10-12T10:59:00.185Z] {"e":"depthUpdate","E":1760266740014,"s":"BTCUSDT","U":77965098859,"u":77965098939,"b":[["111634.54000000","3.47804000"],["111630.52000000","0.05256000"],["111608.50000000","0.00000000"],["111607.55000000","0.00000000"],["111606.25000000","0.01390000"],["111606.24000000","0.00000000"],["111595.86000000","0.04283000"],["111400.00000000","1.10451000"],["111399.28000000","0.00000000"],["109960.02000000","0.00100000"],["106000.00000000","32.64502000"],["100470.00000000","0.00010000"],["89307.64000000","0.00022000"]],"a":[["111634.55000000","3.58776000"],["111634.56000000","0.00623000"],["111639.57000000","0.00722000"],["111640.02000000","0.00000000"],["111641.28000000","0.00000000"],["111641.32000000","0.00000000"],["111641.33000000","0.00000000"],["111641.34000000","0.00000000"],["111641.35000000","0.00000000"],["111641.39000000","0.02688000"],["111717.46000000","0.00000000"],["111717.47000000","0.00000000"],["111859.10000000","0.02597000"],["112040.82000000","0.55838000"],["113309.07000000","0.00100000"],["149260.00000000","0.00004000"]]}
[2025-10-12T10:59:01.185Z] {"e":"depthUpdate","E":1760266741014,"s":"BTCUSDT","U":77965098940,"u":77965098989,"b":[["111634.54000000","3.47799000"],["111634.53000000","0.00545000"],["111630.52000000","0.05251000"],["111630.43000000","0.00000000"],["111622.54000000","0.15000000"],["111622.29000000","0.34547000"],["111619.07000000","0.00000000"],["111616.40000000","0.00000000"],["111606.25000000","0.00000000"],["111606.14000000","0.01390000"],["111547.63000000","0.01402000"],["110964.74000000","0.00019000"],["110583.60000000","0.00239000"],["109960.02000000","0.00100000"],["100471.00000000","0.01637000"],["100470.00000000","0.00010000"],["89307.64000000","0.00022000"]],"a":[["111634.55000000","4.03546000"],["111634.56000000","0.00618000"],["111640.68000000","0.01797000"],["111641.32000000","0.00000000"],["111641.34000000","0.02688000"],["111641.39000000","0.00000000"],["111663.98000000","0.00000000"],["111682.51000000","0.00000000"],["111718.26000000","0.00000000"],["111718.46000000","0.00100000"],["111718.47000000","0.00100000"],["111753.17000000","0.01402000"],["111859.05000000","0.02597000"],["112707.97000000","0.00234000"],["113309.07000000","0.00100000"]]}
[2025-10-12T10:59:02.186Z] {"e":"depthUpdate","E":1760266742014,"s":"BTCUSDT","U":77965098990,"u":77965099232,"b":[["111634.54000000","2.42669000"],["111634.53000000","0.00535000"],["111634.48000000","0.02177000"],["111634.39000000","0.00010000"],["111634.38000000","0.00911000"],["111634.18000000","0.00000000"],["111634.17000000","0.00010000"],["111634.16000000","0.07729000"],["111633.89000000","0.00000000"],["111633.88000000","0.05200000"],["111633.78000000","0.00000000"],["111632.61000000","0.00000000"],["111632.60000000","0.00000000"],["111632.38000000","0.00000000"],["111631.26000000","0.00000000"],["111630.64000000","0.00547000"],["111630.58000000","0.00000000"],["111630.57000000","0.04809000"],["111630.43000000","0.00000000"],["111629.75000000","0.00000000"],["111629.53000000","0.00000000"],["111629.52000000","0.00717000"],["111629.33000000","0.00000000"],["111629.17000000","0.00000000"],["111628.88000000","0.00000000"],["111628.50000000","0.00000000"],["111628.42000000","0.00010000"],["111628.41000000","0.01792000"],["111628.21000000","0.00000000"],["111627.76000000","0.00155000"],["111627.73000000","0.00000000"],["111627.16000000","0.31150000"],["111627.15000000","0.29547000"],["111627.09000000","0.00000000"],["111626.58000000","0.03950000"],["111626.01000000","0.17905000"],["111626.00000000","0.00265000"],["111625.49000000","0.00000000"],["111625.46000000","0.04031000"],["111624.81000000","0.02693000"],["111624.00000000","0.00260000"],["111623.19000000","0.04000000"],["111622.54000000","0.00000000"],["111622.29000000","0.00000000"],["111622.17000000","0.09911000"],["111620.04000000","0.32533000"],["111619.07000000","0.15000000"],["111618.27000000","0.00000000"],["111616.40000000","0.00000000"],["111616.32000000","0.00447000"],["111615.19000000","0.00000000"],["111615.18000000","0.00000000"],["111614.78000000","0.00000000"],["111613.26000000","0.00000000"],["111610.89000000","0.35811000"],["111610.63000000","0.00000000"],["111610.62000000","0.70953000"],["111610.61000000","0.00000000"],["111608.01000000","0.00000000"],["111606.49000000","0.01390000"],["111606.14000000","0.00000000"],["111603.62000000","0.00000000"],["111600.43000000","0.04415000"],["111595.86000000","0.00000000"],["111595.69000000","1.22309000"],["111593.06000000","0.00000000"],["111591.29000000","0.32244000"],["111590.75000000","0.00000000"],["111588.76000000","0.00000000"],["111586.63000000","0.00000000"],["111586.62000000","0.00000000"],["111584.69000000","0.00000000"],["111584.61000000","0.00005000"],["111582.30000000","0.30218000"],["111582.09000000","0.00000000"],["111568.73000000","0.04283000"],["111520.00000000","0.00260000"],["111515.25000000","0.00196000"],["111507.49000000","0.00000000"],["111007.97000000","0.00000000"],["110964.74000000","0.00000000"],["109960.02000000","0.00100000"],["100470.00000000","0.00010000"],["89307.64000000","0.00022000"],["33000.00000000","3.87311000"]],"a":[["111634.55000000","4.76511000"],["111634.56000000","0.00623000"],["111634.94000000","0.01359000"],["111635.57000000","0.00005000"],["111635.58000000","0.17192000"],["111636.63000000","0.00005000"],["111637.15000000","0.00000000"],["111638.25000000","0.00005000"],["111638.45000000","0.00537000"],["111639.56000000","0.04000000"],["111641.25000000","0.04565000"],["111641.26000000","0.00000000"],["111643.44000000","0.04017000"],["111643.50000000","0.00400000"],["111644.56000000","0.04093000"],["111646.33000000","0.00000000"],["111646.64000000","0.00000000"],["111647.67000000","0.00000000"],["111647.98000000","0.00000000"],["111650.49000000","0.00000000"],["111650.51000000","0.51945000"],["111651.21000000","0.00000000"],["111651.89000000","0.40306000"],["111653.21000000","0.06646000"],["111654.86000000","0.00000000"],["111655.18000000","0.32226000"],["111655.98000000","0.15000000"],["111656.00000000","0.82282000"],["111659.09000000","1.25396000"],["111669.78000000","1.17222000"],["111672.41000000","0.00000000"],["111675.42000000","0.00000000"],["111676.01000000","0.00000000"],["111682.95000000","0.00000000"],["111710.38000000","0.00000000"],["111726.43000000","0.02280000"],["111744.26000000","0.00000000"],["111746.18000000","0.02091000"],["111751.21000000","0.00000000"],["111752.10000000","0.00196000"],["111903.18000000","0.02508000"],["112033.44000000","0.55838000"],["112040.82000000","0.00000000"],["113309.07000000","0.00100000"],["119659.00000000","0.00010000"]]}
[2025-10-12T10:59:03.185Z] {"e":"depthUpdate","E":1760266743014,"s":"BTCUSDT","U":77965099233,"u":77965099305,"b":[["111634.54000000","2.65009000"],["111634.53000000","0.00545000"],["111634.39000000","0.00000000"],["111634.38000000","0.00906000"],["111634.16000000","0.15432000"],["111633.89000000","0.00005000"],["111629.68000000","0.29547000"],["111629.52000000","0.00727000"],["111629.35000000","0.06646000"],["111628.68000000","0.00000000"],["111628.42000000","0.04485000"],["111627.15000000","0.00000000"],["111626.02000000","0.40306000"],["111624.81000000","0.02688000"],["111622.54000000","0.00000000"],["111622.39000000","0.00100000"],["111622.17000000","0.05436000"],["111619.07000000","0.15000000"],["111618.81000000","0.00000000"],["111616.40000000","0.00000000"],["111606.49000000","0.00000000"],["111606.12000000","0.33630000"],["111600.43000000","0.00000000"],["111587.99000000","0.00000000"],["111585.81000000","0.04415000"],["111568.73000000","0.00000000"],["111564.94000000","0.02125000"],["111554.63000000","0.04283000"],["111281.87000000","0.00000000"],["111007.97000000","0.89110000"],["110583.60000000","0.00000000"],["109960.02000000","0.00100000"],["100471.00000000","0.01647000"],["100470.00000000","0.00010000"],["89307.64000000","0.00022000"],["40188.44000000","0.00510000"]],"a":[["111634.55000000","4.76511000"],["111634.57000000","0.04986000"],["111634.70000000","0.00080000"],["111635.57000000","0.00010000"],["111641.14000000","0.00000000"],["111644.72000000","0.00100000"],["111645.99000000","0.01390000"],["111650.49000000","0.15000000"],["111655.98000000","0.00000000"],["111666.80000000","0.00000000"],["111678.82000000","0.02126000"],["111793.29000000","0.02597000"],["111988.17000000","0.00000000"],["112033.44000000","0.00000000"],["112707.97000000","0.00000000"],["113309.07000000","0.00100000"]]}
[2025-10-12T10:59:04.189Z] {"e":"depthUpdate","E":1760266744014,"s":"BTCUSDT","U":77965099306,"u":77965099490,"b":[["111634.54000000","3.27119000"],["111634.53000000","0.00545000"],["111633.88000000","0.05200000"],["111631.99000000","0.29551000"],["111630.64000000","0.00542000"],["111629.68000000","0.00000000"],["111627.76000000","0.00155000"],["111626.58000000","0.03928000"],["111626.00000000","0.00260000"],["111625.46000000","0.04078000"],["111624.81000000","0.02693000"],["111622.54000000","0.15000000"],["111619.07000000","0.00000000"],["111616.40000000","0.00000000"],["111612.21000000","0.01464000"],["111606.15000000","0.01390000"],["111606.12000000","0.32240000"],["111606.07000000","0.00000000"],["111601.50000000","0.00000000"],["111601.10000000","0.00000000"],["111601.04000000","0.00300000"],["111588.01000000","0.00000000"],["111586.16000000","0.30216000"],["111582.30000000","0.00000000"],["111577.39000000","0.00000000"],["111562.32000000","0.04283000"],["111554.63000000","0.00000000"],["111510.00000000","0.00349000"],["111400.00000000","1.09877000"],["111399.28000000","0.00574000"],["111398.76000000","0.00000000"],["111324.98000000","0.00000000"],["111231.61000000","0.00000000"],["109960.02000000","0.00100000"],["102703.79000000","0.00010000"],["100471.00000000","0.01637000"],["100470.00000000","0.00010000"],["89307.64000000","0.00022000"],["60000.00000000","53.14032000"]],"a":[["111634.55000000","4.55597000"],["111634.56000000","0.00623000"],["111634.57000000","0.04986000"],["111634.71000000","0.00906000"],["111634.74000000","0.00000000"],["111634.76000000","0.00000000"],["111634.77000000","0.17478000"],["111634.78000000","0.29555000"],["111634.81000000","0.00000000"],["111634.82000000","0.00000000"],["111634.94000000","0.01359000"],["111635.58000000","0.17197000"],["111635.85000000","0.00000000"],["111635.86000000","0.00000000"],["111636.63000000","0.00010000"],["111636.64000000","0.04352000"],["111637.93000000","0.00005000"],["111637.94000000","0.04667000"],["111638.45000000","0.00542000"],["111638.93000000","0.00322000"],["111639.55000000","0.00000000"],["111639.56000000","0.09683000"],["111639.99000000","0.04109000"],["111640.68000000","0.01797000"],["111641.11000000","0.04052000"],["111641.25000000","0.00000000"],["111643.44000000","0.00000000"],["111644.56000000","0.00000000"],["111645.47000000","0.02000000"],["111645.60000000","0.00000000"],["111645.99000000","0.00000000"],["111646.56000000","0.00073000"],["111646.65000000","0.38227000"],["111646.66000000","0.35810000"],["111649.02000000","0.00000000"],["111650.07000000","0.00000000"],["111650.49000000","0.15000000"],["111651.89000000","0.00000000"],["111653.93000000","0.01390000"],["111655.98000000","0.00000000"],["111656.00000000","0.37317000"],["111659.09000000","0.00000000"],["111668.05000000","0.00300000"],["111668.11000000","0.00000000"],["111753.17000000","0.00000000"],["111833.64000000","0.00000000"],["111838.60000000","0.07521000"],["113309.07000000","0.00100000"]]}
[2025-10-12T10:59:05.185Z] {"e":"depthUpdate","E":1760266745014,"s":"BTCUSDT","U":77965099491,"u":77965099627,"b":[["111634.54000000","3.74590000"],["111634.53000000","0.00550000"],["111634.51000000","0.02611000"],["111634.16000000","0.11138000"],["111633.88000000","0.05205000"],["111633.39000000","0.00000000"],["111632.81000000","0.04114000"],["111631.99000000","0.00000000"],["111631.69000000","0.04131000"],["111631.25000000","0.04089000"],["111630.64000000","0.00542000"],["111627.62000000","0.00100000"],["111626.58000000","0.00000000"],["111625.46000000","0.00005000"],["111624.81000000","0.02688000"],["111622.39000000","0.00000000"],["111610.60000000","0.40742000"],["111606.25000000","0.01390000"],["111606.15000000","0.00000000"],["111595.69000000","0.00000000"],["111595.68000000","1.23250000"],["111591.29000000","0.00000000"],["111589.08000000","0.00005000"],["111584.61000000","0.00000000"],["111584.30000000","0.04283000"],["111562.32000000","0.00000000"],["111511.18000000","0.00010000"],["111392.66000000","4.84728000"],["111392.60000000","0.00000000"],["111120.35000000","0.00000000"],["110992.43000000","0.00000000"],["110848.80000000","0.00000000"],["110690.25000000","0.00000000"],["110615.42000000","0.00000000"],["109960.02000000","0.00100000"],["102703.79000000","0.00000000"],["100470.00000000","0.00010000"],["89308.00000000","0.00000000"],["89307.64000000","0.00022000"],["60000.00000000","53.14022000"]],"a":[["111634.55000000","4.55450000"],["111634.56000000","0.00623000"],["111634.57000000","0.04986000"],["111634.71000000","0.00906000"],["111634.76000000","0.00010000"],["111634.77000000","0.17488000"],["111635.58000000","0.17192000"],["111637.93000000","0.00000000"],["111638.45000000","0.00537000"],["111639.56000000","0.05683000"],["111639.99000000","0.00000000"],["111640.46000000","0.04045000"],["111644.72000000","0.00000000"],["111649.06000000","0.16206000"],["111649.95000000","0.00100000"],["111652.36000000","0.40306000"],["111655.18000000","0.00000000"],["111658.02000000","0.00000000"],["111667.97000000","0.08794000"],["111667.98000000","1.09728000"],["111668.93000000","1.17927000"],["111669.78000000","0.00000000"],["111671.68000000","0.32221000"],["111693.63000000","0.00000000"],["111707.67000000","0.00000000"],["111764.04000000","0.00083000"],["111770.00000000","0.00360000"],["111824.46000000","0.00000000"],["111838.51000000","0.00000000"],["111870.05000000","0.00000000"],["111872.12000000","4.74001000"],["112025.16000000","0.02398000"],["112033.44000000","0.55838000"],["113309.07000000","0.00100000"],["149460.00000000","0.00004000"]]}
[2025-10-12T10:59:06.186Z] {"e":"depthUpdate","E":1760266746014,"s":"BTCUSDT","U":77965099628,"u":77965099704,"b":[["111634.54000000","3.73285000"],["111632.38000000","0.00005000"],["111632.00000000","0.00270000"],["111630.57000000","0.00000000"],["111630.43000000","0.01819000"],["111629.54000000","0.06652000"],["111625.46000000","0.00000000"],["111610.60000000","0.08504000"],["111606.32000000","0.01390000"],["111606.25000000","0.00000000"],["111603.40000000","0.04415000"],["111594.01000000","0.32243000"],["111585.81000000","0.00000000"],["111574.51000000","0.00380000"],["111547.63000000","0.00000000"],["111488.90000000","0.00010000"],["111438.81000000","0.00010000"],["111367.05000000","0.00010000"],["111276.23000000","0.00010000"],["111168.00000000","0.00010000"],["111043.57000000","0.00010000"],["111005.38000000","0.00230000"],["110903.86000000","0.00022000"],["110831.94000000","0.00000000"],["109960.02000000","0.00100000"],["107000.00000000","45.29512000"],["106000.00000000","32.64502000"],["100471.00000000","0.01637000"],["100470.00000000","0.00010000"],["89307.64000000","0.00022000"],["42000.00000000","1.49196000"],["40188.44000000","0.00525000"],["33000.00000000","3.87311000"]],"a":[["111634.55000000","4.10132000"],["111634.56000000","0.00569000"],["111640.46000000","0.00000000"],["111640.47000000","0.00000000"],["111645.08000000","0.00000000"],["111712.52000000","0.00218000"],["111764.04000000","0.00000000"],["111775.92000000","0.00000000"],["111907.94000000","0.00080000"],["112033.44000000","0.55838000"],["113309.07000000","0.00100000"]]}
[2025-10-12T10:59:07.186Z] {"e":"depthUpdate","E":1760266747014,"s":"BTCUSDT","U":77965099705,"u":77965100421,"b":[["111634.54000000","5.25697000"],["111634.53000000","0.00525000"],["111634.52000000","0.00020000"],["111634.51000000","0.02631000"],["111634.50000000","0.00020000"],["111634.49000000","0.00000000"],["111634.48000000","0.02177000"],["111634.38000000","0.00906000"],["111634.37000000","0.00010000"],["111634.17000000","0.40316000"],["111634.16000000","0.39395000"],["111634.15000000","0.01354000"],["111634.01000000","0.04485000"],["111633.89000000","0.00000000"],["111633.88000000","0.05210000"],["111633.78000000","0.00005000"],["111633.34000000","0.00100000"],["111633.24000000","0.00000000"],["111632.81000000","0.04109000"],["111631.69000000","0.04126000"],["111630.64000000","0.00537000"],["111630.52000000","0.05256000"],["111630.00000000","0.00364000"],["111629.56000000","0.45020000"],["111629.55000000","0.40306000"],["111629.52000000","0.00722000"],["111629.35000000","0.06651000"],["111628.70000000","0.08509000"],["111628.68000000","0.00087000"],["111628.50000000","0.00400000"],["111628.42000000","0.00010000"],["111627.76000000","0.00150000"],["111627.62000000","0.00000000"],["111627.43000000","0.00086000"],["111626.33000000","0.05280000"],["111626.03000000","0.00447000"],["111626.01000000","0.00000000"],["111626.00000000","0.00260000"],["111625.88000000","0.00000000"],["111625.30000000","0.00239000"],["111624.81000000","0.00000000"],["111623.37000000","0.09095000"],["111623.19000000","0.00000000"],["111622.81000000","0.04283000"],["111622.66000000","0.06000000"],["111622.55000000","0.00000000"],["111622.54000000","0.00000000"],["111621.88000000","0.04415000"],["111621.63000000","0.00000000"],["111621.62000000","0.08504000"],["111620.04000000","0.78029000"],["111620.03000000","0.16388000"],["111619.08000000","0.15000000"],["111619.07000000","0.00000000"],["111619.06000000","1.25396000"],["111618.91000000","0.13426000"],["111617.81000000","0.00000000"],["111617.74000000","0.13426000"],["111617.10000000","0.32236000"],["111616.38000000","0.84947000"],["111616.32000000","0.00000000"],["111615.97000000","0.13426000"],["111615.24000000","1.25396000"],["111614.77000000","0.00000000"],["111611.25000000","0.00000000"],["111610.88000000","0.00000000"],["111610.65000000","0.00000000"],["111610.64000000","1.27630000"],["111610.63000000","1.25396000"],["111610.62000000","0.00000000"],["111610.59000000","0.32243000"],["111610.32000000","0.00000000"],["111609.06000000","0.00000000"],["111608.46000000","0.08000000"],["111606.85000000","0.00000000"],["111606.64000000","0.01390000"],["111606.32000000","0.00000000"],["111605.28000000","0.03829000"],["111605.00000000","0.32640000"],["111604.13000000","0.00000000"],["111603.40000000","0.00000000"],["111602.94000000","0.00000000"],["111602.81000000","0.00000000"],["111602.52000000","0.00000000"],["111602.01000000","0.30212000"],["111601.18000000","0.00000000"],["111600.62000000","0.00000000"],["111600.49000000","0.00009000"],["111598.28000000","0.00018000"],["111597.56000000","0.00000000"],["111595.92000000","0.00000000"],["111595.69000000","0.00000000"],["111594.01000000","0.00000000"],["111593.11000000","0.00000000"],["111590.79000000","0.00000000"],["111590.75000000","0.00000000"],["111590.10000000","0.00009000"],["111589.08000000","0.00000000"],["111588.75000000","0.00000000"],["111588.57000000","0.00000000"],["111587.65000000","0.22377000"],["111587.52000000","0.00000000"],["111586.16000000","0.00000000"],["111584.87000000","0.04310000"],["111584.30000000","0.00000000"],["111580.40000000","0.00000000"],["111578.74000000","0.00000000"],["111564.55000000","0.00630000"],["111559.74000000","0.00000000"],["111558.80000000","0.00000000"],["111557.39000000","0.05275000"],["111556.39000000","0.00000000"],["111555.22000000","0.13426000"],["111554.76000000","0.00090000"],["111552.47000000","0.00000000"],["111550.39000000","0.13426000"],["111550.15000000","0.09235000"],["111549.71000000","0.00000000"],["111548.81000000","0.00000000"],["111545.06000000","0.00000000"],["111544.38000000","0.00000000"],["111528.98000000","0.00000000"],["111528.96000000","0.13436000"],["111528.84000000","0.00000000"],["111528.66000000","0.00000000"],["111528.56000000","0.00000000"],["111528.24000000","0.00000000"],["111526.41000000","0.00000000"],["111522.97000000","0.00000000"],["111521.39000000","0.17904000"],["111492.11000000","0.00000000"],["111476.75000000","0.05624000"],["111475.08000000","0.00000000"],["111447.31000000","0.09467000"],["111436.84000000","0.99653000"],["111431.23000000","0.00000000"],["111429.56000000","0.00000000"],["111412.78000000","0.00000000"],["111307.90000000","0.03493000"],["111200.00000000","0.25140000"],["111131.38000000","0.00062000"],["111007.97000000","0.00000000"],["110749.62000000","0.00010000"],["110676.82000000","0.00017000"],["109960.02000000","0.00100000"],["100470.00000000","0.00010000"],["89307.64000000","0.00022000"]],"a":[["111634.55000000","2.96745000"],["111634.56000000","0.00579000"],["111634.57000000","0.04686000"],["111634.71000000","0.00906000"],["111634.76000000","0.00000000"],["111634.77000000","0.00000000"],["111634.78000000","0.00000000"],["111634.93000000","0.00010000"],["111634.94000000","0.01354000"],["111635.20000000","0.00000000"],["111635.57000000","0.00000000"],["111635.58000000","0.00000000"],["111636.63000000","0.00000000"],["111636.64000000","0.00000000"],["111636.81000000","0.00005000"],["111637.93000000","0.00010000"],["111637.94000000","0.04672000"],["111638.25000000","0.00000000"],["111638.45000000","0.00542000"],["111638.93000000","0.00317000"],["111639.56000000","0.00000000"],["111639.57000000","0.00727000"],["111639.65000000","0.00000000"],["111639.66000000","0.00000000"],["111640.38000000","0.00000000"],["111640.52000000","0.00000000"],["111640.67000000","0.00010000"],["111640.68000000","0.01802000"],["111641.11000000","0.00000000"],["111641.34000000","0.00000000"],["111642.41000000","0.00005000"],["111642.42000000","0.05230000"],["111642.72000000","0.00000000"],["111643.41000000","0.05512000"],["111643.44000000","0.00000000"],["111643.50000000","0.00000000"],["111643.55000000","0.29543000"],["111644.80000000","0.00000000"],["111645.47000000","0.00000000"],["111645.71000000","0.22763000"],["111645.72000000","0.45305000"],["111646.34000000","0.00000000"],["111646.65000000","0.00000000"],["111646.66000000","0.00000000"],["111646.67000000","0.00000000"],["111646.97000000","0.00331000"],["111647.19000000","0.00000000"],["111647.22000000","0.00069000"],["111648.55000000","0.00000000"],["111648.56000000","0.00000000"],["111649.00000000","0.00000000"],["111649.01000000","0.00005000"],["111649.02000000","0.00000000"],["111649.03000000","0.00000000"],["111649.06000000","0.12206000"],["111649.95000000","0.00000000"],["111650.06000000","0.17187000"],["111650.08000000","0.00000000"],["111650.23000000","0.00000000"],["111650.49000000","0.04801000"],["111650.50000000","0.00000000"],["111650.51000000","0.04013000"],["111650.55000000","0.00000000"],["111650.81000000","0.00000000"],["111650.82000000","0.02688000"],["111650.88000000","0.00000000"],["111651.30000000","0.00000000"],["111651.35000000","0.03999000"],["111651.66000000","0.00005000"],["111652.34000000","0.00000000"],["111652.36000000","0.00000000"],["111653.05000000","0.00000000"],["111653.21000000","0.00000000"],["111653.25000000","0.00000000"],["111653.52000000","0.00000000"],["111653.66000000","0.00000000"],["111653.70000000","0.00000000"],["111653.71000000","0.00000000"],["111653.93000000","0.00000000"],["111654.08000000","0.06000000"],["111654.45000000","0.00000000"],["111654.99000000","0.00447000"],["111655.00000000","0.00000000"],["111655.50000000","0.00011000"],["111655.72000000","0.00000000"],["111655.74000000","0.00000000"],["111655.99000000","0.35810000"],["111656.87000000","0.00100000"],["111656.88000000","0.11490000"],["111656.89000000","0.45000000"],["111657.66000000","0.00000000"],["111657.89000000","0.00000000"],["111658.31000000","0.00000000"],["111659.10000000","0.00000000"],["111659.17000000","0.00000000"],["111659.52000000","0.40306000"],["111659.70000000","0.00000000"],["111659.76000000","0.00000000"],["111660.08000000","0.08504000"],["111661.66000000","0.00000000"],["111661.69000000","0.00000000"],["111661.88000000","0.00005000"],["111662.46000000","0.15000000"],["111662.48000000","0.69657000"],["111662.49000000","0.00000000"],["111662.70000000","0.01390000"],["111664.32000000","0.00000000"],["111664.91000000","0.00000000"],["111665.79000000","0.00000000"],["111665.84000000","0.00000000"],["111665.86000000","0.21904000"],["111665.88000000","0.00000000"],["111666.04000000","0.00000000"],["111666.21000000","0.00000000"],["111666.83000000","0.00000000"],["111666.85000000","0.00000000"],["111667.96000000","0.00000000"],["111667.97000000","0.00000000"],["111667.98000000","0.67571000"],["111668.93000000","0.00000000"],["111669.58000000","0.00000000"],["111669.59000000","0.00000000"],["111669.60000000","0.00000000"],["111669.84000000","0.40306000"],["111669.85000000","1.19565000"],["111669.96000000","0.00000000"],["111670.07000000","0.00000000"],["111670.32000000","0.13426000"],["111670.34000000","0.32221000"],["111671.43000000","0.08794000"],["111671.45000000","0.00000000"],["111671.68000000","0.00000000"],["111672.45000000","0.00012000"],["111673.13000000","0.00000000"],["111673.23000000","0.08504000"],["111673.71000000","0.20529000"],["111676.26000000","0.32219000"],["111677.74000000","0.13426000"],["111677.99000000","0.05696000"],["111678.97000000","0.13426000"],["111680.74000000","0.32218000"],["111682.06000000","0.00000000"],["111682.61000000","0.32218000"],["111682.95000000","0.00005000"],["111683.18000000","0.08795000"],["111685.24000000","0.00000000"],["111685.99000000","0.00000000"],["111687.42000000","0.00005000"],["111690.98000000","0.22377000"],["111691.21000000","0.05280000"],["111691.73000000","0.22377000"],["111691.89000000","0.00005000"],["111696.23000000","0.04800000"],["111696.36000000","0.00000000"],["111698.73000000","0.00000000"],["111698.87000000","0.00000000"],["111703.51000000","0.00000000"],["111705.09000000","0.00000000"],["111705.15000000","0.06760000"],["111712.52000000","0.00000000"],["111713.38000000","0.00651000"],["111718.37000000","0.00894000"],["111718.46000000","0.00000000"],["111718.47000000","0.00000000"],["111719.41000000","0.00000000"],["111719.42000000","0.00000000"],["111719.46000000","0.02597000"],["111719.47000000","0.02597000"],["111719.64000000","0.00000000"],["111719.65000000","0.00000000"],["111719.82000000","0.00223000"],["111720.46000000","0.00000000"],["111720.47000000","0.00000000"],["111726.43000000","0.00000000"],["111738.92000000","0.02446000"],["111741.97000000","0.00000000"],["111741.99000000","0.00223000"],["111742.65000000","0.00000000"],["111743.06000000","0.00000000"],["111744.19000000","0.00000000"],["111746.18000000","0.00000000"],["111751.83000000","0.00000000"],["111751.97000000","0.02398000"],["111752.63000000","0.00000000"],["111758.64000000","0.00000000"],["111767.64000000","0.00000000"],["111767.73000000","0.49416000"],["111768.76000000","0.09440000"],["111769.13000000","0.22377000"],["111769.88000000","0.22377000"],["111777.79000000","0.00218000"],["111786.40000000","0.02398000"],["111853.17000000","0.00089000"],["111860.00000000","0.00115000"],["111907.94000000","0.00000000"],["111937.36000000","0.00011000"],["111947.58000000","0.02398000"],["111973.22000000","0.00080000"],["111979.72000000","0.00000000"],["111986.51000000","0.00000000"],["111986.59000000","0.00000000"],["111986.61000000","0.00000000"],["112003.67000000","0.00000000"],["112005.04000000","0.00000000"],["112008.96000000","0.00000000"],["112010.35000000","0.02687000"],["112012.84000000","0.02687000"],["112016.66000000","0.02687000"],["112033.44000000","0.00000000"],["112149.78000000","0.03513000"],["112229.86000000","0.00000000"],["112230.00000000","0.00630000"],["112242.45000000","0.02398000"],["112242.80000000","0.02398000"],["113309.07000000","0.00100000"]]}
[2025-10-12T10:59:08.185Z] {"e":"depthUpdate","E":1760266748014,"s":"BTCUSDT","U":77965100422,"u":77965100529,"b":[["111634.54000000","5.25694000"],["111634.48000000","0.02177000"],["111634.38000000","0.00906000"],["111634.37000000","0.00010000"],["111634.18000000","0.62487000"],["111634.17000000","0.40316000"],["111634.16000000","0.00000000"],["111633.68000000","0.00005000"],["111632.00000000","0.00275000"],["111631.83000000","0.04800000"],["111631.25000000","0.04094000"],["111630.65000000","0.04800000"],["111630.62000000","0.04800000"],["111630.00000000","0.00359000"],["111629.99000000","0.00000000"],["111629.60000000","0.07200000"],["111628.42000000","0.00005000"],["111628.41000000","0.11152000"],["111624.77000000","0.00895000"],["111618.12000000","0.00000000"],["111616.94000000","0.00000000"],["111616.60000000","0.00000000"],["111615.44000000","0.00000000"],["111615.23000000","0.00000000"],["111606.77000000","0.01390000"],["111606.64000000","0.00000000"],["111602.01000000","0.00000000"],["111600.01000000","0.30213000"],["111598.21000000","0.05280000"],["111587.65000000","0.22377000"],["111555.98000000","0.53732000"],["111528.96000000","0.00000000"],["111528.43000000","0.13436000"],["111528.06000000","0.00000000"],["111527.54000000","0.00000000"],["111394.79000000","0.07521000"],["111382.56000000","0.00000000"],["111007.97000000","0.89110000"],["111005.38000000","0.00000000"],["110896.88000000","0.00442000"],["109960.02000000","0.00100000"],["100471.00000000","0.01637000"],["100470.00000000","0.00010000"],["89307.64000000","0.00022000"],["42000.00000000","1.49096000"]],"a":[["111634.55000000","2.96107000"],["111634.56000000","0.00579000"],["111645.25000000","0.17187000"],["111645.71000000","0.00000000"],["111645.72000000","0.45305000"],["111650.06000000","0.00000000"],["111650.51000000","0.00000000"],["111650.82000000","0.00000000"],["111650.83000000","0.00000000"],["111650.93000000","0.02688000"],["111653.61000000","0.00000000"],["111653.80000000","0.00069000"],["111655.50000000","0.00005000"],["111656.87000000","0.00000000"],["111728.58000000","0.00000000"],["111767.73000000","0.38497000"],["111777.79000000","0.00000000"],["111784.06000000","0.00218000"],["111973.22000000","0.00000000"],["111979.50000000","0.00080000"],["112003.05000000","0.00000000"],["113309.07000000","0.00100000"]]}
[2025-10-12T10:59:09.186Z] {"e":"depthUpdate","E":1760266749014,"s":"BTCUSDT","U":77965100530,"u":77965100681,"b":[["111634.54000000","5.41370000"],["111634.53000000","0.01025000"],["111634.51000000","0.03131000"],["111634.48000000","0.02677000"],["111634.27000000","0.01390000"],["111633.28000000","0.00006000"],["111630.64000000","0.00542000"],["111630.00000000","0.00364000"],["111629.35000000","0.06646000"],["111628.95000000","0.11190000"],["111628.70000000","0.00005000"],["111628.42000000","0.00000000"],["111626.03000000","0.00000000"],["111622.82000000","0.00447000"],["111622.81000000","0.00000000"],["111622.67000000","1.25396000"],["111621.58000000","0.08504000"],["111617.74000000","0.00000000"],["111611.23000000","0.03074000"],["111608.48000000","0.30210000"],["111608.15000000","0.04283000"],["111607.84000000","0.00000000"],["111606.77000000","0.00000000"],["111603.71000000","0.07680000"],["111602.53000000","0.04800000"],["111602.51000000","0.04800000"],["111602.45000000","1.18962000"],["111601.48000000","0.07200000"],["111601.05000000","0.04477000"],["111600.29000000","0.09360000"],["111600.01000000","0.00000000"],["111595.68000000","0.00000000"],["111587.38000000","0.13436000"],["111560.25000000","0.00000000"],["111560.14000000","0.00000000"],["111555.98000000","0.40306000"],["111555.22000000","0.00000000"],["111536.63000000","0.00000000"],["111535.46000000","0.00000000"],["111528.43000000","0.00000000"],["111527.54000000","0.00000000"],["111526.37000000","0.00000000"],["111526.36000000","0.00000000"],["111524.86000000","0.00000000"],["111521.93000000","0.00000000"],["111399.39000000","4.60905000"],["111399.28000000","0.00000000"],["111398.70000000","0.00574000"],["111392.66000000","0.00000000"],["111309.21000000","0.03500000"],["111301.86000000","0.00000000"],["111142.69000000","0.00000000"],["110964.74000000","0.00000000"],["109960.02000000","0.00100000"],["100471.09000000","0.00019000"],["100470.00000000","0.00010000"],["89307.64000000","0.00022000"]],"a":[["111634.55000000","2.76452000"],["111634.63000000","0.00010000"],["111643.41000000","0.00000000"],["111643.55000000","0.00000000"],["111645.25000000","0.00000000"],["111645.72000000","0.00305000"],["111645.95000000","0.29542000"],["111646.48000000","0.17187000"],["111650.36000000","0.00000000"],["111650.49000000","0.00000000"],["111650.67000000","0.00000000"],["111651.35000000","0.00000000"],["111651.66000000","0.00000000"],["111651.93000000","0.04030000"],["111653.05000000","0.04055000"],["111653.65000000","0.00000000"],["111653.80000000","0.00000000"],["111653.90000000","0.00069000"],["111655.50000000","0.00005000"],["111656.85000000","0.00100000"],["111659.52000000","0.00000000"],["111662.83000000","0.00000000"],["111662.94000000","0.00000000"],["111666.61000000","0.00000000"],["111667.98000000","0.40312000"],["111668.04000000","0.04478000"],["111669.85000000","0.00000000"],["111679.78000000","1.16167000"],["111680.00000000","0.01991000"],["111680.08000000","1.20385000"],["111700.83000000","0.00005000"],["111705.15000000","0.00000000"],["111705.33000000","2.00328000"],["111707.10000000","0.00000000"],["111723.46000000","0.00100000"],["111723.47000000","0.00100000"],["111806.35000000","0.00000000"],["111811.92000000","0.00000000"],["111863.13000000","0.02597000"],["111865.56000000","0.02418000"],["111870.00000000","0.00189000"],["111872.12000000","0.00000000"],["111884.82000000","4.81295000"],["111889.51000000","0.00000000"],["111893.10000000","0.00000000"],["111902.17000000","0.00000000"],["111925.38000000","0.01701000"],["111954.73000000","0.00000000"],["111978.42000000","0.00000000"],["111989.30000000","0.02597000"],["112013.92000000","0.02687000"],["113309.07000000","0.00100000"]]}
[2025-10-12T10:59:10.185Z] {"e":"depthUpdate","E":1760266750014,"s":"BTCUSDT","U":77965100682,"u":77965100856,"b":[["111634.54000000","5.04305000"],["111634.53000000","0.01030000"],["111634.48000000","0.02677000"],["111634.38000000","0.00906000"],["111634.37000000","0.00010000"],["111634.27000000","0.00000000"],["111634.18000000","0.62487000"],["111634.17000000","0.40311000"],["111633.88000000","0.05210000"],["111632.99000000","0.01390000"],["111632.81000000","0.04114000"],["111632.34000000","0.04800000"],["111627.94000000","0.07200000"],["111627.16000000","0.64547000"],["111625.79000000","0.05760000"],["111625.70000000","0.06720000"],["111625.61000000","0.07200000"],["111622.69000000","0.15000000"],["111620.72000000","0.00000000"],["111619.08000000","0.00000000"],["111618.91000000","0.00000000"],["111618.71000000","0.13426000"],["111618.69000000","0.13426000"],["111616.31000000","0.00000000"],["111615.28000000","0.98970000"],["111614.08000000","0.00000000"],["111614.01000000","0.00000000"],["111608.48000000","0.00000000"],["111606.67000000","0.00000000"],["111606.34000000","0.30211000"],["111606.33000000","0.00443000"],["111588.00000000","0.00285000"],["111587.63000000","0.13436000"],["111587.38000000","0.00000000"],["111560.22000000","0.00000000"],["111560.20000000","0.00000000"],["111559.46000000","1.00328000"],["111559.23000000","0.00000000"],["111556.19000000","0.13426000"],["111556.17000000","0.13436000"],["111547.69000000","0.00000000"],["111537.64000000","0.00110000"],["111531.05000000","0.01402000"],["111528.29000000","0.00000000"],["111525.11000000","0.13436000"],["111516.49000000","0.00000000"],["111448.58000000","0.99314000"],["111436.84000000","0.00000000"],["109960.02000000","0.00100000"],["102703.79000000","0.00010000"],["100471.09000000","0.00000000"],["100471.00000000","0.01637000"],["100470.00000000","0.00010000"],["89307.64000000","0.00022000"],["55817.27000000","0.00020000"],["55741.92000000","0.00040000"],["40188.44000000","0.00540000"]],"a":[["111634.55000000","2.71315000"],["111634.56000000","0.00584000"],["111634.59000000","0.00005000"],["111642.42000000","0.05225000"],["111643.77000000","0.00000000"],["111643.84000000","0.00000000"],["111645.95000000","0.00000000"],["111646.12000000","0.29542000"],["111647.21000000","0.00000000"],["111651.92000000","0.04371000"],["111655.04000000","0.00069000"],["111656.85000000","0.00000000"],["111657.99000000","0.00018000"],["111658.92000000","0.00000000"],["111662.45000000","0.40306000"],["111662.48000000","0.47143000"],["111663.96000000","0.00895000"],["111664.05000000","0.00005000"],["111664.19000000","0.00000000"],["111665.38000000","0.00000000"],["111676.80000000","0.04800000"],["111677.86000000","0.01402000"],["111679.01000000","0.04800000"],["111679.78000000","1.00841000"],["111693.05000000","0.00000000"],["111696.36000000","0.00005000"],["111700.83000000","0.00000000"],["111707.63000000","0.06650000"],["111714.50000000","0.00617000"],["111758.45000000","0.00000000"],["111768.92000000","0.04800000"],["111888.09000000","0.00000000"],["111904.54000000","0.02398000"],["112026.51000000","0.02398000"],["112030.34000000","0.02398000"],["112031.99000000","0.02398000"],["112032.81000000","0.02398000"],["112055.58000000","0.55838000"],["113309.07000000","0.00100000"]]}
[2025-10-12T10:59:11.185Z] {"e":"depthUpdate","E":1760266751014,"s":"BTCUSDT","U":77965100857,"u":77965100927,"b":[["111634.54000000","5.17702000"],["111633.88000000","0.05210000"],["111632.99000000","0.00000000"],["111632.41000000","0.00000000"],["111623.26000000","0.01390000"],["111606.61000000","0.00000000"],["111601.05000000","0.00000000"],["111587.65000000","0.22377000"],["111587.63000000","0.00000000"],["111560.23000000","0.13426000"],["111556.17000000","0.00010000"],["111547.69000000","0.06720000"],["111531.05000000","0.00000000"],["111527.67000000","0.13436000"],["111525.11000000","0.00000000"],["109960.02000000","0.00100000"],["102703.79000000","0.00000000"],["100470.00000000","0.00010000"],["89307.64000000","0.00022000"],["40188.44000000","0.00570000"]],"a":[["111634.55000000","2.71438000"],["111634.56000000","0.00579000"],["111642.42000000","0.05225000"],["111647.55000000","0.04823000"],["111650.93000000","0.00000000"],["111650.95000000","0.00000000"],["111651.09000000","0.02688000"],["111651.92000000","0.03187000"],["111651.93000000","0.00000000"],["111653.55000000","0.00000000"],["111668.04000000","0.00000000"],["111674.39000000","0.07200000"],["111675.58000000","0.07200000"],["111688.86000000","0.00000000"],["111690.03000000","0.00000000"],["111753.02000000","0.07200000"],["111754.20000000","0.07200000"],["111768.92000000","0.00000000"],["111892.58000000","0.00000000"],["111910.20000000","0.02508000"],["111912.35000000","0.02508000"],["113309.07000000","0.00100000"],["149760.00000000","0.00004000"]]}
[2025-10-12T10:59:12.189Z] {"e":"depthUpdate","E":1760266752017,"s":"BTCUSDT","U":77965100928,"u":77965101720,"b":[["111640.67000000","3.27788000"],["111640.66000000","1.52430000"],["111639.66000000","0.00000000"],["111639.62000000","0.00000000"],["111639.56000000","0.19456000"],["111639.55000000","0.00020000"],["111638.92000000","0.00020000"],["111638.91000000","0.00010000"],["111638.75000000","0.09027000"],["111638.74000000","0.00060000"],["111638.53000000","0.70306000"],["111638.44000000","0.34018000"],["111638.43000000","0.00010000"],["111638.00000000","0.02380000"],["111637.94000000","0.21318000"],["111637.93000000","0.88538000"],["111637.92000000","0.00020000"],["111637.23000000","0.30000000"],["111637.00000000","0.02380000"],["111636.80000000","0.00000000"],["111636.78000000","0.30833000"],["111636.77000000","4.97357000"],["111636.76000000","0.00020000"],["111636.29000000","0.69685000"],["111636.28000000","0.40988000"],["111636.27000000","0.00010000"],["111636.08000000","0.00000000"],["111636.05000000","0.00000000"],["111636.00000000","0.02380000"],["111635.69000000","0.00000000"],["111635.03000000","0.00000000"],["111635.00000000","0.02380000"],["111634.94000000","1.13544000"],["111634.93000000","2.06764000"],["111634.92000000","0.00000000"],["111634.89000000","0.00000000"],["111634.70000000","0.00000000"],["111634.69000000","0.14670000"],["111634.62000000","0.00000000"],["111634.61000000","0.00000000"],["111634.58000000","0.00000000"],["111634.57000000","0.00000000"],["111634.56000000","0.01916000"],["111634.55000000","2.54760000"],["111634.54000000","2.72148000"],["111634.53000000","0.01015000"],["111634.52000000","0.00000000"],["111634.51000000","0.03106000"],["111634.50000000","0.00000000"],["111634.48000000","0.02672000"],["111634.47000000","0.00000000"],["111634.40000000","0.00080000"],["111634.38000000","0.00901000"],["111634.37000000","0.00000000"],["111634.18000000","0.00005000"],["111634.17000000","0.40306000"],["111634.15000000","0.01349000"],["111634.01000000","0.04480000"],["111634.00000000","0.02645000"],["111633.89000000","0.00447000"],["111633.88000000","0.05205000"],["111630.00000000","0.00354000"],["111629.52000000","0.00717000"],["111629.35000000","0.00000000"],["111629.16000000","0.48000000"],["111628.70000000","0.00005000"],["111628.68000000","0.00000000"],["111628.62000000","0.04283000"],["111627.43000000","0.00000000"],["111627.18000000","0.00000000"],["111625.97000000","0.00000000"],["111625.30000000","0.00000000"],["111624.55000000","0.00000000"],["111623.26000000","0.00000000"],["111622.82000000","0.00000000"],["111622.69000000","0.15000000"],["111621.74000000","0.32235000"],["111621.58000000","0.00000000"],["111620.06000000","0.00000000"],["111619.08000000","0.00000000"],["111608.15000000","0.00000000"],["111607.37000000","0.00000000"],["111606.81000000","0.00000000"],["111606.12000000","0.00000000"],["111605.00000000","0.00400000"],["111604.55000000","0.00000000"],["111604.05000000","0.00000000"],["111601.12000000","0.00000000"],["111587.65000000","0.00000000"],["111587.32000000","0.13436000"],["111560.23000000","0.00000000"],["111556.19000000","0.00000000"],["111539.66000000","0.00000000"],["111539.28000000","0.00000000"],["111527.67000000","0.00000000"],["111524.80000000","0.00000000"],["111522.93000000","0.13091000"],["111521.39000000","0.00000000"],["111495.01000000","0.06000000"],["111372.02000000","0.00000000"],["111334.54000000","0.00000000"],["111151.51000000","0.00274000"],["109960.02000000","0.00000000"],["108800.01000000","0.02757000"],["108200.01000000","0.02772000"],["107400.01000000","0.02793000"],["106075.42000000","0.00000000"],["106073.40000000","0.00000000"],["106071.72000000","0.00000000"],["106058.10000000","0.00010000"],["106056.81000000","0.00010000"],["106053.54000000","0.00010000"],["106052.81000000","0.00010000"],["106000.00000000","32.64502000"],["103931.00000000","0.00006000"],["100471.00000000","0.01637000"],["100470.00000000","0.00010000"],["89307.64000000","0.00022000"],["55752.88000000","0.00000000"],["55750.00000000","0.00015000"],["55741.92000000","0.00000000"],["40188.44000000","0.00585000"],["33000.00000000","3.87311000"]],"a":[["111634.55000000","0.00000000"],["111634.56000000","0.00000000"],["111634.57000000","0.00000000"],["111634.58000000","0.00000000"],["111634.59000000","0.00000000"],["111634.63000000","0.00000000"],["111634.70000000","0.00000000"],["111634.71000000","0.00000000"],["111634.93000000","0.00000000"],["111634.94000000","0.00000000"],["111635.70000000","0.00000000"],["111636.09000000","0.00000000"],["111636.78000000","0.00000000"],["111636.81000000","0.00000000"],["111637.24000000","0.00000000"],["111637.93000000","0.00000000"],["111637.94000000","0.00000000"],["111638.45000000","0.00000000"],["111638.54000000","0.00000000"],["111638.76000000","0.00000000"],["111638.93000000","0.00000000"],["111639.57000000","0.00000000"],["111639.63000000","0.00000000"],["111640.67000000","0.00000000"],["111640.68000000","0.00055000"],["111640.69000000","0.00045000"],["111642.41000000","0.00010000"],["111642.42000000","0.00010000"],["111643.20000000","0.00122000"],["111646.11000000","0.00010000"],["111646.12000000","0.00005000"],["111646.47000000","0.00010000"],["111646.48000000","0.00005000"],["111646.56000000","0.00000000"],["111647.30000000","0.00000000"],["111647.54000000","0.00010000"],["111647.55000000","0.00005000"],["111648.73000000","0.00000000"],["111649.05000000","0.00005000"],["111649.06000000","0.00005000"],["111650.09000000","0.00000000"],["111651.66000000","0.00005000"],["111651.92000000","0.00000000"],["111652.03000000","0.00000000"],["111652.06000000","0.00000000"],["111652.77000000","0.03188000"],["111652.78000000","0.00000000"],["111653.05000000","0.00000000"],["111653.57000000","0.00007000"],["111653.90000000","0.00069000"],["111654.08000000","0.00000000"],["111654.99000000","0.00000000"],["111655.99000000","0.00000000"],["111656.26000000","0.04000000"],["111656.88000000","0.00300000"],["111656.89000000","0.00000000"],["111658.64000000","0.00073000"],["111660.08000000","0.00000000"],["111660.33000000","0.17187000"],["111661.87000000","0.00000000"],["111662.44000000","0.58188000"],["111662.45000000","0.00000000"],["111662.46000000","0.00000000"],["111662.48000000","0.00000000"],["111662.70000000","0.00000000"],["111664.13000000","0.00000000"],["111665.86000000","0.00000000"],["111666.36000000","0.15000000"],["111666.38000000","0.40306000"],["111668.30000000","0.00000000"],["111668.45000000","0.01390000"],["111668.90000000","0.00005000"],["111670.34000000","0.00000000"],["111671.44000000","0.00000000"],["111671.72000000","0.00000000"],["111674.24000000","0.00000000"],["111676.26000000","0.00000000"],["111678.64000000","0.00000000"],["111680.08000000","0.00000000"],["111680.74000000","0.00000000"],["111682.61000000","0.00000000"],["111696.36000000","0.00000000"],["111697.82000000","0.04800000"],["111707.63000000","0.00000000"],["111723.46000000","0.00000000"],["111723.47000000","0.00000000"],["111725.41000000","0.00100000"],["111725.42000000","0.00100000"],["111733.88000000","0.00000000"],["111741.99000000","0.00000000"],["111788.14000000","0.00000000"],["111853.17000000","0.00000000"],["111916.35000000","0.89307000"],["111978.13000000","0.00000000"],["112044.51000000","0.00000000"],["112055.58000000","0.00000000"],["112129.91000000","0.45000000"],["112150.86000000","0.03493000"],["112181.77000000","0.00000000"],["112192.72000000","0.00000000"],["112583.44000000","0.00000000"],["113309.07000000","0.00100000"]]}
[2025-10-12T10:59:13.187Z] {"e":"depthUpdate","E":1760266753014,"s":"BTCUSDT","U":77965101721,"u":77965104101,"b":[["111655.99000000","7.92081000"],["111655.98000000","0.31247000"],["111655.97000000","0.00020000"],["111655.92000000","0.15014000"],["111655.91000000","0.00020000"],["111655.90000000","0.00000000"],["111655.81000000","0.00000000"],["111655.80000000","0.00000000"],["111655.56000000","0.00000000"],["111655.55000000","0.00005000"],["111655.54000000","0.00000000"],["111654.58000000","0.00005000"],["111654.43000000","0.04046000"],["111654.42000000","0.00010000"],["111653.56000000","0.00000000"],["111653.47000000","0.00005000"],["111652.86000000","0.00000000"],["111652.77000000","0.00000000"],["111652.76000000","0.00000000"],["111652.75000000","0.00000000"],["111652.55000000","0.10666000"],["111652.54000000","0.00010000"],["111652.51000000","0.00000000"],["111651.66000000","0.00005000"],["111651.65000000","0.00000000"],["111651.55000000","0.00000000"],["111651.52000000","0.06657000"],["111651.51000000","0.29541000"],["111651.38000000","0.00010000"],["111651.35000000","0.00000000"],["111651.32000000","0.00000000"],["111651.08000000","0.00000000"],["111650.27000000","0.00100000"],["111650.13000000","0.00044000"],["111649.65000000","0.00000000"],["111649.05000000","0.00000000"],["111648.79000000","0.00000000"],["111647.54000000","0.00000000"],["111647.53000000","0.00000000"],["111647.21000000","0.00000000"],["111647.19000000","0.00005000"],["111646.99000000","0.23509000"],["111646.98000000","0.40306000"],["111646.97000000","0.00000000"],["111646.96000000","0.37062000"],["111646.95000000","0.00000000"],["111646.75000000","0.00938000"],["111646.47000000","0.00000000"],["111646.46000000","0.00000000"],["111646.11000000","0.00000000"],["111646.10000000","0.00000000"],["111645.87000000","0.00000000"],["111645.72000000","0.00000000"],["111645.71000000","0.04475000"],["111645.70000000","0.00000000"],["111645.44000000","0.00000000"],["111644.82000000","0.11524000"],["111644.50000000","0.00000000"],["111643.21000000","0.61694000"],["111643.20000000","0.45020000"],["111643.19000000","0.04003000"],["111643.18000000","0.00000000"],["111642.90000000","0.00000000"],["111642.77000000","0.00005000"],["111642.75000000","0.00000000"],["111642.72000000","0.00005000"],["111642.46000000","0.00000000"],["111642.45000000","0.00000000"],["111642.43000000","0.00000000"],["111642.42000000","0.40306000"],["111642.41000000","0.03998000"],["111642.40000000","0.00000000"],["111642.35000000","0.00005000"],["111642.33000000","0.00000000"],["111642.21000000","0.00000000"],["111642.09000000","0.00000000"],["111641.84000000","0.00010000"],["111641.47000000","0.10574000"],["111640.70000000","0.00000000"],["111640.69000000","0.15000000"],["111640.68000000","0.00000000"],["111640.67000000","0.75764000"],["111640.66000000","0.00205000"],["111640.65000000","0.00000000"],["111640.64000000","0.00007000"],["111640.50000000","0.00885000"],["111640.48000000","0.04815000"],["111640.35000000","0.00000000"],["111639.70000000","0.00005000"],["111639.64000000","0.00005000"],["111639.57000000","0.00000000"],["111639.56000000","0.04508000"],["111639.55000000","0.00000000"],["111639.24000000","0.00069000"],["111638.92000000","0.00000000"],["111638.91000000","0.00000000"],["111638.77000000","0.05760000"],["111638.76000000","0.35807000"],["111638.75000000","0.00000000"],["111638.74000000","0.00000000"],["111638.73000000","0.00000000"],["111638.53000000","0.40306000"],["111638.44000000","0.03998000"],["111638.43000000","0.00000000"],["111638.25000000","0.00005000"],["111638.00000000","0.00000000"],["111637.94000000","0.00000000"],["111637.93000000","0.03998000"],["111637.92000000","0.00000000"],["111637.48000000","0.05280000"],["111637.31000000","0.00007000"],["111637.23000000","0.00000000"],["111637.00000000","0.00000000"],["111636.95000000","0.00000000"],["111636.79000000","0.83785000"],["111636.78000000","0.00000000"],["111636.77000000","0.00000000"],["111636.76000000","0.00000000"],["111636.35000000","0.09360000"],["111636.29000000","0.00000000"],["111636.28000000","0.03998000"],["111636.27000000","0.00000000"],["111636.26000000","0.00010000"],["111636.05000000","0.00000000"],["111636.00000000","0.00000000"],["111635.79000000","0.45000000"],["111635.17000000","0.09360000"],["111635.00000000","0.00000000"],["111634.94000000","0.04187000"],["111634.93000000","0.00000000"],["111634.81000000","0.00000000"],["111634.69000000","0.00000000"],["111634.56000000","0.00000000"],["111634.55000000","0.00000000"],["111634.54000000","1.57855000"],["111634.53000000","0.00500000"],["111634.51000000","0.00000000"],["111634.48000000","0.02152000"],["111634.40000000","0.00000000"],["111634.38000000","0.00896000"],["111634.18000000","0.00000000"],["111634.15000000","0.01344000"],["111634.01000000","0.00000000"],["111634.00000000","0.00260000"],["111633.89000000","0.00000000"],["111633.88000000","0.00000000"],["111633.56000000","0.06240000"],["111633.34000000","0.00000000"],["111632.81000000","0.00000000"],["111632.39000000","0.00000000"],["111632.38000000","0.00000000"],["111632.10000000","0.00000000"],["111632.00000000","0.00260000"],["111631.94000000","0.00044000"],["111631.85000000","0.00000000"],["111631.69000000","0.00000000"],["111631.44000000","0.00000000"],["111631.43000000","0.00000000"],["111631.27000000","0.00000000"],["111631.25000000","0.00000000"],["111631.20000000","0.00000000"],["111631.07000000","0.08000000"],["111630.87000000","0.00015000"],["111630.68000000","0.00000000"],["111630.64000000","0.00537000"],["111630.52000000","0.05251000"],["111630.37000000","0.00895000"],["111630.01000000","0.01164000"],["111630.00000000","0.00349000"],["111629.81000000","0.08504000"],["111629.62000000","0.65357000"],["111629.61000000","1.25396000"],["111629.60000000","0.00007000"],["111629.54000000","0.00000000"],["111629.02000000","0.00000000"],["111628.95000000","0.00000000"],["111628.62000000","0.00000000"],["111628.53000000","0.04283000"],["111628.41000000","0.01792000"],["111627.76000000","0.00000000"],["111627.65000000","0.00000000"],["111627.58000000","0.01390000"],["111627.18000000","0.00000000"],["111627.16000000","1.15492000"],["111626.46000000","0.32234000"],["111626.19000000","0.00000000"],["111626.03000000","1.25396000"],["111624.77000000","0.00000000"],["111622.88000000","0.03829000"],["111622.80000000","0.00000000"],["111622.69000000","0.00000000"],["111622.50000000","0.05477000"],["111622.49000000","0.00008000"],["111622.17000000","0.00006000"],["111622.16000000","0.00000000"],["111621.88000000","0.00000000"],["111620.44000000","1.19190000"],["111620.27000000","0.00269000"],["111620.03000000","0.08504000"],["111619.07000000","0.00000000"],["111618.96000000","0.06646000"],["111618.26000000","0.00000000"],["111617.11000000","0.30208000"],["111616.29000000","0.36022000"],["111616.26000000","0.00179000"],["111615.63000000","0.00000000"],["111615.28000000","0.00000000"],["111614.48000000","0.00000000"],["111612.22000000","0.00000000"],["111612.21000000","0.00300000"],["111611.92000000","0.00000000"],["111610.89000000","0.00000000"],["111610.79000000","0.32238000"],["111610.64000000","0.00000000"],["111610.59000000","0.00000000"],["111609.45000000","0.00012000"],["111608.46000000","0.00000000"],["111608.40000000","0.00009000"],["111607.68000000","0.00000000"],["111607.10000000","0.00000000"],["111606.96000000","0.00000000"],["111606.57000000","0.00000000"],["111606.34000000","0.00000000"],["111606.18000000","0.00018000"],["111605.43000000","0.00000000"],["111605.28000000","0.00000000"],["111604.88000000","0.00000000"],["111603.48000000","1.27993000"],["111602.49000000","0.00000000"],["111602.45000000","0.00000000"],["111602.17000000","0.17904000"],["111601.04000000","0.00000000"],["111601.00000000","0.00000000"],["111600.49000000","0.00000000"],["111599.92000000","0.00000000"],["111598.37000000","0.06836000"],["111598.28000000","0.00000000"],["111598.05000000","0.20543000"],["111598.02000000","0.00000000"],["111598.00000000","0.00269000"],["111596.70000000","0.00000000"],["111593.55000000","0.00000000"],["111590.82000000","0.04362000"],["111590.10000000","0.00000000"],["111589.50000000","0.00000000"],["111589.00000000","0.00008000"],["111584.87000000","0.00000000"],["111583.81000000","0.00000000"],["111582.25000000","0.00623000"],["111581.59000000","0.00630000"],["111579.90000000","0.00655000"],["111577.56000000","0.00618000"],["111577.48000000","0.00000000"],["111571.94000000","0.00000000"],["111570.26000000","0.00000000"],["111569.16000000","0.13426000"],["111564.55000000","0.00000000"],["111564.09000000","0.00000000"],["111562.86000000","0.13426000"],["111562.65000000","0.00090000"],["111561.35000000","0.00000000"],["111560.82000000","0.00000000"],["111560.44000000","0.00000000"],["111556.88000000","0.00000000"],["111555.50000000","0.00008000"],["111555.28000000","0.00000000"],["111555.10000000","0.09759000"],["111554.89000000","0.00000000"],["111554.76000000","0.08795000"],["111554.21000000","0.93757000"],["111553.92000000","0.89597000"],["111553.28000000","0.08795000"],["111552.45000000","0.02451000"],["111552.35000000","0.09845000"],["111552.01000000","0.00163000"],["111550.15000000","0.18030000"],["111549.32000000","0.04051000"],["111545.01000000","0.00000000"],["111542.78000000","0.00000000"],["111542.71000000","0.07757000"],["111542.53000000","0.00223000"],["111541.36000000","0.22377000"],["111540.20000000","0.00000000"],["111539.84000000","0.22377000"],["111539.00000000","0.00000000"],["111538.44000000","0.00000000"],["111536.13000000","0.00000000"],["111531.77000000","0.13436000"],["111530.84000000","0.00000000"],["111527.43000000","0.00000000"],["111526.46000000","0.00000000"],["111525.00000000","0.00000000"],["111522.68000000","0.17904000"],["111522.00000000","0.00268000"],["111518.01000000","0.00223000"],["111517.19000000","0.00000000"],["111516.05000000","0.00000000"],["111512.10000000","0.00000000"],["111504.95000000","0.00000000"],["111488.51000000","0.00008000"],["111479.98000000","0.00000000"],["111471.46000000","0.00000000"],["111456.87000000","0.08694000"],["111443.69000000","0.00000000"],["111430.71000000","0.00089000"],["111424.28000000","0.00000000"],["111419.24000000","0.00000000"],["111418.83000000","0.00000000"],["111417.17000000","0.00000000"],["111416.75000000","4.65992000"],["111401.00000000","0.00000000"],["111399.39000000","0.00000000"],["111361.00000000","0.70054000"],["111329.23000000","0.00000000"],["111324.91000000","0.00000000"],["111319.33000000","0.00000000"],["111306.89000000","0.03582000"],["111305.00000000","0.00000000"],["111300.00000000","0.30989000"],["111253.99000000","0.00000000"],["111163.00000000","1.37783000"],["111152.23000000","0.00000000"],["111121.00000000","2.04696000"],["111086.00000000","0.00000000"],["111079.00000000","2.77593000"],["111053.21000000","0.26378000"],["111007.97000000","0.00000000"],["111004.28000000","0.89110000"],["111000.00000000","16.83585000"],["110986.06000000","0.00000000"],["110167.17000000","0.00000000"],["110135.48000000","0.00008000"],["109981.15000000","0.00100000"],["100489.00000000","0.00034000"],["100470.00000000","0.00000000"],["89324.80000000","0.00022000"],["89307.64000000","0.00000000"],["78158.58000000","0.00000000"],["78153.97000000","0.00000000"],["78149.35000000","0.00000000"],["55828.00000000","0.00140000"]],"a":[["111640.68000000","0.00000000"],["111640.69000000","0.00000000"],["111642.10000000","0.00000000"],["111642.22000000","0.00000000"],["111642.41000000","0.00000000"],["111642.42000000","0.00000000"],["111642.76000000","0.00000000"],["111643.20000000","0.00000000"],["111644.51000000","0.00000000"],["111645.45000000","0.00000000"],["111645.72000000","0.00000000"],["111645.88000000","0.00000000"],["111646.11000000","0.00000000"],["111646.12000000","0.00000000"],["111646.47000000","0.00000000"],["111646.48000000","0.00000000"],["111646.97000000","0.00000000"],["111646.98000000","0.00000000"],["111646.99000000","0.00000000"],["111647.22000000","0.00000000"],["111647.54000000","0.00000000"],["111647.55000000","0.00000000"],["111648.80000000","0.00000000"],["111649.01000000","0.00000000"],["111649.05000000","0.00000000"],["111649.06000000","0.00000000"],["111649.66000000","0.00000000"],["111651.08000000","0.00000000"],["111651.09000000","0.00000000"],["111651.36000000","0.00000000"],["111651.66000000","0.00000000"],["111652.14000000","0.00000000"],["111652.15000000","0.00000000"],["111652.76000000","0.00000000"],["111652.77000000","0.00000000"],["111652.87000000","0.00000000"],["111653.57000000","0.00000000"],["111653.90000000","0.00000000"],["111654.08000000","0.00000000"],["111654.99000000","0.00000000"],["111655.04000000","0.00000000"],["111655.19000000","0.00000000"],["111655.26000000","0.00000000"],["111655.36000000","0.00000000"],["111655.50000000","0.00000000"],["111655.92000000","0.00000000"],["111655.99000000","0.00000000"],["111656.00000000","1.04701000"],["111656.01000000","0.00070000"],["111656.02000000","0.00562000"],["111656.03000000","0.00020000"],["111656.08000000","0.00010000"],["111656.09000000","0.00000000"],["111656.13000000","0.00000000"],["111656.25000000","0.00000000"],["111656.26000000","0.00000000"],["111656.35000000","0.00010000"],["111656.48000000","0.00000000"],["111656.88000000","0.00000000"],["111656.89000000","0.00000000"],["111657.30000000","0.00000000"],["111657.31000000","0.00000000"],["111657.43000000","0.00000000"],["111657.90000000","0.00000000"],["111657.91000000","0.00000000"],["111658.15000000","0.00000000"],["111658.16000000","0.00005000"],["111658.24000000","0.00010000"],["111658.25000000","0.04866000"],["111658.26000000","0.00010000"],["111658.39000000","0.00000000"],["111658.41000000","0.00000000"],["111658.45000000","0.00000000"],["111658.64000000","0.00000000"],["111658.89000000","0.00000000"],["111659.45000000","0.00010000"],["111659.46000000","0.30010000"],["111659.66000000","0.00000000"],["111660.08000000","0.00000000"],["111660.32000000","0.00010000"],["111660.33000000","0.17197000"],["111660.60000000","0.00000000"],["111660.97000000","0.00000000"],["111660.98000000","0.00005000"],["111661.27000000","0.00000000"],["111661.33000000","0.00000000"],["111661.45000000","0.00010000"],["111661.46000000","0.12337000"],["111661.47000000","0.32005000"],["111661.48000000","0.00005000"],["111661.53000000","0.00000000"],["111661.87000000","0.00000000"],["111661.88000000","0.00000000"],["111661.94000000","0.00000000"],["111661.95000000","0.00000000"],["111662.07000000","0.00000000"],["111662.10000000","0.04067000"],["111662.44000000","0.00000000"],["111663.08000000","0.00000000"],["111663.14000000","0.00000000"],["111663.15000000","0.00000000"],["111663.34000000","0.00000000"],["111663.35000000","0.00000000"],["111663.72000000","0.00150000"],["111663.96000000","0.00000000"],["111664.15000000","0.00000000"],["111664.99000000","0.00010000"],["111665.26000000","0.00000000"],["111665.63000000","0.01024000"],["111666.07000000","0.01791000"],["111666.36000000","0.00000000"],["111666.38000000","0.00000000"],["111666.51000000","0.02126000"],["111666.95000000","0.00005000"],["111667.17000000","0.00150000"],["111667.96000000","0.00000000"],["111668.05000000","0.00310000"],["111668.28000000","0.00332000"],["111668.38000000","0.08509000"],["111668.45000000","0.00000000"],["111668.59000000","0.00072000"],["111668.63000000","0.00000000"],["111668.74000000","0.00000000"],["111670.08000000","0.00000000"],["111670.20000000","0.00005000"],["111670.42000000","0.00070000"],["111670.44000000","0.00000000"],["111670.52000000","0.07657000"],["111670.65000000","0.00000000"],["111670.75000000","0.04010000"],["111671.43000000","0.00000000"],["111672.42000000","0.00000000"],["111672.45000000","0.00000000"],["111672.60000000","0.00105000"],["111672.74000000","0.11190000"],["111672.75000000","0.00156000"],["111672.96000000","0.01015000"],["111673.04000000","0.00007000"],["111673.12000000","0.00000000"],["111673.14000000","0.58843000"],["111673.15000000","0.00000000"],["111673.23000000","0.08504000"],["111673.47000000","0.04800000"],["111673.59000000","0.00000000"],["111673.71000000","0.00000000"],["111674.38000000","0.00447000"],["111674.39000000","0.00000000"],["111674.92000000","0.00000000"],["111675.58000000","0.00000000"],["111676.75000000","0.00000000"],["111676.80000000","0.04800000"],["111677.37000000","0.00000000"],["111677.38000000","0.35805000"],["111677.39000000","0.00000000"],["111677.86000000","0.00000000"],["111677.99000000","0.15000000"],["111678.23000000","0.08895000"],["111678.34000000","0.00300000"],["111678.82000000","0.02126000"],["111679.01000000","0.04800000"],["111679.78000000","0.69582000"],["111679.79000000","0.04002000"],["111680.00000000","0.01991000"],["111680.21000000","0.08504000"],["111680.87000000","0.00000000"],["111681.06000000","0.00000000"],["111681.75000000","0.00000000"],["111681.96000000","0.32218000"],["111682.67000000","0.00000000"],["111683.17000000","0.00442000"],["111683.18000000","0.00000000"],["111683.54000000","0.01390000"],["111684.24000000","0.08794000"],["111684.25000000","0.05696000"],["111684.38000000","0.09600000"],["111685.38000000","0.17986000"],["111685.48000000","0.19711000"],["111685.84000000","0.00000000"],["111686.84000000","0.00000000"],["111687.33000000","0.01812000"],["111688.81000000","0.04800000"],["111688.86000000","0.32216000"],["111689.41000000","0.00000000"],["111689.49000000","0.04478000"],["111689.50000000","0.00308000"],["111689.98000000","0.04800000"],["111690.18000000","0.00012000"],["111692.66000000","0.00272000"],["111692.94000000","0.00000000"],["111693.75000000","0.17904000"],["111693.99000000","0.00000000"],["111694.38000000","0.32214000"],["111696.08000000","0.32214000"],["111696.13000000","0.00000000"],["111696.36000000","0.00005000"],["111697.17000000","0.20525000"],["111698.98000000","0.00000000"],["111699.90000000","0.04330000"],["111700.83000000","0.00005000"],["111703.38000000","0.00000000"],["111703.99000000","0.02687000"],["111704.56000000","0.00000000"],["111705.07000000","0.00000000"],["111705.30000000","0.00542000"],["111705.84000000","0.00000000"],["111705.91000000","0.00000000"],["111705.98000000","0.00000000"],["111707.54000000","0.00000000"],["111708.47000000","0.00156000"],["111710.82000000","0.05551000"],["111711.74000000","0.00000000"],["111712.25000000","0.00000000"],["111712.31000000","0.00155000"],["111712.98000000","0.00000000"],["111713.38000000","0.00000000"],["111713.90000000","0.00000000"],["111713.97000000","0.00000000"],["111714.14000000","1.17218000"],["111715.61000000","0.00000000"],["111715.89000000","0.00000000"],["111715.98000000","0.00000000"],["111716.94000000","0.00000000"],["111717.58000000","0.00000000"],["111717.75000000","0.00000000"],["111718.37000000","0.00000000"],["111718.45000000","0.00000000"],["111719.65000000","0.00629000"],["111719.82000000","0.00000000"],["111721.83000000","0.00625000"],["111722.09000000","0.06577000"],["111722.99000000","0.00008000"],["111723.88000000","1.25396000"],["111724.31000000","0.00000000"],["111724.66000000","0.00894000"],["111724.86000000","0.00000000"],["111725.41000000","0.00000000"],["111725.42000000","0.00000000"],["111725.73000000","0.00000000"],["111726.11000000","0.00000000"],["111726.89000000","0.00223000"],["111728.91000000","0.00659000"],["111729.57000000","0.05906000"],["111737.99000000","0.00000000"],["111739.41000000","0.00000000"],["111740.98000000","0.00223000"],["111743.39000000","0.00000000"],["111744.45000000","0.07363000"],["111745.35000000","0.04017000"],["111746.19000000","0.00111000"],["111746.71000000","0.00000000"],["111748.20000000","0.02140000"],["111750.24000000","0.00000000"],["111751.83000000","0.05280000"],["111751.98000000","0.10817000"],["111753.00000000","0.00000000"],["111753.43000000","0.06017000"],["111753.67000000","0.00000000"],["111754.83000000","0.04800000"],["111756.49000000","0.00008000"],["111757.48000000","0.04800000"],["111758.64000000","0.04800000"],["111759.23000000","0.04800000"],["111760.31000000","0.00000000"],["111760.42000000","0.04800000"],["111760.76000000","0.00000000"],["111763.04000000","0.00223000"],["111763.05000000","0.20354000"],["111763.30000000","0.00000000"],["111763.72000000","0.00000000"],["111763.82000000","0.00000000"],["111766.32000000","0.00008000"],["111767.16000000","0.02280000"],["111769.13000000","0.22377000"],["111771.86000000","0.00000000"],["111771.95000000","0.00000000"],["111772.90000000","0.00000000"],["111773.33000000","0.38980000"],["111776.83000000","0.99528000"],["111779.47000000","0.04947000"],["111781.91000000","0.00000000"],["111782.98000000","0.00000000"],["111783.09000000","0.00000000"],["111784.06000000","0.00000000"],["111784.74000000","0.01236000"],["111789.99000000","0.00008000"],["111797.70000000","0.00000000"],["111797.92000000","0.08794000"],["111800.32000000","0.34629000"],["111800.50000000","0.09845000"],["111800.69000000","0.00218000"],["111800.88000000","0.00000000"],["111806.39000000","0.00000000"],["111814.86000000","0.00000000"],["111817.86000000","0.00000000"],["111819.06000000","0.00000000"],["111819.17000000","0.00000000"],["111819.76000000","0.15638000"],["111819.77000000","0.00000000"],["111820.02000000","0.00000000"],["111823.20000000","0.02689000"],["111823.48000000","0.00008000"],["111825.05000000","0.00000000"],["111825.47000000","0.00000000"],["111829.62000000","0.00089000"],["111831.25000000","0.00000000"],["111837.28000000","0.00089000"],["111843.22000000","0.00000000"],["111863.13000000","0.00000000"],["111865.81000000","0.08894000"],["111867.99000000","0.02418000"],["111868.67000000","0.08894000"],["111870.00000000","0.00100000"],["111870.18000000","0.08894000"],["111871.50000000","0.08894000"],["111871.73000000","0.00000000"],["111871.79000000","0.08900000"],["111872.57000000","0.02418000"],["111872.85000000","0.00000000"],["111873.45000000","0.08894000"],["111874.61000000","0.00089000"],["111874.62000000","0.02418000"],["111875.44000000","0.00000000"],["111875.66000000","0.00000000"],["111876.18000000","0.02418000"],["111877.26000000","0.00000000"],["111878.19000000","0.04836000"],["111878.50000000","0.00000000"],["111881.37000000","0.00000000"],["111883.87000000","0.00000000"],["111884.82000000","0.00000000"],["111886.95000000","0.00000000"],["111887.55000000","0.00000000"],["111889.63000000","0.00000000"],["111889.71000000","0.00000000"],["111891.63000000","0.00000000"],["111892.85000000","0.00000000"],["111899.11000000","0.08795000"],["111901.66000000","0.00000000"],["111905.30000000","0.00000000"],["111906.84000000","0.08794000"],["111908.04000000","0.08794000"],["111909.19000000","0.08794000"],["111910.18000000","0.08694000"],["111910.29000000","0.08794000"],["111910.82000000","0.08794000"],["111911.82000000","0.00000000"],["111915.41000000","0.00000000"],["111917.22000000","0.00000000"],["111917.42000000","4.87908000"],["111918.94000000","0.00000000"],["111919.58000000","0.00000000"],["111919.91000000","0.02507000"],["111920.20000000","0.02507000"],["111920.54000000","0.02507000"],["111921.25000000","0.00000000"],["111921.39000000","0.02507000"],["111923.44000000","0.02507000"],["111934.92000000","0.01701000"],["111961.14000000","0.00000000"],["111961.38000000","0.00000000"],["111975.34000000","0.00000000"],["111975.35000000","0.00000000"],["111976.84000000","0.00010000"],["111977.37000000","0.00000000"],["111978.38000000","0.00000000"],["111979.00000000","0.00000000"],["111979.50000000","0.00000000"],["111981.14000000","0.00000000"],["111981.51000000","0.00000000"],["111981.58000000","0.00000000"],["111981.68000000","0.00000000"],["111981.75000000","0.00000000"],["111981.86000000","0.00000000"],["111981.90000000","0.00000000"],["111982.01000000","0.00000000"],["111982.11000000","0.02686000"],["111982.42000000","0.00010000"],["111982.50000000","0.00000000"],["111982.67000000","0.00000000"],["111982.73000000","0.00000000"],["111982.84000000","0.00006000"],["111983.36000000","0.00000000"],["111983.71000000","0.00000000"],["111984.06000000","0.00000000"],["111984.54000000","0.00000000"],["111984.57000000","0.00000000"],["111985.00000000","0.00000000"],["111985.17000000","0.00000000"],["111985.22000000","0.00000000"],["111985.27000000","0.00000000"],["111988.00000000","0.00010000"],["111993.58000000","0.00000000"],["111996.15000000","0.00080000"],["111999.73000000","0.02604000"],["112000.26000000","0.00000000"],["112001.61000000","0.03582000"],["112001.79000000","0.03582000"],["112001.92000000","0.00000000"],["112001.96000000","0.03582000"],["112002.42000000","0.03582000"],["112002.82000000","0.03582000"],["112003.06000000","0.03582000"],["112003.33000000","0.03582000"],["112003.46000000","0.02597000"],["112003.48000000","0.00000000"],["112004.52000000","0.05697000"],["112004.93000000","0.05697000"],["112006.17000000","0.03582000"],["112006.55000000","0.03582000"],["112006.61000000","0.00000000"],["112006.72000000","0.03582000"],["112006.96000000","0.03582000"],["112007.25000000","0.03582000"],["112007.59000000","0.03582000"],["112007.62000000","0.03582000"],["112007.96000000","0.03582000"],["112008.17000000","0.00000000"],["112009.61000000","0.03582000"],["112010.45000000","0.03582000"],["112011.35000000","0.03582000"],["112011.67000000","0.03582000"],["112011.72000000","0.03582000"],["112020.28000000","0.00000000"],["112021.27000000","0.02687000"],["112024.56000000","0.02687000"],["112025.42000000","0.00000000"],["112027.84000000","0.05373000"],["112029.04000000","0.00000000"],["112029.82000000","0.00000000"],["112153.95000000","0.03582000"],["112160.00000000","0.68125000"],["112186.39000000","0.07194000"],["112214.27000000","0.00106000"],["112221.86000000","0.00000000"],["112221.96000000","0.00000000"],["112222.00000000","0.00035000"],["112223.59000000","0.00000000"],["112246.00000000","0.12151000"],["112246.05000000","0.02398000"],["112605.07000000","0.00071000"],["113309.07000000","0.00000000"],["113330.84000000","0.00100000"],["122020.00000000","0.13741000"]]}
[2025-10-12T10:59:14.185Z] {"e":"depthUpdate","E":1760266754014,"s":"BTCUSDT","U":77965104102,"u":77965104294,"b":[["111655.99000000","7.78666000"],["111655.98000000","0.31252000"],["111655.92000000","0.15019000"],["111655.91000000","0.00020000"],["111654.58000000","0.00000000"],["111654.44000000","0.17911000"],["111654.43000000","0.04051000"],["111654.42000000","0.00010000"],["111654.16000000","0.29545000"],["111654.15000000","0.00000000"],["111652.54000000","0.00000000"],["111651.52000000","0.06662000"],["111651.51000000","0.00000000"],["111651.32000000","0.01808000"],["111648.80000000","0.00005000"],["111646.99000000","0.23514000"],["111646.98000000","0.40306000"],["111646.75000000","0.00948000"],["111645.72000000","0.00447000"],["111643.21000000","0.61247000"],["111642.43000000","0.35805000"],["111639.56000000","0.04503000"],["111638.76000000","0.00000000"],["111638.44000000","0.03998000"],["111634.94000000","0.00000000"],["111634.54000000","1.57812000"],["111627.87000000","0.01390000"],["111627.58000000","0.00000000"],["111622.50000000","0.01000000"],["111620.45000000","1.17663000"],["111620.04000000","0.00000000"],["111610.81000000","0.05760000"],["111601.90000000","0.00000000"],["111580.06000000","0.13360000"],["111561.00000000","0.00163000"],["111557.40000000","0.00223000"],["111553.27000000","0.00000000"],["111552.01000000","0.00000000"],["111551.44000000","0.00000000"],["111542.53000000","0.00000000"],["111537.52000000","0.00223000"],["111525.21000000","0.35387000"],["111518.01000000","0.00000000"],["111503.70000000","0.06000000"],["111492.21000000","0.00000000"],["111490.86000000","0.17314000"],["111450.03000000","0.00065000"],["111446.18000000","0.00089000"],["111430.71000000","0.00000000"],["111428.27000000","0.00000000"],["111425.83000000","0.00089000"],["111406.32000000","0.00574000"],["111403.35000000","0.00000000"],["111398.70000000","0.00000000"],["110539.43000000","0.00007000"],["110150.00000000","0.02389000"],["109981.15000000","0.00100000"],["106970.40000000","0.00000000"],["100490.00000000","0.00010000"],["100489.00000000","0.00024000"],["89324.80000000","0.00022000"],["60000.00000000","53.14032000"]],"a":[["111656.00000000","1.30673000"],["111656.01000000","0.00432000"],["111668.38000000","0.08514000"],["111668.73000000","0.02688000"],["111670.75000000","0.04015000"],["111671.98000000","0.00895000"],["111672.75000000","0.00161000"],["111672.95000000","0.00447000"],["111672.96000000","0.01015000"],["111674.24000000","0.00565000"],["111674.38000000","0.00000000"],["111678.24000000","0.00000000"],["111679.82000000","0.00565000"],["111680.82000000","0.00000000"],["111684.31000000","0.04800000"],["111684.77000000","1.55443000"],["111685.36000000","0.07200000"],["111686.54000000","0.07200000"],["111687.91000000","0.00000000"],["111688.19000000","1.19219000"],["111689.49000000","0.00000000"],["111699.01000000","0.00000000"],["111714.14000000","0.00000000"],["111725.89000000","0.00447000"],["111726.88000000","0.02398000"],["111738.58000000","0.00100000"],["111738.59000000","0.00100000"],["111739.70000000","0.00005000"],["111745.96000000","0.00005000"],["111747.79000000","0.00000000"],["111749.98000000","0.02398000"],["111750.89000000","0.31175000"],["111754.86000000","0.04800000"],["111773.33000000","0.00000000"],["111776.83000000","0.00000000"],["111780.95000000","0.00000000"],["111782.13000000","0.00000000"],["111782.48000000","0.02398000"],["111784.25000000","0.99391000"],["111800.69000000","0.00000000"],["111804.84000000","0.00000000"],["111824.22000000","0.00000000"],["111824.75000000","0.00218000"],["111824.96000000","0.50638000"],["111829.62000000","0.00000000"],["111837.28000000","0.00000000"],["111838.28000000","0.00089000"],["111852.98000000","0.00089000"],["111870.86000000","0.08894000"],["111873.45000000","0.00000000"],["111908.28000000","0.08694000"],["111910.17000000","0.08694000"],["111910.82000000","0.00000000"],["111920.47000000","0.02507000"],["111921.21000000","0.02507000"],["111923.38000000","0.02507000"],["111996.15000000","0.00000000"],["112020.22000000","0.00080000"],["112062.95000000","0.55838000"],["112184.80000000","0.00205000"],["113330.84000000","0.00100000"],["114207.94000000","0.00007000"],["119705.00000000","0.00010000"]]}
[2025-10-12T10:59:15.186Z] {"e":"depthUpdate","E":1760266755014,"s":"BTCUSDT","U":77965104295,"u":77965105112,"b":[["111655.99000000","8.63452000"],["111655.98000000","0.31237000"],["111655.93000000","0.00000000"],["111655.92000000","0.28562000"],["111655.91000000","0.00020000"],["111655.83000000","0.00906000"],["111655.82000000","0.00010000"],["111655.60000000","0.01348000"],["111655.59000000","0.00010000"],["111655.55000000","0.03996000"],["111655.54000000","0.00000000"],["111654.58000000","0.00005000"],["111654.45000000","0.00000000"],["111654.44000000","0.00000000"],["111654.43000000","0.04056000"],["111654.42000000","0.00000000"],["111654.16000000","0.29545000"],["111653.76000000","0.00358000"],["111653.34000000","0.00105000"],["111653.14000000","0.01390000"],["111652.56000000","0.00000000"],["111652.55000000","0.10671000"],["111652.09000000","0.00537000"],["111651.74000000","0.04334000"],["111651.52000000","0.06657000"],["111651.38000000","0.00005000"],["111651.32000000","0.01813000"],["111650.36000000","0.40306000"],["111650.28000000","0.00447000"],["111650.27000000","0.00000000"],["111650.13000000","0.00087000"],["111648.88000000","0.00043000"],["111647.01000000","0.35598000"],["111647.00000000","0.35805000"],["111646.99000000","0.00000000"],["111646.96000000","0.29062000"],["111646.75000000","0.00948000"],["111645.72000000","0.00000000"],["111645.71000000","0.00000000"],["111645.55000000","0.04800000"],["111645.45000000","0.00005000"],["111644.82000000","0.00334000"],["111644.80000000","0.00005000"],["111644.39000000","0.00006000"],["111643.23000000","0.15000000"],["111643.21000000","0.45409000"],["111642.43000000","0.00000000"],["111641.48000000","0.00000000"],["111641.47000000","0.10569000"],["111641.16000000","0.07200000"],["111640.69000000","0.00000000"],["111640.67000000","0.31010000"],["111640.66000000","0.00200000"],["111640.50000000","0.00880000"],["111640.04000000","0.05280000"],["111639.70000000","0.00000000"],["111639.56000000","0.03998000"],["111638.93000000","0.06720000"],["111638.85000000","0.06720000"],["111638.78000000","0.00000000"],["111638.77000000","0.05760000"],["111638.55000000","1.95583000"],["111638.54000000","1.25396000"],["111638.28000000","0.32230000"],["111636.79000000","0.00000000"],["111636.71000000","0.13426000"],["111636.40000000","0.13426000"],["111634.97000000","0.06000000"],["111634.74000000","0.08504000"],["111634.55000000","1.25396000"],["111634.15000000","0.00000000"],["111632.58000000","0.32232000"],["111632.34000000","0.00000000"],["111630.64000000","0.00000000"],["111630.37000000","0.00000000"],["111629.52000000","0.00000000"],["111628.53000000","0.00000000"],["111628.41000000","0.00000000"],["111627.94000000","0.00000000"],["111627.87000000","0.00000000"],["111627.67000000","0.00000000"],["111626.33000000","0.00000000"],["111625.70000000","0.00000000"],["111625.61000000","0.00000000"],["111625.01000000","0.00000000"],["111624.83000000","1.16638000"],["111624.74000000","0.00455000"],["111623.38000000","0.30206000"],["111622.66000000","0.00000000"],["111620.45000000","0.00000000"],["111620.44000000","0.00000000"],["111620.03000000","0.00000000"],["111618.71000000","0.00000000"],["111617.11000000","0.00000000"],["111617.10000000","0.00000000"],["111614.20000000","0.00009000"],["111611.98000000","0.00018000"],["111611.92000000","0.03872000"],["111610.79000000","0.00000000"],["111610.64000000","0.99029000"],["111609.09000000","0.00000000"],["111608.40000000","0.00000000"],["111608.31000000","0.08504000"],["111606.33000000","0.00000000"],["111606.18000000","0.00000000"],["111605.25000000","0.00000000"],["111603.80000000","0.00009000"],["111603.19000000","0.13436000"],["111598.54000000","0.04445000"],["111598.00000000","0.00260000"],["111590.82000000","0.00000000"],["111587.32000000","0.00000000"],["111586.67000000","0.02242000"],["111582.76000000","0.00000000"],["111577.87000000","0.00447000"],["111577.18000000","0.00000000"],["111572.80000000","0.00000000"],["111572.76000000","0.00000000"],["111571.20000000","0.00000000"],["111571.06000000","0.00000000"],["111569.84000000","0.00000000"],["111569.16000000","0.00000000"],["111568.45000000","0.00090000"],["111567.18000000","0.00000000"],["111562.86000000","0.00000000"],["111562.65000000","0.00000000"],["111556.42000000","0.00000000"],["111556.28000000","0.00000000"],["111555.44000000","0.01800000"],["111551.72000000","0.08694000"],["111551.71000000","0.00000000"],["111550.33000000","0.22377000"],["111547.75000000","0.00000000"],["111547.69000000","0.00000000"],["111547.37000000","0.00000000"],["111541.36000000","0.00000000"],["111540.10000000","0.13436000"],["111539.84000000","0.00000000"],["111539.46000000","0.00196000"],["111538.31000000","0.00000000"],["111538.30000000","0.00000000"],["111533.57000000","0.00000000"],["111531.77000000","0.00000000"],["111531.61000000","0.00000000"],["111531.60000000","0.00000000"],["111529.64000000","0.53005000"],["111515.25000000","0.00000000"],["111507.86000000","0.08634000"],["111484.40000000","0.00000000"],["111476.75000000","0.00000000"],["111472.45000000","0.00000000"],["111460.85000000","0.09466000"],["111459.29000000","0.99094000"],["111448.58000000","0.00000000"],["111447.31000000","0.00000000"],["111421.36000000","0.00000000"],["111310.33000000","0.03582000"],["111304.72000000","0.03582000"],["111158.82000000","0.00000000"],["111158.02000000","0.00000000"],["109981.15000000","0.00100000"],["100490.00000000","0.00010000"],["89324.80000000","0.00022000"],["60000.00000000","53.14022000"],["40196.16000000","0.00075000"]],"a":[["111656.00000000","0.05867000"],["111656.01000000","0.03813000"],["111656.02000000","0.00567000"],["111656.18000000","0.00010000"],["111656.35000000","0.00010000"],["111656.38000000","0.00010000"],["111656.39000000","0.01353000"],["111656.40000000","0.00010000"],["111658.00000000","0.00010000"],["111658.16000000","0.00000000"],["111658.24000000","0.00000000"],["111658.25000000","0.00000000"],["111658.26000000","0.00000000"],["111659.25000000","0.00000000"],["111659.41000000","0.00000000"],["111659.45000000","0.00000000"],["111659.46000000","0.00000000"],["111659.47000000","0.00000000"],["111659.90000000","0.00547000"],["111660.32000000","0.00000000"],["111660.33000000","0.00000000"],["111660.42000000","0.00005000"],["111660.48000000","0.00000000"],["111660.82000000","0.00000000"],["111660.98000000","0.00000000"],["111661.02000000","0.00727000"],["111661.45000000","0.00000000"],["111661.46000000","0.00000000"],["111661.47000000","0.00000000"],["111661.48000000","0.00000000"],["111662.09000000","0.00000000"],["111662.10000000","0.00005000"],["111662.13000000","0.00010000"],["111662.14000000","0.01796000"],["111662.37000000","0.00000000"],["111663.57000000","0.00000000"],["111663.72000000","0.00155000"],["111665.07000000","0.00000000"],["111665.26000000","0.00010000"],["111665.27000000","0.06010000"],["111665.63000000","0.01024000"],["111666.07000000","0.00000000"],["111666.51000000","0.00000000"],["111666.55000000","0.00000000"],["111666.56000000","0.00010000"],["111666.57000000","0.08010000"],["111666.58000000","0.00000000"],["111666.61000000","0.00000000"],["111666.62000000","0.04774000"],["111667.43000000","0.00000000"],["111667.44000000","0.17187000"],["111667.97000000","0.00000000"],["111667.98000000","0.29577000"],["111668.05000000","0.00305000"],["111668.28000000","0.00332000"],["111668.38000000","0.00005000"],["111668.58000000","0.00000000"],["111668.73000000","0.00000000"],["111668.97000000","0.16000000"],["111669.17000000","0.32000000"],["111669.84000000","0.00000000"],["111670.25000000","0.00000000"],["111670.32000000","0.00000000"],["111670.52000000","0.07657000"],["111670.75000000","0.00005000"],["111671.46000000","0.00000000"],["111671.49000000","0.02688000"],["111671.98000000","0.00000000"],["111672.60000000","0.00005000"],["111672.74000000","0.00000000"],["111672.75000000","0.00156000"],["111672.95000000","0.00000000"],["111672.96000000","0.01015000"],["111673.14000000","0.33950000"],["111673.19000000","0.00000000"],["111673.23000000","0.00000000"],["111673.47000000","0.00000000"],["111674.23000000","0.00000000"],["111674.24000000","0.00000000"],["111675.35000000","0.00070000"],["111675.37000000","0.08504000"],["111675.60000000","0.00005000"],["111675.67000000","0.00000000"],["111676.80000000","0.00000000"],["111677.38000000","0.00000000"],["111677.42000000","0.00000000"],["111677.74000000","0.00000000"],["111677.99000000","0.00000000"],["111678.02000000","0.00000000"],["111678.23000000","0.00000000"],["111678.32000000","0.00447000"],["111678.33000000","0.11190000"],["111678.53000000","0.00005000"],["111678.67000000","0.00000000"],["111678.85000000","0.00000000"],["111678.96000000","0.00895000"],["111678.97000000","0.00000000"],["111679.01000000","0.00000000"],["111679.15000000","0.00000000"],["111679.76000000","0.00000000"],["111679.78000000","0.25795000"],["111679.79000000","0.00000000"],["111679.82000000","0.00000000"],["111680.87000000","0.00000000"],["111680.89000000","0.00000000"],["111680.91000000","0.00000000"],["111681.96000000","0.00000000"],["111682.28000000","0.35805000"],["111682.29000000","0.13426000"],["111683.54000000","0.00000000"],["111683.55000000","0.04000000"],["111683.85000000","0.01390000"],["111684.03000000","0.08504000"],["111684.24000000","0.00000000"],["111684.75000000","0.15000000"],["111684.77000000","1.53279000"],["111685.24000000","0.00000000"],["111686.88000000","0.00000000"],["111688.86000000","0.00000000"],["111689.93000000","0.32215000"],["111690.72000000","0.13426000"],["111690.82000000","0.00000000"],["111691.95000000","0.13426000"],["111694.00000000","0.08894000"],["111695.85000000","0.02127000"],["111696.08000000","0.00000000"],["111699.73000000","0.32213000"],["111699.90000000","0.00000000"],["111712.21000000","0.00000000"],["111714.24000000","0.00005000"],["111714.50000000","0.00000000"],["111719.46000000","0.00000000"],["111719.82000000","0.40306000"],["111722.09000000","0.00010000"],["111723.22000000","0.00000000"],["111724.81000000","0.00000000"],["111725.62000000","0.00000000"],["111726.04000000","0.06765000"],["111729.57000000","0.42584000"],["111730.58000000","1.25396000"],["111733.45000000","0.00005000"],["111734.80000000","0.00632000"],["111738.58000000","0.00000000"],["111738.59000000","0.00000000"],["111738.92000000","0.00000000"],["111739.57000000","0.00100000"],["111739.58000000","0.00100000"],["111743.48000000","0.01800000"],["111749.09000000","0.00005000"],["111750.05000000","0.00000000"],["111752.10000000","0.00000000"],["111758.07000000","0.02435000"],["111758.45000000","0.04800000"],["111758.96000000","0.13426000"],["111763.04000000","0.00223000"],["111763.99000000","0.02398000"],["111767.16000000","0.00000000"],["111768.76000000","0.00000000"],["111769.40000000","0.00005000"],["111774.14000000","0.00000000"],["111774.15000000","0.00000000"],["111775.80000000","0.00000000"],["111777.66000000","0.00000000"],["111778.39000000","0.00000000"],["111782.34000000","0.09439000"],["111782.36000000","0.00196000"],["111809.60000000","0.00005000"],["111810.52000000","0.09759000"],["111812.07000000","0.00000000"],["111812.38000000","0.01937000"],["111814.04000000","0.00000000"],["111818.53000000","0.00000000"],["111818.98000000","0.00000000"],["111823.01000000","0.02398000"],["111845.76000000","0.02398000"],["111870.04000000","0.08894000"],["111871.50000000","0.00000000"],["111871.79000000","0.00006000"],["111872.46000000","0.08894000"],["111874.61000000","0.00089000"],["111875.72000000","0.08894000"],["111877.98000000","0.02418000"],["111878.02000000","0.02418000"],["111878.20000000","0.02398000"],["111880.00000000","0.00129000"],["111881.31000000","0.02418000"],["111881.50000000","0.02418000"],["111881.63000000","0.04836000"],["111881.66000000","0.02418000"],["111883.89000000","0.00000000"],["111884.41000000","0.00000000"],["111884.44000000","0.00000000"],["111886.42000000","0.00000000"],["111887.16000000","0.00000000"],["111909.62000000","0.08694000"],["111910.18000000","0.00000000"],["111910.29000000","0.00000000"],["111912.82000000","0.08694000"],["111914.05000000","0.02398000"],["111922.76000000","0.02507000"],["111960.09000000","0.00000000"],["111968.01000000","0.00000000"],["111973.19000000","0.00010000"],["111974.29000000","0.00000000"],["111976.93000000","0.00000000"],["111977.14000000","0.00000000"],["111978.19000000","0.00000000"],["111980.85000000","0.00000000"],["111981.40000000","0.00000000"],["111981.53000000","0.00000000"],["111983.65000000","0.00000000"],["112004.57000000","0.02597000"],["112005.45000000","0.00000000"],["112005.76000000","0.02597000"],["112007.34000000","0.02597000"],["112013.44000000","0.03582000"],["112013.67000000","0.03582000"],["112013.68000000","0.03582000"],["112013.71000000","0.03582000"],["112015.11000000","0.03582000"],["112032.00000000","0.02686000"],["112032.48000000","0.02686000"],["112038.16000000","0.02398000"],["112040.47000000","0.02398000"],["112042.32000000","0.02398000"],["112044.17000000","0.02403000"],["112045.64000000","0.02398000"],["112046.30000000","0.02398000"],["112164.50000000","0.03582000"],["112228.86000000","0.00000000"],["112242.80000000","0.00000000"],["112246.00000000","0.00161000"],["112246.05000000","0.00000000"],["113330.84000000","0.00100000"],["119067.55000000","0.00007000"],["125669.06000000","0.00008000"]]}
[2025-10-12T10:59:16.186Z] {"e":"depthUpdate","E":1760266756014,"s":"BTCUSDT","U":77965105113,"u":77965105312,"b":[["111655.99000000","8.29853000"],["111655.55000000","0.04001000"],["111654.60000000","0.01390000"],["111654.16000000","0.29545000"],["111653.34000000","0.00100000"],["111653.14000000","0.00000000"],["111651.32000000","0.01813000"],["111650.40000000","0.11190000"],["111650.28000000","0.00000000"],["111647.78000000","0.00043000"],["111647.02000000","0.00447000"],["111647.00000000","0.00000000"],["111646.75000000","0.00953000"],["111645.59000000","0.35804000"],["111645.58000000","0.04800000"],["111644.82000000","0.00339000"],["111644.39000000","0.04816000"],["111644.38000000","0.04800000"],["111643.34000000","0.07200000"],["111643.19000000","0.03998000"],["111642.90000000","0.00043000"],["111642.35000000","0.00000000"],["111642.16000000","0.09360000"],["111642.10000000","0.00005000"],["111638.87000000","0.05760000"],["111636.52000000","0.00005000"],["111636.47000000","0.00895000"],["111636.35000000","0.00000000"],["111635.66000000","0.00043000"],["111635.17000000","0.00000000"],["111631.83000000","0.00000000"],["111630.65000000","0.00000000"],["111630.62000000","0.00000000"],["111629.11000000","0.00000000"],["111625.79000000","0.00000000"],["111624.83000000","0.00000000"],["111624.08000000","0.22377000"],["111619.07000000","0.53629000"],["111618.69000000","0.00000000"],["111617.53000000","0.04800000"],["111613.14000000","0.07200000"],["111610.91000000","0.06720000"],["111610.83000000","0.06720000"],["111609.09000000","0.00000000"],["111608.60000000","0.00000000"],["111583.76000000","0.00015000"],["111578.18000000","0.00015000"],["111572.31000000","0.13426000"],["111571.43000000","0.13426000"],["111555.47000000","0.00000000"],["111554.36000000","0.00000000"],["111550.47000000","0.00000000"],["111550.46000000","0.00000000"],["111547.68000000","0.00000000"],["111546.95000000","0.22377000"],["111534.02000000","0.11194000"],["111507.19000000","0.06000000"],["111015.35000000","0.89110000"],["111004.28000000","0.00000000"],["109981.15000000","0.00100000"],["102703.79000000","0.00000000"],["100490.00000000","0.00010000"],["89324.80000000","0.00022000"],["42000.00000000","1.49196000"],["40196.16000000","0.00105000"]],"a":[["111656.00000000","0.23312000"],["111656.01000000","0.03813000"],["111656.08000000","0.00010000"],["111656.18000000","0.00000000"],["111656.79000000","0.00005000"],["111658.00000000","0.00000000"],["111661.02000000","0.00727000"],["111661.51000000","0.00015000"],["111661.52000000","0.17192000"],["111662.14000000","0.01796000"],["111663.97000000","0.00005000"],["111663.98000000","0.29543000"],["111665.26000000","0.00005000"],["111665.27000000","0.06005000"],["111665.63000000","0.01019000"],["111666.56000000","0.00000000"],["111666.57000000","0.08005000"],["111667.17000000","0.00155000"],["111667.41000000","0.04106000"],["111667.44000000","0.00000000"],["111668.28000000","0.00337000"],["111668.53000000","0.04095000"],["111670.20000000","0.00000000"],["111670.52000000","0.07652000"],["111671.49000000","0.00000000"],["111672.96000000","0.01015000"],["111675.35000000","0.00000000"],["111675.37000000","0.08504000"],["111675.41000000","0.00000000"],["111675.52000000","0.00070000"],["111684.25000000","0.00000000"],["111685.18000000","0.04800000"],["111685.24000000","0.02686000"],["111688.19000000","0.00000000"],["111690.82000000","0.02238000"],["111694.37000000","0.05696000"],["111697.82000000","0.00000000"],["111706.44000000","0.32211000"],["111709.77000000","0.00005000"],["111714.24000000","0.00000000"],["111739.57000000","0.00000000"],["111739.58000000","0.00000000"],["111739.59000000","0.00000000"],["111750.27000000","0.00005000"],["111753.67000000","0.00000000"],["111768.92000000","0.04800000"],["111774.81000000","0.05241000"],["111782.80000000","0.00005000"],["111924.76000000","0.02507000"],["111925.22000000","0.02507000"],["111925.51000000","0.02507000"],["111925.88000000","0.02507000"],["111927.85000000","0.02507000"],["111982.42000000","0.00000000"],["111988.00000000","0.00000000"],["112258.90000000","0.02398000"],["112258.92000000","0.02398000"],["112259.00000000","0.04996000"],["113330.84000000","0.00100000"]]}
[2025-10-12T10:59:17.186Z] {"e":"depthUpdate","E":1760266757014,"s":"BTCUSDT","U":77965105313,"u":77965105458,"b":[["111655.99000000","8.10541000"],["111655.92000000","0.28567000"],["111655.91000000","0.00020000"],["111655.90000000","0.00080000"],["111655.89000000","0.00010000"],["111655.60000000","0.01353000"],["111655.59000000","0.00000000"],["111655.55000000","0.04006000"],["111655.37000000","0.01005000"],["111654.60000000","0.00000000"],["111654.43000000","0.04061000"],["111654.16000000","0.29545000"],["111653.77000000","0.00000000"],["111652.55000000","0.10666000"],["111649.02000000","0.00005000"],["111647.76000000","0.00044000"],["111646.75000000","0.00953000"],["111646.00000000","0.00043000"],["111645.89000000","0.00005000"],["111645.71000000","0.00000000"],["111644.39000000","0.04811000"],["111644.38000000","0.04800000"],["111640.50000000","0.00800000"],["111637.36000000","0.01390000"],["111634.54000000","1.55168000"],["111628.15000000","0.00000000"],["111626.19000000","1.21819000"],["111624.50000000","0.22377000"],["111610.85000000","0.05760000"],["111575.78000000","0.04800000"],["111549.92000000","0.00000000"],["111548.75000000","0.00000000"],["111548.69000000","0.00000000"],["111493.11000000","0.00000000"],["111033.79000000","0.00000000"],["111015.35000000","0.00000000"],["109981.15000000","0.00100000"],["100490.00000000","0.00000000"],["100489.00000000","0.00034000"],["89324.80000000","0.00022000"],["33000.00000000","3.87311000"]],"a":[["111656.00000000","0.25649000"],["111656.01000000","0.00100000"],["111656.03000000","0.00020000"],["111656.10000000","0.00080000"],["111656.11000000","0.00010000"],["111656.39000000","0.01358000"],["111656.40000000","0.00000000"],["111661.33000000","0.29538000"],["111661.52000000","0.17197000"],["111662.14000000","0.01801000"],["111663.97000000","0.00010000"],["111663.98000000","0.00010000"],["111665.63000000","0.01024000"],["111667.41000000","0.00000000"],["111670.52000000","0.07662000"],["111670.75000000","0.00000000"],["111671.76000000","0.00000000"],["111671.98000000","0.02693000"],["111672.75000000","0.00151000"],["111700.70000000","1.22162000"],["111703.08000000","0.00000000"],["111719.46000000","0.03582000"],["111726.31000000","0.05430000"],["111740.57000000","0.18004000"],["111740.58000000","0.00100000"],["111753.67000000","0.04800000"],["111785.97000000","0.00000000"],["111890.00000000","0.00189000"],["111924.42000000","0.04297000"],["112258.98000000","0.04796000"],["113330.84000000","0.00100000"],["149960.00000000","2.17590000"]]}
[2025-10-12T10:59:18.186Z] {"e":"depthUpdate","E":1760266758014,"s":"BTCUSDT","U":77965105459,"u":77965105676,"b":[["111655.99000000","8.06078000"],["111655.92000000","0.28567000"],["111655.90000000","0.01090000"],["111655.55000000","0.03996000"],["111655.37000000","0.00000000"],["111654.43000000","0.04061000"],["111654.16000000","0.29540000"],["111653.80000000","0.01390000"],["111651.32000000","0.01818000"],["111650.41000000","0.00042000"],["111650.40000000","0.00000000"],["111650.36000000","0.40311000"],["111647.75000000","0.05545000"],["111646.75000000","0.00953000"],["111645.71000000","0.04475000"],["111645.55000000","0.04805000"],["111645.35000000","0.01575000"],["111644.82000000","0.11524000"],["111644.39000000","0.04806000"],["111644.38000000","0.04800000"],["111641.53000000","0.00074000"],["111638.28000000","0.00000000"],["111637.36000000","0.00000000"],["111633.39000000","0.00005000"],["111630.52000000","0.00000000"],["111628.28000000","0.00000000"],["111627.77000000","0.00000000"],["111622.21000000","0.06016000"],["111621.12000000","0.32235000"],["111608.60000000","0.00005000"],["111587.69000000","0.00000000"],["111490.08000000","0.00000000"],["111033.79000000","0.89110000"],["110111.00000000","0.02639000"],["109981.15000000","0.00100000"],["106000.00000000","32.64502000"],["89325.00000000","0.00200000"],["89324.80000000","0.00022000"],["42000.00000000","1.49096000"]],"a":[["111656.00000000","0.51412000"],["111656.01000000","0.05139000"],["111656.39000000","0.01358000"],["111656.79000000","0.00000000"],["111661.02000000","0.00727000"],["111661.32000000","0.00010000"],["111661.33000000","0.29548000"],["111662.13000000","0.00000000"],["111662.14000000","0.01801000"],["111663.39000000","0.00010000"],["111663.40000000","0.05569000"],["111663.97000000","0.00000000"],["111663.98000000","0.00000000"],["111665.26000000","0.00000000"],["111665.27000000","0.06000000"],["111665.63000000","0.01019000"],["111666.56000000","0.00000000"],["111667.17000000","0.00150000"],["111670.52000000","0.07657000"],["111671.98000000","0.00005000"],["111671.99000000","0.02688000"],["111672.25000000","0.00005000"],["111672.75000000","0.00156000"],["111675.52000000","0.00000000"],["111678.02000000","0.00100000"],["111689.03000000","0.04800000"],["111691.26000000","0.04800000"],["111696.57000000","1.30383000"],["111700.37000000","0.00000000"],["111702.60000000","0.00000000"],["111706.43000000","0.02398000"],["111711.99000000","0.02398000"],["111723.87000000","0.02398000"],["111726.04000000","0.00000000"],["111728.76000000","0.00360000"],["111740.57000000","0.17904000"],["111740.58000000","0.00000000"],["111752.84000000","0.00000000"],["111758.45000000","0.00000000"],["111867.19000000","0.02398000"],["111881.66000000","0.00000000"],["111901.19000000","0.02398000"],["111935.76000000","0.02398000"],["113330.84000000","0.00100000"]]}
[2025-10-12T10:59:19.186Z] {"e":"depthUpdate","E":1760266759015,"s":"BTCUSDT","U":77965105677,"u":77965105767,"b":[["111655.99000000","8.06160000"],["111655.55000000","0.03996000"],["111654.66000000","0.00000000"],["111654.43000000","0.04056000"],["111653.80000000","0.00000000"],["111653.76000000","0.00363000"],["111653.50000000","0.01390000"],["111645.35000000","0.01575000"],["111638.75000000","0.00005000"],["111637.58000000","0.32231000"],["111629.20000000","0.00000000"],["111627.99000000","0.00000000"],["111621.12000000","0.00000000"],["111611.95000000","0.00000000"],["111584.55000000","0.00219000"],["111409.09000000","0.00574000"],["111406.32000000","0.00000000"],["109981.15000000","0.00100000"],["106970.40000000","0.00012000"],["100490.00000000","0.00000000"],["89324.80000000","0.00022000"],["86000.00000000","9.01043000"],["40196.16000000","0.00135000"]],"a":[["111656.00000000","0.37450000"],["111656.01000000","0.05144000"],["111656.39000000","0.01358000"],["111661.02000000","0.00727000"],["111661.32000000","0.00000000"],["111661.33000000","0.00000000"],["111662.13000000","0.00010000"],["111662.14000000","0.01806000"],["111663.40000000","0.05569000"],["111663.51000000","0.29543000"],["111670.52000000","0.07657000"],["111671.99000000","0.00000000"],["111672.03000000","0.00000000"],["111672.04000000","0.02688000"],["111672.75000000","0.00156000"],["111675.34000000","0.00000000"],["111675.35000000","0.00000000"],["111678.95000000","0.00005000"],["111726.82000000","0.06819000"],["111741.52000000","0.00100000"],["111741.53000000","0.00100000"],["111758.45000000","0.04800000"],["113330.84000000","0.00100000"],["114468.48000000","0.00896000"],["118000.00000000","19.27730000"]]}
[2025-10-12T10:59:20.186Z] {"e":"depthUpdate","E":1760266760014,"s":"BTCUSDT","U":77965105768,"u":77965105827,"b":[["111655.99000000","8.36166000"],["111653.76000000","0.00363000"],["111653.50000000","0.00000000"],["111653.43000000","0.01390000"],["111645.35000000","0.01575000"],["111635.40000000","0.00005000"],["111627.82000000","0.00000000"],["111626.20000000","1.17712000"],["111626.19000000","0.00000000"],["111615.30000000","0.00000000"],["111605.99000000","0.00558000"],["111561.42000000","0.01401000"],["111523.31000000","0.08694000"],["110150.00000000","0.02394000"],["109981.15000000","0.00100000"],["100490.00000000","0.00010000"],["100489.00000000","0.00024000"],["89324.80000000","0.00022000"]],"a":[["111656.00000000","0.37442000"],["111656.01000000","0.05144000"],["111656.39000000","0.01358000"],["111661.02000000","0.00727000"],["111661.25000000","0.00010000"],["111661.26000000","0.29543000"],["111662.13000000","0.00000000"],["111662.14000000","0.01801000"],["111663.40000000","0.05569000"],["111663.51000000","0.00000000"],["111667.41000000","0.04096000"],["111672.75000000","0.00156000"],["111682.30000000","0.00005000"],["111700.20000000","1.22470000"],["111700.70000000","0.00000000"],["111760.24000000","0.01401000"],["111872.49000000","0.08694000"],["112062.95000000","0.00000000"],["112066.64000000","0.55838000"],["113330.84000000","0.00100000"],["120000.00000000","40.81984000"]]}
[2025-10-12T10:59:21.185Z] {"e":"depthUpdate","E":1760266761014,"s":"BTCUSDT","U":77965105828,"u":77965105928,"b":[["111655.99000000","8.35791000"],["111655.98000000","0.31247000"],["111653.76000000","0.00358000"],["111653.43000000","0.00000000"],["111645.35000000","0.01580000"],["111637.58000000","0.00000000"],["111628.22000000","0.01390000"],["111623.38000000","0.00000000"],["111621.76000000","0.30207000"],["111620.48000000","0.32236000"],["111579.64000000","0.00000000"],["111561.42000000","0.00000000"],["111033.79000000","0.00000000"],["110986.06000000","0.00000000"],["110648.01000000","0.00239000"],["109981.15000000","0.00100000"],["102703.79000000","0.00010000"],["100490.00000000","0.00010000"],["89324.80000000","0.00022000"]],"a":[["111656.00000000","0.59284000"],["111656.01000000","0.05139000"],["111656.39000000","0.01353000"],["111658.82000000","0.00010000"],["111658.83000000","0.29544000"],["111659.02000000","0.00005000"],["111659.90000000","0.00552000"],["111660.48000000","0.00010000"],["111660.49000000","0.04699000"],["111661.02000000","0.00727000"],["111661.25000000","0.00000000"],["111661.26000000","0.00000000"],["111661.52000000","0.17192000"],["111663.39000000","0.00000000"],["111663.40000000","0.05564000"],["111666.57000000","0.08000000"],["111666.62000000","0.00000000"],["111667.17000000","0.00155000"],["111670.52000000","0.07662000"],["111671.76000000","0.01827000"],["111671.98000000","0.00000000"],["111672.75000000","0.00151000"],["111677.99000000","0.15000000"],["111684.75000000","0.00000000"],["111685.22000000","0.32217000"],["111706.44000000","0.00000000"],["111753.05000000","0.00000000"],["112773.61000000","0.00234000"],["113330.84000000","0.00100000"]]}
[2025-10-12T10:59:22.185Z] {"e":"depthUpdate","E":1760266762014,"s":"BTCUSDT","U":77965105929,"u":77965106051,"b":[["111655.99000000","8.39503000"],["111655.98000000","0.31237000"],["111654.16000000","0.29545000"],["111652.55000000","0.10661000"],["111651.74000000","0.00000000"],["111645.71000000","0.00000000"],["111644.39000000","0.04811000"],["111638.10000000","0.04340000"],["111632.05000000","0.00005000"],["111628.22000000","0.00000000"],["111627.69000000","0.00000000"],["111610.65000000","0.02597000"],["111521.64000000","0.01401000"],["111361.00000000","0.00000000"],["111360.00000000","0.70225000"],["111357.25000000","0.02997000"],["111163.00000000","0.00000000"],["111157.00000000","1.37783000"],["111121.00000000","0.00044000"],["111115.00000000","2.04652000"],["111079.00000000","0.00000000"],["111073.00000000","2.77703000"],["111026.41000000","0.89110000"],["109981.15000000","0.00100000"],["109777.28000000","0.00000000"],["102703.79000000","0.00000000"],["100490.00000000","0.00010000"],["89324.80000000","0.00022000"],["40196.16000000","0.00150000"],["33000.00000000","3.87311000"]],"a":[["111656.00000000","0.59587000"],["111656.01000000","0.00095000"],["111656.39000000","0.01358000"],["111658.82000000","0.00000000"],["111658.83000000","0.00000000"],["111659.02000000","0.00000000"],["111660.42000000","0.00000000"],["111660.49000000","0.04704000"],["111661.00000000","0.00010000"],["111661.01000000","0.29548000"],["111661.52000000","0.17197000"],["111663.39000000","0.00005000"],["111663.40000000","0.05569000"],["111677.99000000","0.00000000"],["111679.78000000","0.38275000"],["111680.88000000","0.15000000"],["111685.65000000","0.00005000"],["111695.96000000","1.23377000"],["111700.20000000","0.00000000"],["111708.93000000","0.00000000"],["111726.82000000","0.00000000"],["111729.57000000","0.40635000"],["111760.24000000","0.00000000"],["111762.44000000","0.00000000"],["111782.34000000","0.00000000"],["111824.75000000","0.00000000"],["111842.28000000","0.00218000"],["112020.22000000","0.00000000"],["112037.76000000","0.00080000"],["112160.00000000","0.00342000"],["112167.00000000","0.67783000"],["112208.98000000","0.00000000"],["112258.38000000","0.02398000"],["113330.84000000","0.00100000"],["119759.00000000","0.00010000"]]}
[2025-10-12T10:59:23.185Z] {"e":"depthUpdate","E":1760266763014,"s":"BTCUSDT","U":77965106052,"u":77965106154,"b":[["111655.99000000","8.36063000"],["111655.92000000","0.28567000"],["111655.90000000","0.00080000"],["111655.55000000","0.04001000"],["111652.55000000","0.10666000"],["111646.75000000","0.00953000"],["111645.71000000","0.04475000"],["111644.38000000","0.04800000"],["111640.67000000","0.30981000"],["111627.98000000","0.00000000"],["111627.52000000","0.01390000"],["111604.51000000","0.04394000"],["111598.54000000","0.00000000"],["111026.41000000","0.00000000"],["111015.35000000","0.89110000"],["110648.01000000","0.00000000"],["110016.41000000","0.00022000"],["109981.15000000","0.00100000"],["100490.00000000","0.00010000"],["89324.80000000","0.00022000"]],"a":[["111656.00000000","0.52047000"],["111656.01000000","0.06560000"],["111656.39000000","0.01358000"],["111659.90000000","0.00547000"],["111660.42000000","0.00005000"],["111660.48000000","0.00000000"],["111660.49000000","0.00000000"],["111662.14000000","0.01806000"],["111663.38000000","0.05270000"],["111663.39000000","0.00010000"],["111665.26000000","0.00005000"],["111665.27000000","0.06005000"],["111672.04000000","0.02693000"],["111734.41000000","0.06783000"],["111967.68000000","0.00000000"],["111998.73000000","0.07520000"],["112020.63000000","0.09419000"],["112067.38000000","0.00000000"],["112115.34000000","0.00000000"],["112161.93000000","0.00000000"],["112773.61000000","0.00000000"],["113330.84000000","0.00100000"]]}
[2025-10-12T10:59:24.185Z] {"e":"depthUpdate","E":1760266764014,"s":"BTCUSDT","U":77965106155,"u":77965106239,"b":[["111655.99000000","8.36051000"],["111638.96000000","0.00293000"],["111627.56000000","0.01390000"],["111627.52000000","0.00000000"],["111626.20000000","0.00000000"],["111625.68000000","1.17383000"],["111600.00000000","0.24212000"],["111521.64000000","0.00000000"],["111410.46000000","0.00574000"],["111409.09000000","0.00000000"],["111300.00000000","0.30983000"],["111033.79000000","0.89110000"],["111015.35000000","0.00000000"],["111000.00000000","16.83579000"],["110986.06000000","0.00000000"],["110700.00000000","2.18469000"],["110400.00000000","0.85558000"],["110100.00000000","0.14588000"],["109981.15000000","0.00100000"],["109800.00000000","11.81896000"],["109500.00000000","12.94247000"],["106000.00000000","32.64502000"],["100490.00000000","0.00010000"],["89324.80000000","0.00022000"],["60000.00000000","53.14032000"]],"a":[["111656.00000000","0.52052000"],["111656.01000000","0.03699000"],["111662.14000000","0.01811000"],["111663.37000000","0.00010000"],["111663.38000000","0.05275000"],["111663.39000000","0.00005000"],["111663.40000000","0.05564000"],["111665.26000000","0.00000000"],["111665.27000000","0.06000000"],["111672.04000000","0.02688000"],["111695.96000000","0.00000000"],["111696.39000000","1.19127000"],["111873.20000000","0.00000000"],["111920.41000000","0.00000000"],["111967.45000000","0.00000000"],["112020.63000000","0.00000000"],["112200.00000000","0.46286000"],["112500.00000000","6.49735000"],["113330.84000000","0.00100000"]]}
[2025-10-12T10:59:25.185Z] {"e":"depthUpdate","E":1760266765014,"s":"BTCUSDT","U":77965106240,"u":77965106328,"b":[["111655.99000000","8.36046000"],["111655.83000000","0.00906000"],["111655.60000000","0.01353000"],["111653.76000000","0.00358000"],["111652.09000000","0.00537000"],["111650.97000000","0.00717000"],["111649.85000000","0.01791000"],["111645.55000000","0.04805000"],["111645.39000000","0.01579000"],["111645.35000000","0.00005000"],["111644.39000000","0.04806000"],["111637.64000000","0.32231000"],["111634.70000000","0.00044000"],["111634.54000000","1.55193000"],["111634.38000000","0.00000000"],["111632.31000000","0.00000000"],["111628.70000000","0.01395000"],["111627.56000000","0.00000000"],["111620.48000000","0.00000000"],["111422.58000000","4.66196000"],["111416.75000000","0.00000000"],["111168.61000000","0.03582000"],["109981.15000000","0.00100000"],["100490.00000000","0.00010000"],["100489.00000000","0.00024000"],["89324.80000000","0.00022000"],["60000.00000000","53.14022000"],["40196.16000000","0.00165000"]],"a":[["111656.00000000","0.51036000"],["111656.01000000","0.04486000"],["111656.16000000","0.00896000"],["111656.39000000","0.01358000"],["111658.23000000","0.00358000"],["111659.90000000","0.00547000"],["111661.02000000","0.00727000"],["111662.14000000","0.01811000"],["111663.39000000","0.00005000"],["111663.40000000","0.05569000"],["111672.04000000","0.02688000"],["111761.21000000","0.13186000"],["111783.09000000","0.09439000"],["111794.50000000","0.02398000"],["111812.38000000","0.01937000"],["111816.50000000","0.00000000"],["111899.64000000","4.61041000"],["111917.42000000","0.00000000"],["112163.58000000","0.03582000"],["112258.03000000","0.02398000"],["113330.84000000","0.00100000"],["120000.00000000","40.79409000"]]}
[2025-10-12T10:59:26.185Z] {"e":"depthUpdate","E":1760266766014,"s":"BTCUSDT","U":77965106329,"u":77965106536,"b":[["111655.99000000","8.35576000"],["111655.98000000","0.32176000"],["111653.34000000","0.00000000"],["111651.32000000","0.01823000"],["111650.97000000","0.00722000"],["111645.35000000","0.00000000"],["111634.54000000","1.54835000"],["111628.70000000","0.01395000"],["111627.62000000","0.00000000"],["111621.76000000","0.00000000"],["111620.01000000","0.30207000"],["111033.79000000","0.00000000"],["109981.15000000","0.00100000"],["100490.00000000","0.00010000"],["89324.80000000","0.00022000"],["42000.00000000","1.49196000"],["40196.16000000","0.00180000"],["33000.00000000","3.87311000"]],"a":[["111656.00000000","0.60111000"],["111656.01000000","0.00105000"],["111656.02000000","0.00572000"],["111656.11000000","0.00010000"],["111656.15000000","0.00000000"],["111656.16000000","0.00901000"],["111656.17000000","0.00010000"],["111656.35000000","0.00000000"],["111656.39000000","0.01363000"],["111658.57000000","0.00000000"],["111658.58000000","0.00000000"],["111659.02000000","0.00005000"],["111659.90000000","0.00547000"],["111660.42000000","0.00000000"],["111660.80000000","0.00010000"],["111660.81000000","0.29549000"],["111661.00000000","0.00000000"],["111661.01000000","0.00000000"],["111662.14000000","0.01806000"],["111663.37000000","0.00005000"],["111663.38000000","0.05270000"],["111663.39000000","0.00000000"],["111663.40000000","0.05564000"],["111667.17000000","0.00155000"],["111667.41000000","0.04127000"],["111670.52000000","0.07652000"],["111671.76000000","0.00000000"],["111671.79000000","0.01805000"],["111671.85000000","0.04000000"],["111673.56000000","0.00100000"],["111677.99000000","0.15000000"],["111678.02000000","0.00000000"],["111680.88000000","0.00000000"],["111683.55000000","0.00000000"],["111728.76000000","0.00000000"],["111740.57000000","0.17904000"],["111740.58000000","0.00000000"],["111741.52000000","0.00100000"],["111741.53000000","0.00100000"],["112062.95000000","0.55838000"],["112066.64000000","0.00000000"],["113330.84000000","0.00100000"]]}
[2025-10-12T10:59:27.186Z] {"e":"depthUpdate","E":1760266767014,"s":"BTCUSDT","U":77965106537,"u":77965106658,"b":[["111655.99000000","8.35598000"],["111654.43000000","0.04051000"],["111650.97000000","0.00727000"],["111650.24000000","0.00100000"],["111645.39000000","0.01579000"],["111631.94000000","0.00000000"],["111628.70000000","0.00005000"],["111627.67000000","0.01390000"],["111620.52000000","0.06589000"],["111598.37000000","0.00000000"],["111556.41000000","0.00000000"],["111355.99000000","0.00000000"],["111026.41000000","0.89110000"],["109981.15000000","0.00100000"],["102703.79000000","0.00000000"],["100490.00000000","0.00010000"],["89324.80000000","0.00022000"]],"a":[["111656.00000000","0.55183000"],["111656.01000000","0.05783000"],["111656.15000000","0.00000000"],["111656.39000000","0.01358000"],["111659.90000000","0.00547000"],["111660.80000000","0.00000000"],["111660.81000000","0.00000000"],["111660.83000000","0.00010000"],["111660.84000000","0.29544000"],["111662.13000000","0.00000000"],["111662.14000000","0.01801000"],["111662.91000000","0.00000000"],["111662.92000000","0.00000000"],["111663.38000000","0.05270000"],["111830.16000000","0.00218000"],["111842.28000000","0.00000000"],["112025.63000000","0.00080000"],["112037.76000000","0.00000000"],["113330.84000000","0.00100000"]]}
[2025-10-12T10:59:28.185Z] {"e":"depthUpdate","E":1760266768014,"s":"BTCUSDT","U":77965106659,"u":77965106770,"b":[["111655.99000000","8.34974000"],["111627.67000000","0.00000000"],["111627.58000000","0.01390000"],["111625.69000000","1.23473000"],["111625.68000000","0.00000000"],["111620.52000000","0.00000000"],["111620.38000000","0.06727000"],["111577.84000000","0.07522000"],["109981.15000000","0.00100000"],["100490.00000000","0.00000000"],["100489.00000000","0.00034000"],["89324.80000000","0.00022000"],["42000.00000000","1.49096000"]],"a":[["111656.00000000","0.59597000"],["111656.01000000","0.00095000"],["111656.15000000","0.00010000"],["111656.39000000","0.01363000"],["111659.90000000","0.00547000"],["111660.83000000","0.00000000"],["111660.84000000","0.00000000"],["111662.13000000","0.00010000"],["111662.14000000","0.01811000"],["111662.99000000","0.00005000"],["111663.00000000","0.29548000"],["111663.37000000","0.00000000"],["111663.38000000","0.05275000"],["111689.43000000","1.66994000"],["111693.66000000","1.19494000"],["111696.39000000","0.00000000"],["111838.60000000","0.00000000"],["111864.71000000","0.07520000"],["112992.05000000","0.00000000"],["113330.84000000","0.00100000"],["120000.00000000","40.81984000"]]}
[2025-10-12T10:59:29.185Z] {"e":"depthUpdate","E":1760266769014,"s":"BTCUSDT","U":77965106771,"u":77965106842,"b":[["111655.99000000","8.34949000"],["111655.98000000","0.32166000"],["111627.72000000","0.00000000"],["111627.65000000","0.00000000"],["111627.58000000","0.00000000"],["111422.59000000","4.80867000"],["111422.58000000","0.00000000"],["111317.44000000","0.03582000"],["111033.79000000","0.89110000"],["111026.41000000","0.00000000"],["109981.15000000","0.00100000"],["106000.00000000","32.64513000"],["100490.00000000","0.00010000"],["100489.00000000","0.00024000"],["89324.80000000","0.00022000"]],"a":[["111656.00000000","0.55079000"],["111656.01000000","0.04520000"],["111656.15000000","0.00000000"],["111663.00000000","0.29543000"],["111663.38000000","0.05270000"],["111667.17000000","0.00150000"],["111667.41000000","0.00000000"],["111667.50000000","0.04017000"],["111671.79000000","0.00000000"],["111677.99000000","0.00000000"],["111680.88000000","0.15000000"],["111734.41000000","0.00000000"],["111761.21000000","0.00000000"],["111784.25000000","0.00000000"],["111796.45000000","0.77016000"],["111798.17000000","0.99775000"],["111819.01000000","0.00218000"],["111830.16000000","0.00000000"],["111842.20000000","0.00000000"],["111899.64000000","0.00000000"],["111899.91000000","4.84305000"],["111922.44000000","0.04197000"],["112014.07000000","0.03582000"],["112014.47000000","0.00080000"],["112025.63000000","0.00000000"],["112995.86000000","0.00022000"],["113330.84000000","0.00100000"]]}
[2025-10-12T10:59:30.186Z] {"e":"depthUpdate","E":1760266770014,"s":"BTCUSDT","U":77965106843,"u":77965107223,"b":[["111656.00000000","10.39965000"],["111655.99000000","0.73927000"],["111655.98000000","0.32166000"],["111655.97000000","0.00020000"],["111655.92000000","0.00010000"],["111655.91000000","0.00000000"],["111655.83000000","0.00911000"],["111655.82000000","0.00010000"],["111655.74000000","0.00100000"],["111655.55000000","0.04001000"],["111654.43000000","0.04046000"],["111654.16000000","0.00000000"],["111652.55000000","0.00010000"],["111652.09000000","0.00542000"],["111651.52000000","0.06662000"],["111651.32000000","0.01818000"],["111650.97000000","0.00722000"],["111650.24000000","0.00000000"],["111649.85000000","0.01796000"],["111648.92000000","0.04454000"],["111647.75000000","0.00000000"],["111646.75000000","0.00948000"],["111645.71000000","0.00000000"],["111645.39000000","0.01584000"],["111644.39000000","0.04811000"],["111642.07000000","0.32229000"],["111627.69000000","0.00000000"],["111627.61000000","0.01390000"],["111624.75000000","0.30206000"],["111621.74000000","0.00000000"],["111620.01000000","0.00000000"],["111616.30000000","0.35868000"],["111616.29000000","0.00000000"],["111605.93000000","0.20541000"],["111600.00000000","0.24301000"],["111598.05000000","0.00000000"],["111541.51000000","0.00196000"],["111539.46000000","0.00000000"],["111539.03000000","0.01401000"],["111033.79000000","0.00000000"],["109981.15000000","0.00000000"],["106000.00000000","32.64502000"],["100490.39000000","0.00019000"],["100490.00000000","0.00010000"],["89324.80000000","0.00022000"]],"a":[["111656.00000000","0.00000000"],["111656.01000000","0.80333000"],["111656.02000000","0.07985000"],["111656.08000000","0.00000000"],["111656.09000000","0.00010000"],["111656.10000000","0.00100000"],["111656.11000000","0.00020000"],["111656.15000000","0.00000000"],["111656.35000000","0.00010000"],["111658.28000000","0.00000000"],["111658.53000000","0.00000000"],["111662.14000000","0.01811000"],["111662.75000000","0.00000000"],["111662.99000000","0.00000000"],["111663.00000000","0.00000000"],["111663.37000000","0.00005000"],["111663.38000000","0.05275000"],["111663.40000000","0.05569000"],["111665.74000000","0.29537000"],["111667.17000000","0.00150000"],["111667.50000000","0.00000000"],["111669.54000000","0.00000000"],["111670.52000000","0.07652000"],["111671.79000000","0.00000000"],["111671.85000000","0.00005000"],["111673.56000000","0.00000000"],["111676.42000000","0.00069000"],["111678.07000000","0.00100000"],["111681.15000000","0.04000000"],["111685.22000000","0.00000000"],["111701.85000000","0.32212000"],["111708.93000000","0.01401000"],["111718.71000000","0.00005000"],["111735.73000000","0.00000000"],["111735.87000000","0.06700000"],["111740.57000000","0.17904000"],["111740.58000000","0.00000000"],["111741.52000000","0.00100000"],["111741.53000000","0.00100000"],["111762.66000000","0.13246000"],["111782.36000000","0.00196000"],["111819.01000000","0.00000000"],["111830.16000000","0.00218000"],["111935.76000000","0.00000000"],["111982.43000000","0.00010000"],["111988.01000000","0.00000000"],["112014.47000000","0.00000000"],["112025.63000000","0.00080000"],["113330.84000000","0.00000000"],["119805.00000000","0.00010000"],["150260.00000000","0.00004000"]]}
[2025-10-12T10:59:31.185Z] {"e":"depthUpdate","E":1760266771014,"s":"BTCUSDT","U":77965107224,"u":77965107600,"b":[["111656.00000000","10.90257000"],["111655.99000000","0.79946000"],["111652.39000000","0.01579000"],["111652.09000000","0.00547000"],["111651.53000000","0.00447000"],["111651.32000000","0.01818000"],["111650.37000000","0.00000000"],["111648.13000000","0.00043000"],["111647.33000000","0.00043000"],["111647.02000000","0.35802000"],["111647.01000000","0.24446000"],["111645.67000000","0.00043000"],["111645.60000000","0.00000000"],["111645.59000000","0.00000000"],["111645.55000000","0.04800000"],["111645.39000000","0.00005000"],["111644.82000000","0.00334000"],["111644.39000000","0.04806000"],["111643.93000000","0.00895000"],["111643.35000000","0.00000000"],["111643.23000000","0.00000000"],["111643.21000000","0.89702000"],["111642.19000000","0.15000000"],["111642.17000000","1.25396000"],["111642.04000000","0.00043000"],["111641.61000000","0.00389000"],["111641.46000000","0.00086000"],["111640.48000000","0.00400000"],["111636.47000000","0.00000000"],["111635.66000000","0.00087000"],["111631.70000000","0.00044000"],["111630.90000000","0.00034000"],["111630.02000000","0.00000000"],["111627.86000000","0.00000000"],["111627.66000000","0.00000000"],["111627.61000000","0.00000000"],["111627.17000000","0.30205000"],["111625.69000000","0.00000000"],["111624.75000000","0.00000000"],["111624.08000000","0.00000000"],["111622.51000000","0.04477000"],["111621.20000000","0.00009000"],["111619.08000000","0.09295000"],["111618.98000000","0.00018000"],["111618.01000000","0.09295000"],["111614.20000000","0.00000000"],["111611.98000000","0.00000000"],["111610.81000000","0.05769000"],["111609.10000000","0.22377000"],["111603.80000000","0.00000000"],["111584.69000000","0.02143000"],["111575.45000000","0.00090000"],["111568.45000000","0.00000000"],["111565.82000000","0.13426000"],["111558.94000000","0.45112000"],["111552.45000000","0.20041000"],["111550.40000000","0.17590000"],["111550.39000000","0.00000000"],["111550.36000000","0.00000000"],["111550.33000000","0.00000000"],["111549.47000000","0.00000000"],["111549.33000000","0.00000000"],["111549.06000000","0.18874000"],["111547.96000000","0.07807000"],["111546.95000000","0.00000000"],["111546.51000000","0.13436000"],["111545.00000000","0.00000000"],["111542.71000000","0.03728000"],["111540.10000000","0.00000000"],["111539.03000000","0.00000000"],["111537.64000000","0.00000000"],["111522.17000000","0.01401000"],["111510.27000000","0.00000000"],["111488.58000000","0.00000000"],["111478.96000000","0.16336000"],["111478.79000000","0.00000000"],["111476.78000000","0.00000000"],["111441.37000000","0.00000000"],["111424.12000000","0.00000000"],["111422.73000000","0.00000000"],["111422.72000000","0.00000000"],["111422.45000000","0.00000000"],["111357.25000000","0.00000000"],["111053.21000000","0.11990000"],["111026.41000000","0.00000000"],["109981.16000000","0.00100000"],["100490.39000000","0.00000000"],["100490.00000000","0.00010000"],["89325.00000000","0.00200000"],["89324.80000000","0.00022000"],["33000.00000000","3.87311000"]],"a":[["111656.01000000","0.09091000"],["111656.02000000","0.07985000"],["111656.39000000","0.01363000"],["111657.14000000","0.00010000"],["111657.98000000","0.00000000"],["111661.02000000","0.00727000"],["111661.51000000","0.00005000"],["111661.52000000","0.00000000"],["111662.14000000","0.01806000"],["111663.37000000","0.00000000"],["111663.38000000","0.00000000"],["111663.39000000","0.00010000"],["111663.40000000","0.05569000"],["111663.72000000","0.00150000"],["111665.27000000","0.00000000"],["111665.63000000","0.01019000"],["111665.74000000","0.00000000"],["111666.54000000","0.00000000"],["111666.57000000","0.00000000"],["111667.98000000","0.00000000"],["111668.28000000","0.00332000"],["111668.33000000","0.04490000"],["111668.53000000","0.00000000"],["111668.97000000","0.00000000"],["111669.17000000","0.00000000"],["111670.51000000","0.00005000"],["111670.52000000","0.07657000"],["111671.74000000","0.00000000"],["111671.85000000","0.00000000"],["111672.04000000","0.00000000"],["111672.26000000","0.15657000"],["111672.27000000","0.14000000"],["111672.74000000","0.00000000"],["111672.75000000","0.00156000"],["111672.96000000","0.01020000"],["111673.32000000","0.17187000"],["111674.20000000","0.00000000"],["111674.62000000","0.00000000"],["111674.64000000","0.02688000"],["111675.37000000","0.00000000"],["111675.99000000","0.00000000"],["111676.08000000","0.48000000"],["111676.75000000","0.04000000"],["111678.07000000","0.00000000"],["111678.32000000","0.00000000"],["111678.33000000","0.00000000"],["111678.81000000","0.00447000"],["111678.96000000","0.00000000"],["111679.43000000","0.08504000"],["111680.88000000","0.00000000"],["111681.15000000","0.00000000"],["111681.21000000","0.00000000"],["111683.91000000","0.11190000"],["111684.75000000","0.15000000"],["111684.77000000","1.10649000"],["111684.78000000","0.00000000"],["111685.38000000","0.00000000"],["111686.45000000","0.00895000"],["111689.41000000","0.00000000"],["111689.42000000","0.00000000"],["111689.50000000","0.04786000"],["111689.93000000","0.00000000"],["111690.92000000","0.00000000"],["111693.66000000","0.00000000"],["111694.00000000","0.00200000"],["111694.10000000","0.00000000"],["111696.57000000","1.28682000"],["111697.61000000","0.17914000"],["111703.98000000","0.08795000"],["111705.98000000","0.02418000"],["111706.82000000","0.32211000"],["111707.54000000","0.02597000"],["111709.89000000","0.00000000"],["111713.13000000","0.01701000"],["111714.24000000","0.00005000"],["111718.71000000","0.00000000"],["111721.83000000","0.00000000"],["111724.66000000","0.00000000"],["111725.60000000","0.13436000"],["111725.89000000","0.00000000"],["111726.88000000","0.00000000"],["111735.55000000","0.00620000"],["111735.87000000","0.00000000"],["111737.27000000","0.51229000"],["111737.28000000","1.25396000"],["111737.43000000","0.00000000"],["111738.29000000","0.00894000"],["111739.99000000","0.00000000"],["111740.52000000","0.00000000"],["111740.57000000","0.00000000"],["111741.12000000","0.00000000"],["111741.51000000","0.00000000"],["111741.53000000","0.00100000"],["111743.11000000","0.00000000"],["111744.98000000","0.00000000"],["111749.98000000","0.00000000"],["111751.97000000","0.00000000"],["111751.98000000","0.06720000"],["111751.99000000","0.00000000"],["111753.20000000","0.13426000"],["111753.98000000","0.00000000"],["111753.99000000","0.00000000"],["111754.81000000","0.00000000"],["111762.66000000","0.00000000"],["111763.03000000","0.00223000"],["111763.04000000","0.00000000"],["111782.48000000","0.00000000"],["111784.48000000","0.17904000"],["111786.40000000","0.00000000"],["111788.13000000","0.13436000"],["111799.88000000","0.00000000"],["111867.17000000","0.09295000"],["111870.18000000","0.00000000"],["111870.86000000","0.00000000"],["111871.27000000","0.09295000"],["111872.46000000","0.00000000"],["111872.49000000","0.00000000"],["111873.24000000","0.09295000"],["111874.60000000","0.00089000"],["111874.61000000","0.00000000"],["111875.72000000","0.00000000"],["111876.14000000","0.09295000"],["111878.37000000","0.09295000"],["111896.83000000","0.02430000"],["111901.59000000","0.00000000"],["111904.54000000","0.00000000"],["111912.00000000","0.00000000"],["111912.82000000","0.00000000"],["111926.73000000","0.02507000"],["111930.21000000","0.02398000"],["111944.37000000","0.01701000"],["111947.58000000","0.00000000"],["111954.82000000","0.00000000"],["111958.21000000","0.00000000"],["111958.53000000","0.00000000"],["111959.39000000","0.00000000"],["111961.03000000","0.00000000"],["111964.14000000","0.00000000"],["111964.39000000","0.00000000"],["111969.20000000","0.00000000"],["112006.53000000","0.02597000"],["112008.44000000","0.05796000"],["112010.81000000","0.05796000"],["112011.22000000","0.05796000"],["112012.03000000","0.05796000"],["112014.05000000","0.05796000"],["112014.89000000","0.05796000"],["112023.70000000","0.00000000"],["112023.76000000","0.00000000"],["112025.16000000","0.00000000"],["112025.32000000","0.00000000"],["112025.34000000","0.00000000"],["112026.51000000","0.00000000"],["112041.96000000","0.02398000"],["112043.98000000","0.02398000"],["112045.73000000","0.02398000"],["112048.02000000","0.02398000"],["112050.07000000","0.02398000"],["112051.38000000","0.02398000"],["112052.09000000","0.02403000"],["112141.08000000","0.45000000"],["112186.39000000","0.00000000"],["112231.84000000","0.00000000"],["112236.17000000","0.00005000"],["112236.69000000","0.00000000"],["113330.86000000","0.00100000"]]}
