[2025-10-12T10:57:07.187Z] {"e":"depthUpdate","E":1760266627014,"s":"BTCUSDT","U":77965067772,"u":77965070157,"b":[["111668.30000000","0.00000000"],["111668.29000000","0.00000000"],["111668.28000000","0.00000000"],["111668.27000000","0.00000000"],["111668.23000000","0.00000000"],["111668.22000000","0.00000000"],["111668.05000000","0.00000000"],["111668.00000000","0.00000000"],["111667.99000000","0.00000000"],["111667.39000000","0.00000000"],["111667.04000000","0.00000000"],["111666.60000000","0.00000000"],["111666.47000000","0.00000000"],["111666.46000000","0.00000000"],["111666.45000000","0.00000000"],["111666.37000000","0.00000000"],["111666.36000000","0.00000000"],["111666.35000000","0.00000000"],["111666.34000000","0.00000000"],["111666.28000000","0.00000000"],["111666.02000000","0.00000000"],["111666.00000000","0.00000000"],["111665.99000000","0.00000000"],["111665.96000000","0.00000000"],["111665.85000000","0.00000000"],["111665.84000000","0.00000000"],["111665.82000000","0.00000000"],["111665.69000000","0.00000000"],["111665.55000000","0.00000000"],["111664.87000000","0.00000000"],["111664.85000000","0.00000000"],["111664.84000000","0.00000000"],["111664.65000000","0.00000000"],["111664.03000000","0.00000000"],["111664.02000000","0.00000000"],["111664.00000000","0.00000000"],["111663.99000000","0.00000000"],["111663.66000000","0.00000000"],["111663.65000000","0.00000000"],["111663.64000000","0.00000000"],["111663.54000000","0.00000000"],["111662.89000000","0.00000000"],["111662.74000000","0.00000000"],["111662.72000000","0.00000000"],["111662.46000000","0.00000000"],["111662.20000000","0.00000000"],["111662.00000000","0.00000000"],["111661.91000000","0.00000000"],["111661.52000000","0.00000000"],["111661.48000000","0.00000000"],["111660.57000000","0.00000000"],["111660.56000000","0.19161000"],["111660.55000000","0.00115000"],["111660.54000000","0.00020000"],["111660.48000000","0.00010000"],["111660.04000000","0.00000000"],["111660.03000000","0.00000000"],["111660.01000000","0.00010000"],["111660.00000000","0.07659000"],["111659.99000000","0.04142000"],["111659.98000000","0.00010000"],["111659.90000000","0.00000000"],["111659.25000000","0.00000000"],["111659.24000000","0.00000000"],["111659.17000000","0.00010000"],["111659.03000000","0.00005000"],["111658.90000000","0.00000000"],["111658.78000000","0.00000000"],["111658.66000000","0.00000000"],["111658.65000000","0.00000000"],["111658.40000000","0.00000000"],["111658.38000000","0.00005000"],["111658.36000000","0.00000000"],["111658.00000000","0.00205000"],["111657.99000000","0.00010000"],["111657.49000000","0.00000000"],["111657.26000000","0.00000000"],["111657.15000000","0.00010000"],["111657.14000000","0.00010000"],["111657.13000000","0.00000000"],["111656.55000000","0.00000000"],["111656.31000000","0.00000000"],["111656.28000000","0.00000000"],["111656.00000000","0.00205000"],["111655.92000000","0.00000000"],["111655.67000000","0.00000000"],["111655.50000000","0.00005000"],["111655.32000000","0.00589000"],["111655.28000000","0.00010000"],["111655.27000000","0.03443000"],["111655.00000000","0.00000000"],["111654.98000000","0.00005000"],["111654.97000000","0.04019000"],["111654.60000000","0.00000000"],["111654.59000000","0.00005000"],["111654.24000000","0.00000000"],["111654.13000000","0.05291000"],["111654.08000000","0.03009000"],["111654.07000000","0.00265000"],["111654.00000000","0.00210000"],["111653.85000000","0.04034000"],["111653.76000000","0.00000000"],["111652.75000000","0.00000000"],["111652.48000000","0.00000000"],["111652.27000000","0.00000000"],["111652.23000000","0.00011000"],["111652.19000000","0.00000000"],["111652.00000000","0.00265000"],["111651.66000000","0.00000000"],["111651.55000000","0.00000000"],["111651.54000000","0.00156000"],["111651.30000000","0.00000000"],["111651.29000000","0.00318000"],["111650.77000000","0.01807000"],["111650.00000000","0.00531000"],["111649.99000000","0.10455000"],["111649.98000000","0.04005000"],["111649.67000000","0.00000000"],["111649.62000000","0.00000000"],["111649.61000000","0.00155000"],["111649.60000000","0.00000000"],["111649.20000000","0.01169000"],["111648.99000000","0.00000000"],["111648.90000000","0.00000000"],["111648.64000000","0.00000000"],["111648.15000000","0.00000000"],["111648.00000000","0.00265000"],["111647.99000000","0.00000000"],["111647.97000000","0.00000000"],["111647.92000000","0.00000000"],["111647.19000000","0.00000000"],["111647.11000000","0.00070000"],["111646.23000000","0.15763000"],["111646.22000000","0.29542000"],["111645.95000000","0.00300000"],["111645.77000000","0.00000000"],["111645.23000000","0.00005000"],["111644.56000000","0.45020000"],["111644.55000000","0.00000000"],["111644.39000000","0.00006000"],["111644.13000000","0.00000000"],["111644.11000000","0.42282000"],["111644.10000000","0.00000000"],["111644.02000000","0.00000000"],["111643.81000000","0.04626000"],["111643.80000000","0.07200000"],["111643.41000000","0.00000000"],["111643.40000000","0.00000000"],["111642.72000000","0.00005000"],["111642.70000000","0.00000000"],["111642.63000000","0.17902000"],["111642.62000000","0.09360000"],["111642.26000000","0.00000000"],["111641.88000000","0.00007000"],["111641.87000000","0.00000000"],["111641.21000000","0.00000000"],["111640.01000000","0.00000000"],["111639.66000000","0.01264000"],["111638.93000000","0.00000000"],["111638.91000000","0.00000000"],["111638.22000000","0.11190000"],["111638.17000000","0.62000000"],["111638.14000000","0.00000000"],["111636.29000000","0.00000000"],["111635.87000000","0.00000000"],["111635.76000000","0.00000000"],["111635.23000000","0.00000000"],["111634.80000000","0.04477000"],["111634.78000000","0.00300000"],["111634.76000000","0.07200000"],["111633.67000000","0.00447000"],["111632.88000000","0.15000000"],["111630.49000000","0.35802000"],["111630.44000000","0.00000000"],["111630.40000000","0.00000000"],["111629.97000000","0.00000000"],["111629.20000000","0.00000000"],["111628.91000000","0.08504000"],["111628.59000000","0.00000000"],["111628.52000000","0.00000000"],["111628.43000000","0.01747000"],["111627.83000000","0.45495000"],["111627.82000000","0.36818000"],["111627.70000000","0.00000000"],["111627.51000000","0.00000000"],["111626.25000000","0.13426000"],["111626.12000000","0.00000000"],["111625.71000000","0.00000000"],["111625.29000000","0.00000000"],["111625.03000000","0.00000000"],["111624.15000000","0.00000000"],["111624.01000000","0.00000000"],["111623.49000000","0.00000000"],["111622.74000000","0.00000000"],["111622.40000000","0.00000000"],["111619.81000000","0.13426000"],["111619.17000000","0.00000000"],["111618.12000000","0.05283000"],["111618.11000000","0.00000000"],["111617.94000000","0.00269000"],["111617.87000000","0.00000000"],["111617.16000000","0.00000000"],["111617.11000000","0.00000000"],["111616.66000000","0.00000000"],["111616.59000000","1.23512000"],["111615.98000000","0.32237000"],["111615.94000000","0.00000000"],["111615.31000000","0.00000000"],["111615.02000000","0.00000000"],["111614.21000000","0.00009000"],["111613.87000000","0.13426000"],["111613.63000000","0.00000000"],["111612.01000000","0.00000000"],["111611.99000000","0.00018000"],["111611.40000000","0.00000000"],["111611.24000000","0.03827000"],["111611.23000000","0.00477000"],["111610.61000000","0.00000000"],["111610.50000000","0.92303000"],["111610.32000000","0.00000000"],["111609.06000000","0.00000000"],["111608.01000000","0.03582000"],["111607.95000000","0.00000000"],["111607.73000000","0.00000000"],["111606.96000000","0.00005000"],["111606.89000000","0.00000000"],["111606.01000000","0.00000000"],["111604.90000000","0.32240000"],["111604.62000000","0.30211000"],["111603.81000000","0.00009000"],["111603.63000000","0.00000000"],["111603.48000000","0.00000000"],["111602.49000000","0.00005000"],["111602.23000000","0.00000000"],["111599.82000000","0.00000000"],["111598.24000000","0.00000000"],["111597.30000000","0.00000000"],["111596.36000000","0.00000000"],["111595.60000000","0.00000000"],["111593.78000000","0.05104000"],["111591.82000000","0.00000000"],["111589.86000000","0.00000000"],["111586.51000000","0.00005000"],["111586.27000000","0.02209000"],["111586.01000000","0.40306000"],["111583.30000000","0.00621000"],["111582.28000000","0.04800000"],["111582.22000000","0.09600000"],["111582.07000000","0.00000000"],["111581.75000000","0.00000000"],["111581.67000000","0.00632000"],["111581.19000000","0.05760000"],["111580.41000000","0.00000000"],["111579.95000000","0.00000000"],["111579.30000000","0.40306000"],["111578.31000000","0.00626000"],["111577.84000000","0.07200000"],["111577.83000000","0.00661000"],["111577.27000000","0.06240000"],["111576.68000000","0.05760000"],["111575.61000000","0.06720000"],["111575.45000000","0.00000000"],["111575.19000000","0.00000000"],["111574.02000000","0.00005000"],["111574.01000000","0.00000000"],["111573.74000000","0.00000000"],["111573.02000000","0.00000000"],["111572.01000000","0.00000000"],["111570.30000000","0.00163000"],["111569.28000000","0.04375000"],["111568.98000000","0.01792000"],["111568.79000000","0.00000000"],["111568.45000000","0.00090000"],["111568.01000000","0.00000000"],["111567.80000000","0.00000000"],["111567.42000000","0.00000000"],["111566.14000000","0.00000000"],["111566.13000000","0.44070000"],["111566.01000000","0.00000000"],["111565.51000000","0.00000000"],["111564.55000000","0.00000000"],["111563.71000000","0.13426000"],["111563.38000000","0.00000000"],["111563.00000000","0.02071000"],["111562.67000000","1.25396000"],["111560.36000000","0.00000000"],["111559.84000000","0.00000000"],["111559.76000000","0.00000000"],["111559.22000000","0.00000000"],["111557.28000000","0.13426000"],["111554.65000000","0.07346000"],["111554.47000000","0.00000000"],["111554.27000000","0.02999000"],["111554.21000000","0.55767000"],["111551.76000000","0.02478000"],["111548.44000000","0.00000000"],["111548.04000000","0.12262000"],["111547.30000000","0.03962000"],["111542.22000000","0.05013000"],["111534.93000000","0.02417000"],["111528.20000000","0.00005000"],["111528.18000000","0.08894000"],["111527.42000000","0.00000000"],["111525.93000000","0.02417000"],["111524.22000000","0.00000000"],["111523.84000000","0.08894000"],["111521.64000000","0.02417000"],["111519.17000000","0.08894000"],["111515.69000000","0.08894000"],["111514.23000000","0.00000000"],["111512.11000000","0.08894000"],["111511.60000000","0.08894000"],["111510.82000000","0.00000000"],["111509.76000000","0.08894000"],["111509.74000000","0.17788000"],["111509.34000000","0.00000000"],["111507.75000000","0.00000000"],["111507.65000000","0.08894000"],["111507.48000000","0.08894000"],["111507.25000000","0.08894000"],["111506.64000000","0.00000000"],["111505.59000000","0.00000000"],["111505.11000000","0.33334000"],["111504.40000000","0.00000000"],["111503.38000000","0.00000000"],["111502.29000000","0.01086000"],["111498.95000000","0.00000000"],["111498.94000000","0.00000000"],["111498.48000000","0.00000000"],["111498.19000000","0.04509000"],["111497.85000000","0.00000000"],["111496.67000000","0.00000000"],["111496.65000000","0.00000000"],["111493.73000000","0.00000000"],["111491.75000000","0.00000000"],["111476.25000000","0.02596000"],["111473.95000000","0.00000000"],["111470.62000000","0.02986000"],["111470.61000000","0.00000000"],["111468.02000000","0.00000000"],["111465.63000000","0.05430000"],["111465.01000000","0.00000000"],["111461.67000000","0.08794000"],["111460.66000000","0.09466000"],["111460.24000000","0.08794000"],["111459.76000000","0.00065000"],["111458.96000000","0.08794000"],["111457.20000000","0.08794000"],["111454.61000000","0.08794000"],["111451.71000000","0.08794000"],["111450.30000000","0.08794000"],["111448.18000000","0.08794000"],["111446.17000000","0.08794000"],["111444.75000000","0.08794000"],["111409.09000000","0.00000000"],["111396.02000000","0.00467000"],["111384.99000000","0.00000000"],["111370.35000000","0.00000000"],["111367.84000000","0.01701000"],["111367.67000000","0.00000000"],["111352.69000000","0.00000000"],["111351.97000000","0.00000000"],["111351.34000000","0.00000000"],["111350.57000000","0.00000000"],["111349.59000000","0.00000000"],["111349.55000000","0.00010000"],["111349.41000000","0.00000000"],["111349.13000000","0.00000000"],["111348.86000000","0.00000000"],["111348.58000000","0.00000000"],["111347.48000000","0.00000000"],["111345.29000000","0.00000000"],["111343.51000000","0.00000000"],["111343.05000000","0.00000000"],["111342.48000000","0.00000000"],["111339.71000000","0.00000000"],["111331.48000000","0.02596000"],["111315.99000000","0.03582000"],["111310.13000000","0.05996000"],["111309.00000000","0.05996000"],["111307.98000000","0.05996000"],["111307.06000000","0.05996000"],["111265.16000000","0.45000000"],["111221.74000000","0.00000000"],["111221.14000000","0.00000000"],["111196.37000000","0.03582000"],["111189.66000000","0.03582000"],["111182.03000000","0.03582000"],["111176.38000000","0.03582000"],["111170.74000000","0.03582000"],["109993.27000000","0.00000000"],["102768.90000000","0.00010000"],["100515.00000000","0.00298000"],["100501.00000000","0.21737000"],["98000.00000000","97.36790000"],["89334.64000000","0.00000000"],["89328.45000000","0.00022000"],["78165.89000000","0.00000000"],["40200.59000000","0.00030000"],["33000.00000000","3.87311000"]],"a":[["111660.57000000","8.85888000"],["111660.58000000","0.00000000"],["111660.60000000","0.00005000"],["111660.63000000","0.00000000"],["111660.65000000","0.00010000"],["111660.70000000","0.00080000"],["111660.78000000","0.00000000"],["111661.69000000","0.04113000"],["111661.92000000","0.17909000"],["111662.01000000","0.00000000"],["111662.90000000","0.00000000"],["111663.55000000","0.00000000"],["111663.66000000","0.00000000"],["111663.67000000","0.00000000"],["111664.01000000","0.00000000"],["111664.66000000","0.00000000"],["111665.07000000","0.00005000"],["111665.56000000","0.00000000"],["111665.70000000","0.00000000"],["111665.83000000","0.00000000"],["111666.00000000","0.00000000"],["111666.01000000","0.00000000"],["111666.03000000","0.00000000"],["111666.34000000","0.00000000"],["111666.36000000","0.71265000"],["111666.37000000","0.76988000"],["111666.38000000","0.44313000"],["111666.43000000","0.00005000"],["111666.44000000","0.00000000"],["111666.45000000","0.00000000"],["111666.50000000","0.00400000"],["111666.66000000","0.04005000"],["111667.98000000","0.18712000"],["111667.99000000","0.00010000"],["111668.00000000","0.00000000"],["111668.01000000","0.01305000"],["111668.06000000","0.00000000"],["111668.23000000","0.00000000"],["111668.28000000","0.00000000"],["111668.29000000","0.00000000"],["111668.30000000","0.20249000"],["111668.31000000","0.00000000"],["111668.39000000","0.00000000"],["111668.40000000","0.00000000"],["111668.62000000","0.04005000"],["111669.02000000","0.02005000"],["111669.11000000","0.00889000"],["111669.16000000","0.00005000"],["111669.42000000","0.00000000"],["111669.97000000","0.00000000"],["111669.98000000","0.00000000"],["111669.99000000","0.00000000"],["111670.00000000","0.04005000"],["111670.01000000","0.00000000"],["111670.02000000","0.00005000"],["111670.08000000","0.03582000"],["111670.91000000","0.00087000"],["111671.23000000","0.00000000"],["111671.24000000","0.00000000"],["111671.44000000","0.00000000"],["111671.45000000","0.06656000"],["111671.74000000","0.45000000"],["111671.95000000","0.00064000"],["111672.06000000","0.00044000"],["111672.36000000","0.00000000"],["111673.16000000","0.15000000"],["111673.18000000","0.49692000"],["111673.19000000","0.40306000"],["111673.89000000","0.11190000"],["111674.51000000","0.00010000"],["111675.07000000","0.04283000"],["111675.09000000","0.08404000"],["111675.57000000","0.00000000"],["111675.59000000","0.00000000"],["111675.60000000","0.00005000"],["111675.61000000","0.00000000"],["111676.00000000","0.01005000"],["111676.01000000","0.01826000"],["111676.32000000","0.00000000"],["111676.84000000","0.00005000"],["111677.15000000","0.13433000"],["111677.16000000","0.00000000"],["111677.41000000","0.40306000"],["111677.42000000","0.04002000"],["111677.60000000","0.00000000"],["111677.61000000","0.00007000"],["111677.81000000","0.00000000"],["111678.02000000","0.04002000"],["111678.54000000","0.00000000"],["111678.65000000","0.00000000"],["111678.67000000","0.04002000"],["111678.82000000","0.08504000"],["111679.29000000","0.00000000"],["111679.47000000","0.00300000"],["111679.48000000","0.00018000"],["111679.76000000","0.00000000"],["111679.80000000","0.00000000"],["111680.13000000","0.08000000"],["111680.75000000","0.05280000"],["111680.78000000","0.32218000"],["111680.89000000","1.25396000"],["111680.91000000","0.04002000"],["111681.25000000","0.08504000"],["111681.46000000","0.02125000"],["111681.91000000","0.00000000"],["111682.83000000","0.00000000"],["111683.19000000","0.04002000"],["111683.41000000","0.00000000"],["111683.52000000","0.00432000"],["111683.72000000","0.00005000"],["111684.26000000","0.04002000"],["111684.46000000","0.03497000"],["111684.50000000","0.00400000"],["111684.77000000","1.10649000"],["111684.78000000","1.25396000"],["111684.79000000","0.00000000"],["111684.81000000","0.08785000"],["111684.97000000","0.00895000"],["111685.06000000","0.00000000"],["111685.13000000","0.04800000"],["111685.14000000","0.00022000"],["111685.35000000","0.00000000"],["111685.48000000","0.01700000"],["111685.67000000","0.00010000"],["111686.17000000","0.32217000"],["111686.22000000","0.04800000"],["111686.65000000","0.00000000"],["111687.36000000","0.04800000"],["111687.45000000","0.00044000"],["111688.27000000","0.00000000"],["111688.29000000","1.25396000"],["111688.30000000","0.00000000"],["111688.63000000","0.00000000"],["111688.73000000","0.00000000"],["111688.83000000","0.00006000"],["111689.00000000","0.00000000"],["111689.26000000","0.00000000"],["111689.43000000","1.12650000"],["111689.52000000","0.15369000"],["111690.13000000","0.01390000"],["111691.19000000","0.06732000"],["111691.47000000","0.18871000"],["111691.63000000","0.04800000"],["111692.12000000","0.32215000"],["111692.25000000","0.07200000"],["111692.57000000","0.08504000"],["111693.43000000","0.07200000"],["111696.27000000","0.00000000"],["111696.71000000","0.04800000"],["111697.15000000","0.00000000"],["111697.89000000","0.02126000"],["111698.26000000","0.00441000"],["111698.33000000","0.00000000"],["111699.06000000","0.00000000"],["111699.96000000","0.04097000"],["111700.32000000","0.18417000"],["111700.36000000","0.00000000"],["111700.91000000","0.04097000"],["111700.92000000","0.08504000"],["111701.00000000","0.00000000"],["111701.27000000","0.00000000"],["111701.36000000","0.00000000"],["111701.79000000","0.00000000"],["111701.81000000","0.04778000"],["111702.16000000","0.00000000"],["111702.44000000","0.00000000"],["111703.05000000","0.00000000"],["111703.09000000","0.08194000"],["111703.67000000","0.04097000"],["111703.68000000","1.78833000"],["111703.69000000","1.20902000"],["111703.76000000","0.00000000"],["111703.79000000","0.00000000"],["111704.12000000","0.00000000"],["111704.91000000","0.04097000"],["111704.93000000","0.00000000"],["111705.30000000","0.00537000"],["111705.32000000","0.89423000"],["111705.33000000","2.17047000"],["111705.78000000","0.00000000"],["111705.93000000","0.00000000"],["111706.12000000","0.00000000"],["111706.28000000","0.00000000"],["111706.42000000","0.00000000"],["111707.47000000","0.22377000"],["111707.55000000","0.04097000"],["111707.89000000","0.00000000"],["111707.97000000","0.00000000"],["111708.01000000","0.00000000"],["111708.05000000","0.00000000"],["111708.06000000","0.00000000"],["111708.92000000","0.00000000"],["111709.38000000","0.00000000"],["111709.51000000","0.04097000"],["111709.69000000","0.00000000"],["111709.77000000","0.00000000"],["111710.38000000","0.02126000"],["111710.65000000","0.00000000"],["111714.08000000","0.00000000"],["111715.21000000","0.00000000"],["111715.22000000","0.00000000"],["111716.07000000","0.00000000"],["111716.33000000","0.04097000"],["111716.51000000","0.45000000"],["111716.88000000","0.00000000"],["111718.73000000","0.00007000"],["111719.86000000","0.00000000"],["111720.16000000","0.00000000"],["111722.50000000","0.00000000"],["111724.26000000","0.00000000"],["111724.58000000","0.00000000"],["111726.62000000","0.00894000"],["111727.68000000","0.00000000"],["111729.15000000","0.02286000"],["111729.28000000","0.00000000"],["111729.84000000","0.00000000"],["111729.86000000","0.00656000"],["111730.85000000","0.00000000"],["111733.95000000","0.00616000"],["111737.35000000","0.00000000"],["111737.37000000","0.00000000"],["111740.48000000","0.13426000"],["111740.99000000","0.04800000"],["111741.48000000","0.00000000"],["111742.09000000","0.04800000"],["111742.10000000","0.04800000"],["111742.70000000","0.13426000"],["111743.22000000","0.04800000"],["111743.25000000","0.00000000"],["111743.94000000","0.02130000"],["111744.36000000","0.00000000"],["111744.48000000","0.00000000"],["111745.15000000","0.15901000"],["111745.75000000","0.00000000"],["111746.76000000","0.00000000"],["111747.60000000","0.00000000"],["111747.75000000","0.02154000"],["111748.35000000","0.00000000"],["111748.76000000","0.00000000"],["111751.99000000","0.00000000"],["111752.26000000","0.00000000"],["111754.30000000","0.00000000"],["111758.70000000","0.02423000"],["111759.27000000","0.00000000"],["111761.61000000","0.00000000"],["111762.62000000","0.00000000"],["111762.98000000","0.00322000"],["111764.55000000","0.00005000"],["111764.74000000","0.00000000"],["111766.64000000","0.00000000"],["111766.69000000","0.00000000"],["111766.95000000","0.00000000"],["111767.04000000","0.22377000"],["111769.21000000","0.23059000"],["111769.22000000","0.00000000"],["111769.73000000","0.00000000"],["111770.16000000","0.00000000"],["111770.50000000","0.00000000"],["111772.09000000","0.13433000"],["111772.31000000","0.00000000"],["111772.82000000","0.04097000"],["111772.83000000","0.00000000"],["111773.33000000","0.09764000"],["111773.70000000","0.00000000"],["111774.29000000","0.04800000"],["111774.69000000","0.00000000"],["111775.19000000","0.00000000"],["111775.28000000","0.00000000"],["111775.92000000","0.00000000"],["111775.98000000","0.00370000"],["111778.04000000","0.00000000"],["111778.92000000","0.00000000"],["111779.34000000","0.00000000"],["111779.48000000","0.00000000"],["111781.81000000","0.04362000"],["111782.15000000","0.09439000"],["111783.44000000","0.00000000"],["111795.48000000","0.00000000"],["111799.23000000","0.00000000"],["111804.61000000","0.00000000"],["111805.56000000","0.02596000"],["111806.75000000","0.00000000"],["111806.83000000","0.70911000"],["111806.86000000","0.00000000"],["111807.15000000","0.00000000"],["111812.38000000","0.44763000"],["111812.97000000","0.02417000"],["111814.86000000","0.02417000"],["111815.18000000","0.00000000"],["111817.86000000","0.03997000"],["111817.89000000","0.00000000"],["111817.90000000","0.00000000"],["111822.22000000","0.02298000"],["111823.00000000","0.00000000"],["111823.20000000","0.02688000"],["111824.79000000","0.02429000"],["111824.96000000","0.47905000"],["111834.90000000","0.00000000"],["111842.45000000","0.14816000"],["111843.35000000","0.08894000"],["111845.00000000","0.08894000"],["111845.52000000","0.00000000"],["111847.18000000","0.08894000"],["111850.71000000","0.08894000"],["111852.99000000","0.08894000"],["111855.01000000","0.08894000"],["111859.31000000","0.08894000"],["111861.74000000","0.08894000"],["111865.10000000","0.00000000"],["111865.57000000","0.08894000"],["111867.86000000","0.08894000"],["111870.10000000","0.08894000"],["111901.66000000","0.01701000"],["111904.99000000","0.08794000"],["111905.63000000","0.03997000"],["111906.70000000","0.08794000"],["111906.74000000","0.53794000"],["111931.54000000","0.00000000"],["111934.96000000","0.00000000"],["111935.13000000","0.00000000"],["111961.51000000","0.00007000"],["111978.19000000","0.03582000"],["111979.21000000","0.02298000"],["111981.97000000","0.00000000"],["111985.18000000","0.06001000"],["111985.60000000","0.05996000"],["111986.11000000","0.05996000"],["111986.55000000","0.05996000"],["111988.44000000","0.05996000"],["111989.02000000","0.05996000"],["111989.55000000","0.05996000"],["111991.27000000","0.05996000"],["111992.71000000","0.05996000"],["111993.20000000","0.05996000"],["111994.64000000","0.03997000"],["111994.66000000","0.05996000"],["111996.58000000","0.05996000"],["112002.88000000","0.00000000"],["112004.62000000","0.00000000"],["112010.20000000","0.00006000"],["112019.58000000","0.21540000"],["112059.26000000","0.00000000"],["112068.32000000","0.00000000"],["112080.76000000","0.00000000"],["112092.24000000","0.00000000"],["112093.56000000","0.00000000"],["112141.08000000","0.00000000"],["112212.90000000","0.00000000"],["112322.52000000","0.00000000"],["113343.33000000","0.00000000"],["116180.94000000","0.00016000"],["116798.14000000","0.00016000"],["117415.34000000","0.00016000"],["118032.54000000","0.00016000"]]}
[2025-10-12T10:57:08.185Z] {"e":"depthUpdate","E":1760266628014,"s":"BTCUSDT","U":77965070158,"u":77965070771,"b":[["111660.56000000","0.33010000"],["111660.55000000","0.00120000"],["111660.54000000","0.00020000"],["111660.48000000","0.00010000"],["111660.18000000","0.00010000"],["111660.17000000","0.01373000"],["111660.16000000","0.00020000"],["111660.02000000","0.00000000"],["111660.01000000","0.02216000"],["111660.00000000","0.02239000"],["111659.99000000","0.04142000"],["111659.98000000","0.00010000"],["111659.23000000","0.00000000"],["111659.20000000","0.00000000"],["111659.17000000","0.00000000"],["111658.00000000","0.00210000"],["111657.99000000","0.00000000"],["111657.92000000","0.00005000"],["111657.15000000","0.00000000"],["111657.14000000","0.00000000"],["111656.66000000","0.00542000"],["111656.00000000","0.00210000"],["111655.99000000","0.00000000"],["111655.54000000","0.00722000"],["111655.27000000","0.05401000"],["111654.98000000","0.00000000"],["111654.97000000","0.00005000"],["111654.75000000","0.00000000"],["111654.74000000","0.00000000"],["111654.43000000","0.00005000"],["111654.42000000","0.01796000"],["111654.14000000","0.00000000"],["111654.13000000","0.05291000"],["111654.09000000","0.00000000"],["111654.08000000","0.03004000"],["111653.85000000","0.04029000"],["111653.56000000","0.00000000"],["111651.54000000","0.04631000"],["111651.29000000","0.00310000"],["111650.77000000","0.00000000"],["111650.55000000","0.01822000"],["111650.01000000","0.16239000"],["111649.98000000","0.04000000"],["111649.61000000","0.00150000"],["111649.20000000","0.01164000"],["111648.80000000","0.29547000"],["111648.00000000","0.00260000"],["111646.23000000","0.00000000"],["111646.22000000","0.00000000"],["111645.95000000","0.00000000"],["111645.91000000","0.00000000"],["111645.90000000","0.00000000"],["111645.77000000","0.02688000"],["111644.86000000","0.00072000"],["111643.81000000","0.00151000"],["111640.29000000","0.00100000"],["111639.17000000","0.00070000"],["111638.92000000","0.57748000"],["111638.83000000","0.00070000"],["111638.17000000","0.30000000"],["111636.90000000","0.00005000"],["111635.21000000","0.00000000"],["111634.80000000","0.00000000"],["111634.67000000","0.32000000"],["111632.88000000","0.15000000"],["111629.60000000","0.00902000"],["111628.52000000","0.00000000"],["111628.46000000","0.08504000"],["111627.06000000","0.00308000"],["111617.79000000","0.00000000"],["111606.09000000","0.00000000"],["111605.36000000","0.06819000"],["111604.60000000","0.84100000"],["111604.21000000","0.00000000"],["111600.76000000","0.32241000"],["111596.94000000","0.04375000"],["111593.56000000","0.00008000"],["111584.28000000","0.00000000"],["111582.29000000","0.02597000"],["111578.56000000","0.13229000"],["111578.31000000","0.03223000"],["111578.01000000","0.02597000"],["111570.89000000","0.00005000"],["111570.31000000","0.02597000"],["111570.29000000","0.00000000"],["111569.28000000","0.00000000"],["111567.77000000","0.00005000"],["111562.04000000","0.00223000"],["111560.07000000","0.00008000"],["111559.72000000","0.02597000"],["111551.69000000","0.13426000"],["111550.78000000","0.00010000"],["111550.49000000","0.00000000"],["111549.06000000","0.44243000"],["111542.01000000","0.00223000"],["111534.54000000","0.03833000"],["111533.14000000","0.02597000"],["111530.81000000","0.11211000"],["111529.48000000","0.08794000"],["111526.76000000","0.02597000"],["111526.57000000","0.00008000"],["111525.65000000","0.08794000"],["111522.93000000","0.08794000"],["111522.48000000","0.02602000"],["111521.30000000","0.02597000"],["111520.51000000","0.08794000"],["111520.23000000","0.20726000"],["111520.01000000","0.00000000"],["111520.00000000","0.00349000"],["111518.73000000","0.02597000"],["111517.27000000","0.00000000"],["111516.85000000","0.02418000"],["111514.82000000","0.08794000"],["111511.56000000","0.08794000"],["111508.77000000","0.17588000"],["111507.27000000","0.02597000"],["111507.04000000","0.02597000"],["111506.98000000","0.17588000"],["111504.58000000","0.17588000"],["111493.07000000","0.00008000"],["111490.05000000","0.02597000"],["111474.35000000","0.02597000"],["111459.22000000","0.99281000"],["111454.97000000","0.08794000"],["111453.11000000","0.08794000"],["111451.11000000","0.08794000"],["111449.95000000","0.08794000"],["111447.02000000","0.08794000"],["111445.44000000","0.17588000"],["111444.30000000","0.17588000"],["111442.94000000","0.08794000"],["111442.93000000","0.08794000"],["111441.31000000","0.17588000"],["111410.46000000","0.00000000"],["111405.31000000","0.00574000"],["111309.71000000","0.05996000"],["111309.44000000","0.05996000"],["111308.99000000","0.05996000"],["111308.10000000","0.05996000"],["111307.78000000","0.05996000"],["111307.25000000","0.05996000"],["111305.47000000","0.05996000"],["111304.77000000","0.05996000"],["111304.10000000","0.05996000"],["111022.72000000","0.89111000"],["109985.65000000","0.00100000"],["102768.90000000","0.00000000"],["100501.00000000","0.21727000"],["100494.00000000","0.00010000"],["89328.45000000","0.00022000"],["42000.00000000","1.49096000"],["40000.00000000","14.93707000"]],"a":[["111660.57000000","9.01826000"],["111660.73000000","0.00906000"],["111660.96000000","0.01353000"],["111661.69000000","0.04128000"],["111661.91000000","0.40962000"],["111661.92000000","0.00000000"],["111662.35000000","0.00005000"],["111662.62000000","0.00100000"],["111662.80000000","0.00358000"],["111663.35000000","0.01799000"],["111664.47000000","0.00542000"],["111664.86000000","0.00005000"],["111666.36000000","0.00000000"],["111666.37000000","0.71610000"],["111666.66000000","0.04005000"],["111666.85000000","0.03582000"],["111667.98000000","0.18712000"],["111667.99000000","0.00005000"],["111668.01000000","0.01305000"],["111668.30000000","0.20116000"],["111670.98000000","0.04800000"],["111674.70000000","0.13426000"],["111675.27000000","0.04800000"],["111675.35000000","0.04800000"],["111676.00000000","0.01000000"],["111676.53000000","0.04800000"],["111676.84000000","0.00000000"],["111677.42000000","0.04002000"],["111677.82000000","0.06720000"],["111678.00000000","0.00000000"],["111678.16000000","0.00005000"],["111679.78000000","0.86394000"],["111681.17000000","0.07200000"],["111682.35000000","0.07200000"],["111682.91000000","0.00300000"],["111683.33000000","0.04800000"],["111684.81000000","0.04309000"],["111685.20000000","0.00000000"],["111685.69000000","0.00005000"],["111688.71000000","0.00000000"],["111689.00000000","0.00005000"],["111691.14000000","0.00000000"],["111691.19000000","0.00012000"],["111691.20000000","0.00000000"],["111691.54000000","0.00275000"],["111692.25000000","0.00000000"],["111693.43000000","0.00000000"],["111693.97000000","0.22377000"],["111694.07000000","0.00008000"],["111695.59000000","0.00000000"],["111695.98000000","0.00000000"],["111696.71000000","0.00000000"],["111696.78000000","0.00000000"],["111701.81000000","0.00300000"],["111705.10000000","0.00035000"],["111705.49000000","0.00000000"],["111707.47000000","0.13426000"],["111707.56000000","0.00000000"],["111707.98000000","0.00000000"],["111709.52000000","0.00000000"],["111709.94000000","0.00000000"],["111711.25000000","0.02685000"],["111712.83000000","0.04446000"],["111716.84000000","0.02237000"],["111718.32000000","0.00000000"],["111726.08000000","0.02597000"],["111727.57000000","0.00008000"],["111736.61000000","0.02597000"],["111742.82000000","0.00100000"],["111742.83000000","0.00105000"],["111751.82000000","0.00000000"],["111761.06000000","0.00008000"],["111764.52000000","0.22309000"],["111764.84000000","0.00000000"],["111764.85000000","0.00000000"],["111766.83000000","0.17904000"],["111767.05000000","0.00000000"],["111767.25000000","0.00000000"],["111767.42000000","0.00000000"],["111767.58000000","0.00000000"],["111767.99000000","0.00223000"],["111768.56000000","0.00000000"],["111771.14000000","0.04097000"],["111771.15000000","0.04800000"],["111772.13000000","0.22377000"],["111778.85000000","0.00000000"],["111781.79000000","0.04097000"],["111785.33000000","0.00000000"],["111791.99000000","0.00000000"],["111792.06000000","0.46740000"],["111792.07000000","0.99091000"],["111793.22000000","0.00000000"],["111794.56000000","0.00008000"],["111795.98000000","0.08794000"],["111796.45000000","0.26462000"],["111797.92000000","0.08794000"],["111798.98000000","0.00000000"],["111799.99000000","0.08794000"],["111800.77000000","0.06000000"],["111802.79000000","0.08794000"],["111804.09000000","0.00536000"],["111806.61000000","0.08794000"],["111806.83000000","0.46720000"],["111809.57000000","0.08794000"],["111811.07000000","0.02597000"],["111817.86000000","0.29986000"],["111818.83000000","0.00000000"],["111819.72000000","0.00000000"],["111825.90000000","0.00000000"],["111828.06000000","0.00008000"],["111834.90000000","0.11762000"],["111835.26000000","0.03997000"],["111837.51000000","0.03997000"],["111839.21000000","0.03997000"],["111852.34000000","0.00000000"],["111860.19000000","0.08794000"],["111866.63000000","0.00000000"],["111874.34000000","0.02418000"],["111887.55000000","0.02507000"],["111890.93000000","0.08794000"],["111894.47000000","0.08794000"],["111897.10000000","0.08794000"],["111898.17000000","0.03997000"],["111920.76000000","0.00000000"],["111982.89000000","0.00000000"],["112021.09000000","0.02686000"],["112070.72000000","0.03582000"],["112077.48000000","0.03582000"],["113335.48000000","0.00100000"],["113712.15000000","0.00016000"],["114329.35000000","0.00016000"],["114946.54000000","0.00016000"],["115563.74000000","0.00016000"]]}
[2025-10-12T10:57:09.185Z] {"e":"depthUpdate","E":1760266629014,"s":"BTCUSDT","U":77965070772,"u":77965071009,"b":[["111660.56000000","0.19001000"],["111660.55000000","0.00115000"],["111660.17000000","0.01378000"],["111660.16000000","0.00020000"],["111660.02000000","0.00010000"],["111660.01000000","0.00015000"],["111659.98000000","0.00000000"],["111655.32000000","0.00584000"],["111655.27000000","0.14634000"],["111654.43000000","0.00000000"],["111651.54000000","0.04631000"],["111651.36000000","0.29541000"],["111650.55000000","0.01827000"],["111650.02000000","0.02761000"],["111650.01000000","0.00000000"],["111650.00000000","0.00526000"],["111649.99000000","0.00000000"],["111649.98000000","0.04005000"],["111649.61000000","0.00150000"],["111648.80000000","0.00005000"],["111645.77000000","0.00000000"],["111645.75000000","0.02688000"],["111643.81000000","0.00151000"],["111642.10000000","0.00005000"],["111641.22000000","0.00330000"],["111638.17000000","0.14000000"],["111636.57000000","0.16000000"],["111632.88000000","0.00000000"],["111628.52000000","0.00000000"],["111627.85000000","0.15000000"],["111621.83000000","0.05996000"],["111621.58000000","0.32235000"],["111617.22000000","1.22680000"],["111616.59000000","0.00000000"],["111610.52000000","0.00000000"],["111605.36000000","0.00000000"],["111605.04000000","0.06578000"],["111600.76000000","0.00000000"],["111578.56000000","0.00000000"],["111578.31000000","0.16645000"],["111504.58000000","0.08794000"],["111472.38000000","0.00000000"],["111435.08000000","0.00000000"],["111407.12000000","0.07517000"],["111307.89000000","0.05996000"],["111307.53000000","0.05996000"],["111306.73000000","0.05996000"],["111304.95000000","0.05996000"],["111304.45000000","0.05996000"],["111303.85000000","0.05996000"],["111243.35000000","0.00016000"],["110626.15000000","0.00016000"],["110000.00000000","26.25780000"],["109985.65000000","0.00100000"],["108100.00000000","17.51784000"],["89328.45000000","0.00022000"],["40197.80000000","0.00015000"]],"a":[["111660.57000000","8.97643000"],["111660.60000000","0.00150000"],["111661.69000000","0.04123000"],["111661.91000000","0.40962000"],["111662.62000000","0.00105000"],["111662.80000000","0.00363000"],["111663.35000000","0.00000000"],["111663.46000000","0.00005000"],["111664.86000000","0.00000000"],["111666.37000000","0.58189000"],["111666.66000000","0.04010000"],["111666.85000000","0.03587000"],["111667.98000000","0.28823000"],["111668.90000000","0.00005000"],["111669.11000000","0.00894000"],["111669.16000000","0.00000000"],["111669.79000000","0.04800000"],["111670.00000000","0.00005000"],["111670.95000000","0.04800000"],["111671.45000000","0.06646000"],["111672.04000000","0.07200000"],["111673.21000000","0.07200000"],["111674.02000000","0.00005000"],["111674.85000000","0.04800000"],["111675.07000000","0.04278000"],["111677.15000000","0.13438000"],["111681.17000000","0.00000000"],["111682.35000000","0.00000000"],["111682.57000000","0.13426000"],["111685.50000000","0.00895000"],["111686.22000000","0.00000000"],["111690.01000000","0.00000000"],["111691.63000000","0.00000000"],["111693.84000000","1.19111000"],["111699.01000000","0.04800000"],["111703.38000000","0.04800000"],["111703.68000000","1.31744000"],["111703.69000000","0.00000000"],["111704.56000000","0.04800000"],["111707.47000000","0.31330000"],["111719.15000000","0.00000000"],["111721.33000000","0.00000000"],["111722.26000000","0.06821000"],["111730.71000000","0.04800000"],["111739.00000000","0.00000000"],["111746.71000000","0.13648000"],["111766.83000000","0.00000000"],["111767.99000000","0.00000000"],["111774.29000000","0.00000000"],["111790.07000000","0.00000000"],["111793.15000000","0.00000000"],["111898.86000000","0.03997000"],["111899.67000000","0.00000000"],["111903.56000000","0.00000000"],["111917.14000000","0.00000000"],["112051.89000000","0.00000000"],["112477.75000000","0.00016000"],["113094.95000000","0.00016000"],["113335.48000000","0.00100000"]]}
[2025-10-12T10:57:10.186Z] {"e":"depthUpdate","E":1760266630014,"s":"BTCUSDT","U":77965071010,"u":77965072673,"b":[["111660.56000000","0.00000000"],["111660.55000000","0.00000000"],["111660.54000000","0.00000000"],["111660.53000000","0.00000000"],["111660.48000000","0.00000000"],["111660.47000000","0.00000000"],["111660.18000000","0.00000000"],["111660.17000000","0.00000000"],["111660.16000000","0.00000000"],["111660.02000000","0.00000000"],["111660.01000000","0.00000000"],["111660.00000000","0.00000000"],["111659.99000000","0.00000000"],["111659.98000000","0.00000000"],["111659.03000000","0.00000000"],["111659.00000000","0.00000000"],["111658.97000000","0.00000000"],["111658.95000000","0.00000000"],["111658.89000000","0.00000000"],["111658.85000000","0.00000000"],["111658.79000000","0.00000000"],["111658.76000000","0.00000000"],["111658.54000000","0.00000000"],["111658.38000000","0.00000000"],["111658.00000000","0.00000000"],["111657.99000000","0.00000000"],["111657.92000000","0.00000000"],["111656.66000000","0.00000000"],["111656.65000000","0.00000000"],["111656.00000000","0.19056000"],["111655.99000000","0.00115000"],["111655.98000000","0.00020000"],["111655.92000000","0.00010000"],["111655.54000000","0.00742000"],["111655.53000000","0.00020000"],["111655.32000000","0.00589000"],["111655.31000000","0.00010000"],["111655.28000000","0.00000000"],["111655.27000000","0.00005000"],["111654.97000000","0.00000000"],["111654.44000000","0.00010000"],["111654.43000000","0.04372000"],["111654.42000000","0.01801000"],["111654.13000000","0.00000000"],["111654.09000000","0.00010000"],["111654.08000000","0.03014000"],["111654.00000000","0.00205000"],["111653.85000000","0.00000000"],["111653.08000000","0.00000000"],["111652.15000000","0.00005000"],["111652.02000000","0.00000000"],["111652.00000000","0.00265000"],["111651.59000000","0.00010000"],["111651.58000000","0.05405000"],["111651.54000000","0.00005000"],["111651.36000000","0.00000000"],["111651.29000000","0.00310000"],["111651.12000000","0.00000000"],["111650.64000000","0.00005000"],["111650.63000000","0.00010000"],["111650.55000000","0.00000000"],["111650.39000000","0.00000000"],["111650.32000000","0.00000000"],["111650.17000000","0.04792000"],["111650.03000000","0.00005000"],["111650.02000000","0.11427000"],["111650.00000000","0.00526000"],["111649.98000000","0.00000000"],["111649.61000000","0.00155000"],["111649.51000000","0.03930000"],["111649.36000000","0.00000000"],["111649.21000000","0.00000000"],["111649.20000000","0.00005000"],["111648.49000000","0.00000000"],["111648.00000000","0.00265000"],["111647.74000000","0.00000000"],["111647.62000000","0.04475000"],["111646.78000000","0.00010000"],["111646.28000000","0.00000000"],["111646.17000000","0.01766000"],["111646.00000000","0.00260000"],["111645.76000000","0.00000000"],["111645.75000000","0.00000000"],["111645.56000000","0.00000000"],["111645.23000000","0.00000000"],["111645.02000000","0.00000000"],["111644.85000000","0.29543000"],["111644.57000000","0.00000000"],["111644.06000000","0.00447000"],["111643.81000000","0.00151000"],["111642.72000000","0.00000000"],["111642.63000000","0.00000000"],["111642.59000000","0.00000000"],["111641.88000000","0.00000000"],["111641.08000000","0.04000000"],["111640.88000000","0.00000000"],["111640.29000000","0.00000000"],["111639.67000000","0.17902000"],["111639.25000000","0.00150000"],["111639.17000000","0.00000000"],["111638.95000000","0.00100000"],["111638.92000000","0.37838000"],["111638.84000000","0.01164000"],["111638.83000000","0.00000000"],["111638.75000000","0.00094000"],["111638.17000000","0.00000000"],["111637.56000000","0.00000000"],["111637.43000000","0.00000000"],["111637.32000000","0.00007000"],["111636.57000000","0.02000000"],["111635.95000000","0.00070000"],["111635.47000000","0.00000000"],["111635.27000000","0.00000000"],["111634.97000000","0.00000000"],["111634.67000000","0.00000000"],["111633.47000000","0.04000000"],["111633.17000000","0.56000000"],["111633.01000000","0.00000000"],["111632.01000000","0.00000000"],["111630.88000000","0.00005000"],["111630.49000000","0.00000000"],["111628.58000000","0.00005000"],["111628.57000000","0.00000000"],["111628.52000000","0.00000000"],["111627.85000000","0.00000000"],["111627.83000000","0.40873000"],["111627.54000000","0.15000000"],["111626.26000000","0.35806000"],["111624.50000000","0.00000000"],["111621.82000000","1.05915000"],["111621.81000000","0.40306000"],["111621.58000000","0.00000000"],["111621.51000000","0.00000000"],["111617.25000000","0.02686000"],["111614.21000000","0.00000000"],["111611.99000000","0.00000000"],["111610.15000000","0.31977000"],["111605.04000000","0.00000000"],["111604.82000000","0.00500000"],["111604.62000000","0.00000000"],["111604.31000000","0.00000000"],["111603.81000000","0.00000000"],["111603.34000000","0.00136000"],["111603.28000000","0.06575000"],["111602.92000000","0.32241000"],["111602.64000000","0.00000000"],["111602.02000000","0.30212000"],["111596.94000000","0.00000000"],["111593.55000000","0.17909000"],["111588.14000000","0.00000000"],["111583.69000000","0.04375000"],["111578.31000000","0.03223000"],["111570.83000000","0.01401000"],["111570.30000000","0.00000000"],["111568.45000000","0.00000000"],["111567.82000000","0.00000000"],["111561.00000000","0.00163000"],["111560.37000000","0.00000000"],["111558.73000000","0.00000000"],["111558.53000000","0.05218000"],["111556.59000000","0.00000000"],["111555.81000000","0.00086000"],["111554.22000000","0.00000000"],["111553.75000000","0.01800000"],["111550.18000000","0.34629000"],["111549.06000000","0.30860000"],["111548.01000000","0.00000000"],["111546.75000000","0.00000000"],["111546.01000000","0.00196000"],["111545.81000000","0.00000000"],["111545.80000000","0.00000000"],["111542.84000000","0.00000000"],["111542.40000000","0.01075000"],["111534.93000000","0.04835000"],["111534.54000000","0.02597000"],["111528.33000000","0.02418000"],["111525.41000000","0.00000000"],["111520.66000000","0.02418000"],["111520.22000000","0.00000000"],["111516.27000000","0.34600000"],["111516.15000000","0.02418000"],["111515.39000000","0.17904000"],["111512.66000000","0.01236000"],["111511.80000000","0.02418000"],["111510.13000000","0.44780000"],["111507.06000000","0.00000000"],["111501.87000000","0.08894000"],["111499.58000000","0.09894000"],["111498.52000000","0.08894000"],["111492.73000000","0.00000000"],["111487.36000000","0.00000000"],["111468.44000000","0.17314000"],["111459.76000000","0.00000000"],["111449.61000000","0.00065000"],["111438.61000000","0.00000000"],["111434.70000000","0.08794000"],["111425.83000000","0.00089000"],["111414.12000000","4.69016000"],["111409.00000000","0.00038000"],["111400.69000000","0.00000000"],["111392.37000000","0.00000000"],["111389.18000000","0.01701000"],["111384.06000000","0.00000000"],["111380.34000000","0.01701000"],["111369.26000000","0.01701000"],["111361.38000000","0.00000000"],["111360.95000000","0.01701000"],["111360.27000000","0.00000000"],["111357.49000000","0.00000000"],["111357.19000000","0.00000000"],["111356.99000000","0.00000000"],["111356.40000000","0.00000000"],["111355.19000000","0.00000000"],["111352.29000000","0.00000000"],["111351.54000000","0.00000000"],["111351.18000000","0.00000000"],["111350.10000000","0.00000000"],["111346.31000000","0.00010000"],["111340.73000000","0.00010000"],["111338.88000000","0.00000000"],["111313.65000000","0.03582000"],["111312.46000000","0.03582000"],["111312.19000000","0.03582000"],["111312.00000000","0.03582000"],["111311.97000000","0.03582000"],["111311.61000000","0.03582000"],["111311.55000000","0.03582000"],["111300.87000000","0.05996000"],["111290.86000000","0.00000000"],["111242.60000000","0.00000000"],["111225.83000000","0.00000000"],["111220.34000000","0.00000000"],["111217.22000000","0.00000000"],["111214.80000000","0.00000000"],["111212.03000000","0.00000000"],["111211.43000000","0.00000000"],["111210.03000000","0.00000000"],["111209.16000000","0.00000000"],["111209.11000000","0.00000000"],["111208.82000000","0.00000000"],["110219.68000000","0.00000000"],["110167.17000000","0.00008000"],["110008.95000000","0.00016000"],["109985.65000000","0.00000000"],["109391.75000000","0.00016000"],["108774.55000000","0.00016000"],["108157.36000000","0.00016000"],["106000.00000000","32.68589000"],["100494.00000000","0.00000000"],["100490.00000000","0.00010000"],["89328.45000000","0.00000000"],["89324.80000000","0.00022000"],["78161.27000000","0.00000000"],["40197.80000000","0.00030000"]],"a":[["111656.01000000","6.80421000"],["111656.07000000","0.00000000"],["111656.09000000","0.00010000"],["111656.10000000","0.00080000"],["111656.13000000","0.00005000"],["111656.34000000","0.00048000"],["111656.64000000","0.00000000"],["111656.67000000","0.00000000"],["111657.98000000","0.00000000"],["111658.01000000","0.04017000"],["111658.86000000","0.00000000"],["111658.96000000","0.00000000"],["111659.01000000","0.00000000"],["111659.98000000","0.00000000"],["111660.00000000","0.00000000"],["111660.01000000","0.04017000"],["111660.15000000","0.00000000"],["111660.17000000","0.00000000"],["111660.18000000","0.31340000"],["111660.19000000","0.00000000"],["111660.24000000","0.00000000"],["111660.26000000","0.00000000"],["111660.36000000","0.04010000"],["111660.46000000","0.00000000"],["111660.48000000","0.00000000"],["111660.49000000","0.00000000"],["111660.50000000","0.00000000"],["111660.51000000","0.00000000"],["111660.54000000","0.00000000"],["111660.55000000","0.41620000"],["111660.56000000","1.34266000"],["111660.57000000","0.56389000"],["111660.65000000","0.00000000"],["111660.70000000","0.00000000"],["111660.96000000","0.01348000"],["111661.69000000","0.04072000"],["111661.91000000","0.00000000"],["111662.25000000","0.11190000"],["111662.80000000","0.00368000"],["111663.35000000","0.01788000"],["111664.46000000","0.00447000"],["111664.47000000","0.00537000"],["111666.15000000","0.00025000"],["111666.34000000","0.00087000"],["111666.36000000","0.41303000"],["111666.37000000","0.35802000"],["111666.38000000","0.44308000"],["111666.66000000","0.04005000"],["111666.85000000","0.03582000"],["111667.22000000","0.05987000"],["111669.61000000","0.00007000"],["111669.95000000","0.00010000"],["111670.02000000","0.00000000"],["111670.08000000","0.03582000"],["111670.89000000","0.00005000"],["111670.91000000","0.00000000"],["111671.72000000","0.00000000"],["111673.05000000","0.00007000"],["111673.16000000","0.00000000"],["111673.18000000","0.93530000"],["111673.89000000","0.00000000"],["111674.70000000","0.00000000"],["111675.07000000","0.00000000"],["111675.14000000","0.00000000"],["111676.27000000","0.00044000"],["111677.39000000","1.25396000"],["111677.40000000","0.02298000"],["111677.61000000","0.00000000"],["111677.64000000","0.00432000"],["111677.72000000","0.00006000"],["111679.48000000","0.00000000"],["111679.89000000","0.32218000"],["111680.28000000","0.00005000"],["111680.78000000","0.00000000"],["111684.81000000","0.04261000"],["111687.45000000","0.00000000"],["111688.54000000","0.00715000"],["111693.97000000","0.00000000"],["111695.74000000","0.18400000"],["111695.76000000","0.00000000"],["111697.79000000","0.01401000"],["111697.82000000","0.04800000"],["111698.98000000","0.12802000"],["111699.56000000","0.00000000"],["111699.91000000","0.00000000"],["111700.01000000","0.04000000"],["111700.29000000","0.00000000"],["111700.32000000","0.00000000"],["111700.83000000","0.00000000"],["111707.46000000","0.00000000"],["111707.47000000","0.00000000"],["111720.08000000","1.90007000"],["111733.93000000","0.13426000"],["111735.44000000","0.00000000"],["111735.52000000","0.00000000"],["111742.81000000","0.00100000"],["111742.83000000","0.00005000"],["111744.18000000","0.00000000"],["111744.45000000","0.00112000"],["111744.90000000","0.01800000"],["111745.79000000","0.04045000"],["111756.81000000","0.61034000"],["111760.69000000","0.00000000"],["111762.69000000","0.00000000"],["111764.23000000","0.00000000"],["111765.86000000","0.00000000"],["111766.96000000","0.00000000"],["111766.99000000","0.22377000"],["111767.04000000","0.00000000"],["111767.06000000","0.00000000"],["111767.73000000","0.34660000"],["111767.74000000","0.22377000"],["111767.99000000","0.00223000"],["111768.61000000","0.00000000"],["111769.21000000","0.00000000"],["111771.36000000","0.00000000"],["111771.70000000","0.07807000"],["111772.13000000","0.00000000"],["111773.01000000","0.00536000"],["111774.29000000","0.00000000"],["111775.80000000","0.09759000"],["111777.38000000","0.00187000"],["111778.81000000","0.37243000"],["111791.28000000","0.00000000"],["111809.48000000","0.00000000"],["111812.38000000","0.28411000"],["111813.55000000","0.00000000"],["111815.04000000","0.00000000"],["111817.86000000","0.32138000"],["111819.77000000","0.02418000"],["111820.02000000","0.02418000"],["111821.35000000","0.02418000"],["111824.96000000","0.47504000"],["111825.36000000","0.02418000"],["111825.47000000","0.02418000"],["111827.42000000","0.00000000"],["111830.78000000","0.00000000"],["111834.90000000","0.00000000"],["111842.45000000","0.00000000"],["111857.13000000","0.00000000"],["111864.81000000","0.00000000"],["111879.99000000","0.00089000"],["111886.23000000","0.00000000"],["111886.80000000","0.02507000"],["111897.08000000","4.77234000"],["111901.59000000","0.01701000"],["111910.28000000","0.00079000"],["111912.31000000","0.02507000"],["111924.84000000","0.00000000"],["111925.97000000","0.00000000"],["111926.06000000","0.00000000"],["111926.77000000","0.00000000"],["111931.13000000","0.00000000"],["111960.34000000","0.00000000"],["111961.14000000","0.05996000"],["111971.91000000","0.02597000"],["111981.75000000","0.03582000"],["111982.50000000","0.03582000"],["111982.67000000","0.03582000"],["111982.84000000","0.03588000"],["111983.36000000","0.03582000"],["111983.71000000","0.03582000"],["111984.06000000","0.03582000"],["111984.57000000","0.03582000"],["111984.96000000","0.02686000"],["111985.72000000","0.03582000"],["111986.35000000","0.03587000"],["111986.51000000","0.02686000"],["111988.17000000","0.03582000"],["111988.63000000","0.05996000"],["111989.23000000","0.00000000"],["111989.90000000","0.00000000"],["111990.46000000","0.05996000"],["111990.87000000","0.05996000"],["111999.04000000","0.00000000"],["112001.25000000","0.00000000"],["112067.02000000","0.00000000"],["112067.48000000","0.00000000"],["112079.62000000","0.00000000"],["112079.84000000","0.00000000"],["112080.08000000","0.00000000"],["112080.11000000","0.00000000"],["112080.15000000","0.00000000"],["112080.31000000","0.00000000"],["112080.34000000","0.00000000"],["112080.43000000","0.00000000"],["112080.68000000","0.00000000"],["112080.75000000","0.00000000"],["112092.15000000","0.00000000"],["112092.39000000","0.00000000"],["112092.64000000","0.00000000"],["112203.84000000","0.00000000"],["112209.18000000","0.00000000"],["112209.83000000","0.00000000"],["112263.85000000","0.00000000"],["113335.48000000","0.00000000"]]}
[2025-10-12T10:57:11.185Z] {"e":"depthUpdate","E":1760266631014,"s":"BTCUSDT","U":77965072674,"u":77965072998,"b":[["111656.00000000","0.35482000"],["111655.99000000","0.00115000"],["111655.92000000","0.00010000"],["111655.28000000","0.00000000"],["111655.26000000","0.00000000"],["111655.00000000","0.00000000"],["111654.58000000","0.00005000"],["111654.43000000","0.11679000"],["111653.47000000","0.00005000"],["111651.58000000","0.05405000"],["111651.29000000","0.00305000"],["111651.15000000","0.00005000"],["111651.14000000","0.29546000"],["111650.64000000","0.00000000"],["111650.63000000","0.00005000"],["111650.18000000","0.00005000"],["111650.03000000","0.00000000"],["111650.02000000","0.11427000"],["111650.00000000","0.00526000"],["111649.61000000","0.00155000"],["111649.51000000","0.00000000"],["111648.03000000","0.03987000"],["111648.00000000","0.00265000"],["111647.62000000","0.04480000"],["111646.91000000","0.04118000"],["111646.78000000","0.00000000"],["111646.17000000","0.00000000"],["111644.87000000","0.00000000"],["111644.86000000","0.00072000"],["111644.85000000","0.00000000"],["111644.20000000","0.01790000"],["111643.80000000","0.00000000"],["111642.62000000","0.00000000"],["111642.21000000","0.02688000"],["111638.95000000","0.00000000"],["111636.57000000","0.00000000"],["111636.22000000","0.00000000"],["111636.14000000","0.00000000"],["111635.95000000","0.00000000"],["111635.17000000","0.02000000"],["111634.78000000","0.00000000"],["111634.76000000","0.07270000"],["111632.88000000","0.00000000"],["111632.05000000","0.00005000"],["111628.52000000","0.15000000"],["111628.26000000","0.01390000"],["111627.54000000","0.00000000"],["111622.50000000","0.00300000"],["111621.78000000","0.32235000"],["111612.60000000","0.00009000"],["111610.39000000","0.00018000"],["111604.82000000","0.00000000"],["111603.28000000","0.00000000"],["111602.92000000","0.00000000"],["111602.21000000","0.00009000"],["111600.51000000","0.00530000"],["111570.83000000","0.00000000"],["111566.86000000","0.00090000"],["111561.52000000","0.00005000"],["111554.27000000","0.00000000"],["111552.04000000","0.00000000"],["111490.30000000","0.04947000"],["111326.25000000","0.02597000"],["111320.95000000","0.02597000"],["111215.27000000","0.03582000"],["111209.60000000","0.03582000"],["111204.07000000","0.03582000"],["111198.47000000","0.03582000"],["111192.43000000","0.03582000"],["111186.52000000","0.03582000"],["111178.95000000","0.03582000"],["111173.25000000","0.03582000"],["111167.18000000","0.03582000"],["111160.41000000","0.03582000"],["110150.00000000","0.02389000"],["109981.16000000","0.00100000"],["107540.16000000","0.00016000"],["106970.40000000","0.00000000"],["106922.96000000","0.00016000"],["106305.76000000","0.00016000"],["105688.56000000","0.00016000"],["105615.00000000","0.00000000"],["100490.00000000","0.00010000"],["89324.80000000","0.00022000"],["40196.16000000","0.00045000"],["33000.00000000","3.87311000"]],"a":[["111656.01000000","6.52923000"],["111658.00000000","0.00010000"],["111658.01000000","0.04022000"],["111659.06000000","0.00100000"],["111660.00000000","0.00010000"],["111660.17000000","0.00010000"],["111660.18000000","0.00010000"],["111660.35000000","0.00000000"],["111660.36000000","0.04010000"],["111660.53000000","0.00000000"],["111660.54000000","0.44267000"],["111660.55000000","0.00000000"],["111660.56000000","0.89512000"],["111660.57000000","0.56362000"],["111660.96000000","0.01353000"],["111661.69000000","0.04067000"],["111662.25000000","0.00000000"],["111662.35000000","0.00000000"],["111662.42000000","0.08504000"],["111662.62000000","0.00005000"],["111663.35000000","0.01798000"],["111663.46000000","0.00000000"],["111663.54000000","0.01115000"],["111665.55000000","0.00005000"],["111666.85000000","0.03587000"],["111667.18000000","0.00300000"],["111667.77000000","0.00005000"],["111667.83000000","0.11190000"],["111668.62000000","0.04000000"],["111669.02000000","0.02000000"],["111669.11000000","0.00889000"],["111670.00000000","0.00000000"],["111672.60000000","0.00005000"],["111674.34000000","0.00799000"],["111675.94000000","0.13426000"],["111684.96000000","0.08503000"],["111687.62000000","0.17904000"],["111692.17000000","0.22377000"],["111692.22000000","0.22377000"],["111701.81000000","0.00000000"],["111704.00000000","0.00200000"],["111706.00000000","0.00200000"],["111708.00000000","0.00200000"],["111710.00000000","0.00200000"],["111712.00000000","0.00200000"],["111714.00000000","0.00200000"],["111715.80000000","0.00000000"],["111716.00000000","0.00200000"],["111716.34000000","0.00000000"],["111718.00000000","0.00200000"],["111720.00000000","0.04879000"],["111738.82000000","0.00100000"],["111738.83000000","0.00100000"],["111742.81000000","0.00000000"],["111742.82000000","0.00000000"],["111752.61000000","0.00520000"],["111763.10000000","0.17904000"],["111764.52000000","0.00000000"],["111766.67000000","0.00187000"],["111766.99000000","0.00000000"],["111767.74000000","0.00000000"],["111770.33000000","0.22377000"],["111770.38000000","0.22377000"],["111771.98000000","0.02507000"],["111776.84000000","0.04097000"],["111777.38000000","0.00000000"],["111899.57000000","0.00088000"],["111910.28000000","0.00000000"],["112013.69000000","0.02686000"],["112048.20000000","0.00000000"],["112218.85000000","0.00106000"],["112609.66000000","0.00071000"],["112654.82000000","0.00000000"],["113330.86000000","0.00100000"]]}
[2025-10-12T10:57:12.185Z] {"e":"depthUpdate","E":1760266632014,"s":"BTCUSDT","U":77965072999,"u":77965073895,"b":[["111656.00000000","0.00000000"],["111655.99000000","0.00000000"],["111655.98000000","0.00000000"],["111655.92000000","0.00000000"],["111655.54000000","0.00000000"],["111655.53000000","0.00000000"],["111655.50000000","0.00000000"],["111655.32000000","0.00000000"],["111655.31000000","0.00000000"],["111655.27000000","0.00000000"],["111654.59000000","0.00000000"],["111654.58000000","0.00000000"],["111654.45000000","0.00000000"],["111654.44000000","0.29724000"],["111654.43000000","0.00125000"],["111654.42000000","0.01826000"],["111654.41000000","0.00020000"],["111654.36000000","0.00010000"],["111654.09000000","0.00010000"],["111654.08000000","0.03014000"],["111654.06000000","0.00010000"],["111652.58000000","0.00000000"],["111652.51000000","0.00000000"],["111652.00000000","0.00260000"],["111651.59000000","0.00000000"],["111651.58000000","0.00000000"],["111651.15000000","0.00000000"],["111651.14000000","0.00000000"],["111650.63000000","0.00000000"],["111650.36000000","0.00000000"],["111650.18000000","0.00000000"],["111650.17000000","0.00000000"],["111650.03000000","0.00000000"],["111650.02000000","0.00000000"],["111650.00000000","0.00531000"],["111649.61000000","0.00150000"],["111649.33000000","0.00005000"],["111649.21000000","0.04367000"],["111648.32000000","0.00000000"],["111648.31000000","0.00000000"],["111648.03000000","0.00000000"],["111648.00000000","0.00260000"],["111647.62000000","0.00000000"],["111646.91000000","0.00005000"],["111646.00000000","0.00260000"],["111645.65000000","0.08853000"],["111645.64000000","0.29553000"],["111644.58000000","0.00010000"],["111644.57000000","0.19789000"],["111644.56000000","0.00000000"],["111644.20000000","0.00005000"],["111644.11000000","0.00000000"],["111644.06000000","0.00452000"],["111644.00000000","0.00265000"],["111643.81000000","0.00156000"],["111643.48000000","0.00000000"],["111642.21000000","0.00000000"],["111642.00000000","0.00265000"],["111641.22000000","0.00335000"],["111641.20000000","0.00000000"],["111641.09000000","0.00010000"],["111641.08000000","0.04005000"],["111641.06000000","0.00000000"],["111639.70000000","0.00000000"],["111639.67000000","0.00000000"],["111639.66000000","0.01164000"],["111639.25000000","0.04625000"],["111638.25000000","0.00000000"],["111638.22000000","0.00000000"],["111637.32000000","0.00000000"],["111637.10000000","0.17903000"],["111636.73000000","0.00000000"],["111636.54000000","0.00000000"],["111636.08000000","0.00000000"],["111636.04000000","0.00000000"],["111635.76000000","0.00007000"],["111635.17000000","0.00000000"],["111634.41000000","0.00100000"],["111633.67000000","0.00000000"],["111633.63000000","0.07200000"],["111633.17000000","0.24000000"],["111632.87000000","0.02000000"],["111632.86000000","0.53718000"],["111632.45000000","0.09360000"],["111632.33000000","0.00068000"],["111632.10000000","0.11190000"],["111630.87000000","0.00000000"],["111630.10000000","0.00447000"],["111629.88000000","0.00022000"],["111629.60000000","0.00007000"],["111629.56000000","0.32000000"],["111628.52000000","0.00000000"],["111628.50000000","0.00000000"],["111628.46000000","0.00000000"],["111628.26000000","0.00000000"],["111627.56000000","0.00000000"],["111627.54000000","0.00000000"],["111626.61000000","0.00000000"],["111626.27000000","0.15000000"],["111626.26000000","0.00000000"],["111625.95000000","0.00000000"],["111623.90000000","0.00957000"],["111622.45000000","0.08504000"],["111621.84000000","0.35806000"],["111621.81000000","0.40306000"],["111621.78000000","0.00000000"],["111620.43000000","0.00000000"],["111619.25000000","0.00000000"],["111618.12000000","0.00000000"],["111616.68000000","0.32237000"],["111616.37000000","0.40306000"],["111615.98000000","0.00000000"],["111612.60000000","0.00000000"],["111610.39000000","0.00000000"],["111608.60000000","0.00014000"],["111608.08000000","0.00012000"],["111608.01000000","0.00000000"],["111606.83000000","0.01701000"],["111606.69000000","0.00442000"],["111606.39000000","0.00018000"],["111602.51000000","0.32241000"],["111602.21000000","0.00000000"],["111602.14000000","0.00005000"],["111602.02000000","0.00000000"],["111600.87000000","0.04476000"],["111600.81000000","0.00000000"],["111600.51000000","0.00000000"],["111599.25000000","0.00000000"],["111598.21000000","0.00009000"],["111598.02000000","0.00005000"],["111596.23000000","0.30213000"],["111594.98000000","0.03682000"],["111593.55000000","0.17909000"],["111589.08000000","0.00000000"],["111575.34000000","0.00000000"],["111573.69000000","0.00000000"],["111572.60000000","0.40306000"],["111566.86000000","0.00000000"],["111564.56000000","0.07200000"],["111563.38000000","0.09360000"],["111562.86000000","0.00090000"],["111562.69000000","0.04277000"],["111559.23000000","0.62745000"],["111558.08000000","0.00000000"],["111555.97000000","1.25396000"],["111554.65000000","0.00000000"],["111524.17000000","0.00000000"],["111523.20000000","0.07301000"],["111513.55000000","0.02597000"],["111510.49000000","0.02597000"],["111510.14000000","0.73587000"],["111508.38000000","0.00000000"],["111503.26000000","0.00000000"],["111501.79000000","0.02597000"],["111501.52000000","0.08894000"],["111498.38000000","0.08894000"],["111493.59000000","0.13655000"],["111492.67000000","0.00000000"],["111491.73000000","0.00000000"],["111491.63000000","0.00000000"],["111491.32000000","0.00000000"],["111489.86000000","0.00052000"],["111488.70000000","0.00000000"],["111488.35000000","0.00000000"],["111488.17000000","0.00000000"],["111470.62000000","0.07773000"],["111458.01000000","0.00000000"],["111447.15000000","0.08794000"],["111445.79000000","0.08794000"],["111444.65000000","0.00089000"],["111443.10000000","0.08794000"],["111440.60000000","0.08794000"],["111439.09000000","0.08794000"],["111436.96000000","0.52240000"],["111436.68000000","0.08794000"],["111434.52000000","0.08794000"],["111434.45000000","0.08794000"],["111416.33000000","0.00152000"],["111382.74000000","0.00000000"],["111356.00000000","0.00000000"],["111350.69000000","0.00538000"],["111345.08000000","0.00000000"],["111337.63000000","0.00000000"],["111337.34000000","0.00000000"],["111336.63000000","0.00000000"],["111336.43000000","0.00000000"],["111327.01000000","0.00100000"],["111326.07000000","0.02597000"],["111320.89000000","0.02597000"],["111301.23000000","0.05996000"],["111300.62000000","0.05996000"],["111299.92000000","0.05996000"],["111299.91000000","0.05996000"],["111298.86000000","0.02686000"],["111290.37000000","0.03582000"],["111271.03000000","0.00000000"],["111215.36000000","0.00100000"],["111159.32000000","0.00000000"],["109981.16000000","0.00000000"],["108100.00000000","17.51802000"],["105071.36000000","0.00016000"],["104454.16000000","0.00016000"],["103836.96000000","0.00016000"],["103219.76000000","0.00016000"],["100490.00000000","0.00010000"],["89324.80000000","0.00000000"],["89323.56000000","0.00022000"],["40196.16000000","0.00060000"]],"a":[["111654.45000000","8.46185000"],["111654.46000000","0.00000000"],["111654.51000000","0.00000000"],["111654.53000000","0.00010000"],["111654.60000000","0.00080000"],["111655.30000000","0.00000000"],["111655.32000000","0.00000000"],["111655.33000000","0.04012000"],["111655.51000000","0.00000000"],["111655.52000000","0.00000000"],["111655.55000000","0.00000000"],["111655.93000000","0.00000000"],["111655.98000000","0.00000000"],["111655.99000000","0.54860000"],["111656.00000000","0.40416000"],["111656.01000000","0.51541000"],["111656.02000000","0.00542000"],["111656.09000000","0.00000000"],["111656.10000000","0.00000000"],["111658.00000000","0.00000000"],["111658.01000000","0.04012000"],["111659.06000000","0.00000000"],["111660.00000000","0.00000000"],["111660.01000000","0.04012000"],["111660.03000000","0.00015000"],["111660.17000000","0.00000000"],["111660.18000000","0.00000000"],["111660.36000000","0.04005000"],["111660.54000000","0.00000000"],["111660.57000000","0.32979000"],["111660.73000000","0.00901000"],["111660.96000000","0.01348000"],["111661.51000000","0.00005000"],["111661.59000000","0.00000000"],["111661.69000000","0.04062000"],["111662.42000000","0.00000000"],["111662.80000000","0.00373000"],["111662.99000000","0.00860000"],["111663.35000000","0.01793000"],["111663.54000000","0.01120000"],["111664.18000000","0.05537000"],["111664.46000000","0.00000000"],["111664.64000000","0.00005000"],["111666.85000000","0.03587000"],["111667.22000000","0.00000000"],["111668.01000000","0.01310000"],["111668.05000000","0.05280000"],["111668.62000000","0.04000000"],["111668.97000000","0.09829000"],["111669.11000000","0.00000000"],["111671.49000000","0.00007000"],["111672.06000000","0.00000000"],["111672.42000000","0.04800000"],["111673.05000000","0.00000000"],["111673.16000000","1.45627000"],["111673.17000000","1.25396000"],["111673.18000000","0.00000000"],["111674.41000000","0.32220000"],["111674.65000000","0.04800000"],["111675.09000000","0.00000000"],["111675.94000000","0.00000000"],["111679.81000000","0.00895000"],["111679.87000000","0.00437000"],["111680.75000000","0.00000000"],["111685.13000000","0.00000000"],["111685.50000000","0.00000000"],["111687.36000000","0.00000000"],["111687.62000000","0.00000000"],["111688.65000000","0.32216000"],["111689.52000000","0.00000000"],["111692.12000000","0.00000000"],["111692.41000000","0.08000000"],["111694.18000000","0.18419000"],["111695.74000000","0.00000000"],["111697.52000000","0.00000000"],["111698.26000000","0.00000000"],["111701.35000000","0.13426000"],["111705.33000000","2.16336000"],["111715.80000000","0.00005000"],["111716.73000000","0.00629000"],["111720.10000000","0.00628000"],["111721.48000000","0.00894000"],["111723.90000000","0.05280000"],["111726.26000000","0.02597000"],["111727.68000000","0.02597000"],["111733.93000000","0.00000000"],["111733.95000000","0.00000000"],["111735.99000000","0.02597000"],["111737.98000000","0.00000000"],["111738.81000000","0.00100000"],["111738.83000000","0.00000000"],["111740.81000000","0.00000000"],["111746.59000000","0.00000000"],["111749.09000000","0.00005000"],["111753.32000000","0.00187000"],["111754.10000000","0.01377000"],["111756.81000000","0.00000000"],["111756.82000000","0.08994000"],["111761.37000000","0.00000000"],["111763.06000000","0.54732000"],["111763.09000000","0.00000000"],["111763.10000000","0.00000000"],["111766.67000000","0.00000000"],["111768.70000000","0.09845000"],["111771.15000000","0.00000000"],["111773.34000000","0.00000000"],["111784.54000000","0.00000000"],["111793.16000000","0.01236000"],["111794.66000000","0.06000000"],["111805.95000000","0.02597000"],["111807.12000000","0.00000000"],["111812.38000000","0.08147000"],["111812.39000000","0.00000000"],["111813.59000000","0.00000000"],["111813.87000000","0.00000000"],["111814.57000000","0.00000000"],["111817.86000000","0.28141000"],["111825.26000000","0.00000000"],["111850.27000000","0.00000000"],["111850.72000000","0.00000000"],["111886.21000000","0.00079000"],["111899.57000000","0.00009000"],["111935.99000000","0.00000000"],["111937.32000000","0.00000000"],["111937.35000000","0.00000000"],["111959.37000000","0.00000000"],["111959.48000000","0.00000000"],["111960.83000000","0.00000000"],["111990.00000000","0.02697000"],["112025.48000000","0.00000000"],["112046.91000000","0.00000000"],["112048.20000000","0.00000000"],["112052.86000000","0.00000000"],["112052.93000000","0.00000000"],["112053.89000000","0.00000000"],["112054.01000000","0.00000000"],["112054.32000000","0.00000000"],["112054.83000000","0.00000000"],["112055.47000000","0.00000000"],["112056.26000000","0.00000000"],["112056.67000000","0.00000000"],["112056.93000000","0.00000000"],["112058.05000000","0.00000000"],["112058.60000000","0.00000000"],["112065.72000000","0.00000000"],["112090.03000000","0.00000000"],["112100.49000000","0.00000000"],["112101.08000000","0.00000000"],["112102.96000000","0.00000000"],["112105.93000000","0.00000000"],["112107.60000000","0.00000000"],["112151.78000000","0.03582000"],["112313.55000000","0.00000000"],["113330.86000000","0.00000000"],["145960.00000000","0.00004000"]]}
[2025-10-12T10:57:13.185Z] {"e":"depthUpdate","E":1760266633014,"s":"BTCUSDT","U":77965073896,"u":77965074194,"b":[["111654.44000000","0.29714000"],["111654.43000000","0.00130000"],["111654.08000000","0.03014000"],["111654.07000000","0.00270000"],["111654.06000000","0.00020000"],["111654.05000000","0.01353000"],["111653.47000000","0.00000000"],["111651.29000000","0.00310000"],["111651.25000000","0.00005000"],["111650.54000000","0.00542000"],["111650.00000000","0.00531000"],["111649.61000000","0.00160000"],["111649.42000000","0.00722000"],["111649.33000000","0.00000000"],["111649.22000000","0.00010000"],["111649.21000000","0.04377000"],["111648.31000000","0.00005000"],["111648.30000000","0.01791000"],["111648.00000000","0.00265000"],["111646.07000000","0.00005000"],["111646.06000000","0.04480000"],["111646.00000000","0.00265000"],["111645.66000000","0.00000000"],["111645.65000000","0.08843000"],["111645.64000000","0.29543000"],["111644.58000000","0.00000000"],["111644.57000000","0.19779000"],["111644.00000000","0.00265000"],["111643.81000000","0.00151000"],["111642.00000000","0.00260000"],["111641.22000000","0.00330000"],["111641.09000000","0.00000000"],["111641.08000000","0.04000000"],["111641.04000000","0.00000000"],["111641.03000000","0.00000000"],["111641.02000000","0.00000000"],["111640.88000000","0.02688000"],["111640.18000000","0.01810000"],["111639.25000000","0.00150000"],["111628.70000000","0.00005000"],["111627.54000000","0.00000000"],["111626.29000000","0.00000000"],["111626.27000000","0.00000000"],["111626.18000000","0.01390000"],["111621.82000000","0.62677000"],["111621.81000000","0.55306000"],["111617.22000000","0.00000000"],["111610.50000000","1.21439000"],["111606.48000000","1.18208000"],["111604.90000000","0.35822000"],["111599.21000000","0.00000000"],["111599.10000000","0.06791000"],["111588.54000000","0.00390000"],["111573.02000000","0.00000000"],["111558.23000000","0.00000000"],["111537.68000000","0.00110000"],["111534.66000000","0.01793000"],["111498.53000000","0.10095000"],["111498.19000000","0.00000000"],["111414.12000000","0.00000000"],["111405.31000000","0.00000000"],["111399.28000000","0.00574000"],["111356.77000000","0.00000000"],["111352.42000000","0.01701000"],["111350.69000000","0.00000000"],["111294.05000000","0.02686000"],["111164.07000000","0.03582000"],["111157.52000000","0.03582000"],["110984.52000000","0.00019000"],["109979.62000000","0.00100000"],["108041.82000000","0.00000000"],["102768.90000000","0.00000000"],["102602.57000000","0.00016000"],["101985.37000000","0.00016000"],["101368.17000000","0.00016000"],["100750.97000000","0.00016000"],["100490.00000000","0.00000000"],["100488.00000000","0.00109000"],["89323.56000000","0.00022000"],["40195.60000000","0.00450000"]],"a":[["111654.45000000","8.32161000"],["111654.61000000","0.00906000"],["111654.84000000","0.01353000"],["111655.33000000","0.04017000"],["111655.99000000","0.54865000"],["111656.01000000","0.33552000"],["111656.68000000","0.00358000"],["111658.01000000","0.04012000"],["111658.35000000","0.00542000"],["111660.01000000","0.04007000"],["111660.36000000","0.04000000"],["111660.56000000","0.89507000"],["111660.73000000","0.00896000"],["111660.96000000","0.00005000"],["111662.20000000","0.00005000"],["111662.80000000","0.00368000"],["111664.47000000","0.00000000"],["111665.94000000","0.00044000"],["111667.04000000","0.00005000"],["111667.99000000","0.00000000"],["111668.01000000","0.01300000"],["111683.40000000","0.00005000"],["111684.97000000","0.00000000"],["111686.77000000","1.16581000"],["111687.04000000","0.00000000"],["111693.84000000","0.00000000"],["111697.79000000","0.00000000"],["111701.35000000","0.13426000"],["111712.45000000","0.00000000"],["111724.05000000","0.06720000"],["111727.12000000","0.00000000"],["111729.56000000","0.04800000"],["111736.68000000","0.00100000"],["111736.69000000","0.00100000"],["111738.81000000","0.00000000"],["111738.82000000","0.00000000"],["111739.69000000","1.24554000"],["111753.32000000","0.00000000"],["111756.59000000","0.55644000"],["111760.51000000","0.00000000"],["111761.06000000","0.00008000"],["111761.30000000","0.17904000"],["111761.40000000","0.00000000"],["111771.15000000","0.04800000"],["111777.53000000","0.01402000"],["111780.00000000","0.00360000"],["111785.22000000","0.00000000"],["111785.65000000","0.00000000"],["111791.19000000","0.00000000"],["111800.00000000","0.00576000"],["111820.00000000","0.00100000"],["111840.00000000","0.00133000"],["111872.58000000","0.00079000"],["111886.21000000","0.00000000"],["111890.38000000","0.08794000"],["111892.24000000","0.08794000"],["111895.67000000","0.08794000"],["111897.08000000","0.00000000"],["111903.57000000","0.00627000"],["111974.29000000","0.03582000"],["111978.16000000","0.05996000"],["111979.59000000","0.05996000"],["111981.00000000","0.05996000"],["111982.58000000","0.05996000"],["111984.21000000","0.03997000"],["111985.94000000","0.05996000"],["111986.47000000","0.05996000"],["111987.04000000","0.05996000"],["111987.90000000","0.05996000"],["111989.33000000","0.05996000"],["112013.75000000","0.02686000"],["112023.93000000","0.02298000"],["112025.50000000","0.02298000"],["112027.06000000","0.02298000"],["112027.85000000","0.02298000"],["112028.43000000","0.02298000"],["112149.89000000","0.03582000"],["112183.88000000","0.02398000"],["112240.42000000","0.02398000"],["112903.85000000","0.00000000"],["113329.27000000","0.00100000"]]}
[2025-10-12T10:57:14.187Z] {"e":"depthUpdate","E":1760266634014,"s":"BTCUSDT","U":77965074195,"u":77965074400,"b":[["111654.44000000","0.31141000"],["111654.43000000","0.00125000"],["111649.21000000","0.04382000"],["111648.36000000","0.00005000"],["111648.35000000","0.10909000"],["111648.34000000","0.29547000"],["111648.31000000","0.00000000"],["111646.07000000","0.00000000"],["111646.06000000","0.04475000"],["111646.00000000","0.00260000"],["111645.65000000","0.00005000"],["111645.64000000","0.00000000"],["111644.53000000","0.03940000"],["111643.41000000","0.04057000"],["111637.33000000","0.00100000"],["111634.41000000","0.00000000"],["111630.11000000","0.00000000"],["111627.54000000","0.15000000"],["111625.35000000","0.00005000"],["111622.14000000","0.00000000"],["111622.12000000","0.32235000"],["111621.86000000","0.00000000"],["111621.81000000","0.40306000"],["111608.54000000","0.00000000"],["111606.42000000","0.00000000"],["111602.51000000","0.00000000"],["111602.01000000","0.00000000"],["111554.94000000","0.00000000"],["111535.71000000","0.07518000"],["111502.29000000","0.00000000"],["111493.59000000","0.18943000"],["111492.21000000","0.06000000"],["111488.42000000","0.01086000"],["111464.36000000","0.02597000"],["111433.83000000","0.08694000"],["111402.07000000","4.71591000"],["111396.02000000","0.00000000"],["111384.84000000","0.00467000"],["111324.58000000","0.00538000"],["111307.28000000","0.03582000"],["111300.52000000","0.00000000"],["111157.52000000","0.00000000"],["110984.52000000","0.00000000"],["109979.62000000","0.00100000"],["108041.43000000","0.00184000"],["100488.00000000","0.00109000"],["100133.77000000","0.00016000"],["99516.57000000","0.00016000"],["98899.37000000","0.00016000"],["98282.17000000","0.00022000"],["89323.56000000","0.00022000"],["60000.00000000","53.14032000"],["40195.60000000","0.00465000"]],"a":[["111654.45000000","8.05780000"],["111656.00000000","0.40316000"],["111658.35000000","0.00542000"],["111659.66000000","0.00100000"],["111659.72000000","0.08504000"],["111663.35000000","0.01788000"],["111663.54000000","0.00005000"],["111666.61000000","0.00006000"],["111670.07000000","0.13426000"],["111685.74000000","0.17904000"],["111701.35000000","0.13426000"],["111735.68000000","0.00000000"],["111735.69000000","0.00000000"],["111736.68000000","0.00100000"],["111736.69000000","0.00100000"],["111739.69000000","1.24367000"],["111754.15000000","0.00187000"],["111761.30000000","0.00000000"],["111761.81000000","0.17904000"],["111763.05000000","0.30778000"],["111779.23000000","0.00000000"],["111872.58000000","0.00000000"],["111887.04000000","0.00079000"],["111890.00000000","4.86836000"],["111912.13000000","0.00000000"],["112044.51000000","0.00000000"],["112903.46000000","0.00018000"],["113329.27000000","0.00100000"]]}
[2025-10-12T10:57:15.185Z] {"e":"depthUpdate","E":1760266635014,"s":"BTCUSDT","U":77965074401,"u":77965074514,"b":[["111654.44000000","0.29938000"],["111654.43000000","0.00120000"],["111649.21000000","0.04387000"],["111648.36000000","0.00005000"],["111648.35000000","0.10904000"],["111648.34000000","0.29542000"],["111643.81000000","0.00151000"],["111640.81000000","0.00100000"],["111639.92000000","0.07615000"],["111637.33000000","0.00000000"],["111632.88000000","0.00000000"],["111630.11000000","0.15000000"],["111627.54000000","0.00000000"],["111622.14000000","0.00000000"],["111621.81000000","0.40306000"],["111595.69000000","0.18887000"],["111573.73000000","0.00447000"],["111308.04000000","0.00539000"],["111297.49000000","0.02686000"],["109979.62000000","0.00100000"],["108100.00000000","17.51820000"],["100488.00000000","0.00109000"],["97664.97000000","0.00016000"],["97047.78000000","0.00016000"],["89323.56000000","0.00022000"],["60000.00000000","53.14022000"]],"a":[["111654.45000000","8.05879000"],["111654.46000000","0.00000000"],["111654.60000000","0.00090000"],["111654.83000000","0.00010000"],["111655.32000000","0.00010000"],["111655.98000000","0.00010000"],["111656.02000000","0.00547000"],["111658.01000000","0.04017000"],["111659.66000000","0.00000000"],["111663.14000000","0.00100000"],["111666.43000000","0.00000000"],["111666.66000000","0.04000000"],["111666.85000000","0.03582000"],["111672.25000000","0.00005000"],["111698.00000000","0.00200000"],["111700.00000000","0.40506000"],["111702.00000000","0.00200000"],["111709.10000000","0.00000000"],["111787.99000000","1.03069000"],["112044.51000000","0.00000000"],["113329.27000000","0.00100000"]]}
[2025-10-12T10:57:16.184Z] {"e":"depthUpdate","E":1760266636014,"s":"BTCUSDT","U":77965074515,"u":77965074577,"b":[["111654.44000000","0.29921000"],["111648.35000000","0.10909000"],["111639.92000000","0.00000000"],["111632.88000000","0.00000000"],["111630.11000000","0.15000000"],["111627.54000000","0.00000000"],["111604.44000000","0.00490000"],["111433.83000000","0.00000000"],["109979.62000000","0.00100000"],["106970.40000000","0.00012000"],["106000.00000000","32.68589000"],["100488.00000000","0.00109000"],["89323.56000000","0.00022000"],["42000.00000000","1.49196000"],["40195.60000000","0.00480000"]],"a":[["111654.45000000","8.06563000"],["111655.99000000","0.54870000"],["111658.35000000","0.00547000"],["111674.34000000","0.00000000"],["111678.95000000","0.00005000"],["111702.40000000","0.00000000"],["111704.55000000","0.04097000"],["111705.99000000","0.04097000"],["111707.04000000","0.04097000"],["111707.99000000","0.04097000"],["111709.50000000","0.04097000"],["111715.99000000","0.04097000"],["111735.68000000","0.00100000"],["111735.69000000","0.00100000"],["111736.68000000","0.00000000"],["111736.69000000","0.00000000"],["111747.48000000","0.04097000"],["111757.99000000","0.04097000"],["111761.99000000","0.04097000"],["111767.42000000","0.04097000"],["111771.97000000","0.04097000"],["111777.53000000","0.00000000"],["111780.25000000","0.04097000"],["111935.50000000","0.00000000"],["112044.51000000","0.55838000"],["113329.27000000","0.00100000"]]}
[2025-10-12T10:57:17.185Z] {"e":"depthUpdate","E":1760266637014,"s":"BTCUSDT","U":77965074578,"u":77965074752,"b":[["111654.44000000","0.30032000"],["111654.43000000","0.00130000"],["111649.21000000","0.04382000"],["111648.36000000","0.00000000"],["111648.00000000","0.00270000"],["111646.78000000","0.05699000"],["111646.06000000","0.04475000"],["111638.25000000","0.00005000"],["111638.09000000","0.00000000"],["111630.11000000","0.15000000"],["111628.48000000","0.00000000"],["111627.54000000","0.00000000"],["111621.81000000","0.40306000"],["111610.50000000","0.88994000"],["111609.01000000","1.23290000"],["111606.48000000","0.00000000"],["111602.99000000","0.00000000"],["111600.01000000","0.30213000"],["111597.75000000","0.00009000"],["111596.23000000","0.00000000"],["111593.55000000","0.17904000"],["111592.17000000","0.00009000"],["111572.30000000","0.13117000"],["111561.00000000","0.00000000"],["111559.73000000","0.00164000"],["111499.03000000","0.08794000"],["111449.61000000","0.00000000"],["111448.01000000","0.00065000"],["111291.18000000","0.00000000"],["111157.57000000","0.03672000"],["109979.62000000","0.00100000"],["100488.00000000","0.00109000"],["89323.56000000","0.00022000"],["33000.00000000","3.87311000"]],"a":[["111654.45000000","8.37899000"],["111654.84000000","0.01353000"],["111655.32000000","0.00000000"],["111655.33000000","0.00005000"],["111655.68000000","0.00005000"],["111655.99000000","0.28019000"],["111656.00000000","0.00010000"],["111656.01000000","0.33557000"],["111658.01000000","0.04022000"],["111659.72000000","0.08509000"],["111660.01000000","0.04012000"],["111660.56000000","0.04181000"],["111662.16000000","0.54409000"],["111662.17000000","0.40306000"],["111662.43000000","0.04274000"],["111662.99000000","0.00865000"],["111663.54000000","0.00000000"],["111664.15000000","0.45020000"],["111664.16000000","0.00000000"],["111664.17000000","0.35808000"],["111664.18000000","0.00000000"],["111666.36000000","0.15000000"],["111666.37000000","0.00000000"],["111671.72000000","0.00000000"],["111673.14000000","0.00000000"],["111673.15000000","1.25396000"],["111673.16000000","1.06717000"],["111673.17000000","0.00000000"],["111674.41000000","0.00000000"],["111675.13000000","0.32220000"],["111675.47000000","0.26489000"],["111677.37000000","0.00000000"],["111684.77000000","1.53323000"],["111685.55000000","1.20313000"],["111685.74000000","0.00000000"],["111686.77000000","0.00000000"],["111691.86000000","0.00000000"],["111699.25000000","0.02685000"],["111702.40000000","0.00005000"],["111704.83000000","0.02238000"],["111711.25000000","0.00000000"],["111716.84000000","0.00000000"],["111735.68000000","0.00000000"],["111735.69000000","0.00000000"],["111736.68000000","0.00100000"],["111736.69000000","0.00100000"],["111754.15000000","0.00000000"],["111761.59000000","0.17904000"],["111761.81000000","0.00000000"],["111762.29000000","0.00187000"],["111887.04000000","0.00000000"],["111895.19000000","0.00079000"],["111896.06000000","0.08794000"],["111897.52000000","0.08794000"],["111899.08000000","0.00000000"],["111901.63000000","0.00000000"],["111905.77000000","0.03997000"],["111908.94000000","0.03997000"],["111931.00000000","0.00107000"],["112044.51000000","0.00000000"],["113329.27000000","0.00100000"]]}
[2025-10-12T10:57:18.184Z] {"e":"depthUpdate","E":1760266638014,"s":"BTCUSDT","U":77965074753,"u":77965074868,"b":[["111654.44000000","0.29778000"],["111654.43000000","0.00130000"],["111654.42000000","0.01826000"],["111654.41000000","0.00020000"],["111654.10000000","0.00010000"],["111654.09000000","0.03049000"],["111654.06000000","0.00010000"],["111654.05000000","0.01353000"],["111652.00000000","0.00265000"],["111651.96000000","0.00005000"],["111651.95000000","0.04090000"],["111649.22000000","0.00005000"],["111649.21000000","0.04382000"],["111648.36000000","0.00000000"],["111648.35000000","0.10904000"],["111644.06000000","0.00447000"],["111644.00000000","0.00260000"],["111640.81000000","0.00000000"],["111639.27000000","0.00000000"],["111638.13000000","0.00000000"],["111638.10000000","0.00000000"],["111637.96000000","0.00100000"],["111634.23000000","0.00000000"],["111633.66000000","0.00000000"],["111632.53000000","0.12000000"],["111632.49000000","0.11520000"],["111632.39000000","0.04800000"],["111630.11000000","0.00000000"],["111628.01000000","0.05280000"],["111627.54000000","0.15000000"],["111610.50000000","1.17108000"],["111610.15000000","0.27177000"],["111605.72000000","0.00000000"],["111554.33000000","0.05280000"],["111554.29000000","0.09600000"],["111549.85000000","0.05280000"],["111493.11000000","0.06000000"],["111312.50000000","0.03672000"],["111291.48000000","0.00000000"],["110150.00000000","0.02394000"],["109979.62000000","0.00100000"],["108100.00000000","17.51838000"],["103997.00000000","0.00000000"],["102768.90000000","0.00010000"],["100488.00000000","0.00109000"],["89323.56000000","0.00022000"],["42000.00000000","1.49096000"]],"a":[["111654.45000000","8.19877000"],["111658.00000000","0.00000000"],["111660.01000000","0.04007000"],["111660.36000000","0.00005000"],["111660.60000000","0.00005000"],["111661.69000000","0.04067000"],["111663.14000000","0.00000000"],["111665.94000000","0.00000000"],["111685.76000000","0.17904000"],["112044.51000000","0.00000000"],["113329.27000000","0.00100000"]]}
[2025-10-12T10:57:19.184Z] {"e":"depthUpdate","E":1760266639014,"s":"BTCUSDT","U":77965074869,"u":77965075198,"b":[["111654.44000000","2.04838000"],["111654.43000000","0.00259000"],["111654.42000000","0.01826000"],["111654.09000000","0.11475000"],["111654.05000000","0.01348000"],["111653.48000000","0.00000000"],["111652.00000000","0.00260000"],["111651.96000000","0.00000000"],["111651.95000000","0.00000000"],["111651.17000000","0.00005000"],["111651.16000000","0.00005000"],["111651.07000000","0.00000000"],["111651.06000000","0.00000000"],["111649.22000000","0.00000000"],["111649.21000000","0.04377000"],["111648.86000000","0.03784000"],["111648.85000000","0.29542000"],["111648.35000000","0.00000000"],["111648.34000000","0.00000000"],["111644.53000000","0.04092000"],["111644.20000000","0.00000000"],["111644.06000000","0.00452000"],["111644.00000000","0.00265000"],["111643.41000000","0.04058000"],["111643.27000000","0.11190000"],["111641.87000000","0.00000000"],["111639.92000000","0.07615000"],["111637.96000000","0.00000000"],["111634.75000000","0.00070000"],["111633.66000000","0.04800000"],["111632.88000000","0.15000000"],["111632.58000000","0.05760000"],["111632.33000000","0.00000000"],["111632.10000000","0.00000000"],["111630.11000000","0.00000000"],["111628.67000000","0.06240000"],["111627.54000000","0.00000000"],["111627.05000000","0.00000000"],["111626.30000000","0.01390000"],["111626.18000000","0.00000000"],["111626.11000000","0.00000000"],["111614.55000000","0.00000000"],["111611.33000000","0.00000000"],["111610.15000000","0.22377000"],["111609.07000000","0.32239000"],["111604.90000000","0.03582000"],["111604.45000000","0.30212000"],["111601.28000000","0.04375000"],["111600.01000000","0.00000000"],["111585.50000000","0.04277000"],["111583.69000000","0.00000000"],["111562.69000000","0.00000000"],["111555.46000000","0.00000000"],["111554.33000000","0.00000000"],["111553.27000000","0.00000000"],["111549.34000000","0.00000000"],["111406.10000000","0.02507000"],["111403.08000000","0.02507000"],["111304.75000000","0.03672000"],["111157.57000000","0.00000000"],["109979.62000000","0.00100000"],["102768.90000000","0.00000000"],["100488.00000000","0.00109000"],["89323.56000000","0.00022000"],["40195.60000000","0.00495000"]],"a":[["111654.45000000","5.71355000"],["111654.61000000","0.00901000"],["111654.82000000","0.00010000"],["111654.83000000","0.22843000"],["111654.84000000","0.18535000"],["111655.98000000","0.00000000"],["111655.99000000","0.00000000"],["111656.00000000","0.00010000"],["111656.01000000","0.29545000"],["111656.02000000","0.00547000"],["111656.68000000","0.00358000"],["111656.79000000","0.00005000"],["111658.01000000","0.00005000"],["111658.20000000","0.00005000"],["111658.34000000","0.00000000"],["111658.35000000","0.00542000"],["111659.70000000","0.00000000"],["111659.72000000","0.00000000"],["111660.01000000","0.00000000"],["111660.52000000","0.00000000"],["111660.53000000","0.00000000"],["111660.55000000","0.00000000"],["111660.56000000","0.00189000"],["111660.57000000","0.08447000"],["111660.73000000","0.00901000"],["111661.69000000","0.04072000"],["111662.16000000","0.00000000"],["111662.17000000","0.00000000"],["111662.43000000","0.04279000"],["111662.79000000","0.00447000"],["111662.94000000","0.40306000"],["111662.99000000","0.00860000"],["111663.35000000","0.01788000"],["111664.13000000","0.57876000"],["111664.14000000","0.00000000"],["111664.17000000","0.00000000"],["111664.20000000","0.00005000"],["111665.92000000","0.08504000"],["111666.35000000","0.35808000"],["111666.36000000","0.15000000"],["111666.50000000","0.00405000"],["111666.66000000","0.00000000"],["111666.85000000","0.03582000"],["111667.98000000","0.43086000"],["111668.30000000","0.06690000"],["111670.65000000","0.04000000"],["111671.72000000","0.00000000"],["111673.13000000","0.00000000"],["111673.15000000","0.00000000"],["111674.87000000","0.32220000"],["111675.13000000","0.00000000"],["111677.37000000","0.00000000"],["111682.30000000","0.00005000"],["111684.20000000","0.13426000"],["111694.24000000","0.02685000"],["111694.40000000","0.00000000"],["111699.05000000","0.00000000"],["111699.25000000","0.00000000"],["111699.49000000","0.45000000"],["111699.83000000","0.02238000"],["111704.83000000","0.00000000"],["111729.15000000","0.00000000"],["111736.68000000","0.00000000"],["111736.70000000","0.00100000"],["111742.03000000","0.02286000"],["111743.94000000","0.00000000"],["111752.61000000","0.00000000"],["111758.64000000","0.02130000"],["111761.58000000","0.00223000"],["111767.99000000","0.00000000"],["111873.53000000","0.00089000"],["111879.99000000","0.00000000"],["111909.08000000","0.03997000"],["111912.24000000","0.03997000"],["111986.98000000","0.07519000"],["112055.52000000","0.00000000"],["113329.27000000","0.00100000"]]}
[2025-10-12T10:57:20.184Z] {"e":"depthUpdate","E":1760266640014,"s":"BTCUSDT","U":77965075199,"u":77965075348,"b":[["111654.44000000","1.59838000"],["111654.43000000","0.00259000"],["111654.42000000","0.01831000"],["111654.09000000","0.10407000"],["111654.05000000","0.01348000"],["111654.00000000","0.00205000"],["111652.90000000","0.00000000"],["111652.89000000","0.00000000"],["111652.00000000","0.00260000"],["111651.77000000","0.00000000"],["111651.46000000","0.00005000"],["111651.45000000","0.29546000"],["111651.17000000","0.00000000"],["111651.16000000","0.00000000"],["111649.42000000","0.00722000"],["111649.22000000","0.00000000"],["111649.21000000","0.04377000"],["111649.05000000","0.00000000"],["111648.86000000","0.03784000"],["111648.85000000","0.00000000"],["111648.00000000","0.00275000"],["111647.93000000","0.04127000"],["111647.52000000","0.00100000"],["111645.65000000","0.00000000"],["111644.53000000","0.00005000"],["111644.06000000","0.00447000"],["111644.03000000","0.00000000"],["111644.00000000","0.00260000"],["111643.41000000","0.00000000"],["111642.72000000","0.00005000"],["111634.76000000","0.07339000"],["111634.75000000","0.00000000"],["111632.55000000","0.00000000"],["111632.53000000","0.05280000"],["111632.49000000","0.04800000"],["111627.48000000","0.32233000"],["111627.08000000","0.06720000"],["111626.30000000","0.00000000"],["111626.25000000","0.14816000"],["111609.07000000","0.00000000"],["111609.01000000","0.00000000"],["111598.02000000","0.00000000"],["111585.50000000","0.00000000"],["111574.06000000","0.00447000"],["111572.18000000","0.01402000"],["111569.51000000","0.04277000"],["111555.46000000","0.04800000"],["111548.68000000","0.06720000"],["111409.08000000","0.02507000"],["111407.18000000","0.02507000"],["111406.31000000","0.02507000"],["111403.34000000","0.02507000"],["109979.62000000","0.00100000"],["108200.00000000","2.43201000"],["100488.00000000","0.00109000"],["89323.56000000","0.00022000"]],"a":[["111654.45000000","5.70521000"],["111658.20000000","0.00000000"],["111666.34000000","0.00043000"],["111666.36000000","0.15000000"],["111666.50000000","0.00405000"],["111669.85000000","0.00100000"],["111674.87000000","0.00000000"],["111676.27000000","0.00000000"],["111685.55000000","0.00000000"],["111685.65000000","0.00005000"],["111692.16000000","0.32215000"],["111700.37000000","0.04800000"],["111702.60000000","0.04800000"],["111710.37000000","0.04097000"],["111736.68000000","0.00000000"],["111736.69000000","0.00000000"],["111736.70000000","0.00000000"],["111737.63000000","0.00100000"],["111737.64000000","0.00100000"],["111743.21000000","0.04097000"],["111746.35000000","0.04097000"],["111749.99000000","0.04097000"],["111760.17000000","0.04097000"],["111764.52000000","0.04097000"],["111771.13000000","0.04097000"],["111771.15000000","0.00000000"],["111773.33000000","0.12966000"],["111774.82000000","0.04097000"],["111776.67000000","0.00000000"],["111777.53000000","0.01402000"],["111784.32000000","0.04097000"],["112051.89000000","0.00000000"],["113329.27000000","0.00100000"]]}
[2025-10-12T10:57:21.183Z] {"e":"depthUpdate","E":1760266641014,"s":"BTCUSDT","U":77965075349,"u":77965075457,"b":[["111654.44000000","2.04792000"],["111654.43000000","0.00125000"],["111654.05000000","0.01353000"],["111649.42000000","0.00727000"],["111649.22000000","0.06355000"],["111649.21000000","0.04377000"],["111649.05000000","0.04009000"],["111648.86000000","0.00000000"],["111648.00000000","0.00275000"],["111647.52000000","0.00000000"],["111644.06000000","0.00452000"],["111644.00000000","0.00260000"],["111642.66000000","0.00100000"],["111634.76000000","0.00139000"],["111629.45000000","0.07200000"],["111627.22000000","0.06720000"],["111627.16000000","0.05760000"],["111613.53000000","1.17613000"],["111610.50000000","0.88994000"],["111604.45000000","0.00000000"],["111602.01000000","0.30212000"],["111582.52000000","0.00000000"],["111572.18000000","0.00000000"],["111559.29000000","0.00000000"],["111549.91000000","0.00000000"],["111548.75000000","0.00000000"],["111548.68000000","0.00000000"],["111547.69000000","0.00000000"],["111546.01000000","0.00000000"],["111535.69000000","0.00000000"],["111528.80000000","0.00196000"],["111511.80000000","0.00000000"],["111402.07000000","0.00000000"],["111325.02000000","0.03997000"],["110531.23000000","0.00239000"],["109979.62000000","0.00100000"],["108100.00000000","17.51856000"],["106000.00000000","32.68600000"],["100488.00000000","0.00109000"],["89323.56000000","0.00022000"]],"a":[["111654.45000000","5.70509000"],["111654.84000000","0.18540000"],["111656.01000000","0.29550000"],["111660.57000000","0.08452000"],["111660.73000000","0.00906000"],["111661.09000000","0.06651000"],["111661.69000000","0.04067000"],["111664.99000000","0.00100000"],["111666.50000000","0.00400000"],["111669.85000000","0.00000000"],["111686.85000000","1.19718000"],["111736.69000000","0.00100000"],["111736.70000000","0.00100000"],["111737.63000000","0.00000000"],["111737.64000000","0.00000000"],["111770.14000000","0.00196000"],["111791.77000000","0.00000000"],["111890.00000000","0.00100000"],["111912.94000000","0.03997000"],["111922.85000000","0.00000000"],["112250.79000000","0.02398000"],["112654.59000000","0.00234000"],["112813.20000000","0.00000000"],["113329.27000000","0.00100000"]]}
[2025-10-12T10:57:22.183Z] {"e":"depthUpdate","E":1760266642014,"s":"BTCUSDT","U":77965075458,"u":77965075522,"b":[["111654.44000000","1.59608000"],["111654.43000000","0.00130000"],["111650.54000000","0.00547000"],["111650.29000000","0.04048000"],["111644.06000000","0.00447000"],["111643.27000000","0.11190000"],["111639.20000000","0.00000000"],["111634.01000000","0.04800000"],["111627.48000000","0.00000000"],["111626.31000000","0.00000000"],["111626.25000000","0.13426000"],["111626.14000000","0.01390000"],["111610.04000000","0.32239000"],["111554.35000000","0.00000000"],["111470.62000000","0.02986000"],["111468.44000000","0.00000000"],["111459.82000000","0.17314000"],["111410.48000000","4.70100000"],["109979.62000000","0.00100000"],["108000.00000000","92.78302000"],["106000.00000000","32.68589000"],["104000.00000000","37.19775000"],["100488.00000000","0.00109000"],["100000.00000000","214.24862000"],["89323.56000000","0.00022000"],["33000.00000000","3.87311000"]],"a":[["111654.45000000","5.70146000"],["111660.57000000","0.08446000"],["111666.34000000","0.00000000"],["111675.30000000","0.32220000"],["111692.16000000","0.00000000"],["111700.40000000","0.00005000"],["111736.68000000","0.00100000"],["111736.70000000","0.00000000"],["111777.53000000","0.01402000"],["111891.12000000","4.84051000"],["112059.27000000","0.55838000"],["112813.20000000","0.00158000"],["113329.27000000","0.00100000"],["116000.00000000","14.11627000"],["120000.00000000","40.80282000"]]}
[2025-10-12T10:57:23.184Z] {"e":"depthUpdate","E":1760266643014,"s":"BTCUSDT","U":77965075523,"u":77965075626,"b":[["111654.44000000","1.58538000"],["111654.43000000","0.00125000"],["111654.42000000","0.00030000"],["111654.41000000","0.00020000"],["111654.29000000","0.00010000"],["111654.28000000","0.00896000"],["111654.27000000","0.00010000"],["111654.05000000","0.01353000"],["111654.00000000","0.00210000"],["111652.21000000","0.00358000"],["111651.45000000","0.29551000"],["111650.54000000","0.00547000"],["111649.42000000","0.00727000"],["111648.30000000","0.01791000"],["111644.53000000","0.00000000"],["111643.27000000","0.00000000"],["111638.22000000","0.11190000"],["111626.24000000","0.00000000"],["111626.14000000","0.00000000"],["111626.10000000","0.01390000"],["111559.74000000","0.00163000"],["111559.73000000","0.00000000"],["111448.19000000","0.00065000"],["111448.01000000","0.00000000"],["111403.09000000","0.00574000"],["111399.28000000","0.00000000"],["111022.72000000","0.00000000"],["111015.35000000","0.89110000"],["110531.23000000","0.00000000"],["109979.62000000","0.00100000"],["108705.33000000","0.00304000"],["100489.00000000","0.00019000"],["100488.00000000","0.00109000"],["89323.56000000","0.00022000"]],"a":[["111654.45000000","5.69967000"],["111654.61000000","0.00901000"],["111654.84000000","0.18540000"],["111656.68000000","0.00358000"],["111658.35000000","0.00547000"],["111659.47000000","0.00722000"],["111660.57000000","0.08446000"],["111660.59000000","0.01796000"],["111660.73000000","0.00005000"],["111661.09000000","0.06646000"],["111661.69000000","0.04062000"],["111662.62000000","0.00000000"],["111662.80000000","0.00010000"],["111762.29000000","0.00000000"],["111777.70000000","0.00187000"],["111895.19000000","0.00000000"],["111910.60000000","0.00079000"],["112654.59000000","0.00000000"],["113329.27000000","0.00100000"]]}
[2025-10-12T10:57:24.184Z] {"e":"depthUpdate","E":1760266644014,"s":"BTCUSDT","U":77965075627,"u":77965075921,"b":[["111654.44000000","0.00661000"],["111654.43000000","0.00100000"],["111654.42000000","0.00025000"],["111654.41000000","0.00000000"],["111654.28000000","0.00921000"],["111654.27000000","0.00020000"],["111654.10000000","0.00000000"],["111654.09000000","0.00010000"],["111654.06000000","0.00020000"],["111654.05000000","0.01353000"],["111653.26000000","0.00010000"],["111651.68000000","0.00000000"],["111651.46000000","0.00000000"],["111651.45000000","0.00000000"],["111650.30000000","0.00010000"],["111650.29000000","0.00010000"],["111649.61000000","0.00155000"],["111649.42000000","0.00722000"],["111649.23000000","0.00000000"],["111649.22000000","0.00000000"],["111649.21000000","0.00005000"],["111649.05000000","0.00000000"],["111648.57000000","0.00000000"],["111648.52000000","0.00000000"],["111648.31000000","0.00005000"],["111648.30000000","0.01796000"],["111648.00000000","0.00265000"],["111647.93000000","0.00000000"],["111647.33000000","0.04614000"],["111646.79000000","0.10628000"],["111646.06000000","0.00000000"],["111646.00000000","0.00265000"],["111645.14000000","0.00000000"],["111644.57000000","0.00000000"],["111644.06000000","0.00452000"],["111644.00000000","0.00265000"],["111642.99000000","0.29543000"],["111642.72000000","0.00000000"],["111642.66000000","0.00000000"],["111641.06000000","0.16046000"],["111640.18000000","0.00000000"],["111639.92000000","0.00000000"],["111639.87000000","0.01759000"],["111639.25000000","0.04625000"],["111638.92000000","0.23965000"],["111635.22000000","0.00000000"],["111633.17000000","0.00000000"],["111632.88000000","0.00000000"],["111632.59000000","0.40306000"],["111631.57000000","0.08000000"],["111630.11000000","0.00000000"],["111629.56000000","0.48000000"],["111628.91000000","0.00000000"],["111627.54000000","0.00000000"],["111626.26000000","0.00000000"],["111626.10000000","0.00000000"],["111622.46000000","0.35807000"],["111622.12000000","0.00000000"],["111621.84000000","0.00000000"],["111621.81000000","0.55306000"],["111613.90000000","0.08504000"],["111603.95000000","0.32240000"],["111602.01000000","0.00000000"],["111600.01000000","0.00000000"],["111596.23000000","0.30213000"],["111593.55000000","0.17909000"],["111566.14000000","0.40306000"],["111554.21000000","0.91994000"],["111551.70000000","1.25396000"],["111396.10000000","0.92231000"],["109979.62000000","0.00100000"],["108100.00000000","17.51874000"],["102722.08000000","0.00000000"],["100488.00000000","0.00109000"],["89323.56000000","0.00022000"],["60000.00000000","53.14032000"]],"a":[["111654.45000000","6.39148000"],["111654.60000000","0.00080000"],["111654.61000000","0.00911000"],["111654.77000000","0.00000000"],["111654.78000000","0.04094000"],["111654.82000000","0.00000000"],["111654.83000000","0.22833000"],["111654.84000000","0.18540000"],["111655.89000000","0.00000000"],["111655.90000000","0.03977000"],["111656.00000000","0.00000000"],["111656.01000000","0.29545000"],["111656.02000000","0.00547000"],["111656.68000000","0.00363000"],["111657.26000000","0.04005000"],["111658.35000000","0.00547000"],["111659.10000000","0.40306000"],["111659.47000000","0.00717000"],["111660.56000000","0.00184000"],["111660.57000000","0.04482000"],["111660.59000000","0.01791000"],["111660.96000000","0.00000000"],["111661.69000000","0.00005000"],["111663.35000000","0.01793000"],["111664.13000000","0.43034000"],["111664.20000000","0.00000000"],["111664.99000000","0.00000000"],["111665.92000000","0.00000000"],["111666.36000000","0.15000000"],["111670.07000000","0.00000000"],["111670.56000000","0.32221000"],["111670.65000000","0.00000000"],["111673.15000000","1.25396000"],["111675.47000000","0.00000000"],["111677.15000000","0.00005000"],["111677.37000000","0.00000000"],["111685.76000000","0.00000000"],["111688.65000000","0.00000000"],["111701.35000000","0.31330000"],["111705.33000000","2.05989000"],["111740.69000000","0.02130000"],["111748.19000000","0.06015000"],["111752.09000000","0.00480000"],["111758.64000000","0.00000000"],["111760.46000000","0.00000000"],["111761.40000000","0.22377000"],["111761.59000000","0.00000000"],["111770.33000000","0.00000000"],["111772.09000000","0.00000000"],["111777.53000000","0.00000000"],["111793.24000000","0.00000000"],["112048.20000000","0.00000000"],["112059.27000000","0.00000000"],["112186.39000000","0.09592000"],["112195.60000000","0.02398000"],["112251.07000000","0.02398000"],["113329.27000000","0.00100000"],["146260.00000000","0.00004000"]]}
[2025-10-12T10:57:25.184Z] {"e":"depthUpdate","E":1760266645014,"s":"BTCUSDT","U":77965075922,"u":77965076098,"b":[["111654.44000000","0.00599000"],["111654.43000000","0.00100000"],["111654.08000000","0.03024000"],["111654.05000000","0.01353000"],["111653.67000000","0.00000000"],["111653.47000000","0.00005000"],["111653.26000000","0.00000000"],["111653.00000000","0.00000000"],["111652.98000000","0.00000000"],["111652.79000000","0.00000000"],["111650.54000000","0.00542000"],["111650.30000000","0.00000000"],["111650.29000000","0.00000000"],["111649.42000000","0.00727000"],["111648.32000000","0.00010000"],["111648.31000000","0.12178000"],["111648.30000000","0.01801000"],["111648.00000000","0.00270000"],["111647.34000000","0.00000000"],["111647.33000000","0.04619000"],["111646.79000000","0.00000000"],["111645.23000000","0.17011000"],["111645.22000000","0.29543000"],["111643.02000000","0.00000000"],["111643.01000000","0.00000000"],["111643.00000000","0.19694000"],["111642.99000000","0.00000000"],["111641.06000000","0.00000000"],["111639.92000000","0.07613000"],["111639.87000000","0.00000000"],["111638.25000000","0.00000000"],["111634.82000000","0.00100000"],["111633.47000000","0.00000000"],["111631.37000000","0.04000000"],["111589.08000000","0.00005000"],["111410.48000000","0.00000000"],["109979.62000000","0.00100000"],["100488.00000000","0.00109000"],["89323.56000000","0.00022000"],["60000.00000000","53.14022000"]],"a":[["111654.45000000","6.24180000"],["111656.68000000","0.00368000"],["111657.15000000","0.00100000"],["111662.99000000","0.00865000"],["111663.16000000","0.08504000"],["111663.35000000","0.01788000"],["111664.78000000","0.00087000"],["111665.94000000","0.00088000"],["111666.36000000","0.15000000"],["111666.50000000","0.00400000"],["111672.78000000","0.00799000"],["111674.71000000","0.00044000"],["111675.19000000","0.13877000"],["111677.37000000","0.00000000"],["111678.82000000","0.00000000"],["111701.10000000","0.13433000"],["111701.35000000","0.31330000"],["111760.46000000","0.00000000"],["111760.58000000","0.00000000"],["111760.64000000","0.22377000"],["111761.40000000","0.00000000"],["111761.73000000","0.00187000"],["111762.66000000","0.13433000"],["111777.70000000","0.00000000"],["111891.12000000","0.00000000"],["111894.62000000","0.00079000"],["111910.60000000","0.00000000"],["113329.27000000","0.00100000"]]}
[2025-10-12T10:57:26.184Z] {"e":"depthUpdate","E":1760266646014,"s":"BTCUSDT","U":77965076099,"u":77965076489,"b":[["111654.44000000","0.00000000"],["111654.43000000","0.00000000"],["111654.42000000","0.00000000"],["111654.36000000","0.00000000"],["111654.29000000","0.00000000"],["111654.28000000","0.01041000"],["111654.27000000","0.00110000"],["111654.08000000","0.03034000"],["111654.07000000","0.00290000"],["111654.06000000","0.00030000"],["111654.04000000","0.00010000"],["111653.99000000","0.00010000"],["111653.67000000","0.00000000"],["111653.47000000","0.00000000"],["111652.98000000","0.00000000"],["111652.35000000","0.00000000"],["111651.67000000","0.00010000"],["111649.42000000","0.00722000"],["111647.34000000","0.00005000"],["111647.33000000","0.00005000"],["111646.78000000","0.05709000"],["111646.06000000","0.00000000"],["111645.23000000","0.00000000"],["111645.22000000","0.00000000"],["111644.06000000","0.00452000"],["111644.05000000","0.00005000"],["111644.00000000","0.00265000"],["111642.93000000","0.03951000"],["111642.66000000","0.29543000"],["111641.08000000","0.00000000"],["111641.05000000","0.00000000"],["111639.70000000","0.00000000"],["111639.25000000","0.04625000"],["111638.01000000","0.00000000"],["111637.10000000","0.17903000"],["111634.82000000","0.00000000"],["111633.09000000","0.04000000"],["111631.57000000","0.00000000"],["111630.16000000","0.08000000"],["111630.10000000","0.00000000"],["111628.68000000","0.00447000"],["111601.28000000","0.00000000"],["111598.02000000","0.00005000"],["111589.08000000","0.00000000"],["111562.04000000","0.00000000"],["111556.01000000","0.00223000"],["111542.01000000","0.00000000"],["111536.02000000","0.00223000"],["111425.83000000","0.00000000"],["111424.28000000","0.00089000"],["111404.84000000","4.77307000"],["111311.53000000","0.00000000"],["111310.62000000","0.00000000"],["111299.04000000","0.05996000"],["111297.13000000","0.05996000"],["111253.99000000","0.45000000"],["109979.62000000","0.00000000"],["109695.42000000","0.00091000"],["108305.00000000","0.00010000"],["100489.00000000","0.00024000"],["100488.00000000","0.00109000"],["100364.63000000","0.00043000"],["89323.56000000","0.00000000"],["89323.43000000","0.00022000"],["42000.00000000","1.49196000"]],"a":[["111654.29000000","8.20725000"],["111654.30000000","0.00000000"],["111654.33000000","0.00000000"],["111654.37000000","0.00010000"],["111654.43000000","0.00000000"],["111654.44000000","2.28868000"],["111654.45000000","0.56133000"],["111654.83000000","0.00010000"],["111655.90000000","0.03977000"],["111656.00000000","0.00447000"],["111658.35000000","0.00542000"],["111660.03000000","0.00000000"],["111660.36000000","0.00000000"],["111660.56000000","0.35992000"],["111660.59000000","0.01796000"],["111661.02000000","0.00000000"],["111662.43000000","0.04274000"],["111662.79000000","0.00000000"],["111663.35000000","0.01788000"],["111666.35000000","0.00000000"],["111670.49000000","0.00000000"],["111679.39000000","0.00010000"],["111701.35000000","0.00000000"],["111727.51000000","0.00223000"],["111739.68000000","0.00223000"],["111742.73000000","0.00000000"],["111754.29000000","0.00000000"],["111760.46000000","0.00000000"],["111760.52000000","0.00000000"],["111760.53000000","0.00000000"],["111761.58000000","0.00000000"],["111761.72000000","0.00223000"],["111781.45000000","0.99252000"],["111792.06000000","0.16094000"],["111792.07000000","0.00000000"],["111839.01000000","0.00089000"],["111851.23000000","0.00089000"],["111869.99000000","0.00000000"],["111873.53000000","0.00089000"],["111881.68000000","0.00000000"],["111889.59000000","4.71348000"],["112044.51000000","0.00000000"],["112131.26000000","0.00439000"],["112715.72000000","0.00000000"],["113329.27000000","0.00000000"]]}
[2025-10-12T10:57:27.186Z] {"e":"depthUpdate","E":1760266647014,"s":"BTCUSDT","U":77965076490,"u":77965079594,"b":[["111654.28000000","0.00000000"],["111654.27000000","0.00000000"],["111654.26000000","0.00000000"],["111654.09000000","0.00000000"],["111654.08000000","0.00000000"],["111654.07000000","0.00000000"],["111654.06000000","0.00000000"],["111654.05000000","0.00000000"],["111654.04000000","0.00000000"],["111654.00000000","0.00000000"],["111653.99000000","0.00000000"],["111653.47000000","0.00000000"],["111652.76000000","0.00000000"],["111652.23000000","0.00000000"],["111652.22000000","0.00000000"],["111652.21000000","0.00000000"],["111652.15000000","0.00000000"],["111652.14000000","0.00000000"],["111652.00000000","0.00000000"],["111651.67000000","0.00000000"],["111651.54000000","0.00000000"],["111651.29000000","0.00000000"],["111651.28000000","0.00000000"],["111651.25000000","0.00000000"],["111650.54000000","0.00000000"],["111650.53000000","0.00000000"],["111650.00000000","0.00000000"],["111649.61000000","0.00000000"],["111649.42000000","0.00000000"],["111649.21000000","0.00000000"],["111649.20000000","0.00000000"],["111649.02000000","0.00000000"],["111648.80000000","0.00000000"],["111648.79000000","0.00000000"],["111648.78000000","0.00000000"],["111648.32000000","0.00000000"],["111648.31000000","0.00000000"],["111648.30000000","0.00000000"],["111648.29000000","0.00000000"],["111648.28000000","0.00000000"],["111648.00000000","0.00000000"],["111647.99000000","0.00000000"],["111647.34000000","0.00000000"],["111647.33000000","0.00000000"],["111647.11000000","0.00000000"],["111646.91000000","0.00000000"],["111646.79000000","0.00000000"],["111646.78000000","0.00000000"],["111646.45000000","0.00000000"],["111646.20000000","0.00000000"],["111646.04000000","0.00000000"],["111646.00000000","0.00000000"],["111645.99000000","0.00000000"],["111645.89000000","0.00000000"],["111645.45000000","0.00000000"],["111645.42000000","0.00000000"],["111645.41000000","0.00000000"],["111645.39000000","0.00000000"],["111644.89000000","0.00000000"],["111644.86000000","0.00000000"],["111644.85000000","0.00000000"],["111644.80000000","0.00000000"],["111644.39000000","0.00000000"],["111644.06000000","0.00000000"],["111644.05000000","0.00000000"],["111644.00000000","0.00000000"],["111643.81000000","0.00000000"],["111643.11000000","0.00000000"],["111643.03000000","0.00000000"],["111643.02000000","0.00000000"],["111643.01000000","0.00000000"],["111643.00000000","0.00000000"],["111642.94000000","0.00000000"],["111642.93000000","0.00000000"],["111642.77000000","0.00000000"],["111642.66000000","0.00000000"],["111642.10000000","0.00000000"],["111642.00000000","0.00000000"],["111641.97000000","0.00000000"],["111641.96000000","0.00000000"],["111641.92000000","0.00000000"],["111641.22000000","0.00000000"],["111640.89000000","0.00000000"],["111640.88000000","0.00000000"],["111640.64000000","0.00000000"],["111640.00000000","0.00000000"],["111639.92000000","0.00000000"],["111639.79000000","0.00000000"],["111639.78000000","0.00000000"],["111639.67000000","0.00000000"],["111639.66000000","0.00000000"],["111639.64000000","0.00000000"],["111639.25000000","0.00000000"],["111639.24000000","0.00000000"],["111638.93000000","0.00000000"],["111638.92000000","0.70345000"],["111638.91000000","0.00120000"],["111638.90000000","0.00020000"],["111638.85000000","0.00010000"],["111638.84000000","0.00005000"],["111638.75000000","0.00114000"],["111638.74000000","0.00020000"],["111638.67000000","0.00000000"],["111638.66000000","0.00000000"],["111638.23000000","0.00000000"],["111638.22000000","0.00000000"],["111638.06000000","0.00000000"],["111638.00000000","0.00270000"],["111637.99000000","0.00010000"],["111637.80000000","0.00000000"],["111637.15000000","0.00000000"],["111637.14000000","0.00000000"],["111637.13000000","0.00000000"],["111637.10000000","0.00000000"],["111637.09000000","0.00000000"],["111636.90000000","0.00000000"],["111636.88000000","0.07905000"],["111636.87000000","0.00000000"],["111636.86000000","0.00010000"],["111636.78000000","0.00000000"],["111636.60000000","0.00000000"],["111636.59000000","0.00000000"],["111636.58000000","0.00000000"],["111636.52000000","0.00000000"],["111636.45000000","0.00010000"],["111636.44000000","0.01806000"],["111636.01000000","0.00000000"],["111636.00000000","0.00265000"],["111635.76000000","0.00000000"],["111635.71000000","0.00005000"],["111635.57000000","0.00010000"],["111635.56000000","0.05437000"],["111635.06000000","0.00000000"],["111635.04000000","0.00000000"],["111634.91000000","0.00000000"],["111634.76000000","0.00000000"],["111634.31000000","0.00000000"],["111634.30000000","0.00000000"],["111634.29000000","0.00005000"],["111634.13000000","0.00000000"],["111634.02000000","0.00010000"],["111634.01000000","0.04810000"],["111634.00000000","0.00265000"],["111633.79000000","0.00155000"],["111633.78000000","0.00000000"],["111633.67000000","0.00005000"],["111633.66000000","0.04805000"],["111633.63000000","0.00000000"],["111633.09000000","0.00000000"],["111633.00000000","0.00005000"],["111632.87000000","0.00000000"],["111632.86000000","0.29648000"],["111632.59000000","0.00000000"],["111632.58000000","0.05770000"],["111632.53000000","0.05285000"],["111632.49000000","0.04805000"],["111632.45000000","0.00000000"],["111632.39000000","0.04805000"],["111632.31000000","0.00000000"],["111632.01000000","0.00000000"],["111632.00000000","0.00270000"],["111631.89000000","0.03951000"],["111631.85000000","0.06023000"],["111631.66000000","0.29546000"],["111631.37000000","0.00000000"],["111631.14000000","0.00000000"],["111630.87000000","0.00000000"],["111630.77000000","0.03974000"],["111630.54000000","0.00000000"],["111630.48000000","0.00000000"],["111630.16000000","0.00000000"],["111630.13000000","0.00000000"],["111630.12000000","0.00000000"],["111630.09000000","0.45020000"],["111630.01000000","0.00000000"],["111630.00000000","0.00354000"],["111629.99000000","0.00000000"],["111629.85000000","0.00000000"],["111629.83000000","0.02693000"],["111629.57000000","0.00000000"],["111629.56000000","0.00000000"],["111629.45000000","0.07200000"],["111629.31000000","0.00000000"],["111628.68000000","0.00000000"],["111628.67000000","0.06240000"],["111628.58000000","0.00000000"],["111628.56000000","0.00000000"],["111628.51000000","0.00000000"],["111628.43000000","0.00000000"],["111628.37000000","0.00000000"],["111627.83000000","0.29476000"],["111627.82000000","0.00000000"],["111627.76000000","0.00150000"],["111627.55000000","0.00000000"],["111627.53000000","0.00000000"],["111627.23000000","0.00000000"],["111626.86000000","0.00000000"],["111626.25000000","0.00000000"],["111626.15000000","0.00332000"],["111625.86000000","0.00000000"],["111625.81000000","0.00072000"],["111625.73000000","0.00070000"],["111625.66000000","0.00000000"],["111624.41000000","0.07614000"],["111624.09000000","0.00000000"],["111624.01000000","0.00000000"],["111623.90000000","0.00062000"],["111623.76000000","0.00000000"],["111623.41000000","0.00000000"],["111622.86000000","0.00000000"],["111622.51000000","0.17905000"],["111622.46000000","0.00000000"],["111622.45000000","0.00000000"],["111622.29000000","0.00000000"],["111622.17000000","0.55559000"],["111622.16000000","0.00000000"],["111622.01000000","0.00000000"],["111621.83000000","0.00000000"],["111621.82000000","0.00000000"],["111621.81000000","0.40306000"],["111621.79000000","0.00000000"],["111621.75000000","0.01264000"],["111621.46000000","0.00000000"],["111620.69000000","0.04000000"],["111620.26000000","0.00000000"],["111620.25000000","0.00005000"],["111620.24000000","0.00007000"],["111620.05000000","0.00000000"],["111620.04000000","0.00000000"],["111619.81000000","0.00000000"],["111619.44000000","0.00069000"],["111618.65000000","0.00005000"],["111617.94000000","0.00000000"],["111617.64000000","0.00000000"],["111617.46000000","0.28000000"],["111617.36000000","0.34000000"],["111617.25000000","0.00000000"],["111617.24000000","0.00000000"],["111616.68000000","0.00000000"],["111616.65000000","0.00000000"],["111616.57000000","0.00000000"],["111616.56000000","0.00000000"],["111616.38000000","0.89232000"],["111616.37000000","0.40306000"],["111616.36000000","0.00000000"],["111616.35000000","0.00000000"],["111615.31000000","0.04477000"],["111614.80000000","0.00300000"],["111614.16000000","0.00000000"],["111613.87000000","0.00000000"],["111613.55000000","0.00000000"],["111612.21000000","0.01164000"],["111612.02000000","0.00447000"],["111612.01000000","0.05996000"],["111611.26000000","0.04800000"],["111611.24000000","0.00000000"],["111610.68000000","0.01390000"],["111610.50000000","0.56756000"],["111610.20000000","0.35809000"],["111610.04000000","0.00000000"],["111610.02000000","0.08504000"],["111609.77000000","0.13426000"],["111609.66000000","0.15000000"],["111609.42000000","0.00000000"],["111608.60000000","0.00005000"],["111607.68000000","0.01829000"],["111606.83000000","0.00000000"],["111606.81000000","0.45354000"],["111606.57000000","0.00179000"],["111606.39000000","0.00000000"],["111604.90000000","0.02597000"],["111604.77000000","0.08000000"],["111604.62000000","0.00000000"],["111604.13000000","0.13426000"],["111603.07000000","0.22377000"],["111602.47000000","0.02125000"],["111600.62000000","0.08504000"],["111600.01000000","0.05373000"],["111599.92000000","0.00269000"],["111599.10000000","0.00000000"],["111598.49000000","0.00000000"],["111598.21000000","0.00000000"],["111598.20000000","0.00009000"],["111597.85000000","0.03827000"],["111597.75000000","0.00000000"],["111597.70000000","0.32242000"],["111597.56000000","0.13426000"],["111596.44000000","0.32242000"],["111596.23000000","0.00000000"],["111595.98000000","0.00018000"],["111595.69000000","0.00000000"],["111594.98000000","0.00100000"],["111594.85000000","0.00000000"],["111593.79000000","0.00000000"],["111593.21000000","0.00000000"],["111592.83000000","0.00000000"],["111592.17000000","0.00000000"],["111591.59000000","0.06621000"],["111590.91000000","0.32244000"],["111590.75000000","0.00000000"],["111590.06000000","0.02126000"],["111589.77000000","0.08000000"],["111589.51000000","1.29068000"],["111589.08000000","0.00005000"],["111588.55000000","0.00000000"],["111588.54000000","0.00000000"],["111587.81000000","0.00009000"],["111587.25000000","0.00000000"],["111584.61000000","0.00005000"],["111583.97000000","0.00000000"],["111583.30000000","0.00000000"],["111582.81000000","0.90023000"],["111582.78000000","0.00390000"],["111582.30000000","0.30218000"],["111581.67000000","0.00000000"],["111580.09000000","0.04375000"],["111579.41000000","0.63890000"],["111578.31000000","0.02597000"],["111577.86000000","0.08504000"],["111577.83000000","0.00000000"],["111576.76000000","0.00000000"],["111574.42000000","0.00000000"],["111572.30000000","0.00000000"],["111571.18000000","0.00000000"],["111569.51000000","0.00000000"],["111569.09000000","0.00000000"],["111566.53000000","0.00000000"],["111565.27000000","0.00000000"],["111565.04000000","0.00000000"],["111564.75000000","0.00632000"],["111563.71000000","0.00000000"],["111563.00000000","0.00000000"],["111562.86000000","0.00000000"],["111560.82000000","0.00633000"],["111560.44000000","0.00660000"],["111559.74000000","0.00000000"],["111559.44000000","0.40306000"],["111558.95000000","0.00000000"],["111557.28000000","0.00000000"],["111556.88000000","0.00631000"],["111556.01000000","0.00000000"],["111554.89000000","0.00005000"],["111554.29000000","0.09600000"],["111554.21000000","0.55767000"],["111552.60000000","0.00000000"],["111552.59000000","0.00000000"],["111552.46000000","0.00090000"],["111552.15000000","0.00000000"],["111551.76000000","0.00000000"],["111551.66000000","0.00000000"],["111551.48000000","0.00000000"],["111550.54000000","0.04283000"],["111550.18000000","0.00000000"],["111549.06000000","0.21471000"],["111548.57000000","0.00000000"],["111548.04000000","0.02417000"],["111547.24000000","0.13426000"],["111546.91000000","0.00000000"],["111545.00000000","1.25396000"],["111544.43000000","0.02507000"],["111544.42000000","0.00000000"],["111544.01000000","0.00163000"],["111543.94000000","0.00000000"],["111543.31000000","0.00000000"],["111542.24000000","0.00000000"],["111542.22000000","0.02417000"],["111541.61000000","0.20072000"],["111540.70000000","0.00223000"],["111540.17000000","0.02507000"],["111539.11000000","0.00000000"],["111539.01000000","0.00000000"],["111538.99000000","0.00000000"],["111537.94000000","0.00000000"],["111536.12000000","0.11501000"],["111536.02000000","0.00000000"],["111536.01000000","0.00000000"],["111533.14000000","0.00000000"],["111532.84000000","0.00000000"],["111530.84000000","0.02462000"],["111530.19000000","0.00000000"],["111529.65000000","0.02507000"],["111529.47000000","0.00000000"],["111529.45000000","0.02072000"],["111527.12000000","0.34629000"],["111524.53000000","0.00000000"],["111523.20000000","0.00000000"],["111522.97000000","0.00000000"],["111522.69000000","0.02507000"],["111521.30000000","0.00000000"],["111520.52000000","0.00223000"],["111519.31000000","0.02507000"],["111519.17000000","0.15986000"],["111517.19000000","0.09759000"],["111516.45000000","0.09845000"],["111516.39000000","0.02597000"],["111512.66000000","0.00000000"],["111512.52000000","0.00006000"],["111512.48000000","0.02507000"],["111510.79000000","0.02507000"],["111510.27000000","0.07807000"],["111510.13000000","0.00000000"],["111507.75000000","0.02507000"],["111506.10000000","0.02507000"],["111499.58000000","0.00000000"],["111498.53000000","0.22173000"],["111496.58000000","0.44787000"],["111493.46000000","0.08901000"],["111491.51000000","0.08594000"],["111491.11000000","0.01236000"],["111490.30000000","0.00000000"],["111490.05000000","0.00000000"],["111489.91000000","0.00000000"],["111488.42000000","0.00000000"],["111488.27000000","0.02597000"],["111487.95000000","0.00000000"],["111487.11000000","0.00000000"],["111485.90000000","0.00000000"],["111483.77000000","0.00000000"],["111477.06000000","0.01086000"],["111476.74000000","0.09894000"],["111476.25000000","0.00000000"],["111475.05000000","0.02597000"],["111474.35000000","0.00000000"],["111473.01000000","0.00000000"],["111472.19000000","0.04947000"],["111465.63000000","0.00000000"],["111460.66000000","0.00000000"],["111460.07000000","0.19686000"],["111459.82000000","0.00000000"],["111459.22000000","0.00000000"],["111458.52000000","0.02597000"],["111458.47000000","0.02597000"],["111448.19000000","0.00000000"],["111444.75000000","0.18261000"],["111444.65000000","0.00000000"],["111442.35000000","0.99540000"],["111442.01000000","0.00065000"],["111438.69000000","0.17314000"],["111438.61000000","0.00000000"],["111438.24000000","0.08594000"],["111436.07000000","0.08594000"],["111436.02000000","0.08594000"],["111434.21000000","0.08594000"],["111433.88000000","0.08594000"],["111433.70000000","0.08594000"],["111432.30000000","0.05430000"],["111429.21000000","0.00007000"],["111429.02000000","0.00089000"],["111424.28000000","0.00000000"],["111416.34000000","0.00000000"],["111407.19000000","0.00089000"],["111404.42000000","0.00000000"],["111389.18000000","0.00000000"],["111384.84000000","0.00000000"],["111380.34000000","0.00000000"],["111374.48000000","0.00000000"],["111373.30000000","0.00467000"],["111372.02000000","0.89744000"],["111367.84000000","0.00000000"],["111365.93000000","0.01701000"],["111357.62000000","0.01701000"],["111354.28000000","0.00000000"],["111351.63000000","0.00000000"],["111349.31000000","0.01701000"],["111348.54000000","0.00000000"],["111346.25000000","0.00000000"],["111345.13000000","0.00000000"],["111343.44000000","0.00000000"],["111342.97000000","0.00000000"],["111342.15000000","0.00000000"],["111341.99000000","0.00000000"],["111339.60000000","0.00000000"],["111339.11000000","0.00000000"],["111338.25000000","0.00007000"],["111337.50000000","0.94765000"],["111336.49000000","0.00000000"],["111335.96000000","0.00000000"],["111335.14000000","0.00000000"],["111334.81000000","0.00010000"],["111333.32000000","0.00000000"],["111333.25000000","0.00000000"],["111332.55000000","0.00000000"],["111331.67000000","0.00000000"],["111330.93000000","0.00000000"],["111330.68000000","0.00163000"],["111330.09000000","0.00000000"],["111330.03000000","0.00000000"],["111329.23000000","0.00010000"],["111328.86000000","0.00009000"],["111327.93000000","0.00000000"],["111327.80000000","0.00000000"],["111327.35000000","0.00000000"],["111327.09000000","0.00000000"],["111326.08000000","0.00000000"],["111325.31000000","0.00000000"],["111324.97000000","0.00000000"],["111324.09000000","0.00000000"],["111323.65000000","0.00010000"],["111322.62000000","0.00000000"],["111321.15000000","0.02597000"],["111319.10000000","0.02597000"],["111318.07000000","0.00000000"],["111306.50000000","0.03672000"],["111305.71000000","0.03672000"],["111302.17000000","0.02686000"],["111300.69000000","0.03672000"],["111300.14000000","0.00000000"],["111300.00000000","0.30877000"],["111299.70000000","0.03672000"],["111299.13000000","0.03672000"],["111298.99000000","0.02686000"],["111298.76000000","0.00000000"],["111298.64000000","0.03672000"],["111298.32000000","0.03672000"],["111297.65000000","0.03672000"],["111296.41000000","0.02686000"],["111293.17000000","0.00000000"],["111292.96000000","0.00000000"],["111292.52000000","0.02686000"],["111291.60000000","0.05995000"],["111290.73000000","0.05995000"],["111272.78000000","0.22084000"],["111259.26000000","0.21862000"],["111214.18000000","0.02769000"],["111200.65000000","0.00000000"],["111196.56000000","0.00000000"],["111189.84000000","0.00000000"],["111170.43000000","0.03672000"],["111163.97000000","0.03672000"],["111158.02000000","0.03672000"],["111155.31000000","0.00000000"],["111151.51000000","0.03946000"],["111015.35000000","0.00000000"],["110959.99000000","0.00135000"],["109979.46000000","0.00000000"],["109964.33000000","0.00100000"],["108100.00000000","17.51892000"],["106000.00000000","32.68589000"],["100488.00000000","0.00099000"],["100483.47000000","0.00019000"],["100474.00000000","0.00010000"],["89323.43000000","0.00000000"],["89319.04000000","0.00000000"],["89311.14000000","0.00022000"],["78156.65000000","0.00000000"],["78152.03000000","0.00000000"],["78147.41000000","0.00000000"],["40195.54000000","0.00015000"],["33000.00000000","3.87311000"]],"a":[["111638.93000000","8.30876000"],["111638.99000000","0.00000000"],["111639.01000000","0.00010000"],["111639.10000000","0.00080000"],["111639.59000000","0.00010000"],["111639.60000000","0.10046000"],["111639.61000000","0.29554000"],["111639.67000000","0.00000000"],["111639.79000000","0.00000000"],["111640.01000000","0.00000000"],["111640.04000000","0.00010000"],["111640.05000000","0.04054000"],["111641.40000000","0.00010000"],["111641.41000000","0.06656000"],["111641.72000000","0.00005000"],["111641.73000000","0.02693000"],["111642.01000000","0.00000000"],["111642.72000000","0.00005000"],["111643.03000000","0.00000000"],["111644.01000000","0.00000000"],["111644.07000000","0.00000000"],["111646.01000000","0.00000000"],["111646.21000000","0.00000000"],["111646.44000000","0.08509000"],["111646.46000000","0.00000000"],["111647.19000000","0.00005000"],["111648.01000000","0.00000000"],["111648.30000000","0.44980000"],["111648.31000000","0.52853000"],["111648.32000000","0.00000000"],["111648.33000000","0.00000000"],["111648.37000000","0.00000000"],["111648.39000000","0.00000000"],["111648.40000000","0.00000000"],["111648.78000000","0.00000000"],["111648.79000000","0.00000000"],["111648.80000000","0.00000000"],["111648.81000000","0.30595000"],["111648.86000000","0.04005000"],["111648.89000000","0.00000000"],["111648.90000000","0.00000000"],["111649.03000000","0.45020000"],["111649.12000000","0.00184000"],["111649.17000000","0.00000000"],["111649.21000000","0.00000000"],["111649.22000000","0.00000000"],["111649.26000000","0.00087000"],["111649.33000000","0.00000000"],["111649.40000000","0.00000000"],["111649.41000000","0.40306000"],["111649.42000000","0.00000000"],["111649.43000000","0.04007000"],["111649.62000000","0.00000000"],["111649.98000000","0.00000000"],["111650.00000000","0.00000000"],["111650.01000000","0.04007000"],["111650.09000000","0.00061000"],["111650.52000000","0.00000000"],["111650.53000000","0.15000000"],["111650.54000000","0.00000000"],["111650.55000000","0.49002000"],["111650.61000000","0.00000000"],["111650.76000000","0.00000000"],["111651.23000000","0.00000000"],["111651.25000000","0.00000000"],["111651.26000000","0.00000000"],["111651.27000000","0.00000000"],["111651.29000000","0.00000000"],["111651.30000000","0.04007000"],["111651.36000000","0.00000000"],["111651.55000000","0.00000000"],["111651.66000000","0.00005000"],["111652.01000000","0.00000000"],["111652.15000000","0.00000000"],["111652.22000000","0.00000000"],["111652.23000000","0.00000000"],["111652.24000000","0.00000000"],["111652.46000000","0.00000000"],["111652.77000000","0.00000000"],["111652.87000000","0.00010000"],["111653.47000000","0.25463000"],["111653.48000000","0.40306000"],["111653.68000000","0.13433000"],["111653.91000000","0.00000000"],["111653.98000000","0.00000000"],["111654.00000000","0.00000000"],["111654.01000000","0.00000000"],["111654.05000000","0.00000000"],["111654.06000000","0.00000000"],["111654.07000000","0.00000000"],["111654.08000000","0.00000000"],["111654.09000000","0.00000000"],["111654.10000000","0.00000000"],["111654.26000000","0.00000000"],["111654.27000000","0.00000000"],["111654.28000000","0.00000000"],["111654.29000000","0.04033000"],["111654.37000000","0.00000000"],["111654.40000000","0.00000000"],["111654.44000000","0.00000000"],["111654.45000000","0.04735000"],["111654.53000000","0.00000000"],["111654.60000000","0.00000000"],["111654.61000000","0.00901000"],["111654.78000000","0.00000000"],["111654.83000000","0.00000000"],["111654.84000000","0.01348000"],["111655.00000000","0.00675000"],["111655.50000000","0.00400000"],["111655.68000000","0.00000000"],["111655.89000000","0.35809000"],["111655.90000000","0.00000000"],["111655.97000000","0.00007000"],["111656.00000000","0.81035000"],["111656.01000000","0.00000000"],["111656.02000000","0.00547000"],["111656.09000000","0.01014000"],["111656.13000000","0.11195000"],["111656.68000000","0.00363000"],["111656.79000000","0.00000000"],["111657.15000000","0.00000000"],["111657.25000000","0.00000000"],["111657.26000000","0.00799000"],["111657.31000000","0.14000000"],["111657.35000000","0.00000000"],["111657.42000000","0.04800000"],["111657.50000000","0.04800000"],["111657.89000000","0.00000000"],["111657.91000000","0.48000000"],["111658.35000000","0.00537000"],["111658.39000000","0.00005000"],["111658.41000000","0.00007000"],["111658.45000000","0.00010000"],["111658.61000000","0.32225000"],["111658.85000000","0.00005000"],["111659.07000000","0.00000000"],["111659.08000000","0.00000000"],["111659.09000000","1.25396000"],["111659.14000000","0.00000000"],["111659.19000000","0.00044000"],["111659.47000000","0.00717000"],["111659.80000000","0.00000000"],["111659.87000000","0.00034000"],["111659.88000000","0.05927000"],["111660.30000000","0.00000000"],["111660.56000000","0.00000000"],["111660.57000000","0.04477000"],["111660.59000000","0.01791000"],["111660.73000000","0.00000000"],["111661.08000000","0.00000000"],["111661.09000000","0.00000000"],["111661.48000000","0.00005000"],["111661.69000000","0.00000000"],["111662.43000000","0.00000000"],["111662.48000000","1.41362000"],["111662.49000000","1.25396000"],["111662.75000000","0.00010000"],["111662.80000000","0.00000000"],["111662.99000000","0.00000000"],["111663.07000000","0.04800000"],["111663.32000000","0.00000000"],["111663.35000000","0.01788000"],["111664.05000000","0.00005000"],["111664.11000000","0.00000000"],["111664.13000000","0.00000000"],["111664.71000000","0.32223000"],["111664.78000000","0.00000000"],["111665.34000000","0.18876000"],["111665.41000000","0.08504000"],["111665.63000000","0.01014000"],["111665.84000000","0.00000000"],["111665.85000000","0.00000000"],["111665.86000000","1.25396000"],["111665.94000000","0.00000000"],["111666.15000000","0.00000000"],["111666.36000000","0.00000000"],["111666.72000000","0.13426000"],["111667.83000000","0.00000000"],["111667.98000000","0.75679000"],["111668.30000000","0.04002000"],["111668.31000000","0.13426000"],["111668.57000000","0.00000000"],["111668.62000000","0.00000000"],["111668.97000000","0.00000000"],["111669.02000000","0.00000000"],["111669.58000000","0.00000000"],["111669.60000000","1.25396000"],["111671.41000000","0.00012000"],["111671.49000000","0.00000000"],["111671.95000000","0.00000000"],["111672.78000000","0.00000000"],["111672.91000000","0.00895000"],["111673.13000000","0.00000000"],["111673.59000000","0.00269000"],["111674.57000000","0.00000000"],["111674.71000000","0.00000000"],["111675.32000000","0.08504000"],["111676.53000000","0.00000000"],["111677.37000000","0.00000000"],["111677.64000000","0.00000000"],["111678.60000000","0.18380000"],["111678.64000000","0.00179000"],["111679.78000000","0.45401000"],["111679.81000000","0.00000000"],["111679.89000000","0.00000000"],["111680.13000000","0.00000000"],["111681.25000000","0.00000000"],["111681.93000000","0.00000000"],["111682.30000000","0.04483000"],["111682.57000000","0.00000000"],["111683.52000000","0.00000000"],["111684.50000000","0.00000000"],["111685.69000000","0.00000000"],["111685.84000000","0.05476000"],["111686.00000000","0.00000000"],["111686.17000000","0.00000000"],["111687.42000000","0.00000000"],["111688.01000000","0.00000000"],["111688.51000000","0.00000000"],["111689.42000000","0.02507000"],["111690.13000000","0.00000000"],["111690.92000000","0.02597000"],["111690.93000000","0.00000000"],["111691.19000000","0.00000000"],["111691.47000000","0.00000000"],["111691.54000000","0.00000000"],["111691.89000000","0.00000000"],["111692.07000000","0.00000000"],["111692.19000000","0.00000000"],["111692.35000000","0.00000000"],["111693.03000000","0.00000000"],["111694.10000000","0.26583000"],["111694.18000000","0.00000000"],["111694.24000000","0.00000000"],["111695.70000000","0.00000000"],["111696.36000000","0.00000000"],["111696.57000000","1.27985000"],["111697.03000000","0.00000000"],["111697.64000000","0.00000000"],["111698.28000000","0.00000000"],["111698.98000000","0.04800000"],["111699.83000000","0.00000000"],["111700.01000000","0.00000000"],["111700.31000000","0.00000000"],["111701.10000000","0.00000000"],["111701.19000000","0.00000000"],["111703.08000000","0.03672000"],["111703.10000000","0.00000000"],["111705.07000000","0.03024000"],["111705.84000000","0.00620000"],["111708.03000000","0.00000000"],["111709.25000000","0.02192000"],["111711.99000000","0.00223000"],["111713.27000000","0.04800000"],["111714.00000000","0.00827000"],["111714.25000000","0.00652000"],["111714.41000000","0.00007000"],["111719.48000000","0.13426000"],["111720.10000000","0.00000000"],["111723.93000000","0.00223000"],["111723.94000000","0.02280000"],["111727.51000000","0.00000000"],["111729.63000000","0.13426000"],["111729.70000000","0.00000000"],["111729.86000000","0.00000000"],["111732.63000000","0.00000000"],["111733.88000000","0.89453000"],["111735.28000000","0.00000000"],["111735.29000000","0.00106000"],["111736.62000000","0.00000000"],["111737.45000000","0.00000000"],["111739.08000000","0.02421000"],["111739.68000000","0.00000000"],["111739.69000000","0.00000000"],["111739.70000000","0.00000000"],["111739.93000000","0.00000000"],["111740.48000000","0.00000000"],["111740.52000000","0.00000000"],["111742.03000000","0.00000000"],["111742.70000000","0.00000000"],["111744.17000000","0.00000000"],["111745.96000000","0.00000000"],["111748.82000000","0.17904000"],["111749.09000000","0.00000000"],["111750.27000000","0.00000000"],["111750.75000000","0.00000000"],["111750.76000000","0.00000000"],["111757.70000000","0.00223000"],["111758.63000000","0.22377000"],["111758.70000000","0.00000000"],["111759.36000000","0.22377000"],["111759.41000000","0.13433000"],["111760.32000000","0.00000000"],["111760.41000000","0.00000000"],["111760.49000000","0.00000000"],["111760.64000000","0.00000000"],["111761.72000000","0.00000000"],["111762.66000000","0.00000000"],["111766.19000000","0.09440000"],["111770.38000000","0.00000000"],["111774.15000000","0.02508000"],["111777.82000000","0.08810000"],["111778.81000000","0.61183000"],["111782.15000000","0.00000000"],["111783.94000000","0.16226000"],["111784.53000000","0.00000000"],["111786.65000000","0.00000000"],["111788.95000000","0.00000000"],["111795.58000000","0.08745000"],["111795.99000000","0.00000000"],["111796.66000000","0.08594000"],["111799.60000000","0.08594000"],["111800.88000000","0.02689000"],["111806.83000000","0.00000000"],["111809.25000000","0.00000000"],["111809.60000000","0.00000000"],["111812.38000000","0.03380000"],["111813.43000000","0.00000000"],["111817.86000000","0.00000000"],["111818.11000000","0.02507000"],["111818.53000000","0.02507000"],["111819.06000000","0.02507000"],["111823.20000000","0.00000000"],["111824.96000000","0.00000000"],["111832.35000000","0.00000000"],["111842.31000000","0.00000000"],["111845.02000000","0.00000000"],["111861.05000000","0.00000000"],["111878.17000000","0.08594000"],["111881.16000000","0.08594000"],["111889.51000000","0.02508000"],["111889.63000000","0.02508000"],["111889.71000000","0.02508000"],["111891.63000000","0.02508000"],["111892.25000000","0.02508000"],["111892.58000000","0.02508000"],["111892.85000000","0.02508000"],["111901.12000000","0.01706000"],["111902.37000000","0.01701000"],["111903.02000000","0.00000000"],["111908.85000000","0.19541000"],["111917.86000000","0.00000000"],["111918.91000000","0.00000000"],["111921.23000000","0.00000000"],["111921.59000000","0.00000000"],["111931.14000000","0.00000000"],["111932.24000000","0.00000000"],["111932.94000000","0.00000000"],["111935.17000000","0.00000000"],["111939.60000000","0.00007000"],["111941.72000000","0.00000000"],["111970.71000000","0.02597000"],["111979.21000000","0.00000000"],["111979.72000000","0.03672000"],["111980.09000000","0.03672000"],["111980.62000000","0.03672000"],["111981.14000000","0.03672000"],["111981.40000000","0.03672000"],["111981.51000000","0.03672000"],["111981.53000000","0.00000000"],["111981.58000000","0.03672000"],["111981.68000000","0.03672000"],["111981.86000000","0.03672000"],["111981.90000000","0.03672000"],["111982.73000000","0.03672000"],["111985.58000000","0.00000000"],["111985.95000000","0.00000000"],["111986.07000000","0.00000000"],["111986.89000000","0.00000000"],["111987.02000000","0.00000000"],["111987.40000000","0.00000000"],["111987.66000000","0.21920000"],["111987.67000000","0.00000000"],["111987.99000000","0.00000000"],["111988.07000000","0.00000000"],["111988.94000000","0.00000000"],["111989.81000000","0.00000000"],["111993.46000000","0.00000000"],["111995.73000000","0.00000000"],["112000.92000000","0.00000000"],["112006.13000000","0.00000000"],["112021.87000000","0.02925000"],["112052.69000000","0.00000000"],["112058.85000000","0.00000000"],["112059.27000000","0.00000000"],["112064.33000000","0.00000000"],["112064.62000000","0.00000000"],["112076.61000000","0.00000000"],["112077.45000000","0.03581000"],["112078.08000000","0.00000000"],["112078.26000000","0.00000000"],["112078.44000000","0.00000000"],["112078.62000000","0.00000000"],["112078.85000000","0.00000000"],["112078.87000000","0.00000000"],["112079.59000000","0.00000000"],["112087.43000000","0.00000000"],["112088.70000000","0.00000000"],["112089.95000000","0.00000000"],["112098.56000000","0.00000000"],["112099.17000000","0.00000000"],["112100.02000000","0.00000000"],["112203.09000000","0.00000000"],["112203.57000000","0.00000000"],["112313.42000000","0.00000000"],["113313.52000000","0.00100000"]]}
[2025-10-12T10:57:28.184Z] {"e":"depthUpdate","E":1760266648014,"s":"BTCUSDT","U":77965079595,"u":77965080040,"b":[["111638.92000000","0.73217000"],["111638.91000000","0.00125000"],["111638.75000000","0.00119000"],["111638.74000000","0.00020000"],["111638.54000000","0.00010000"],["111638.53000000","0.01354000"],["111638.52000000","0.00010000"],["111638.00000000","0.00270000"],["111637.99000000","0.00010000"],["111636.89000000","0.00010000"],["111636.88000000","0.02405000"],["111636.87000000","0.00000000"],["111636.86000000","0.00000000"],["111636.82000000","0.00005000"],["111635.56000000","0.05447000"],["111635.02000000","0.00542000"],["111634.29000000","0.00000000"],["111634.02000000","0.00000000"],["111634.01000000","0.00005000"],["111634.00000000","0.00270000"],["111633.90000000","0.00722000"],["111633.79000000","0.00155000"],["111633.67000000","0.00000000"],["111633.66000000","0.00000000"],["111633.22000000","0.29546000"],["111633.00000000","0.00000000"],["111632.87000000","0.00010000"],["111632.86000000","0.20565000"],["111632.78000000","0.01792000"],["111632.58000000","0.00000000"],["111632.53000000","0.00000000"],["111632.49000000","0.00000000"],["111632.39000000","0.00005000"],["111632.29000000","0.00000000"],["111631.90000000","0.00000000"],["111631.89000000","0.03956000"],["111631.85000000","0.06023000"],["111631.66000000","0.00000000"],["111630.77000000","0.03979000"],["111630.54000000","0.04475000"],["111630.00000000","0.00359000"],["111629.83000000","0.00000000"],["111629.82000000","0.02688000"],["111629.62000000","0.01771000"],["111629.45000000","0.00000000"],["111628.72000000","0.00000000"],["111628.67000000","0.00000000"],["111628.01000000","0.00000000"],["111627.22000000","0.00000000"],["111627.16000000","0.00000000"],["111627.08000000","0.00000000"],["111627.06000000","0.00300000"],["111622.63000000","0.07200000"],["111622.17000000","0.51084000"],["111621.45000000","0.09360000"],["111620.83000000","0.04800000"],["111619.44000000","0.00000000"],["111616.48000000","0.05280000"],["111616.40000000","0.15000000"],["111616.38000000","0.54126000"],["111615.31000000","0.00000000"],["111613.82000000","0.00895000"],["111613.53000000","0.00000000"],["111611.92000000","0.00005000"],["111609.66000000","0.00000000"],["111605.43000000","0.00008000"],["111604.07000000","0.32240000"],["111603.95000000","0.00000000"],["111600.87000000","0.00000000"],["111598.01000000","0.02687000"],["111593.56000000","0.00000000"],["111593.51000000","0.00000000"],["111593.09000000","1.21063000"],["111591.59000000","0.00000000"],["111591.24000000","0.06789000"],["111586.28000000","0.30217000"],["111585.67000000","0.00000000"],["111582.30000000","0.00000000"],["111578.76000000","0.00012000"],["111573.18000000","0.00012000"],["111571.94000000","0.00008000"],["111560.07000000","0.00000000"],["111554.36000000","0.04800000"],["111554.33000000","0.05280000"],["111553.27000000","0.05760000"],["111549.92000000","0.07200000"],["111549.35000000","0.06240000"],["111549.03000000","0.00005000"],["111548.69000000","0.06720000"],["111547.69000000","0.06720000"],["111545.91000000","0.00005000"],["111538.44000000","0.00008000"],["111536.63000000","0.00000000"],["111535.46000000","0.00000000"],["111526.57000000","0.00000000"],["111526.37000000","0.04800000"],["111521.93000000","0.00000000"],["111514.80000000","0.00005000"],["111504.95000000","0.00008000"],["111493.07000000","0.00000000"],["111471.46000000","0.00008000"],["111442.01000000","0.00000000"],["111433.70000000","0.00000000"],["111432.31000000","0.00065000"],["111423.54000000","0.08594000"],["111310.79000000","0.03997000"],["111304.94000000","0.02687000"],["111302.48000000","0.02687000"],["111300.01000000","0.02687000"],["111297.62000000","0.02687000"],["111295.18000000","0.02687000"],["111294.07000000","0.05996000"],["111293.25000000","0.05996000"],["111292.34000000","0.02687000"],["111292.33000000","0.05996000"],["111290.62000000","0.05996000"],["111288.88000000","0.05996000"],["111287.82000000","0.02687000"],["111287.52000000","0.05996000"],["111287.02000000","0.05996000"],["111286.56000000","0.05996000"],["111285.41000000","0.05996000"],["111149.18000000","0.03582000"],["100483.47000000","0.00000000"],["100475.00000000","0.00024000"],["100474.00000000","0.00010000"],["89311.14000000","0.00022000"],["42000.00000000","1.49096000"]],"a":[["111638.93000000","8.25433000"],["111639.08000000","0.00010000"],["111639.09000000","0.00906000"],["111639.32000000","0.01354000"],["111640.05000000","0.00015000"],["111640.14000000","0.00005000"],["111641.16000000","0.00358000"],["111641.40000000","0.00000000"],["111641.41000000","0.06656000"],["111641.42000000","0.04077000"],["111641.72000000","0.00000000"],["111641.73000000","0.02698000"],["111642.54000000","0.04003000"],["111642.66000000","0.00005000"],["111642.83000000","0.00542000"],["111644.08000000","0.00105000"],["111648.29000000","0.35811000"],["111648.30000000","0.44975000"],["111648.31000000","0.52848000"],["111648.81000000","0.30590000"],["111650.10000000","0.00300000"],["111650.53000000","0.00000000"],["111650.54000000","0.38482000"],["111653.47000000","0.00000000"],["111654.29000000","0.09285000"],["111654.61000000","0.00896000"],["111654.84000000","0.00005000"],["111655.00000000","0.00680000"],["111655.33000000","0.04800000"],["111655.89000000","0.00000000"],["111655.92000000","0.00005000"],["111655.98000000","0.15000000"],["111656.02000000","0.00537000"],["111656.09000000","0.01014000"],["111656.29000000","0.04800000"],["111656.68000000","0.00358000"],["111657.50000000","0.11520000"],["111658.01000000","0.00000000"],["111658.35000000","0.00000000"],["111658.55000000","0.07200000"],["111658.61000000","0.00000000"],["111658.64000000","0.00000000"],["111658.68000000","0.04800000"],["111659.24000000","0.04800000"],["111659.47000000","0.00000000"],["111659.72000000","0.07200000"],["111659.81000000","0.04800000"],["111660.59000000","0.00000000"],["111660.92000000","0.04800000"],["111662.46000000","0.00000000"],["111663.00000000","0.04800000"],["111666.80000000","0.01390000"],["111668.05000000","0.00000000"],["111669.58000000","0.02398000"],["111669.59000000","0.08594000"],["111669.79000000","0.00000000"],["111670.95000000","0.00000000"],["111670.98000000","0.00000000"],["111672.04000000","0.00000000"],["111672.42000000","0.00008000"],["111672.91000000","0.00000000"],["111673.14000000","1.63317000"],["111673.16000000","0.00000000"],["111673.21000000","0.00000000"],["111673.47000000","1.16545000"],["111674.65000000","0.00000000"],["111674.85000000","0.00000000"],["111675.19000000","0.00000000"],["111675.27000000","0.00000000"],["111675.35000000","0.00000000"],["111677.82000000","0.00000000"],["111679.93000000","0.32218000"],["111682.30000000","0.00005000"],["111682.91000000","0.00000000"],["111683.33000000","0.00000000"],["111684.24000000","0.01069000"],["111684.77000000","1.10649000"],["111686.84000000","0.02687000"],["111686.85000000","0.00000000"],["111689.82000000","0.01069000"],["111694.07000000","0.00000000"],["111699.20000000","0.04340000"],["111705.26000000","0.00000000"],["111705.91000000","0.00008000"],["111708.00000000","0.00260000"],["111710.00000000","0.00260000"],["111712.00000000","0.00260000"],["111712.83000000","0.00000000"],["111714.00000000","0.00887000"],["111716.00000000","0.00260000"],["111718.00000000","0.00260000"],["111720.00000000","0.04939000"],["111727.57000000","0.00000000"],["111739.41000000","0.00008000"],["111739.48000000","0.00187000"],["111743.22000000","0.00000000"],["111745.98000000","0.00223000"],["111746.36000000","0.00000000"],["111750.89000000","0.21636000"],["111757.70000000","0.00000000"],["111761.06000000","0.00000000"],["111761.73000000","0.00000000"],["111762.98000000","0.00000000"],["111771.29000000","0.00000000"],["111772.90000000","0.00008000"],["111782.04000000","0.06000000"],["111794.56000000","0.00000000"],["111806.39000000","0.00008000"],["111806.73000000","0.53141000"],["111808.68000000","0.00000000"],["111809.60000000","0.00005000"],["111818.98000000","0.02508000"],["111824.09000000","0.00000000"],["111828.06000000","0.00000000"],["111840.37000000","0.07519000"],["111861.56000000","0.00079000"],["111887.60000000","0.00000000"],["111893.10000000","0.02508000"],["111894.62000000","0.00000000"],["111899.53000000","0.02398000"],["111917.64000000","0.00000000"],["111930.08000000","0.00000000"],["111958.44000000","0.00010000"],["111973.41000000","0.05996000"],["111981.84000000","0.02687000"],["111982.11000000","0.06358000"],["111984.24000000","0.02687000"],["111985.15000000","0.00000000"],["111986.59000000","0.02687000"],["112074.59000000","0.00000000"],["112090.71000000","0.02398000"],["112099.08000000","0.00000000"],["112137.29000000","0.03582000"],["113313.52000000","0.00100000"]]}
[2025-10-12T10:57:29.183Z] {"e":"depthUpdate","E":1760266649014,"s":"BTCUSDT","U":77965080041,"u":77965080199,"b":[["111638.92000000","0.79946000"],["111638.91000000","0.00125000"],["111635.56000000","0.05447000"],["111633.90000000","0.00722000"],["111633.23000000","0.00005000"],["111633.22000000","0.29551000"],["111632.87000000","0.00005000"],["111632.86000000","0.20570000"],["111631.89000000","0.03951000"],["111626.51000000","0.00000000"],["111625.81000000","0.00000000"],["111624.99000000","0.00100000"],["111622.02000000","0.04800000"],["111621.75000000","0.01164000"],["111620.83000000","0.09600000"],["111593.10000000","1.19881000"],["111592.71000000","0.00000000"],["111591.24000000","0.00000000"],["111591.05000000","0.06628000"],["111564.26000000","0.13553000"],["111555.81000000","0.02683000"],["111555.28000000","0.00005000"],["111549.06000000","0.63380000"],["111548.75000000","0.05760000"],["111547.31000000","0.02597000"],["111534.01000000","0.02597000"],["111527.54000000","0.00000000"],["111526.37000000","0.00000000"],["111526.36000000","0.00000000"],["111519.31000000","0.05104000"],["111511.08000000","0.02597000"],["111505.35000000","0.02597000"],["111500.23000000","0.02597000"],["111491.52000000","0.02597000"],["111423.54000000","0.00000000"],["111404.84000000","0.00000000"],["111393.28000000","0.02508000"],["111391.19000000","0.02508000"],["111000.59000000","0.89110000"],["109964.33000000","0.00100000"],["102722.08000000","0.00010000"],["100474.00000000","0.00010000"],["89311.14000000","0.00022000"],["40190.01000000","0.00015000"]],"a":[["111638.93000000","8.25012000"],["111639.31000000","0.00010000"],["111639.60000000","0.10051000"],["111639.61000000","0.29554000"],["111640.04000000","0.00000000"],["111640.05000000","0.00005000"],["111641.25000000","0.00005000"],["111641.41000000","0.06661000"],["111641.42000000","0.00000000"],["111641.73000000","0.02698000"],["111642.22000000","0.04119000"],["111642.54000000","0.00005000"],["111642.66000000","0.00000000"],["111642.83000000","0.00547000"],["111643.34000000","0.04038000"],["111644.08000000","0.00005000"],["111646.44000000","0.08509000"],["111647.32000000","0.00100000"],["111652.14000000","0.00005000"],["111654.84000000","0.00000000"],["111655.00000000","0.00670000"],["111655.50000000","0.00406000"],["111657.26000000","0.00000000"],["111659.19000000","0.00000000"],["111666.34000000","0.00895000"],["111671.44000000","0.02298000"],["111678.00000000","0.02298000"],["111682.25000000","0.05290000"],["111687.20000000","0.04800000"],["111717.07000000","0.00322000"],["111719.47000000","0.02597000"],["111723.89000000","0.02597000"],["111725.74000000","0.04800000"],["111728.91000000","0.00187000"],["111730.52000000","0.04800000"],["111739.48000000","0.00000000"],["111742.08000000","0.21295000"],["111753.58000000","0.00000000"],["111762.15000000","0.00000000"],["111850.94000000","0.00079000"],["111861.56000000","0.00000000"],["111889.59000000","0.00000000"],["111928.37000000","0.00000000"],["111950.00000000","0.01590000"],["112003.05000000","0.02298000"],["112003.67000000","0.02298000"],["112005.45000000","0.02298000"],["113313.52000000","0.00100000"],["120720.08000000","0.00350000"]]}
[2025-10-12T10:57:30.184Z] {"e":"depthUpdate","E":1760266650014,"s":"BTCUSDT","U":77965080200,"u":77965080353,"b":[["111638.92000000","0.80008000"],["111638.91000000","0.00120000"],["111638.53000000","0.01354000"],["111638.00000000","0.00275000"],["111637.99000000","0.00010000"],["111636.98000000","0.03987000"],["111636.97000000","0.04078000"],["111636.88000000","0.00010000"],["111635.61000000","0.00000000"],["111635.56000000","0.05442000"],["111633.90000000","0.00722000"],["111633.23000000","0.00000000"],["111633.22000000","0.00000000"],["111633.20000000","0.15149000"],["111633.19000000","0.29546000"],["111632.87000000","0.00000000"],["111632.86000000","0.00000000"],["111632.78000000","0.01792000"],["111630.09000000","0.00000000"],["111630.00000000","0.00354000"],["111629.83000000","0.00000000"],["111629.82000000","0.00000000"],["111629.65000000","0.02693000"],["111629.62000000","0.00000000"],["111629.56000000","0.01825000"],["111626.35000000","0.00073000"],["111622.19000000","0.15000000"],["111616.40000000","0.00000000"],["111616.30000000","0.00000000"],["111615.30000000","0.00005000"],["111610.61000000","0.35811000"],["111610.20000000","0.00000000"],["111609.66000000","0.00000000"],["111599.23000000","0.70332000"],["111591.05000000","0.00000000"],["111588.92000000","0.00215000"],["111586.28000000","0.00000000"],["111584.69000000","0.30217000"],["111564.26000000","0.00000000"],["111562.83000000","0.01402000"],["111391.20000000","4.84990000"],["109964.33000000","0.00100000"],["108100.00000000","17.51910000"],["102722.08000000","0.00000000"],["102000.00000000","86.39856000"],["100475.00000000","0.00024000"],["100474.00000000","0.00010000"],["89311.14000000","0.00022000"]],"a":[["111638.93000000","8.24757000"],["111638.94000000","0.00025000"],["111641.40000000","0.00005000"],["111648.80000000","0.00005000"],["111649.01000000","0.00005000"],["111650.01000000","0.04012000"],["111650.53000000","0.15000000"],["111651.30000000","0.04002000"],["111654.29000000","0.09280000"],["111654.45000000","0.04730000"],["111655.26000000","0.00005000"],["111655.98000000","0.00000000"],["111679.78000000","0.67145000"],["111682.00000000","0.00200000"],["111684.00000000","0.00200000"],["111685.65000000","0.00000000"],["111686.00000000","0.00200000"],["111688.00000000","0.00200000"],["111690.00000000","0.00200000"],["111692.00000000","0.00200000"],["111694.00000000","0.00200000"],["111696.00000000","0.00200000"],["111717.42000000","0.00187000"],["111722.66000000","0.00100000"],["111722.67000000","0.00100000"],["111728.91000000","0.00000000"],["111736.68000000","0.00000000"],["111736.69000000","0.00000000"],["111737.43000000","0.14257000"],["111749.52000000","0.01402000"],["111839.45000000","0.00079000"],["111850.94000000","0.00000000"],["111877.08000000","4.72936000"],["113313.52000000","0.00100000"],["146460.00000000","0.00004000"]]}
[2025-10-12T10:57:31.184Z] {"e":"depthUpdate","E":1760266651014,"s":"BTCUSDT","U":77965080354,"u":77965080684,"b":[["111638.92000000","0.71534000"],["111638.91000000","0.00100000"],["111638.53000000","0.01354000"],["111638.00000000","0.00275000"],["111637.99000000","0.00010000"],["111636.99000000","0.00010000"],["111636.98000000","0.02376000"],["111636.97000000","0.04078000"],["111636.89000000","0.00000000"],["111636.88000000","0.00000000"],["111636.44000000","0.01806000"],["111636.00000000","0.00260000"],["111635.57000000","0.00000000"],["111635.56000000","0.00005000"],["111633.79000000","0.00155000"],["111633.21000000","0.00005000"],["111633.20000000","0.12785000"],["111633.19000000","0.00000000"],["111632.78000000","0.01797000"],["111632.00000000","0.00270000"],["111631.95000000","0.05617000"],["111631.89000000","0.00000000"],["111631.85000000","0.06018000"],["111630.78000000","0.00000000"],["111630.77000000","0.00000000"],["111630.54000000","0.00000000"],["111630.39000000","0.00000000"],["111630.11000000","0.00000000"],["111630.00000000","0.00359000"],["111629.65000000","0.00000000"],["111629.63000000","0.00000000"],["111629.56000000","0.00000000"],["111629.42000000","0.00000000"],["111628.51000000","0.29547000"],["111628.43000000","0.02688000"],["111627.76000000","0.00150000"],["111627.75000000","0.45000000"],["111627.52000000","0.00000000"],["111625.94000000","0.00000000"],["111624.99000000","0.00000000"],["111624.84000000","0.00000000"],["111622.19000000","0.15000000"],["111622.17000000","0.55559000"],["111621.83000000","0.00000000"],["111621.81000000","0.00000000"],["111620.44000000","0.00100000"],["111619.43000000","0.00069000"],["111616.40000000","0.00000000"],["111611.95000000","0.00005000"],["111611.86000000","0.00000000"],["111610.68000000","0.00000000"],["111610.51000000","0.41696000"],["111604.07000000","0.00000000"],["111603.31000000","0.32240000"],["111596.44000000","0.00000000"],["111590.83000000","0.00000000"],["111589.61000000","0.06573000"],["111588.19000000","0.43103000"],["111585.72000000","0.32246000"],["111584.69000000","0.00000000"],["111582.82000000","0.00000000"],["111582.78000000","0.00000000"],["111582.29000000","0.00000000"],["111581.77000000","0.00000000"],["111580.14000000","0.00005000"],["111580.10000000","0.00000000"],["111578.31000000","0.00000000"],["111578.01000000","0.00000000"],["111577.87000000","0.30219000"],["111575.63000000","0.00390000"],["111572.80000000","0.08504000"],["111570.31000000","0.00000000"],["111555.98000000","0.40306000"],["111547.57000000","0.00000000"],["111547.30000000","0.00000000"],["111544.44000000","0.00164000"],["111544.01000000","0.00000000"],["111539.70000000","0.00000000"],["111538.31000000","0.58443000"],["111538.30000000","1.25396000"],["111536.96000000","0.00000000"],["111530.81000000","0.08794000"],["111526.46000000","0.03992000"],["111526.04000000","0.00000000"],["111520.23000000","0.23234000"],["111512.89000000","0.02508000"],["111504.07000000","0.02508000"],["111499.39000000","0.02508000"],["111498.38000000","0.00000000"],["111484.04000000","0.08594000"],["111434.21000000","0.00000000"],["111433.88000000","0.00000000"],["111432.82000000","0.00065000"],["111432.31000000","0.00000000"],["111422.45000000","0.08794000"],["111421.36000000","0.08794000"],["111369.26000000","0.00000000"],["111360.95000000","0.00000000"],["111352.20000000","0.01701000"],["111343.88000000","0.01701000"],["111341.00000000","0.00000000"],["111337.62000000","0.00000000"],["111323.73000000","0.00000000"],["111323.67000000","0.00000000"],["111321.00000000","0.00000000"],["111320.57000000","0.00000000"],["111316.19000000","0.00000000"],["111316.17000000","0.02597000"],["111311.77000000","0.00000000"],["111310.94000000","0.02597000"],["111308.54000000","0.00000000"],["111290.37000000","0.00000000"],["111287.89000000","0.03672000"],["111287.54000000","0.03672000"],["111287.13000000","0.03672000"],["111286.49000000","0.03672000"],["111205.31000000","0.00000000"],["111199.21000000","0.00000000"],["111193.58000000","0.00000000"],["111185.84000000","0.00000000"],["111170.64000000","0.03582000"],["111165.26000000","0.03582000"],["111158.82000000","0.03582000"],["111152.23000000","0.03582000"],["111145.27000000","0.03582000"],["109964.33000000","0.00100000"],["100474.00000000","0.00010000"],["89311.14000000","0.00022000"],["40190.01000000","0.00030000"],["33000.00000000","3.87311000"]],"a":[["111638.93000000","8.64584000"],["111639.60000000","0.16446000"],["111642.22000000","0.04124000"],["111642.77000000","0.00100000"],["111643.34000000","0.04038000"],["111644.08000000","0.00000000"],["111644.51000000","0.11190000"],["111645.88000000","0.00005000"],["111646.01000000","0.40306000"],["111646.44000000","0.00000000"],["111647.32000000","0.00000000"],["111648.31000000","0.39422000"],["111650.53000000","0.15000000"],["111652.15000000","0.00005000"],["111654.44000000","0.06427000"],["111655.98000000","0.00000000"],["111656.13000000","0.00005000"],["111658.02000000","0.19652000"],["111659.85000000","0.32224000"],["111679.93000000","0.00000000"],["111682.30000000","0.00000000"],["111704.51000000","0.00187000"],["111713.90000000","0.13426000"],["111717.42000000","0.00000000"],["111719.46000000","0.02597000"],["111719.48000000","0.00000000"],["111722.26000000","0.00000000"],["111727.90000000","0.00000000"],["111728.58000000","0.00400000"],["111734.62000000","0.00005000"],["111745.15000000","0.26312000"],["111748.82000000","0.00000000"],["111800.04000000","0.00000000"],["111809.60000000","0.02513000"],["111812.07000000","0.02508000"],["111826.54000000","0.00079000"],["111836.41000000","0.00000000"],["111836.52000000","0.00000000"],["111839.45000000","0.00000000"],["111916.06000000","0.00000000"],["111917.42000000","0.00000000"],["111960.09000000","0.02597000"],["111961.38000000","0.05996000"],["111968.01000000","0.02597000"],["111975.24000000","0.03672000"],["111976.67000000","0.03672000"],["111976.93000000","0.03672000"],["111977.14000000","0.03672000"],["111977.37000000","0.03672000"],["111978.13000000","0.03582000"],["111978.38000000","0.03672000"],["111980.85000000","0.03672000"],["111983.65000000","0.02687000"],["111983.78000000","0.00000000"],["111984.13000000","0.00023000"],["111984.49000000","0.00000000"],["111984.50000000","0.00000000"],["112029.75000000","0.00000000"],["112051.26000000","0.00000000"],["112061.60000000","0.00000000"],["112061.95000000","0.00000000"],["112071.99000000","0.00000000"],["112072.73000000","0.00000000"],["112072.97000000","0.00000000"],["112073.32000000","0.00352000"],["112073.64000000","0.00000000"],["112073.99000000","0.00000000"],["112074.19000000","0.00000000"],["112080.67000000","0.00000000"],["112083.45000000","0.00000000"],["112086.16000000","0.00000000"],["112198.64000000","0.00000000"],["113313.52000000","0.00100000"],["133333.00000000","5.06411000"]]}
[2025-10-12T10:57:32.185Z] {"e":"depthUpdate","E":1760266652014,"s":"BTCUSDT","U":77965080685,"u":77965082196,"b":[["111638.92000000","0.00000000"],["111638.91000000","0.00000000"],["111638.90000000","0.00000000"],["111638.85000000","0.00000000"],["111638.84000000","0.00000000"],["111638.75000000","0.00000000"],["111638.74000000","0.00000000"],["111638.73000000","0.00000000"],["111638.54000000","0.00000000"],["111638.53000000","0.00644000"],["111638.52000000","0.00110000"],["111638.51000000","0.00020000"],["111638.00000000","0.00285000"],["111637.99000000","0.00020000"],["111637.93000000","0.00005000"],["111636.99000000","0.00000000"],["111636.98000000","0.00000000"],["111636.97000000","0.00000000"],["111636.82000000","0.00000000"],["111636.44000000","0.01806000"],["111636.43000000","0.00010000"],["111636.33000000","0.00010000"],["111636.16000000","0.00010000"],["111635.99000000","0.00010000"],["111635.97000000","0.00000000"],["111635.69000000","0.00000000"],["111633.90000000","0.00722000"],["111633.68000000","0.00000000"],["111633.28000000","0.00000000"],["111633.21000000","0.00000000"],["111633.20000000","0.00000000"],["111632.79000000","0.00010000"],["111632.78000000","0.01802000"],["111632.00000000","0.00265000"],["111631.96000000","0.00000000"],["111631.95000000","0.00000000"],["111631.86000000","0.00010000"],["111631.85000000","0.06033000"],["111630.53000000","0.00010000"],["111630.52000000","0.05261000"],["111630.27000000","0.00000000"],["111630.00000000","0.00364000"],["111629.60000000","0.00000000"],["111629.15000000","0.00000000"],["111629.03000000","0.00010000"],["111629.02000000","0.05363000"],["111628.51000000","0.00000000"],["111628.43000000","0.00000000"],["111628.24000000","0.00000000"],["111628.11000000","0.00000000"],["111627.84000000","0.00000000"],["111627.83000000","0.01628000"],["111627.76000000","0.00155000"],["111627.75000000","0.00000000"],["111627.57000000","0.00000000"],["111627.55000000","0.00000000"],["111627.20000000","0.00000000"],["111627.06000000","0.00305000"],["111626.43000000","0.00000000"],["111626.15000000","0.00000000"],["111624.93000000","0.00000000"],["111624.41000000","0.00000000"],["111624.09000000","0.00000000"],["111623.81000000","0.03935000"],["111622.64000000","0.00000000"],["111622.63000000","0.00000000"],["111622.51000000","0.00000000"],["111622.19000000","0.00000000"],["111622.18000000","0.15654000"],["111622.17000000","0.15823000"],["111622.02000000","0.00000000"],["111621.47000000","0.29549000"],["111621.45000000","0.00000000"],["111621.06000000","0.00000000"],["111620.83000000","0.00000000"],["111620.54000000","0.00000000"],["111620.51000000","0.01530000"],["111620.44000000","0.00000000"],["111620.37000000","0.00000000"],["111619.77000000","0.00000000"],["111619.17000000","0.00000000"],["111619.16000000","0.00000000"],["111618.99000000","0.00070000"],["111618.01000000","0.00000000"],["111617.46000000","0.00000000"],["111617.38000000","0.00005000"],["111617.36000000","0.00000000"],["111617.08000000","0.00000000"],["111616.48000000","0.00000000"],["111616.40000000","0.00000000"],["111616.39000000","0.17906000"],["111616.38000000","0.30019000"],["111616.37000000","0.00000000"],["111616.06000000","0.00000000"],["111614.71000000","0.00000000"],["111614.06000000","0.00000000"],["111613.90000000","0.00000000"],["111613.82000000","0.00000000"],["111613.56000000","0.00000000"],["111613.21000000","0.00332000"],["111612.26000000","0.00000000"],["111612.02000000","0.00000000"],["111612.01000000","0.00000000"],["111611.86000000","0.00000000"],["111611.01000000","0.11190000"],["111610.66000000","0.02000000"],["111610.61000000","0.00000000"],["111610.52000000","0.00000000"],["111610.51000000","0.40306000"],["111610.20000000","0.00447000"],["111610.02000000","0.00000000"],["111609.77000000","0.00000000"],["111609.66000000","0.00000000"],["111609.64000000","0.00000000"],["111608.97000000","0.00895000"],["111608.46000000","0.60000000"],["111608.08000000","0.00000000"],["111606.83000000","0.00000000"],["111606.81000000","0.36760000"],["111606.69000000","0.00000000"],["111605.43000000","0.04485000"],["111605.25000000","0.00005000"],["111605.03000000","0.04800000"],["111604.62000000","0.00000000"],["111603.48000000","0.35813000"],["111603.34000000","0.06132000"],["111603.31000000","0.00000000"],["111602.95000000","0.15000000"],["111602.52000000","0.08504000"],["111600.64000000","0.05280000"],["111600.62000000","0.17298000"],["111599.00000000","0.13426000"],["111598.20000000","0.00000000"],["111597.85000000","0.00000000"],["111597.70000000","0.00000000"],["111595.98000000","0.00000000"],["111595.84000000","0.00000000"],["111595.46000000","0.08504000"],["111593.78000000","0.00000000"],["111593.10000000","0.83808000"],["111593.09000000","0.00000000"],["111590.18000000","1.20361000"],["111589.61000000","0.00000000"],["111589.50000000","0.00012000"],["111589.28000000","0.00000000"],["111588.30000000","0.00009000"],["111588.00000000","0.00733000"],["111587.81000000","0.00000000"],["111587.21000000","0.00000000"],["111586.27000000","0.00000000"],["111586.11000000","0.00000000"],["111586.08000000","0.00018000"],["111585.43000000","0.45020000"],["111583.62000000","0.00000000"],["111583.61000000","0.00000000"],["111583.48000000","0.03827000"],["111583.41000000","0.00000000"],["111582.23000000","0.00000000"],["111580.10000000","0.00000000"],["111580.09000000","0.00000000"],["111578.41000000","0.32248000"],["111578.00000000","0.34782000"],["111577.90000000","0.00009000"],["111577.87000000","0.00000000"],["111577.72000000","0.00000000"],["111577.30000000","0.32248000"],["111576.10000000","0.00000000"],["111575.63000000","0.00000000"],["111574.06000000","0.00000000"],["111573.73000000","0.00000000"],["111572.87000000","0.00000000"],["111572.86000000","0.13433000"],["111571.20000000","0.00005000"],["111570.20000000","0.30221000"],["111567.33000000","0.04375000"],["111564.75000000","0.00000000"],["111560.42000000","0.00000000"],["111559.49000000","0.00360000"],["111559.45000000","0.45020000"],["111558.53000000","0.00000000"],["111556.42000000","0.02181000"],["111554.28000000","0.00000000"],["111553.75000000","0.00000000"],["111552.46000000","0.00000000"],["111551.71000000","0.40306000"],["111549.33000000","0.02144000"],["111548.81000000","0.00616000"],["111547.24000000","0.00000000"],["111544.44000000","0.00000000"],["111544.01000000","0.00164000"],["111542.71000000","0.07757000"],["111542.56000000","0.00090000"],["111542.41000000","0.00000000"],["111540.16000000","0.00000000"],["111539.32000000","0.00000000"],["111537.68000000","0.00000000"],["111536.95000000","0.00000000"],["111536.76000000","0.00000000"],["111536.48000000","0.13426000"],["111535.24000000","0.00000000"],["111533.57000000","0.01800000"],["111533.13000000","0.00000000"],["111531.60000000","1.25396000"],["111528.80000000","0.00000000"],["111528.24000000","0.05218000"],["111526.37000000","0.04800000"],["111521.93000000","0.00000000"],["111520.00000000","0.00260000"],["111516.49000000","0.00112000"],["111510.60000000","0.00000000"],["111510.34000000","0.13433000"],["111504.92000000","0.00196000"],["111500.87000000","0.02597000"],["111500.00000000","0.19075000"],["111495.94000000","0.02597000"],["111494.15000000","0.08594000"],["111493.02000000","0.02597000"],["111490.19000000","0.08594000"],["111487.59000000","0.08594000"],["111485.44000000","0.08594000"],["111485.42000000","0.08594000"],["111484.40000000","0.02597000"],["111479.70000000","0.00000000"],["111476.78000000","0.08594000"],["111476.51000000","0.00000000"],["111476.01000000","0.00000000"],["111475.23000000","0.00000000"],["111473.69000000","0.08594000"],["111473.54000000","0.00000000"],["111472.45000000","0.08684000"],["111470.62000000","0.00000000"],["111470.58000000","0.00019000"],["111442.35000000","0.00000000"],["111441.37000000","0.16197000"],["111434.45000000","0.00000000"],["111432.82000000","0.00000000"],["111432.31000000","0.00065000"],["111424.12000000","0.08794000"],["111423.35000000","0.99516000"],["111422.73000000","0.08794000"],["111422.72000000","0.08794000"],["111418.83000000","0.08794000"],["111411.23000000","0.08794000"],["111381.98000000","0.23925000"],["111380.18000000","0.02508000"],["111368.17000000","0.21203000"],["111337.88000000","0.00010000"],["111325.58000000","0.00000000"],["111323.98000000","0.00000000"],["111323.65000000","0.00000000"],["111323.51000000","0.00000000"],["111322.41000000","0.00000000"],["111322.12000000","0.00000000"],["111321.26000000","0.00000000"],["111321.17000000","0.00000000"],["111320.63000000","0.00000000"],["111319.21000000","0.00000000"],["111303.85000000","0.00000000"],["111299.92000000","0.00000000"],["111299.91000000","0.00000000"],["111299.04000000","0.00000000"],["111286.95000000","0.03672000"],["111284.89000000","0.03672000"],["111283.94000000","0.03672000"],["111283.57000000","0.05996000"],["111282.91000000","0.03672000"],["111282.79000000","0.05996000"],["111282.77000000","0.05996000"],["111282.74000000","0.05996000"],["111281.93000000","0.02692000"],["111278.65000000","0.02687000"],["111278.57000000","0.05996000"],["111255.23000000","0.00000000"],["111242.82000000","0.45000000"],["111163.46000000","0.00493000"],["111000.59000000","0.00000000"],["110985.84000000","0.89110000"],["109964.33000000","0.00000000"],["100475.00000000","0.00024000"],["100474.00000000","0.00010000"],["89311.14000000","0.00000000"],["89310.83000000","0.00022000"],["40190.01000000","0.00045000"]],"a":[["111638.54000000","10.45011000"],["111638.59000000","0.00000000"],["111638.62000000","0.00010000"],["111638.70000000","0.00080000"],["111638.75000000","0.53434000"],["111638.76000000","0.08124000"],["111638.78000000","0.00000000"],["111638.79000000","0.00000000"],["111638.81000000","0.00000000"],["111638.84000000","0.00000000"],["111638.92000000","0.40316000"],["111638.93000000","0.21911000"],["111638.94000000","0.00000000"],["111639.01000000","0.00000000"],["111639.08000000","0.00000000"],["111639.10000000","0.00000000"],["111639.31000000","0.00000000"],["111639.32000000","0.01354000"],["111639.41000000","0.00100000"],["111639.59000000","0.00000000"],["111639.60000000","0.00005000"],["111639.61000000","0.00000000"],["111641.15000000","0.00000000"],["111641.40000000","0.00000000"],["111641.41000000","0.06656000"],["111642.22000000","0.04119000"],["111642.42000000","0.40306000"],["111642.76000000","0.00005000"],["111642.77000000","0.00000000"],["111642.83000000","0.00547000"],["111643.00000000","0.06000000"],["111643.33000000","0.00000000"],["111643.34000000","0.04043000"],["111644.50000000","0.00005000"],["111644.51000000","0.11212000"],["111645.35000000","0.03588000"],["111645.45000000","0.00005000"],["111646.08000000","0.04800000"],["111646.14000000","0.04800000"],["111646.16000000","0.04308000"],["111647.30000000","0.01000000"],["111647.43000000","0.00187000"],["111647.48000000","0.08504000"],["111648.29000000","0.00000000"],["111648.31000000","0.21071000"],["111648.81000000","0.30585000"],["111648.86000000","0.00005000"],["111649.41000000","0.48810000"],["111650.01000000","0.04007000"],["111650.03000000","0.00044000"],["111650.36000000","0.00005000"],["111650.49000000","0.15000000"],["111650.50000000","0.00000000"],["111650.51000000","1.28525000"],["111650.52000000","1.25396000"],["111650.53000000","0.00000000"],["111650.54000000","0.00000000"],["111652.60000000","0.00000000"],["111653.12000000","0.32226000"],["111653.68000000","0.00000000"],["111653.71000000","0.00895000"],["111655.07000000","0.00000000"],["111655.29000000","0.00151000"],["111655.37000000","1.25396000"],["111655.98000000","0.00000000"],["111657.31000000","0.08000000"],["111658.02000000","0.28246000"],["111658.80000000","0.00044000"],["111659.07000000","0.00000000"],["111659.87000000","0.00000000"],["111659.88000000","0.00000000"],["111661.33000000","0.00448000"],["111662.46000000","0.00000000"],["111663.16000000","0.00000000"],["111665.41000000","0.00000000"],["111665.84000000","0.00000000"],["111666.34000000","0.00000000"],["111666.51000000","0.02126000"],["111666.72000000","0.00000000"],["111668.28000000","1.17329000"],["111668.31000000","0.00000000"],["111669.58000000","0.02398000"],["111672.42000000","0.04486000"],["111673.12000000","0.00000000"],["111673.14000000","1.19597000"],["111673.47000000","0.00000000"],["111675.16000000","0.00000000"],["111675.30000000","0.00000000"],["111678.21000000","0.18374000"],["111678.60000000","0.00000000"],["111678.95000000","0.00000000"],["111679.87000000","0.00000000"],["111681.59000000","0.00000000"],["111682.88000000","0.07329000"],["111684.20000000","0.00000000"],["111684.46000000","0.00000000"],["111685.64000000","0.00000000"],["111685.82000000","0.00000000"],["111692.17000000","0.00000000"],["111692.22000000","0.00000000"],["111693.42000000","0.04437000"],["111696.13000000","0.00624000"],["111697.89000000","0.00000000"],["111698.87000000","0.00658000"],["111699.20000000","0.00000000"],["111704.51000000","0.00000000"],["111704.79000000","0.02280000"],["111705.09000000","0.06642000"],["111708.44000000","0.00000000"],["111710.95000000","0.00000000"],["111713.35000000","0.13426000"],["111713.36000000","0.13426000"],["111713.90000000","0.00000000"],["111714.25000000","0.00000000"],["111716.73000000","0.00000000"],["111717.59000000","0.00000000"],["111719.29000000","0.00000000"],["111719.83000000","0.99215000"],["111720.07000000","0.00000000"],["111722.53000000","0.02130000"],["111723.94000000","0.00000000"],["111723.96000000","0.00000000"],["111723.97000000","0.00000000"],["111724.31000000","0.00109000"],["111724.81000000","0.01800000"],["111724.86000000","0.03993000"],["111726.62000000","0.00000000"],["111727.52000000","0.00000000"],["111728.32000000","0.07067000"],["111729.57000000","0.31485000"],["111729.63000000","0.00000000"],["111731.89000000","0.00000000"],["111734.62000000","0.00000000"],["111735.56000000","0.01377000"],["111740.69000000","0.00000000"],["111740.86000000","0.00000000"],["111744.45000000","0.00000000"],["111744.90000000","0.00000000"],["111745.11000000","0.00000000"],["111745.78000000","0.00000000"],["111745.79000000","0.00000000"],["111746.62000000","0.00000000"],["111748.00000000","0.00456000"],["111749.52000000","0.00000000"],["111752.68000000","0.00000000"],["111754.10000000","0.00000000"],["111758.63000000","0.00000000"],["111758.98000000","0.99612000"],["111759.36000000","0.00000000"],["111759.41000000","0.00000000"],["111766.32000000","0.06008000"],["111769.45000000","0.00079000"],["111770.14000000","0.00000000"],["111771.84000000","0.08594000"],["111778.81000000","0.37243000"],["111781.45000000","0.00000000"],["111788.14000000","0.08794000"],["111796.45000000","0.38031000"],["111797.18000000","0.00000000"],["111799.88000000","0.08794000"],["111800.77000000","0.00000000"],["111803.61000000","0.00000000"],["111806.85000000","0.00000000"],["111808.32000000","0.08894000"],["111809.51000000","0.00000000"],["111810.12000000","0.00000000"],["111811.24000000","0.00000000"],["111822.22000000","0.00000000"],["111826.05000000","0.08594000"],["111826.37000000","0.00000000"],["111826.54000000","0.00000000"],["111828.69000000","0.08594000"],["111831.57000000","0.08594000"],["111832.99000000","0.08594000"],["111835.02000000","0.08594000"],["111890.67000000","0.00000000"],["111893.21000000","0.00000000"],["111895.23000000","0.00000000"],["111895.61000000","0.00000000"],["111895.62000000","0.00000000"],["111896.55000000","0.00000000"],["111899.65000000","0.00000000"],["111902.17000000","0.01701000"],["111923.94000000","0.00000000"],["111926.46000000","0.00000000"],["111949.12000000","0.00000000"],["111952.07000000","0.05995000"],["111952.44000000","0.05995000"],["111952.80000000","0.00000000"],["111953.50000000","0.05995000"],["111954.44000000","0.05995000"],["111954.82000000","0.05995000"],["111955.24000000","0.05995000"],["111957.20000000","0.00000000"],["111958.21000000","0.05995000"],["111958.26000000","0.00000000"],["111979.35000000","0.00000000"],["111992.43000000","0.00000000"],["112006.51000000","0.02749000"],["112035.27000000","0.00000000"],["112036.65000000","0.00000000"],["112036.99000000","0.00000000"],["112041.58000000","0.00000000"],["112041.66000000","0.00000000"],["112042.45000000","0.00000000"],["112043.34000000","0.00000000"],["112045.71000000","0.00000000"],["112048.60000000","0.00000000"],["112048.64000000","0.00492000"],["112049.03000000","0.00000000"],["112049.16000000","0.00000000"],["112049.20000000","0.00000000"],["112049.76000000","0.00000000"],["112049.78000000","0.00000000"],["112050.73000000","0.00000000"],["112051.17000000","0.00000000"],["112051.18000000","0.00000000"],["112083.67000000","0.00000000"],["112092.60000000","0.00000000"],["112092.93000000","0.00000000"],["112093.87000000","0.00000000"],["112094.72000000","0.00000000"],["112094.93000000","0.00000000"],["112095.96000000","0.00000000"],["112096.50000000","0.00000000"],["112097.27000000","0.00000000"],["112129.91000000","0.00000000"],["112133.62000000","0.00000000"],["112231.84000000","0.02398000"],["112305.75000000","0.00009000"],["112306.05000000","0.00000000"],["112306.76000000","0.00000000"],["112308.34000000","0.00000000"],["112310.78000000","0.00000000"],["112311.33000000","0.00000000"],["112311.60000000","0.00000000"],["112311.89000000","0.00000000"],["113313.12000000","0.00100000"],["113313.52000000","0.00000000"]]}
[2025-10-12T10:57:33.185Z] {"e":"depthUpdate","E":1760266653014,"s":"BTCUSDT","U":77965082197,"u":77965084515,"b":[["111638.53000000","0.00000000"],["111638.52000000","0.00000000"],["111638.51000000","0.00000000"],["111638.00000000","0.00000000"],["111637.99000000","0.00000000"],["111637.93000000","0.00000000"],["111637.92000000","0.00000000"],["111637.91000000","0.00000000"],["111636.45000000","0.00000000"],["111636.44000000","0.00000000"],["111636.43000000","0.00000000"],["111636.33000000","0.00000000"],["111636.16000000","0.00000000"],["111636.04000000","0.00000000"],["111636.01000000","0.00000000"],["111636.00000000","0.00000000"],["111635.99000000","0.00000000"],["111635.98000000","0.00000000"],["111635.71000000","0.00000000"],["111635.70000000","0.00000000"],["111635.56000000","0.00000000"],["111635.55000000","0.00000000"],["111635.40000000","0.00000000"],["111635.02000000","0.00000000"],["111635.01000000","0.00000000"],["111635.00000000","0.00000000"],["111634.99000000","0.00141000"],["111634.98000000","0.00105000"],["111634.60000000","0.00005000"],["111634.01000000","0.00005000"],["111634.00000000","0.00285000"],["111633.99000000","0.00020000"],["111633.90000000","0.00742000"],["111633.89000000","0.00020000"],["111633.79000000","0.00005000"],["111633.49000000","0.00005000"],["111633.39000000","0.00000000"],["111633.20000000","0.00010000"],["111633.17000000","0.00010000"],["111633.11000000","0.00010000"],["111632.95000000","0.00000000"],["111632.78000000","0.01802000"],["111632.77000000","0.00000000"],["111632.00000000","0.00265000"],["111631.99000000","0.00000000"],["111631.86000000","0.00000000"],["111631.85000000","0.00010000"],["111631.56000000","0.00005000"],["111631.10000000","0.00542000"],["111630.88000000","0.00000000"],["111630.52000000","0.05261000"],["111630.26000000","0.00005000"],["111630.00000000","0.00359000"],["111629.98000000","0.00727000"],["111629.03000000","0.00000000"],["111629.02000000","0.00000000"],["111628.88000000","0.00010000"],["111628.87000000","0.01802000"],["111628.12000000","0.00000000"],["111627.84000000","0.00000000"],["111627.83000000","0.00000000"],["111627.76000000","0.00160000"],["111627.06000000","0.00005000"],["111626.35000000","0.00000000"],["111625.73000000","0.00000000"],["111625.28000000","0.00010000"],["111625.27000000","0.01472000"],["111625.26000000","0.00010000"],["111625.25000000","0.04221000"],["111624.01000000","0.00000000"],["111624.00000000","0.00260000"],["111623.82000000","0.00000000"],["111623.81000000","0.00005000"],["111622.58000000","0.00000000"],["111622.57000000","0.00000000"],["111622.56000000","0.00005000"],["111622.50000000","0.00305000"],["111622.20000000","0.00000000"],["111622.19000000","0.09151000"],["111622.18000000","0.00000000"],["111622.17000000","0.04636000"],["111622.00000000","0.00270000"],["111621.76000000","0.17907000"],["111621.75000000","0.01164000"],["111621.47000000","0.00000000"],["111620.69000000","0.00000000"],["111620.63000000","0.00000000"],["111620.51000000","0.00000000"],["111620.24000000","0.00000000"],["111619.95000000","0.29549000"],["111619.81000000","0.00000000"],["111619.70000000","0.00000000"],["111619.32000000","0.00000000"],["111618.99000000","0.00070000"],["111618.96000000","0.00151000"],["111618.58000000","0.00000000"],["111618.03000000","0.00000000"],["111618.02000000","0.00000000"],["111618.01000000","0.00000000"],["111617.79000000","0.00000000"],["111617.78000000","0.00000000"],["111617.61000000","0.00000000"],["111617.57000000","0.04117000"],["111617.12000000","0.00000000"],["111616.49000000","0.03986000"],["111616.39000000","0.00000000"],["111616.38000000","0.27754000"],["111616.32000000","0.00007000"],["111616.28000000","0.00000000"],["111615.18000000","0.00000000"],["111615.17000000","0.45020000"],["111614.01000000","0.00000000"],["111613.91000000","0.00073000"],["111613.36000000","0.00069000"],["111610.70000000","0.04000000"],["111610.66000000","0.00000000"],["111610.59000000","0.00005000"],["111610.51000000","0.00000000"],["111610.20000000","0.00000000"],["111609.06000000","0.02000000"],["111608.47000000","0.40306000"],["111608.46000000","0.12000000"],["111606.23000000","0.04800000"],["111605.65000000","0.00000000"],["111605.43000000","0.00008000"],["111605.07000000","0.00447000"],["111605.06000000","0.04800000"],["111604.90000000","0.00000000"],["111604.55000000","0.38720000"],["111604.05000000","0.16000000"],["111603.99000000","0.07200000"],["111603.34000000","0.00136000"],["111602.95000000","0.00000000"],["111602.93000000","0.00000000"],["111602.81000000","0.09360000"],["111601.50000000","0.00300000"],["111600.62000000","0.08504000"],["111600.01000000","0.00000000"],["111599.25000000","0.00000000"],["111596.24000000","0.15000000"],["111593.12000000","0.00000000"],["111592.49000000","0.00000000"],["111592.44000000","0.32244000"],["111591.31000000","0.00000000"],["111590.91000000","0.00000000"],["111589.51000000","1.25396000"],["111588.30000000","0.00000000"],["111586.08000000","0.00000000"],["111584.01000000","0.01701000"],["111583.40000000","0.03583000"],["111581.98000000","0.00000000"],["111581.88000000","0.00000000"],["111581.69000000","0.00000000"],["111581.39000000","0.00000000"],["111581.01000000","0.06016000"],["111579.41000000","0.45000000"],["111578.85000000","0.06549000"],["111577.90000000","0.00000000"],["111577.37000000","0.67467000"],["111572.39000000","0.03672000"],["111572.38000000","0.00000000"],["111559.72000000","0.00000000"],["111555.09000000","0.00000000"],["111552.58000000","0.00000000"],["111552.06000000","0.13420000"],["111549.06000000","0.60783000"],["111548.04000000","0.00000000"],["111545.01000000","0.40306000"],["111542.78000000","0.00005000"],["111542.56000000","0.00000000"],["111542.22000000","0.00000000"],["111536.63000000","0.07200000"],["111536.12000000","0.02507000"],["111535.46000000","0.09360000"],["111534.93000000","0.02418000"],["111534.54000000","0.00000000"],["111533.93000000","0.00000000"],["111532.83000000","0.00000000"],["111531.61000000","0.98119000"],["111530.37000000","0.00000000"],["111529.64000000","0.00000000"],["111528.34000000","0.02508000"],["111527.54000000","0.00000000"],["111527.43000000","0.77051000"],["111527.12000000","0.37137000"],["111526.76000000","0.00000000"],["111526.37000000","0.00000000"],["111526.36000000","0.00000000"],["111525.93000000","0.00000000"],["111525.61000000","0.00000000"],["111525.00000000","1.25396000"],["111524.01000000","0.02508000"],["111522.48000000","0.00005000"],["111521.64000000","0.00000000"],["111521.50000000","0.00000000"],["111520.01000000","0.02508000"],["111518.73000000","0.00000000"],["111513.56000000","0.02508000"],["111509.66000000","0.02997000"],["111503.65000000","0.02508000"],["111494.30000000","0.02508000"],["111490.38000000","0.02508000"],["111481.58000000","0.08594000"],["111478.79000000","0.08594000"],["111476.75000000","0.12619000"],["111475.08000000","0.08594000"],["111464.67000000","0.00000000"],["111464.36000000","0.00000000"],["111453.12000000","0.14284000"],["111445.29000000","0.05194000"],["111444.75000000","0.08794000"],["111440.23000000","0.02597000"],["111431.23000000","0.09468000"],["111425.12000000","0.00000000"],["111412.78000000","0.08694000"],["111405.30000000","0.00000000"],["111373.30000000","0.00000000"],["111359.92000000","0.00467000"],["111352.42000000","0.00000000"],["111340.18000000","0.00000000"],["111336.36000000","0.00000000"],["111335.25000000","0.01701000"],["111333.14000000","0.00000000"],["111331.48000000","0.00000000"],["111330.20000000","0.00000000"],["111326.71000000","0.00000000"],["111326.13000000","0.00000000"],["111325.72000000","0.00000000"],["111324.56000000","0.00000000"],["111324.00000000","0.00000000"],["111317.86000000","0.02597000"],["111312.50000000","0.00000000"],["111312.27000000","0.02597000"],["111312.26000000","0.03583000"],["111309.42000000","0.02597000"],["111307.28000000","0.00000000"],["111306.81000000","0.03583000"],["111306.62000000","0.02597000"],["111305.71000000","0.00000000"],["111305.44000000","0.00000000"],["111304.92000000","0.03583000"],["111304.75000000","0.00000000"],["111304.45000000","0.00000000"],["111304.10000000","0.00000000"],["111303.66000000","0.02597000"],["111285.92000000","0.03672000"],["111285.23000000","0.03672000"],["111283.73000000","0.03672000"],["111282.67000000","0.03672000"],["111282.50000000","0.03672000"],["111281.87000000","0.03672000"],["111278.85000000","0.02687000"],["111278.65000000","0.05374000"],["111278.20000000","0.05996000"],["111277.29000000","0.05996000"],["111275.99000000","0.05996000"],["111275.41000000","0.05996000"],["111274.33000000","0.05996000"],["111137.52000000","0.03583000"],["111135.37000000","0.00000000"],["110831.94000000","0.00442000"],["110701.72000000","0.00000000"],["110000.00000000","26.25980000"],["109963.95000000","0.00000000"],["109960.47000000","0.00100000"],["109500.00000000","12.93339000"],["106000.00000000","32.68589000"],["100474.00000000","0.00000000"],["100471.00000000","0.01647000"],["89310.83000000","0.00000000"],["89308.00000000","0.00022000"],["40188.60000000","0.00015000"]],"a":[["111635.00000000","9.37089000"],["111635.01000000","2.55894000"],["111635.02000000","0.85341000"],["111635.03000000","0.04017000"],["111635.08000000","0.00000000"],["111635.09000000","0.00000000"],["111635.11000000","0.00010000"],["111635.17000000","0.00906000"],["111635.20000000","0.00080000"],["111635.40000000","0.01354000"],["111635.57000000","0.00000000"],["111635.69000000","0.00000000"],["111635.70000000","0.00000000"],["111635.71000000","0.00000000"],["111635.72000000","0.30590000"],["111635.78000000","0.00000000"],["111635.91000000","0.00000000"],["111635.98000000","0.00000000"],["111636.00000000","0.00000000"],["111636.01000000","0.00000000"],["111636.02000000","0.00000000"],["111636.17000000","0.00000000"],["111636.34000000","0.00000000"],["111636.42000000","0.00000000"],["111636.44000000","0.00000000"],["111636.45000000","0.04017000"],["111636.46000000","0.00000000"],["111637.24000000","0.00358000"],["111637.91000000","0.00000000"],["111637.93000000","0.00000000"],["111637.94000000","0.18088000"],["111637.95000000","0.00000000"],["111637.96000000","0.00000000"],["111637.98000000","0.00000000"],["111637.99000000","0.00000000"],["111638.00000000","0.00000000"],["111638.01000000","0.04007000"],["111638.07000000","0.00000000"],["111638.09000000","0.00000000"],["111638.10000000","0.00000000"],["111638.25000000","0.00005000"],["111638.51000000","0.00000000"],["111638.52000000","0.00000000"],["111638.53000000","0.00000000"],["111638.54000000","0.19292000"],["111638.62000000","0.00000000"],["111638.70000000","0.00000000"],["111638.75000000","0.00000000"],["111638.76000000","0.04119000"],["111638.91000000","0.00537000"],["111638.92000000","0.40306000"],["111638.93000000","0.27032000"],["111639.09000000","0.00005000"],["111639.32000000","0.01344000"],["111639.41000000","0.00000000"],["111640.14000000","0.00000000"],["111641.25000000","0.00000000"],["111641.41000000","0.06651000"],["111641.73000000","0.02698000"],["111642.00000000","0.00400000"],["111642.20000000","0.30466000"],["111642.21000000","0.35815000"],["111642.22000000","0.04114000"],["111642.54000000","0.00000000"],["111642.82000000","0.00000000"],["111642.83000000","0.00010000"],["111643.34000000","0.04048000"],["111644.18000000","0.05725000"],["111644.50000000","0.00000000"],["111644.80000000","0.00005000"],["111644.96000000","0.04800000"],["111645.35000000","0.03588000"],["111645.99000000","1.25396000"],["111646.00000000","0.69403000"],["111646.08000000","0.04805000"],["111646.14000000","0.04805000"],["111646.16000000","0.06720000"],["111646.51000000","0.00044000"],["111647.20000000","0.07200000"],["111647.21000000","0.00007000"],["111647.30000000","0.01000000"],["111647.48000000","0.08504000"],["111648.30000000","0.00000000"],["111648.38000000","0.07200000"],["111648.81000000","0.04002000"],["111648.86000000","0.00000000"],["111649.12000000","0.00000000"],["111649.43000000","0.04002000"],["111649.66000000","0.00010000"],["111650.01000000","0.04002000"],["111650.49000000","0.00000000"],["111651.66000000","0.04805000"],["111651.83000000","0.02900000"],["111651.85000000","0.04800000"],["111652.06000000","0.00007000"],["111653.34000000","0.00799000"],["111654.61000000","0.00000000"],["111655.29000000","0.00000000"],["111655.35000000","0.15000000"],["111655.97000000","0.00000000"],["111656.29000000","0.00000000"],["111656.68000000","0.00000000"],["111657.42000000","0.00000000"],["111657.50000000","0.00000000"],["111658.02000000","0.08594000"],["111658.55000000","0.00000000"],["111659.07000000","0.00000000"],["111659.72000000","0.00000000"],["111660.57000000","0.00000000"],["111662.46000000","0.00000000"],["111662.57000000","0.00022000"],["111663.00000000","0.00000000"],["111663.07000000","0.00000000"],["111666.40000000","0.00010000"],["111666.50000000","0.00000000"],["111670.56000000","0.00000000"],["111672.42000000","0.00008000"],["111674.13000000","0.04800000"],["111674.69000000","0.18374000"],["111675.39000000","0.00000000"],["111678.21000000","0.00000000"],["111681.90000000","0.00000000"],["111682.95000000","0.00000000"],["111685.14000000","0.00000000"],["111685.43000000","0.00000000"],["111686.95000000","0.04385000"],["111693.42000000","0.00000000"],["111711.58000000","0.13426000"],["111713.36000000","0.00000000"],["111716.50000000","0.00000000"],["111719.65000000","0.02455000"],["111721.48000000","0.00000000"],["111723.95000000","0.00000000"],["111723.97000000","1.62087000"],["111725.74000000","0.00000000"],["111733.45000000","0.00000000"],["111739.08000000","0.00000000"],["111741.09000000","0.00000000"],["111741.16000000","0.00000000"],["111741.28000000","0.00000000"],["111741.60000000","0.00000000"],["111741.87000000","0.22377000"],["111742.05000000","0.00000000"],["111742.10000000","0.00000000"],["111742.21000000","0.00000000"],["111742.22000000","0.00000000"],["111742.38000000","0.13433000"],["111743.08000000","0.00000000"],["111744.06000000","0.00000000"],["111752.63000000","0.09441000"],["111764.53000000","0.00000000"],["111766.19000000","0.00000000"],["111769.45000000","0.00000000"],["111787.99000000","0.92256000"],["111796.20000000","0.00000000"],["111801.62000000","0.00000000"],["111802.40000000","0.67355000"],["111806.35000000","0.02597000"],["111806.73000000","0.47483000"],["111810.52000000","0.02508000"],["111811.92000000","0.02508000"],["111814.04000000","0.04925000"],["111830.99000000","0.00000000"],["111882.72000000","0.03997000"],["111884.44000000","0.02508000"],["111885.22000000","0.03997000"],["111887.16000000","0.02508000"],["111891.46000000","0.00083000"],["111911.95000000","0.00000000"],["111912.80000000","0.00000000"],["111915.11000000","0.00000000"],["111954.73000000","0.02597000"],["111964.39000000","0.05996000"],["111974.23000000","0.00000000"],["111975.35000000","0.03583000"],["111978.33000000","0.00000000"],["111978.42000000","0.02687000"],["111980.56000000","0.03583000"],["111983.65000000","0.05374000"],["111984.54000000","0.02687000"],["111986.61000000","0.02687000"],["111990.00000000","0.00100000"],["112026.07000000","0.55838000"],["112050.46000000","0.00000000"],["112076.72000000","0.00000000"],["112077.71000000","0.00000000"],["112096.40000000","0.45000000"],["112107.57000000","0.45000000"],["112118.74000000","0.00000000"],["112188.24000000","0.00000000"],["112193.44000000","0.00000000"],["112228.86000000","0.02398000"],["113309.54000000","0.00100000"],["113313.12000000","0.00000000"]]}
