[2025-10-12T11:04:57.183Z] {"e":"depthUpdate","E":1760267097014,"s":"BTCUSDT","U":77965285848,"u":77965286414,"b":[["111526.36000000","7.22251000"],["111526.35000000","1.34179000"],["111526.34000000","0.00015000"],["111526.33000000","1.03804000"],["111526.20000000","0.00080000"],["111526.19000000","0.35821000"],["111526.18000000","0.00100000"],["111525.21000000","0.03992000"],["111524.10000000","0.00364000"],["111522.90000000","0.00000000"],["111520.75000000","0.11228000"],["111520.36000000","0.00087000"],["111518.14000000","0.00086000"],["111517.39000000","0.00086000"],["111517.10000000","0.00043000"],["111515.29000000","0.00000000"],["111515.23000000","0.00538000"],["111515.19000000","0.15000000"],["111514.80000000","0.00005000"],["111514.50000000","0.01000000"],["111513.08000000","0.00000000"],["111512.81000000","0.00000000"],["111512.70000000","0.05760000"],["111512.46000000","0.00994000"],["111512.12000000","0.00086000"],["111511.66000000","0.00043000"],["111510.83000000","0.00043000"],["111510.79000000","0.00087000"],["111510.75000000","0.01032000"],["111510.42000000","0.05760000"],["111509.67000000","0.00000000"],["111509.30000000","0.04470000"],["111509.17000000","0.04800000"],["111508.19000000","0.07920000"],["111507.96000000","0.00091000"],["111507.21000000","0.00634000"],["111506.96000000","0.10080000"],["111506.89000000","0.02623000"],["111506.45000000","0.00000000"],["111506.35000000","0.00044000"],["111505.29000000","0.00000000"],["111503.67000000","0.06240000"],["111503.52000000","0.07200000"],["111502.28000000","0.00044000"],["111501.84000000","0.00000000"],["111501.52000000","0.00044000"],["111501.03000000","0.00000000"],["111500.48000000","0.00088000"],["111499.77000000","0.04479000"],["111499.43000000","0.04426000"],["111498.70000000","0.01388000"],["111498.51000000","0.00000000"],["111497.44000000","0.00000000"],["111496.20000000","0.00000000"],["111494.05000000","0.00000000"],["111492.95000000","0.00000000"],["111492.88000000","0.00000000"],["111491.71000000","0.00000000"],["111488.17000000","1.16951000"],["111488.04000000","0.00009000"],["111487.35000000","0.00000000"],["111486.23000000","0.00000000"],["111486.11000000","0.00000000"],["111485.83000000","0.00018000"],["111484.64000000","0.00000000"],["111482.43000000","0.00000000"],["111481.41000000","0.18906000"],["111480.00000000","0.00379000"],["111479.48000000","0.00000000"],["111479.30000000","0.13444000"],["111477.67000000","0.00009000"],["111476.15000000","0.00000000"],["111474.27000000","0.00000000"],["111465.54000000","0.00000000"],["111450.06000000","0.13434000"],["111442.40000000","0.00090000"],["111439.00000000","0.00000000"],["111436.96000000","0.00000000"],["111435.49000000","0.06720000"],["111428.98000000","0.01800000"],["111419.47000000","0.00000000"],["111418.57000000","0.22384000"],["111416.14000000","0.13444000"],["111411.96000000","0.00006000"],["111410.93000000","0.04800000"],["111408.82000000","0.00000000"],["111392.40000000","0.00006000"],["111378.14000000","0.02510000"],["111374.37000000","0.06041000"],["111348.81000000","0.00000000"],["111348.44000000","0.00006000"],["111331.76000000","0.00574000"],["111330.78000000","0.00000000"],["111285.44000000","0.00006000"],["111226.33000000","0.00000000"],["111205.71000000","0.00006000"],["111175.87000000","0.00000000"],["111110.69000000","0.00006000"],["110000.00000000","26.34872000"],["109853.46000000","0.00100000"],["109853.43000000","0.00000000"],["105000.00000000","217.11999000"],["100373.00000000","0.00010000"],["89221.09000000","0.00022000"],["89221.07000000","0.00000000"],["40149.48000000","0.00015000"],["33000.00000000","3.87311000"]],"a":[["111526.34000000","0.00000000"],["111526.35000000","0.00000000"],["111526.36000000","0.00000000"],["111526.37000000","0.01913000"],["111526.38000000","0.00085000"],["111526.39000000","0.00020000"],["111526.73000000","0.01375000"],["111526.74000000","0.00020000"],["111526.91000000","0.00005000"],["111528.00000000","0.00200000"],["111528.01000000","0.00010000"],["111530.01000000","0.00010000"],["111532.51000000","0.03895000"],["111533.44000000","0.00000000"],["111533.45000000","0.00000000"],["111535.01000000","0.00010000"],["111535.02000000","0.05713000"],["111535.33000000","0.00000000"],["111535.55000000","0.00000000"],["111535.63000000","0.00000000"],["111535.85000000","0.00000000"],["111536.00000000","0.00215000"],["111536.64000000","0.00005000"],["111536.65000000","0.02005000"],["111536.75000000","0.04010000"],["111536.80000000","0.00000000"],["111536.85000000","0.08005000"],["111536.97000000","0.00155000"],["111537.49000000","0.04481000"],["111537.50000000","0.00000000"],["111537.94000000","0.00000000"],["111538.53000000","0.00000000"],["111539.45000000","0.00000000"],["111539.60000000","0.00000000"],["111539.90000000","0.01913000"],["111540.75000000","0.48000000"],["111540.84000000","0.00000000"],["111547.01000000","0.00069000"],["111547.12000000","0.00070000"],["111548.49000000","0.00000000"],["111548.63000000","0.35816000"],["111548.64000000","0.11195000"],["111550.76000000","0.04800000"],["111551.85000000","0.32649000"],["111551.86000000","0.04481000"],["111551.87000000","0.00000000"],["111551.97000000","0.06240000"],["111551.98000000","0.40616000"],["111552.30000000","0.04000000"],["111552.96000000","0.07200000"],["111554.21000000","0.07200000"],["111554.41000000","0.08507000"],["111554.46000000","0.01388000"],["111555.35000000","0.00000000"],["111555.50000000","0.00000000"],["111556.12000000","0.00000000"],["111557.42000000","0.04800000"],["111557.43000000","0.00000000"],["111557.59000000","0.04800000"],["111558.84000000","0.00896000"],["111559.10000000","0.30000000"],["111559.71000000","0.35816000"],["111559.79000000","0.00000000"],["111560.96000000","0.61301000"],["111560.97000000","0.00000000"],["111561.20000000","0.00000000"],["111563.60000000","0.00000000"],["111572.09000000","0.00000000"],["111572.60000000","1.18321000"],["111573.29000000","0.00000000"],["111573.31000000","0.00000000"],["111575.99000000","0.02689000"],["111577.61000000","0.00000000"],["111578.76000000","0.00000000"],["111578.83000000","0.00000000"],["111580.87000000","0.00000000"],["111587.96000000","0.02600000"],["111593.35000000","0.03586000"],["111595.26000000","0.00000000"],["111600.71000000","0.00000000"],["111602.34000000","0.00628000"],["111602.98000000","0.06727000"],["111603.98000000","0.00000000"],["111608.83000000","0.00000000"],["111609.59000000","0.00000000"],["111611.98000000","0.02398000"],["111612.92000000","0.00000000"],["111612.93000000","0.04800000"],["111613.90000000","0.02398000"],["111614.51000000","0.00000000"],["111616.44000000","0.00000000"],["111621.79000000","0.00000000"],["111627.92000000","0.04800000"],["111627.96000000","0.74192000"],["111628.74000000","0.02444000"],["111629.13000000","0.04800000"],["111629.14000000","0.06240000"],["111631.28000000","0.00000000"],["111634.59000000","0.04800000"],["111634.66000000","0.04800000"],["111635.38000000","0.02398000"],["111643.74000000","0.02398000"],["111647.99000000","0.00000000"],["111649.22000000","0.00000000"],["111670.59000000","0.02398000"],["111693.45000000","0.00000000"],["111695.74000000","0.00000000"],["111749.40000000","0.08000000"],["111817.31000000","0.00000000"],["111827.80000000","0.00000000"],["111828.53000000","0.00000000"],["111841.42000000","0.00000000"],["111858.54000000","0.07530000"],["111874.96000000","0.00000000"],["111888.21000000","0.07172000"],["111890.73000000","0.00000000"],["111922.81000000","0.02398000"],["111975.10000000","0.00000000"],["112034.62000000","0.03586000"],["112133.40000000","0.02398000"],["112134.20000000","0.02398000"],["113199.24000000","0.00000000"]]}
[2025-10-12T11:04:58.181Z] {"e":"depthUpdate","E":1760267098014,"s":"BTCUSDT","U":77965286415,"u":77965286527,"b":[["111526.36000000","7.40353000"],["111526.35000000","0.57150000"],["111526.34000000","0.00010000"],["111526.33000000","0.67916000"],["111525.21000000","0.03992000"],["111524.48000000","0.01388000"],["111524.18000000","0.00000000"],["111517.14000000","0.00041000"],["111515.19000000","0.00000000"],["111512.59000000","0.04800000"],["111511.69000000","0.00043000"],["111511.36000000","0.00005000"],["111511.07000000","0.00006000"],["111510.62000000","0.13434000"],["111506.26000000","0.00043000"],["111505.29000000","0.15000000"],["111502.57000000","0.00044000"],["111498.79000000","0.00000000"],["111498.70000000","0.00000000"],["111498.43000000","0.00000000"],["111497.93000000","0.30247000"],["111491.83000000","0.00000000"],["111484.78000000","0.05760000"],["111451.22000000","0.13434000"],["111450.06000000","0.00000000"],["111436.96000000","0.10080000"],["111426.15000000","0.40486000"],["111410.16000000","0.00000000"],["111346.43000000","0.00009000"],["111001.43000000","0.00006000"],["110878.73000000","0.00006000"],["109853.46000000","0.00100000"],["100373.00000000","0.00010000"],["92500.00000000","3.56609000"],["89221.09000000","0.00022000"],["42000.00000000","1.49096000"]],"a":[["111526.37000000","0.01913000"],["111526.38000000","0.00085000"],["111527.30000000","0.00010000"],["111527.34000000","0.00000000"],["111527.59000000","0.00000000"],["111539.25000000","0.04891000"],["111539.90000000","0.00000000"],["111540.00000000","0.00200000"],["111540.01000000","0.00000000"],["111540.11000000","0.01918000"],["111545.30000000","0.00000000"],["111551.82000000","0.01806000"],["111572.59000000","0.93471000"],["111573.28000000","0.00000000"],["111616.82000000","0.00100000"],["111616.83000000","0.00100000"],["111627.91000000","0.04097000"],["111629.96000000","0.04097000"],["111632.71000000","0.04097000"],["111637.65000000","0.00000000"],["111641.59000000","0.40247000"],["111643.73000000","0.04097000"],["111647.97000000","0.04097000"],["111653.40000000","0.04097000"],["111657.25000000","0.04097000"],["111665.77000000","0.04097000"],["111688.19000000","0.02510000"],["111722.36000000","0.08994000"],["111737.26000000","0.08795000"],["111739.46000000","0.00000000"],["111896.96000000","0.55835000"],["111908.02000000","0.06646000"],["113199.27000000","0.00100000"]]}
[2025-10-12T11:04:59.185Z] {"e":"depthUpdate","E":1760267099014,"s":"BTCUSDT","U":77965286528,"u":77965291735,"b":[["111538.24000000","6.94177000"],["111538.23000000","0.00010000"],["111538.19000000","0.06351000"],["111538.18000000","0.00000000"],["111538.17000000","0.00010000"],["111538.00000000","0.35816000"],["111537.99000000","3.51064000"],["111537.98000000","0.00010000"],["111537.93000000","0.00000000"],["111537.74000000","0.00000000"],["111537.49000000","0.00000000"],["111537.48000000","0.48369000"],["111537.47000000","0.00010000"],["111537.46000000","0.00000000"],["111537.45000000","0.00005000"],["111537.44000000","0.00005000"],["111537.43000000","0.36482000"],["111537.42000000","0.00000000"],["111537.41000000","0.00000000"],["111537.37000000","0.00000000"],["111537.36000000","0.00000000"],["111537.30000000","0.00080000"],["111537.00000000","0.00000000"],["111536.98000000","0.00000000"],["111536.97000000","0.00005000"],["111536.96000000","0.70330000"],["111536.95000000","0.00000000"],["111536.91000000","0.00000000"],["111536.90000000","0.00005000"],["111536.89000000","0.00000000"],["111536.80000000","0.00000000"],["111536.00000000","0.00000000"],["111535.99000000","0.00000000"],["111535.98000000","0.00000000"],["111535.94000000","0.00000000"],["111535.80000000","0.00005000"],["111535.44000000","0.00005000"],["111535.20000000","0.00000000"],["111535.04000000","0.00000000"],["111535.02000000","0.00100000"],["111535.01000000","0.00000000"],["111535.00000000","0.00000000"],["111534.99000000","0.00000000"],["111534.97000000","0.00000000"],["111534.96000000","0.00000000"],["111534.94000000","0.00000000"],["111534.90000000","0.00000000"],["111534.89000000","0.00005000"],["111534.76000000","0.00000000"],["111534.75000000","0.45020000"],["111534.74000000","0.00000000"],["111534.73000000","0.04003000"],["111534.72000000","0.00000000"],["111534.67000000","0.00000000"],["111534.58000000","0.35816000"],["111534.31000000","0.04163000"],["111534.17000000","0.00000000"],["111534.15000000","0.00000000"],["111534.14000000","0.00000000"],["111534.13000000","0.00000000"],["111534.02000000","0.00000000"],["111534.01000000","0.00000000"],["111534.00000000","0.11937000"],["111533.99000000","0.03998000"],["111533.98000000","0.00000000"],["111533.85000000","0.00000000"],["111533.53000000","0.00000000"],["111533.40000000","0.00000000"],["111533.39000000","0.00005000"],["111533.38000000","0.00000000"],["111533.36000000","0.00000000"],["111533.35000000","0.04003000"],["111533.34000000","0.00000000"],["111533.33000000","0.00000000"],["111532.82000000","0.08507000"],["111532.50000000","0.00000000"],["111532.49000000","0.00000000"],["111532.47000000","0.00000000"],["111532.46000000","0.04008000"],["111532.45000000","0.00000000"],["111532.14000000","0.00000000"],["111532.10000000","0.00000000"],["111532.03000000","0.00000000"],["111531.99000000","0.00000000"],["111531.77000000","0.05076000"],["111531.63000000","0.00000000"],["111531.54000000","0.00000000"],["111531.51000000","0.00043000"],["111531.50000000","0.00000000"],["111531.46000000","0.00044000"],["111531.35000000","0.00000000"],["111531.34000000","0.00000000"],["111531.33000000","0.00000000"],["111531.28000000","0.00000000"],["111531.18000000","0.00000000"],["111531.16000000","0.00000000"],["111531.15000000","0.00000000"],["111531.14000000","0.00000000"],["111531.10000000","0.00000000"],["111531.05000000","0.00000000"],["111531.03000000","0.00000000"],["111531.02000000","0.04003000"],["111531.01000000","0.00000000"],["111530.97000000","0.00005000"],["111530.96000000","0.00000000"],["111530.95000000","0.00000000"],["111530.42000000","0.00071000"],["111530.29000000","0.00000000"],["111530.28000000","0.27648000"],["111530.27000000","0.00000000"],["111530.26000000","0.22384000"],["111530.25000000","0.00005000"],["111530.24000000","0.35816000"],["111530.23000000","0.04003000"],["111530.22000000","0.00000000"],["111530.18000000","0.00000000"],["111530.17000000","0.00000000"],["111530.10000000","0.00000000"],["111530.05000000","0.00086000"],["111530.00000000","0.00000000"],["111529.99000000","0.00000000"],["111529.20000000","0.00448000"],["111529.19000000","0.03998000"],["111529.18000000","0.00000000"],["111529.13000000","0.00000000"],["111528.76000000","0.00000000"],["111528.41000000","0.00000000"],["111528.39000000","0.30746000"],["111528.38000000","0.04003000"],["111528.37000000","0.00000000"],["111528.22000000","0.00000000"],["111528.19000000","0.00000000"],["111528.01000000","0.00000000"],["111528.00000000","0.00000000"],["111527.99000000","0.00000000"],["111527.98000000","0.00000000"],["111527.51000000","0.00000000"],["111527.39000000","0.00000000"],["111527.29000000","0.00000000"],["111527.17000000","0.00000000"],["111526.94000000","0.00000000"],["111526.75000000","0.00000000"],["111526.73000000","0.00000000"],["111526.72000000","0.00000000"],["111526.71000000","0.00000000"],["111526.65000000","0.00000000"],["111526.54000000","0.00000000"],["111526.50000000","0.00005000"],["111526.39000000","0.00000000"],["111526.38000000","0.00000000"],["111526.37000000","0.00000000"],["111526.36000000","0.28704000"],["111526.35000000","0.00581000"],["111526.34000000","0.36053000"],["111526.33000000","0.20829000"],["111526.32000000","0.00000000"],["111526.26000000","0.00000000"],["111526.20000000","0.00000000"],["111526.19000000","0.35816000"],["111526.18000000","0.00000000"],["111525.94000000","0.01345000"],["111525.84000000","0.00044000"],["111525.79000000","0.00043000"],["111525.50000000","0.00086000"],["111525.44000000","0.00046000"],["111525.25000000","0.00538000"],["111525.21000000","0.03992000"],["111524.70000000","0.00000000"],["111524.48000000","0.00000000"],["111524.30000000","0.00000000"],["111524.11000000","0.00000000"],["111524.10000000","0.00359000"],["111524.04000000","0.00005000"],["111523.85000000","0.00300000"],["111523.59000000","0.00000000"],["111523.22000000","0.00000000"],["111523.03000000","0.00010000"],["111522.71000000","0.00000000"],["111522.43000000","0.00538000"],["111522.04000000","0.00000000"],["111521.98000000","0.00000000"],["111521.53000000","0.40323000"],["111521.52000000","0.08505000"],["111521.50000000","0.00005000"],["111521.29000000","0.00000000"],["111521.08000000","0.00000000"],["111521.06000000","0.00000000"],["111521.00000000","0.00000000"],["111520.93000000","0.00000000"],["111520.75000000","0.00000000"],["111520.36000000","0.00000000"],["111520.29000000","0.76224000"],["111520.28000000","1.25396000"],["111520.27000000","0.00000000"],["111520.26000000","0.00000000"],["111520.23000000","0.08701000"],["111520.21000000","0.00005000"],["111520.15000000","0.04426000"],["111520.06000000","0.00010000"],["111519.84000000","0.00000000"],["111519.54000000","0.00103000"],["111519.51000000","0.00051000"],["111519.40000000","0.00000000"],["111519.27000000","0.00000000"],["111519.20000000","0.00007000"],["111519.18000000","0.00086000"],["111519.00000000","0.02126000"],["111518.89000000","0.08064000"],["111518.84000000","0.00000000"],["111518.83000000","0.00000000"],["111518.80000000","0.04479000"],["111518.77000000","0.00007000"],["111518.72000000","0.00086000"],["111518.46000000","0.02691000"],["111518.32000000","0.06000000"],["111518.27000000","0.05760000"],["111518.14000000","0.00000000"],["111518.00000000","0.00509000"],["111517.89000000","0.00086000"],["111517.84000000","0.00087000"],["111517.78000000","0.01032000"],["111517.40000000","0.00000000"],["111517.39000000","0.00000000"],["111517.34000000","0.00000000"],["111517.13000000","0.00000000"],["111517.10000000","0.00000000"],["111516.92000000","0.00005000"],["111516.50000000","0.00895000"],["111516.35000000","0.00990000"],["111516.33000000","0.00010000"],["111516.10000000","0.01165000"],["111516.07000000","0.00000000"],["111515.61000000","0.00784000"],["111515.28000000","0.03449000"],["111515.20000000","0.00000000"],["111515.19000000","0.00000000"],["111515.18000000","0.67436000"],["111514.75000000","0.00044000"],["111514.63000000","0.00043000"],["111513.86000000","0.00000000"],["111513.84000000","1.25396000"],["111513.50000000","0.00000000"],["111513.26000000","0.00000000"],["111512.46000000","0.00943000"],["111512.21000000","0.00044000"],["111512.15000000","0.00044000"],["111512.12000000","0.00000000"],["111512.00000000","0.00005000"],["111511.95000000","0.00044000"],["111511.83000000","0.00000000"],["111511.69000000","0.00000000"],["111511.66000000","0.00000000"],["111511.58000000","0.00000000"],["111511.43000000","0.00034000"],["111511.15000000","0.01388000"],["111511.11000000","0.00088000"],["111510.86000000","0.00000000"],["111510.83000000","0.00000000"],["111510.79000000","0.00000000"],["111510.75000000","0.00000000"],["111510.62000000","0.00000000"],["111510.43000000","0.30244000"],["111510.35000000","0.00000000"],["111510.13000000","0.00000000"],["111509.30000000","0.00000000"],["111508.92000000","0.00010000"],["111507.96000000","0.00000000"],["111507.67000000","0.00000000"],["111507.47000000","0.00000000"],["111507.21000000","0.00000000"],["111506.89000000","0.00000000"],["111506.88000000","0.00000000"],["111506.71000000","0.00000000"],["111506.64000000","0.00000000"],["111506.50000000","0.00000000"],["111506.35000000","0.00000000"],["111506.26000000","0.00000000"],["111506.05000000","0.04367000"],["111506.01000000","0.08505000"],["111505.86000000","0.07680000"],["111505.50000000","0.00000000"],["111505.29000000","0.00000000"],["111504.66000000","0.00000000"],["111504.50000000","0.00000000"],["111504.00000000","0.00000000"],["111502.57000000","0.00000000"],["111502.28000000","0.00000000"],["111502.03000000","0.00010000"],["111501.74000000","0.00000000"],["111501.52000000","0.00000000"],["111500.83000000","0.00000000"],["111500.81000000","0.00000000"],["111500.80000000","0.00000000"],["111500.66000000","0.03498000"],["111500.48000000","0.00000000"],["111499.77000000","0.00000000"],["111499.43000000","0.00000000"],["111498.76000000","0.00000000"],["111498.47000000","0.31984000"],["111498.19000000","0.00000000"],["111498.14000000","0.00009000"],["111497.93000000","0.00000000"],["111497.71000000","0.00000000"],["111497.66000000","0.00000000"],["111497.18000000","0.00000000"],["111496.66000000","0.00012000"],["111496.02000000","0.00000000"],["111495.93000000","0.00018000"],["111495.74000000","0.04481000"],["111495.35000000","0.00000000"],["111495.23000000","0.00000000"],["111495.09000000","0.00000000"],["111495.08000000","0.35816000"],["111494.69000000","0.00000000"],["111491.84000000","0.00000000"],["111491.39000000","0.00000000"],["111491.35000000","0.00000000"],["111491.24000000","0.00000000"],["111491.08000000","0.00000000"],["111490.58000000","0.00000000"],["111490.48000000","0.00000000"],["111490.11000000","0.00000000"],["111488.04000000","0.00000000"],["111488.00000000","0.00000000"],["111487.77000000","0.00009000"],["111487.63000000","0.00000000"],["111486.62000000","0.00000000"],["111486.56000000","0.00000000"],["111486.52000000","0.00000000"],["111485.83000000","0.00000000"],["111484.66000000","0.04800000"],["111483.74000000","0.00000000"],["111483.18000000","0.00000000"],["111482.62000000","0.00446000"],["111482.58000000","0.00000000"],["111482.30000000","0.00000000"],["111482.16000000","0.00000000"],["111479.51000000","0.00000000"],["111479.30000000","0.00000000"],["111477.67000000","0.00000000"],["111477.34000000","0.00000000"],["111476.95000000","0.06580000"],["111475.10000000","0.00000000"],["111466.34000000","0.08795000"],["111465.43000000","0.00100000"],["111463.43000000","0.08795000"],["111462.95000000","0.02185000"],["111462.90000000","0.13434000"],["111462.20000000","0.10920000"],["111459.54000000","0.00000000"],["111459.52000000","0.00224000"],["111459.51000000","0.00632000"],["111459.48000000","0.00654000"],["111458.09000000","0.00000000"],["111456.82000000","0.00000000"],["111456.01000000","0.02510000"],["111454.91000000","0.00000000"],["111454.20000000","0.79885000"],["111454.16000000","0.00000000"],["111453.78000000","0.00631000"],["111452.49000000","0.00090000"],["111452.24000000","0.00000000"],["111451.27000000","0.00156000"],["111451.24000000","0.00000000"],["111451.22000000","0.00000000"],["111450.63000000","0.00000000"],["111448.90000000","0.00000000"],["111447.46000000","0.00000000"],["111446.82000000","0.00000000"],["111445.09000000","0.11255000"],["111444.71000000","0.05180000"],["111443.31000000","0.00007000"],["111442.40000000","0.00000000"],["111442.19000000","0.00000000"],["111442.16000000","0.00000000"],["111441.25000000","0.00000000"],["111440.76000000","0.00000000"],["111440.22000000","0.00224000"],["111440.21000000","0.00218000"],["111440.01000000","0.02420000"],["111438.86000000","0.02420000"],["111438.10000000","0.07920000"],["111438.09000000","0.00000000"],["111437.83000000","0.00000000"],["111434.74000000","0.00000000"],["111432.99000000","0.00000000"],["111432.83000000","0.00000000"],["111432.82000000","0.00000000"],["111432.20000000","0.00000000"],["111431.75000000","0.02420000"],["111431.05000000","0.00000000"],["111430.78000000","0.00000000"],["111430.41000000","0.00000000"],["111429.61000000","0.00000000"],["111429.11000000","0.02427000"],["111428.89000000","0.00010000"],["111428.38000000","0.00000000"],["111428.28000000","0.00000000"],["111428.01000000","0.00000000"],["111426.24000000","0.00000000"],["111424.76000000","0.00111000"],["111424.61000000","0.03952000"],["111423.90000000","0.00000000"],["111423.89000000","0.00000000"],["111423.29000000","0.00000000"],["111422.44000000","0.00000000"],["111421.48000000","0.07807000"],["111420.07000000","0.00000000"],["111419.53000000","0.00000000"],["111418.74000000","0.00000000"],["111418.57000000","0.00000000"],["111416.14000000","0.00000000"],["111415.38000000","0.00000000"],["111413.28000000","0.00000000"],["111412.90000000","0.08795000"],["111410.96000000","0.08794000"],["111410.43000000","0.08795000"],["111409.73000000","0.08795000"],["111409.60000000","0.08794000"],["111408.68000000","0.08829000"],["111407.08000000","0.00000000"],["111407.02000000","0.00000000"],["111404.88000000","0.08795000"],["111404.15000000","0.08795000"],["111403.74000000","0.00000000"],["111403.39000000","0.02689000"],["111403.12000000","0.00000000"],["111401.59000000","0.00000000"],["111400.48000000","0.08795000"],["111397.66000000","0.08795000"],["111394.36000000","0.08795000"],["111393.33000000","0.08903000"],["111392.94000000","0.08795000"],["111391.06000000","0.08795000"],["111382.14000000","0.00000000"],["111378.37000000","0.06000000"],["111367.40000000","0.00000000"],["111364.39000000","0.00000000"],["111361.12000000","0.00000000"],["111360.49000000","0.00000000"],["111360.22000000","0.00000000"],["111357.01000000","0.00000000"],["111356.96000000","0.00000000"],["111356.50000000","0.00000000"],["111355.05000000","0.00000000"],["111354.21000000","0.00000000"],["111353.21000000","0.00000000"],["111350.05000000","0.00000000"],["111349.30000000","0.00000000"],["111348.94000000","0.00000000"],["111347.17000000","0.00089000"],["111347.04000000","0.00000000"],["111345.99000000","0.00000000"],["111345.40000000","0.00000000"],["111338.39000000","0.09476000"],["111336.57000000","0.00000000"],["111335.20000000","0.99376000"],["111332.06000000","0.00000000"],["111330.77000000","0.00000000"],["111328.28000000","0.08794000"],["111327.85000000","0.00089000"],["111323.38000000","0.00000000"],["111321.90000000","0.00000000"],["111316.50000000","0.00000000"],["111302.90000000","0.00000000"],["111293.52000000","0.00000000"],["111291.54000000","0.00000000"],["111289.93000000","0.00000000"],["111289.83000000","0.00000000"],["111288.20000000","0.00000000"],["111287.69000000","0.00000000"],["111285.11000000","0.00000000"],["111268.98000000","0.02689000"],["111248.36000000","0.00000000"],["111248.19000000","0.02689000"],["111227.26000000","0.94804000"],["111217.37000000","0.00000000"],["111214.47000000","0.00000000"],["111210.61000000","0.00000000"],["111210.52000000","0.03586000"],["111210.21000000","0.03586000"],["111209.35000000","0.45000000"],["111205.04000000","0.00000000"],["111198.19000000","0.45000000"],["111196.50000000","0.00000000"],["111187.03000000","0.00000000"],["111175.87000000","0.00000000"],["111157.15000000","0.03675000"],["111156.09000000","0.03676000"],["111153.26000000","0.00000000"],["111144.58000000","0.00080000"],["111140.41000000","0.00000000"],["111120.43000000","0.00000000"],["111120.13000000","0.00000000"],["111110.22000000","0.00000000"],["111003.45000000","0.00000000"],["110998.53000000","0.00000000"],["110867.79000000","0.00000000"],["110857.21000000","0.00000000"],["110762.91000000","0.00000000"],["110700.00000000","2.18489000"],["110200.00000000","1.26431000"],["109864.41000000","0.00100000"],["109853.46000000","0.00000000"],["108000.00000000","92.66183000"],["100382.00000000","0.00010000"],["100373.00000000","0.00000000"],["89230.60000000","0.00022000"],["89224.20000000","0.00000000"],["89221.09000000","0.00000000"],["78075.15000000","0.00000000"],["78070.67000000","0.00256000"]],"a":[["111526.37000000","0.00000000"],["111526.38000000","0.00000000"],["111526.39000000","0.00000000"],["111526.42000000","0.00000000"],["111526.72000000","0.00000000"],["111526.73000000","0.00000000"],["111526.74000000","0.00000000"],["111526.91000000","0.00000000"],["111526.95000000","0.00000000"],["111527.30000000","0.00000000"],["111527.99000000","0.00000000"],["111528.00000000","0.00000000"],["111528.01000000","0.00000000"],["111528.02000000","0.00000000"],["111528.20000000","0.00000000"],["111528.23000000","0.00000000"],["111528.37000000","0.00000000"],["111528.40000000","0.00000000"],["111529.20000000","0.00000000"],["111529.21000000","0.00000000"],["111530.00000000","0.00000000"],["111530.01000000","0.00000000"],["111530.24000000","0.00000000"],["111530.25000000","0.00000000"],["111530.26000000","0.00000000"],["111530.27000000","0.00000000"],["111530.28000000","0.00000000"],["111530.29000000","0.00000000"],["111531.03000000","0.00000000"],["111531.04000000","0.00000000"],["111531.35000000","0.00000000"],["111531.36000000","0.00000000"],["111531.51000000","0.00000000"],["111531.55000000","0.00000000"],["111531.64000000","0.00000000"],["111532.00000000","0.00000000"],["111532.01000000","0.00000000"],["111532.04000000","0.00000000"],["111532.15000000","0.00000000"],["111532.46000000","0.00000000"],["111532.47000000","0.00000000"],["111532.48000000","0.00000000"],["111532.50000000","0.00000000"],["111532.51000000","0.00000000"],["111532.52000000","0.00000000"],["111532.77000000","0.00000000"],["111533.40000000","0.00000000"],["111533.41000000","0.00000000"],["111533.42000000","0.00000000"],["111533.54000000","0.00000000"],["111533.60000000","0.00000000"],["111533.86000000","0.00000000"],["111534.00000000","0.00000000"],["111534.01000000","0.00000000"],["111534.74000000","0.00000000"],["111534.75000000","0.00000000"],["111534.90000000","0.00000000"],["111535.01000000","0.00000000"],["111535.02000000","0.00000000"],["111535.03000000","0.00000000"],["111535.04000000","0.00000000"],["111535.21000000","0.00000000"],["111536.00000000","0.00000000"],["111536.01000000","0.00000000"],["111536.02000000","0.00000000"],["111536.53000000","0.00000000"],["111536.64000000","0.00000000"],["111536.65000000","0.00000000"],["111536.74000000","0.00000000"],["111536.75000000","0.00000000"],["111536.85000000","0.00000000"],["111536.97000000","0.00000000"],["111536.98000000","0.00000000"],["111536.99000000","0.00000000"],["111537.44000000","0.00000000"],["111537.45000000","0.00000000"],["111537.46000000","0.00000000"],["111537.49000000","0.00000000"],["111537.50000000","0.00000000"],["111537.51000000","0.00000000"],["111537.75000000","0.00000000"],["111538.00000000","0.00000000"],["111538.01000000","0.00000000"],["111538.25000000","0.00149000"],["111538.26000000","0.00095000"],["111538.89000000","0.00000000"],["111538.90000000","0.00000000"],["111539.16000000","0.00000000"],["111539.19000000","0.00000000"],["111539.20000000","0.00000000"],["111539.25000000","0.00000000"],["111539.69000000","0.00010000"],["111539.96000000","0.00000000"],["111540.00000000","0.00220000"],["111540.01000000","0.00020000"],["111540.11000000","0.00000000"],["111540.30000000","0.00000000"],["111540.34000000","0.00000000"],["111540.35000000","0.00000000"],["111540.55000000","0.00000000"],["111540.57000000","0.00000000"],["111540.58000000","0.00000000"],["111540.59000000","0.00000000"],["111540.75000000","0.00000000"],["111541.38000000","0.00000000"],["111541.39000000","0.00000000"],["111541.47000000","0.00005000"],["111541.51000000","0.00010000"],["111541.62000000","0.00000000"],["111541.74000000","0.00010000"],["111541.79000000","0.00010000"],["111542.00000000","0.00200000"],["111542.83000000","0.00000000"],["111542.84000000","0.00000000"],["111543.07000000","0.00005000"],["111543.36000000","0.00000000"],["111543.86000000","0.00000000"],["111543.87000000","0.00000000"],["111544.00000000","0.00200000"],["111544.01000000","0.00000000"],["111544.40000000","0.00000000"],["111544.60000000","0.00000000"],["111544.70000000","0.00000000"],["111544.95000000","0.00005000"],["111544.96000000","0.00000000"],["111545.14000000","0.00000000"],["111545.15000000","0.00005000"],["111545.52000000","0.00155000"],["111545.55000000","0.00000000"],["111545.56000000","0.00000000"],["111545.93000000","0.00305000"],["111546.00000000","0.00260000"],["111546.35000000","0.00010000"],["111546.36000000","0.14010000"],["111546.93000000","0.00000000"],["111546.94000000","0.00005000"],["111547.01000000","0.00000000"],["111547.05000000","0.00000000"],["111547.06000000","0.00000000"],["111547.12000000","0.00000000"],["111547.20000000","0.00000000"],["111547.28000000","0.00000000"],["111547.39000000","0.05309000"],["111547.47000000","0.00000000"],["111547.74000000","0.00000000"],["111547.75000000","0.00000000"],["111547.95000000","0.00000000"],["111547.96000000","0.00000000"],["111548.00000000","0.00265000"],["111548.02000000","0.00000000"],["111548.05000000","0.00000000"],["111548.14000000","0.00000000"],["111548.47000000","0.00000000"],["111548.59000000","0.00000000"],["111548.63000000","0.00000000"],["111548.64000000","0.00000000"],["111548.68000000","0.00000000"],["111548.96000000","0.00000000"],["111549.06000000","0.00000000"],["111549.99000000","0.00010000"],["111550.00000000","0.05801000"],["111550.13000000","0.00155000"],["111550.45000000","0.00010000"],["111550.46000000","0.48010000"],["111550.62000000","0.00010000"],["111550.63000000","0.30253000"],["111550.75000000","0.00010000"],["111550.76000000","0.04815000"],["111550.80000000","0.00069000"],["111550.92000000","0.00000000"],["111550.93000000","0.04805000"],["111551.28000000","0.00000000"],["111551.82000000","0.00000000"],["111551.85000000","0.00000000"],["111551.86000000","0.00000000"],["111551.90000000","0.04805000"],["111551.98000000","0.04800000"],["111552.04000000","0.00000000"],["111552.18000000","0.00000000"],["111552.30000000","0.00000000"],["111552.31000000","0.00000000"],["111552.40000000","0.00000000"],["111552.54000000","0.00000000"],["111552.72000000","0.00000000"],["111552.74000000","0.00151000"],["111552.81000000","0.00000000"],["111552.96000000","0.00000000"],["111553.32000000","0.00000000"],["111553.63000000","0.00000000"],["111553.66000000","0.00000000"],["111553.70000000","0.04476000"],["111553.93000000","0.00000000"],["111553.99000000","0.00000000"],["111554.21000000","0.00000000"],["111554.41000000","0.00000000"],["111554.46000000","0.00000000"],["111554.64000000","0.00000000"],["111554.65000000","0.01164000"],["111554.83000000","0.00000000"],["111555.02000000","0.00007000"],["111555.17000000","0.00073000"],["111555.51000000","0.00006000"],["111555.52000000","0.44608000"],["111555.57000000","0.00000000"],["111555.63000000","0.00000000"],["111555.72000000","0.45000000"],["111555.93000000","0.00000000"],["111556.05000000","0.00000000"],["111556.46000000","0.00331000"],["111556.66000000","0.00000000"],["111556.96000000","0.00448000"],["111556.97000000","0.00000000"],["111557.04000000","0.00000000"],["111557.05000000","0.00000000"],["111557.56000000","0.00000000"],["111557.58000000","0.04013000"],["111557.76000000","0.00000000"],["111558.00000000","0.00260000"],["111558.18000000","0.00000000"],["111558.54000000","0.00000000"],["111558.70000000","0.03982000"],["111558.84000000","0.00000000"],["111559.10000000","0.00000000"],["111559.12000000","0.00000000"],["111559.54000000","0.00000000"],["111559.71000000","0.00000000"],["111559.72000000","0.01397000"],["111560.30000000","0.11195000"],["111560.31000000","0.00000000"],["111560.32000000","0.00000000"],["111560.33000000","0.00000000"],["111560.96000000","0.28368000"],["111561.39000000","0.00000000"],["111561.54000000","0.00000000"],["111561.70000000","0.00005000"],["111561.71000000","0.02561000"],["111561.84000000","0.04482000"],["111562.74000000","0.00000000"],["111562.76000000","0.00000000"],["111563.10000000","0.00000000"],["111563.33000000","0.00000000"],["111563.80000000","0.01388000"],["111563.92000000","0.04479000"],["111566.08000000","0.02126000"],["111566.50000000","0.00000000"],["111566.64000000","0.35844000"],["111566.65000000","0.15000000"],["111566.66000000","0.15000000"],["111566.67000000","0.51021000"],["111566.68000000","0.35816000"],["111567.28000000","0.00000000"],["111567.89000000","0.00895000"],["111567.94000000","0.00000000"],["111568.44000000","0.00000000"],["111568.49000000","0.00300000"],["111568.76000000","0.00000000"],["111569.90000000","0.04000000"],["111571.88000000","0.00012000"],["111571.90000000","0.00000000"],["111572.08000000","0.00000000"],["111572.11000000","0.16069000"],["111573.30000000","0.13430000"],["111574.08000000","0.13434000"],["111574.52000000","0.13430000"],["111575.27000000","0.08507000"],["111576.48000000","0.08505000"],["111576.86000000","0.00179000"],["111577.12000000","0.00000000"],["111577.14000000","0.00179000"],["111577.17000000","0.15952000"],["111577.30000000","0.00268000"],["111578.30000000","0.00000000"],["111579.28000000","0.00000000"],["111579.67000000","0.18889000"],["111583.46000000","0.08507000"],["111583.99000000","0.04123000"],["111584.61000000","0.64321000"],["111584.67000000","0.02128000"],["111588.23000000","0.00000000"],["111589.92000000","0.00000000"],["111590.16000000","0.08505000"],["111591.81000000","0.00010000"],["111592.28000000","0.00000000"],["111593.34000000","0.03675000"],["111593.55000000","0.00005000"],["111597.57000000","0.00000000"],["111598.02000000","0.00005000"],["111602.69000000","0.05438000"],["111602.81000000","0.13444000"],["111602.98000000","0.00000000"],["111603.21000000","0.00627000"],["111603.24000000","0.00000000"],["111603.25000000","0.00000000"],["111605.28000000","0.00000000"],["111606.16000000","0.00000000"],["111606.29000000","0.00000000"],["111607.22000000","0.00000000"],["111608.38000000","0.00661000"],["111609.38000000","0.02185000"],["111609.63000000","0.00000000"],["111611.12000000","0.00000000"],["111611.27000000","0.00448000"],["111611.48000000","0.00000000"],["111611.94000000","0.00448000"],["111612.27000000","0.35816000"],["111612.55000000","0.00000000"],["111612.68000000","0.00000000"],["111613.31000000","0.00000000"],["111613.39000000","0.02510000"],["111613.48000000","0.00000000"],["111613.75000000","0.00628000"],["111614.98000000","0.00000000"],["111615.00000000","0.00000000"],["111616.82000000","0.00000000"],["111616.83000000","0.00000000"],["111618.02000000","0.00000000"],["111618.31000000","0.00000000"],["111618.97000000","0.35816000"],["111621.97000000","0.00000000"],["111621.98000000","0.00000000"],["111623.27000000","0.00223000"],["111623.28000000","0.44462000"],["111623.81000000","0.01800000"],["111624.00000000","0.00265000"],["111625.67000000","0.35816000"],["111627.13000000","0.00000000"],["111629.98000000","0.00000000"],["111630.31000000","0.02175000"],["111632.37000000","0.35816000"],["111633.42000000","0.00109000"],["111633.98000000","0.00000000"],["111634.23000000","0.00000000"],["111637.91000000","0.13434000"],["111639.99000000","0.00000000"],["111640.04000000","1.25396000"],["111642.34000000","0.00000000"],["111644.47000000","0.00000000"],["111645.70000000","0.00223000"],["111647.96000000","0.00223000"],["111648.87000000","0.00000000"],["111649.06000000","0.00000000"],["111652.65000000","0.00000000"],["111652.66000000","0.00000000"],["111652.80000000","0.00000000"],["111653.43000000","0.00000000"],["111653.52000000","0.00000000"],["111654.78000000","0.00000000"],["111654.94000000","0.00000000"],["111655.40000000","0.00000000"],["111655.85000000","0.08408000"],["111657.01000000","0.00000000"],["111658.80000000","0.00000000"],["111660.24000000","0.00000000"],["111660.91000000","0.00000000"],["111662.58000000","0.00000000"],["111662.83000000","0.09449000"],["111664.26000000","0.00000000"],["111664.98000000","0.13444000"],["111665.20000000","0.00000000"],["111667.27000000","0.11018000"],["111667.28000000","0.00000000"],["111668.01000000","0.00000000"],["111668.94000000","0.00000000"],["111670.59000000","0.00000000"],["111670.90000000","0.99094000"],["111671.33000000","0.00000000"],["111671.48000000","0.00000000"],["111674.07000000","0.00000000"],["111674.08000000","0.00000000"],["111674.16000000","0.00000000"],["111675.90000000","0.00000000"],["111676.25000000","0.06000000"],["111676.94000000","0.00000000"],["111680.68000000","0.07807000"],["111681.62000000","0.08903000"],["111684.36000000","0.09759000"],["111689.64000000","0.00000000"],["111690.46000000","0.00000000"],["111699.33000000","0.00000000"],["111699.56000000","0.00000000"],["111700.23000000","0.00000000"],["111701.29000000","0.00000000"],["111701.46000000","0.17314000"],["111702.33000000","0.00000000"],["111703.21000000","0.00007000"],["111703.87000000","0.00000000"],["111703.94000000","0.00000000"],["111706.89000000","0.00000000"],["111707.56000000","0.00000000"],["111708.48000000","0.07500000"],["111708.50000000","0.00000000"],["111709.21000000","0.00000000"],["111709.38000000","0.00000000"],["111711.92000000","0.02691000"],["111712.80000000","0.00000000"],["111714.20000000","0.00000000"],["111714.41000000","0.01236000"],["111714.76000000","0.02420000"],["111719.07000000","0.44680000"],["111722.85000000","0.00000000"],["111723.99000000","1.47973000"],["111725.58000000","0.08795000"],["111726.01000000","0.04947000"],["111727.17000000","0.08795000"],["111729.27000000","0.08795000"],["111729.38000000","0.08795000"],["111730.22000000","0.08795000"],["111731.74000000","0.08795000"],["111732.06000000","0.08795000"],["111733.34000000","0.08795000"],["111734.31000000","0.34629000"],["111734.79000000","0.00089000"],["111735.16000000","0.08795000"],["111735.80000000","0.08795000"],["111735.91000000","0.08795000"],["111738.60000000","0.08795000"],["111739.38000000","0.08795000"],["111739.82000000","0.08795000"],["111741.14000000","0.00000000"],["111742.93000000","0.08795000"],["111743.14000000","0.08795000"],["111744.73000000","0.08795000"],["111744.76000000","0.08795000"],["111745.17000000","0.08795000"],["111745.34000000","0.00000000"],["111746.95000000","0.26385000"],["111753.18000000","0.00000000"],["111756.94000000","0.00089000"],["111758.16000000","0.02420000"],["111758.30000000","0.00000000"],["111758.91000000","0.00089000"],["111760.00000000","0.00443000"],["111761.14000000","0.02420000"],["111765.23000000","0.00000000"],["111766.84000000","0.00000000"],["111767.34000000","0.00000000"],["111768.17000000","0.00000000"],["111776.37000000","0.03997000"],["111778.02000000","0.00000000"],["111778.74000000","0.00000000"],["111781.76000000","0.04007000"],["111782.35000000","0.08795000"],["111784.16000000","0.17590000"],["111785.71000000","0.08794000"],["111792.55000000","0.03997000"],["111797.90000000","0.03997000"],["111800.41000000","0.03997000"],["111803.02000000","0.03997000"],["111803.93000000","0.01703000"],["111804.11000000","0.00000000"],["111811.60000000","0.02398000"],["111812.09000000","0.01703000"],["111832.31000000","0.00010000"],["111834.34000000","0.00000000"],["111834.40000000","0.00000000"],["111839.90000000","0.00000000"],["111840.16000000","0.00010000"],["111840.90000000","0.00000000"],["111844.87000000","0.00000000"],["111845.27000000","0.00000000"],["111845.29000000","0.00000000"],["111845.47000000","0.00000000"],["111845.73000000","0.00010000"],["111845.99000000","0.00000000"],["111846.64000000","0.00000000"],["111846.69000000","0.00000000"],["111846.70000000","0.00000000"],["111848.03000000","0.00000000"],["111848.23000000","0.00000000"],["111849.16000000","0.00006000"],["111849.60000000","0.00000000"],["111850.32000000","0.00000000"],["111851.07000000","0.00000000"],["111852.48000000","0.00000000"],["111853.88000000","0.00000000"],["111854.15000000","0.00000000"],["111854.20000000","0.00000000"],["111855.80000000","0.03997000"],["111855.96000000","0.00000000"],["111856.89000000","0.03997000"],["111858.15000000","0.00000000"],["111859.97000000","0.00000000"],["111862.59000000","0.03997000"],["111867.09000000","0.03997000"],["111871.67000000","0.03997000"],["111876.37000000","0.05896000"],["111876.69000000","0.05896000"],["111876.91000000","0.03997000"],["111877.07000000","0.05896000"],["111877.45000000","0.05896000"],["111878.28000000","0.05896000"],["111878.71000000","0.02689000"],["111879.17000000","0.05896000"],["111880.00000000","0.04126000"],["111880.36000000","0.05896000"],["111880.67000000","0.03997000"],["111881.12000000","0.05896000"],["111881.32000000","0.02689000"],["111881.60000000","0.05896000"],["111883.27000000","0.05896000"],["111883.76000000","0.12542000"],["111884.16000000","0.05896000"],["111885.41000000","0.05896000"],["111885.78000000","0.00000000"],["111886.83000000","0.05896000"],["111887.59000000","0.00000000"],["111887.79000000","0.00000000"],["111889.07000000","0.05896000"],["111889.70000000","0.05896000"],["111889.93000000","0.00000000"],["111890.28000000","0.05896000"],["111892.91000000","0.03586000"],["111893.76000000","0.00000000"],["111895.41000000","0.03586000"],["111895.89000000","0.07261000"],["111895.92000000","0.03586000"],["111896.96000000","0.00000000"],["111898.32000000","0.00000000"],["111899.16000000","0.00000000"],["111902.05000000","0.00000000"],["111905.32000000","0.00000000"],["111908.44000000","0.02689000"],["111910.10000000","0.02689000"],["111921.82000000","0.00005000"],["111927.34000000","0.94995000"],["111977.82000000","0.00000000"],["111983.90000000","0.00000000"],["111987.25000000","0.00000000"],["111987.41000000","0.00000000"],["112028.40000000","0.03676000"],["112034.50000000","0.03676000"],["112039.57000000","0.07352000"],["112041.24000000","0.03675000"],["112047.05000000","0.03675000"],["112065.18000000","0.00000000"],["112070.88000000","0.00000000"],["112105.97000000","0.00000000"],["112107.02000000","0.00000000"],["112107.56000000","0.00000000"],["112107.57000000","0.00000000"],["112107.64000000","0.00000000"],["112111.72000000","0.02398000"],["112127.64000000","0.02398000"],["112142.86000000","0.02398000"],["112143.07000000","0.02398000"],["112143.25000000","0.02398000"],["112143.41000000","0.02398000"],["112144.21000000","0.02398000"],["112145.39000000","0.02434000"],["112145.83000000","0.02398000"],["112145.86000000","0.04796000"],["113199.27000000","0.00000000"],["113204.00000000","0.00000000"]]}
[2025-10-12T11:05:00.185Z] {"e":"depthUpdate","E":1760267100014,"s":"BTCUSDT","U":77965291736,"u":77965294766,"b":[["111553.66000000","7.31303000"],["111553.65000000","0.20633000"],["111553.64000000","0.00010000"],["111553.60000000","0.00000000"],["111553.58000000","0.00010000"],["111553.54000000","0.00000000"],["111553.50000000","0.00991000"],["111553.49000000","0.00010000"],["111553.32000000","0.00005000"],["111553.27000000","0.01345000"],["111552.73000000","0.00000000"],["111552.55000000","0.02786000"],["111552.54000000","0.04081000"],["111552.53000000","0.00000000"],["111552.45000000","0.00005000"],["111551.99000000","0.00000000"],["111551.86000000","0.00000000"],["111551.45000000","0.00000000"],["111551.44000000","0.00000000"],["111551.43000000","0.00364000"],["111550.74000000","0.00000000"],["111550.52000000","0.04163000"],["111550.45000000","0.00000000"],["111550.25000000","0.01819000"],["111550.24000000","0.00000000"],["111549.99000000","0.00000000"],["111549.76000000","0.00538000"],["111549.51000000","0.06656000"],["111548.97000000","0.21543000"],["111548.96000000","0.35816000"],["111548.85000000","0.00005000"],["111548.65000000","0.00722000"],["111548.08000000","0.00052000"],["111547.99000000","0.00000000"],["111547.69000000","0.00044000"],["111547.57000000","0.00000000"],["111547.53000000","0.01793000"],["111547.38000000","0.00000000"],["111546.93000000","0.00000000"],["111546.43000000","0.00000000"],["111546.35000000","0.00000000"],["111545.99000000","0.00000000"],["111545.92000000","0.00000000"],["111545.51000000","0.00000000"],["111545.47000000","0.00000000"],["111545.29000000","0.11195000"],["111545.00000000","0.00400000"],["111544.86000000","0.00005000"],["111544.85000000","0.35816000"],["111544.76000000","0.00000000"],["111544.43000000","0.00000000"],["111544.38000000","0.00005000"],["111543.99000000","0.00000000"],["111543.64000000","0.00000000"],["111543.30000000","0.00000000"],["111543.06000000","0.00000000"],["111542.50000000","0.00314000"],["111542.19000000","0.42071000"],["111542.18000000","0.00000000"],["111542.02000000","0.00000000"],["111542.01000000","0.15000000"],["111542.00000000","0.00000000"],["111541.99000000","0.99386000"],["111541.98000000","0.00000000"],["111541.97000000","0.00000000"],["111541.94000000","0.00005000"],["111541.93000000","0.00000000"],["111541.92000000","0.00000000"],["111541.90000000","0.00000000"],["111541.89000000","0.00000000"],["111541.78000000","0.00000000"],["111541.77000000","0.00000000"],["111541.59000000","0.00000000"],["111541.58000000","0.00000000"],["111541.50000000","0.00000000"],["111541.49000000","0.00000000"],["111541.48000000","0.00000000"],["111541.47000000","0.35816000"],["111541.46000000","0.00000000"],["111541.43000000","0.00000000"],["111541.42000000","0.00000000"],["111541.28000000","0.00007000"],["111540.93000000","0.06656000"],["111540.01000000","0.00000000"],["111540.00000000","0.00000000"],["111539.99000000","0.00000000"],["111539.94000000","0.00000000"],["111539.92000000","0.00000000"],["111539.91000000","0.00005000"],["111539.90000000","0.00000000"],["111539.86000000","0.00458000"],["111539.85000000","0.00000000"],["111539.68000000","0.00000000"],["111539.64000000","0.00000000"],["111539.59000000","0.00000000"],["111539.45000000","0.00043000"],["111539.13000000","0.00000000"],["111538.80000000","0.04800000"],["111538.30000000","1.25396000"],["111538.29000000","0.00000000"],["111538.27000000","0.70313000"],["111538.26000000","0.10000000"],["111538.25000000","0.00005000"],["111538.24000000","0.04003000"],["111538.23000000","0.00000000"],["111538.19000000","0.00000000"],["111538.18000000","0.00000000"],["111538.17000000","0.00000000"],["111538.13000000","0.04168000"],["111538.11000000","0.00044000"],["111538.10000000","0.00000000"],["111538.00000000","0.35826000"],["111537.99000000","0.00000000"],["111537.98000000","0.00000000"],["111537.80000000","0.05760000"],["111537.79000000","0.05760000"],["111537.72000000","0.00000000"],["111537.48000000","0.17432000"],["111537.47000000","0.00000000"],["111537.45000000","0.00000000"],["111537.44000000","0.00000000"],["111537.43000000","0.01790000"],["111537.34000000","0.08505000"],["111537.30000000","0.00000000"],["111536.97000000","0.00000000"],["111536.96000000","0.00000000"],["111536.93000000","0.00150000"],["111536.90000000","0.00000000"],["111536.65000000","0.00000000"],["111535.80000000","0.00000000"],["111535.76000000","0.00000000"],["111535.28000000","0.00989000"],["111535.02000000","0.01165000"],["111535.00000000","0.00007000"],["111534.89000000","0.00000000"],["111534.85000000","0.04456000"],["111534.77000000","0.00000000"],["111534.73000000","0.03998000"],["111534.54000000","0.00000000"],["111534.40000000","0.07680000"],["111534.31000000","0.00000000"],["111534.21000000","0.03448000"],["111534.03000000","0.00000000"],["111533.99000000","0.03998000"],["111533.87000000","0.08507000"],["111533.80000000","0.00000000"],["111533.68000000","0.00000000"],["111533.62000000","0.00000000"],["111533.39000000","0.00000000"],["111533.35000000","0.03998000"],["111533.26000000","0.05760000"],["111533.05000000","0.00000000"],["111532.83000000","0.04479000"],["111532.46000000","0.03998000"],["111532.43000000","0.00010000"],["111532.22000000","0.02000000"],["111532.19000000","0.07200000"],["111532.11000000","1.17191000"],["111532.10000000","1.25396000"],["111532.00000000","0.00400000"],["111531.82000000","0.04000000"],["111531.77000000","0.00000000"],["111531.51000000","0.00000000"],["111531.46000000","0.00000000"],["111531.06000000","0.00000000"],["111531.05000000","0.00000000"],["111531.03000000","0.35843000"],["111531.02000000","0.03998000"],["111530.42000000","0.00000000"],["111530.28000000","0.00000000"],["111530.25000000","0.00000000"],["111530.24000000","0.35823000"],["111530.23000000","0.03998000"],["111530.05000000","0.00000000"],["111529.20000000","0.00000000"],["111529.19000000","0.03998000"],["111529.12000000","0.00022000"],["111528.84000000","0.00044000"],["111528.76000000","0.00000000"],["111528.74000000","1.25396000"],["111528.56000000","0.00005000"],["111528.39000000","0.00000000"],["111528.38000000","0.03998000"],["111527.80000000","0.00044000"],["111527.78000000","0.00000000"],["111527.32000000","0.00000000"],["111527.11000000","0.00000000"],["111527.10000000","0.00000000"],["111527.09000000","0.92275000"],["111527.08000000","0.45000000"],["111526.49000000","0.00000000"],["111526.44000000","0.00000000"],["111526.36000000","0.13704000"],["111526.34000000","0.00000000"],["111526.33000000","0.16829000"],["111526.17000000","0.00000000"],["111526.12000000","0.00000000"],["111526.08000000","0.00010000"],["111525.94000000","0.00000000"],["111525.84000000","0.00000000"],["111525.79000000","0.00000000"],["111525.50000000","0.00000000"],["111525.44000000","0.00000000"],["111525.42000000","0.01388000"],["111525.33000000","0.00000000"],["111525.21000000","0.00000000"],["111525.12000000","0.06720000"],["111524.92000000","0.13430000"],["111524.88000000","0.00000000"],["111524.86000000","1.25396000"],["111524.50000000","0.00000000"],["111524.45000000","0.00000000"],["111524.32000000","0.56000000"],["111524.10000000","0.00000000"],["111523.86000000","0.00000000"],["111523.69000000","0.13430000"],["111523.33000000","0.00000000"],["111523.27000000","0.00000000"],["111522.70000000","0.30240000"],["111522.48000000","0.00005000"],["111522.43000000","0.00000000"],["111522.18000000","0.00006000"],["111521.53000000","0.00000000"],["111521.52000000","0.00000000"],["111521.34000000","0.00000000"],["111521.01000000","0.04426000"],["111520.30000000","0.00000000"],["111520.20000000","0.04481000"],["111520.15000000","0.00000000"],["111520.07000000","0.00000000"],["111519.54000000","0.00000000"],["111519.51000000","0.00000000"],["111519.18000000","0.00000000"],["111518.89000000","0.00000000"],["111518.77000000","0.00000000"],["111518.72000000","0.00000000"],["111518.32000000","0.00000000"],["111518.27000000","0.00000000"],["111518.13000000","0.07920000"],["111518.11000000","0.00000000"],["111518.00000000","0.00000000"],["111517.89000000","0.00000000"],["111517.84000000","0.00000000"],["111517.78000000","0.00000000"],["111516.89000000","0.10080000"],["111516.51000000","0.00000000"],["111516.50000000","0.00000000"],["111516.36000000","0.00000000"],["111516.35000000","0.00000000"],["111516.14000000","0.00000000"],["111515.61000000","0.00000000"],["111515.35000000","0.00000000"],["111515.28000000","0.00000000"],["111515.20000000","0.00000000"],["111515.19000000","0.00000000"],["111514.75000000","0.00012000"],["111514.63000000","0.00000000"],["111514.57000000","0.02128000"],["111513.89000000","0.00000000"],["111513.86000000","0.31984000"],["111513.15000000","0.00009000"],["111512.83000000","0.08000000"],["111512.26000000","0.00270000"],["111512.21000000","0.00000000"],["111512.15000000","0.00000000"],["111512.00000000","0.00000000"],["111511.95000000","0.00000000"],["111511.43000000","0.00000000"],["111511.15000000","0.00000000"],["111511.11000000","0.00000000"],["111510.94000000","0.00018000"],["111510.43000000","0.00000000"],["111509.35000000","0.00000000"],["111508.62000000","0.00000000"],["111508.35000000","0.01701000"],["111508.19000000","0.00000000"],["111507.52000000","0.00000000"],["111506.98000000","0.00438000"],["111506.96000000","0.00000000"],["111506.81000000","0.22384000"],["111506.05000000","0.00000000"],["111504.15000000","0.00000000"],["111504.02000000","0.00000000"],["111503.68000000","0.00000000"],["111502.92000000","0.00000000"],["111502.77000000","0.00009000"],["111502.22000000","0.00000000"],["111501.81000000","0.00000000"],["111501.65000000","0.00000000"],["111501.24000000","0.00000000"],["111500.23000000","0.00000000"],["111500.00000000","0.00100000"],["111499.60000000","0.08508000"],["111498.47000000","0.00000000"],["111498.43000000","0.17932000"],["111498.14000000","0.00000000"],["111496.66000000","0.00000000"],["111495.93000000","0.00000000"],["111495.74000000","0.00000000"],["111495.70000000","0.00000000"],["111495.54000000","0.00000000"],["111495.40000000","0.00007000"],["111494.50000000","0.04048000"],["111493.93000000","0.18904000"],["111492.81000000","0.00000000"],["111491.39000000","0.00000000"],["111488.75000000","0.00000000"],["111488.68000000","0.00000000"],["111488.17000000","0.00000000"],["111487.77000000","0.00000000"],["111487.69000000","0.00380000"],["111483.05000000","0.00000000"],["111481.41000000","0.00000000"],["111477.54000000","0.00617000"],["111477.53000000","0.00665000"],["111475.50000000","0.00000000"],["111474.47000000","0.02140000"],["111474.01000000","0.00222000"],["111468.81000000","0.01438000"],["111468.23000000","0.00000000"],["111467.49000000","0.00090000"],["111467.15000000","0.24234000"],["111466.34000000","0.17589000"],["111464.75000000","0.00000000"],["111463.03000000","0.13434000"],["111462.90000000","0.00000000"],["111460.55000000","0.00000000"],["111460.23000000","0.00000000"],["111459.52000000","0.00000000"],["111459.51000000","0.00000000"],["111459.48000000","0.00000000"],["111458.02000000","0.00164000"],["111457.25000000","0.00000000"],["111454.21000000","0.00222000"],["111454.20000000","0.21631000"],["111454.02000000","0.00000000"],["111453.78000000","0.00000000"],["111452.68000000","0.02468000"],["111452.49000000","0.00000000"],["111452.40000000","0.02510000"],["111450.55000000","0.00000000"],["111450.18000000","0.00000000"],["111449.13000000","0.00000000"],["111448.62000000","0.01800000"],["111448.46000000","0.36595000"],["111448.45000000","0.00000000"],["111446.67000000","0.00111000"],["111446.01000000","0.00000000"],["111445.94000000","0.03958000"],["111445.63000000","0.00000000"],["111445.59000000","0.00000000"],["111444.79000000","0.00000000"],["111444.78000000","0.00000000"],["111444.35000000","0.00000000"],["111442.64000000","0.02420000"],["111442.24000000","0.11219000"],["111440.22000000","0.00000000"],["111439.53000000","0.09759000"],["111439.37000000","0.05760000"],["111437.27000000","0.00000000"],["111436.96000000","0.00000000"],["111435.95000000","0.22506000"],["111435.49000000","0.00000000"],["111432.14000000","0.00008000"],["111430.71000000","0.23726000"],["111430.26000000","0.22384000"],["111429.98000000","0.00000000"],["111429.11000000","0.00000000"],["111428.98000000","0.00000000"],["111427.38000000","0.13444000"],["111426.67000000","0.00196000"],["111425.56000000","0.01403000"],["111424.76000000","0.00000000"],["111424.61000000","0.00000000"],["111420.00000000","0.00563000"],["111417.66000000","0.08794000"],["111415.19000000","0.08856000"],["111410.93000000","0.00000000"],["111410.66000000","0.08794000"],["111409.61000000","0.21146000"],["111408.75000000","0.08794000"],["111407.93000000","0.08794000"],["111407.89000000","0.08794000"],["111405.96000000","0.08794000"],["111405.95000000","0.08794000"],["111404.09000000","0.00000000"],["111402.17000000","0.02689000"],["111401.86000000","0.00000000"],["111400.00000000","1.09977000"],["111395.30000000","0.08634000"],["111388.15000000","0.00000000"],["111386.65000000","0.02510000"],["111380.80000000","0.00005000"],["111380.00000000","0.00117000"],["111368.83000000","0.15857000"],["111365.57000000","0.00000000"],["111364.92000000","0.00000000"],["111364.08000000","0.00000000"],["111363.69000000","0.00000000"],["111363.43000000","0.00000000"],["111362.45000000","0.00000000"],["111362.40000000","0.00000000"],["111362.05000000","0.00000000"],["111361.60000000","0.00000000"],["111360.00000000","0.00171000"],["111358.56000000","0.00000000"],["111353.10000000","0.09475000"],["111351.32000000","0.51857000"],["111347.16000000","0.00000000"],["111344.21000000","0.08794000"],["111343.43000000","0.00089000"],["111342.79000000","0.08794000"],["111338.45000000","0.00000000"],["111338.39000000","0.00000000"],["111327.85000000","0.00000000"],["111327.84000000","0.00000000"],["111305.40000000","0.00000000"],["111302.89000000","0.00000000"],["111302.88000000","0.00000000"],["111302.17000000","0.00000000"],["111300.78000000","0.00000000"],["111297.74000000","4.81007000"],["111296.85000000","0.01703000"],["111293.04000000","0.00000000"],["111278.34000000","0.00000000"],["111274.76000000","0.18197000"],["111270.85000000","0.00000000"],["111251.97000000","0.05896000"],["111251.48000000","0.05896000"],["111250.90000000","0.05896000"],["111246.86000000","0.00000000"],["111230.19000000","0.00000000"],["111227.11000000","0.00000000"],["111225.79000000","0.05896000"],["111225.48000000","0.05896000"],["111225.09000000","0.05896000"],["111224.74000000","0.05896000"],["111223.36000000","0.00000000"],["111222.61000000","0.05896000"],["111220.25000000","0.00000000"],["111214.53000000","0.03675000"],["111214.22000000","0.03675000"],["111198.19000000","0.45000000"],["111176.25000000","0.21417000"],["111173.50000000","0.00000000"],["111155.62000000","0.03675000"],["111133.07000000","0.00000000"],["111132.80000000","0.00000000"],["111132.22000000","0.00000000"],["111131.26000000","0.00000000"],["111130.59000000","0.00000000"],["111130.16000000","0.00000000"],["111129.86000000","0.00000000"],["111124.50000000","0.00000000"],["111123.40000000","0.00000000"],["111115.06000000","0.00000000"],["111112.60000000","0.00000000"],["111098.58000000","0.00000000"],["111003.67000000","0.00000000"],["109880.35000000","0.00100000"],["109864.41000000","0.00000000"],["109500.00000000","12.83832000"],["102591.46000000","0.00010000"],["100397.00000000","0.00010000"],["100386.00000000","0.00282000"],["100382.00000000","0.00000000"],["89242.93000000","0.00022000"],["89233.60000000","0.00000000"],["89230.60000000","0.00000000"],["78084.11000000","0.00000000"],["78079.63000000","0.00000000"]],"a":[["111538.25000000","0.00000000"],["111538.26000000","0.00000000"],["111538.27000000","0.00000000"],["111539.65000000","0.00000000"],["111539.69000000","0.00000000"],["111540.00000000","0.00000000"],["111540.01000000","0.00000000"],["111540.02000000","0.00000000"],["111540.03000000","0.00000000"],["111541.43000000","0.00000000"],["111541.47000000","0.00000000"],["111541.51000000","0.00000000"],["111541.60000000","0.00000000"],["111541.74000000","0.00000000"],["111541.79000000","0.00000000"],["111542.00000000","0.00000000"],["111542.01000000","0.00000000"],["111542.02000000","0.00000000"],["111542.74000000","0.00000000"],["111542.77000000","0.00000000"],["111543.07000000","0.00000000"],["111543.31000000","0.00000000"],["111543.65000000","0.00000000"],["111544.00000000","0.00000000"],["111544.01000000","0.00000000"],["111544.32000000","0.00000000"],["111544.64000000","0.00000000"],["111544.70000000","0.00000000"],["111544.72000000","0.00000000"],["111544.77000000","0.00000000"],["111544.95000000","0.00000000"],["111545.15000000","0.00000000"],["111545.52000000","0.00000000"],["111545.53000000","0.00000000"],["111545.90000000","0.00000000"],["111545.91000000","0.00000000"],["111545.92000000","0.00000000"],["111545.93000000","0.00000000"],["111545.94000000","0.00000000"],["111546.00000000","0.00000000"],["111546.35000000","0.00000000"],["111546.36000000","0.00000000"],["111546.41000000","0.00000000"],["111546.44000000","0.00000000"],["111546.94000000","0.00000000"],["111547.38000000","0.00000000"],["111547.39000000","0.00000000"],["111548.00000000","0.00000000"],["111548.30000000","0.00000000"],["111549.02000000","0.00000000"],["111549.54000000","0.00000000"],["111549.99000000","0.00000000"],["111550.00000000","0.00000000"],["111550.13000000","0.00000000"],["111550.28000000","0.00000000"],["111550.45000000","0.00000000"],["111550.46000000","0.00000000"],["111550.62000000","0.00000000"],["111550.63000000","0.00000000"],["111550.75000000","0.00000000"],["111550.76000000","0.00000000"],["111550.80000000","0.00000000"],["111550.93000000","0.00000000"],["111551.24000000","0.00000000"],["111551.42000000","0.00000000"],["111551.45000000","0.00000000"],["111551.65000000","0.00000000"],["111551.90000000","0.00000000"],["111551.91000000","0.00000000"],["111551.97000000","0.00000000"],["111551.98000000","0.00000000"],["111552.00000000","0.00000000"],["111552.14000000","0.00000000"],["111552.74000000","0.00000000"],["111553.66000000","0.00000000"],["111553.67000000","0.15746000"],["111553.68000000","0.00090000"],["111553.69000000","0.00020000"],["111553.70000000","0.00005000"],["111553.75000000","0.00010000"],["111553.82000000","0.00010000"],["111553.83000000","0.00921000"],["111553.84000000","0.00020000"],["111553.95000000","0.00000000"],["111553.96000000","0.00000000"],["111554.00000000","0.00260000"],["111554.01000000","0.00010000"],["111554.05000000","0.00010000"],["111554.06000000","0.01350000"],["111554.07000000","0.00010000"],["111554.65000000","0.00000000"],["111555.02000000","0.00000000"],["111555.17000000","0.00000000"],["111555.24000000","0.00000000"],["111555.27000000","0.00000000"],["111555.51000000","0.00000000"],["111555.52000000","0.00000000"],["111555.54000000","0.00000000"],["111555.55000000","0.00000000"],["111555.56000000","0.00000000"],["111555.60000000","0.00005000"],["111555.71000000","0.00000000"],["111555.72000000","0.00000000"],["111555.84000000","0.00000000"],["111555.90000000","0.00359000"],["111556.00000000","0.00260000"],["111556.01000000","0.00000000"],["111556.36000000","0.00000000"],["111556.46000000","0.00000000"],["111556.96000000","0.00000000"],["111557.02000000","0.00000000"],["111557.03000000","0.00000000"],["111557.14000000","0.00000000"],["111557.15000000","0.00005000"],["111557.42000000","0.00000000"],["111557.48000000","0.00000000"],["111557.57000000","0.00543000"],["111557.58000000","0.00000000"],["111557.59000000","0.00000000"],["111557.79000000","0.00000000"],["111558.00000000","0.00265000"],["111558.01000000","0.00000000"],["111558.16000000","0.00000000"],["111558.29000000","0.00005000"],["111558.32000000","0.00000000"],["111558.33000000","0.00000000"],["111558.68000000","0.00722000"],["111558.70000000","0.00000000"],["111558.73000000","0.00155000"],["111559.02000000","0.00000000"],["111559.71000000","0.00010000"],["111559.72000000","0.01402000"],["111559.79000000","0.00010000"],["111559.80000000","0.01811000"],["111559.81000000","0.00000000"],["111560.00000000","0.00260000"],["111560.17000000","0.00000000"],["111560.29000000","0.00000000"],["111560.30000000","0.00000000"],["111560.93000000","0.00000000"],["111560.94000000","0.00000000"],["111560.95000000","0.00005000"],["111560.96000000","0.00000000"],["111561.36000000","0.00010000"],["111561.37000000","0.00005000"],["111561.65000000","0.00000000"],["111561.70000000","0.00005000"],["111561.71000000","0.02566000"],["111561.84000000","0.00005000"],["111561.95000000","0.00000000"],["111561.96000000","0.00000000"],["111561.97000000","0.00005000"],["111562.00000000","0.00260000"],["111562.03000000","0.00000000"],["111562.26000000","0.00000000"],["111562.76000000","0.00000000"],["111562.77000000","0.00000000"],["111563.31000000","0.00000000"],["111563.32000000","0.00000000"],["111563.35000000","0.00000000"],["111563.40000000","0.30241000"],["111563.54000000","0.00000000"],["111563.80000000","0.00000000"],["111563.88000000","0.00000000"],["111563.92000000","0.00000000"],["111563.93000000","0.00005000"],["111564.00000000","0.00260000"],["111564.22000000","0.00005000"],["111564.30000000","0.00000000"],["111564.60000000","0.00005000"],["111564.83000000","0.00150000"],["111564.87000000","0.02000000"],["111565.97000000","0.60000000"],["111566.00000000","0.00265000"],["111566.07000000","0.00000000"],["111566.08000000","0.00000000"],["111566.63000000","0.00000000"],["111566.64000000","0.00000000"],["111566.65000000","0.00000000"],["111566.66000000","0.00000000"],["111566.67000000","0.36027000"],["111566.68000000","0.00000000"],["111566.72000000","0.04805000"],["111566.73000000","0.00000000"],["111566.88000000","0.06245000"],["111567.61000000","0.04481000"],["111567.87000000","0.00000000"],["111567.88000000","0.00000000"],["111567.89000000","0.00000000"],["111568.00000000","0.00260000"],["111568.17000000","0.00005000"],["111568.25000000","0.00000000"],["111568.27000000","0.00332000"],["111568.49000000","0.00300000"],["111568.88000000","0.00000000"],["111568.94000000","0.01388000"],["111568.99000000","0.00074000"],["111569.09000000","0.00000000"],["111569.12000000","0.00000000"],["111569.13000000","0.00000000"],["111569.38000000","0.00069000"],["111569.90000000","0.00000000"],["111570.00000000","0.00260000"],["111570.19000000","0.00992000"],["111570.28000000","0.00005000"],["111570.40000000","0.00150000"],["111570.63000000","0.00000000"],["111570.69000000","0.00007000"],["111571.31000000","0.00000000"],["111571.68000000","0.00000000"],["111571.80000000","0.00000000"],["111571.88000000","0.00000000"],["111571.91000000","0.00000000"],["111572.11000000","0.00000000"],["111572.25000000","0.04800000"],["111572.31000000","0.01330000"],["111572.38000000","0.00000000"],["111572.43000000","0.04002000"],["111572.57000000","0.00000000"],["111572.59000000","0.30263000"],["111572.60000000","0.00000000"],["111573.05000000","0.00000000"],["111573.25000000","0.00000000"],["111573.27000000","0.00000000"],["111573.30000000","0.00000000"],["111573.35000000","0.00000000"],["111573.37000000","0.00000000"],["111573.81000000","0.00000000"],["111574.06000000","0.00000000"],["111574.07000000","0.00000000"],["111574.08000000","0.00000000"],["111574.14000000","0.00000000"],["111574.30000000","0.00000000"],["111574.52000000","0.00000000"],["111575.26000000","0.00000000"],["111575.27000000","0.00000000"],["111575.40000000","0.00000000"],["111575.98000000","0.11195000"],["111575.99000000","0.00748000"],["111576.48000000","0.00000000"],["111576.52000000","0.00005000"],["111576.86000000","0.00000000"],["111576.88000000","0.00000000"],["111577.14000000","0.00000000"],["111577.17000000","0.00000000"],["111577.30000000","0.00000000"],["111577.59000000","0.08507000"],["111578.21000000","0.00022000"],["111578.70000000","0.00000000"],["111578.71000000","0.00000000"],["111578.72000000","0.55669000"],["111578.93000000","0.00000000"],["111579.10000000","0.00000000"],["111579.42000000","0.04800000"],["111579.67000000","0.00000000"],["111579.99000000","0.00000000"],["111580.04000000","0.00000000"],["111580.05000000","0.35841000"],["111580.85000000","0.04800000"],["111581.64000000","0.00000000"],["111581.95000000","0.04800000"],["111582.66000000","0.04479000"],["111582.67000000","0.01164000"],["111582.96000000","0.00895000"],["111583.08000000","0.04800000"],["111583.70000000","0.00000000"],["111583.99000000","0.02620000"],["111584.06000000","0.00442000"],["111584.30000000","0.00000000"],["111584.35000000","0.00000000"],["111584.59000000","0.15000000"],["111584.90000000","0.00000000"],["111586.65000000","0.05896000"],["111586.73000000","0.15000000"],["111587.13000000","0.04482000"],["111587.14000000","0.00300000"],["111587.70000000","0.00000000"],["111587.96000000","0.00000000"],["111587.98000000","0.02126000"],["111588.30000000","0.04000000"],["111589.09000000","0.02420000"],["111589.10000000","0.96632000"],["111589.22000000","0.13430000"],["111589.66000000","0.17932000"],["111590.01000000","0.00000000"],["111590.41000000","0.13434000"],["111590.45000000","0.13430000"],["111590.89000000","0.08507000"],["111590.90000000","0.00012000"],["111591.74000000","0.08505000"],["111591.99000000","0.02689000"],["111593.34000000","0.00000000"],["111593.35000000","0.00000000"],["111593.49000000","0.16092000"],["111594.00000000","0.02019000"],["111594.48000000","0.14957000"],["111594.49000000","0.00000000"],["111594.77000000","0.22384000"],["111595.27000000","0.00000000"],["111595.36000000","0.00179000"],["111595.54000000","0.08000000"],["111595.79000000","0.00276000"],["111597.99000000","0.05378000"],["111600.08000000","0.07316000"],["111601.99000000","0.00000000"],["111602.34000000","0.00000000"],["111602.49000000","0.00005000"],["111603.21000000","0.00000000"],["111603.40000000","0.00000000"],["111603.41000000","0.00000000"],["111603.99000000","0.00000000"],["111605.41000000","0.01701000"],["111605.99000000","0.03675000"],["111606.88000000","0.00000000"],["111606.96000000","0.00005000"],["111607.66000000","0.08508000"],["111607.99000000","0.00000000"],["111608.38000000","0.00005000"],["111609.02000000","0.00156000"],["111610.54000000","0.08000000"],["111610.69000000","0.00000000"],["111611.27000000","0.00000000"],["111611.94000000","0.00000000"],["111611.98000000","0.00000000"],["111611.99000000","0.00000000"],["111613.53000000","0.00000000"],["111613.90000000","0.00000000"],["111614.15000000","0.00000000"],["111614.90000000","0.00000000"],["111614.99000000","0.00000000"],["111615.33000000","0.00000000"],["111615.88000000","0.00000000"],["111615.90000000","0.00005000"],["111616.43000000","0.00000000"],["111617.17000000","0.00000000"],["111617.86000000","0.00615000"],["111617.99000000","0.00000000"],["111619.18000000","0.00000000"],["111620.46000000","0.00000000"],["111621.99000000","0.00000000"],["111623.27000000","0.00000000"],["111623.32000000","0.00651000"],["111623.81000000","0.00000000"],["111623.82000000","0.00000000"],["111624.13000000","0.00896000"],["111624.39000000","0.00000000"],["111625.13000000","0.00000000"],["111625.99000000","0.00000000"],["111627.90000000","0.00000000"],["111627.94000000","0.00000000"],["111627.96000000","0.70095000"],["111628.24000000","0.06869000"],["111628.74000000","0.00000000"],["111629.10000000","0.00000000"],["111629.21000000","0.02509000"],["111629.97000000","0.00000000"],["111630.25000000","0.00005000"],["111630.73000000","0.00000000"],["111630.74000000","0.00000000"],["111631.21000000","0.02398000"],["111632.00000000","0.00260000"],["111634.22000000","0.08277000"],["111635.38000000","0.00000000"],["111635.40000000","0.00005000"],["111636.51000000","0.00005000"],["111636.71000000","0.08494000"],["111637.91000000","0.00000000"],["111638.08000000","0.00000000"],["111638.09000000","0.00100000"],["111639.07000000","0.35816000"],["111639.23000000","0.00000000"],["111639.99000000","0.00222000"],["111640.03000000","0.73615000"],["111640.77000000","0.04800000"],["111640.86000000","0.04800000"],["111640.94000000","0.01800000"],["111641.18000000","0.03999000"],["111641.57000000","0.00000000"],["111641.58000000","0.00000000"],["111641.59000000","0.04197000"],["111641.60000000","0.00000000"],["111642.82000000","0.00000000"],["111643.74000000","0.00000000"],["111643.75000000","0.00000000"],["111644.39000000","0.00006000"],["111645.69000000","0.58205000"],["111645.70000000","1.25396000"],["111645.71000000","0.04197000"],["111645.99000000","0.00000000"],["111647.96000000","0.00000000"],["111647.98000000","0.00000000"],["111648.00000000","0.07460000"],["111649.22000000","0.00000000"],["111649.99000000","0.00000000"],["111650.68000000","0.02472000"],["111651.95000000","0.00000000"],["111651.97000000","0.00000000"],["111652.39000000","0.47893000"],["111652.40000000","1.25396000"],["111652.57000000","0.00000000"],["111652.89000000","0.13434000"],["111653.46000000","0.00000000"],["111655.84000000","0.04097000"],["111656.76000000","0.00000000"],["111656.93000000","0.00000000"],["111657.07000000","0.00000000"],["111658.03000000","0.01403000"],["111658.17000000","0.06023000"],["111659.16000000","0.01707000"],["111659.88000000","0.00000000"],["111660.00000000","0.02051000"],["111660.25000000","0.04800000"],["111660.65000000","0.04800000"],["111661.38000000","0.04800000"],["111661.98000000","0.00222000"],["111661.99000000","0.04097000"],["111662.05000000","0.00000000"],["111662.20000000","0.00005000"],["111662.49000000","0.04800000"],["111662.52000000","0.00000000"],["111662.82000000","0.00223000"],["111662.83000000","0.00000000"],["111663.32000000","0.22909000"],["111664.07000000","0.00196000"],["111664.71000000","0.00000000"],["111665.17000000","0.00000000"],["111665.99000000","0.00000000"],["111667.10000000","0.00000000"],["111667.26000000","0.04097000"],["111667.27000000","0.11018000"],["111667.98000000","0.00000000"],["111668.23000000","0.00000000"],["111670.90000000","0.00000000"],["111671.99000000","0.04097000"],["111673.68000000","0.05244000"],["111673.69000000","0.00000000"],["111674.85000000","0.00000000"],["111678.03000000","0.00000000"],["111678.09000000","0.09448000"],["111679.20000000","0.22384000"],["111679.64000000","0.00000000"],["111679.69000000","0.00000000"],["111679.78000000","0.04097000"],["111680.07000000","0.00000000"],["111681.85000000","0.00000000"],["111684.36000000","0.00000000"],["111684.56000000","0.36616000"],["111684.57000000","0.00000000"],["111684.61000000","0.99916000"],["111687.04000000","0.00000000"],["111695.84000000","0.00000000"],["111695.87000000","0.00000000"],["111696.04000000","0.00000000"],["111697.07000000","0.16288000"],["111701.46000000","0.00000000"],["111709.58000000","0.00000000"],["111710.40000000","0.00000000"],["111711.92000000","0.00000000"],["111712.55000000","0.00000000"],["111714.41000000","0.00000000"],["111714.67000000","0.00000000"],["111714.76000000","0.00000000"],["111715.76000000","0.17314000"],["111716.24000000","0.00000000"],["111717.43000000","0.00000000"],["111719.04000000","0.00000000"],["111719.07000000","0.00000000"],["111722.50000000","0.13544000"],["111722.61000000","0.00000000"],["111725.94000000","0.00000000"],["111726.01000000","0.00000000"],["111726.13000000","0.00000000"],["111726.50000000","0.00000000"],["111729.37000000","0.22384000"],["111729.39000000","0.01236000"],["111730.91000000","0.03997000"],["111734.15000000","0.47095000"],["111734.16000000","0.44680000"],["111734.31000000","0.00000000"],["111734.79000000","0.00000000"],["111735.08000000","0.02420000"],["111735.74000000","0.08794000"],["111737.63000000","0.02420000"],["111738.29000000","0.08794000"],["111738.35000000","0.02420000"],["111739.88000000","0.41410000"],["111740.92000000","0.03997000"],["111741.24000000","0.04947000"],["111741.71000000","0.02420000"],["111741.82000000","0.08794000"],["111743.60000000","0.03997000"],["111744.73000000","0.17589000"],["111745.36000000","0.12791000"],["111747.05000000","0.02420000"],["111747.49000000","0.08794000"],["111750.17000000","0.08794000"],["111750.40000000","0.00089000"],["111750.50000000","0.03997000"],["111753.70000000","0.08794000"],["111754.69000000","0.02420000"],["111755.47000000","0.12791000"],["111756.82000000","0.08794000"],["111756.94000000","0.00000000"],["111758.91000000","0.00000000"],["111759.27000000","0.02420000"],["111759.77000000","0.08794000"],["111761.29000000","0.00000000"],["111761.75000000","0.00000000"],["111764.95000000","0.00000000"],["111765.22000000","0.02420000"],["111766.22000000","0.00000000"],["111766.35000000","0.00000000"],["111766.68000000","0.00000000"],["111767.22000000","0.00000000"],["111767.79000000","0.34629000"],["111768.61000000","0.02420000"],["111769.26000000","0.00000000"],["111771.99000000","0.00089000"],["111772.49000000","0.00000000"],["111772.72000000","0.00000000"],["111775.06000000","0.00089000"],["111775.07000000","0.00000000"],["111775.58000000","0.00000000"],["111781.03000000","0.08794000"],["111782.33000000","0.08794000"],["111784.37000000","0.08794000"],["111785.83000000","0.08794000"],["111786.73000000","0.00000000"],["111787.40000000","4.88683000"],["111788.29000000","0.08794000"],["111790.19000000","0.08794000"],["111792.11000000","0.08794000"],["111795.23000000","0.08794000"],["111811.60000000","0.00000000"],["111814.72000000","0.03997000"],["111822.47000000","0.01703000"],["111840.55000000","0.00000000"],["111841.25000000","0.00000000"],["111841.49000000","0.00000000"],["111842.13000000","0.00000000"],["111842.44000000","0.00000000"],["111843.62000000","0.00000000"],["111844.09000000","0.00000000"],["111844.22000000","0.00000000"],["111845.73000000","0.00000000"],["111847.24000000","0.00007000"],["111848.13000000","0.00010000"],["111849.77000000","0.00000000"],["111849.96000000","0.00000000"],["111851.67000000","0.00010000"],["111852.05000000","0.00000000"],["111853.19000000","0.00000000"],["111853.39000000","0.00000000"],["111853.70000000","0.00000000"],["111856.59000000","0.00000000"],["111857.24000000","0.00010000"],["111858.35000000","0.00000000"],["111859.18000000","0.00000000"],["111859.27000000","0.00000000"],["111860.90000000","0.00000000"],["111862.81000000","0.00010000"],["111864.00000000","0.00000000"],["111866.15000000","0.00000000"],["111866.35000000","0.00000000"],["111868.38000000","0.00000000"],["111868.71000000","0.00000000"],["111872.64000000","0.00000000"],["111872.81000000","0.00000000"],["111872.99000000","0.00000000"],["111873.16000000","0.00000000"],["111873.33000000","0.00000000"],["111873.65000000","0.00000000"],["111873.70000000","0.00000000"],["111876.31000000","0.00000000"],["111878.39000000","0.00000000"],["111878.58000000","0.00000000"],["111878.60000000","0.00000000"],["111884.12000000","0.00000000"],["111885.77000000","0.02689000"],["111888.97000000","0.05896000"],["111889.16000000","0.02689000"],["111889.99000000","0.05896000"],["111891.07000000","0.05896000"],["111891.88000000","0.03997000"],["111892.03000000","0.02689000"],["111892.12000000","0.05896000"],["111892.36000000","0.03997000"],["111892.45000000","0.02689000"],["111893.19000000","0.05896000"],["111894.16000000","0.05896000"],["111895.29000000","0.05896000"],["111897.49000000","0.05897000"],["111897.81000000","0.00000000"],["111902.33000000","0.03675000"],["111902.70000000","0.00000000"],["111902.72000000","0.00000000"],["111903.83000000","0.07350000"],["111904.18000000","0.00000000"],["111906.01000000","0.07350000"],["111906.28000000","0.03675000"],["111906.37000000","0.03675000"],["111906.48000000","0.03675000"],["111906.87000000","0.03675000"],["111906.94000000","0.03675000"],["111907.96000000","0.03675000"],["111908.09000000","0.03675000"],["111910.71000000","0.03675000"],["111912.91000000","0.02689000"],["111915.11000000","0.00000000"],["111915.26000000","0.02689000"],["111915.82000000","0.02689000"],["111916.04000000","0.00000000"],["111916.75000000","0.00000000"],["111917.41000000","0.00000000"],["111919.04000000","0.00000000"],["111920.00000000","0.00110000"],["111920.20000000","0.00000000"],["111920.99000000","0.00000000"],["111922.81000000","0.00000000"],["111938.46000000","0.02905000"],["111989.46000000","0.00000000"],["112004.86000000","0.00000000"],["112036.30000000","0.03675000"],["112042.63000000","0.03675000"],["112048.32000000","0.03675000"],["112051.74000000","0.45000000"],["112053.38000000","0.07350000"],["112072.37000000","0.00000000"],["112081.51000000","0.00000000"],["112100.00000000","1.71417000"],["112143.25000000","0.00000000"],["112143.41000000","0.00000000"],["112144.21000000","0.00000000"],["112145.39000000","0.00036000"],["112145.83000000","0.00000000"],["112145.86000000","0.00000000"],["113215.13000000","0.00000000"],["113226.98000000","0.00100000"]]}
[2025-10-12T11:05:01.182Z] {"e":"depthUpdate","E":1760267101014,"s":"BTCUSDT","U":77965294767,"u":77965295248,"b":[["111553.66000000","6.75533000"],["111553.65000000","0.20638000"],["111553.27000000","0.01350000"],["111552.55000000","0.02791000"],["111552.54000000","0.04081000"],["111551.43000000","0.00359000"],["111551.34000000","0.00005000"],["111550.25000000","0.00005000"],["111549.76000000","0.00543000"],["111549.51000000","0.00010000"],["111549.41000000","0.00000000"],["111549.40000000","0.01794000"],["111548.99000000","0.39078000"],["111548.98000000","0.45020000"],["111548.97000000","0.00000000"],["111545.47000000","0.00043000"],["111545.29000000","0.00000000"],["111544.43000000","0.00043000"],["111542.50000000","0.11509000"],["111542.01000000","0.00000000"],["111541.99000000","0.69287000"],["111539.86000000","0.00463000"],["111538.91000000","0.05760000"],["111538.32000000","0.00000000"],["111538.31000000","1.06153000"],["111538.27000000","0.00000000"],["111538.25000000","0.00000000"],["111538.24000000","0.03998000"],["111538.16000000","0.00043000"],["111538.13000000","0.00000000"],["111537.69000000","0.04800000"],["111537.68000000","0.04800000"],["111537.43000000","0.01785000"],["111536.70000000","0.07920000"],["111535.46000000","0.10080000"],["111534.77000000","0.15000000"],["111532.19000000","0.13440000"],["111532.02000000","0.07200000"],["111531.62000000","0.00895000"],["111530.26000000","0.00000000"],["111529.34000000","0.04311000"],["111528.04000000","0.00005000"],["111525.42000000","0.00000000"],["111525.37000000","0.00000000"],["111525.21000000","0.00000000"],["111522.70000000","0.00000000"],["111520.24000000","0.00143000"],["111520.23000000","0.08729000"],["111520.20000000","0.00000000"],["111520.19000000","0.00008000"],["111520.12000000","0.22384000"],["111519.33000000","0.00000000"],["111518.39000000","0.03498000"],["111518.13000000","0.00000000"],["111517.14000000","0.00000000"],["111516.89000000","0.00000000"],["111516.11000000","0.00000000"],["111515.18000000","1.07461000"],["111513.87000000","0.30243000"],["111512.70000000","1.25046000"],["111507.92000000","0.00000000"],["111506.68000000","0.35816000"],["111500.66000000","0.00000000"],["111497.77000000","0.06561000"],["111492.87000000","0.00000000"],["111486.73000000","0.00008000"],["111481.49000000","0.00617000"],["111480.71000000","0.00620000"],["111476.95000000","0.00000000"],["111469.81000000","0.01493000"],["111468.81000000","0.00000000"],["111466.82000000","0.00000000"],["111464.24000000","0.01502000"],["111461.30000000","0.13430000"],["111460.26000000","0.27146000"],["111460.06000000","0.13430000"],["111459.41000000","0.00000000"],["111458.03000000","0.00000000"],["111458.02000000","0.00164000"],["111453.26000000","0.00008000"],["111447.48000000","0.02420000"],["111447.27000000","0.22384000"],["111446.01000000","0.02420000"],["111445.34000000","0.00000000"],["111439.31000000","0.00000000"],["111439.08000000","0.00005000"],["111436.95000000","0.00000000"],["111435.95000000","0.16488000"],["111435.94000000","0.00000000"],["111434.81000000","0.00000000"],["111434.68000000","0.00000000"],["111433.72000000","0.00000000"],["111430.71000000","0.15783000"],["111426.15000000","0.29795000"],["111426.14000000","0.00000000"],["111425.96000000","0.00000000"],["111425.56000000","0.00000000"],["111422.67000000","0.00000000"],["111421.27000000","0.13467000"],["111421.26000000","0.00000000"],["111419.80000000","0.00008000"],["111419.28000000","0.17932000"],["111413.17000000","0.00000000"],["111409.61000000","0.31567000"],["111407.93000000","0.08794000"],["111400.34000000","0.06000000"],["111392.50000000","0.00000000"],["111386.33000000","0.00008000"],["111364.48000000","0.00000000"],["111359.04000000","0.00000000"],["111353.68000000","0.00000000"],["111351.35000000","0.99102000"],["111349.46000000","0.00000000"],["111347.18000000","0.00066000"],["111339.71000000","0.00000000"],["111339.25000000","0.00000000"],["111335.20000000","0.00000000"],["111320.53000000","0.00000000"],["111258.39000000","0.02689000"],["111143.76000000","0.00000000"],["111132.87000000","0.02749000"],["111047.72000000","0.00000000"],["110915.75000000","0.89111000"],["110550.74000000","0.00239000"],["109880.35000000","0.00100000"],["107388.88000000","0.04655000"],["105900.00000000","0.07792000"],["102591.46000000","0.00000000"],["100398.00000000","0.00600000"],["100397.00000000","0.00010000"],["90000.00000000","52.75715000"],["89242.93000000","0.00022000"]],"a":[["111553.67000000","0.29217000"],["111553.68000000","0.00080000"],["111553.75000000","0.00010000"],["111554.00000000","0.00265000"],["111554.06000000","0.01365000"],["111554.07000000","0.00010000"],["111554.34000000","0.00000000"],["111554.36000000","0.00000000"],["111554.39000000","0.00000000"],["111554.40000000","0.00000000"],["111555.54000000","0.00010000"],["111555.55000000","0.05914000"],["111556.00000000","0.00265000"],["111556.88000000","0.00005000"],["111558.00000000","0.00270000"],["111559.62000000","0.04107000"],["111559.72000000","0.01412000"],["111559.80000000","0.01808000"],["111560.00000000","0.00260000"],["111560.74000000","0.04099000"],["111561.31000000","0.17403000"],["111561.32000000","0.00000000"],["111561.36000000","0.00000000"],["111561.37000000","0.00000000"],["111561.70000000","0.00005000"],["111561.71000000","0.02566000"],["111561.97000000","0.00000000"],["111562.00000000","0.00265000"],["111562.03000000","0.04476000"],["111563.39000000","0.00000000"],["111563.40000000","0.00000000"],["111564.00000000","0.00260000"],["111564.73000000","0.00000000"],["111564.74000000","0.00000000"],["111564.83000000","0.00155000"],["111564.86000000","0.16561000"],["111564.87000000","0.04690000"],["111565.96000000","0.16421000"],["111566.00000000","0.00260000"],["111566.48000000","0.30242000"],["111566.72000000","0.04800000"],["111566.88000000","0.06240000"],["111567.61000000","0.00000000"],["111568.17000000","0.07618000"],["111569.99000000","0.00448000"],["111570.19000000","0.00000000"],["111570.38000000","0.06646000"],["111571.19000000","0.00009000"],["111572.43000000","0.00000000"],["111572.59000000","0.26961000"],["111574.11000000","0.03400000"],["111575.40000000","0.04000000"],["111575.90000000","0.00000000"],["111575.97000000","0.35816000"],["111575.99000000","0.00300000"],["111576.33000000","0.04800000"],["111576.76000000","0.01761000"],["111576.77000000","0.00009000"],["111577.56000000","0.04800000"],["111578.53000000","0.07200000"],["111578.61000000","0.00005000"],["111579.79000000","0.07200000"],["111580.04000000","0.30000000"],["111583.19000000","0.04800000"],["111584.59000000","0.00000000"],["111586.73000000","0.00000000"],["111587.13000000","0.00000000"],["111587.14000000","0.00308000"],["111588.30000000","0.00000000"],["111592.15000000","0.00000000"],["111593.26000000","0.00000000"],["111593.38000000","0.00000000"],["111594.11000000","0.16175000"],["111594.48000000","0.49788000"],["111599.79000000","1.22912000"],["111611.43000000","0.00005000"],["111615.90000000","0.00000000"],["111620.60000000","0.00008000"],["111626.71000000","0.00000000"],["111628.24000000","0.00000000"],["111628.25000000","0.06611000"],["111631.54000000","0.00000000"],["111632.88000000","0.00620000"],["111638.09000000","0.00000000"],["111639.63000000","0.00005000"],["111641.99000000","0.04097000"],["111643.99000000","0.04097000"],["111645.88000000","0.00005000"],["111649.23000000","0.00000000"],["111649.99000000","0.04097000"],["111652.88000000","0.04097000"],["111654.07000000","0.00008000"],["111655.83000000","0.04097000"],["111655.85000000","0.08408000"],["111657.06000000","0.00000000"],["111658.03000000","0.00000000"],["111659.26000000","0.04097000"],["111660.17000000","0.00000000"],["111660.25000000","0.00000000"],["111660.65000000","0.00000000"],["111661.38000000","0.00000000"],["111662.49000000","0.00000000"],["111662.59000000","0.00000000"],["111669.99000000","0.04097000"],["111675.99000000","0.04097000"],["111679.99000000","0.04097000"],["111683.99000000","0.04097000"],["111687.53000000","0.00008000"],["111693.08000000","0.00000000"],["111693.15000000","0.00000000"],["111693.63000000","0.00000000"],["111693.99000000","0.04097000"],["111694.64000000","0.00000000"],["111694.79000000","0.00000000"],["111694.90000000","0.00000000"],["111695.89000000","0.00000000"],["111704.22000000","0.02510000"],["111712.39000000","0.02510000"],["111721.00000000","0.00008000"],["111734.20000000","0.02691000"],["111745.75000000","0.26431000"],["111780.00000000","0.00449000"],["111811.29000000","0.02510000"],["111811.86000000","0.02510000"],["111812.50000000","0.02510000"],["111812.90000000","0.02510000"],["111813.34000000","0.02510000"],["111813.93000000","0.02510000"],["111814.89000000","0.02510000"],["111816.60000000","0.02510000"],["111817.53000000","0.02510000"],["111818.50000000","0.02510000"],["111818.96000000","0.02510000"],["111820.93000000","0.02510000"],["111939.55000000","0.02741000"],["112154.81000000","0.02398000"],["112673.88000000","0.00234000"],["113226.98000000","0.00100000"]]}
[2025-10-12T11:05:02.183Z] {"e":"depthUpdate","E":1760267102014,"s":"BTCUSDT","U":77965295249,"u":77965296310,"b":[["111553.66000000","1.08127000"],["111553.65000000","0.20723000"],["111553.50000000","0.00996000"],["111553.49000000","0.00010000"],["111553.32000000","0.00000000"],["111553.29000000","0.00010000"],["111553.28000000","0.00010000"],["111553.27000000","0.01350000"],["111552.56000000","0.00000000"],["111552.55000000","0.00000000"],["111552.54000000","0.00005000"],["111552.31000000","0.00000000"],["111551.45000000","0.00010000"],["111551.44000000","0.00000000"],["111551.43000000","0.00364000"],["111551.20000000","0.00010000"],["111551.19000000","0.00000000"],["111551.10000000","0.00000000"],["111551.09000000","0.00000000"],["111550.53000000","0.00000000"],["111550.52000000","0.00000000"],["111549.77000000","0.00000000"],["111549.76000000","0.00538000"],["111549.51000000","0.00005000"],["111549.40000000","0.00000000"],["111548.99000000","0.00000000"],["111548.98000000","0.00000000"],["111548.96000000","0.00000000"],["111548.85000000","0.00000000"],["111547.69000000","0.00000000"],["111547.54000000","0.00000000"],["111545.59000000","0.00000000"],["111545.47000000","0.00000000"],["111545.00000000","0.00005000"],["111544.86000000","0.00000000"],["111544.85000000","0.00000000"],["111544.43000000","0.00000000"],["111544.38000000","0.00000000"],["111542.50000000","0.45319000"],["111542.27000000","0.00000000"],["111542.20000000","0.00000000"],["111542.19000000","0.32069000"],["111542.00000000","0.00000000"],["111541.99000000","0.20289000"],["111541.94000000","0.00000000"],["111541.47000000","0.00000000"],["111540.93000000","0.00000000"],["111539.99000000","0.00000000"],["111539.86000000","0.00020000"],["111539.79000000","0.04000000"],["111539.45000000","0.00000000"],["111539.30000000","0.00069000"],["111539.21000000","0.00325000"],["111538.74000000","0.00058000"],["111538.34000000","0.00000000"],["111538.33000000","0.42358000"],["111538.32000000","0.35816000"],["111538.31000000","0.00000000"],["111538.30000000","0.00000000"],["111538.26000000","0.10000000"],["111538.24000000","0.00000000"],["111538.16000000","0.00000000"],["111538.11000000","0.00078000"],["111538.00000000","0.00010000"],["111537.80000000","0.05765000"],["111537.79000000","0.05765000"],["111537.78000000","0.00000000"],["111537.69000000","0.04805000"],["111537.68000000","0.04805000"],["111537.48000000","0.00000000"],["111537.43000000","0.01790000"],["111537.35000000","0.00000000"],["111537.34000000","0.00000000"],["111536.98000000","0.00005000"],["111536.93000000","0.00150000"],["111536.70000000","0.07920000"],["111536.54000000","0.00000000"],["111535.28000000","0.00000000"],["111534.77000000","0.00000000"],["111534.75000000","0.00000000"],["111534.73000000","0.00000000"],["111534.58000000","0.00000000"],["111534.21000000","0.00000000"],["111534.00000000","0.00000000"],["111533.99000000","0.00000000"],["111533.87000000","0.00000000"],["111533.60000000","0.00005000"],["111533.59000000","0.35816000"],["111533.35000000","0.00000000"],["111533.29000000","0.00006000"],["111533.02000000","0.00070000"],["111532.83000000","0.00000000"],["111532.82000000","0.00000000"],["111532.46000000","0.00000000"],["111532.22000000","0.00000000"],["111532.13000000","0.00000000"],["111532.12000000","0.00000000"],["111532.11000000","0.15601000"],["111532.10000000","0.00000000"],["111532.02000000","0.07200000"],["111532.00000000","0.00000000"],["111531.82000000","0.00000000"],["111531.62000000","0.00000000"],["111531.49000000","0.00070000"],["111531.34000000","0.00000000"],["111531.03000000","0.00000000"],["111531.02000000","0.00000000"],["111530.26000000","0.00000000"],["111530.23000000","0.00000000"],["111529.42000000","0.00000000"],["111529.36000000","0.00000000"],["111529.35000000","0.00000000"],["111529.34000000","0.00000000"],["111529.19000000","0.00000000"],["111528.84000000","0.00000000"],["111528.76000000","0.00000000"],["111528.74000000","0.00000000"],["111528.38000000","0.00000000"],["111527.92000000","0.00000000"],["111527.83000000","0.00895000"],["111527.11000000","0.00000000"],["111526.46000000","0.00000000"],["111526.36000000","0.00260000"],["111526.33000000","0.12831000"],["111526.32000000","0.02000000"],["111526.08000000","0.00010000"],["111525.77000000","0.11195000"],["111525.61000000","0.00448000"],["111525.60000000","0.04352000"],["111525.23000000","0.00000000"],["111524.92000000","0.00000000"],["111524.88000000","0.00000000"],["111524.86000000","0.00000000"],["111524.35000000","0.00000000"],["111524.34000000","0.00000000"],["111524.33000000","1.25396000"],["111524.04000000","0.00000000"],["111523.82000000","0.04000000"],["111523.69000000","0.00000000"],["111522.70000000","0.00000000"],["111521.01000000","0.00000000"],["111520.92000000","0.00000000"],["111520.75000000","0.08505000"],["111520.30000000","0.19480000"],["111519.21000000","0.08507000"],["111518.80000000","0.00000000"],["111518.39000000","0.00000000"],["111517.80000000","0.00000000"],["111517.43000000","0.08507000"],["111515.20000000","0.00000000"],["111515.11000000","0.13434000"],["111514.68000000","0.00000000"],["111513.87000000","0.00000000"],["111513.15000000","0.00000000"],["111512.70000000","0.05760000"],["111511.55000000","0.00000000"],["111510.94000000","0.00000000"],["111510.43000000","0.00000000"],["111509.35000000","0.00009000"],["111509.32000000","0.13430000"],["111508.74000000","0.07920000"],["111508.62000000","0.00005000"],["111508.43000000","0.00000000"],["111508.08000000","0.13430000"],["111507.88000000","0.00000000"],["111507.51000000","0.10080000"],["111507.13000000","0.00018000"],["111506.02000000","0.00000000"],["111505.31000000","0.00000000"],["111504.18000000","0.00000000"],["111504.15000000","0.00005000"],["111502.77000000","0.00000000"],["111502.19000000","0.00000000"],["111501.55000000","0.05760000"],["111500.78000000","1.22509000"],["111500.00000000","0.00118000"],["111499.21000000","0.03498000"],["111499.07000000","0.00000000"],["111498.97000000","0.00009000"],["111498.44000000","0.00000000"],["111497.77000000","0.00000000"],["111496.22000000","0.00000000"],["111495.94000000","0.00000000"],["111495.21000000","0.00005000"],["111494.45000000","0.00000000"],["111492.82000000","0.00000000"],["111491.79000000","0.30249000"],["111489.70000000","0.00000000"],["111488.00000000","0.00005000"],["111487.89000000","0.00000000"],["111487.69000000","0.00000000"],["111487.64000000","0.00000000"],["111487.00000000","0.04479000"],["111486.58000000","0.00000000"],["111484.00000000","0.00260000"],["111483.46000000","0.13444000"],["111483.34000000","0.00000000"],["111482.00000000","0.00260000"],["111481.42000000","0.04426000"],["111480.34000000","0.00000000"],["111477.21000000","0.00000000"],["111474.63000000","0.04800000"],["111474.48000000","0.00223000"],["111474.09000000","0.00000000"],["111474.01000000","0.00000000"],["111473.54000000","0.00000000"],["111470.97000000","0.00000000"],["111467.85000000","0.00000000"],["111467.49000000","0.00000000"],["111464.73000000","0.00000000"],["111464.06000000","0.00000000"],["111463.68000000","0.00090000"],["111461.61000000","0.00000000"],["111461.30000000","0.00000000"],["111461.23000000","0.00000000"],["111460.06000000","0.00000000"],["111458.03000000","0.00000000"],["111458.02000000","0.00000000"],["111455.37000000","0.00000000"],["111454.22000000","0.00222000"],["111454.21000000","0.00000000"],["111452.25000000","0.00000000"],["111447.24000000","0.01794000"],["111446.84000000","0.13430000"],["111445.60000000","0.13430000"],["111442.24000000","0.08286000"],["111440.21000000","0.00000000"],["111440.09000000","0.00000000"],["111439.77000000","0.00000000"],["111439.53000000","0.00000000"],["111439.37000000","0.00000000"],["111438.85000000","0.00000000"],["111438.10000000","0.00000000"],["111436.95000000","0.00000000"],["111433.53000000","0.00016000"],["111430.71000000","0.11770000"],["111427.38000000","0.00000000"],["111424.17000000","0.00000000"],["111421.05000000","0.00000000"],["111420.98000000","0.13444000"],["111418.34000000","0.00000000"],["111416.70000000","0.00218000"],["111411.69000000","0.00000000"],["111407.89000000","0.08794000"],["111407.69000000","0.09759000"],["111405.45000000","0.00000000"],["111402.46000000","0.00000000"],["111401.70000000","0.00000000"],["111396.09000000","0.00000000"],["111389.85000000","0.00000000"],["111384.36000000","0.00000000"],["111377.38000000","0.00000000"],["111375.81000000","0.07303000"],["111371.14000000","0.00000000"],["111364.90000000","0.00000000"],["111362.98000000","0.00089000"],["111355.55000000","0.00006000"],["111347.19000000","0.00000000"],["111347.18000000","0.00000000"],["111347.17000000","0.00000000"],["111344.26000000","0.00000000"],["111343.44000000","0.00089000"],["111343.43000000","0.00000000"],["111338.97000000","0.00000000"],["111336.47000000","0.00011000"],["111328.67000000","0.00000000"],["111323.39000000","0.08794000"],["111322.76000000","0.08794000"],["111320.88000000","0.00000000"],["111313.09000000","0.00028000"],["111305.30000000","0.00000000"],["111297.51000000","0.00000000"],["111289.72000000","0.00033000"],["111281.93000000","0.00000000"],["111274.14000000","0.00000000"],["111266.35000000","0.00000000"],["111263.09000000","0.01703000"],["111258.56000000","0.00000000"],["111251.97000000","0.00000000"],["111251.48000000","0.00000000"],["111250.90000000","0.00000000"],["111250.77000000","0.00000000"],["111242.99000000","0.00000000"],["111235.20000000","0.00005000"],["111227.41000000","0.00000000"],["111219.63000000","0.00000000"],["111211.84000000","0.00000000"],["111204.06000000","0.00000000"],["111196.28000000","0.00000000"],["111196.27000000","0.02689000"],["111188.49000000","0.00000000"],["111188.28000000","0.05896000"],["111187.96000000","0.05896000"],["111187.64000000","0.05913000"],["111187.03000000","0.45000000"],["111180.71000000","0.00000000"],["111173.51000000","0.00000000"],["111172.93000000","0.00000000"],["111165.15000000","0.00000000"],["111157.37000000","0.00009000"],["111144.58000000","0.00000000"],["111121.10000000","0.00080000"],["111118.26000000","0.00000000"],["110915.75000000","0.00000000"],["110908.37000000","0.89111000"],["109880.35000000","0.00100000"],["100398.00000000","0.00600000"],["100397.00000000","0.00010000"],["89242.93000000","0.00022000"],["33000.00000000","3.87311000"]],"a":[["111553.67000000","4.74950000"],["111553.68000000","0.00020000"],["111553.69000000","0.00020000"],["111553.70000000","0.04491000"],["111553.71000000","0.00010000"],["111553.82000000","0.00000000"],["111553.83000000","0.00901000"],["111553.84000000","0.00010000"],["111554.00000000","0.00265000"],["111554.01000000","0.00000000"],["111554.05000000","0.00000000"],["111554.06000000","0.01370000"],["111554.07000000","0.00000000"],["111554.50000000","0.00000000"],["111554.51000000","0.04005000"],["111555.50000000","0.00000000"],["111555.51000000","0.03590000"],["111555.52000000","0.00000000"],["111555.54000000","0.10167000"],["111555.55000000","0.05914000"],["111555.84000000","0.00005000"],["111555.88000000","0.00000000"],["111555.89000000","0.03964000"],["111556.53000000","0.03590000"],["111557.01000000","0.04041000"],["111557.04000000","0.00000000"],["111557.05000000","0.00000000"],["111557.06000000","0.00000000"],["111557.57000000","0.00538000"],["111557.79000000","0.00005000"],["111557.98000000","0.03585000"],["111558.29000000","0.00000000"],["111558.39000000","0.00000000"],["111558.47000000","0.00000000"],["111558.68000000","0.00717000"],["111558.73000000","0.00155000"],["111558.81000000","0.00000000"],["111559.24000000","0.00000000"],["111559.61000000","0.00000000"],["111559.62000000","0.00000000"],["111559.71000000","0.06646000"],["111559.72000000","0.01402000"],["111559.79000000","0.00000000"],["111559.80000000","0.01798000"],["111560.00000000","0.00260000"],["111560.09000000","0.00000000"],["111560.37000000","0.00000000"],["111560.65000000","0.08507000"],["111560.74000000","0.00000000"],["111561.31000000","0.00000000"],["111561.51000000","0.00000000"],["111561.71000000","0.02561000"],["111562.00000000","0.00260000"],["111562.03000000","0.00000000"],["111562.11000000","0.35816000"],["111562.26000000","0.00005000"],["111562.96000000","0.00000000"],["111562.97000000","0.01805000"],["111563.93000000","0.00000000"],["111564.22000000","0.00000000"],["111564.30000000","0.11195000"],["111564.50000000","0.00400000"],["111564.58000000","0.00000000"],["111564.60000000","0.00000000"],["111564.64000000","0.00000000"],["111564.82000000","0.00000000"],["111564.83000000","0.00150000"],["111564.85000000","0.37749000"],["111564.86000000","0.00000000"],["111564.87000000","0.02690000"],["111565.60000000","0.04000000"],["111565.95000000","0.15000000"],["111565.96000000","0.35816000"],["111565.97000000","0.00000000"],["111566.48000000","0.00000000"],["111566.63000000","0.15000000"],["111566.65000000","0.58174000"],["111566.66000000","0.40324000"],["111566.67000000","0.00000000"],["111566.73000000","0.00005000"],["111567.76000000","0.00000000"],["111568.27000000","0.00000000"],["111568.94000000","0.00000000"],["111568.99000000","0.00000000"],["111569.38000000","0.00000000"],["111569.99000000","0.00000000"],["111570.40000000","0.04950000"],["111570.86000000","0.00000000"],["111570.88000000","0.45000000"],["111571.20000000","0.13435000"],["111571.38000000","0.04800000"],["111571.91000000","0.35816000"],["111572.57000000","0.00000000"],["111572.58000000","1.25396000"],["111572.59000000","0.64977000"],["111573.37000000","0.00000000"],["111573.52000000","0.00000000"],["111574.01000000","0.00000000"],["111574.05000000","0.08507000"],["111574.31000000","0.08505000"],["111574.50000000","0.00000000"],["111574.75000000","0.00000000"],["111575.39000000","0.00000000"],["111575.40000000","0.00000000"],["111575.94000000","0.00000000"],["111575.96000000","1.25396000"],["111575.98000000","0.00000000"],["111577.13000000","0.00000000"],["111577.59000000","0.00000000"],["111578.50000000","0.00400000"],["111578.70000000","0.00000000"],["111580.04000000","0.00000000"],["111580.05000000","0.00000000"],["111580.26000000","0.00000000"],["111582.66000000","0.00000000"],["111583.33000000","1.17119000"],["111583.38000000","0.00000000"],["111583.46000000","0.00000000"],["111584.82000000","0.00000000"],["111584.93000000","0.00000000"],["111585.01000000","0.00000000"],["111585.25000000","0.00000000"],["111585.58000000","0.22384000"],["111586.50000000","0.00000000"],["111589.22000000","0.00000000"],["111589.63000000","0.00000000"],["111589.66000000","0.00000000"],["111590.00000000","0.00530000"],["111590.26000000","0.18887000"],["111590.41000000","0.00000000"],["111590.45000000","0.00000000"],["111590.89000000","0.00000000"],["111591.74000000","0.00000000"],["111592.75000000","0.00000000"],["111594.48000000","0.08329000"],["111594.77000000","0.00000000"],["111595.88000000","0.00000000"],["111599.00000000","0.00000000"],["111599.79000000","0.00000000"],["111600.53000000","0.40316000"],["111602.13000000","0.00000000"],["111602.49000000","0.00000000"],["111602.81000000","0.00000000"],["111605.25000000","0.00000000"],["111606.96000000","0.00000000"],["111608.38000000","0.00000000"],["111609.56000000","0.00000000"],["111611.43000000","0.00000000"],["111613.91000000","0.00000000"],["111614.63000000","0.00000000"],["111615.13000000","0.00000000"],["111617.37000000","0.00000000"],["111620.88000000","0.00000000"],["111624.00000000","0.00260000"],["111625.18000000","0.00000000"],["111628.79000000","0.00000000"],["111629.09000000","0.00000000"],["111629.49000000","0.13434000"],["111629.51000000","0.13430000"],["111630.25000000","0.00000000"],["111632.78000000","0.00000000"],["111633.38000000","0.00000000"],["111635.65000000","0.00480000"],["111636.51000000","0.00000000"],["111636.69000000","0.00000000"],["111637.55000000","0.00000000"],["111637.91000000","0.00000000"],["111637.96000000","0.00000000"],["111639.63000000","0.00000000"],["111640.77000000","0.00000000"],["111640.86000000","0.00000000"],["111642.76000000","0.00000000"],["111643.12000000","0.00000000"],["111643.53000000","0.02137000"],["111645.88000000","0.00000000"],["111648.62000000","0.00000000"],["111649.01000000","0.00000000"],["111649.23000000","0.07200000"],["111652.58000000","0.00000000"],["111652.89000000","0.00000000"],["111655.40000000","0.00000000"],["111658.39000000","0.00000000"],["111659.77000000","0.00000000"],["111660.02000000","0.00000000"],["111660.12000000","0.00000000"],["111660.35000000","0.00000000"],["111660.72000000","0.00000000"],["111660.83000000","0.00000000"],["111662.19000000","0.00000000"],["111662.31000000","0.00000000"],["111662.82000000","0.04220000"],["111662.92000000","0.00000000"],["111663.32000000","0.52469000"],["111663.68000000","0.00000000"],["111664.09000000","0.09759000"],["111664.64000000","0.00000000"],["111664.79000000","0.00000000"],["111664.98000000","0.00000000"],["111665.02000000","0.02027000"],["111665.18000000","0.99901000"],["111666.11000000","0.00000000"],["111666.34000000","0.00000000"],["111666.46000000","0.00000000"],["111666.86000000","0.00000000"],["111667.52000000","0.00000000"],["111671.13000000","0.03997000"],["111673.68000000","0.09067000"],["111674.02000000","0.00000000"],["111675.60000000","0.00005000"],["111675.72000000","0.00000000"],["111679.20000000","0.00000000"],["111680.28000000","0.00000000"],["111680.97000000","0.03997000"],["111684.56000000","0.09976000"],["111684.61000000","0.00000000"],["111688.58000000","0.00000000"],["111689.25000000","0.00000000"],["111689.66000000","0.00000000"],["111694.99000000","0.00000000"],["111695.00000000","0.00000000"],["111695.91000000","0.00000000"],["111696.83000000","0.12910000"],["111698.80000000","0.00000000"],["111703.32000000","0.17626000"],["111705.29000000","0.00000000"],["111705.33000000","0.00259000"],["111711.55000000","0.00000000"],["111718.53000000","0.13118000"],["111720.07000000","0.00000000"],["111720.08000000","0.04130000"],["111720.93000000","0.00000000"],["111723.99000000","0.26352000"],["111724.00000000","0.00260000"],["111727.19000000","0.00000000"],["111728.00000000","0.00260000"],["111734.20000000","0.00000000"],["111736.58000000","0.00000000"],["111742.83000000","0.00000000"],["111752.22000000","0.00000000"],["111753.69000000","0.13418000"],["111758.48000000","0.00000000"],["111768.37000000","0.03997000"],["111771.00000000","0.00000000"],["111773.09000000","0.03997000"],["111779.02000000","0.03997000"],["111780.00000000","0.00360000"],["111781.56000000","0.00000000"],["111783.28000000","0.03997000"],["111786.64000000","0.00000000"],["111788.00000000","0.00310000"],["111789.39000000","0.03997000"],["111792.90000000","0.00000000"],["111799.16000000","0.00000000"],["111799.50000000","0.03997000"],["111804.78000000","0.03997000"],["111807.13000000","0.03997000"],["111808.56000000","0.00000000"],["111809.86000000","0.03997000"],["111820.69000000","0.00000000"],["111828.52000000","0.00000000"],["111836.35000000","0.00000000"],["111844.17000000","0.00000000"],["111852.00000000","0.00000000"],["111859.83000000","0.00000000"],["111867.66000000","0.00000000"],["111875.49000000","0.00000000"],["111883.33000000","0.00000000"],["111891.16000000","0.00000000"],["111898.99000000","0.00000000"],["111906.82000000","0.00000000"],["111907.76000000","0.03675000"],["111914.66000000","0.00000000"],["111922.49000000","0.00000000"],["112053.38000000","0.03675000"],["113226.98000000","0.00100000"],["116530.24000000","0.00000000"]]}
[2025-10-12T11:05:03.182Z] {"e":"depthUpdate","E":1760267103014,"s":"BTCUSDT","U":77965296311,"u":77965297042,"b":[["111553.66000000","2.03679000"],["111553.65000000","0.28967000"],["111553.50000000","0.00996000"],["111553.49000000","0.00010000"],["111553.29000000","0.00010000"],["111553.28000000","0.01832000"],["111553.27000000","0.01345000"],["111552.79000000","0.00010000"],["111552.78000000","0.00000000"],["111552.60000000","0.00000000"],["111552.59000000","0.00000000"],["111551.67000000","0.00010000"],["111551.66000000","0.00000000"],["111551.45000000","0.00000000"],["111551.43000000","0.00359000"],["111551.20000000","0.00000000"],["111550.94000000","0.00000000"],["111550.93000000","0.00000000"],["111549.76000000","0.00538000"],["111548.67000000","0.00000000"],["111548.66000000","0.01130000"],["111548.65000000","0.00722000"],["111547.83000000","0.00000000"],["111547.82000000","0.00000000"],["111547.81000000","0.00000000"],["111547.80000000","0.00000000"],["111547.55000000","0.01192000"],["111547.54000000","0.00000000"],["111547.53000000","0.01798000"],["111546.76000000","0.00000000"],["111546.75000000","0.00000000"],["111546.74000000","0.00000000"],["111546.69000000","0.00000000"],["111546.68000000","0.00000000"],["111545.00000000","0.00000000"],["111544.95000000","0.00005000"],["111542.52000000","0.00010000"],["111542.51000000","0.24075000"],["111542.50000000","0.45314000"],["111542.20000000","0.00000000"],["111542.19000000","0.00000000"],["111542.01000000","0.00000000"],["111539.91000000","0.00005000"],["111539.86000000","0.00005000"],["111539.21000000","0.00000000"],["111538.91000000","0.00000000"],["111538.80000000","0.00000000"],["111538.74000000","0.00000000"],["111538.33000000","0.15978000"],["111538.32000000","0.00000000"],["111538.11000000","0.00073000"],["111537.80000000","0.00000000"],["111537.79000000","0.00000000"],["111537.69000000","0.00000000"],["111537.68000000","0.00005000"],["111537.46000000","0.00100000"],["111536.93000000","0.00150000"],["111536.70000000","0.00000000"],["111535.98000000","0.00058000"],["111535.46000000","0.00005000"],["111535.02000000","0.01170000"],["111534.85000000","0.04456000"],["111534.40000000","0.00000000"],["111533.26000000","0.00000000"],["111532.19000000","0.00000000"],["111532.11000000","0.10992000"],["111532.02000000","0.00000000"],["111532.00000000","0.00400000"],["111530.26000000","0.15000000"],["111527.83000000","0.00000000"],["111527.80000000","0.00000000"],["111527.11000000","0.00000000"],["111527.09000000","0.54417000"],["111525.60000000","0.00000000"],["111524.89000000","0.00331000"],["111524.57000000","0.05760000"],["111524.50000000","0.04800000"],["111524.35000000","0.00000000"],["111524.34000000","0.00000000"],["111524.33000000","0.00000000"],["111523.51000000","0.05760000"],["111523.33000000","0.04800000"],["111523.13000000","0.00895000"],["111522.36000000","0.07920000"],["111521.12000000","0.10080000"],["111520.98000000","0.04311000"],["111520.30000000","0.04480000"],["111520.17000000","0.07680000"],["111517.95000000","0.07200000"],["111517.86000000","0.06240000"],["111517.69000000","0.07200000"],["111517.44000000","0.35847000"],["111511.07000000","0.08513000"],["111510.42000000","0.00000000"],["111510.27000000","0.00000000"],["111510.00000000","0.00200000"],["111509.35000000","0.00000000"],["111509.17000000","0.00000000"],["111508.94000000","0.06023000"],["111508.74000000","0.00000000"],["111508.00000000","0.00200000"],["111507.51000000","0.00000000"],["111507.13000000","0.00000000"],["111506.00000000","0.00200000"],["111504.65000000","0.00009000"],["111504.00000000","0.00200000"],["111503.67000000","0.00000000"],["111503.52000000","0.00000000"],["111502.43000000","0.00018000"],["111502.00000000","0.00200000"],["111501.56000000","0.00000000"],["111501.55000000","0.00000000"],["111500.00000000","0.00318000"],["111499.68000000","0.00005000"],["111499.22000000","0.30247000"],["111498.97000000","0.00000000"],["111498.00000000","0.00200000"],["111496.00000000","0.00200000"],["111495.21000000","0.00000000"],["111494.70000000","0.00000000"],["111494.27000000","0.00009000"],["111494.12000000","0.06752000"],["111491.79000000","0.00000000"],["111487.89000000","0.00000000"],["111481.42000000","0.00000000"],["111480.00000000","0.00439000"],["111478.00000000","0.00265000"],["111477.53000000","0.00000000"],["111472.64000000","0.00460000"],["111469.81000000","0.01160000"],["111469.25000000","0.00000000"],["111466.58000000","0.04426000"],["111464.24000000","0.01160000"],["111463.68000000","0.00000000"],["111461.61000000","0.00005000"],["111461.23000000","0.00005000"],["111461.18000000","0.00654000"],["111458.99000000","0.00090000"],["111458.02000000","0.00164000"],["111456.85000000","0.05760000"],["111456.74000000","0.04800000"],["111446.70000000","0.00000000"],["111442.24000000","0.09936000"],["111440.43000000","0.05760000"],["111439.37000000","0.00000000"],["111439.17000000","0.04800000"],["111438.72000000","0.07316000"],["111438.18000000","0.07920000"],["111436.95000000","0.00000000"],["111435.99000000","0.07686000"],["111433.78000000","0.07200000"],["111433.74000000","0.06240000"],["111433.63000000","0.07200000"],["111416.70000000","0.00000000"],["111405.21000000","0.00218000"],["111403.26000000","0.00000000"],["111399.87000000","0.13405000"],["111397.28000000","0.02510000"],["111389.19000000","0.02510000"],["111375.81000000","0.00000000"],["111351.36000000","0.99407000"],["111351.35000000","0.00000000"],["111346.44000000","0.00066000"],["111339.98000000","0.00574000"],["111331.76000000","0.00000000"],["111325.59000000","0.00000000"],["111322.65000000","0.08794000"],["111258.39000000","0.00000000"],["111249.78000000","0.02689000"],["111206.92000000","0.02689000"],["111187.03000000","0.00000000"],["111186.59000000","0.02689000"],["111158.00000000","0.03172000"],["111121.10000000","0.00000000"],["111107.79000000","0.00080000"],["110908.37000000","0.00000000"],["110550.74000000","0.00000000"],["109880.35000000","0.00100000"],["109363.02000000","0.00000000"],["100397.00000000","0.00010000"],["89242.93000000","0.00022000"],["40159.32000000","0.00015000"]],"a":[["111553.67000000","5.03484000"],["111553.68000000","0.00030000"],["111553.69000000","0.00030000"],["111553.70000000","0.04491000"],["111553.71000000","0.00010000"],["111553.82000000","0.00010000"],["111553.83000000","0.00901000"],["111553.84000000","0.00010000"],["111554.01000000","0.00000000"],["111554.05000000","0.00010000"],["111554.06000000","0.01375000"],["111554.07000000","0.00000000"],["111554.50000000","0.00010000"],["111554.51000000","0.04015000"],["111554.63000000","0.00005000"],["111554.64000000","0.16322000"],["111554.65000000","0.05388000"],["111555.06000000","0.04124000"],["111555.50000000","0.00000000"],["111555.51000000","0.03590000"],["111555.54000000","0.00000000"],["111555.89000000","0.03959000"],["111556.00000000","0.00270000"],["111556.53000000","0.03590000"],["111557.01000000","0.04041000"],["111557.27000000","0.00000000"],["111557.57000000","0.00548000"],["111557.97000000","0.00448000"],["111558.73000000","0.00160000"],["111559.77000000","0.00100000"],["111560.00000000","0.00265000"],["111561.71000000","0.02566000"],["111561.84000000","0.00000000"],["111562.10000000","0.16892000"],["111562.11000000","0.00000000"],["111563.40000000","0.04000000"],["111564.85000000","0.00000000"],["111565.05000000","0.00005000"],["111565.60000000","0.00000000"],["111565.95000000","0.00000000"],["111566.63000000","0.30000000"],["111567.73000000","0.07200000"],["111568.98000000","0.07200000"],["111569.96000000","0.13434000"],["111569.99000000","0.13430000"],["111571.90000000","0.00000000"],["111572.56000000","0.00000000"],["111572.57000000","0.98546000"],["111572.59000000","0.00000000"],["111573.10000000","0.00000000"],["111573.97000000","0.06899000"],["111574.11000000","0.00000000"],["111575.90000000","0.00000000"],["111575.94000000","0.00000000"],["111578.53000000","0.00000000"],["111579.79000000","0.00000000"],["111581.12000000","0.08507000"],["111582.33000000","0.22384000"],["111582.96000000","0.00000000"],["111583.31000000","0.35816000"],["111583.32000000","1.07472000"],["111584.61000000","0.00005000"],["111585.58000000","0.00000000"],["111600.53000000","0.53760000"],["111617.72000000","0.04097000"],["111621.29000000","0.04097000"],["111627.90000000","0.04097000"],["111629.49000000","0.00000000"],["111631.21000000","0.06495000"],["111632.44000000","0.13434000"],["111633.26000000","0.13430000"],["111633.99000000","0.04097000"],["111634.88000000","0.00100000"],["111634.89000000","0.00100000"],["111636.71000000","0.12591000"],["111637.39000000","0.04442000"],["111640.77000000","0.04800000"],["111640.86000000","0.04800000"],["111641.55000000","0.01707000"],["111643.53000000","0.00000000"],["111647.96000000","0.04097000"],["111649.23000000","0.00000000"],["111651.96000000","0.08294000"],["111655.85000000","0.08408000"],["111656.42000000","0.02137000"],["111657.99000000","0.04097000"],["111659.16000000","0.00000000"],["111659.74000000","0.00000000"],["111660.04000000","0.00000000"],["111660.13000000","0.00000000"],["111660.22000000","0.00000000"],["111660.38000000","0.00000000"],["111660.48000000","0.00000000"],["111661.97000000","0.04097000"],["111671.12000000","0.04097000"],["111711.92000000","0.02691000"],["111803.16000000","0.03997000"],["111804.28000000","0.00000000"],["111814.72000000","0.00000000"],["111912.01000000","0.02398000"],["111912.11000000","0.02398000"],["111913.80000000","0.02406000"],["111915.65000000","0.02398000"],["111921.05000000","0.02398000"],["111923.55000000","0.02398000"],["111925.25000000","0.02398000"],["111926.87000000","0.02398000"],["111928.55000000","0.02420000"],["111929.53000000","0.02398000"],["111930.05000000","0.02398000"],["112673.88000000","0.00000000"],["113226.98000000","0.00100000"],["117589.89000000","0.00021000"]]}
[2025-10-12T11:05:04.182Z] {"e":"depthUpdate","E":1760267104014,"s":"BTCUSDT","U":77965297043,"u":77965297301,"b":[["111553.66000000","1.10899000"],["111553.65000000","0.20698000"],["111553.50000000","0.00991000"],["111553.49000000","0.00010000"],["111553.29000000","0.00000000"],["111553.28000000","0.00010000"],["111553.27000000","0.01350000"],["111552.79000000","0.00000000"],["111551.67000000","0.00000000"],["111549.83000000","0.00000000"],["111549.82000000","0.00000000"],["111549.76000000","0.00543000"],["111548.66000000","0.02683000"],["111548.65000000","0.00727000"],["111547.55000000","0.01197000"],["111547.54000000","0.00010000"],["111547.53000000","0.01793000"],["111545.04000000","0.00010000"],["111545.03000000","0.05671000"],["111542.51000000","0.06179000"],["111542.50000000","0.00314000"],["111542.00000000","0.00000000"],["111541.60000000","0.00005000"],["111539.79000000","0.00000000"],["111539.16000000","0.00005000"],["111537.46000000","0.00000000"],["111536.49000000","0.04000000"],["111532.00000000","0.00000000"],["111527.09000000","1.02654000"],["111524.58000000","1.25396000"],["111519.03000000","0.05760000"],["111505.86000000","0.00000000"],["111504.76000000","0.00000000"],["111503.65000000","0.00000000"],["111500.78000000","0.00000000"],["111498.05000000","0.00000000"],["111497.33000000","1.19429000"],["111494.00000000","0.00200000"],["111492.00000000","0.00200000"],["111490.00000000","0.00200000"],["111488.00000000","0.00205000"],["111486.00000000","0.00200000"],["111466.58000000","0.00000000"],["111451.97000000","0.04426000"],["111448.46000000","0.51244000"],["111446.70000000","0.04800000"],["111439.37000000","0.05760000"],["111436.95000000","0.10080000"],["111434.87000000","0.00000000"],["111405.21000000","0.00000000"],["111386.75000000","0.00218000"],["111351.36000000","0.00000000"],["111297.74000000","0.00000000"],["111294.94000000","4.88355000"],["111187.03000000","0.45000000"],["111107.79000000","0.00000000"],["111091.19000000","0.00080000"],["110900.99000000","0.89111000"],["109880.35000000","0.00100000"],["100398.00000000","0.00600000"],["100397.00000000","0.00010000"],["89242.93000000","0.00022000"],["60000.00000000","53.14042000"]],"a":[["111553.67000000","5.22446000"],["111555.66000000","0.00100000"],["111559.77000000","0.00000000"],["111562.10000000","0.25425000"],["111562.52000000","0.35816000"],["111563.30000000","0.04000000"],["111563.40000000","0.00000000"],["111566.63000000","0.30000000"],["111570.46000000","0.03400000"],["111571.75000000","0.00005000"],["111572.56000000","0.00000000"],["111574.54000000","0.00895000"],["111578.72000000","0.89122000"],["111582.33000000","0.00000000"],["111582.63000000","1.18471000"],["111583.32000000","0.00000000"],["111583.33000000","0.00000000"],["111584.27000000","0.78201000"],["111584.28000000","0.00000000"],["111584.80000000","0.22384000"],["111593.35000000","0.02398000"],["111599.33000000","0.00000000"],["111600.53000000","0.40316000"],["111603.99000000","0.02398000"],["111617.99000000","0.02398000"],["111637.99000000","0.02398000"],["111645.88000000","0.00005000"],["111648.62000000","0.00005000"],["111649.23000000","0.07200000"],["111651.96000000","0.10692000"],["111659.77000000","0.00000000"],["111660.08000000","0.00000000"],["111660.21000000","0.00000000"],["111660.37000000","0.00000000"],["111660.43000000","0.00000000"],["111661.08000000","0.00000000"],["111661.81000000","0.00000000"],["111662.38000000","0.00000000"],["111662.90000000","0.00007000"],["111667.25000000","0.04097000"],["111675.98000000","0.04097000"],["111786.88000000","4.70524000"],["111787.40000000","0.00000000"],["111790.00000000","0.00449000"],["111926.92000000","0.02398000"],["111928.58000000","0.02398000"],["111929.57000000","0.02398000"],["111930.09000000","0.02398000"],["113226.98000000","0.00100000"]]}
[2025-10-12T11:05:05.181Z] {"e":"depthUpdate","E":1760267105014,"s":"BTCUSDT","U":77965297302,"u":77965297398,"b":[["111553.66000000","1.17447000"],["111553.65000000","0.29145000"],["111553.28000000","0.00000000"],["111548.67000000","0.00010000"],["111548.66000000","0.03843000"],["111548.65000000","0.00727000"],["111548.09000000","0.01197000"],["111547.55000000","0.00000000"],["111547.53000000","0.01798000"],["111544.82000000","0.00005000"],["111544.81000000","0.04540000"],["111542.52000000","0.00005000"],["111542.51000000","0.18821000"],["111542.50000000","0.45314000"],["111536.98000000","0.00000000"],["111535.02000000","0.01165000"],["111534.85000000","0.00000000"],["111532.75000000","0.00100000"],["111528.66000000","0.00005000"],["111527.03000000","0.00042000"],["111520.23000000","0.08659000"],["111464.73000000","0.00005000"],["111453.43000000","0.00005000"],["111434.87000000","0.05760000"],["111392.99000000","0.00218000"],["111386.75000000","0.00000000"],["111327.42000000","0.99299000"],["111280.10000000","0.00000000"],["111273.19000000","0.00250000"],["111097.43000000","0.00080000"],["111091.19000000","0.00000000"],["100397.00000000","0.00010000"],["89242.93000000","0.00022000"],["60000.00000000","53.14032000"],["40159.32000000","0.00030000"]],"a":[["111553.67000000","4.77056000"],["111560.35000000","0.01388000"],["111560.44000000","0.04804000"],["111584.80000000","0.00000000"],["111600.53000000","0.17932000"],["111600.60000000","0.13444000"],["111655.85000000","0.12860000"],["111659.92000000","0.00000000"],["111660.47000000","0.22384000"],["111661.02000000","0.35828000"],["111733.49000000","0.02689000"],["111769.82000000","0.00000000"],["111822.59000000","0.20114000"],["111840.00000000","0.17066000"],["111910.55000000","0.02689000"],["111915.40000000","0.55803000"],["111956.06000000","0.00000000"],["111963.01000000","0.00250000"],["113226.98000000","0.00100000"]]}
[2025-10-12T11:05:06.182Z] {"e":"depthUpdate","E":1760267106014,"s":"BTCUSDT","U":77965297399,"u":77965297637,"b":[["111553.66000000","0.86243000"],["111553.65000000","0.26403000"],["111553.28000000","0.00000000"],["111548.67000000","0.00000000"],["111548.66000000","0.01197000"],["111548.65000000","0.00722000"],["111548.09000000","0.00000000"],["111547.84000000","0.00000000"],["111547.83000000","0.00000000"],["111547.54000000","0.00010000"],["111547.53000000","0.01803000"],["111547.35000000","0.00010000"],["111547.34000000","0.00000000"],["111547.07000000","0.00000000"],["111547.06000000","0.02691000"],["111546.72000000","0.00000000"],["111546.71000000","0.00005000"],["111545.04000000","0.00000000"],["111545.03000000","0.00000000"],["111544.82000000","0.00010000"],["111544.81000000","0.04545000"],["111542.52000000","0.00005000"],["111542.51000000","0.06184000"],["111542.50000000","0.00314000"],["111539.16000000","0.00000000"],["111538.25000000","0.00005000"],["111535.98000000","0.00000000"],["111532.75000000","0.00000000"],["111524.58000000","0.00000000"],["111520.30000000","0.00000000"],["111518.46000000","0.00000000"],["111512.47000000","0.00095000"],["111501.40000000","0.00000000"],["111499.22000000","0.00000000"],["111499.19000000","1.39315000"],["111495.09000000","0.00000000"],["111491.79000000","0.30248000"],["111482.62000000","0.00267000"],["111477.54000000","0.00000000"],["111467.85000000","0.00005000"],["111461.52000000","0.00618000"],["111459.00000000","0.00164000"],["111458.02000000","0.00000000"],["111451.97000000","0.00000000"],["111445.63000000","0.00005000"],["111442.11000000","0.04426000"],["111405.61000000","0.00218000"],["111392.99000000","0.00000000"],["111389.87000000","0.02510000"],["111346.44000000","0.00065000"],["111110.02000000","0.00080000"],["111097.43000000","0.00000000"],["109880.35000000","0.00100000"],["105900.00000000","0.07803000"],["102591.46000000","0.00000000"],["101100.00000000","1.02286000"],["100398.00000000","0.00600000"],["100397.00000000","0.00010000"],["89242.93000000","0.00022000"],["42000.00000000","1.49196000"]],"a":[["111553.67000000","5.75515000"],["111556.53000000","0.03585000"],["111557.01000000","0.00000000"],["111558.37000000","0.08507000"],["111560.00000000","0.00260000"],["111560.35000000","0.00000000"],["111560.65000000","0.00000000"],["111563.30000000","0.00000000"],["111566.66000000","0.35844000"],["111569.96000000","0.00000000"],["111569.99000000","0.00000000"],["111571.20000000","0.00005000"],["111574.36000000","0.01388000"],["111575.10000000","0.00005000"],["111598.33000000","0.01384000"],["111600.53000000","0.89560000"],["111600.60000000","0.00000000"],["111621.30000000","0.09598000"],["111628.86000000","0.13434000"],["111629.51000000","0.00000000"],["111632.44000000","0.00000000"],["111633.26000000","0.00000000"],["111642.74000000","0.02398000"],["111657.31000000","0.02076000"],["111659.87000000","0.00000000"],["111660.03000000","0.00000000"],["111660.15000000","0.00000000"],["111660.47000000","0.00000000"],["111660.91000000","0.00000000"],["111661.02000000","0.00000000"],["111661.20000000","0.01736000"],["111673.67000000","0.03997000"],["111678.08000000","0.02398000"],["111684.56000000","0.00000000"],["111684.74000000","0.07320000"],["111688.71000000","0.00000000"],["111735.95000000","0.02689000"],["111793.30000000","0.00000000"],["111805.60000000","0.02398000"],["111810.49000000","0.02420000"],["111836.07000000","0.00000000"],["111838.29000000","0.00000000"],["111892.45000000","0.00000000"],["111899.81000000","0.03765000"],["111905.75000000","0.02689000"],["111908.26000000","0.02689000"],["111910.62000000","0.02689000"],["111915.40000000","0.00000000"],["112053.38000000","0.00000000"],["112136.49000000","0.02398000"],["112136.57000000","0.02398000"],["112136.65000000","0.02398000"],["112136.74000000","0.02398000"],["112138.82000000","0.02398000"],["112139.13000000","0.02398000"],["112140.73000000","0.02398000"],["112141.56000000","0.02398000"],["113226.98000000","0.00100000"]]}
[2025-10-12T11:05:07.182Z] {"e":"depthUpdate","E":1760267107014,"s":"BTCUSDT","U":77965297638,"u":77965297826,"b":[["111553.66000000","0.94263000"],["111553.65000000","0.20703000"],["111553.56000000","0.00005000"],["111553.28000000","0.00010000"],["111548.66000000","0.01197000"],["111548.65000000","0.00722000"],["111547.55000000","0.00000000"],["111547.54000000","0.00010000"],["111547.53000000","0.01803000"],["111547.35000000","0.00000000"],["111547.07000000","0.00000000"],["111547.06000000","0.00000000"],["111546.95000000","0.00010000"],["111546.94000000","0.00000000"],["111546.80000000","0.00000000"],["111544.82000000","0.00005000"],["111544.81000000","0.04550000"],["111543.44000000","0.04420000"],["111543.01000000","0.00000000"],["111542.52000000","0.00000000"],["111542.51000000","0.00005000"],["111542.50000000","0.00314000"],["111541.89000000","0.00000000"],["111537.68000000","0.00000000"],["111537.43000000","0.00005000"],["111536.93000000","0.00155000"],["111533.59000000","0.00000000"],["111532.95000000","0.00058000"],["111530.26000000","0.15000000"],["111530.24000000","0.00007000"],["111527.11000000","0.00000000"],["111527.09000000","0.54417000"],["111526.35000000","0.00000000"],["111526.33000000","0.12602000"],["111520.28000000","0.00000000"],["111519.33000000","0.35847000"],["111517.44000000","0.00000000"],["111501.40000000","0.00005000"],["111487.36000000","0.03000000"],["111482.62000000","0.00088000"],["111472.64000000","0.00000000"],["111470.97000000","0.00005000"],["111442.24000000","0.14538000"],["111437.83000000","0.00005000"],["109880.35000000","0.00100000"],["105900.00000000","0.07792000"],["100398.00000000","0.00600000"],["100397.00000000","0.00010000"],["89242.93000000","0.00022000"],["40159.32000000","0.00045000"],["33000.00000000","3.87311000"]],"a":[["111553.67000000","5.38647000"],["111554.06000000","0.01370000"],["111554.50000000","0.00000000"],["111554.51000000","0.00005000"],["111554.63000000","0.00010000"],["111554.65000000","0.05393000"],["111555.89000000","0.03964000"],["111569.95000000","0.13434000"],["111574.34000000","0.01388000"],["111574.36000000","0.00000000"],["111578.45000000","0.00005000"],["111580.00000000","0.02052000"],["111587.97000000","0.02689000"],["111600.53000000","0.89560000"],["111628.86000000","0.00000000"],["111632.43000000","0.13434000"],["111659.76000000","0.00000000"],["111660.05000000","0.00000000"],["111660.67000000","0.00000000"],["111674.59000000","0.02510000"],["111679.98000000","0.02510000"],["111684.73000000","0.02510000"],["111687.99000000","0.02510000"],["111695.51000000","0.02510000"],["111911.71000000","0.55803000"],["113226.98000000","0.00100000"],["158260.00000000","0.00004000"]]}
[2025-10-12T11:05:08.182Z] {"e":"depthUpdate","E":1760267108014,"s":"BTCUSDT","U":77965297827,"u":77965297954,"b":[["111553.66000000","0.99805000"],["111553.65000000","0.27656000"],["111547.53000000","0.01803000"],["111546.95000000","0.00000000"],["111546.65000000","0.00010000"],["111546.64000000","0.02691000"],["111544.82000000","0.00010000"],["111544.81000000","0.04545000"],["111543.45000000","0.00000000"],["111542.00000000","0.06081000"],["111541.28000000","0.00000000"],["111538.33000000","0.03415000"],["111536.93000000","0.00150000"],["111536.49000000","0.00000000"],["111534.90000000","0.00005000"],["111532.11000000","0.14627000"],["111531.19000000","0.04000000"],["111530.72000000","0.15000000"],["111530.70000000","0.35816000"],["111530.28000000","0.00000000"],["111530.26000000","0.00000000"],["111504.75000000","0.00000000"],["111497.33000000","0.00000000"],["111494.59000000","1.18435000"],["111494.12000000","0.00000000"],["111493.92000000","0.00000000"],["111493.10000000","0.06569000"],["111474.09000000","0.00005000"],["111463.30000000","0.00510000"],["111430.03000000","0.00005000"],["111419.48000000","0.07528000"],["111405.61000000","0.00000000"],["111399.87000000","0.00000000"],["111392.05000000","0.00000000"],["111374.09000000","0.09011000"],["111294.94000000","0.00000000"],["111292.20000000","4.85789000"],["111205.65000000","0.02599000"],["111110.02000000","0.00000000"],["111078.55000000","0.00080000"],["109880.35000000","0.00100000"],["109500.00000000","12.83923000"],["100397.00000000","0.00010000"],["89242.93000000","0.00022000"],["42000.00000000","1.49096000"]],"a":[["111553.67000000","5.40002000"],["111555.55000000","0.05919000"],["111558.00000000","0.00275000"],["111566.63000000","0.30000000"],["111569.61000000","0.13430000"],["111570.46000000","0.00000000"],["111571.90000000","0.00000000"],["111572.49000000","0.00012000"],["111572.56000000","0.00000000"],["111576.48000000","1.19217000"],["111578.72000000","0.61410000"],["111582.63000000","0.00000000"],["111585.15000000","0.00005000"],["111590.90000000","0.00000000"],["111659.79000000","0.13444000"],["111659.96000000","0.00000000"],["111661.31000000","0.00000000"],["111730.72000000","0.02398000"],["111749.29000000","0.00000000"],["111779.12000000","4.73856000"],["111786.88000000","0.00000000"],["111884.55000000","0.02599000"],["111911.71000000","0.55803000"],["111930.09000000","0.00000000"],["113226.98000000","0.00100000"],["120000.00000000","40.38044000"]]}
[2025-10-12T11:05:09.182Z] {"e":"depthUpdate","E":1760267109014,"s":"BTCUSDT","U":77965297955,"u":77965298555,"b":[["111553.66000000","2.71770000"],["111553.65000000","0.20678000"],["111553.56000000","0.00000000"],["111553.50000000","0.00996000"],["111553.49000000","0.00010000"],["111553.29000000","0.00010000"],["111553.28000000","0.01894000"],["111553.27000000","0.01350000"],["111551.43000000","0.00364000"],["111550.20000000","0.00010000"],["111550.19000000","0.04570000"],["111549.76000000","0.00548000"],["111549.52000000","0.01192000"],["111548.85000000","0.00005000"],["111548.67000000","0.00010000"],["111548.66000000","0.02941000"],["111547.54000000","0.00000000"],["111547.53000000","0.01798000"],["111546.65000000","0.00000000"],["111546.64000000","0.02696000"],["111546.59000000","0.04000000"],["111544.82000000","0.00000000"],["111544.81000000","0.04545000"],["111544.50000000","0.00400000"],["111544.38000000","0.00005000"],["111543.45000000","0.00000000"],["111543.44000000","0.00000000"],["111542.51000000","0.31165000"],["111542.50000000","0.45314000"],["111542.01000000","0.00000000"],["111542.00000000","0.00000000"],["111541.28000000","0.00007000"],["111539.71000000","0.11195000"],["111539.22000000","0.00000000"],["111539.20000000","0.35816000"],["111539.06000000","0.00005000"],["111538.58000000","0.00000000"],["111538.36000000","0.21916000"],["111538.35000000","0.00000000"],["111538.33000000","0.00000000"],["111538.27000000","0.00000000"],["111538.26000000","0.10005000"],["111537.43000000","0.00000000"],["111535.46000000","0.00000000"],["111535.26000000","0.15000000"],["111535.24000000","0.35816000"],["111533.92000000","0.00448000"],["111533.91000000","0.04073000"],["111533.57000000","0.06646000"],["111533.29000000","0.00006000"],["111532.95000000","0.00000000"],["111532.93000000","0.00058000"],["111532.79000000","0.03941000"],["111532.50000000","0.00400000"],["111531.19000000","0.00000000"],["111530.80000000","0.13434000"],["111530.72000000","0.00000000"],["111529.31000000","0.01785000"],["111528.06000000","0.13430000"],["111527.63000000","0.00000000"],["111527.09000000","1.02425000"],["111526.83000000","0.13430000"],["111526.34000000","1.25396000"],["111525.77000000","0.00000000"],["111525.61000000","0.00000000"],["111525.34000000","0.01388000"],["111523.88000000","0.05760000"],["111523.59000000","0.04480000"],["111522.70000000","1.25396000"],["111520.98000000","0.00000000"],["111519.34000000","1.25396000"],["111515.11000000","0.00000000"],["111512.70000000","0.00000000"],["111509.32000000","0.00000000"],["111508.08000000","0.00000000"],["111505.28000000","0.00000000"],["111504.73000000","0.04479000"],["111504.15000000","0.00000000"],["111503.22000000","0.13444000"],["111502.87000000","0.30245000"],["111502.81000000","0.00000000"],["111499.68000000","0.00000000"],["111498.68000000","0.00000000"],["111494.50000000","0.00000000"],["111491.79000000","0.00000000"],["111487.00000000","0.00000000"],["111483.46000000","0.00000000"],["111477.21000000","0.00005000"],["111476.45000000","0.04426000"],["111468.24000000","0.13434000"],["111465.72000000","0.00000000"],["111463.03000000","0.00000000"],["111461.33000000","0.00000000"],["111460.59000000","0.13430000"],["111459.35000000","0.13430000"],["111448.77000000","0.00000000"],["111446.84000000","0.00000000"],["111446.44000000","0.00000000"],["111445.60000000","0.00000000"],["111442.11000000","0.00000000"],["111436.33000000","0.28756000"],["111436.32000000","0.13444000"],["111435.95000000","0.00000000"],["111422.23000000","0.00005000"],["111420.98000000","0.00000000"],["111413.67000000","0.00000000"],["111402.46000000","0.02330000"],["111399.87000000","0.13210000"],["111399.45000000","0.02330000"],["111396.32000000","0.00218000"],["111374.09000000","0.08793000"],["111351.36000000","0.99787000"],["111327.42000000","0.00000000"],["111233.09000000","0.00468000"],["111197.04000000","0.00000000"],["111187.03000000","0.00000000"],["111183.97000000","0.02599000"],["111100.75000000","0.00080000"],["111078.55000000","0.00000000"],["109880.35000000","0.00100000"],["100398.00000000","0.00600000"],["100397.00000000","0.00010000"],["89242.93000000","0.00022000"]],"a":[["111553.67000000","3.59900000"],["111553.68000000","0.00025000"],["111553.69000000","0.00000000"],["111553.70000000","0.00005000"],["111553.71000000","0.00000000"],["111553.75000000","0.00010000"],["111553.83000000","0.00921000"],["111553.84000000","0.00020000"],["111554.00000000","0.00285000"],["111554.01000000","0.00020000"],["111554.06000000","0.01365000"],["111554.07000000","0.00010000"],["111554.63000000","0.00000000"],["111554.64000000","0.00010000"],["111554.65000000","0.05388000"],["111554.66000000","0.00010000"],["111555.05000000","0.00000000"],["111555.06000000","0.00000000"],["111555.51000000","0.00000000"],["111555.53000000","0.00010000"],["111555.54000000","0.14515000"],["111555.55000000","0.05914000"],["111555.66000000","0.00000000"],["111555.73000000","0.00000000"],["111555.89000000","0.00000000"],["111556.00000000","0.00270000"],["111556.07000000","0.03975000"],["111556.15000000","0.00000000"],["111556.16000000","0.00000000"],["111556.53000000","0.00000000"],["111556.61000000","0.00000000"],["111556.76000000","0.03595000"],["111557.19000000","0.04084000"],["111557.27000000","0.03590000"],["111557.28000000","0.03585000"],["111557.57000000","0.00538000"],["111557.79000000","0.00000000"],["111557.86000000","0.00000000"],["111557.97000000","0.00000000"],["111557.98000000","0.00000000"],["111558.00000000","0.00270000"],["111558.37000000","0.00000000"],["111558.68000000","0.00717000"],["111558.73000000","0.00155000"],["111558.98000000","0.06646000"],["111559.71000000","0.00000000"],["111559.72000000","0.01402000"],["111559.80000000","0.01798000"],["111560.00000000","0.00265000"],["111560.44000000","0.04804000"],["111561.70000000","0.00005000"],["111562.00000000","0.00265000"],["111562.03000000","0.04481000"],["111562.10000000","0.00000000"],["111562.52000000","0.00000000"],["111562.97000000","0.00000000"],["111563.20000000","0.01831000"],["111564.00000000","0.00260000"],["111564.30000000","0.00000000"],["111564.50000000","0.00400000"],["111564.83000000","0.00150000"],["111564.86000000","0.12901000"],["111565.50000000","0.04000000"],["111565.70000000","0.00448000"],["111565.71000000","0.00000000"],["111566.01000000","0.00000000"],["111566.63000000","0.30000000"],["111566.66000000","0.00000000"],["111568.10000000","0.00000000"],["111568.25000000","0.00000000"],["111568.97000000","0.35846000"],["111569.45000000","0.00000000"],["111569.61000000","0.00000000"],["111569.95000000","0.00000000"],["111570.40000000","0.16145000"],["111571.90000000","0.00000000"],["111572.56000000","0.00000000"],["111573.44000000","0.08507000"],["111574.05000000","0.00000000"],["111578.10000000","0.00000000"],["111583.69000000","0.13430000"],["111584.90000000","0.13430000"],["111585.34000000","0.17932000"],["111586.48000000","0.22384000"],["111586.60000000","0.22384000"],["111588.76000000","0.08507000"],["111589.43000000","0.13434000"],["111600.08000000","0.00000000"],["111600.41000000","0.13444000"],["111600.53000000","0.00000000"],["111602.49000000","0.00005000"],["111606.96000000","0.00000000"],["111631.56000000","0.07252000"],["111632.43000000","0.00000000"],["111634.88000000","0.00000000"],["111634.89000000","0.00000000"],["111635.78000000","0.00100000"],["111635.79000000","0.00100000"],["111638.81000000","0.00000000"],["111641.55000000","0.00000000"],["111646.17000000","0.13430000"],["111647.39000000","0.13430000"],["111651.52000000","0.00000000"],["111651.91000000","0.13434000"],["111654.31000000","0.01707000"],["111655.85000000","0.18144000"],["111656.42000000","0.00000000"],["111660.04000000","0.00000000"],["111660.13000000","0.00000000"],["111660.57000000","0.17932000"],["111662.62000000","0.22384000"],["111662.89000000","0.02137000"],["111664.70000000","0.22384000"],["111678.73000000","0.02398000"],["111764.69000000","0.02330000"],["111768.82000000","0.02330000"],["111911.71000000","0.00000000"],["111914.74000000","0.02599000"],["113226.98000000","0.00100000"]]}
[2025-10-12T11:05:10.182Z] {"e":"depthUpdate","E":1760267110014,"s":"BTCUSDT","U":77965298556,"u":77965299144,"b":[["111553.66000000","3.35221000"],["111553.65000000","0.20683000"],["111553.32000000","0.00005000"],["111553.27000000","0.01355000"],["111552.55000000","0.01197000"],["111550.20000000","0.00000000"],["111550.19000000","0.04565000"],["111549.77000000","0.00000000"],["111549.76000000","0.00548000"],["111549.52000000","0.00000000"],["111549.13000000","0.01388000"],["111548.67000000","0.00000000"],["111548.65000000","0.00727000"],["111547.98000000","0.00100000"],["111547.53000000","0.01798000"],["111547.37000000","0.00000000"],["111546.64000000","0.02691000"],["111546.59000000","0.00000000"],["111544.50000000","0.00400000"],["111542.87000000","0.00000000"],["111542.77000000","0.48811000"],["111542.76000000","0.35816000"],["111542.52000000","0.00000000"],["111542.51000000","0.00000000"],["111539.22000000","0.00000000"],["111539.06000000","0.00000000"],["111538.36000000","0.35091000"],["111536.93000000","0.00150000"],["111535.27000000","0.45020000"],["111535.26000000","0.15000000"],["111534.84000000","0.08507000"],["111533.02000000","0.00000000"],["111532.11000000","0.21887000"],["111531.55000000","0.00005000"],["111531.49000000","0.00000000"],["111530.72000000","0.00000000"],["111529.73000000","0.04413000"],["111528.82000000","0.04479000"],["111525.78000000","0.00000000"],["111525.34000000","0.00000000"],["111523.81000000","0.04800000"],["111523.59000000","0.00000000"],["111521.91000000","0.04426000"],["111519.21000000","0.00000000"],["111517.96000000","0.00000000"],["111515.24000000","0.30242000"],["111515.18000000","0.00000000"],["111513.87000000","0.64980000"],["111512.59000000","0.00000000"],["111510.34000000","0.00000000"],["111508.62000000","0.00000000"],["111508.10000000","0.00000000"],["111507.35000000","0.00009000"],["111505.13000000","0.00018000"],["111504.73000000","0.00000000"],["111504.65000000","0.00000000"],["111503.23000000","0.00000000"],["111502.87000000","0.00000000"],["111502.43000000","0.00000000"],["111496.97000000","0.00009000"],["111494.27000000","0.00000000"],["111484.79000000","0.17388000"],["111482.65000000","0.08694000"],["111480.34000000","0.00005000"],["111476.45000000","0.00000000"],["111461.68000000","0.00090000"],["111458.99000000","0.00000000"],["111457.15000000","0.01403000"],["111420.78000000","0.08694000"],["111418.85000000","0.08694000"],["111416.91000000","0.08694000"],["111414.43000000","0.00005000"],["111413.03000000","0.08694000"],["111411.10000000","0.08694000"],["111366.58000000","0.00000000"],["111366.44000000","0.00000000"],["111366.12000000","0.00000000"],["111351.36000000","0.00000000"],["111349.13000000","0.99160000"],["111307.36000000","0.00000000"],["111307.28000000","0.00000000"],["111306.65000000","0.00000000"],["111305.82000000","0.00000000"],["111305.81000000","0.00000000"],["111231.39000000","0.05896000"],["111231.12000000","0.05896000"],["111230.31000000","0.05896000"],["111230.04000000","0.05978000"],["111229.77000000","0.05896000"],["111229.50000000","0.05896000"],["111228.86000000","0.05896000"],["111228.59000000","0.05896000"],["111137.95000000","0.00000000"],["111137.41000000","0.03587000"],["111134.52000000","0.00000000"],["111133.88000000","0.00000000"],["111133.61000000","0.00000000"],["111133.34000000","0.00000000"],["109880.35000000","0.00100000"],["100397.00000000","0.00010000"],["89242.93000000","0.00022000"]],"a":[["111553.67000000","0.55295000"],["111553.68000000","0.00020000"],["111553.69000000","0.00000000"],["111554.00000000","0.00285000"],["111554.01000000","0.00020000"],["111554.06000000","0.01360000"],["111554.07000000","0.00010000"],["111554.51000000","0.00000000"],["111554.64000000","0.00000000"],["111554.65000000","0.00000000"],["111554.66000000","0.00000000"],["111555.53000000","0.00000000"],["111555.54000000","0.00000000"],["111555.55000000","0.00000000"],["111555.77000000","0.00005000"],["111556.00000000","0.00265000"],["111556.07000000","0.00000000"],["111556.15000000","0.00010000"],["111556.16000000","0.62010000"],["111556.76000000","0.00000000"],["111557.07000000","0.00000000"],["111557.08000000","0.00000000"],["111557.19000000","0.00000000"],["111557.27000000","0.00000000"],["111557.28000000","0.00000000"],["111557.38000000","0.04618000"],["111557.57000000","0.00543000"],["111558.68000000","0.00722000"],["111558.73000000","0.00150000"],["111558.92000000","0.00000000"],["111558.93000000","0.00000000"],["111558.95000000","0.00010000"],["111558.96000000","0.30252000"],["111558.97000000","0.00000000"],["111558.98000000","0.00000000"],["111559.71000000","0.00000000"],["111559.72000000","0.00005000"],["111559.80000000","0.01808000"],["111560.00000000","0.00265000"],["111560.05000000","0.00000000"],["111560.43000000","0.00005000"],["111560.44000000","0.04814000"],["111561.70000000","0.02005000"],["111562.00000000","0.00260000"],["111562.02000000","0.00000000"],["111562.03000000","0.00005000"],["111562.26000000","0.00000000"],["111563.20000000","0.00000000"],["111564.00000000","0.00260000"],["111564.47000000","0.00000000"],["111564.50000000","0.00005000"],["111564.83000000","0.00155000"],["111564.86000000","0.00000000"],["111564.87000000","0.02695000"],["111565.37000000","0.00000000"],["111565.50000000","0.00000000"],["111565.59000000","0.00000000"],["111565.70000000","0.00453000"],["111565.96000000","0.00000000"],["111566.00000000","0.00265000"],["111566.63000000","0.00000000"],["111566.64000000","0.00000000"],["111567.61000000","0.04476000"],["111568.97000000","0.00000000"],["111569.68000000","0.00000000"],["111570.29000000","0.00100000"],["111570.40000000","0.04950000"],["111570.71000000","0.03400000"],["111571.37000000","0.35845000"],["111571.90000000","0.30000000"],["111572.56000000","0.00000000"],["111572.58000000","0.00000000"],["111573.44000000","0.00000000"],["111573.97000000","0.00000000"],["111574.54000000","0.00000000"],["111575.94000000","0.00000000"],["111575.98000000","0.11195000"],["111577.25000000","0.00895000"],["111578.00000000","0.04260000"],["111578.40000000","0.08507000"],["111592.70000000","0.01403000"],["111611.43000000","0.00005000"],["111635.78000000","0.00000000"],["111635.79000000","0.00000000"],["111635.84000000","0.00000000"],["111635.85000000","0.00000000"],["111636.79000000","0.00000000"],["111636.80000000","0.00000000"],["111637.39000000","0.00000000"],["111637.84000000","0.00100000"],["111643.50000000","0.04338000"],["111656.79000000","0.00000000"],["111660.56000000","0.00223000"],["111661.98000000","0.00000000"],["111662.61000000","0.37071000"],["111662.89000000","0.00000000"],["111662.95000000","0.00000000"],["111663.32000000","0.00000000"],["111664.09000000","0.00000000"],["111665.02000000","0.00000000"],["111665.18000000","0.00000000"],["111672.56000000","0.00000000"],["111678.73000000","0.00000000"],["111689.81000000","0.02398000"],["111771.99000000","0.00089000"],["111805.60000000","0.00000000"],["111817.41000000","0.02398000"],["111930.05000000","0.00000000"],["111940.87000000","0.02398000"],["112138.82000000","0.00000000"],["112139.05000000","0.00000000"],["112139.13000000","0.00000000"],["112139.21000000","0.00000000"],["112151.98000000","0.02398000"],["112152.22000000","0.02398000"],["112152.39000000","0.02398000"],["112152.40000000","0.02398000"],["113226.98000000","0.00100000"],["116520.00000000","0.01166000"]]}
[2025-10-12T11:05:11.182Z] {"e":"depthUpdate","E":1760267111014,"s":"BTCUSDT","U":77965299145,"u":77965299345,"b":[["111553.66000000","3.34988000"],["111553.65000000","0.20693000"],["111553.32000000","0.00000000"],["111550.20000000","0.00010000"],["111549.76000000","0.00548000"],["111549.25000000","0.05522000"],["111549.24000000","0.04022000"],["111549.13000000","0.00000000"],["111548.67000000","0.00000000"],["111548.66000000","0.00000000"],["111548.65000000","0.00732000"],["111548.12000000","0.04122000"],["111538.26000000","0.10005000"],["111535.29000000","0.15000000"],["111535.26000000","0.00000000"],["111533.91000000","0.00000000"],["111532.79000000","0.00000000"],["111528.94000000","0.07920000"],["111528.84000000","0.00044000"],["111528.82000000","0.00000000"],["111528.20000000","0.00005000"],["111527.80000000","0.00044000"],["111527.71000000","0.10080000"],["111525.60000000","0.00000000"],["111525.49000000","0.00000000"],["111525.48000000","0.00000000"],["111525.35000000","0.01388000"],["111522.36000000","0.00000000"],["111521.12000000","0.00000000"],["111515.64000000","0.04479000"],["111515.24000000","0.00000000"],["111512.47000000","0.00095000"],["111511.45000000","0.00000000"],["111508.95000000","0.30244000"],["111508.62000000","0.00005000"],["111504.15000000","0.00000000"],["111499.19000000","0.96680000"],["111494.59000000","0.00000000"],["111483.46000000","0.00005000"],["111472.22000000","0.00000000"],["111457.15000000","0.00000000"],["111436.95000000","0.00000000"],["111421.27000000","0.20816000"],["111406.63000000","0.00005000"],["111349.13000000","0.99470000"],["110000.00000000","26.34882000"],["109880.35000000","0.00100000"],["109020.57000000","0.00091000"],["108988.26000000","0.00000000"],["102591.46000000","0.00010000"],["100398.00000000","0.00600000"],["100397.00000000","0.00010000"],["100000.00000000","214.28550000"],["89242.93000000","0.00022000"]],"a":[["111553.67000000","0.83179000"],["111555.77000000","0.00000000"],["111555.91000000","0.00010000"],["111556.00000000","0.00265000"],["111556.16000000","0.62010000"],["111557.37000000","0.00000000"],["111557.38000000","0.00000000"],["111559.80000000","0.01808000"],["111560.43000000","0.00005000"],["111561.70000000","0.02950000"],["111562.00000000","0.00260000"],["111563.20000000","0.00000000"],["111564.00000000","0.00260000"],["111564.13000000","0.00000000"],["111564.14000000","0.01825000"],["111564.47000000","0.00000000"],["111564.87000000","0.02695000"],["111565.59000000","0.00000000"],["111566.00000000","0.00270000"],["111566.07000000","0.04009000"],["111566.63000000","0.15000000"],["111567.19000000","0.04039000"],["111567.29000000","0.00000000"],["111570.29000000","0.00000000"],["111571.90000000","0.15000000"],["111572.57000000","0.58333000"],["111576.48000000","0.00000000"],["111592.70000000","0.00000000"],["111606.96000000","0.00005000"],["111611.43000000","0.00000000"],["111637.85000000","0.00100000"],["111660.56000000","0.00223000"],["111662.61000000","0.58606000"],["111662.96000000","0.99920000"],["111683.67000000","0.00000000"],["111683.80000000","0.00000000"],["111684.14000000","0.00000000"],["111689.69000000","0.00000000"],["111771.99000000","0.00089000"],["111911.71000000","0.00000000"],["113226.98000000","0.00100000"]]}
[2025-10-12T11:05:12.183Z] {"e":"depthUpdate","E":1760267112014,"s":"BTCUSDT","U":77965299346,"u":77965299797,"b":[["111553.66000000","4.15530000"],["111553.65000000","0.21446000"],["111553.50000000","0.00991000"],["111553.32000000","0.00005000"],["111553.29000000","0.00000000"],["111553.28000000","0.12753000"],["111553.27000000","0.01345000"],["111552.55000000","0.00000000"],["111552.52000000","0.00000000"],["111550.31000000","0.35816000"],["111550.20000000","0.00000000"],["111549.76000000","0.00543000"],["111549.25000000","0.18022000"],["111549.24000000","0.04027000"],["111549.08000000","0.01798000"],["111548.76000000","0.01388000"],["111548.65000000","0.00727000"],["111547.98000000","0.00000000"],["111547.69000000","0.00044000"],["111546.64000000","0.02696000"],["111546.15000000","0.35816000"],["111545.47000000","0.00043000"],["111545.12000000","0.06646000"],["111544.50000000","0.00405000"],["111542.79000000","0.15000000"],["111542.65000000","0.00000000"],["111539.86000000","0.00000000"],["111539.71000000","0.00000000"],["111539.30000000","0.00000000"],["111539.22000000","0.00000000"],["111538.36000000","0.74242000"],["111538.26000000","0.10000000"],["111538.11000000","0.00044000"],["111537.59000000","0.08505000"],["111537.57000000","0.13434000"],["111536.62000000","0.00000000"],["111536.28000000","0.00000000"],["111535.30000000","1.25396000"],["111535.29000000","0.00000000"],["111535.02000000","0.05165000"],["111533.06000000","0.00058000"],["111532.93000000","0.00000000"],["111532.27000000","0.04379000"],["111532.11000000","0.56867000"],["111530.81000000","1.25396000"],["111530.80000000","0.00000000"],["111529.73000000","0.00000000"],["111529.64000000","0.00895000"],["111527.71000000","0.14559000"],["111525.71000000","0.00000000"],["111525.35000000","0.00000000"],["111524.89000000","0.00000000"],["111524.85000000","0.00005000"],["111523.82000000","0.00000000"],["111523.52000000","0.00000000"],["111523.13000000","0.00000000"],["111522.84000000","0.00000000"],["111521.35000000","0.22384000"],["111520.75000000","0.00000000"],["111520.51000000","0.00000000"],["111520.12000000","0.00000000"],["111517.96000000","0.30241000"],["111517.43000000","0.00000000"],["111516.11000000","0.00000000"],["111515.64000000","0.00000000"],["111511.05000000","0.00009000"],["111508.95000000","0.00000000"],["111508.83000000","0.00018000"],["111508.62000000","0.00000000"],["111507.35000000","0.00000000"],["111506.81000000","0.00000000"],["111506.80000000","0.00000000"],["111506.66000000","1.24105000"],["111505.13000000","0.00000000"],["111501.01000000","0.07920000"],["111500.67000000","0.00009000"],["111499.79000000","0.10080000"],["111496.97000000","0.00000000"],["111486.58000000","0.00005000"],["111478.50000000","0.13434000"],["111477.71000000","0.00667000"],["111477.65000000","0.00633000"],["111475.58000000","0.00322000"],["111473.80000000","0.00000000"],["111472.41000000","0.00000000"],["111468.24000000","0.00000000"],["111465.38000000","0.00090000"],["111461.68000000","0.00000000"],["111461.52000000","0.00000000"],["111461.18000000","0.00000000"],["111447.27000000","0.00000000"],["111444.74000000","0.00000000"],["111443.25000000","0.22384000"],["111442.18000000","0.00000000"],["111438.18000000","0.00000000"],["111436.95000000","0.00000000"],["111432.14000000","0.08039000"],["111430.71000000","0.00000000"],["111430.26000000","0.00000000"],["111398.83000000","0.00005000"],["111349.13000000","0.00000000"],["111253.66000000","0.00000000"],["111159.82000000","0.00000000"],["111159.46000000","0.00000000"],["109880.35000000","0.00100000"],["105900.00000000","0.07792000"],["102591.46000000","0.00000000"],["100398.00000000","0.00600000"],["100397.00000000","0.00010000"],["89242.93000000","0.00022000"],["33000.00000000","3.87311000"]],"a":[["111553.67000000","0.17887000"],["111553.68000000","0.00035000"],["111553.69000000","0.00020000"],["111553.83000000","0.00921000"],["111553.95000000","0.00010000"],["111554.00000000","0.00265000"],["111554.01000000","0.00010000"],["111554.03000000","0.00000000"],["111554.04000000","0.00000000"],["111554.05000000","0.00010000"],["111554.06000000","0.01360000"],["111554.64000000","0.00000000"],["111555.60000000","0.00015000"],["111555.91000000","0.00000000"],["111556.00000000","0.00265000"],["111556.15000000","0.00000000"],["111556.16000000","0.00000000"],["111557.44000000","0.00000000"],["111557.45000000","0.00000000"],["111558.68000000","0.00722000"],["111558.95000000","0.00000000"],["111558.96000000","0.00000000"],["111559.79000000","0.00010000"],["111559.80000000","0.01808000"],["111559.86000000","0.00010000"],["111559.87000000","0.30010000"],["111560.36000000","0.00005000"],["111560.37000000","0.32010000"],["111560.43000000","0.00000000"],["111560.44000000","0.04809000"],["111561.70000000","0.00005000"],["111561.71000000","0.02571000"],["111562.00000000","0.00265000"],["111563.71000000","0.10042000"],["111563.72000000","0.30242000"],["111564.14000000","0.00000000"],["111564.87000000","0.02695000"],["111565.70000000","0.00000000"],["111566.00000000","0.00260000"],["111566.07000000","0.00000000"],["111566.63000000","0.00000000"],["111566.65000000","0.41803000"],["111566.72000000","0.00000000"],["111566.88000000","0.00000000"],["111567.19000000","0.00000000"],["111567.61000000","0.00000000"],["111567.73000000","0.00000000"],["111568.49000000","0.00372000"],["111568.93000000","0.00000000"],["111568.98000000","0.00000000"],["111569.56000000","0.00070000"],["111570.05000000","0.00000000"],["111570.38000000","0.00000000"],["111570.98000000","0.00329000"],["111571.37000000","0.00000000"],["111571.59000000","0.00000000"],["111571.90000000","0.00448000"],["111571.91000000","0.00000000"],["111572.25000000","0.00000000"],["111572.55000000","0.00000000"],["111572.57000000","0.08747000"],["111574.14000000","0.00000000"],["111574.31000000","0.00000000"],["111575.94000000","0.00000000"],["111575.96000000","0.00000000"],["111575.97000000","0.35816000"],["111575.98000000","0.11195000"],["111577.09000000","0.00018000"],["111577.25000000","0.00000000"],["111578.00000000","0.00260000"],["111578.40000000","0.00000000"],["111578.50000000","0.00000000"],["111578.70000000","0.15000000"],["111578.72000000","0.43901000"],["111579.20000000","0.04800000"],["111579.41000000","0.35843000"],["111580.04000000","0.15000000"],["111580.06000000","0.00000000"],["111580.80000000","0.00000000"],["111581.04000000","0.00895000"],["111583.71000000","0.08507000"],["111584.25000000","0.00000000"],["111586.20000000","0.04000000"],["111589.40000000","1.19578000"],["111591.15000000","0.08505000"],["111637.84000000","0.00000000"],["111637.85000000","0.00000000"],["111654.31000000","0.00000000"],["111655.85000000","0.54250000"],["111656.93000000","0.04800000"],["111659.10000000","1.25396000"],["111660.55000000","0.00223000"],["111660.56000000","0.00000000"],["111685.36000000","0.09759000"],["111710.02000000","0.02510000"],["111734.12000000","0.11193000"],["111741.15000000","0.00000000"],["111771.98000000","0.00089000"],["111771.99000000","0.00000000"],["111800.00000000","0.00595000"],["111875.77000000","0.00000000"],["111876.42000000","0.00000000"],["111878.07000000","0.00000000"],["111903.22000000","0.00000000"],["111904.16000000","0.02599000"],["111907.76000000","0.00000000"],["111914.46000000","0.03675000"],["111914.79000000","0.03675000"],["111916.03000000","0.03675000"],["111937.53000000","0.55803000"],["112063.58000000","0.03765000"],["112065.75000000","0.03765000"],["113226.98000000","0.00100000"]]}
[2025-10-12T11:05:13.182Z] {"e":"depthUpdate","E":1760267113014,"s":"BTCUSDT","U":77965299798,"u":77965299882,"b":[["111553.66000000","3.81877000"],["111553.27000000","0.01350000"],["111550.31000000","0.35821000"],["111549.08000000","0.01793000"],["111548.76000000","0.00000000"],["111548.08000000","0.11247000"],["111544.81000000","0.04550000"],["111544.75000000","0.08507000"],["111542.79000000","0.00000000"],["111538.38000000","0.15000000"],["111538.16000000","0.00043000"],["111525.46000000","0.01388000"],["111519.81000000","0.22384000"],["111517.96000000","0.00000000"],["111517.27000000","0.03498000"],["111515.24000000","0.30242000"],["111504.48000000","0.03696000"],["111499.21000000","0.00000000"],["111489.70000000","0.00005000"],["111487.36000000","0.00000000"],["111441.67000000","0.22384000"],["111391.03000000","0.00005000"],["111349.12000000","0.99641000"],["111342.66000000","0.00574000"],["111340.54000000","0.00000000"],["111339.98000000","0.00000000"],["111298.98000000","0.07528000"],["111263.40000000","0.00000000"],["111000.00000000","16.80623000"],["109880.35000000","0.00100000"],["100398.00000000","0.00600000"],["100397.00000000","0.00010000"],["89242.93000000","0.00022000"]],"a":[["111553.67000000","0.17554000"],["111553.68000000","0.00040000"],["111554.17000000","0.00010000"],["111555.60000000","0.00005000"],["111555.63000000","0.00000000"],["111561.71000000","0.02571000"],["111562.00000000","0.00270000"],["111563.64000000","0.04527000"],["111567.61000000","0.04476000"],["111567.79000000","0.00144000"],["111568.93000000","0.03983000"],["111570.05000000","0.03982000"],["111570.28000000","0.00000000"],["111572.57000000","0.16983000"],["111575.63000000","0.00100000"],["111579.27000000","0.06240000"],["111580.25000000","0.07200000"],["111581.52000000","0.07200000"],["111584.76000000","0.04800000"],["111601.09000000","0.00000000"],["111601.22000000","0.00000000"],["111606.67000000","0.00000000"],["111657.07000000","0.06240000"],["111662.52000000","0.04800000"],["111675.93000000","0.00000000"],["111677.15000000","0.00000000"],["111714.54000000","0.02510000"],["111742.74000000","0.00000000"],["113226.98000000","0.00100000"]]}
[2025-10-12T11:05:14.182Z] {"e":"depthUpdate","E":1760267114014,"s":"BTCUSDT","U":77965299883,"u":77965300116,"b":[["111553.66000000","3.41284000"],["111553.65000000","0.21451000"],["111549.24000000","0.04027000"],["111549.19000000","0.00000000"],["111548.08000000","0.00052000"],["111547.53000000","0.01803000"],["111547.20000000","0.00100000"],["111545.29000000","0.11195000"],["111544.81000000","0.04545000"],["111544.75000000","0.00000000"],["111544.50000000","0.00405000"],["111539.73000000","0.00334000"],["111538.38000000","0.15000000"],["111538.34000000","0.08507000"],["111535.32000000","0.00000000"],["111527.71000000","0.10080000"],["111526.12000000","0.00000000"],["111525.97000000","0.01388000"],["111525.46000000","0.00000000"],["111521.91000000","0.00000000"],["111516.48000000","0.04479000"],["111515.24000000","0.00000000"],["111512.47000000","0.30338000"],["111509.00000000","0.04426000"],["111492.82000000","0.00005000"],["111481.52000000","0.00000000"],["111443.26000000","0.26526000"],["111442.24000000","0.00000000"],["111428.07000000","0.00218000"],["111396.32000000","0.00000000"],["111383.24000000","0.00005000"],["111132.45000000","0.00080000"],["111100.75000000","0.00000000"],["110926.81000000","0.00000000"],["110900.99000000","0.00000000"],["109880.35000000","0.00100000"],["103856.00000000","0.00014000"],["100397.00000000","0.00010000"],["89242.93000000","0.00022000"],["60000.00000000","53.14042000"]],"a":[["111553.67000000","0.57988000"],["111553.68000000","0.00050000"],["111553.75000000","0.00010000"],["111553.95000000","0.00000000"],["111554.06000000","0.01360000"],["111554.17000000","0.00000000"],["111556.00000000","0.00270000"],["111557.39000000","0.00010000"],["111557.40000000","0.04227000"],["111557.57000000","0.00543000"],["111558.00000000","0.00270000"],["111558.62000000","0.00000000"],["111558.63000000","0.00000000"],["111558.68000000","0.00722000"],["111558.73000000","0.00150000"],["111559.74000000","0.00000000"],["111559.75000000","0.00000000"],["111559.78000000","0.00010000"],["111559.79000000","0.21123000"],["111559.80000000","0.01803000"],["111559.86000000","0.00000000"],["111559.87000000","0.30005000"],["111559.99000000","0.00000000"],["111560.00000000","0.02063000"],["111560.36000000","0.00000000"],["111560.37000000","0.32000000"],["111560.44000000","0.04809000"],["111561.16000000","0.04045000"],["111561.71000000","0.02566000"],["111562.00000000","0.00270000"],["111562.28000000","0.03947000"],["111563.64000000","0.00000000"],["111564.00000000","0.00260000"],["111564.14000000","0.00000000"],["111564.83000000","0.00155000"],["111564.87000000","0.02695000"],["111565.51000000","0.01777000"],["111566.89000000","0.00000000"],["111568.49000000","0.00300000"],["111568.93000000","0.00000000"],["111569.51000000","0.00100000"],["111570.05000000","0.00000000"],["111570.28000000","0.00005000"],["111571.48000000","0.06646000"],["111571.90000000","0.30448000"],["111571.91000000","0.35816000"],["111572.57000000","0.18131000"],["111575.63000000","0.00000000"],["111575.95000000","0.00000000"],["111578.70000000","0.00000000"],["111580.04000000","0.00000000"],["111583.29000000","1.49196000"],["111583.30000000","1.25396000"],["111584.27000000","0.00000000"],["111589.40000000","0.00000000"],["111591.56000000","1.19608000"],["111637.99000000","0.02498000"],["111638.00000000","0.00360000"],["111664.67000000","0.01707000"],["113226.98000000","0.00100000"],["123000.00000000","22.85109000"],["158460.00000000","0.00004000"]]}
[2025-10-12T11:05:15.182Z] {"e":"depthUpdate","E":1760267115014,"s":"BTCUSDT","U":77965300117,"u":77965300278,"b":[["111553.66000000","3.41187000"],["111553.65000000","0.21446000"],["111547.53000000","0.01798000"],["111547.20000000","0.00000000"],["111544.50000000","0.00405000"],["111544.43000000","0.00043000"],["111540.13000000","0.00000000"],["111539.73000000","0.00000000"],["111526.36000000","0.00260000"],["111525.97000000","0.00000000"],["111525.30000000","0.01388000"],["111514.39000000","1.21777000"],["111506.66000000","0.00000000"],["111498.47000000","0.00218000"],["111495.94000000","0.00005000"],["111487.07000000","0.00430000"],["111477.91000000","0.00448000"],["111439.97000000","0.00000000"],["111434.00000000","0.00456000"],["111428.07000000","0.00000000"],["111426.67000000","0.00000000"],["111375.44000000","0.00005000"],["111292.20000000","0.00000000"],["111202.74000000","0.00080000"],["111144.33000000","0.00000000"],["111132.45000000","0.00000000"],["110915.75000000","0.89111000"],["110884.34000000","0.00019000"],["109880.35000000","0.00100000"],["100398.00000000","0.00600000"],["100397.00000000","0.00010000"],["89242.93000000","0.00022000"],["60000.00000000","53.14032000"]],"a":[["111553.67000000","0.17535000"],["111553.68000000","0.00035000"],["111554.06000000","0.01360000"],["111554.18000000","0.00010000"],["111555.33000000","0.00000000"],["111555.64000000","0.00000000"],["111556.00000000","0.00265000"],["111557.39000000","0.00000000"],["111557.40000000","0.00000000"],["111558.68000000","0.00722000"],["111559.78000000","0.00000000"],["111559.79000000","0.00010000"],["111559.80000000","0.01808000"],["111559.86000000","0.00010000"],["111559.87000000","0.30010000"],["111559.99000000","0.00005000"],["111560.00000000","0.02068000"],["111560.37000000","0.32005000"],["111560.44000000","0.04809000"],["111560.93000000","0.00000000"],["111561.16000000","0.00000000"],["111561.83000000","0.05064000"],["111562.00000000","0.00265000"],["111562.28000000","0.00000000"],["111564.87000000","0.02695000"],["111565.51000000","0.00000000"],["111565.54000000","0.00000000"],["111566.89000000","0.00074000"],["111567.45000000","0.00000000"],["111568.57000000","0.00000000"],["111568.91000000","0.04102000"],["111569.51000000","0.00000000"],["111570.03000000","0.04011000"],["111571.90000000","0.00448000"],["111571.91000000","0.00000000"],["111572.40000000","0.00000000"],["111575.85000000","0.00100000"],["111575.95000000","0.00000000"],["111578.70000000","0.30000000"],["111591.56000000","0.00000000"],["111593.40000000","1.21864000"],["111635.65000000","0.00000000"],["111664.07000000","0.00000000"],["111675.99000000","0.04293000"],["111779.12000000","0.00000000"],["113226.98000000","0.00100000"]]}
[2025-10-12T11:05:16.184Z] {"e":"depthUpdate","E":1760267116014,"s":"BTCUSDT","U":77965300279,"u":77965302712,"b":[["111559.99000000","8.18045000"],["111559.98000000","0.00010000"],["111559.97000000","0.00000000"],["111559.95000000","0.00000000"],["111559.93000000","0.00000000"],["111559.92000000","0.00010000"],["111559.90000000","0.00090000"],["111559.89000000","0.00010000"],["111559.87000000","0.05989000"],["111559.86000000","0.10005000"],["111559.85000000","0.00000000"],["111559.80000000","0.00000000"],["111559.79000000","0.10000000"],["111559.78000000","0.00000000"],["111559.73000000","0.00000000"],["111559.72000000","0.00000000"],["111559.07000000","0.00000000"],["111558.75000000","0.00000000"],["111558.73000000","0.00000000"],["111558.72000000","0.00000000"],["111558.71000000","0.00000000"],["111558.70000000","0.00000000"],["111558.68000000","0.00000000"],["111558.67000000","0.00000000"],["111558.66000000","0.00000000"],["111558.37000000","0.00000000"],["111558.35000000","0.00000000"],["111558.34000000","0.00000000"],["111558.33000000","0.00000000"],["111558.28000000","0.00000000"],["111558.00000000","0.00000000"],["111557.99000000","0.00000000"],["111557.98000000","0.00000000"],["111557.79000000","0.00005000"],["111557.56000000","0.00000000"],["111557.14000000","0.00000000"],["111556.87000000","0.00000000"],["111556.00000000","0.00000000"],["111555.99000000","0.00005000"],["111555.98000000","0.00000000"],["111555.89000000","0.00000000"],["111555.83000000","0.00000000"],["111555.59000000","0.00000000"],["111554.99000000","0.00000000"],["111554.26000000","0.00000000"],["111554.17000000","0.00000000"],["111554.08000000","0.00000000"],["111554.06000000","0.47576000"],["111554.05000000","0.06017000"],["111554.04000000","0.00000000"],["111554.02000000","0.00044000"],["111554.00000000","0.00000000"],["111553.99000000","0.00000000"],["111553.98000000","0.00000000"],["111553.93000000","0.00000000"],["111553.92000000","0.00000000"],["111553.90000000","0.00000000"],["111553.89000000","0.00000000"],["111553.88000000","0.00000000"],["111553.83000000","0.00000000"],["111553.82000000","0.00000000"],["111553.81000000","0.00000000"],["111553.74000000","0.00000000"],["111553.73000000","0.00000000"],["111553.69000000","0.00000000"],["111553.68000000","0.00000000"],["111553.67000000","0.45020000"],["111553.66000000","0.37215000"],["111553.65000000","0.21431000"],["111553.64000000","0.00000000"],["111553.58000000","0.00000000"],["111553.50000000","0.00901000"],["111553.49000000","0.00000000"],["111553.28000000","0.00000000"],["111553.27000000","0.01350000"],["111553.25000000","0.06646000"],["111553.12000000","0.00055000"],["111552.45000000","0.00000000"],["111551.43000000","0.00359000"],["111551.34000000","0.00000000"],["111551.32000000","0.00005000"],["111550.76000000","0.00000000"],["111550.32000000","0.00448000"],["111550.31000000","0.35816000"],["111550.19000000","0.00000000"],["111550.15000000","0.00000000"],["111549.25000000","0.27428000"],["111549.11000000","0.00043000"],["111549.08000000","0.01798000"],["111548.66000000","0.01076000"],["111548.30000000","0.00005000"],["111547.69000000","0.00000000"],["111547.53000000","0.01798000"],["111547.48000000","0.00000000"],["111547.21000000","0.05556000"],["111546.71000000","0.00000000"],["111546.64000000","0.02696000"],["111546.58000000","0.00072000"],["111546.45000000","0.00337000"],["111546.17000000","0.15000000"],["111546.16000000","0.00058000"],["111546.03000000","0.00000000"],["111545.86000000","0.00010000"],["111545.47000000","0.00000000"],["111544.81000000","0.00000000"],["111544.50000000","0.00400000"],["111544.48000000","0.00086000"],["111544.43000000","0.00000000"],["111543.48000000","0.00000000"],["111542.94000000","0.04800000"],["111542.80000000","0.00000000"],["111542.79000000","1.16875000"],["111542.78000000","1.25396000"],["111542.77000000","0.00000000"],["111542.65000000","0.05760000"],["111542.26000000","0.13446000"],["111541.94000000","0.05760000"],["111541.93000000","0.05760000"],["111541.61000000","0.00519000"],["111541.41000000","0.04800000"],["111541.33000000","0.00007000"],["111540.87000000","0.00197000"],["111540.62000000","0.00000000"],["111540.41000000","0.07920000"],["111540.15000000","0.00000000"],["111539.89000000","0.01165000"],["111539.45000000","0.00000000"],["111539.43000000","0.02000000"],["111539.32000000","1.25396000"],["111539.18000000","0.10080000"],["111538.62000000","0.07680000"],["111538.39000000","0.00000000"],["111538.38000000","0.00000000"],["111538.34000000","0.00000000"],["111538.26000000","0.00000000"],["111538.16000000","0.00000000"],["111538.11000000","0.00000000"],["111538.04000000","0.06720000"],["111537.67000000","0.00300000"],["111537.57000000","0.00000000"],["111537.22000000","0.00895000"],["111536.98000000","0.00005000"],["111536.93000000","0.00000000"],["111536.43000000","0.04320000"],["111536.39000000","0.07200000"],["111535.98000000","0.06240000"],["111535.00000000","0.00000000"],["111534.96000000","0.00000000"],["111534.45000000","0.00034000"],["111533.92000000","0.00000000"],["111533.06000000","0.00000000"],["111532.27000000","0.00000000"],["111532.11000000","0.62763000"],["111531.59000000","0.00000000"],["111529.64000000","0.00000000"],["111529.15000000","0.00010000"],["111528.94000000","0.00000000"],["111527.71000000","0.00000000"],["111527.34000000","0.22384000"],["111526.40000000","0.04481000"],["111526.32000000","0.00000000"],["111525.39000000","0.00000000"],["111525.30000000","0.00000000"],["111525.21000000","0.00000000"],["111525.12000000","0.00000000"],["111524.57000000","0.00000000"],["111524.50000000","0.00000000"],["111523.88000000","0.00000000"],["111523.81000000","0.00000000"],["111523.56000000","0.00000000"],["111523.51000000","0.00000000"],["111521.36000000","0.00000000"],["111521.35000000","0.00000000"],["111521.17000000","0.04479000"],["111520.23000000","0.02948000"],["111520.19000000","0.31770000"],["111519.81000000","0.00000000"],["111518.15000000","0.00000000"],["111517.96000000","0.30241000"],["111517.86000000","0.00000000"],["111517.35000000","0.00009000"],["111516.48000000","0.00000000"],["111516.10000000","0.00000000"],["111515.23000000","0.03137000"],["111515.13000000","0.00018000"],["111514.80000000","0.00000000"],["111514.40000000","1.10888000"],["111514.01000000","0.05760000"],["111513.87000000","0.00000000"],["111513.86000000","0.00000000"],["111513.13000000","0.13446000"],["111513.09000000","0.00000000"],["111512.69000000","0.18900000"],["111512.62000000","0.00000000"],["111512.47000000","0.00095000"],["111512.26000000","0.00488000"],["111511.05000000","0.00000000"],["111509.07000000","0.00000000"],["111509.00000000","0.00000000"],["111508.83000000","0.00000000"],["111507.15000000","0.13444000"],["111506.97000000","0.00009000"],["111506.80000000","0.00000000"],["111503.22000000","0.00000000"],["111502.19000000","0.00005000"],["111500.67000000","0.00000000"],["111499.07000000","0.00005000"],["111498.84000000","0.04426000"],["111498.47000000","0.00000000"],["111496.01000000","0.02509000"],["111493.93000000","0.00000000"],["111493.11000000","0.02509000"],["111492.01000000","0.02509000"],["111484.79000000","0.34778000"],["111484.17000000","0.00448000"],["111481.99000000","0.08695000"],["111478.50000000","0.00000000"],["111478.14000000","0.00000000"],["111476.97000000","0.00000000"],["111472.62000000","0.06990000"],["111471.68000000","0.00090000"],["111467.29000000","0.08090000"],["111465.70000000","0.60777000"],["111465.69000000","0.00000000"],["111465.43000000","0.11125000"],["111465.38000000","0.00000000"],["111464.88000000","0.00000000"],["111464.01000000","0.02330000"],["111463.42000000","0.00000000"],["111461.61000000","0.00000000"],["111461.23000000","0.00000000"],["111460.60000000","0.00000000"],["111453.71000000","0.00000000"],["111453.67000000","0.00000000"],["111453.60000000","0.22384000"],["111453.37000000","0.00000000"],["111447.48000000","0.04750000"],["111446.70000000","0.00000000"],["111446.23000000","0.00000000"],["111445.46000000","0.00000000"],["111445.31000000","0.09759000"],["111444.67000000","0.13444000"],["111444.01000000","0.00000000"],["111443.26000000","0.00000000"],["111443.25000000","0.00000000"],["111441.67000000","0.00000000"],["111439.37000000","0.00000000"],["111436.32000000","0.00000000"],["111426.96000000","0.02509000"],["111425.29000000","0.00000000"],["111421.92000000","0.02509000"],["111419.11000000","0.02509000"],["111417.68000000","0.08595000"],["111415.74000000","0.08595000"],["111414.09000000","0.08594000"],["111411.86000000","0.08595000"],["111411.82000000","0.08594000"],["111410.98000000","0.02509000"],["111408.88000000","0.08594000"],["111407.69000000","0.00000000"],["111407.00000000","0.02599000"],["111404.25000000","0.08595000"],["111402.18000000","0.08595000"],["111394.20000000","0.00000000"],["111375.60000000","0.00000000"],["111373.43000000","0.00000000"],["111372.35000000","0.00000000"],["111371.64000000","0.00000000"],["111370.09000000","0.00000000"],["111369.93000000","0.00000000"],["111369.73000000","0.00000000"],["111369.72000000","0.00000000"],["111368.92000000","0.00000000"],["111368.76000000","0.00000000"],["111361.78000000","0.00000000"],["111361.45000000","0.00000000"],["111360.85000000","0.00000000"],["111357.23000000","0.00000000"],["111356.46000000","0.00000000"],["111355.11000000","0.99421000"],["111355.01000000","0.00000000"],["111354.52000000","0.00000000"],["111353.92000000","0.00000000"],["111351.24000000","0.00000000"],["111349.12000000","0.00000000"],["111348.34000000","0.00000000"],["111348.24000000","0.00000000"],["111340.61000000","0.00000000"],["111311.27000000","4.85152000"],["111309.69000000","0.00000000"],["111309.66000000","0.00000000"],["111309.36000000","0.00000000"],["111308.04000000","0.00000000"],["111307.84000000","0.00000000"],["111260.93000000","0.01703000"],["111257.88000000","0.30007000"],["111257.47000000","0.94779000"],["111253.90000000","0.03675000"],["111242.71000000","0.03897000"],["111242.18000000","0.03897000"],["111238.73000000","0.00000000"],["111237.85000000","0.05896000"],["111237.58000000","0.05896000"],["111237.31000000","0.05896000"],["111237.04000000","0.05896000"],["111236.98000000","0.00000000"],["111236.77000000","0.05896000"],["111236.72000000","0.00000000"],["111236.50000000","0.05896000"],["111236.33000000","0.00000000"],["111236.04000000","0.00000000"],["111235.71000000","0.00000000"],["111235.69000000","0.05896000"],["111235.10000000","0.00000000"],["111233.96000000","0.02599000"],["111233.69000000","0.02599000"],["111233.16000000","0.00000000"],["111233.02000000","0.00000000"],["111231.28000000","0.02599000"],["111227.26000000","0.00000000"],["111225.58000000","0.03675000"],["111225.41000000","0.03675000"],["111224.12000000","0.03675000"],["111223.89000000","0.03675000"],["111223.37000000","0.03675000"],["111222.57000000","0.03675000"],["111220.87000000","0.03675000"],["111219.01000000","0.03675000"],["111218.92000000","0.03675000"],["111218.64000000","0.03675000"],["111218.41000000","0.03675000"],["111218.37000000","0.03675000"],["111218.10000000","0.03675000"],["111217.03000000","0.03675000"],["111216.50000000","0.00080000"],["111214.17000000","0.03675000"],["111214.11000000","0.03675000"],["111213.94000000","0.03675000"],["111213.53000000","0.03675000"],["111213.13000000","0.03675000"],["111210.33000000","0.02670000"],["111208.06000000","0.02599000"],["111205.80000000","0.02599000"],["111202.74000000","0.00000000"],["111197.25000000","0.00012000"],["111173.58000000","0.00000000"],["111158.89000000","0.03675000"],["111157.89000000","0.03722000"],["111155.28000000","0.03675000"],["111150.01000000","0.00000000"],["111148.11000000","0.00000000"],["111147.43000000","0.00000000"],["111147.42000000","0.00000000"],["111147.07000000","0.00000000"],["111146.82000000","0.00000000"],["111146.41000000","0.00000000"],["111146.21000000","0.00000000"],["111145.94000000","0.00000000"],["111145.67000000","0.00000000"],["111144.81000000","0.00000000"],["111144.48000000","0.00000000"],["111144.28000000","0.00000000"],["111144.15000000","0.00000000"],["111143.77000000","0.00000000"],["111143.28000000","0.00000000"],["111142.88000000","0.00000000"],["111142.50000000","0.00000000"],["111138.86000000","0.00000000"],["111137.64000000","0.00000000"],["111137.41000000","0.00000000"],["111136.89000000","0.00000000"],["111136.84000000","0.00000000"],["111132.74000000","0.00000000"],["111132.20000000","0.00000000"],["111131.71000000","0.00010000"],["111131.64000000","0.00000000"],["111131.57000000","0.00000000"],["111128.34000000","0.00000000"],["111126.51000000","0.00000000"],["111125.88000000","0.00000000"],["111121.19000000","0.00000000"],["111009.62000000","0.00000000"],["111009.55000000","0.00000000"],["111004.32000000","0.00000000"],["111003.91000000","0.00000000"],["111000.00000000","16.77479000"],["110915.75000000","0.00000000"],["110884.34000000","0.00000000"],["109880.35000000","0.00000000"],["109037.00000000","0.00100000"],["106970.40000000","0.00000000"],["100404.00000000","0.00010000"],["100398.00000000","0.00600000"],["100397.00000000","0.00000000"],["89248.00000000","0.00028000"],["89242.93000000","0.00000000"],["78088.59000000","0.00000000"],["42000.00000000","1.49196000"],["33000.00000000","3.87311000"]],"a":[["111553.67000000","0.00000000"],["111553.68000000","0.00000000"],["111553.69000000","0.00000000"],["111553.70000000","0.00000000"],["111553.75000000","0.00000000"],["111553.82000000","0.00000000"],["111553.83000000","0.00000000"],["111553.84000000","0.00000000"],["111554.00000000","0.00000000"],["111554.01000000","0.00000000"],["111554.05000000","0.00000000"],["111554.06000000","0.00000000"],["111554.07000000","0.00000000"],["111554.18000000","0.00000000"],["111554.27000000","0.00000000"],["111555.00000000","0.00000000"],["111555.60000000","0.00000000"],["111555.63000000","0.00000000"],["111555.84000000","0.00000000"],["111555.90000000","0.00000000"],["111555.91000000","0.00000000"],["111556.00000000","0.00000000"],["111556.88000000","0.00000000"],["111557.15000000","0.00000000"],["111557.57000000","0.00000000"],["111557.61000000","0.00000000"],["111558.00000000","0.00000000"],["111558.35000000","0.00000000"],["111558.36000000","0.00000000"],["111558.68000000","0.00000000"],["111558.73000000","0.00000000"],["111558.74000000","0.00000000"],["111559.72000000","0.00000000"],["111559.79000000","0.00000000"],["111559.80000000","0.00000000"],["111559.86000000","0.00000000"],["111559.87000000","0.00000000"],["111559.88000000","0.00000000"],["111559.94000000","0.00000000"],["111559.99000000","0.00000000"],["111560.00000000","0.69658000"],["111560.01000000","0.00080000"],["111560.02000000","0.00020000"],["111560.08000000","0.00010000"],["111560.24000000","0.00000000"],["111560.36000000","0.00000000"],["111560.37000000","0.00000000"],["111560.43000000","0.00000000"],["111560.44000000","0.00000000"],["111561.70000000","0.00015000"],["111561.71000000","0.02596000"],["111561.72000000","0.00020000"],["111561.83000000","0.00000000"],["111562.00000000","0.00265000"],["111562.01000000","0.00010000"],["111562.43000000","0.00005000"],["111562.92000000","0.00000000"],["111563.28000000","0.00010000"],["111563.29000000","0.05859000"],["111563.30000000","0.00010000"],["111563.40000000","0.00000000"],["111563.71000000","0.00000000"],["111563.72000000","0.00000000"],["111563.94000000","0.00000000"],["111564.01000000","0.00000000"],["111564.36000000","0.00000000"],["111564.77000000","0.00000000"],["111564.83000000","0.00150000"],["111564.87000000","0.00005000"],["111564.95000000","0.00000000"],["111566.00000000","0.00260000"],["111566.16000000","0.00010000"],["111566.17000000","0.14010000"],["111566.62000000","0.00000000"],["111566.65000000","0.00000000"],["111566.73000000","0.00000000"],["111566.89000000","0.00000000"],["111567.06000000","0.00010000"],["111567.07000000","0.16005000"],["111567.60000000","0.00000000"],["111567.61000000","0.00005000"],["111567.65000000","0.00005000"],["111567.66000000","0.23995000"],["111567.67000000","0.32005000"],["111567.79000000","0.00149000"],["111568.00000000","0.00265000"],["111568.17000000","0.00000000"],["111568.23000000","0.04481000"],["111568.49000000","0.00000000"],["111568.81000000","0.00000000"],["111568.91000000","0.00000000"],["111569.20000000","0.00000000"],["111569.56000000","0.00000000"],["111569.82000000","0.00005000"],["111569.99000000","0.00000000"],["111570.00000000","0.00270000"],["111570.03000000","0.00000000"],["111570.06000000","0.00000000"],["111570.07000000","0.00000000"],["111570.12000000","0.00000000"],["111570.16000000","0.02217000"],["111570.28000000","0.00000000"],["111570.32000000","0.00000000"],["111570.39000000","0.00000000"],["111570.40000000","0.00150000"],["111570.69000000","0.00000000"],["111570.71000000","0.00000000"],["111570.87000000","0.00000000"],["111570.88000000","0.00000000"],["111570.98000000","0.00000000"],["111571.16000000","0.45005000"],["111571.19000000","0.00000000"],["111571.20000000","0.00000000"],["111571.38000000","0.00000000"],["111571.48000000","0.00000000"],["111571.55000000","0.00000000"],["111571.90000000","0.00005000"],["111571.92000000","0.00000000"],["111572.00000000","0.00265000"],["111572.31000000","0.01340000"],["111572.49000000","0.00000000"],["111572.57000000","0.00000000"],["111572.84000000","0.00000000"],["111572.85000000","0.07631000"],["111573.53000000","0.16096000"],["111573.54000000","0.30240000"],["111573.69000000","0.00000000"],["111573.90000000","0.00000000"],["111574.00000000","0.00265000"],["111574.34000000","0.00000000"],["111574.45000000","0.00331000"],["111575.29000000","0.00069000"],["111575.44000000","0.00150000"],["111575.85000000","0.00000000"],["111575.96000000","0.00000000"],["111575.97000000","0.00000000"],["111575.98000000","0.00000000"],["111575.99000000","0.00300000"],["111576.50000000","0.03988000"],["111576.76000000","0.00000000"],["111576.77000000","0.00000000"],["111577.03000000","0.00007000"],["111577.31000000","0.00100000"],["111577.62000000","0.04101000"],["111578.68000000","0.00000000"],["111578.70000000","0.00000000"],["111578.72000000","0.00000000"],["111579.41000000","0.00000000"],["111579.42000000","0.00000000"],["111579.59000000","0.00000000"],["111579.77000000","0.00000000"],["111579.87000000","0.00000000"],["111579.96000000","0.00000000"],["111580.20000000","0.15000000"],["111580.21000000","0.00000000"],["111580.22000000","0.47542000"],["111580.23000000","0.45020000"],["111580.24000000","0.00000000"],["111580.68000000","0.00000000"],["111580.75000000","0.01752000"],["111580.84000000","0.00448000"],["111581.04000000","0.00000000"],["111581.12000000","0.00000000"],["111581.50000000","0.35816000"],["111581.51000000","0.15000000"],["111581.53000000","0.00000000"],["111581.55000000","0.11195000"],["111583.27000000","0.00000000"],["111583.29000000","0.00000000"],["111583.30000000","0.00000000"],["111583.31000000","0.00000000"],["111583.71000000","0.00000000"],["111585.33000000","0.55107000"],["111585.88000000","0.04800000"],["111586.20000000","0.00000000"],["111586.38000000","0.00895000"],["111586.64000000","0.00000000"],["111586.65000000","0.00000000"],["111586.73000000","0.00000000"],["111586.75000000","0.00000000"],["111586.83000000","0.04800000"],["111587.80000000","0.08507000"],["111587.97000000","0.00000000"],["111587.98000000","0.02126000"],["111587.99000000","0.35840000"],["111588.40000000","0.01388000"],["111588.50000000","0.00005000"],["111588.76000000","0.00000000"],["111589.08000000","0.00005000"],["111589.10000000","0.96632000"],["111590.00000000","0.00260000"],["111590.26000000","0.00000000"],["111590.76000000","0.04800000"],["111591.71000000","0.00012000"],["111591.98000000","0.05896000"],["111592.80000000","0.04000000"],["111593.33000000","0.04482000"],["111593.35000000","0.00000000"],["111593.47000000","0.00300000"],["111602.69000000","0.00000000"],["111603.98000000","0.02599000"],["111603.99000000","0.00000000"],["111604.60000000","0.08507000"],["111604.80000000","0.00000000"],["111605.88000000","0.08512000"],["111605.99000000","0.00000000"],["111611.43000000","0.00005000"],["111613.75000000","0.00000000"],["111615.90000000","0.00005000"],["111617.86000000","0.00000000"],["111617.94000000","0.02126000"],["111617.99000000","0.00000000"],["111618.75000000","0.08507000"],["111621.30000000","0.07200000"],["111621.99000000","0.03675000"],["111625.78000000","0.05429000"],["111628.25000000","0.00000000"],["111628.62000000","0.00000000"],["111631.41000000","0.00000000"],["111631.60000000","0.00000000"],["111632.61000000","0.00615000"],["111632.70000000","0.00000000"],["111632.92000000","0.06632000"],["111633.42000000","0.00000000"],["111634.22000000","0.20625000"],["111635.13000000","0.00622000"],["111635.39000000","0.00000000"],["111636.79000000","0.45020000"],["111637.99000000","0.00000000"],["111638.00000000","0.00260000"],["111638.99000000","0.00000000"],["111639.00000000","0.00000000"],["111639.99000000","0.00222000"],["111640.00000000","0.02051000"],["111641.59000000","0.00000000"],["111642.74000000","0.00000000"],["111643.50000000","0.00000000"],["111645.68000000","0.35816000"],["111651.96000000","0.04097000"],["111652.38000000","0.35816000"],["111654.82000000","0.00112000"],["111656.61000000","0.00000000"],["111659.27000000","0.00000000"],["111660.55000000","0.00000000"],["111660.65000000","0.00000000"],["111662.51000000","1.25396000"],["111662.61000000","0.37071000"],["111662.82000000","0.03997000"],["111662.96000000","0.00000000"],["111664.47000000","0.00000000"],["111664.67000000","0.00000000"],["111665.36000000","0.00000000"],["111667.24000000","0.00223000"],["111667.27000000","0.00000000"],["111667.44000000","0.00000000"],["111668.70000000","0.00000000"],["111668.79000000","0.00000000"],["111669.98000000","0.00222000"],["111670.36000000","0.01707000"],["111670.96000000","0.02137000"],["111671.11000000","0.02509000"],["111671.14000000","0.00000000"],["111671.39000000","0.00000000"],["111672.84000000","0.00000000"],["111674.60000000","0.00000000"],["111676.68000000","0.99663000"],["111678.08000000","0.00000000"],["111684.72000000","0.02509000"],["111684.75000000","0.00000000"],["111690.45000000","0.23826000"],["111691.74000000","0.00000000"],["111694.36000000","0.00000000"],["111694.52000000","0.00000000"],["111696.84000000","0.00000000"],["111701.99000000","0.02509000"],["111702.88000000","0.09845000"],["111705.43000000","0.02509000"],["111708.72000000","0.00000000"],["111710.56000000","0.02509000"],["111711.92000000","0.00000000"],["111713.31000000","0.02509000"],["111718.53000000","0.00000000"],["111722.22000000","0.02509000"],["111722.27000000","0.08694000"],["111722.50000000","0.00000000"],["111725.86000000","0.00000000"],["111728.33000000","0.00000000"],["111729.04000000","0.00000000"],["111730.72000000","0.00000000"],["111731.62000000","0.00000000"],["111733.43000000","0.00000000"],["111734.12000000","0.02398000"],["111734.20000000","0.02691000"],["111739.84000000","0.00000000"],["111757.53000000","0.00000000"],["111759.93000000","0.17388000"],["111766.36000000","0.08594000"],["111769.16000000","0.08594000"],["111771.98000000","0.00000000"],["111777.59000000","0.02330000"],["111779.01000000","0.00089000"],["111780.02000000","0.00000000"],["111783.13000000","0.02330000"],["111795.22000000","4.74587000"],["111797.84000000","0.00000000"],["111800.03000000","0.00000000"],["111818.64000000","0.04097000"],["111821.03000000","0.04097000"],["111823.76000000","0.04097000"],["111825.77000000","0.02420000"],["111828.90000000","0.02420000"],["111833.90000000","0.01703000"],["111844.61000000","0.00010000"],["111847.92000000","0.00000000"],["111856.32000000","0.00000000"],["111856.33000000","0.00000000"],["111857.77000000","0.00000000"],["111858.55000000","0.00000000"],["111858.81000000","0.00007000"],["111869.14000000","0.00010000"],["111869.29000000","0.00000000"],["111874.71000000","0.00000000"],["111874.76000000","0.00000000"],["111874.86000000","0.00000000"],["111875.52000000","0.00000000"],["111878.41000000","0.00035000"],["111879.20000000","0.00000000"],["111897.25000000","0.05896000"],["111902.33000000","0.00000000"],["111906.96000000","0.02599000"],["111907.24000000","0.02599000"],["111911.63000000","0.03675000"],["111914.62000000","0.00000000"],["111915.65000000","0.00000000"],["111916.73000000","0.00000000"],["111919.06000000","0.03675000"],["111924.60000000","0.02599000"],["111925.91000000","0.03757000"],["111928.58000000","0.00000000"],["111929.57000000","0.00000000"],["111937.53000000","0.00000000"],["112006.26000000","0.00000000"],["112008.72000000","0.00000000"],["112059.75000000","0.03675000"],["112062.90000000","0.45000000"],["112067.21000000","0.03675000"],["112071.30000000","0.03675000"],["112130.56000000","0.00000000"],["112130.82000000","0.00000000"],["112131.84000000","0.00000000"],["112132.23000000","0.00000000"],["112133.40000000","0.00000000"],["112140.73000000","0.00000000"],["112153.61000000","0.11990000"],["113226.98000000","0.00000000"],["113233.40000000","0.00100000"]]}
