[2025-10-12T10:59:32.186Z] {"e":"depthUpdate","E":1760266772014,"s":"BTCUSDT","U":77965107601,"u":77965107763,"b":[["111656.00000000","10.89140000"],["111654.43000000","0.04046000"],["111653.76000000","0.00368000"],["111653.17000000","0.01390000"],["111652.39000000","0.01584000"],["111652.09000000","0.00542000"],["111652.02000000","0.00000000"],["111651.53000000","0.00000000"],["111651.52000000","0.06657000"],["111651.32000000","0.01813000"],["111650.97000000","0.00727000"],["111650.15000000","0.05285000"],["111650.09000000","0.05760000"],["111649.85000000","0.01806000"],["111649.04000000","0.00447000"],["111649.03000000","0.07200000"],["111648.92000000","0.04459000"],["111647.85000000","0.39380000"],["111647.84000000","0.09360000"],["111647.33000000","0.00086000"],["111647.01000000","0.00000000"],["111646.75000000","0.00943000"],["111646.20000000","0.06240000"],["111645.39000000","0.00000000"],["111643.34000000","0.00000000"],["111642.16000000","0.00000000"],["111638.77000000","0.00000000"],["111637.48000000","0.00000000"],["111633.56000000","0.00000000"],["111627.68000000","0.00000000"],["111627.49000000","1.16824000"],["111622.51000000","0.00000000"],["111622.16000000","0.05280000"],["111609.10000000","0.00000000"],["111586.96000000","0.00156000"],["111554.33000000","0.00000000"],["111551.62000000","0.07519000"],["111550.48000000","0.22377000"],["111534.93000000","0.10913000"],["111532.01000000","0.16990000"],["111529.60000000","0.08495000"],["111527.35000000","0.08495000"],["111523.56000000","0.00000000"],["111508.19000000","0.06000000"],["111041.17000000","0.00000000"],["110986.07000000","0.00019000"],["109981.16000000","0.00100000"],["102703.79000000","0.00010000"],["100490.00000000","0.00010000"],["89324.80000000","0.00022000"],["40196.16000000","0.00195000"]],"a":[["111656.01000000","0.09091000"],["111656.02000000","0.07990000"],["111656.79000000","0.00005000"],["111657.26000000","0.00000000"],["111662.10000000","0.00000000"],["111663.72000000","0.00000000"],["111665.63000000","0.01019000"],["111666.57000000","0.00005000"],["111666.58000000","0.17192000"],["111668.28000000","0.00337000"],["111668.32000000","0.00005000"],["111668.33000000","0.04490000"],["111669.37000000","0.09108000"],["111669.82000000","0.29536000"],["111670.51000000","0.00000000"],["111672.26000000","0.00000000"],["111672.96000000","0.01015000"],["111673.32000000","0.00000000"],["111674.64000000","0.00000000"],["111675.48000000","0.00000000"],["111675.49000000","0.02688000"],["111689.43000000","1.12650000"],["111689.50000000","0.00308000"],["111699.36000000","0.00000000"],["111701.80000000","1.21020000"],["111740.54000000","0.06823000"],["111741.52000000","0.00000000"],["111741.53000000","0.00000000"],["111743.47000000","0.00100000"],["111743.48000000","0.01900000"],["111767.41000000","0.04297000"],["111776.84000000","0.08394000"],["111780.65000000","0.04297000"],["111786.01000000","0.04297000"],["111790.12000000","0.04297000"],["111798.90000000","0.04297000"],["111869.62000000","0.08495000"],["111872.58000000","0.08495000"],["111874.07000000","0.08495000"],["111875.82000000","0.08495000"],["111877.76000000","0.08495000"],["111911.72000000","0.08795000"],["111913.87000000","0.08795000"],["113330.86000000","0.00100000"],["127980.00000000","0.66221000"]]}
[2025-10-12T11:04:28.113Z] Snapshot loaded successfully.
[2025-10-12T11:04:31.193Z] WebSocket connected successfully.
[2025-10-12T11:04:32.183Z] {"e":"depthUpdate","E":1760267072014,"s":"BTCUSDT","U":77965269399,"u":77965269637,"b":[["111477.61000000","2.10488000"],["111468.00000000","0.00265000"],["111467.90000000","0.00005000"],["111466.47000000","0.00000000"],["111463.12000000","0.05104000"],["111461.57000000","0.00100000"],["111461.47000000","0.01172000"],["111452.42000000","0.15000000"],["111449.48000000","0.00000000"],["111449.40000000","0.01388000"],["111449.32000000","0.00000000"],["111449.18000000","0.00000000"],["111448.48000000","0.00000000"],["111446.19000000","0.00413000"],["111438.11000000","0.00000000"],["111435.02000000","0.30266000"],["111429.90000000","0.00000000"],["111427.60000000","0.00547000"],["111421.27000000","0.12673000"],["111399.21000000","0.00005000"],["111378.32000000","0.00000000"],["111369.73000000","0.28378000"],["111275.45000000","0.99360000"],["111244.49000000","0.00000000"],["111229.42000000","4.74590000"],["111165.15000000","0.00005000"],["111000.00000000","16.80003000"],["109805.44000000","0.00100000"],["105900.00000000","0.07792000"],["105000.00000000","217.12457000"],["102614.52000000","0.00010000"],["100329.00000000","0.00010000"],["89182.09000000","0.00022000"],["33000.00000000","3.87311000"]],"a":[["111477.62000000","4.62396000"],["111477.63000000","0.00035000"],["111477.64000000","0.00020000"],["111477.80000000","0.00085000"],["111477.81000000","0.00010000"],["111479.85000000","0.00000000"],["111480.00000000","0.05457000"],["111480.14000000","0.00010000"],["111480.15000000","0.03598000"],["111481.05000000","0.00000000"],["111481.06000000","0.00000000"],["111481.22000000","0.00010000"],["111481.23000000","0.03608000"],["111481.36000000","0.00000000"],["111481.37000000","0.00000000"],["111481.52000000","0.00548000"],["111481.85000000","0.00000000"],["111481.86000000","0.03593000"],["111482.16000000","0.00005000"],["111482.18000000","0.04062000"],["111482.26000000","0.00000000"],["111482.27000000","0.13446000"],["111482.28000000","0.45020000"],["111482.63000000","0.00718000"],["111482.94000000","0.04766000"],["111483.06000000","0.11127000"],["111484.65000000","0.00005000"],["111489.15000000","0.00000000"],["111490.50000000","0.00270000"],["111490.87000000","0.42051000"],["111491.95000000","0.35816000"],["111491.96000000","0.30000000"],["111495.96000000","0.00000000"],["111496.79000000","0.06240000"],["111497.28000000","0.00000000"],["111502.19000000","0.04800000"],["111509.62000000","0.00000000"],["111515.14000000","0.00000000"],["111520.00000000","0.00200000"],["111522.00000000","0.00200000"],["111524.00000000","0.00200000"],["111526.00000000","0.00200000"],["111526.76000000","0.00000000"],["111528.00000000","0.00200000"],["111530.00000000","0.00200000"],["111532.00000000","0.00200000"],["111534.00000000","0.00200000"],["111536.00000000","0.00200000"],["111538.00000000","0.00200000"],["111546.00000000","0.00260000"],["111546.08000000","0.00896000"],["111548.00000000","0.00260000"],["111550.00000000","0.00260000"],["111552.00000000","0.00260000"],["111554.00000000","0.00260000"],["111556.00000000","0.00260000"],["111558.00000000","0.08454000"],["111558.35000000","0.00000000"],["111560.00000000","0.00260000"],["111562.00000000","0.00260000"],["111564.00000000","0.00260000"],["111589.10000000","0.77121000"],["111667.27000000","0.20148000"],["111709.83000000","4.60998000"],["111720.08000000","1.89773000"],["111734.40000000","0.02511000"],["111740.10000000","0.00000000"],["111805.34000000","0.03997000"],["111809.83000000","0.03997000"],["111810.83000000","0.03997000"],["111896.96000000","0.55835000"],["111941.22000000","0.00000000"],["113149.79000000","0.00100000"]]}
[2025-10-12T11:04:33.183Z] {"e":"depthUpdate","E":1760267073014,"s":"BTCUSDT","U":77965269638,"u":77965271855,"b":[["111481.51000000","9.06482000"],["111481.44000000","0.00010000"],["111481.23000000","0.41120000"],["111481.22000000","0.00000000"],["111480.28000000","0.00000000"],["111480.27000000","0.00000000"],["111480.02000000","0.00000000"],["111480.00000000","0.00000000"],["111479.99000000","0.04008000"],["111479.98000000","0.00000000"],["111479.83000000","0.00000000"],["111479.45000000","0.00000000"],["111479.44000000","0.17442000"],["111479.43000000","0.00000000"],["111479.36000000","0.00000000"],["111478.84000000","0.00000000"],["111478.01000000","0.00000000"],["111478.00000000","0.00000000"],["111477.99000000","0.80846000"],["111477.93000000","0.00000000"],["111477.87000000","0.00000000"],["111477.86000000","0.00000000"],["111477.80000000","0.00000000"],["111477.79000000","0.00000000"],["111477.78000000","0.00000000"],["111477.77000000","0.00000000"],["111477.76000000","0.00000000"],["111477.70000000","0.00005000"],["111477.69000000","0.00000000"],["111477.63000000","0.00000000"],["111477.62000000","0.00000000"],["111477.61000000","0.19482000"],["111477.60000000","0.00000000"],["111477.59000000","0.00005000"],["111477.54000000","0.00000000"],["111477.53000000","0.00010000"],["111477.52000000","0.24207000"],["111477.45000000","0.00907000"],["111477.22000000","0.01351000"],["111476.50000000","0.00000000"],["111476.49000000","0.04018000"],["111476.23000000","0.00000000"],["111475.86000000","0.08507000"],["111475.55000000","0.00044000"],["111475.39000000","0.00364000"],["111475.24000000","0.00005000"],["111475.12000000","0.06646000"],["111474.77000000","0.13535000"],["111474.76000000","0.00005000"],["111474.37000000","0.01760000"],["111474.24000000","0.00000000"],["111473.71000000","0.00548000"],["111473.32000000","0.00086000"],["111473.24000000","0.00005000"],["111472.61000000","0.00538000"],["111472.60000000","0.00718000"],["111472.41000000","0.35816000"],["111471.65000000","0.00000000"],["111471.48000000","0.01799000"],["111471.16000000","0.00000000"],["111471.04000000","0.05314000"],["111470.89000000","0.00548000"],["111470.41000000","0.00000000"],["111470.31000000","0.08507000"],["111469.46000000","0.00000000"],["111469.45000000","0.02697000"],["111469.42000000","0.00000000"],["111469.15000000","0.60499000"],["111469.14000000","1.25396000"],["111468.79000000","0.00000000"],["111468.50000000","0.01400000"],["111468.25000000","0.00000000"],["111468.24000000","0.00000000"],["111468.00000000","0.00270000"],["111467.73000000","0.13430000"],["111467.49000000","0.06005000"],["111467.29000000","0.05760000"],["111467.28000000","0.05760000"],["111467.15000000","0.06646000"],["111466.63000000","0.00006000"],["111466.50000000","0.13430000"],["111465.72000000","0.15000000"],["111465.71000000","0.00000000"],["111465.70000000","1.37184000"],["111465.69000000","1.25396000"],["111465.68000000","0.00000000"],["111465.49000000","0.00000000"],["111465.32000000","0.00000000"],["111464.93000000","0.00000000"],["111464.36000000","0.04366000"],["111464.27000000","0.00000000"],["111463.92000000","0.07680000"],["111463.85000000","0.00000000"],["111463.84000000","0.00300000"],["111463.67000000","0.00000000"],["111463.42000000","0.06720000"],["111463.28000000","0.00150000"],["111463.12000000","0.05099000"],["111462.86000000","0.00007000"],["111462.80000000","0.05760000"],["111462.30000000","0.00000000"],["111462.09000000","0.00000000"],["111462.04000000","0.00005000"],["111461.71000000","0.07200000"],["111461.69000000","0.00000000"],["111461.57000000","0.00000000"],["111461.47000000","0.01167000"],["111461.25000000","0.00000000"],["111461.22000000","0.00000000"],["111460.91000000","0.00000000"],["111460.86000000","0.00000000"],["111460.76000000","0.08505000"],["111460.62000000","0.00000000"],["111460.60000000","1.25396000"],["111460.59000000","0.00000000"],["111460.27000000","0.00000000"],["111460.26000000","0.72211000"],["111460.01000000","0.00000000"],["111459.25000000","0.00024000"],["111458.96000000","0.00000000"],["111458.25000000","0.00000000"],["111457.75000000","0.00000000"],["111457.43000000","0.00000000"],["111457.27000000","0.00000000"],["111457.25000000","1.25396000"],["111456.86000000","0.00000000"],["111456.20000000","0.04479000"],["111455.72000000","0.30261000"],["111455.71000000","0.00000000"],["111455.49000000","0.00000000"],["111454.50000000","0.00400000"],["111454.22000000","0.00000000"],["111453.78000000","0.00931000"],["111453.15000000","0.00000000"],["111452.97000000","0.00000000"],["111452.42000000","0.00000000"],["111452.08000000","0.00000000"],["111452.07000000","0.01814000"],["111451.99000000","0.00000000"],["111451.83000000","0.00000000"],["111451.63000000","0.00000000"],["111451.41000000","0.00000000"],["111450.87000000","0.00005000"],["111450.29000000","0.02128000"],["111450.10000000","0.00000000"],["111449.83000000","0.00000000"],["111449.64000000","0.00000000"],["111449.40000000","0.00000000"],["111449.23000000","0.00000000"],["111448.03000000","0.00000000"],["111447.78000000","0.04481000"],["111447.68000000","0.00000000"],["111447.47000000","0.00000000"],["111446.19000000","0.00000000"],["111445.00000000","0.01614000"],["111444.62000000","0.08507000"],["111444.45000000","0.00000000"],["111444.24000000","0.01701000"],["111443.52000000","0.00009000"],["111443.18000000","0.08913000"],["111443.01000000","0.00000000"],["111441.76000000","0.31598000"],["111441.31000000","0.00018000"],["111441.09000000","0.03498000"],["111441.00000000","0.00400000"],["111440.77000000","0.00000000"],["111439.69000000","0.00000000"],["111439.02000000","0.08000000"],["111438.70000000","0.00413000"],["111436.15000000","0.08507000"],["111435.65000000","0.04426000"],["111435.12000000","0.00000000"],["111435.05000000","0.00000000"],["111435.02000000","0.00000000"],["111433.16000000","0.00016000"],["111433.10000000","0.00000000"],["111432.91000000","0.00000000"],["111431.51000000","0.00000000"],["111430.82000000","0.00000000"],["111430.41000000","0.00005000"],["111429.30000000","0.00000000"],["111428.64000000","0.00000000"],["111427.85000000","0.00000000"],["111424.75000000","0.00000000"],["111424.17000000","0.00005000"],["111421.15000000","0.00000000"],["111419.53000000","0.00000000"],["111419.44000000","0.00000000"],["111412.32000000","0.00000000"],["111411.93000000","0.00000000"],["111411.26000000","0.00000000"],["111409.21000000","0.00653000"],["111408.55000000","0.00624000"],["111406.48000000","0.00000000"],["111403.36000000","0.00018000"],["111402.36000000","0.13430000"],["111402.26000000","0.00000000"],["111401.13000000","0.13430000"],["111401.04000000","0.00000000"],["111397.91000000","0.00090000"],["111397.62000000","0.00000000"],["111396.26000000","0.00000000"],["111392.40000000","0.00000000"],["111389.79000000","0.00000000"],["111389.51000000","0.00000000"],["111387.47000000","0.00000000"],["111387.43000000","0.00000000"],["111387.22000000","0.00000000"],["111387.01000000","0.00000000"],["111385.99000000","0.00000000"],["111384.76000000","0.02461000"],["111383.24000000","0.00000000"],["111379.20000000","0.09845000"],["111376.77000000","0.37862000"],["111375.73000000","0.00000000"],["111375.63000000","0.22384000"],["111373.23000000","0.00066000"],["111373.11000000","0.00000000"],["111365.41000000","0.00000000"],["111363.23000000","0.00000000"],["111334.09000000","0.00000000"],["111327.15000000","0.13666000"],["111324.62000000","0.00000000"],["111321.03000000","0.00218000"],["111291.23000000","0.00250000"],["111278.31000000","0.99394000"],["111275.45000000","0.00000000"],["111275.44000000","0.00000000"],["111262.34000000","0.00000000"],["111214.98000000","0.00000000"],["111198.29000000","0.00000000"],["111157.18000000","0.03595000"],["111155.36000000","0.03588000"],["111131.25000000","0.00000000"],["111106.62000000","0.00000000"],["111095.50000000","0.00206000"],["110980.30000000","0.07174000"],["110979.27000000","0.00000000"],["110827.22000000","0.00000000"],["109809.28000000","0.00100000"],["109805.44000000","0.00000000"],["109572.00000000","0.00300000"],["102614.52000000","0.00000000"],["100333.00000000","0.05438000"],["100332.00000000","0.00309000"],["100329.00000000","0.00000000"],["98103.47000000","0.00012000"],["98102.39000000","0.00000000"],["98101.90000000","0.21199000"],["98100.51000000","0.00000000"],["89185.21000000","0.00022000"],["89182.09000000","0.00000000"]],"a":[["111477.62000000","0.00000000"],["111477.63000000","0.00000000"],["111477.64000000","0.00000000"],["111477.70000000","0.00000000"],["111477.77000000","0.00000000"],["111477.78000000","0.00000000"],["111477.79000000","0.00000000"],["111477.80000000","0.00000000"],["111477.81000000","0.00000000"],["111478.00000000","0.00000000"],["111478.01000000","0.00000000"],["111478.02000000","0.00000000"],["111479.44000000","0.00000000"],["111479.45000000","0.00000000"],["111479.46000000","0.00000000"],["111479.84000000","0.00000000"],["111479.85000000","0.00000000"],["111479.99000000","0.00000000"],["111480.00000000","0.00000000"],["111480.01000000","0.00000000"],["111480.03000000","0.00000000"],["111480.14000000","0.00000000"],["111480.15000000","0.00000000"],["111480.28000000","0.00000000"],["111481.22000000","0.00000000"],["111481.23000000","0.00000000"],["111481.24000000","0.00000000"],["111481.52000000","0.30791000"],["111481.53000000","0.00055000"],["111481.54000000","0.00020000"],["111481.60000000","0.00010000"],["111481.85000000","0.00000000"],["111481.86000000","0.00000000"],["111482.16000000","0.00000000"],["111482.18000000","0.00000000"],["111482.27000000","0.00000000"],["111482.28000000","0.00000000"],["111482.63000000","0.00743000"],["111482.64000000","0.00020000"],["111482.80000000","0.00000000"],["111482.94000000","0.00000000"],["111482.95000000","0.00005000"],["111483.02000000","0.00000000"],["111483.06000000","0.00000000"],["111483.56000000","0.00000000"],["111483.61000000","0.00005000"],["111483.66000000","0.00000000"],["111483.74000000","0.00010000"],["111483.75000000","0.01819000"],["111483.76000000","0.00010000"],["111484.46000000","0.00000000"],["111484.70000000","0.00010000"],["111484.71000000","0.00010000"],["111484.72000000","0.00010000"],["111485.26000000","0.00000000"],["111485.27000000","0.00000000"],["111485.81000000","0.00000000"],["111486.49000000","0.00000000"],["111486.50000000","0.00000000"],["111486.62000000","0.00000000"],["111487.85000000","0.00010000"],["111487.86000000","0.06015000"],["111487.87000000","0.00000000"],["111488.08000000","0.00010000"],["111488.09000000","0.05079000"],["111488.76000000","0.00000000"],["111488.77000000","0.00305000"],["111488.85000000","0.00000000"],["111489.15000000","0.00000000"],["111490.41000000","0.00000000"],["111490.50000000","0.00000000"],["111490.85000000","0.00000000"],["111490.86000000","0.00000000"],["111490.87000000","0.00000000"],["111490.88000000","0.00000000"],["111491.05000000","0.00010000"],["111491.06000000","0.56005000"],["111491.08000000","0.00000000"],["111491.35000000","0.00000000"],["111491.53000000","0.00000000"],["111491.95000000","0.00000000"],["111491.96000000","0.00000000"],["111491.97000000","0.00000000"],["111491.98000000","0.00000000"],["111492.10000000","0.00000000"],["111492.11000000","0.05489000"],["111492.42000000","0.00000000"],["111492.43000000","0.00005000"],["111492.59000000","0.00069000"],["111492.61000000","0.00327000"],["111493.05000000","0.00000000"],["111493.17000000","0.00000000"],["111493.66000000","0.00000000"],["111494.01000000","0.00000000"],["111494.17000000","0.00000000"],["111494.34000000","0.00000000"],["111494.63000000","0.00000000"],["111494.65000000","0.00000000"],["111494.90000000","0.00074000"],["111495.15000000","0.00000000"],["111495.54000000","0.00000000"],["111495.74000000","0.00000000"],["111495.89000000","0.00000000"],["111495.90000000","0.00005000"],["111495.98000000","0.00000000"],["111496.00000000","0.00000000"],["111496.01000000","0.00000000"],["111496.14000000","0.01171000"],["111496.79000000","0.00005000"],["111497.05000000","0.00000000"],["111497.28000000","0.00000000"],["111497.30000000","0.00000000"],["111497.52000000","0.00000000"],["111497.54000000","0.00000000"],["111497.65000000","0.04815000"],["111497.73000000","0.00000000"],["111497.94000000","0.10416000"],["111497.95000000","0.04626000"],["111498.53000000","0.00007000"],["111499.21000000","0.30258000"],["111499.22000000","0.00000000"],["111499.29000000","0.00000000"],["111499.57000000","0.00000000"],["111499.58000000","0.00000000"],["111499.59000000","0.00000000"],["111499.89000000","0.00000000"],["111499.90000000","0.00000000"],["111499.91000000","0.00000000"],["111499.92000000","0.00000000"],["111499.96000000","0.00006000"],["111500.26000000","0.00005000"],["111501.20000000","0.04805000"],["111501.26000000","0.03978000"],["111501.30000000","0.00000000"],["111501.32000000","0.00005000"],["111501.37000000","0.01811000"],["111501.61000000","0.00007000"],["111501.70000000","0.00000000"],["111501.72000000","0.45601000"],["111501.73000000","0.00000000"],["111501.74000000","0.45020000"],["111501.75000000","0.45000000"],["111501.94000000","0.00000000"],["111502.19000000","0.00000000"],["111502.38000000","0.04127000"],["111503.06000000","0.00000000"],["111503.10000000","0.00100000"],["111503.46000000","0.15000000"],["111503.48000000","0.00000000"],["111503.50000000","0.15000000"],["111503.52000000","0.11195000"],["111503.69000000","0.00000000"],["111503.72000000","0.00000000"],["111503.73000000","0.00000000"],["111503.74000000","0.00000000"],["111503.79000000","0.00000000"],["111503.81000000","0.00000000"],["111503.82000000","0.00000000"],["111504.05000000","0.00000000"],["111504.82000000","0.00000000"],["111504.93000000","0.00018000"],["111504.97000000","0.00000000"],["111505.11000000","0.00000000"],["111505.71000000","0.00000000"],["111506.92000000","0.00000000"],["111506.93000000","0.00000000"],["111507.89000000","0.00000000"],["111507.90000000","0.00000000"],["111507.93000000","0.00000000"],["111508.96000000","0.06783000"],["111509.69000000","0.01388000"],["111510.21000000","0.00000000"],["111510.25000000","0.00000000"],["111511.41000000","0.00000000"],["111511.43000000","0.71400000"],["111511.44000000","0.00000000"],["111512.02000000","0.04800000"],["111512.55000000","0.00000000"],["111513.08000000","0.04800000"],["111513.39000000","0.00896000"],["111513.44000000","0.04482000"],["111513.54000000","0.00000000"],["111513.71000000","0.00000000"],["111513.86000000","0.00000000"],["111514.77000000","0.00000000"],["111515.18000000","0.00000000"],["111515.19000000","0.00000000"],["111515.21000000","0.45000000"],["111515.39000000","0.18900000"],["111515.71000000","0.00000000"],["111516.33000000","0.92901000"],["111517.36000000","0.04000000"],["111517.88000000","0.00000000"],["111518.18000000","0.00000000"],["111521.48000000","1.18361000"],["111522.13000000","0.13430000"],["111522.21000000","0.13434000"],["111522.35000000","0.08507000"],["111523.36000000","0.13430000"],["111523.68000000","0.01786000"],["111524.06000000","0.02126000"],["111526.76000000","0.00005000"],["111527.13000000","0.00000000"],["111527.37000000","0.04800000"],["111527.48000000","0.06240000"],["111530.25000000","0.22384000"],["111530.73000000","0.00000000"],["111531.22000000","0.00005000"],["111531.32000000","0.00000000"],["111531.65000000","0.00000000"],["111532.41000000","0.08505000"],["111532.90000000","0.04800000"],["111533.14000000","0.08507000"],["111533.19000000","0.00000000"],["111536.88000000","0.08507000"],["111540.14000000","0.00005000"],["111540.48000000","1.21570000"],["111542.32000000","0.00000000"],["111544.60000000","0.00005000"],["111545.48000000","0.00000000"],["111545.72000000","0.01701000"],["111545.83000000","0.13444000"],["111546.08000000","0.00000000"],["111555.26000000","0.05427000"],["111557.52000000","0.00624000"],["111558.77000000","0.00448000"],["111559.58000000","0.00000000"],["111560.95000000","0.00000000"],["111561.88000000","0.00000000"],["111563.69000000","0.06868000"],["111568.74000000","0.00000000"],["111570.50000000","0.00000000"],["111571.22000000","0.04097000"],["111571.40000000","0.00000000"],["111571.41000000","0.00000000"],["111571.49000000","0.00000000"],["111571.50000000","0.00000000"],["111571.54000000","0.00000000"],["111571.55000000","0.00000000"],["111575.59000000","0.00000000"],["111575.60000000","0.00000000"],["111576.30000000","0.00000000"],["111578.00000000","0.00260000"],["111582.78000000","0.13434000"],["111583.96000000","0.00000000"],["111584.33000000","0.00000000"],["111584.34000000","0.00000000"],["111584.79000000","0.00000000"],["111586.74000000","0.00000000"],["111586.80000000","0.01707000"],["111588.39000000","0.00000000"],["111589.10000000","0.47991000"],["111590.14000000","0.02137000"],["111593.45000000","0.00000000"],["111597.54000000","0.00000000"],["111599.27000000","0.00000000"],["111599.94000000","0.00000000"],["111604.40000000","0.04800000"],["111604.79000000","0.00000000"],["111605.52000000","0.04800000"],["111606.67000000","0.00000000"],["111607.11000000","0.00000000"],["111608.29000000","0.22384000"],["111610.84000000","0.99059000"],["111611.33000000","0.00413000"],["111618.27000000","0.00000000"],["111618.68000000","0.09759000"],["111637.66000000","0.09845000"],["111638.32000000","0.04947000"],["111639.98000000","0.00000000"],["111651.93000000","0.19953000"],["111655.08000000","0.00010000"],["111695.79000000","0.00000000"],["111695.80000000","0.00000000"],["111709.38000000","0.02422000"],["111717.16000000","0.00931000"],["111724.51000000","0.00000000"],["111728.33000000","0.00000000"],["111758.30000000","0.04097000"],["111770.13000000","0.00000000"],["111782.97000000","0.00000000"],["111784.61000000","0.00000000"],["111805.74000000","0.00000000"],["111805.95000000","0.00000000"],["111808.38000000","0.00000000"],["111834.34000000","0.02601000"],["111834.40000000","0.02601000"],["111838.03000000","0.00024000"],["111849.22000000","0.00000000"],["111864.88000000","0.00218000"],["111901.67000000","0.00000000"],["111906.65000000","0.00000000"],["111906.68000000","0.00000000"],["111906.80000000","0.00000000"],["111921.28000000","0.00000000"],["111967.26000000","0.00250000"],["111977.82000000","0.03588000"],["111983.90000000","0.03588000"],["111987.41000000","0.03588000"],["111989.46000000","0.03588000"],["112000.00000000","2.59042000"],["112000.86000000","0.00000000"],["112040.91000000","0.00000000"],["112055.47000000","0.00000000"],["112089.17000000","0.02398000"],["112181.34000000","0.00200000"],["112192.56000000","0.00000000"],["113149.79000000","0.00000000"]]}
[2025-10-12T11:04:34.183Z] {"e":"depthUpdate","E":1760267074014,"s":"BTCUSDT","U":77965271856,"u":77965272229,"b":[["111481.51000000","8.28429000"],["111481.25000000","0.20528000"],["111481.23000000","0.41115000"],["111479.99000000","0.00000000"],["111479.44000000","0.00000000"],["111477.61000000","0.04289000"],["111476.75000000","0.00100000"],["111476.49000000","0.04013000"],["111475.93000000","0.11200000"],["111475.86000000","0.00000000"],["111475.12000000","0.06646000"],["111474.09000000","0.00005000"],["111471.25000000","0.00005000"],["111470.31000000","0.08512000"],["111470.10000000","0.08507000"],["111468.50000000","0.01405000"],["111468.36000000","0.05760000"],["111468.00000000","0.00265000"],["111467.73000000","0.00000000"],["111467.49000000","0.06005000"],["111467.29000000","0.05760000"],["111467.28000000","0.05760000"],["111467.09000000","0.04800000"],["111467.08000000","0.04800000"],["111466.50000000","0.00000000"],["111466.11000000","0.07920000"],["111464.88000000","0.10080000"],["111464.01000000","0.13434000"],["111461.67000000","0.06240000"],["111461.56000000","0.07200000"],["111459.81000000","0.00896000"],["111456.22000000","0.13430000"],["111456.20000000","0.00000000"],["111455.72000000","0.00000000"],["111455.67000000","0.00044000"],["111455.29000000","0.00000000"],["111454.99000000","0.13430000"],["111453.10000000","0.01388000"],["111451.72000000","0.00000000"],["111451.31000000","0.00000000"],["111450.80000000","0.00000000"],["111450.58000000","0.00000000"],["111450.38000000","0.22384000"],["111450.34000000","0.00000000"],["111450.21000000","0.00000000"],["111449.17000000","0.00000000"],["111449.10000000","0.00000000"],["111448.47000000","0.00000000"],["111448.04000000","0.22384000"],["111447.78000000","0.00000000"],["111446.92000000","0.00000000"],["111445.87000000","0.00000000"],["111445.10000000","0.30263000"],["111442.96000000","0.04479000"],["111439.31000000","0.05760000"],["111435.94000000","0.07680000"],["111435.65000000","0.00000000"],["111435.40000000","0.06720000"],["111434.81000000","0.05760000"],["111434.68000000","0.00000000"],["111434.33000000","0.13444000"],["111433.72000000","0.07200000"],["111421.87000000","0.00000000"],["111408.57000000","0.04431000"],["111406.10000000","0.13434000"],["111402.36000000","0.00000000"],["111401.13000000","0.00000000"],["111393.78000000","0.13430000"],["111392.55000000","0.13430000"],["111389.87000000","0.00000000"],["111387.47000000","0.05760000"],["111383.10000000","0.00000000"],["111382.25000000","0.00000000"],["111378.72000000","0.00000000"],["111375.62000000","0.00000000"],["111374.91000000","0.22384000"],["111371.89000000","0.13444000"],["111269.26000000","0.00000000"],["111157.37000000","0.00014000"],["110849.35000000","0.00000000"],["110812.63000000","0.00019000"],["109809.28000000","0.00100000"],["89185.21000000","0.00022000"],["60000.00000000","53.14042000"]],"a":[["111481.52000000","0.45158000"],["111481.53000000","0.00065000"],["111482.63000000","0.00748000"],["111482.64000000","0.00020000"],["111483.12000000","0.00010000"],["111483.13000000","0.04606000"],["111483.14000000","0.00010000"],["111483.75000000","0.01814000"],["111483.76000000","0.00010000"],["111484.70000000","0.00000000"],["111484.71000000","0.00000000"],["111484.72000000","0.00005000"],["111487.85000000","0.00010000"],["111487.87000000","0.00000000"],["111488.09000000","0.05074000"],["111488.77000000","0.00305000"],["111489.33000000","0.00000000"],["111489.34000000","0.00005000"],["111490.88000000","0.00000000"],["111490.89000000","0.00000000"],["111490.90000000","0.00000000"],["111490.91000000","0.00000000"],["111490.92000000","0.00000000"],["111490.93000000","0.00000000"],["111490.94000000","0.00005000"],["111490.95000000","0.02697000"],["111491.05000000","0.00000000"],["111491.06000000","0.56005000"],["111491.35000000","0.00005000"],["111492.10000000","0.00000000"],["111492.11000000","0.05494000"],["111492.37000000","0.04481000"],["111495.90000000","0.00005000"],["111496.14000000","0.01166000"],["111497.64000000","0.00000000"],["111497.65000000","0.04815000"],["111497.66000000","0.06646000"],["111497.94000000","0.10416000"],["111497.95000000","0.00150000"],["111500.26000000","0.00000000"],["111501.19000000","0.00000000"],["111501.20000000","0.04800000"],["111501.26000000","0.03973000"],["111501.32000000","0.00000000"],["111501.37000000","0.00000000"],["111501.48000000","0.01789000"],["111501.70000000","0.00000000"],["111502.56000000","0.00000000"],["111503.10000000","0.00000000"],["111503.42000000","0.00000000"],["111503.44000000","0.00000000"],["111503.46000000","0.00000000"],["111503.48000000","0.15000000"],["111503.67000000","0.00005000"],["111507.44000000","0.04800000"],["111508.65000000","0.17109000"],["111508.66000000","0.04800000"],["111508.96000000","0.00000000"],["111509.64000000","0.07200000"],["111510.90000000","0.07200000"],["111511.99000000","0.00005000"],["111513.44000000","0.00000000"],["111514.17000000","0.04800000"],["111514.33000000","0.04800000"],["111517.33000000","0.08507000"],["111517.67000000","0.08505000"],["111526.46000000","0.00000000"],["111527.48000000","0.00000000"],["111527.70000000","0.00000000"],["111528.18000000","0.00000000"],["111528.68000000","0.00000000"],["111529.94000000","1.25396000"],["111532.41000000","0.00000000"],["111532.90000000","0.00000000"],["111533.14000000","0.00000000"],["111533.24000000","0.00000000"],["111535.68000000","0.00005000"],["111544.60000000","0.00000000"],["111555.00000000","0.00000000"],["111555.07000000","0.08793000"],["111558.20000000","0.00896000"],["111575.60000000","0.00100000"],["111575.61000000","0.00100000"],["111592.15000000","0.07200000"],["111593.38000000","0.07200000"],["111599.99000000","0.04800000"],["111601.20000000","0.04800000"],["111606.55000000","0.54303000"],["111606.67000000","0.04800000"],["111606.74000000","0.00000000"],["111618.89000000","0.00000000"],["111655.85000000","0.15834000"],["111835.91000000","0.00627000"],["112086.76000000","0.02398000"],["113153.75000000","0.00100000"]]}
[2025-10-12T11:04:35.182Z] {"e":"depthUpdate","E":1760267075014,"s":"BTCUSDT","U":77965272230,"u":77965272812,"b":[["111482.62000000","5.44855000"],["111482.54000000","0.00010000"],["111482.46000000","0.00907000"],["111482.23000000","0.01355000"],["111482.16000000","0.00005000"],["111482.07000000","0.00000000"],["111481.59000000","0.46477000"],["111481.54000000","0.00000000"],["111481.52000000","0.39154000"],["111481.51000000","0.06523000"],["111481.44000000","0.00000000"],["111481.25000000","0.20528000"],["111481.23000000","0.00000000"],["111480.40000000","0.00364000"],["111478.72000000","0.00543000"],["111477.99000000","0.80841000"],["111477.53000000","0.00005000"],["111477.52000000","0.24202000"],["111477.45000000","0.00005000"],["111477.22000000","0.01351000"],["111477.21000000","0.00005000"],["111477.05000000","0.00150000"],["111476.75000000","0.00000000"],["111476.49000000","0.04008000"],["111475.93000000","0.11195000"],["111475.12000000","0.06651000"],["111474.68000000","0.04934000"],["111474.00000000","0.00260000"],["111473.71000000","0.00005000"],["111473.32000000","0.00043000"],["111472.60000000","0.00000000"],["111472.44000000","0.00005000"],["111471.90000000","0.00156000"],["111471.48000000","0.00000000"],["111471.04000000","0.00000000"],["111469.45000000","0.02692000"],["111468.75000000","0.00000000"],["111468.50000000","0.01400000"],["111468.36000000","0.05760000"],["111468.00000000","0.00260000"],["111467.49000000","0.06000000"],["111464.55000000","0.00005000"],["111464.01000000","0.00000000"],["111463.28000000","0.00000000"],["111442.87000000","0.31626000"],["111441.76000000","0.00000000"],["111440.42000000","1.17478000"],["111439.08000000","0.09605000"],["111438.10000000","1.22444000"],["111437.56000000","0.00000000"],["111431.97000000","0.19912000"],["111431.96000000","0.00000000"],["111428.29000000","0.00000000"],["111414.41000000","0.04426000"],["111408.57000000","0.00005000"],["111408.01000000","0.13434000"],["111406.10000000","0.00000000"],["111393.35000000","0.07200000"],["111383.61000000","0.00000000"],["111379.19000000","0.00000000"],["111379.17000000","0.00000000"],["111378.28000000","0.00000000"],["111378.14000000","0.00000000"],["111376.49000000","0.00000000"],["111374.87000000","0.00000000"],["111309.67000000","0.00574000"],["111297.74000000","0.00000000"],["111289.52000000","0.00000000"],["111230.46000000","0.07530000"],["111162.34000000","0.00010000"],["111158.98000000","0.00000000"],["110812.63000000","0.00000000"],["109810.38000000","0.00100000"],["109809.28000000","0.00000000"],["100333.00000000","0.05448000"],["100332.00000000","0.00299000"],["98103.47000000","0.00000000"],["89186.10000000","0.00022000"],["89185.21000000","0.00000000"],["60000.00000000","53.14032000"],["40133.75000000","0.00015000"]],"a":[["111481.52000000","0.00000000"],["111481.53000000","0.00000000"],["111481.54000000","0.00000000"],["111481.60000000","0.00000000"],["111482.63000000","2.17662000"],["111482.64000000","0.00080000"],["111482.65000000","0.00020000"],["111482.71000000","0.00010000"],["111483.12000000","0.00000000"],["111483.13000000","0.00000000"],["111483.14000000","0.00000000"],["111483.61000000","0.00000000"],["111483.75000000","0.01844000"],["111483.76000000","0.00020000"],["111486.21000000","0.00010000"],["111486.22000000","0.30273000"],["111486.23000000","0.00010000"],["111486.53000000","0.00548000"],["111486.54000000","0.00010000"],["111487.24000000","0.00005000"],["111487.64000000","0.00723000"],["111487.70000000","0.00010000"],["111487.71000000","0.04704000"],["111487.72000000","0.00000000"],["111487.87000000","0.00000000"],["111488.09000000","0.05079000"],["111488.76000000","0.01799000"],["111488.77000000","0.00310000"],["111488.89000000","0.00000000"],["111488.90000000","0.04013000"],["111489.34000000","0.00000000"],["111489.84000000","0.00000000"],["111490.02000000","0.04112000"],["111490.94000000","0.00000000"],["111490.95000000","0.00000000"],["111491.05000000","0.00000000"],["111491.06000000","0.56000000"],["111491.32000000","0.00000000"],["111491.34000000","0.00000000"],["111491.48000000","0.00000000"],["111491.74000000","0.00000000"],["111491.79000000","0.02692000"],["111492.11000000","0.05489000"],["111492.37000000","0.04476000"],["111492.59000000","0.00000000"],["111494.90000000","0.00000000"],["111495.76000000","0.00072000"],["111495.93000000","0.00000000"],["111495.96000000","0.00000000"],["111496.10000000","0.00070000"],["111496.14000000","0.01171000"],["111497.64000000","0.03469000"],["111497.65000000","0.04810000"],["111497.94000000","0.00000000"],["111497.95000000","0.00150000"],["111498.53000000","0.00000000"],["111499.21000000","0.00000000"],["111499.64000000","0.00007000"],["111501.20000000","0.04800000"],["111501.26000000","0.00000000"],["111501.48000000","0.00000000"],["111501.72000000","0.15000000"],["111501.73000000","0.42048000"],["111502.38000000","0.00000000"],["111502.88000000","0.00100000"],["111503.44000000","0.00000000"],["111503.46000000","0.00000000"],["111503.48000000","0.00000000"],["111506.92000000","0.01832000"],["111511.54000000","0.00005000"],["111555.00000000","0.00005000"],["111558.22000000","0.00448000"],["111575.60000000","0.00000000"],["111575.61000000","0.00000000"],["111575.64000000","0.00100000"],["111575.65000000","0.00100000"],["111595.27000000","0.08558000"],["111606.74000000","0.04800000"],["111731.05000000","0.04454000"],["113153.75000000","0.00000000"],["113154.87000000","0.00100000"]]}
[2025-10-12T11:04:36.182Z] {"e":"depthUpdate","E":1760267076014,"s":"BTCUSDT","U":77965272813,"u":77965272989,"b":[["111482.62000000","5.25301000"],["111482.61000000","0.00040000"],["111482.50000000","0.00080000"],["111477.50000000","0.00000000"],["111473.32000000","0.00000000"],["111466.99000000","0.13434000"],["111464.36000000","0.00000000"],["111461.76000000","0.04327000"],["111457.85000000","0.00005000"],["111455.95000000","0.01388000"],["111455.67000000","0.00000000"],["111453.10000000","0.00000000"],["111443.31000000","0.66008000"],["111428.46000000","0.00000000"],["111418.69000000","0.00070000"],["111406.18000000","0.00000000"],["111396.41000000","0.00019000"],["111329.80000000","0.00218000"],["111321.03000000","0.00000000"],["110849.35000000","0.00000000"],["109810.38000000","0.00100000"],["100334.00000000","0.00000000"],["100333.00000000","0.05448000"],["89186.10000000","0.00022000"],["42000.00000000","1.49196000"],["40133.75000000","0.00030000"]],"a":[["111482.63000000","2.25203000"],["111482.64000000","0.00075000"],["111488.76000000","0.01799000"],["111488.77000000","0.00310000"],["111488.90000000","0.00000000"],["111490.02000000","0.00000000"],["111490.17000000","0.04121000"],["111491.06000000","0.56000000"],["111491.29000000","0.03957000"],["111491.79000000","0.00000000"],["111491.81000000","0.00000000"],["111491.82000000","0.00000000"],["111491.83000000","0.02692000"],["111492.61000000","0.00332000"],["111492.81000000","0.01775000"],["111494.70000000","0.00005000"],["111508.42000000","0.00005000"],["111514.67000000","0.00005000"],["111551.65000000","0.00000000"],["111559.72000000","0.27980000"],["111575.64000000","0.00000000"],["111575.66000000","0.00100000"],["111864.88000000","0.00000000"],["111873.69000000","0.00218000"],["112087.67000000","0.02398000"],["113154.87000000","0.00100000"]]}
[2025-10-12T11:04:37.182Z] {"e":"depthUpdate","E":1760267077014,"s":"BTCUSDT","U":77965272990,"u":77965273140,"b":[["111482.62000000","5.25479000"],["111481.52000000","0.39054000"],["111478.72000000","0.00548000"],["111478.36000000","0.00100000"],["111450.99000000","0.22384000"],["111448.04000000","0.00000000"],["111374.91000000","0.00000000"],["111374.11000000","0.22384000"],["111355.20000000","0.00132000"],["111353.54000000","0.00231000"],["111343.96000000","0.00000000"],["111343.60000000","0.00000000"],["111342.65000000","0.44850000"],["111329.80000000","0.00000000"],["110980.30000000","0.03587000"],["110813.73000000","0.00019000"],["109810.38000000","0.00100000"],["105900.00000000","0.07803000"],["100334.00000000","0.00000000"],["100333.00000000","0.05448000"],["89186.10000000","0.00022000"],["33000.00000000","3.87311000"]],"a":[["111482.63000000","2.12255000"],["111482.64000000","0.00075000"],["111487.71000000","0.00010000"],["111488.76000000","0.01799000"],["111488.77000000","0.00305000"],["111490.17000000","0.00000000"],["111490.94000000","0.00000000"],["111491.06000000","0.56005000"],["111491.29000000","0.00005000"],["111491.83000000","0.02692000"],["111492.06000000","0.00000000"],["111492.37000000","0.04476000"],["111492.61000000","0.00332000"],["111492.81000000","0.00000000"],["111494.98000000","0.00000000"],["111496.14000000","0.01176000"],["111496.68000000","0.00000000"],["111497.55000000","0.01738000"],["111497.65000000","0.04805000"],["111497.66000000","0.06651000"],["111497.80000000","0.00000000"],["111501.72000000","0.00000000"],["111503.48000000","0.00000000"],["111503.50000000","0.00000000"],["111505.30000000","0.00005000"],["111508.63000000","0.30000000"],["111517.79000000","0.00005000"],["111550.38000000","0.02398000"],["111572.31000000","0.00166000"],["111653.23000000","0.01236000"],["111761.23000000","0.00000000"],["111873.69000000","0.00000000"],["111876.61000000","0.02398000"],["111897.54000000","0.00218000"],["111928.55000000","0.00022000"],["112008.74000000","0.00000000"],["112102.62000000","0.00000000"],["113154.87000000","0.00100000"]]}
[2025-10-12T11:04:38.182Z] {"e":"depthUpdate","E":1760267078014,"s":"BTCUSDT","U":77965273141,"u":77965273325,"b":[["111482.62000000","5.83862000"],["111478.72000000","0.00543000"],["111478.36000000","0.00000000"],["111472.61000000","0.00543000"],["111472.01000000","0.00448000"],["111464.76000000","0.40348000"],["111454.50000000","0.00405000"],["111453.54000000","0.00000000"],["111452.08000000","0.30262000"],["111450.99000000","0.00000000"],["111445.88000000","1.18757000"],["111445.10000000","0.00000000"],["111443.32000000","0.00000000"],["111443.31000000","0.29356000"],["111440.42000000","0.00000000"],["111435.79000000","0.22384000"],["111388.41000000","0.00164000"],["111376.60000000","0.00000000"],["111376.02000000","0.00000000"],["111374.11000000","0.00000000"],["111291.62000000","0.00089000"],["111285.12000000","0.00000000"],["111283.64000000","0.00000000"],["111276.37000000","0.00065000"],["111273.08000000","0.00089000"],["111240.74000000","0.02511000"],["111237.67000000","0.02511000"],["111236.98000000","0.02511000"],["111236.72000000","0.02511000"],["111236.33000000","0.02511000"],["111236.04000000","0.02511000"],["111235.71000000","0.02511000"],["111235.10000000","0.02511000"],["111233.02000000","0.02511000"],["111000.00000000","16.80353000"],["110838.28000000","0.89111000"],["110813.73000000","0.00000000"],["110600.00000000","0.95730000"],["109810.38000000","0.00100000"],["106000.00000000","32.65633000"],["105900.00000000","0.07792000"],["102614.52000000","0.00000000"],["100334.00000000","0.00000000"],["100333.00000000","0.05448000"],["89186.10000000","0.00022000"],["42000.00000000","1.49096000"],["40133.75000000","0.00045000"]],"a":[["111482.63000000","0.92686000"],["111482.64000000","0.00060000"],["111483.75000000","0.01839000"],["111483.76000000","0.00020000"],["111486.21000000","0.00000000"],["111486.22000000","0.00000000"],["111486.23000000","0.00000000"],["111487.64000000","0.00723000"],["111487.65000000","0.00010000"],["111487.70000000","0.00000000"],["111487.71000000","0.00000000"],["111488.09000000","0.05084000"],["111488.75000000","0.00010000"],["111488.76000000","0.01804000"],["111489.38000000","0.00005000"],["111489.39000000","0.30267000"],["111491.05000000","0.00005000"],["111491.83000000","0.02697000"],["111492.11000000","0.05489000"],["111492.37000000","0.00000000"],["111492.61000000","0.00332000"],["111493.15000000","0.05976000"],["111496.14000000","0.01181000"],["111496.67000000","0.06418000"],["111496.68000000","0.00000000"],["111497.64000000","0.00000000"],["111497.66000000","0.06646000"],["111497.80000000","0.00000000"],["111498.05000000","0.00005000"],["111499.34000000","0.00000000"],["111499.35000000","0.04476000"],["111500.52000000","0.04127000"],["111501.19000000","0.00448000"],["111501.64000000","0.03973000"],["111501.72000000","0.15000000"],["111502.18000000","0.00005000"],["111502.88000000","0.00000000"],["111503.48000000","0.00000000"],["111503.50000000","0.15000000"],["111506.91000000","0.04482000"],["111507.39000000","0.00000000"],["111507.41000000","0.42989000"],["111507.42000000","0.35816000"],["111507.43000000","0.35866000"],["111508.61000000","0.00000000"],["111508.62000000","0.00005000"],["111508.63000000","0.00000000"],["111508.65000000","0.06240000"],["111516.33000000","0.50577000"],["111520.91000000","0.00005000"],["111521.48000000","0.00000000"],["111522.78000000","0.02398000"],["111522.79000000","1.23497000"],["111540.47000000","0.02398000"],["111548.30000000","0.00000000"],["111567.92000000","0.00223000"],["111575.99000000","0.00000000"],["111576.77000000","0.04346000"],["111589.98000000","0.00223000"],["111591.98000000","0.00223000"],["111606.66000000","0.00000000"],["111625.09000000","0.02398000"],["111679.44000000","0.00089000"],["111693.99000000","0.00000000"],["111701.28000000","0.00089000"],["111703.20000000","0.00089000"],["111718.40000000","0.00000000"],["111731.05000000","0.00000000"],["111804.44000000","0.00000000"],["111943.54000000","0.02398000"],["111987.25000000","0.03677000"],["113154.87000000","0.00100000"]]}
[2025-10-12T11:04:39.182Z] {"e":"depthUpdate","E":1760267079014,"s":"BTCUSDT","U":77965273326,"u":77965273694,"b":[["111482.62000000","6.11993000"],["111482.61000000","0.00000000"],["111482.46000000","0.00912000"],["111482.24000000","0.06656000"],["111481.51000000","0.06518000"],["111481.25000000","0.20528000"],["111480.40000000","0.00364000"],["111479.86000000","0.00000000"],["111477.99000000","0.80841000"],["111477.69000000","0.00000000"],["111477.61000000","0.04284000"],["111477.23000000","0.00000000"],["111476.49000000","0.04018000"],["111476.01000000","0.00448000"],["111475.94000000","0.21263000"],["111475.80000000","0.05568000"],["111475.39000000","0.00369000"],["111475.15000000","0.08507000"],["111475.12000000","0.06646000"],["111474.77000000","0.00000000"],["111474.68000000","0.00000000"],["111474.43000000","0.00043000"],["111472.61000000","0.00538000"],["111472.01000000","0.00000000"],["111470.89000000","0.00543000"],["111470.31000000","0.08507000"],["111470.10000000","0.00000000"],["111469.46000000","0.00000000"],["111469.16000000","0.35865000"],["111467.50000000","0.04482000"],["111466.99000000","0.00000000"],["111466.60000000","0.13434000"],["111466.22000000","0.00000000"],["111464.76000000","0.00000000"],["111462.52000000","0.00000000"],["111456.78000000","0.00044000"],["111455.95000000","0.00000000"],["111455.66000000","0.01388000"],["111454.42000000","0.00000000"],["111451.15000000","0.00005000"],["111450.38000000","0.00000000"],["111449.18000000","0.04481000"],["111435.79000000","0.13434000"],["111432.75000000","0.04426000"],["111414.41000000","0.00000000"],["111408.01000000","0.00000000"],["111405.31000000","0.00000000"],["111376.79000000","0.00000000"],["111376.76000000","0.00000000"],["111376.60000000","0.00000000"],["111376.52000000","0.13444000"],["111376.25000000","0.00000000"],["111376.18000000","0.00000000"],["111375.63000000","0.00000000"],["111375.48000000","0.00000000"],["111375.45000000","0.22384000"],["111373.87000000","0.00000000"],["111371.90000000","0.00218000"],["111371.89000000","0.00000000"],["111353.54000000","0.00013000"],["111048.31000000","0.00000000"],["111047.52000000","0.00080000"],["110470.00000000","0.00043000"],["110000.00000000","26.25142000"],["109810.38000000","0.00100000"],["100334.36000000","0.00019000"],["100333.00000000","0.05448000"],["89186.10000000","0.00022000"],["40133.75000000","0.00060000"]],"a":[["111482.63000000","0.07152000"],["111482.64000000","0.00568000"],["111482.65000000","0.00020000"],["111482.71000000","0.00010000"],["111482.80000000","0.00100000"],["111482.81000000","0.00020000"],["111483.61000000","0.00005000"],["111483.75000000","0.01819000"],["111483.76000000","0.00010000"],["111485.12000000","0.00010000"],["111486.01000000","0.00010000"],["111486.08000000","0.00000000"],["111486.13000000","0.00000000"],["111486.21000000","0.00000000"],["111486.54000000","0.00000000"],["111487.65000000","0.00000000"],["111488.76000000","0.01804000"],["111488.77000000","0.00310000"],["111489.38000000","0.00000000"],["111489.39000000","0.00000000"],["111491.06000000","0.56005000"],["111491.29000000","0.00000000"],["111491.73000000","0.00000000"],["111491.83000000","0.00000000"],["111491.88000000","0.00000000"],["111491.89000000","0.02697000"],["111492.11000000","0.05484000"],["111492.61000000","0.00327000"],["111493.15000000","0.00000000"],["111495.15000000","0.30262000"],["111496.14000000","0.01171000"],["111496.67000000","0.00000000"],["111496.73000000","0.00000000"],["111496.79000000","0.00000000"],["111497.55000000","0.01743000"],["111497.65000000","0.00000000"],["111497.66000000","0.00000000"],["111497.95000000","0.00155000"],["111499.06000000","0.00005000"],["111500.52000000","0.00000000"],["111500.56000000","0.00000000"],["111501.19000000","0.00000000"],["111501.28000000","0.04034000"],["111501.40000000","0.00005000"],["111501.64000000","0.00000000"],["111501.71000000","0.41971000"],["111501.72000000","0.30000000"],["111501.73000000","0.00000000"],["111502.40000000","0.04092000"],["111503.49000000","0.00000000"],["111503.50000000","0.00000000"],["111504.83000000","0.00448000"],["111504.84000000","0.00000000"],["111505.86000000","0.01782000"],["111506.91000000","0.00000000"],["111506.92000000","0.00000000"],["111507.39000000","0.00000000"],["111507.41000000","0.14167000"],["111507.42000000","0.00000000"],["111507.43000000","0.00000000"],["111509.63000000","0.00000000"],["111510.89000000","0.04482000"],["111512.01000000","0.35865000"],["111512.06000000","0.04800000"],["111516.07000000","0.04482000"],["111517.57000000","0.04800000"],["111524.03000000","0.00005000"],["111527.37000000","0.00000000"],["111540.09000000","0.06240000"],["111543.24000000","0.04800000"],["111544.34000000","0.04800000"],["111544.95000000","0.00000000"],["111545.56000000","0.04800000"],["111575.65000000","0.00000000"],["111575.66000000","0.00000000"],["111576.65000000","0.00000000"],["111576.66000000","0.00000000"],["111577.60000000","0.00000000"],["111577.61000000","0.04800000"],["111586.80000000","0.00000000"],["111589.97000000","0.00223000"],["111589.98000000","0.00000000"],["111590.14000000","0.00000000"],["111594.13000000","0.00000000"],["111597.63000000","0.00000000"],["111601.09000000","0.04800000"],["111606.64000000","0.04800000"],["111606.67000000","0.00000000"],["111651.93000000","0.32588000"],["111654.24000000","0.44680000"],["111664.59000000","0.34629000"],["111698.10000000","0.00000000"],["111701.28000000","0.00089000"],["111753.18000000","0.04097000"],["111830.67000000","0.00000000"],["111897.54000000","0.00000000"],["111915.97000000","0.00218000"],["113154.87000000","0.00100000"]]}
[2025-10-12T11:04:40.182Z] {"e":"depthUpdate","E":1760267080014,"s":"BTCUSDT","U":77965273695,"u":77965273906,"b":[["111482.62000000","5.67293000"],["111482.61000000","0.00005000"],["111482.23000000","0.01355000"],["111481.67000000","0.00000000"],["111481.52000000","0.39054000"],["111477.99000000","0.80841000"],["111476.49000000","0.04013000"],["111476.01000000","0.00000000"],["111475.12000000","0.06651000"],["111474.38000000","0.00000000"],["111472.62000000","0.00448000"],["111470.89000000","0.00543000"],["111470.31000000","0.08507000"],["111469.16000000","0.00000000"],["111468.75000000","0.00699000"],["111467.08000000","0.04844000"],["111465.73000000","0.35866000"],["111462.36000000","0.00000000"],["111455.66000000","0.00000000"],["111454.87000000","0.01388000"],["111454.59000000","0.08000000"],["111454.50000000","0.00405000"],["111452.08000000","0.00000000"],["111450.98000000","0.22384000"],["111450.78000000","0.22384000"],["111449.18000000","0.00000000"],["111448.47000000","0.30263000"],["111401.65000000","0.01403000"],["111375.04000000","0.22397000"],["110849.35000000","0.89111000"],["110838.28000000","0.00000000"],["109810.38000000","0.00100000"],["106970.40000000","0.00000000"],["100334.36000000","0.00000000"],["100334.00000000","0.00000000"],["100333.00000000","0.05448000"],["89186.10000000","0.00022000"],["40133.75000000","0.00075000"]],"a":[["111482.63000000","0.56287000"],["111482.64000000","0.00573000"],["111482.71000000","0.00010000"],["111483.61000000","0.00000000"],["111485.12000000","0.00000000"],["111486.01000000","0.00000000"],["111486.05000000","0.00000000"],["111486.54000000","0.00010000"],["111488.76000000","0.01804000"],["111488.77000000","0.00315000"],["111490.99000000","0.00005000"],["111491.00000000","0.04481000"],["111491.05000000","0.00005000"],["111491.06000000","0.56005000"],["111491.21000000","0.04420000"],["111491.89000000","0.00000000"],["111491.92000000","0.00000000"],["111491.93000000","0.00000000"],["111491.97000000","0.00000000"],["111492.11000000","0.05489000"],["111492.12000000","0.00000000"],["111492.16000000","0.00000000"],["111492.17000000","0.00000000"],["111492.18000000","0.02692000"],["111492.61000000","0.00332000"],["111495.14000000","0.09999000"],["111495.54000000","0.00005000"],["111495.93000000","0.00005000"],["111497.95000000","0.00150000"],["111499.35000000","0.00000000"],["111501.97000000","0.00448000"],["111504.83000000","0.00000000"],["111508.10000000","0.00005000"],["111516.07000000","0.00000000"],["111527.16000000","0.00005000"],["111529.36000000","0.00000000"],["111538.44000000","0.00000000"],["111538.72000000","0.04800000"],["111539.98000000","0.04800000"],["111540.14000000","0.00000000"],["111541.60000000","0.00000000"],["111545.57000000","0.04800000"],["111576.65000000","0.00100000"],["111576.66000000","0.00100000"],["111593.79000000","0.00000000"],["111595.27000000","0.05262000"],["111599.99000000","0.00000000"],["111601.20000000","0.00000000"],["111604.40000000","0.00000000"],["111605.52000000","0.00000000"],["111606.74000000","0.00000000"],["111613.74000000","0.01403000"],["111683.32000000","0.07531000"],["111716.64000000","0.00000000"],["113154.87000000","0.00100000"],["119000.00000000","12.34058000"]]}
[2025-10-12T11:04:41.186Z] {"e":"depthUpdate","E":1760267081014,"s":"BTCUSDT","U":77965273907,"u":77965278009,"b":[["111505.64000000","8.03445000"],["111505.58000000","0.00000000"],["111505.57000000","0.00010000"],["111505.42000000","0.20125000"],["111505.32000000","0.00000000"],["111505.30000000","0.26588000"],["111505.29000000","0.00000000"],["111504.92000000","0.00000000"],["111504.83000000","0.00000000"],["111504.74000000","0.00000000"],["111504.51000000","0.00000000"],["111504.47000000","0.00000000"],["111504.46000000","0.00005000"],["111504.19000000","0.00000000"],["111504.18000000","0.00000000"],["111503.03000000","0.00000000"],["111503.01000000","0.24630000"],["111503.00000000","0.00000000"],["111502.98000000","0.00000000"],["111502.95000000","0.00000000"],["111502.94000000","0.00000000"],["111502.93000000","0.58205000"],["111502.92000000","0.11590000"],["111502.87000000","0.00000000"],["111502.86000000","0.00000000"],["111502.85000000","0.00000000"],["111502.75000000","0.00000000"],["111502.70000000","0.00000000"],["111502.69000000","0.00005000"],["111502.39000000","0.00000000"],["111502.30000000","0.00000000"],["111501.97000000","0.00000000"],["111501.96000000","0.00000000"],["111501.80000000","0.04098000"],["111501.70000000","0.00000000"],["111501.57000000","0.00000000"],["111501.27000000","0.00000000"],["111501.20000000","0.00000000"],["111501.19000000","0.00000000"],["111500.57000000","0.00005000"],["111500.06000000","0.00000000"],["111500.00000000","0.00005000"],["111499.74000000","0.00000000"],["111499.67000000","0.00016000"],["111499.19000000","0.30717000"],["111499.18000000","0.35816000"],["111498.79000000","0.06651000"],["111497.78000000","0.08512000"],["111497.54000000","0.00000000"],["111497.45000000","0.00000000"],["111497.34000000","0.00081000"],["111496.95000000","0.00000000"],["111496.85000000","0.04417000"],["111496.78000000","0.00000000"],["111496.61000000","0.00000000"],["111496.13000000","0.00000000"],["111495.89000000","0.00000000"],["111495.79000000","0.00010000"],["111495.54000000","0.00005000"],["111495.50000000","0.00410000"],["111495.14000000","0.00000000"],["111495.13000000","0.00000000"],["111495.12000000","0.00000000"],["111495.09000000","0.00000000"],["111495.08000000","0.35816000"],["111494.73000000","0.00000000"],["111494.69000000","0.00000000"],["111494.28000000","0.00000000"],["111493.92000000","0.00000000"],["111493.20000000","0.00000000"],["111492.60000000","0.00000000"],["111492.42000000","0.00000000"],["111492.17000000","0.00000000"],["111492.16000000","0.00000000"],["111492.10000000","0.00000000"],["111492.09000000","0.00000000"],["111491.84000000","0.00305000"],["111491.82000000","0.05760000"],["111491.80000000","0.06000000"],["111491.78000000","0.96126000"],["111491.77000000","0.45039000"],["111491.76000000","0.45000000"],["111491.72000000","0.00010000"],["111491.70000000","0.11195000"],["111491.34000000","0.00070000"],["111491.25000000","0.00000000"],["111491.24000000","0.00000000"],["111491.23000000","1.25396000"],["111491.22000000","0.00000000"],["111491.21000000","0.00000000"],["111491.20000000","0.35821000"],["111491.19000000","0.00000000"],["111491.16000000","0.00000000"],["111491.13000000","0.00000000"],["111491.08000000","0.00005000"],["111491.07000000","0.00000000"],["111491.06000000","0.00453000"],["111491.05000000","0.04003000"],["111491.04000000","0.00000000"],["111490.99000000","0.00000000"],["111490.46000000","0.06646000"],["111490.14000000","0.01811000"],["111490.06000000","0.08505000"],["111489.70000000","0.00005000"],["111489.11000000","0.00000000"],["111488.90000000","0.00000000"],["111488.76000000","0.00000000"],["111488.75000000","0.04003000"],["111488.74000000","0.00000000"],["111488.60000000","0.00000000"],["111488.48000000","0.07680000"],["111488.42000000","0.07527000"],["111488.24000000","0.00000000"],["111488.08000000","0.00000000"],["111488.07000000","0.00000000"],["111488.02000000","0.00000000"],["111487.98000000","0.00010000"],["111487.93000000","0.06720000"],["111487.89000000","0.15000000"],["111487.88000000","1.03985000"],["111487.87000000","1.25396000"],["111487.86000000","0.00000000"],["111487.85000000","0.35816000"],["111487.84000000","0.00000000"],["111487.79000000","0.00000000"],["111487.63000000","0.03998000"],["111487.38000000","0.00044000"],["111487.35000000","0.05760000"],["111487.23000000","0.00000000"],["111486.99000000","0.00007000"],["111486.85000000","0.00000000"],["111486.84000000","0.08507000"],["111486.62000000","0.00005000"],["111486.53000000","0.00000000"],["111486.52000000","0.03998000"],["111486.24000000","0.07200000"],["111486.13000000","0.13434000"],["111486.08000000","0.00007000"],["111486.00000000","0.00000000"],["111485.67000000","0.00000000"],["111485.48000000","0.00138000"],["111485.30000000","0.00000000"],["111485.27000000","0.00000000"],["111484.72000000","0.00000000"],["111484.71000000","0.00000000"],["111484.64000000","0.00000000"],["111484.30000000","0.01165000"],["111484.27000000","0.00000000"],["111484.00000000","0.00000000"],["111483.78000000","0.00000000"],["111483.77000000","0.00000000"],["111483.76000000","1.25396000"],["111483.75000000","0.35861000"],["111483.74000000","0.03998000"],["111483.73000000","0.00000000"],["111483.68000000","0.00000000"],["111483.67000000","0.00000000"],["111483.46000000","0.00000000"],["111483.25000000","0.00000000"],["111483.23000000","0.00000000"],["111483.22000000","0.00000000"],["111483.21000000","0.00000000"],["111483.19000000","0.00000000"],["111483.18000000","0.03998000"],["111483.13000000","0.00000000"],["111483.00000000","0.00000000"],["111482.94000000","0.00000000"],["111482.90000000","0.00000000"],["111482.80000000","0.00000000"],["111482.79000000","0.00000000"],["111482.70000000","0.00000000"],["111482.66000000","0.00000000"],["111482.64000000","1.07661000"],["111482.63000000","0.00000000"],["111482.62000000","0.04400000"],["111482.61000000","0.00000000"],["111482.54000000","0.00000000"],["111482.50000000","0.00000000"],["111482.46000000","0.00897000"],["111482.41000000","0.00010000"],["111482.30000000","0.02126000"],["111482.24000000","0.06646000"],["111482.23000000","0.01345000"],["111482.00000000","0.00400000"],["111481.98000000","0.00000000"],["111481.60000000","0.00000000"],["111481.59000000","0.35816000"],["111481.52000000","0.00000000"],["111481.51000000","0.01217000"],["111481.26000000","0.00000000"],["111481.25000000","0.00000000"],["111481.24000000","0.05760000"],["111481.12000000","0.04800000"],["111481.00000000","0.00000000"],["111480.69000000","0.00300000"],["111480.50000000","0.00000000"],["111480.40000000","0.00359000"],["111479.91000000","0.04482000"],["111479.90000000","0.45000000"],["111479.43000000","0.00000000"],["111479.42000000","0.00000000"],["111479.41000000","1.25396000"],["111478.87000000","0.00000000"],["111478.73000000","0.00000000"],["111478.72000000","0.00538000"],["111478.60000000","0.56000000"],["111478.01000000","0.00000000"],["111478.00000000","0.00005000"],["111477.99000000","0.80836000"],["111477.95000000","0.00005000"],["111477.83000000","0.00005000"],["111477.74000000","0.00006000"],["111477.61000000","0.00260000"],["111477.57000000","0.00000000"],["111477.53000000","0.00000000"],["111477.45000000","0.00000000"],["111477.23000000","0.00000000"],["111477.22000000","0.01346000"],["111477.12000000","0.00010000"],["111477.08000000","0.00044000"],["111477.05000000","0.00000000"],["111476.81000000","0.00000000"],["111476.69000000","0.00000000"],["111476.66000000","0.00000000"],["111476.56000000","0.00000000"],["111476.49000000","0.00000000"],["111476.39000000","0.00000000"],["111476.38000000","0.00000000"],["111475.96000000","1.02043000"],["111475.95000000","1.25396000"],["111475.94000000","0.00000000"],["111475.93000000","0.00000000"],["111475.85000000","0.00000000"],["111475.80000000","0.00000000"],["111475.55000000","0.00000000"],["111475.40000000","0.30255000"],["111475.39000000","0.00359000"],["111475.24000000","0.00000000"],["111475.16000000","0.00000000"],["111475.15000000","0.00000000"],["111475.12000000","0.06646000"],["111475.10000000","0.08505000"],["111474.76000000","0.00000000"],["111474.52000000","0.00000000"],["111474.43000000","0.00000000"],["111474.42000000","0.00000000"],["111474.08000000","0.13430000"],["111474.06000000","0.00271000"],["111474.00000000","0.00260000"],["111473.95000000","0.01165000"],["111473.92000000","0.00010000"],["111473.80000000","0.00000000"],["111473.71000000","0.00000000"],["111473.26000000","0.00000000"],["111473.10000000","0.22384000"],["111472.84000000","0.13430000"],["111472.62000000","0.00000000"],["111472.59000000","0.00000000"],["111472.58000000","1.25396000"],["111472.47000000","0.00000000"],["111472.43000000","0.00000000"],["111472.01000000","0.08995000"],["111471.90000000","0.00000000"],["111471.76000000","0.00000000"],["111471.57000000","0.04479000"],["111470.89000000","0.00538000"],["111470.37000000","0.00442000"],["111470.31000000","0.00000000"],["111469.47000000","0.04481000"],["111469.16000000","0.00000000"],["111468.75000000","0.00000000"],["111467.83000000","0.00009000"],["111467.51000000","0.00000000"],["111467.50000000","0.00000000"],["111467.49000000","0.00000000"],["111467.30000000","0.00000000"],["111467.28000000","0.00000000"],["111467.08000000","0.00000000"],["111466.60000000","0.00000000"],["111466.33000000","0.00113000"],["111465.83000000","0.31890000"],["111465.73000000","0.00000000"],["111465.72000000","0.00000000"],["111465.62000000","0.00018000"],["111465.08000000","0.00000000"],["111464.80000000","0.00000000"],["111463.84000000","0.00000000"],["111463.19000000","0.00000000"],["111463.12000000","0.00000000"],["111463.11000000","0.00000000"],["111462.86000000","0.00000000"],["111462.15000000","0.03498000"],["111462.04000000","0.00000000"],["111461.76000000","0.00000000"],["111461.47000000","0.00000000"],["111461.33000000","0.00000000"],["111460.76000000","0.00000000"],["111460.55000000","0.08508000"],["111459.86000000","0.00000000"],["111459.81000000","0.00000000"],["111459.59000000","0.13444000"],["111459.45000000","0.00000000"],["111459.25000000","0.00000000"],["111459.09000000","0.00000000"],["111459.08000000","0.00000000"],["111458.03000000","0.00000000"],["111457.46000000","0.00009000"],["111456.78000000","0.00000000"],["111456.43000000","0.00012000"],["111455.81000000","0.00000000"],["111455.40000000","0.00000000"],["111455.33000000","0.00000000"],["111454.98000000","0.00000000"],["111454.92000000","0.00000000"],["111454.87000000","0.00000000"],["111454.73000000","0.00000000"],["111454.59000000","0.00000000"],["111454.19000000","0.00000000"],["111453.85000000","0.04426000"],["111453.84000000","0.00000000"],["111453.78000000","0.00000000"],["111452.66000000","0.18911000"],["111452.39000000","0.00000000"],["111452.07000000","0.00000000"],["111451.29000000","0.00000000"],["111450.98000000","0.00000000"],["111450.94000000","0.00000000"],["111450.78000000","0.00000000"],["111450.51000000","0.00000000"],["111450.16000000","0.00000000"],["111450.15000000","0.00000000"],["111448.77000000","0.04928000"],["111448.47000000","0.00000000"],["111448.10000000","0.00024000"],["111447.66000000","0.00000000"],["111446.48000000","0.00000000"],["111445.88000000","0.00000000"],["111444.26000000","0.00000000"],["111444.16000000","0.00000000"],["111443.52000000","0.00000000"],["111443.18000000","0.00408000"],["111442.96000000","0.00000000"],["111442.87000000","0.00000000"],["111442.63000000","0.00931000"],["111442.23000000","0.08995000"],["111442.22000000","0.06587000"],["111442.02000000","0.00000000"],["111441.31000000","0.00000000"],["111441.09000000","0.00000000"],["111440.11000000","0.00000000"],["111438.70000000","0.00000000"],["111436.09000000","0.00000000"],["111435.79000000","0.00000000"],["111434.69000000","0.00000000"],["111434.33000000","0.00000000"],["111433.16000000","0.00007000"],["111432.75000000","0.00000000"],["111432.45000000","0.00000000"],["111432.20000000","0.02219000"],["111431.97000000","0.13047000"],["111430.01000000","0.04206000"],["111427.56000000","0.00413000"],["111427.45000000","0.00000000"],["111425.66000000","0.00661000"],["111425.57000000","0.00631000"],["111425.51000000","0.13434000"],["111424.97000000","0.00448000"],["111422.21000000","0.00090000"],["111421.27000000","0.06279000"],["111421.26000000","0.07200000"],["111420.92000000","0.00000000"],["111420.91000000","0.00000000"],["111415.84000000","0.00006000"],["111414.01000000","0.08995000"],["111413.28000000","0.05170000"],["111412.41000000","0.00000000"],["111410.47000000","0.00164000"],["111410.46000000","0.00000000"],["111410.45000000","0.53995000"],["111410.34000000","0.00218000"],["111410.26000000","0.00000000"],["111409.42000000","0.00000000"],["111409.21000000","0.00000000"],["111409.01000000","0.00224000"],["111408.82000000","0.01800000"],["111408.74000000","0.00624000"],["111408.56000000","0.00000000"],["111408.55000000","0.00000000"],["111408.26000000","0.08995000"],["111407.06000000","0.00000000"],["111407.02000000","0.02463000"],["111406.22000000","0.00000000"],["111404.41000000","0.00223000"],["111403.74000000","0.04015000"],["111403.12000000","0.00112000"],["111402.79000000","0.00000000"],["111402.33000000","0.00000000"],["111401.86000000","0.09759000"],["111401.65000000","0.00000000"],["111400.54000000","0.00000000"],["111399.21000000","0.00000000"],["111399.16000000","0.00000000"],["111398.70000000","0.34964000"],["111397.91000000","0.00000000"],["111397.04000000","0.00006000"],["111396.68000000","0.00000000"],["111396.06000000","0.13444000"],["111395.62000000","0.00000000"],["111395.04000000","0.22384000"],["111394.89000000","0.00196000"],["111394.88000000","0.00000000"],["111393.78000000","0.00000000"],["111392.97000000","0.00000000"],["111392.62000000","0.00000000"],["111392.55000000","0.00000000"],["111392.06000000","0.24709000"],["111389.08000000","0.00000000"],["111388.41000000","0.00000000"],["111388.40000000","0.00000000"],["111388.19000000","0.00000000"],["111387.52000000","0.00000000"],["111387.51000000","0.00000000"],["111387.47000000","0.00000000"],["111387.44000000","0.00000000"],["111387.06000000","0.00000000"],["111386.73000000","0.00000000"],["111386.54000000","0.00000000"],["111386.05000000","0.00000000"],["111384.76000000","0.00000000"],["111384.69000000","0.00000000"],["111383.46000000","0.00000000"],["111382.58000000","0.00000000"],["111382.46000000","0.00000000"],["111382.14000000","0.07807000"],["111382.12000000","0.00000000"],["111379.85000000","0.00000000"],["111378.47000000","0.00000000"],["111376.77000000","0.20814000"],["111376.52000000","0.00000000"],["111375.45000000","0.00000000"],["111375.04000000","0.00013000"],["111371.90000000","0.00000000"],["111361.68000000","0.00000000"],["111361.60000000","0.08995000"],["111361.12000000","0.08819000"],["111360.93000000","0.00000000"],["111358.09000000","0.00000000"],["111357.58000000","0.00000000"],["111349.69000000","0.00099000"],["111348.81000000","0.06000000"],["111344.19000000","0.00000000"],["111332.44000000","0.00000000"],["111332.13000000","0.00000000"],["111327.96000000","0.00000000"],["111321.89000000","0.08695000"],["111310.96000000","0.00574000"],["111309.67000000","0.00000000"],["111300.41000000","0.99714000"],["111299.86000000","0.00066000"],["111299.85000000","0.00000000"],["111299.54000000","0.09480000"],["111292.09000000","0.00000000"],["111291.23000000","0.00000000"],["111280.10000000","0.00250000"],["111278.31000000","0.00000000"],["111276.37000000","0.00000000"],["111273.07000000","0.00000000"],["111265.33000000","0.02600000"],["111257.83000000","0.00000000"],["111256.37000000","0.00000000"],["111254.71000000","0.00000000"],["111231.67000000","0.00000000"],["111182.00000000","0.00000000"],["111176.43000000","0.00000000"],["111170.86000000","0.00000000"],["111165.29000000","0.00000000"],["111162.34000000","0.00000000"],["111155.31000000","0.03677000"],["111153.55000000","0.00000000"],["111142.40000000","0.00000000"],["111136.11000000","0.00000000"],["111132.23000000","0.03677000"],["111119.25000000","0.00000000"],["111110.74000000","0.03677000"],["111110.63000000","0.03677000"],["111095.50000000","0.00006000"],["111085.88000000","0.00080000"],["111084.39000000","0.00200000"],["111062.13000000","0.00000000"],["111047.52000000","0.00000000"],["110992.75000000","0.00000000"],["110987.56000000","0.00000000"],["110987.48000000","0.00000000"],["110980.30000000","0.00000000"],["110849.35000000","0.00000000"],["110539.34000000","0.00000000"],["110457.19000000","0.00252000"],["110000.00000000","26.34232000"],["109833.05000000","0.00100000"],["109810.38000000","0.00000000"],["100354.00000000","0.00010000"],["100352.00000000","0.00065000"],["100334.00000000","0.00000000"],["100333.00000000","0.05438000"],["98104.70000000","0.00000000"],["89204.52000000","0.00022000"],["89202.40000000","0.00000000"],["89186.10000000","0.00000000"],["78052.75000000","0.00000000"],["78048.27000000","0.00000000"],["78043.79000000","0.00000000"],["78039.31000000","0.00000000"]],"a":[["111482.63000000","0.00000000"],["111482.64000000","0.00000000"],["111482.65000000","0.00000000"],["111482.71000000","0.00000000"],["111482.80000000","0.00000000"],["111482.81000000","0.00000000"],["111482.95000000","0.00000000"],["111483.74000000","0.00000000"],["111483.75000000","0.00000000"],["111483.76000000","0.00000000"],["111484.65000000","0.00000000"],["111484.72000000","0.00000000"],["111484.73000000","0.00000000"],["111486.53000000","0.00000000"],["111486.54000000","0.00000000"],["111487.24000000","0.00000000"],["111487.64000000","0.00000000"],["111487.85000000","0.00000000"],["111487.86000000","0.00000000"],["111488.08000000","0.00000000"],["111488.09000000","0.00000000"],["111488.75000000","0.00000000"],["111488.76000000","0.00000000"],["111488.77000000","0.00000000"],["111489.12000000","0.00000000"],["111490.99000000","0.00000000"],["111491.00000000","0.00000000"],["111491.05000000","0.00000000"],["111491.06000000","0.00000000"],["111491.07000000","0.00000000"],["111491.20000000","0.00000000"],["111491.21000000","0.00000000"],["111491.22000000","0.00000000"],["111491.35000000","0.00000000"],["111491.36000000","0.00000000"],["111492.10000000","0.00000000"],["111492.11000000","0.00000000"],["111492.17000000","0.00000000"],["111492.18000000","0.00000000"],["111492.43000000","0.00000000"],["111492.61000000","0.00000000"],["111493.93000000","0.00000000"],["111494.68000000","0.00000000"],["111494.70000000","0.00000000"],["111495.13000000","0.00000000"],["111495.14000000","0.00000000"],["111495.15000000","0.00000000"],["111495.54000000","0.00000000"],["111495.76000000","0.00000000"],["111495.90000000","0.00000000"],["111495.93000000","0.00000000"],["111496.10000000","0.00000000"],["111496.14000000","0.00000000"],["111497.54000000","0.00000000"],["111497.55000000","0.00000000"],["111497.67000000","0.00000000"],["111497.95000000","0.00000000"],["111498.05000000","0.00000000"],["111499.06000000","0.00000000"],["111499.50000000","0.00000000"],["111499.64000000","0.00000000"],["111499.96000000","0.00000000"],["111500.00000000","0.00000000"],["111500.24000000","0.00000000"],["111501.19000000","0.00000000"],["111501.20000000","0.00000000"],["111501.27000000","0.00000000"],["111501.28000000","0.00000000"],["111501.40000000","0.00000000"],["111501.58000000","0.00000000"],["111501.61000000","0.00000000"],["111501.70000000","0.00000000"],["111501.71000000","0.00000000"],["111501.72000000","0.00000000"],["111501.74000000","0.00000000"],["111501.75000000","0.00000000"],["111501.88000000","0.00000000"],["111501.97000000","0.00000000"],["111501.98000000","0.00000000"],["111502.18000000","0.00000000"],["111502.40000000","0.00000000"],["111502.68000000","0.00000000"],["111502.70000000","0.00000000"],["111502.93000000","0.00000000"],["111502.94000000","0.00000000"],["111502.95000000","0.00000000"],["111502.97000000","0.00000000"],["111502.98000000","0.00000000"],["111503.01000000","0.00000000"],["111503.02000000","0.00000000"],["111503.03000000","0.00000000"],["111503.20000000","0.00000000"],["111503.28000000","0.00000000"],["111503.31000000","0.00000000"],["111503.36000000","0.00000000"],["111503.43000000","0.00000000"],["111503.44000000","0.00000000"],["111503.50000000","0.00000000"],["111503.52000000","0.00000000"],["111503.57000000","0.00000000"],["111503.67000000","0.00000000"],["111503.69000000","0.00000000"],["111503.72000000","0.00000000"],["111503.84000000","0.00000000"],["111504.08000000","0.00000000"],["111504.15000000","0.00000000"],["111504.18000000","0.00000000"],["111504.19000000","0.00000000"],["111504.20000000","0.00000000"],["111504.47000000","0.00000000"],["111504.48000000","0.00000000"],["111504.52000000","0.00000000"],["111504.75000000","0.00000000"],["111504.82000000","0.00000000"],["111504.93000000","0.00000000"],["111504.98000000","0.00000000"],["111504.99000000","0.00000000"],["111505.30000000","0.00000000"],["111505.33000000","0.00000000"],["111505.42000000","0.00000000"],["111505.44000000","0.00000000"],["111505.49000000","0.00000000"],["111505.54000000","0.00000000"],["111505.55000000","0.00000000"],["111505.63000000","0.00000000"],["111505.65000000","0.00094000"],["111505.66000000","0.00045000"],["111505.67000000","0.00020000"],["111505.71000000","0.00010000"],["111505.80000000","0.00000000"],["111505.86000000","0.00000000"],["111506.82000000","0.00000000"],["111506.83000000","0.00000000"],["111506.95000000","0.00000000"],["111507.39000000","0.00000000"],["111507.41000000","0.00000000"],["111507.42000000","0.00000000"],["111507.43000000","0.00000000"],["111507.44000000","0.00000000"],["111507.76000000","0.00000000"],["111507.77000000","0.00000000"],["111507.78000000","0.00000000"],["111507.79000000","0.00000000"],["111508.04000000","0.00005000"],["111508.10000000","0.00005000"],["111508.62000000","0.00000000"],["111508.64000000","0.00000000"],["111508.65000000","0.00000000"],["111508.66000000","0.00000000"],["111508.70000000","0.00000000"],["111508.71000000","0.00000000"],["111508.75000000","0.00000000"],["111508.76000000","0.00000000"],["111508.97000000","0.00000000"],["111509.02000000","0.00000000"],["111509.03000000","0.00000000"],["111509.05000000","0.00000000"],["111509.20000000","0.00010000"],["111509.51000000","0.00000000"],["111509.52000000","0.00000000"],["111509.53000000","0.00000000"],["111509.64000000","0.00000000"],["111509.68000000","0.00000000"],["111509.69000000","0.00000000"],["111509.77000000","0.00000000"],["111509.78000000","0.00000000"],["111509.88000000","0.00005000"],["111510.23000000","0.00000000"],["111510.50000000","0.00000000"],["111510.83000000","0.00010000"],["111510.89000000","0.00000000"],["111510.90000000","0.00000000"],["111510.92000000","0.00000000"],["111510.93000000","0.00000000"],["111510.96000000","0.00010000"],["111511.03000000","0.00000000"],["111511.07000000","0.00325000"],["111511.08000000","0.00020000"],["111511.31000000","0.00000000"],["111511.41000000","0.00000000"],["111511.43000000","0.00000000"],["111511.45000000","0.00000000"],["111511.65000000","0.00000000"],["111511.99000000","0.00000000"],["111512.01000000","0.00000000"],["111512.02000000","0.00000000"],["111512.06000000","0.00000000"],["111512.39000000","0.00000000"],["111512.43000000","0.00000000"],["111512.46000000","0.00010000"],["111512.47000000","0.05809000"],["111512.48000000","0.00010000"],["111512.69000000","0.00000000"],["111512.70000000","0.00005000"],["111512.71000000","0.00000000"],["111512.77000000","0.00000000"],["111512.81000000","0.00000000"],["111513.08000000","0.00000000"],["111513.09000000","0.00000000"],["111513.20000000","0.00000000"],["111513.35000000","0.00000000"],["111513.39000000","0.00000000"],["111513.63000000","0.00000000"],["111513.64000000","0.00000000"],["111514.08000000","0.00160000"],["111514.14000000","0.00000000"],["111514.17000000","0.00000000"],["111514.33000000","0.00000000"],["111515.20000000","0.00000000"],["111515.21000000","0.00000000"],["111515.22000000","0.00000000"],["111515.23000000","0.00000000"],["111515.24000000","0.00000000"],["111515.30000000","0.00000000"],["111515.39000000","0.00000000"],["111516.01000000","0.00000000"],["111516.31000000","0.00000000"],["111516.32000000","0.00000000"],["111516.33000000","0.00000000"],["111516.58000000","0.00000000"],["111516.59000000","0.00000000"],["111516.62000000","0.00000000"],["111516.63000000","0.00010000"],["111516.64000000","0.14010000"],["111516.71000000","0.00000000"],["111517.13000000","0.00000000"],["111517.17000000","0.00000000"],["111517.21000000","0.00000000"],["111517.22000000","0.00329000"],["111517.33000000","0.00000000"],["111517.36000000","0.00000000"],["111517.37000000","0.00000000"],["111517.42000000","0.00010000"],["111517.43000000","0.10731000"],["111517.54000000","0.00000000"],["111517.55000000","0.00000000"],["111517.56000000","0.00000000"],["111517.57000000","0.00000000"],["111517.58000000","0.00000000"],["111517.59000000","0.00010000"],["111517.60000000","0.02696000"],["111517.67000000","0.00000000"],["111517.83000000","0.00000000"],["111519.12000000","0.00005000"],["111519.13000000","0.19613000"],["111519.14000000","0.16005000"],["111519.43000000","0.00000000"],["111519.44000000","0.00000000"],["111519.46000000","0.00000000"],["111519.58000000","0.04481000"],["111519.66000000","0.00161000"],["111519.74000000","0.00000000"],["111519.76000000","0.00000000"],["111519.78000000","0.00000000"],["111519.82000000","0.00000000"],["111519.89000000","0.03964000"],["111519.95000000","0.00000000"],["111520.00000000","0.00210000"],["111520.23000000","0.30257000"],["111520.24000000","0.32005000"],["111520.32000000","0.00000000"],["111520.42000000","0.00000000"],["111521.01000000","0.04105000"],["111521.35000000","0.00000000"],["111521.36000000","0.00000000"],["111521.96000000","0.00000000"],["111521.97000000","0.00000000"],["111521.98000000","0.00000000"],["111522.00000000","0.00205000"],["111522.10000000","0.00000000"],["111522.13000000","0.00000000"],["111522.21000000","0.00000000"],["111522.35000000","0.00000000"],["111522.38000000","0.00150000"],["111522.48000000","0.00005000"],["111522.67000000","0.00007000"],["111522.74000000","0.00000000"],["111522.78000000","0.00000000"],["111522.79000000","0.00000000"],["111523.01000000","0.00000000"],["111523.36000000","0.00000000"],["111523.67000000","0.00000000"],["111523.68000000","0.00000000"],["111523.82000000","0.00000000"],["111523.95000000","0.00000000"],["111523.96000000","0.00000000"],["111524.06000000","0.00000000"],["111524.20000000","0.00000000"],["111524.24000000","0.01772000"],["111524.27000000","0.01164000"],["111524.60000000","0.00000000"],["111525.02000000","0.00000000"],["111525.09000000","0.00000000"],["111525.14000000","0.00000000"],["111525.32000000","0.00300000"],["111525.65000000","0.00000000"],["111525.95000000","0.00000000"],["111526.24000000","0.00010000"],["111526.25000000","0.00000000"],["111526.35000000","0.13435000"],["111526.36000000","0.00000000"],["111526.37000000","0.00000000"],["111526.38000000","0.45000000"],["111526.40000000","0.00000000"],["111527.22000000","0.00000000"],["111527.38000000","0.00000000"],["111527.50000000","0.00000000"],["111527.54000000","0.00000000"],["111527.79000000","0.00005000"],["111527.95000000","0.11195000"],["111527.99000000","0.00448000"],["111528.62000000","0.00000000"],["111528.63000000","0.00000000"],["111528.65000000","0.00005000"],["111528.82000000","0.00000000"],["111529.12000000","0.00000000"],["111529.13000000","0.30000000"],["111529.14000000","0.25382000"],["111529.20000000","0.00000000"],["111529.94000000","0.00000000"],["111530.07000000","0.00000000"],["111531.24000000","0.00012000"],["111531.32000000","0.04481000"],["111531.33000000","0.00000000"],["111531.64000000","0.00000000"],["111531.67000000","0.08507000"],["111531.87000000","0.00000000"],["111532.15000000","0.04800000"],["111532.51000000","0.03916000"],["111532.66000000","0.00000000"],["111533.00000000","0.00000000"],["111533.62000000","0.00000000"],["111533.63000000","0.00000000"],["111533.64000000","0.66163000"],["111533.65000000","0.00000000"],["111533.85000000","0.06646000"],["111534.62000000","0.01164000"],["111534.72000000","0.35856000"],["111534.81000000","0.16083000"],["111535.12000000","0.00000000"],["111536.00000000","0.04200000"],["111536.38000000","0.04482000"],["111536.47000000","0.00300000"],["111536.75000000","0.00000000"],["111536.88000000","0.00000000"],["111537.54000000","0.00271000"],["111537.72000000","0.04800000"],["111538.17000000","0.04800000"],["111538.47000000","0.13434000"],["111538.54000000","0.13430000"],["111538.72000000","0.00000000"],["111539.13000000","0.04800000"],["111539.76000000","0.13430000"],["111540.18000000","0.00000000"],["111540.47000000","0.00000000"],["111540.88000000","0.17912000"],["111542.31000000","0.01826000"],["111542.40000000","0.08507000"],["111542.65000000","0.17012000"],["111542.66000000","0.00179000"],["111542.69000000","0.15945000"],["111542.73000000","0.00179000"],["111543.23000000","0.18895000"],["111543.39000000","1.20469000"],["111543.94000000","0.00000000"],["111543.95000000","0.00000000"],["111544.60000000","0.00005000"],["111545.38000000","0.00442000"],["111545.49000000","0.00000000"],["111545.51000000","0.00000000"],["111545.56000000","0.00000000"],["111546.37000000","0.00000000"],["111547.12000000","0.00000000"],["111548.02000000","0.02126000"],["111549.06000000","0.00005000"],["111550.25000000","0.22384000"],["111550.38000000","0.00000000"],["111550.76000000","0.00000000"],["111551.47000000","0.00000000"],["111553.46000000","0.00000000"],["111553.52000000","0.00005000"],["111553.66000000","0.02128000"],["111553.99000000","0.02398000"],["111555.26000000","0.00000000"],["111555.95000000","0.00000000"],["111557.02000000","0.00010000"],["111557.18000000","0.00000000"],["111557.52000000","0.00000000"],["111557.98000000","0.00005000"],["111558.20000000","0.00000000"],["111558.22000000","0.00000000"],["111558.77000000","0.00000000"],["111559.27000000","0.00000000"],["111559.54000000","0.08505000"],["111560.94000000","0.00000000"],["111561.54000000","0.08507000"],["111561.76000000","0.00000000"],["111562.44000000","0.00005000"],["111562.76000000","1.25396000"],["111563.21000000","0.00000000"],["111563.69000000","0.00000000"],["111563.99000000","0.00000000"],["111566.66000000","0.00000000"],["111566.73000000","0.26588000"],["111566.90000000","0.00000000"],["111567.71000000","0.00000000"],["111567.92000000","0.00000000"],["111567.93000000","0.00000000"],["111568.25000000","0.21938000"],["111569.20000000","0.00000000"],["111569.28000000","0.00628000"],["111569.37000000","0.00000000"],["111569.40000000","0.00000000"],["111569.82000000","0.02126000"],["111571.22000000","0.00000000"],["111571.87000000","0.00616000"],["111571.95000000","0.00000000"],["111572.63000000","0.00000000"],["111572.80000000","0.00448000"],["111573.17000000","0.00000000"],["111573.27000000","0.35816000"],["111573.37000000","1.25396000"],["111573.53000000","0.00000000"],["111574.76000000","0.00658000"],["111575.25000000","0.00000000"],["111576.65000000","0.00000000"],["111576.66000000","0.00000000"],["111576.77000000","0.00000000"],["111576.80000000","0.00000000"],["111576.81000000","0.00000000"],["111576.87000000","0.00000000"],["111576.96000000","0.00000000"],["111577.27000000","0.00000000"],["111578.03000000","0.00000000"],["111578.30000000","0.02219000"],["111579.28000000","0.05427000"],["111579.96000000","0.35816000"],["111580.06000000","1.25396000"],["111580.85000000","0.00000000"],["111580.87000000","0.00618000"],["111581.63000000","0.00000000"],["111581.99000000","0.00000000"],["111582.09000000","0.00000000"],["111582.78000000","0.00000000"],["111582.79000000","0.06839000"],["111583.83000000","0.00000000"],["111585.99000000","0.00000000"],["111586.29000000","0.01800000"],["111586.75000000","1.25396000"],["111586.84000000","0.07413000"],["111587.00000000","0.00000000"],["111587.95000000","0.00224000"],["111588.20000000","0.00000000"],["111589.97000000","0.00000000"],["111589.99000000","0.00000000"],["111590.73000000","0.00000000"],["111591.66000000","0.00112000"],["111591.98000000","0.00000000"],["111592.75000000","0.00005000"],["111593.44000000","1.25396000"],["111597.67000000","0.03961000"],["111597.99000000","0.00000000"],["111598.88000000","0.00000000"],["111599.26000000","0.00000000"],["111599.47000000","0.00000000"],["111600.00000000","0.06852000"],["111600.13000000","1.25396000"],["111600.17000000","0.00413000"],["111600.92000000","0.13434000"],["111601.22000000","0.06240000"],["111603.41000000","0.06024000"],["111604.40000000","0.04800000"],["111604.80000000","0.04800000"],["111605.53000000","0.04800000"],["111606.55000000","0.27688000"],["111606.67000000","0.04800000"],["111608.83000000","0.02413000"],["111608.94000000","0.00000000"],["111609.57000000","0.00000000"],["111609.58000000","0.00000000"],["111609.99000000","0.00000000"],["111610.84000000","0.00000000"],["111611.33000000","0.00000000"],["111611.99000000","0.00224000"],["111612.16000000","0.00000000"],["111612.27000000","0.00224000"],["111612.29000000","0.00000000"],["111612.85000000","0.00000000"],["111612.93000000","0.04800000"],["111613.74000000","0.00000000"],["111614.74000000","0.00000000"],["111615.38000000","0.00000000"],["111615.59000000","0.00000000"],["111616.01000000","0.02137000"],["111616.45000000","0.45000000"],["111618.46000000","0.00010000"],["111618.68000000","0.00000000"],["111620.07000000","0.07200000"],["111621.29000000","0.00000000"],["111621.79000000","0.02398000"],["111621.80000000","0.00196000"],["111622.97000000","0.99467000"],["111624.17000000","0.00010000"],["111625.09000000","0.00000000"],["111626.38000000","0.09452000"],["111626.43000000","0.00000000"],["111629.00000000","0.04800000"],["111629.73000000","0.17912000"],["111633.97000000","0.00000000"],["111634.41000000","0.13444000"],["111634.55000000","0.04889000"],["111635.98000000","0.00000000"],["111636.71000000","0.08494000"],["111637.64000000","0.00000000"],["111638.32000000","0.00000000"],["111641.60000000","0.00000000"],["111641.96000000","0.12565000"],["111641.97000000","0.00000000"],["111641.98000000","0.00000000"],["111643.22000000","0.00000000"],["111643.34000000","0.00008000"],["111644.38000000","0.54364000"],["111644.82000000","0.00000000"],["111644.86000000","0.00000000"],["111645.08000000","0.00000000"],["111648.87000000","0.07807000"],["111649.06000000","0.08768000"],["111649.23000000","0.00000000"],["111651.62000000","0.00000000"],["111651.93000000","0.00000000"],["111652.00000000","0.00260000"],["111652.80000000","0.09759000"],["111653.23000000","0.00000000"],["111654.14000000","0.00000000"],["111654.24000000","0.00000000"],["111657.99000000","0.00000000"],["111660.63000000","0.17314000"],["111664.59000000","0.00000000"],["111665.77000000","0.00000000"],["111667.09000000","0.00000000"],["111667.36000000","0.02692000"],["111667.74000000","0.00537000"],["111672.17000000","0.01236000"],["111673.68000000","0.32204000"],["111675.06000000","0.00000000"],["111675.46000000","0.44680000"],["111676.77000000","0.00000000"],["111678.13000000","0.00000000"],["111679.44000000","0.00000000"],["111684.56000000","0.00000000"],["111688.63000000","0.34629000"],["111690.55000000","0.04947000"],["111693.45000000","0.02398000"],["111698.09000000","0.00000000"],["111699.90000000","0.00089000"],["111700.57000000","0.00000000"],["111701.28000000","0.00000000"],["111701.98000000","0.00000000"],["111702.90000000","0.00000000"],["111703.20000000","0.00000000"],["111705.36000000","0.00000000"],["111705.69000000","0.00000000"],["111705.99000000","0.00931000"],["111707.47000000","0.00000000"],["111708.48000000","1.47496000"],["111708.71000000","0.00000000"],["111710.66000000","0.00000000"],["111711.92000000","0.00000000"],["111712.55000000","0.02421000"],["111714.67000000","0.02421000"],["111716.24000000","0.02421000"],["111717.16000000","0.00000000"],["111718.33000000","0.08994000"],["111719.04000000","0.02421000"],["111719.53000000","0.00000000"],["111721.21000000","0.00000000"],["111721.22000000","0.00000000"],["111721.23000000","0.00000000"],["111722.36000000","0.17989000"],["111722.61000000","0.02421000"],["111723.98000000","0.00089000"],["111723.99000000","0.00089000"],["111725.94000000","0.02421000"],["111726.13000000","0.02600000"],["111726.50000000","0.02421000"],["111728.33000000","0.02421000"],["111729.04000000","0.08994000"],["111731.62000000","0.08994000"],["111733.43000000","0.08994000"],["111735.58000000","0.00000000"],["111736.64000000","0.00000000"],["111739.58000000","0.08995000"],["111747.02000000","0.00000000"],["111755.88000000","0.08994000"],["111756.02000000","0.08994000"],["111757.36000000","0.08995000"],["111758.51000000","0.08994000"],["111759.72000000","0.08995000"],["111760.26000000","0.08995000"],["111778.02000000","0.01703000"],["111778.74000000","0.01703000"],["111800.24000000","0.00000000"],["111800.42000000","0.00000000"],["111800.72000000","0.00000000"],["111803.70000000","0.00000000"],["111805.34000000","0.00000000"],["111809.12000000","0.00010000"],["111810.83000000","0.00000000"],["111811.95000000","0.00000000"],["111812.06000000","0.00010000"],["111813.60000000","0.00000000"],["111813.74000000","0.00000000"],["111814.03000000","0.00000000"],["111814.31000000","0.00000000"],["111814.37000000","0.00000000"],["111814.60000000","0.00000000"],["111814.83000000","0.00000000"],["111814.89000000","0.00000000"],["111815.47000000","0.00000000"],["111815.49000000","0.00000000"],["111815.61000000","0.00000000"],["111816.11000000","0.00000000"],["111816.18000000","0.00000000"],["111816.32000000","0.00000000"],["111816.94000000","0.00000000"],["111817.63000000","0.00000000"],["111823.20000000","0.00000000"],["111826.85000000","0.00024000"],["111828.77000000","0.00000000"],["111834.03000000","0.00000000"],["111838.03000000","0.00000000"],["111841.25000000","0.05896000"],["111842.13000000","0.05896000"],["111843.62000000","0.05896000"],["111844.09000000","0.05896000"],["111844.87000000","0.05896000"],["111845.27000000","0.05896000"],["111845.99000000","0.05896000"],["111846.64000000","0.05896000"],["111848.03000000","0.05896000"],["111849.16000000","0.05902000"],["111849.96000000","0.02600000"],["111850.33000000","0.03677000"],["111851.07000000","0.05896000"],["111853.39000000","0.02600000"],["111853.54000000","0.05896000"],["111853.71000000","0.05896000"],["111853.88000000","0.05896000"],["111854.20000000","0.03677000"],["111855.79000000","0.05896000"],["111855.96000000","0.05896000"],["111858.15000000","0.03677000"],["111860.12000000","0.00000000"],["111883.33000000","0.00005000"],["111898.32000000","0.02398000"],["111899.16000000","0.02398000"],["111906.12000000","0.00005000"],["111906.21000000","0.00000000"],["111915.97000000","0.00000000"],["111930.68000000","0.00000000"],["111943.54000000","0.00000000"],["111954.57000000","0.00218000"],["111956.06000000","0.00250000"],["111967.26000000","0.00000000"],["112004.86000000","0.03677000"],["112006.26000000","0.03677000"],["112013.40000000","0.03677000"],["112031.04000000","0.02398000"],["112089.17000000","0.00000000"],["112170.12000000","0.00200000"],["112181.34000000","0.00000000"],["112578.54000000","0.00234000"],["113154.87000000","0.00000000"],["113175.56000000","0.00029000"],["116259.06000000","0.00000000"]]}
[2025-10-12T11:04:42.183Z] {"e":"depthUpdate","E":1760267082014,"s":"BTCUSDT","U":77965278010,"u":77965279083,"b":[["111512.46000000","6.62489000"],["111512.45000000","0.00000000"],["111512.40000000","0.00000000"],["111512.39000000","0.00020000"],["111512.38000000","0.15442000"],["111512.37000000","0.00000000"],["111511.63000000","0.00000000"],["111511.62000000","0.00010000"],["111511.61000000","0.08340000"],["111511.60000000","0.00000000"],["111511.59000000","0.00000000"],["111511.36000000","0.00000000"],["111511.35000000","0.00010000"],["111511.34000000","0.03971000"],["111511.22000000","0.00000000"],["111511.06000000","0.00000000"],["111510.70000000","0.00000000"],["111510.69000000","0.00000000"],["111510.27000000","0.00005000"],["111509.51000000","0.00000000"],["111509.45000000","0.00005000"],["111508.41000000","0.00000000"],["111508.09000000","0.00000000"],["111508.03000000","0.00000000"],["111507.42000000","0.00000000"],["111505.70000000","0.00000000"],["111505.67000000","0.00000000"],["111505.66000000","0.00000000"],["111505.65000000","0.00010000"],["111505.64000000","0.10141000"],["111505.57000000","0.00000000"],["111505.42000000","0.00000000"],["111505.31000000","0.00000000"],["111505.30000000","0.00000000"],["111504.75000000","0.00005000"],["111503.01000000","0.00000000"],["111502.95000000","0.00000000"],["111502.94000000","0.13780000"],["111502.93000000","0.35816000"],["111502.92000000","0.01776000"],["111502.69000000","0.00000000"],["111501.80000000","0.00005000"],["111501.69000000","0.04005000"],["111501.07000000","0.00100000"],["111500.57000000","0.00000000"],["111499.69000000","0.04561000"],["111499.67000000","0.00000000"],["111498.79000000","0.00005000"],["111498.53000000","0.00010000"],["111498.52000000","0.11195000"],["111497.96000000","0.08844000"],["111497.78000000","0.00000000"],["111497.12000000","0.00007000"],["111496.85000000","0.00000000"],["111495.79000000","0.00005000"],["111495.50000000","0.00415000"],["111493.80000000","0.00007000"],["111492.95000000","0.05760000"],["111491.84000000","0.00305000"],["111491.83000000","0.00000000"],["111491.80000000","0.06010000"],["111491.77000000","0.45109000"],["111491.74000000","0.00330000"],["111491.71000000","0.04800000"],["111491.70000000","0.00000000"],["111491.25000000","0.00000000"],["111491.20000000","0.35816000"],["111491.16000000","0.00069000"],["111491.06000000","0.00448000"],["111491.05000000","0.03998000"],["111490.73000000","0.07920000"],["111490.71000000","0.08507000"],["111490.46000000","0.06646000"],["111490.40000000","0.00000000"],["111490.14000000","0.01801000"],["111489.49000000","0.10080000"],["111488.75000000","0.03998000"],["111488.42000000","0.00000000"],["111487.89000000","0.15000000"],["111487.64000000","0.04481000"],["111487.38000000","0.00000000"],["111486.99000000","0.00000000"],["111486.65000000","0.00896000"],["111486.23000000","0.06240000"],["111486.11000000","0.07200000"],["111485.48000000","0.00000000"],["111484.16000000","0.00000000"],["111484.14000000","0.01388000"],["111484.09000000","0.00000000"],["111483.78000000","0.00000000"],["111483.56000000","0.00005000"],["111483.33000000","0.04358000"],["111479.91000000","0.00000000"],["111479.00000000","0.00300000"],["111477.08000000","0.00000000"],["111475.40000000","0.00000000"],["111472.64000000","0.31916000"],["111470.90000000","0.00000000"],["111469.47000000","0.00000000"],["111469.15000000","0.86853000"],["111468.15000000","0.22384000"],["111467.30000000","0.00000000"],["111467.28000000","1.22971000"],["111465.83000000","0.00000000"],["111464.09000000","0.00000000"],["111463.93000000","0.30258000"],["111462.53000000","0.00000000"],["111453.85000000","0.00000000"],["111451.15000000","0.00000000"],["111436.83000000","0.02692000"],["111436.45000000","0.04426000"],["111434.74000000","0.00448000"],["111432.83000000","0.00223000"],["111418.69000000","0.00000000"],["111411.92000000","0.00067000"],["111409.01000000","0.00000000"],["111408.57000000","0.00000000"],["111407.10000000","0.00000000"],["111406.63000000","0.00000000"],["111406.19000000","0.00000000"],["111406.05000000","0.00000000"],["111404.40000000","0.00000000"],["111402.78000000","0.00000000"],["111402.31000000","0.00000000"],["111397.64000000","0.22384000"],["111396.41000000","0.00000000"],["111394.76000000","0.00000000"],["111393.35000000","0.00000000"],["111392.06000000","0.00000000"],["111389.64000000","0.00022000"],["111388.54000000","0.00000000"],["111385.26000000","0.00000000"],["111363.43000000","0.00000000"],["111327.15000000","0.00000000"],["111321.90000000","0.00089000"],["111309.40000000","0.99950000"],["111302.90000000","0.00089000"],["111300.41000000","0.00000000"],["111291.62000000","0.00000000"],["111273.08000000","0.00000000"],["111212.46000000","0.00000000"],["111185.16000000","0.00000000"],["111164.71000000","0.45000000"],["111153.55000000","0.45000000"],["110849.35000000","0.89111000"],["110091.67000000","0.00088000"],["109839.77000000","0.00100000"],["109833.05000000","0.00000000"],["109666.66000000","0.05932000"],["100361.00000000","0.00000000"],["100360.00000000","0.02133000"],["100354.00000000","0.00000000"],["89209.97000000","0.00037000"],["89204.52000000","0.00000000"],["78057.23000000","0.00000000"],["40144.49000000","0.00015000"],["33000.00000000","3.87311000"]],"a":[["111505.65000000","0.00000000"],["111505.66000000","0.00000000"],["111505.67000000","0.00000000"],["111505.71000000","0.00000000"],["111508.04000000","0.00000000"],["111508.10000000","0.00000000"],["111508.42000000","0.00000000"],["111509.20000000","0.00000000"],["111509.88000000","0.00000000"],["111510.83000000","0.00000000"],["111510.89000000","0.00000000"],["111510.96000000","0.00000000"],["111511.06000000","0.00000000"],["111511.07000000","0.00000000"],["111511.08000000","0.00000000"],["111511.36000000","0.00000000"],["111511.47000000","0.00000000"],["111511.54000000","0.00000000"],["111512.46000000","0.00000000"],["111512.47000000","3.91231000"],["111512.48000000","0.00020000"],["111512.49000000","0.00000000"],["111512.55000000","0.00010000"],["111512.60000000","0.00000000"],["111512.70000000","0.00000000"],["111512.80000000","0.00000000"],["111512.90000000","0.00000000"],["111513.00000000","0.00000000"],["111513.02000000","0.00000000"],["111513.10000000","0.00000000"],["111513.13000000","0.00000000"],["111513.21000000","0.00000000"],["111513.29000000","0.00000000"],["111513.94000000","0.00000000"],["111514.08000000","0.00000000"],["111514.09000000","0.00000000"],["111514.11000000","0.00000000"],["111514.26000000","0.00000000"],["111514.27000000","0.00000000"],["111514.28000000","0.00000000"],["111514.40000000","0.00000000"],["111514.67000000","0.00000000"],["111514.76000000","0.00010000"],["111514.77000000","0.02202000"],["111514.78000000","0.03617000"],["111514.79000000","0.00020000"],["111514.88000000","0.00000000"],["111515.11000000","0.00000000"],["111515.12000000","0.00010000"],["111515.13000000","0.03607000"],["111515.14000000","0.00010000"],["111515.15000000","0.00000000"],["111515.81000000","0.00005000"],["111516.10000000","0.00005000"],["111516.25000000","0.00000000"],["111516.26000000","0.00000000"],["111516.27000000","0.00000000"],["111516.62000000","0.00000000"],["111516.63000000","0.00010000"],["111516.64000000","0.14010000"],["111516.65000000","0.00000000"],["111517.04000000","0.00000000"],["111517.22000000","0.00000000"],["111517.42000000","0.00000000"],["111517.43000000","0.00010000"],["111517.54000000","0.00000000"],["111517.56000000","0.00005000"],["111517.59000000","0.00000000"],["111517.60000000","0.00000000"],["111517.61000000","0.00000000"],["111518.49000000","0.00005000"],["111518.50000000","0.04005000"],["111518.65000000","0.00000000"],["111518.66000000","0.03952000"],["111518.67000000","0.00000000"],["111519.12000000","0.00000000"],["111519.13000000","0.24815000"],["111519.14000000","0.16005000"],["111519.15000000","0.00000000"],["111519.57000000","0.00000000"],["111519.58000000","0.04481000"],["111519.66000000","0.00156000"],["111519.88000000","0.00000000"],["111519.89000000","0.00000000"],["111520.00000000","0.00210000"],["111520.22000000","0.00000000"],["111520.23000000","0.00000000"],["111520.24000000","0.32000000"],["111521.01000000","0.00000000"],["111521.33000000","0.06651000"],["111521.54000000","0.00000000"],["111522.38000000","0.00160000"],["111522.67000000","0.00000000"],["111522.70000000","0.00000000"],["111523.37000000","0.00100000"],["111524.00000000","0.00205000"],["111524.24000000","0.01777000"],["111524.27000000","0.01169000"],["111525.32000000","0.00305000"],["111526.00000000","0.00600000"],["111526.35000000","0.23543000"],["111526.36000000","0.15000000"],["111526.97000000","0.09609000"],["111527.99000000","0.00448000"],["111529.06000000","0.15000000"],["111529.08000000","0.48298000"],["111529.09000000","0.35816000"],["111529.10000000","0.00000000"],["111529.12000000","0.00000000"],["111529.13000000","0.00000000"],["111529.14000000","0.00000000"],["111529.20000000","0.00150000"],["111529.35000000","0.01388000"],["111529.49000000","0.00007000"],["111531.03000000","0.04800000"],["111531.75000000","0.00000000"],["111531.92000000","0.39840000"],["111533.26000000","0.07200000"],["111533.62000000","0.00000000"],["111534.52000000","0.07200000"],["111534.60000000","0.00499000"],["111534.72000000","0.35856000"],["111534.81000000","0.00000000"],["111535.12000000","0.00000000"],["111536.00000000","0.00200000"],["111536.38000000","0.00000000"],["111536.97000000","0.00005000"],["111537.70000000","0.04800000"],["111538.00000000","0.00600000"],["111538.17000000","0.07112000"],["111539.91000000","0.00005000"],["111540.88000000","0.00000000"],["111541.60000000","0.00005000"],["111543.39000000","0.00000000"],["111545.93000000","0.00300000"],["111549.29000000","1.22761000"],["111552.31000000","0.16083000"],["111557.79000000","0.00005000"],["111557.98000000","0.00000000"],["111559.31000000","0.00000000"],["111560.66000000","0.00322000"],["111562.26000000","0.00000000"],["111562.44000000","0.00000000"],["111566.73000000","0.26583000"],["111582.58000000","0.00448000"],["111582.79000000","0.00000000"],["111583.88000000","0.06751000"],["111587.95000000","0.00000000"],["111589.10000000","0.69371000"],["111589.63000000","0.00005000"],["111596.94000000","0.04425000"],["111597.66000000","0.00223000"],["111599.00000000","0.00005000"],["111601.21000000","0.04800000"],["111606.74000000","0.04800000"],["111611.99000000","0.00000000"],["111612.27000000","0.00000000"],["111612.85000000","0.04800000"],["111618.68000000","0.00000000"],["111619.99000000","0.00223000"],["111620.07000000","0.00000000"],["111620.61000000","0.01707000"],["111621.30000000","0.00000000"],["111621.78000000","0.00223000"],["111623.62000000","0.02027000"],["111627.92000000","0.00000000"],["111629.00000000","0.00000000"],["111629.73000000","0.00000000"],["111634.55000000","0.00089000"],["111634.59000000","0.00000000"],["111647.98000000","0.04197000"],["111677.88000000","0.13749000"],["111723.98000000","0.00000000"],["111730.83000000","0.00089000"],["111752.01000000","0.00536000"],["111765.89000000","0.00536000"],["111766.35000000","0.02510000"],["111766.68000000","0.02510000"],["111767.34000000","0.02510000"],["111768.17000000","0.02510000"],["111769.31000000","0.02510000"],["111770.34000000","0.02510000"],["111773.24000000","0.02510000"],["111803.59000000","0.00000000"],["111816.03000000","0.00010000"],["111821.60000000","0.00010000"],["112107.56000000","0.02398000"],["112107.57000000","0.02398000"],["112507.19000000","0.00000000"],["112642.59000000","0.00447000"],["113185.16000000","0.00100000"],["116693.06000000","0.00021000"]]}
[2025-10-12T11:04:43.182Z] {"e":"depthUpdate","E":1760267083014,"s":"BTCUSDT","U":77965279084,"u":77965279560,"b":[["111512.46000000","3.09057000"],["111512.45000000","0.06720000"],["111512.44000000","0.00000000"],["111512.43000000","0.00000000"],["111512.40000000","0.00000000"],["111512.39000000","0.00010000"],["111512.38000000","0.00000000"],["111512.30000000","0.00080000"],["111511.89000000","0.00010000"],["111511.88000000","0.04217000"],["111511.62000000","0.00000000"],["111511.61000000","0.00000000"],["111511.34000000","0.03976000"],["111510.29000000","0.00010000"],["111510.28000000","0.04177000"],["111505.65000000","0.00005000"],["111505.64000000","0.10005000"],["111504.46000000","0.00000000"],["111502.95000000","0.00000000"],["111502.94000000","0.03120000"],["111502.93000000","0.00000000"],["111502.80000000","0.00000000"],["111501.69000000","0.04005000"],["111501.40000000","0.00005000"],["111501.07000000","0.00000000"],["111500.89000000","0.00000000"],["111499.19000000","0.16830000"],["111499.18000000","0.00000000"],["111495.79000000","0.00000000"],["111495.50000000","0.00015000"],["111492.55000000","0.00073000"],["111492.52000000","0.00070000"],["111491.78000000","0.55760000"],["111491.71000000","0.04800000"],["111491.23000000","0.00000000"],["111491.06000000","0.00448000"],["111491.05000000","0.00000000"],["111490.73000000","0.07920000"],["111490.46000000","0.00000000"],["111487.89000000","0.00000000"],["111487.87000000","0.00000000"],["111484.14000000","0.00000000"],["111484.07000000","0.01388000"],["111484.03000000","0.00000000"],["111483.78000000","0.00000000"],["111482.63000000","0.00282000"],["111481.52000000","0.00283000"],["111479.43000000","0.15000000"],["111479.01000000","0.00008000"],["111471.57000000","0.00000000"],["111463.93000000","0.00000000"],["111460.61000000","0.30259000"],["111458.88000000","0.04479000"],["111454.98000000","0.00005000"],["111454.50000000","0.00400000"],["111445.55000000","0.00008000"],["111444.17000000","0.00000000"],["111436.45000000","0.00000000"],["111423.07000000","0.04426000"],["111417.53000000","0.00218000"],["111412.10000000","0.00008000"],["111410.72000000","0.00000000"],["111410.34000000","0.00000000"],["111390.48000000","0.15082000"],["111378.65000000","0.00008000"],["111377.28000000","0.00084000"],["111345.19000000","0.00008000"],["111343.84000000","0.00000000"],["111310.39000000","0.00000000"],["111309.40000000","0.99897000"],["111215.00000000","0.34522000"],["111093.06000000","0.00080000"],["111085.88000000","0.00000000"],["110457.19000000","0.00013000"],["109839.77000000","0.00100000"],["106970.40000000","0.00011000"],["105900.00000000","0.07792000"],["102591.46000000","0.00010000"],["100360.00000000","0.02133000"],["89209.97000000","0.00037000"]],"a":[["111512.47000000","4.24826000"],["111512.48000000","0.00020000"],["111513.09000000","0.00005000"],["111513.22000000","0.00010000"],["111513.23000000","0.05281000"],["111513.24000000","0.06676000"],["111513.25000000","0.00020000"],["111513.59000000","0.00005000"],["111514.76000000","0.00000000"],["111514.77000000","0.00010000"],["111514.78000000","0.03597000"],["111514.79000000","0.00010000"],["111515.13000000","0.03607000"],["111515.14000000","0.00010000"],["111515.54000000","0.00010000"],["111515.55000000","0.03592000"],["111516.10000000","0.00000000"],["111516.63000000","0.00000000"],["111516.64000000","0.14005000"],["111517.43000000","0.00005000"],["111518.49000000","0.00000000"],["111518.50000000","0.00000000"],["111518.60000000","0.00000000"],["111518.65000000","0.17609000"],["111518.66000000","0.03957000"],["111519.13000000","0.00000000"],["111519.14000000","0.16005000"],["111519.58000000","0.00000000"],["111520.24000000","0.32000000"],["111521.33000000","0.06651000"],["111521.50000000","0.00005000"],["111521.52000000","0.00000000"],["111521.56000000","0.00000000"],["111521.60000000","0.02691000"],["111522.38000000","0.00160000"],["111523.19000000","0.00000000"],["111523.37000000","0.00000000"],["111524.27000000","0.01169000"],["111525.32000000","0.00300000"],["111525.56000000","0.36132000"],["111525.57000000","0.35816000"],["111526.35000000","0.00000000"],["111526.36000000","0.30000000"],["111529.06000000","0.00000000"],["111529.35000000","0.00000000"],["111529.60000000","0.04000000"],["111532.10000000","0.00000000"],["111533.53000000","0.01388000"],["111533.62000000","1.18254000"],["111533.63000000","1.25396000"],["111533.64000000","0.00000000"],["111535.83000000","0.00896000"],["111543.99000000","0.22384000"],["111544.51000000","0.00000000"],["111545.83000000","0.00000000"],["111545.92000000","0.00008000"],["111550.25000000","0.00000000"],["111553.32000000","0.00005000"],["111553.52000000","0.00000000"],["111557.02000000","0.00010000"],["111557.56000000","0.13444000"],["111557.79000000","0.00000000"],["111559.31000000","0.17912000"],["111572.32000000","0.00889000"],["111577.95000000","0.00000000"],["111578.72000000","0.61665000"],["111579.38000000","0.00008000"],["111583.38000000","0.00005000"],["111590.75000000","0.00000000"],["111595.82000000","0.00100000"],["111595.83000000","0.00100000"],["111605.25000000","0.00005000"],["111611.39000000","0.00000000"],["111612.28000000","0.20449000"],["111612.83000000","0.00008000"],["111618.31000000","0.13444000"],["111618.49000000","0.00000000"],["111618.58000000","0.00000000"],["111618.71000000","0.00000000"],["111618.79000000","0.00000000"],["111618.80000000","0.00000000"],["111619.09000000","0.00000000"],["111619.47000000","0.00000000"],["111622.05000000","0.22384000"],["111634.41000000","0.00000000"],["111644.84000000","0.00000000"],["111646.28000000","0.00008000"],["111652.65000000","0.17046000"],["111679.74000000","0.00008000"],["111703.32000000","0.76576000"],["111954.57000000","0.00000000"],["111961.80000000","0.00218000"],["112107.64000000","0.02398000"],["112578.54000000","0.00000000"],["113185.16000000","0.00100000"]]}
[2025-10-12T11:04:44.185Z] {"e":"depthUpdate","E":1760267084014,"s":"BTCUSDT","U":77965279561,"u":77965281832,"b":[["111520.23000000","8.80947000"],["111520.22000000","0.00005000"],["111520.17000000","0.00000000"],["111520.16000000","0.00010000"],["111519.99000000","0.00000000"],["111519.65000000","0.00000000"],["111519.36000000","0.00000000"],["111519.13000000","0.00000000"],["111519.12000000","0.00000000"],["111518.86000000","0.00000000"],["111518.84000000","0.06054000"],["111518.83000000","0.11813000"],["111518.82000000","0.00000000"],["111518.76000000","0.00000000"],["111518.70000000","0.00000000"],["111517.84000000","0.20179000"],["111517.56000000","0.00005000"],["111516.91000000","0.00000000"],["111516.66000000","0.00000000"],["111516.64000000","0.00000000"],["111516.63000000","0.00000000"],["111516.62000000","0.00000000"],["111516.11000000","0.00005000"],["111515.94000000","0.06656000"],["111515.80000000","0.00000000"],["111515.54000000","0.00000000"],["111515.52000000","0.00000000"],["111515.49000000","0.00000000"],["111515.29000000","0.00453000"],["111515.28000000","0.00000000"],["111515.13000000","0.00000000"],["111515.12000000","0.00000000"],["111515.11000000","0.00000000"],["111514.94000000","0.00000000"],["111514.93000000","0.00000000"],["111514.92000000","0.00000000"],["111514.79000000","0.35816000"],["111514.78000000","0.21602000"],["111514.77000000","0.13434000"],["111514.76000000","0.00000000"],["111514.71000000","0.00000000"],["111514.50000000","0.01005000"],["111513.74000000","0.00000000"],["111513.23000000","0.00000000"],["111513.22000000","0.00000000"],["111513.09000000","0.00005000"],["111512.99000000","0.00000000"],["111512.94000000","0.00000000"],["111512.74000000","0.05157000"],["111512.72000000","0.00000000"],["111512.71000000","0.00000000"],["111512.54000000","0.00000000"],["111512.49000000","0.00000000"],["111512.47000000","0.00000000"],["111512.46000000","0.53724000"],["111512.45000000","0.00000000"],["111512.44000000","0.00000000"],["111512.43000000","0.00000000"],["111512.39000000","0.00000000"],["111512.30000000","0.00000000"],["111511.89000000","0.00000000"],["111511.88000000","0.00000000"],["111511.36000000","0.00000000"],["111511.35000000","0.00000000"],["111511.34000000","0.03971000"],["111510.31000000","0.13777000"],["111510.30000000","0.00005000"],["111510.29000000","0.00000000"],["111510.28000000","0.00000000"],["111509.45000000","0.00000000"],["111508.62000000","0.00005000"],["111508.16000000","0.00007000"],["111507.46000000","0.00543000"],["111507.23000000","0.04481000"],["111507.22000000","0.06646000"],["111507.19000000","0.00000000"],["111506.88000000","0.00007000"],["111506.75000000","0.00005000"],["111506.68000000","0.35816000"],["111506.56000000","0.01388000"],["111506.50000000","0.00400000"],["111505.85000000","0.00074000"],["111505.65000000","0.00000000"],["111505.64000000","0.00005000"],["111505.50000000","0.00535000"],["111504.91000000","0.00010000"],["111504.50000000","0.00405000"],["111504.33000000","0.12814000"],["111504.15000000","0.00005000"],["111504.00000000","0.00400000"],["111503.62000000","0.40462000"],["111503.61000000","0.45000000"],["111502.95000000","0.00000000"],["111502.94000000","0.00000000"],["111502.92000000","0.01776000"],["111502.86000000","0.35816000"],["111502.47000000","0.08512000"],["111502.10000000","0.00150000"],["111501.83000000","0.15000000"],["111501.81000000","0.56000000"],["111501.80000000","0.00000000"],["111501.69000000","0.00000000"],["111501.57000000","0.00007000"],["111499.69000000","0.00000000"],["111499.45000000","0.00000000"],["111499.19000000","0.96680000"],["111498.79000000","0.00000000"],["111498.67000000","0.35816000"],["111498.52000000","0.00000000"],["111498.51000000","0.05760000"],["111497.98000000","0.06646000"],["111497.96000000","0.00000000"],["111497.94000000","0.00000000"],["111497.92000000","1.25396000"],["111497.78000000","0.00000000"],["111497.56000000","0.00000000"],["111497.34000000","0.00000000"],["111496.77000000","0.00000000"],["111496.61000000","0.00000000"],["111496.02000000","0.01165000"],["111495.73000000","0.00000000"],["111495.70000000","0.00022000"],["111495.50000000","0.00000000"],["111495.16000000","0.00010000"],["111495.10000000","0.00000000"],["111495.09000000","0.00000000"],["111495.08000000","0.35816000"],["111494.56000000","1.25396000"],["111493.80000000","0.00000000"],["111493.50000000","0.00400000"],["111492.55000000","0.00000000"],["111491.84000000","0.00300000"],["111491.80000000","0.06000000"],["111491.78000000","0.83947000"],["111491.77000000","0.45020000"],["111491.71000000","0.04800000"],["111491.23000000","0.00000000"],["111491.21000000","1.25396000"],["111491.16000000","0.00000000"],["111491.09000000","0.13430000"],["111491.06000000","0.00000000"],["111490.71000000","0.00000000"],["111489.86000000","0.13430000"],["111489.12000000","0.00005000"],["111488.85000000","0.00006000"],["111487.90000000","0.00000000"],["111487.88000000","1.03985000"],["111487.86000000","1.25396000"],["111487.65000000","0.30252000"],["111487.64000000","0.00000000"],["111486.84000000","0.00000000"],["111486.13000000","0.00000000"],["111484.07000000","0.00000000"],["111483.78000000","0.00000000"],["111483.51000000","0.08000000"],["111483.34000000","0.08507000"],["111483.05000000","0.02128000"],["111482.58000000","0.03498000"],["111482.00000000","0.00000000"],["111481.51000000","0.00000000"],["111481.27000000","0.04479000"],["111481.24000000","0.00000000"],["111480.43000000","0.31862000"],["111479.43000000","0.00000000"],["111479.01000000","0.04489000"],["111478.60000000","0.00000000"],["111478.00000000","0.00005000"],["111477.84000000","0.00009000"],["111477.34000000","0.00012000"],["111477.25000000","0.00000000"],["111475.81000000","0.00000000"],["111475.62000000","0.00018000"],["111475.50000000","0.01701000"],["111474.37000000","0.00000000"],["111473.95000000","0.00000000"],["111473.24000000","0.00000000"],["111473.10000000","0.00000000"],["111473.01000000","0.00000000"],["111472.64000000","0.00000000"],["111469.46000000","0.00000000"],["111469.25000000","0.06024000"],["111468.78000000","0.00000000"],["111468.50000000","0.01000000"],["111468.15000000","0.00000000"],["111467.83000000","0.00000000"],["111467.46000000","0.00009000"],["111466.82000000","0.17912000"],["111466.59000000","0.00000000"],["111465.62000000","0.00000000"],["111465.54000000","0.18908000"],["111464.32000000","0.00000000"],["111462.20000000","0.02125000"],["111462.15000000","0.08994000"],["111460.61000000","0.00000000"],["111459.54000000","0.06633000"],["111459.45000000","0.00000000"],["111458.88000000","0.00000000"],["111458.01000000","0.08994000"],["111457.46000000","0.00000000"],["111457.26000000","0.08994000"],["111456.43000000","0.00000000"],["111456.22000000","0.00000000"],["111454.99000000","0.00000000"],["111454.98000000","0.00000000"],["111454.50000000","0.00000000"],["111454.05000000","0.15640000"],["111453.53000000","0.00010000"],["111453.24000000","0.04426000"],["111452.66000000","0.00000000"],["111450.29000000","0.35976000"],["111447.47000000","0.02510000"],["111445.52000000","0.00000000"],["111444.65000000","0.02510000"],["111444.24000000","0.00000000"],["111443.31000000","0.20658000"],["111442.22000000","0.00000000"],["111441.00000000","0.00000000"],["111439.02000000","0.00000000"],["111437.96000000","0.13434000"],["111437.27000000","0.02199000"],["111436.15000000","0.00000000"],["111435.01000000","0.00000000"],["111433.22000000","0.00000000"],["111432.99000000","0.00631000"],["111432.20000000","0.02309000"],["111431.25000000","0.02243000"],["111425.51000000","0.00000000"],["111423.07000000","0.00000000"],["111422.21000000","0.00000000"],["111421.27000000","0.09417000"],["111420.40000000","0.09845000"],["111417.93000000","0.00000000"],["111417.53000000","0.00000000"],["111414.81000000","0.00000000"],["111413.72000000","0.00000000"],["111410.48000000","0.08994000"],["111409.24000000","0.22384000"],["111409.00000000","0.00038000"],["111408.99000000","0.24025000"],["111408.74000000","0.00000000"],["111408.37000000","0.00000000"],["111408.26000000","0.17989000"],["111408.25000000","0.00000000"],["111407.92000000","0.08994000"],["111407.79000000","0.22384000"],["111407.35000000","0.08994000"],["111406.66000000","0.00000000"],["111405.68000000","0.00000000"],["111405.46000000","0.13444000"],["111402.46000000","0.08994000"],["111402.40000000","0.02600000"],["111402.32000000","0.00000000"],["111401.70000000","0.08994000"],["111401.60000000","0.61617000"],["111401.58000000","0.00000000"],["111401.57000000","0.00000000"],["111398.70000000","0.24589000"],["111397.64000000","0.00000000"],["111396.06000000","0.00000000"],["111395.04000000","0.00000000"],["111388.15000000","0.17912000"],["111387.14000000","0.03974000"],["111379.20000000","0.00000000"],["111363.43000000","0.13271000"],["111358.56000000","0.08690000"],["111356.96000000","0.08794000"],["111354.00000000","0.00000000"],["111346.38000000","0.00000000"],["111345.11000000","0.00000000"],["111344.83000000","0.00000000"],["111342.82000000","0.00000000"],["111342.48000000","0.00000000"],["111342.30000000","0.00000000"],["111339.08000000","0.00000000"],["111338.76000000","0.00000000"],["111338.49000000","0.00000000"],["111336.10000000","0.00000000"],["111335.93000000","0.00000000"],["111335.05000000","0.00000000"],["111327.84000000","0.15934000"],["111321.89000000","0.00000000"],["111317.73000000","0.00000000"],["111316.66000000","0.00000000"],["111299.54000000","0.00000000"],["111289.13000000","0.00000000"],["111277.52000000","0.00000000"],["111269.05000000","0.00000000"],["111266.97000000","0.00000000"],["111265.33000000","0.00000000"],["111263.33000000","0.00000000"],["111260.64000000","0.00000000"],["111258.93000000","0.00000000"],["111257.79000000","4.67743000"],["111246.86000000","0.21006000"],["111229.42000000","0.00000000"],["111218.53000000","0.00000000"],["111193.97000000","0.00000000"],["111188.40000000","0.00000000"],["111164.71000000","0.00000000"],["111153.55000000","0.00000000"],["111139.18000000","0.03587000"],["111133.20000000","0.03587000"],["111108.72000000","0.00080000"],["111093.06000000","0.00000000"],["110998.00000000","0.00305000"],["110992.91000000","0.00000000"],["110397.35000000","0.00005000"],["109847.42000000","0.00100000"],["109839.77000000","0.00000000"],["102591.46000000","0.00000000"],["100366.00000000","0.00000000"],["100360.00000000","0.02133000"],["89216.19000000","0.00022000"],["89209.97000000","0.00015000"],["78061.71000000","0.00000000"],["70000.00000000","43.20205000"],["60000.00000000","53.14042000"]],"a":[["111512.47000000","0.00000000"],["111512.48000000","0.00000000"],["111512.49000000","0.00000000"],["111512.55000000","0.00000000"],["111512.93000000","0.00000000"],["111513.09000000","0.00000000"],["111513.22000000","0.00000000"],["111513.23000000","0.00000000"],["111513.24000000","0.00000000"],["111513.25000000","0.00000000"],["111513.59000000","0.00000000"],["111514.05000000","0.00000000"],["111514.77000000","0.00000000"],["111514.78000000","0.00000000"],["111514.79000000","0.00000000"],["111514.80000000","0.00000000"],["111514.93000000","0.00000000"],["111514.94000000","0.00000000"],["111514.95000000","0.00000000"],["111515.12000000","0.00000000"],["111515.13000000","0.00000000"],["111515.14000000","0.00000000"],["111515.53000000","0.00000000"],["111515.54000000","0.00000000"],["111515.55000000","0.00000000"],["111515.81000000","0.00000000"],["111516.63000000","0.00000000"],["111516.64000000","0.00000000"],["111516.92000000","0.00000000"],["111517.31000000","0.00000000"],["111517.43000000","0.00000000"],["111517.56000000","0.00000000"],["111517.79000000","0.00000000"],["111518.42000000","0.00000000"],["111518.64000000","0.00000000"],["111518.65000000","0.00000000"],["111518.66000000","0.00000000"],["111518.84000000","0.00000000"],["111518.85000000","0.00000000"],["111519.13000000","0.00000000"],["111519.14000000","0.00000000"],["111519.37000000","0.00000000"],["111519.50000000","0.00000000"],["111519.54000000","0.00000000"],["111519.58000000","0.00000000"],["111519.66000000","0.00000000"],["111520.00000000","0.00000000"],["111520.01000000","0.00000000"],["111520.08000000","0.00000000"],["111520.23000000","0.00000000"],["111520.24000000","0.21247000"],["111520.25000000","0.00055000"],["111520.26000000","0.00020000"],["111520.32000000","0.00010000"],["111520.61000000","0.00000000"],["111520.62000000","0.00000000"],["111520.91000000","0.00000000"],["111520.93000000","0.00000000"],["111520.94000000","0.00020000"],["111520.95000000","0.00020000"],["111521.33000000","0.00000000"],["111521.60000000","0.00000000"],["111521.66000000","0.00000000"],["111521.67000000","0.00000000"],["111522.00000000","0.00205000"],["111522.01000000","0.00010000"],["111522.08000000","0.00000000"],["111522.14000000","0.00000000"],["111522.18000000","0.00000000"],["111522.30000000","0.00000000"],["111522.38000000","0.00005000"],["111522.61000000","0.00000000"],["111522.80000000","0.00010000"],["111522.81000000","0.05774000"],["111522.82000000","0.00010000"],["111523.97000000","0.00000000"],["111523.98000000","0.00000000"],["111524.00000000","0.00205000"],["111524.01000000","0.00000000"],["111524.03000000","0.00000000"],["111524.24000000","0.00000000"],["111524.27000000","0.00005000"],["111524.42000000","0.00150000"],["111524.44000000","0.00000000"],["111525.32000000","0.00305000"],["111525.56000000","0.00000000"],["111525.57000000","0.00000000"],["111526.00000000","0.00205000"],["111526.33000000","0.00010000"],["111526.34000000","0.62010000"],["111526.36000000","0.00000000"],["111526.37000000","0.00000000"],["111526.38000000","0.00000000"],["111526.40000000","0.00000000"],["111526.49000000","0.00010000"],["111526.50000000","0.05627000"],["111526.76000000","0.00000000"],["111526.79000000","0.00000000"],["111526.96000000","0.00000000"],["111526.97000000","0.00000000"],["111527.91000000","0.00000000"],["111527.95000000","0.00000000"],["111527.99000000","0.00005000"],["111528.00000000","0.00205000"],["111528.19000000","0.00000000"],["111528.20000000","0.02641000"],["111528.43000000","0.00000000"],["111528.44000000","0.00000000"],["111528.47000000","0.00000000"],["111528.81000000","0.00010000"],["111528.82000000","0.03405000"],["111529.06000000","0.00000000"],["111529.08000000","0.00000000"],["111529.09000000","0.00000000"],["111529.14000000","0.00005000"],["111529.15000000","0.45025000"],["111529.20000000","0.00005000"],["111529.26000000","0.00000000"],["111529.49000000","0.00000000"],["111529.60000000","0.00000000"],["111530.00000000","0.00205000"],["111530.25000000","0.00000000"],["111530.38000000","0.00000000"],["111531.03000000","0.04810000"],["111531.06000000","0.00000000"],["111531.22000000","0.00000000"],["111531.24000000","0.00000000"],["111531.32000000","0.00000000"],["111531.33000000","0.00000000"],["111531.51000000","0.00155000"],["111531.55000000","0.00005000"],["111531.67000000","0.00000000"],["111531.91000000","0.00000000"],["111531.92000000","0.00000000"],["111532.00000000","0.00205000"],["111532.05000000","0.00000000"],["111532.15000000","0.04810000"],["111532.40000000","0.00000000"],["111532.45000000","0.00000000"],["111532.51000000","0.03902000"],["111533.26000000","0.00000000"],["111533.31000000","0.00005000"],["111533.34000000","0.07960000"],["111533.53000000","0.00000000"],["111533.54000000","0.01164000"],["111533.61000000","0.00000000"],["111533.62000000","0.33825000"],["111533.63000000","0.30250000"],["111533.85000000","0.00000000"],["111534.21000000","0.00000000"],["111534.43000000","0.00000000"],["111534.52000000","0.00000000"],["111534.60000000","0.00000000"],["111534.72000000","0.00000000"],["111534.73000000","0.00000000"],["111534.77000000","0.00000000"],["111535.13000000","0.00000000"],["111535.21000000","0.00007000"],["111535.80000000","0.00000000"],["111535.83000000","0.00000000"],["111536.90000000","0.00000000"],["111536.97000000","0.00155000"],["111536.98000000","0.00000000"],["111537.00000000","0.00000000"],["111537.08000000","0.30000000"],["111537.10000000","0.45000000"],["111537.26000000","0.00007000"],["111537.54000000","0.00000000"],["111537.98000000","0.00000000"],["111537.99000000","0.00000000"],["111538.00000000","0.00200000"],["111538.14000000","0.00000000"],["111538.16000000","0.00000000"],["111538.47000000","0.00000000"],["111538.54000000","0.00000000"],["111538.65000000","0.00000000"],["111539.10000000","0.04000000"],["111539.49000000","0.00000000"],["111539.68000000","0.00896000"],["111539.76000000","0.00000000"],["111540.37000000","0.00000000"],["111540.38000000","0.49066000"],["111540.39000000","0.35816000"],["111540.40000000","0.00000000"],["111540.46000000","0.00000000"],["111540.47000000","0.00000000"],["111540.48000000","0.04800000"],["111540.49000000","0.00000000"],["111542.40000000","0.00000000"],["111542.64000000","0.00448000"],["111542.65000000","0.08507000"],["111542.66000000","0.00000000"],["111542.69000000","0.00000000"],["111542.73000000","0.00000000"],["111543.23000000","0.00000000"],["111543.65000000","0.00018000"],["111543.75000000","0.02241000"],["111543.98000000","0.00000000"],["111543.99000000","0.22384000"],["111544.00000000","0.36016000"],["111544.67000000","0.00000000"],["111544.68000000","0.17912000"],["111544.77000000","0.00022000"],["111545.91000000","0.00000000"],["111545.92000000","0.04490000"],["111545.98000000","0.00000000"],["111545.99000000","0.00000000"],["111546.20000000","0.00000000"],["111546.41000000","0.00007000"],["111547.70000000","0.00000000"],["111547.71000000","0.99600000"],["111548.48000000","0.01388000"],["111548.67000000","0.00000000"],["111550.00000000","0.00260000"],["111550.39000000","0.00000000"],["111550.75000000","0.00000000"],["111551.10000000","0.00000000"],["111551.86000000","0.40334000"],["111551.87000000","0.57059000"],["111552.72000000","0.00012000"],["111554.83000000","0.13430000"],["111555.52000000","1.21515000"],["111555.57000000","0.13434000"],["111556.05000000","0.13430000"],["111556.97000000","0.08507000"],["111557.79000000","0.00005000"],["111558.00000000","0.08723000"],["111558.54000000","0.08505000"],["111559.31000000","0.00000000"],["111560.31000000","0.00179000"],["111560.33000000","0.16110000"],["111562.26000000","0.00005000"],["111562.69000000","0.00000000"],["111563.54000000","0.22384000"],["111563.93000000","0.08000000"],["111566.73000000","0.26588000"],["111567.02000000","0.00000000"],["111568.25000000","0.08508000"],["111569.28000000","0.00000000"],["111571.87000000","0.00000000"],["111572.80000000","0.00000000"],["111573.28000000","0.45656000"],["111574.76000000","0.00000000"],["111575.67000000","0.00005000"],["111578.93000000","0.08000000"],["111580.14000000","0.00005000"],["111583.88000000","0.00000000"],["111584.61000000","0.64316000"],["111584.87000000","0.00448000"],["111585.74000000","0.00000000"],["111586.27000000","0.00000000"],["111586.29000000","0.00000000"],["111586.66000000","0.35816000"],["111586.77000000","0.00000000"],["111588.01000000","0.00000000"],["111588.14000000","0.00000000"],["111588.23000000","0.00632000"],["111588.97000000","0.00000000"],["111589.21000000","0.00000000"],["111589.92000000","0.00652000"],["111590.34000000","0.00000000"],["111591.66000000","0.00000000"],["111591.81000000","0.00643000"],["111591.99000000","0.00000000"],["111593.36000000","0.35816000"],["111595.26000000","0.02398000"],["111595.82000000","0.00000000"],["111595.83000000","0.00000000"],["111595.86000000","0.00000000"],["111595.87000000","0.00000000"],["111595.99000000","0.00000000"],["111597.66000000","0.00000000"],["111600.00000000","0.06863000"],["111600.12000000","0.70956000"],["111600.92000000","0.00000000"],["111601.63000000","0.00000000"],["111603.24000000","0.01800000"],["111605.19000000","0.00000000"],["111605.28000000","0.00223000"],["111606.53000000","0.59722000"],["111606.54000000","1.25396000"],["111606.55000000","0.00000000"],["111608.29000000","0.00000000"],["111609.56000000","0.00005000"],["111611.50000000","0.00000000"],["111612.28000000","0.63486000"],["111612.55000000","0.00111000"],["111613.24000000","1.25396000"],["111613.91000000","0.13430000"],["111614.63000000","0.00005000"],["111615.13000000","0.13430000"],["111615.98000000","0.00000000"],["111616.01000000","0.00000000"],["111616.44000000","0.02398000"],["111618.01000000","0.27812000"],["111618.02000000","0.13434000"],["111618.35000000","0.00000000"],["111619.99000000","0.00000000"],["111620.14000000","0.17912000"],["111620.61000000","0.00000000"],["111621.78000000","0.00000000"],["111622.97000000","0.00000000"],["111623.28000000","0.15165000"],["111623.62000000","0.00000000"],["111623.86000000","0.02137000"],["111623.96000000","0.00000000"],["111623.98000000","0.00000000"],["111624.62000000","0.00000000"],["111624.64000000","0.00000000"],["111625.12000000","0.00000000"],["111625.98000000","0.00000000"],["111626.38000000","0.00000000"],["111626.42000000","0.00000000"],["111627.95000000","0.00222000"],["111629.98000000","0.00223000"],["111634.22000000","0.12115000"],["111634.54000000","0.00000000"],["111637.66000000","0.00000000"],["111641.60000000","0.22384000"],["111641.90000000","0.57113000"],["111641.91000000","0.99898000"],["111641.96000000","0.00000000"],["111648.57000000","0.00000000"],["111649.99000000","0.00000000"],["111651.96000000","0.02398000"],["111656.61000000","0.02510000"],["111659.27000000","0.02510000"],["111660.63000000","0.00000000"],["111664.47000000","0.02510000"],["111666.83000000","0.00000000"],["111667.36000000","0.00000000"],["111667.44000000","0.02510000"],["111667.73000000","0.00000000"],["111669.05000000","0.00000000"],["111671.39000000","0.09845000"],["111672.17000000","0.00000000"],["111672.84000000","0.02510000"],["111673.68000000","0.00000000"],["111674.07000000","0.16779000"],["111674.60000000","0.02510000"],["111675.46000000","0.00000000"],["111677.88000000","0.00000000"],["111679.96000000","0.00000000"],["111681.40000000","0.00000000"],["111682.73000000","0.17314000"],["111682.75000000","0.00000000"],["111683.20000000","0.00000000"],["111684.56000000","0.09976000"],["111685.04000000","0.00000000"],["111685.05000000","0.00000000"],["111688.63000000","0.00000000"],["111688.75000000","0.00000000"],["111689.13000000","0.00000000"],["111689.64000000","0.02692000"],["111690.55000000","0.00000000"],["111691.01000000","0.00000000"],["111691.04000000","0.01236000"],["111691.57000000","0.00000000"],["111691.83000000","0.39016000"],["111693.32000000","0.00000000"],["111694.26000000","0.44680000"],["111699.90000000","0.00000000"],["111703.94000000","0.02298000"],["111708.48000000","0.07500000"],["111708.63000000","0.04947000"],["111709.83000000","0.00000000"],["111713.63000000","0.30914000"],["111713.64000000","0.34629000"],["111714.20000000","0.00089000"],["111714.23000000","0.00000000"],["111714.75000000","0.00000000"],["111720.07000000","0.62869000"],["111723.99000000","0.00000000"],["111725.02000000","0.00000000"],["111730.83000000","0.00000000"],["111730.84000000","0.00000000"],["111732.75000000","0.00000000"],["111733.72000000","0.00000000"],["111734.40000000","0.00000000"],["111736.32000000","0.00000000"],["111737.00000000","0.02421000"],["111737.41000000","0.00000000"],["111737.53000000","0.02421000"],["111738.61000000","0.00089000"],["111741.08000000","0.02421000"],["111741.14000000","0.00089000"],["111744.13000000","4.62557000"],["111752.01000000","0.00000000"],["111758.79000000","0.08994000"],["111758.92000000","0.08994000"],["111760.58000000","0.08994000"],["111761.02000000","0.08994000"],["111763.49000000","0.08994000"],["111765.89000000","0.00000000"],["111765.94000000","0.08994000"],["111766.07000000","0.08994000"],["111768.97000000","0.08994000"],["111771.45000000","0.08994000"],["111773.87000000","0.08994000"],["111786.73000000","0.01703000"],["111801.31000000","0.00000000"],["111801.75000000","0.00000000"],["111802.12000000","0.00000000"],["111803.37000000","0.00000000"],["111805.96000000","0.00000000"],["111808.12000000","0.00000000"],["111808.52000000","0.00000000"],["111809.48000000","0.00000000"],["111809.83000000","0.00000000"],["111810.84000000","0.00000000"],["111813.37000000","0.00000000"],["111813.44000000","0.00000000"],["111828.26000000","0.00000000"],["111829.67000000","0.00010000"],["111830.61000000","0.00000000"],["111833.01000000","0.00000000"],["111833.11000000","0.00000000"],["111835.24000000","0.00000000"],["111839.30000000","0.00000000"],["111842.51000000","0.00000000"],["111848.55000000","0.00000000"],["111849.06000000","0.00000000"],["111865.08000000","0.05896000"],["111865.40000000","0.05896000"],["111865.95000000","0.05896000"],["111866.33000000","0.05896000"],["111866.73000000","0.05896000"],["111867.60000000","0.05896000"],["111868.64000000","0.05896000"],["111869.01000000","0.05896000"],["111869.59000000","0.05896000"],["111869.96000000","0.05896000"],["111872.81000000","0.07172000"],["111873.70000000","0.02690000"],["111874.76000000","0.03586000"],["111875.52000000","0.03586000"],["111876.31000000","0.02690000"],["111876.61000000","0.00000000"],["111879.20000000","0.02690000"],["111882.01000000","0.00063000"],["111882.89000000","0.00000000"],["111884.12000000","0.02690000"],["111885.78000000","0.02690000"],["111889.93000000","0.02690000"],["111896.96000000","0.00000000"],["111901.13000000","0.00000000"],["111905.78000000","0.00000000"],["111905.88000000","0.00005000"],["111915.11000000","0.02298000"],["111916.04000000","0.02298000"],["111916.75000000","0.02298000"],["111961.80000000","0.00000000"],["112015.79000000","0.03587000"],["112022.94000000","0.03586000"],["112023.79000000","0.03587000"],["112031.04000000","0.00000000"],["112040.15000000","0.00000000"],["112086.76000000","0.00000000"],["112087.67000000","0.00000000"],["112105.97000000","0.11990000"],["112107.02000000","0.02398000"],["112107.68000000","0.04796000"],["113185.16000000","0.00000000"]]}
[2025-10-12T11:04:45.183Z] {"e":"depthUpdate","E":1760267085014,"s":"BTCUSDT","U":77965281833,"u":77965282206,"b":[["111520.23000000","8.83672000"],["111520.22000000","0.20198000"],["111520.21000000","0.04506000"],["111520.20000000","0.00000000"],["111520.19000000","0.00000000"],["111520.16000000","0.00010000"],["111520.15000000","0.00000000"],["111520.10000000","0.00080000"],["111520.07000000","0.00902000"],["111520.06000000","0.00000000"],["111519.84000000","0.01350000"],["111518.84000000","0.00105000"],["111518.83000000","0.11813000"],["111518.04000000","0.00005000"],["111518.00000000","0.00364000"],["111517.84000000","0.00000000"],["111516.33000000","0.00538000"],["111516.11000000","0.00000000"],["111515.94000000","0.06651000"],["111515.29000000","0.00005000"],["111514.80000000","0.33898000"],["111514.79000000","0.35816000"],["111514.78000000","0.00000000"],["111514.65000000","0.11195000"],["111512.74000000","0.05162000"],["111512.46000000","0.52856000"],["111511.35000000","0.00448000"],["111511.34000000","0.03976000"],["111510.84000000","0.08512000"],["111510.27000000","0.00000000"],["111509.07000000","0.00300000"],["111507.22000000","0.06646000"],["111506.56000000","0.00000000"],["111503.68000000","0.00005000"],["111502.92000000","0.01771000"],["111502.47000000","0.08507000"],["111501.83000000","0.15000000"],["111499.21000000","0.00000000"],["111498.43000000","0.04800000"],["111497.44000000","0.07920000"],["111496.20000000","0.10080000"],["111495.85000000","0.04421000"],["111495.63000000","0.00896000"],["111495.35000000","0.00005000"],["111494.68000000","0.00005000"],["111491.87000000","0.01388000"],["111490.73000000","0.00000000"],["111489.49000000","0.00000000"],["111488.00000000","0.00005000"],["111486.65000000","0.00000000"],["111486.07000000","0.00000000"],["111483.33000000","0.00000000"],["111482.23000000","0.00000000"],["111481.12000000","0.00000000"],["111479.01000000","0.00008000"],["111479.00000000","0.00000000"],["111478.72000000","0.00000000"],["111477.22000000","0.00000000"],["111475.39000000","0.00000000"],["111469.15000000","0.60499000"],["111467.28000000","0.00000000"],["111457.01000000","0.00218000"],["111446.82000000","0.01070000"],["111441.25000000","0.01070000"],["111436.83000000","0.00000000"],["111431.25000000","0.00000000"],["111416.45000000","0.00000000"],["111398.50000000","0.08794000"],["111394.46000000","0.08794000"],["111391.05000000","0.23056000"],["111391.04000000","0.08794000"],["111390.48000000","0.00000000"],["111387.26000000","0.09224000"],["111387.25000000","0.08794000"],["111387.14000000","0.00000000"],["111382.99000000","0.08794000"],["111378.35000000","0.08794000"],["111374.92000000","0.08794000"],["111373.43000000","0.08794000"],["111371.64000000","0.08794000"],["111364.39000000","0.06000000"],["111356.93000000","0.17314000"],["111317.40000000","0.99720000"],["111316.50000000","0.09478000"],["111309.40000000","0.00000000"],["111291.61000000","0.00000000"],["111132.47000000","0.00080000"],["111108.72000000","0.00000000"],["110929.53000000","0.00035000"],["110851.11000000","0.00019000"],["110814.08000000","0.00000000"],["109847.42000000","0.00100000"],["100368.00000000","0.00061000"],["100360.00000000","0.02123000"],["89216.19000000","0.00022000"],["60000.00000000","53.14032000"]],"a":[["111520.24000000","0.15832000"],["111520.25000000","0.00060000"],["111520.26000000","0.00020000"],["111520.62000000","0.00010000"],["111520.63000000","0.01375000"],["111520.64000000","0.00020000"],["111520.94000000","0.00000000"],["111520.95000000","0.00000000"],["111521.36000000","0.00005000"],["111522.00000000","0.00205000"],["111522.01000000","0.00010000"],["111522.61000000","0.00010000"],["111522.65000000","0.00000000"],["111522.81000000","0.05774000"],["111524.00000000","0.00210000"],["111524.01000000","0.00000000"],["111524.14000000","0.00543000"],["111524.27000000","0.00000000"],["111524.42000000","0.00155000"],["111525.25000000","0.00722000"],["111525.32000000","0.00005000"],["111526.00000000","0.00205000"],["111526.34000000","0.62010000"],["111526.37000000","0.01803000"],["111526.49000000","0.00000000"],["111526.50000000","0.00000000"],["111528.20000000","0.02631000"],["111528.65000000","0.00000000"],["111528.81000000","0.00000000"],["111528.82000000","0.00000000"],["111529.14000000","0.00010000"],["111529.15000000","0.45025000"],["111530.00000000","0.00210000"],["111530.08000000","0.02691000"],["111530.46000000","0.00010000"],["111530.47000000","0.05913000"],["111531.03000000","0.04810000"],["111531.39000000","0.04476000"],["111532.15000000","0.04805000"],["111532.51000000","0.03892000"],["111533.31000000","0.00000000"],["111533.33000000","0.00000000"],["111533.34000000","0.07955000"],["111533.61000000","0.00000000"],["111536.97000000","0.00150000"],["111537.08000000","0.30000000"],["111538.17000000","0.04800000"],["111539.10000000","0.00000000"],["111539.68000000","0.00000000"],["111540.36000000","0.00000000"],["111540.73000000","0.03400000"],["111542.54000000","0.11195000"],["111543.02000000","0.07200000"],["111543.75000000","0.00000000"],["111544.27000000","0.07200000"],["111545.92000000","0.00008000"],["111546.48000000","0.08507000"],["111547.71000000","0.62684000"],["111549.29000000","0.00000000"],["111552.18000000","0.01487000"],["111553.70000000","0.04300000"],["111557.76000000","0.01487000"],["111564.24000000","0.00000000"],["111565.47000000","0.00000000"],["111571.20000000","0.00005000"],["111580.14000000","0.00000000"],["111592.21000000","0.06800000"],["111596.94000000","0.00000000"],["111604.92000000","0.00100000"],["111604.93000000","0.00100000"],["111608.38000000","0.00005000"],["111617.37000000","0.00005000"],["111620.07000000","0.07200000"],["111621.30000000","0.00000000"],["111631.28000000","0.01707000"],["111644.47000000","0.09450000"],["111708.48000000","0.11365000"],["111786.17000000","0.02510000"],["111826.14000000","0.00010000"],["111829.67000000","0.00000000"],["113193.05000000","0.00100000"]]}
[2025-10-12T11:04:46.182Z] {"e":"depthUpdate","E":1760267086014,"s":"BTCUSDT","U":77965282207,"u":77965282350,"b":[["111520.23000000","9.01941000"],["111520.22000000","0.00000000"],["111518.83000000","0.11813000"],["111518.00000000","0.00369000"],["111516.73000000","0.04145000"],["111515.94000000","0.06646000"],["111511.45000000","0.00005000"],["111504.69000000","0.00044000"],["111504.00000000","0.00400000"],["111501.83000000","0.15000000"],["111500.24000000","0.00005000"],["111499.96000000","0.00006000"],["111499.21000000","0.00000000"],["111499.07000000","0.00005000"],["111497.94000000","0.00000000"],["111494.38000000","0.00044000"],["111491.87000000","0.00000000"],["111487.65000000","0.00000000"],["111484.31000000","0.30252000"],["111478.67000000","1.23342000"],["111457.85000000","0.00000000"],["111436.96000000","0.10080000"],["111424.69000000","0.34629000"],["111374.15000000","0.00000000"],["111325.19000000","0.00574000"],["111310.96000000","0.00000000"],["110851.11000000","0.00000000"],["109847.42000000","0.00100000"],["107888.00000000","0.52081000"],["100368.00000000","0.00061000"],["100000.00000000","214.28583000"],["89216.19000000","0.00022000"],["42000.00000000","1.49196000"]],"a":[["111520.24000000","0.15802000"],["111520.26000000","0.00025000"],["111522.47000000","0.00005000"],["111522.49000000","0.00010000"],["111522.53000000","0.00010000"],["111522.56000000","0.00010000"],["111522.61000000","0.00000000"],["111522.82000000","0.00010000"],["111529.15000000","0.45025000"],["111530.00000000","0.00215000"],["111530.08000000","0.00000000"],["111530.09000000","0.02696000"],["111530.47000000","0.05908000"],["111531.51000000","0.00155000"],["111532.00000000","0.00200000"],["111532.15000000","0.04800000"],["111537.06000000","0.00000000"],["111537.08000000","0.30000000"],["111538.18000000","0.04031000"],["111538.25000000","0.00005000"],["111539.10000000","0.00000000"],["111540.36000000","0.00000000"],["111545.30000000","0.00005000"],["111547.07000000","0.00896000"],["111547.90000000","0.04000000"],["111553.70000000","0.00300000"],["111561.00000000","0.88472000"],["111562.86000000","1.19581000"],["111577.13000000","0.00005000"],["111592.21000000","0.00000000"],["111604.92000000","0.00000000"],["111604.93000000","0.00000000"],["111604.94000000","0.00000000"],["111621.30000000","0.07200000"],["111713.84000000","0.08794000"],["111716.77000000","0.08794000"],["111720.89000000","0.08794000"],["111723.60000000","0.08794000"],["111896.96000000","0.55835000"],["113193.05000000","0.00100000"]]}
[2025-10-12T11:04:47.182Z] {"e":"depthUpdate","E":1760267087014,"s":"BTCUSDT","U":77965282351,"u":77965282507,"b":[["111520.23000000","9.01864000"],["111520.22000000","0.00884000"],["111518.84000000","0.00110000"],["111518.83000000","0.10005000"],["111518.79000000","0.00000000"],["111517.54000000","0.01752000"],["111516.73000000","0.04140000"],["111514.77000000","0.00000000"],["111508.10000000","0.00005000"],["111505.50000000","0.00540000"],["111504.83000000","0.00000000"],["111504.50000000","0.00400000"],["111502.19000000","0.00005000"],["111501.83000000","0.15000000"],["111500.79000000","0.03586000"],["111499.21000000","0.00000000"],["111499.09000000","0.13434000"],["111497.94000000","0.00000000"],["111495.94000000","0.00005000"],["111461.20000000","0.50000000"],["111263.40000000","0.07530000"],["111230.46000000","0.00000000"],["110851.11000000","0.00000000"],["109847.42000000","0.00100000"],["100368.00000000","0.00061000"],["89216.19000000","0.00022000"],["33000.00000000","3.87311000"]],"a":[["111520.24000000","0.29629000"],["111520.25000000","0.00065000"],["111520.32000000","0.00010000"],["111520.63000000","0.01375000"],["111521.99000000","0.00000000"],["111522.00000000","0.00205000"],["111522.26000000","0.00000000"],["111522.49000000","0.00000000"],["111522.53000000","0.00000000"],["111522.56000000","0.00000000"],["111522.81000000","0.05774000"],["111522.82000000","0.00010000"],["111524.14000000","0.00543000"],["111524.42000000","0.00160000"],["111524.63000000","0.00010000"],["111524.64000000","0.05261000"],["111526.24000000","0.00000000"],["111526.34000000","0.62010000"],["111526.37000000","0.01798000"],["111529.14000000","0.00005000"],["111529.15000000","0.45025000"],["111530.00000000","0.00210000"],["111530.09000000","0.02691000"],["111530.46000000","0.00000000"],["111530.47000000","0.00000000"],["111531.51000000","0.00155000"],["111536.97000000","0.00155000"],["111537.08000000","0.30000000"],["111540.36000000","0.00000000"],["111540.42000000","0.06646000"],["111542.31000000","0.01926000"],["111544.95000000","0.00005000"],["111572.32000000","0.00000000"],["111592.33000000","0.00000000"],["111592.49000000","0.00000000"],["111606.89000000","0.00100000"],["111606.90000000","0.00100000"],["111623.86000000","0.00000000"],["111683.93000000","0.00000000"],["111687.01000000","0.13444000"],["111750.00000000","0.15253000"],["111829.38000000","0.00010000"],["111834.95000000","0.00000000"],["111847.24000000","0.04004000"],["111852.05000000","0.03997000"],["111856.32000000","0.03997000"],["111858.35000000","0.03997000"],["113193.05000000","0.00100000"],["152260.00000000","0.00004000"]]}
[2025-10-12T11:04:48.182Z] {"e":"depthUpdate","E":1760267088014,"s":"BTCUSDT","U":77965282508,"u":77965282668,"b":[["111520.23000000","8.97805000"],["111518.83000000","0.10005000"],["111518.00000000","0.00374000"],["111517.54000000","0.01798000"],["111516.73000000","0.04140000"],["111514.65000000","0.00000000"],["111514.26000000","0.00044000"],["111512.74000000","0.05162000"],["111512.46000000","0.30472000"],["111511.86000000","0.11195000"],["111511.74000000","0.00000000"],["111511.34000000","0.03971000"],["111510.84000000","0.00005000"],["111506.50000000","0.00405000"],["111506.26000000","0.08507000"],["111505.50000000","0.00535000"],["111501.83000000","0.15000000"],["111499.21000000","0.00000000"],["111497.94000000","0.00000000"],["111493.34000000","0.01388000"],["111492.82000000","0.00005000"],["111481.02000000","0.22384000"],["111478.00000000","0.00205000"],["111473.23000000","0.00000000"],["111469.35000000","0.00430000"],["111415.44000000","0.45975000"],["111415.42000000","0.00000000"],["111414.95000000","0.00000000"],["111277.41000000","4.65002000"],["111257.79000000","0.00000000"],["110882.55000000","0.00017000"],["110851.11000000","0.00000000"],["110849.35000000","0.00000000"],["109847.42000000","0.00100000"],["100368.00000000","0.00061000"],["89216.19000000","0.00022000"],["42000.00000000","1.49096000"]],"a":[["111520.24000000","0.16020000"],["111520.25000000","0.00065000"],["111520.32000000","0.00010000"],["111520.63000000","0.01375000"],["111520.64000000","0.00020000"],["111521.97000000","0.00000000"],["111521.98000000","0.00000000"],["111521.99000000","0.00000000"],["111522.60000000","0.00000000"],["111522.61000000","0.00000000"],["111522.82000000","0.00010000"],["111526.34000000","0.62010000"],["111529.14000000","0.00005000"],["111529.15000000","0.45025000"],["111530.00000000","0.00205000"],["111530.09000000","0.00000000"],["111530.22000000","0.02691000"],["111537.08000000","0.15000000"],["111540.36000000","0.15000000"],["111548.30000000","0.00005000"],["111592.78000000","0.06822000"],["111744.13000000","0.00000000"],["111763.78000000","4.83267000"],["111812.67000000","0.00536000"],["111859.27000000","0.03997000"],["113193.05000000","0.00100000"]]}
[2025-10-12T11:04:49.182Z] {"e":"depthUpdate","E":1760267089014,"s":"BTCUSDT","U":77965282669,"u":77965282925,"b":[["111520.23000000","7.03913000"],["111520.22000000","0.00929000"],["111520.21000000","0.00010000"],["111519.84000000","0.01345000"],["111518.84000000","0.05703000"],["111518.83000000","0.10005000"],["111518.00000000","0.00369000"],["111517.54000000","0.00000000"],["111516.73000000","0.04140000"],["111516.39000000","0.00000000"],["111515.94000000","0.00000000"],["111515.43000000","0.00000000"],["111514.80000000","0.00000000"],["111514.79000000","0.00000000"],["111514.50000000","0.01010000"],["111514.28000000","0.01776000"],["111514.02000000","0.00000000"],["111512.75000000","0.08902000"],["111512.74000000","0.05167000"],["111512.46000000","0.09031000"],["111510.31000000","0.24710000"],["111510.07000000","0.35816000"],["111507.46000000","0.00538000"],["111507.23000000","0.00000000"],["111505.50000000","0.00535000"],["111505.31000000","0.00005000"],["111503.64000000","0.15000000"],["111503.62000000","0.56377000"],["111502.87000000","0.35854000"],["111501.83000000","0.00000000"],["111500.80000000","0.04481000"],["111497.94000000","0.00000000"],["111486.58000000","0.00005000"],["111484.31000000","0.00000000"],["111483.75000000","0.00000000"],["111481.16000000","0.22384000"],["111480.44000000","0.00000000"],["111478.67000000","0.00000000"],["111477.59000000","0.00000000"],["111475.97000000","0.30254000"],["111474.08000000","0.00000000"],["111474.03000000","1.20551000"],["111472.84000000","0.00000000"],["111469.35000000","0.00000000"],["111464.06000000","0.00500000"],["111461.20000000","0.50005000"],["111453.24000000","0.00000000"],["111440.41000000","0.04426000"],["111427.22000000","0.13437000"],["111425.91000000","0.13430000"],["111317.40000000","0.00000000"],["111317.39000000","0.99411000"],["110400.00000000","0.85594000"],["109847.42000000","0.00100000"],["105900.00000000","0.07792000"],["102591.46000000","0.00010000"],["100368.00000000","0.00061000"],["89216.19000000","0.00022000"]],"a":[["111520.24000000","0.43885000"],["111520.25000000","0.00070000"],["111520.63000000","0.01375000"],["111520.64000000","0.00020000"],["111521.98000000","0.00010000"],["111521.99000000","0.00010000"],["111522.00000000","0.00200000"],["111522.01000000","0.00010000"],["111522.61000000","0.00000000"],["111522.80000000","0.00000000"],["111522.81000000","0.00000000"],["111522.82000000","0.00000000"],["111524.64000000","0.05261000"],["111525.25000000","0.00722000"],["111526.32000000","0.00010000"],["111526.33000000","0.19063000"],["111526.34000000","0.62005000"],["111528.20000000","0.02631000"],["111529.14000000","0.19786000"],["111529.15000000","0.45020000"],["111530.00000000","0.00210000"],["111530.22000000","0.00000000"],["111530.23000000","0.00000000"],["111530.24000000","0.00000000"],["111530.25000000","0.02691000"],["111532.00000000","0.00205000"],["111532.51000000","0.03885000"],["111536.32000000","0.00000000"],["111537.08000000","0.15000000"],["111537.29000000","0.04055000"],["111540.36000000","0.15000000"],["111542.31000000","0.01826000"],["111558.30000000","1.21541000"],["111560.66000000","0.00000000"],["111561.00000000","0.56278000"],["111562.86000000","0.00000000"],["111593.87000000","0.00000000"],["111606.87000000","0.00100000"],["111606.88000000","0.00100000"],["111606.89000000","0.00000000"],["111606.90000000","0.00000000"],["111609.56000000","0.04459000"],["111631.71000000","0.02137000"],["111760.00000000","0.00532000"],["111772.72000000","0.04097000"],["111775.58000000","0.04097000"],["111780.02000000","0.04097000"],["111799.96000000","0.00536000"],["113193.05000000","0.00100000"],["152460.00000000","0.00004000"]]}
[2025-10-12T11:04:50.182Z] {"e":"depthUpdate","E":1760267090014,"s":"BTCUSDT","U":77965282926,"u":77965283193,"b":[["111520.23000000","6.45982000"],["111520.22000000","0.00899000"],["111520.21000000","0.00020000"],["111520.10000000","0.00090000"],["111520.09000000","0.00010000"],["111519.84000000","0.01350000"],["111518.84000000","0.05708000"],["111516.73000000","0.04145000"],["111516.39000000","0.04000000"],["111514.28000000","0.01771000"],["111513.45000000","0.19594000"],["111513.44000000","0.35816000"],["111512.75000000","0.00000000"],["111511.86000000","0.00000000"],["111511.35000000","0.00000000"],["111508.43000000","0.00005000"],["111507.47000000","0.00448000"],["111506.28000000","0.11195000"],["111505.50000000","0.00530000"],["111498.05000000","0.00005000"],["111493.34000000","0.00000000"],["111491.88000000","0.01388000"],["111483.77000000","0.00000000"],["111483.46000000","0.00005000"],["111481.03000000","0.30253000"],["111475.97000000","0.00000000"],["111464.55000000","0.00000000"],["111442.18000000","0.00322000"],["111430.27000000","0.01403000"],["111426.01000000","0.00164000"],["111415.43000000","0.00000000"],["111410.47000000","0.00000000"],["111400.88000000","0.02600000"],["111317.39000000","0.99310000"],["111314.17000000","0.00065000"],["111299.86000000","0.00000000"],["111278.85000000","0.00000000"],["111209.38000000","0.00000000"],["111074.15000000","0.00022000"],["110882.55000000","0.00017000"],["109864.45000000","0.00000000"],["109847.42000000","0.00100000"],["103804.00000000","0.00000000"],["102591.46000000","0.00000000"],["100368.00000000","0.00061000"],["89216.19000000","0.00022000"]],"a":[["111520.24000000","1.21677000"],["111520.25000000","0.00070000"],["111520.63000000","0.01375000"],["111520.64000000","0.00020000"],["111521.94000000","0.00010000"],["111521.95000000","0.18670000"],["111521.96000000","0.00010000"],["111521.97000000","0.00000000"],["111521.98000000","0.00000000"],["111521.99000000","0.00000000"],["111524.01000000","0.00000000"],["111524.64000000","0.05261000"],["111525.25000000","0.00722000"],["111526.32000000","0.00000000"],["111526.33000000","0.00010000"],["111526.34000000","0.62010000"],["111526.37000000","0.01798000"],["111526.83000000","0.06646000"],["111528.60000000","0.11195000"],["111529.13000000","0.00005000"],["111529.14000000","0.19791000"],["111529.15000000","0.45020000"],["111530.00000000","0.00210000"],["111530.24000000","0.00000000"],["111530.25000000","0.00000000"],["111530.27000000","0.02691000"],["111531.39000000","0.00000000"],["111532.15000000","0.04805000"],["111532.51000000","0.03885000"],["111541.41000000","0.00100000"],["111542.54000000","0.00000000"],["111551.65000000","0.00005000"],["111556.12000000","0.18893000"],["111562.34000000","0.01403000"],["111601.99000000","0.04197000"],["111603.40000000","0.04197000"],["111606.88000000","0.04297000"],["111611.99000000","0.04197000"],["111614.99000000","0.04197000"],["111617.99000000","0.04197000"],["111629.21000000","0.06706000"],["111635.39000000","0.04197000"],["111641.59000000","0.04197000"],["111645.71000000","0.28590000"],["111653.42000000","0.04197000"],["113193.05000000","0.00100000"]]}
[2025-10-12T11:04:51.182Z] {"e":"depthUpdate","E":1760267091014,"s":"BTCUSDT","U":77965283194,"u":77965283400,"b":[["111520.23000000","6.44855000"],["111520.22000000","0.00904000"],["111520.08000000","0.00010000"],["111519.85000000","0.00010000"],["111518.85000000","0.00010000"],["111518.84000000","0.05713000"],["111518.83000000","0.10010000"],["111518.46000000","0.02696000"],["111518.00000000","0.00364000"],["111516.73000000","0.00005000"],["111516.39000000","0.04000000"],["111516.33000000","0.00543000"],["111514.70000000","0.00100000"],["111514.26000000","0.00000000"],["111512.74000000","0.05162000"],["111512.46000000","0.05033000"],["111511.55000000","0.00005000"],["111509.07000000","0.00305000"],["111505.64000000","0.00000000"],["111504.69000000","0.00000000"],["111500.79000000","0.00000000"],["111498.35000000","0.04397000"],["111495.85000000","0.00000000"],["111494.70000000","0.00005000"],["111491.95000000","0.01388000"],["111491.88000000","0.00000000"],["111491.81000000","0.00000000"],["111481.03000000","0.00000000"],["111480.34000000","0.00005000"],["111478.00000000","0.30458000"],["111469.45000000","0.00000000"],["111467.90000000","0.00000000"],["111444.69000000","0.00000000"],["111430.27000000","0.00000000"],["111414.97000000","0.00000000"],["110851.11000000","0.00000000"],["109847.42000000","0.00100000"],["108666.66000000","0.08269000"],["100368.00000000","0.00061000"],["89216.19000000","0.00022000"]],"a":[["111520.24000000","2.07603000"],["111520.25000000","0.00080000"],["111520.63000000","0.01375000"],["111520.64000000","0.00020000"],["111521.94000000","0.00000000"],["111521.95000000","0.00000000"],["111521.96000000","0.00000000"],["111522.00000000","0.00205000"],["111522.01000000","0.00010000"],["111523.30000000","0.00010000"],["111523.31000000","0.03596000"],["111523.32000000","0.00010000"],["111523.58000000","0.00005000"],["111524.64000000","0.05261000"],["111524.87000000","0.00005000"],["111524.88000000","0.30363000"],["111524.89000000","0.30258000"],["111526.33000000","0.00005000"],["111526.34000000","0.62005000"],["111526.37000000","0.01803000"],["111526.82000000","0.00000000"],["111526.83000000","0.06646000"],["111528.20000000","0.02626000"],["111529.13000000","0.00000000"],["111529.14000000","0.19786000"],["111530.00000000","0.00210000"],["111530.97000000","0.00005000"],["111531.03000000","0.04800000"],["111531.39000000","0.04476000"],["111531.51000000","0.00150000"],["111532.00000000","0.00200000"],["111532.15000000","0.04800000"],["111533.62000000","0.25301000"],["111533.63000000","0.00000000"],["111537.00000000","0.00500000"],["111541.41000000","0.00000000"],["111575.67000000","0.00000000"],["111616.43000000","0.04197000"],["111627.94000000","0.04197000"],["111631.21000000","0.06595000"],["111636.71000000","0.12691000"],["111641.58000000","0.04197000"],["111651.96000000","0.06595000"],["113193.05000000","0.00100000"],["116122.76000000","0.13681000"]]}
[2025-10-12T11:04:52.182Z] {"e":"depthUpdate","E":1760267092014,"s":"BTCUSDT","U":77965283401,"u":77965283521,"b":[["111520.23000000","6.52462000"],["111520.22000000","0.01909000"],["111518.84000000","0.04088000"],["111518.46000000","0.02691000"],["111516.73000000","0.00000000"],["111516.39000000","0.00000000"],["111514.68000000","0.00005000"],["111512.46000000","0.04906000"],["111506.50000000","0.00405000"],["111505.80000000","0.00005000"],["111500.80000000","0.08904000"],["111498.35000000","0.00000000"],["111482.62000000","0.04444000"],["111478.00000000","0.00205000"],["111475.97000000","0.30254000"],["111473.36000000","0.00218000"],["111457.01000000","0.00000000"],["111330.78000000","0.00574000"],["111325.19000000","0.00000000"],["111277.41000000","0.00000000"],["111270.85000000","4.65381000"],["111148.79000000","0.00080000"],["111132.47000000","0.00000000"],["110867.79000000","0.89111000"],["109847.42000000","0.00100000"],["100368.00000000","0.00061000"],["89216.19000000","0.00022000"],["33000.00000000","3.87311000"]],"a":[["111520.24000000","0.51022000"],["111520.25000000","0.00300000"],["111521.99000000","0.17460000"],["111524.64000000","0.05261000"],["111524.87000000","0.00000000"],["111524.88000000","0.00000000"],["111524.89000000","0.00000000"],["111525.25000000","0.00722000"],["111526.32000000","0.00010000"],["111526.33000000","0.21047000"],["111526.83000000","0.06651000"],["111528.60000000","0.00000000"],["111529.34000000","0.30253000"],["111531.03000000","0.04805000"],["111531.39000000","0.04481000"],["111534.18000000","0.11195000"],["111627.92000000","0.00222000"],["111627.93000000","0.00000000"],["111627.95000000","0.00000000"],["111683.32000000","0.00000000"],["111714.18000000","0.07530000"],["111738.60000000","0.00089000"],["111738.61000000","0.00000000"],["111761.29000000","4.78766000"],["111763.78000000","0.00000000"],["111896.96000000","0.00000000"],["113193.05000000","0.00100000"]]}
[2025-10-12T11:04:53.183Z] {"e":"depthUpdate","E":1760267093014,"s":"BTCUSDT","U":77965283522,"u":77965284383,"b":[["111526.33000000","6.79055000"],["111526.32000000","0.00080000"],["111526.31000000","0.00010000"],["111526.27000000","0.00000000"],["111526.26000000","0.00010000"],["111526.20000000","0.00090000"],["111526.19000000","0.00010000"],["111525.99000000","0.00000000"],["111525.81000000","0.00000000"],["111525.24000000","0.00000000"],["111524.63000000","0.00000000"],["111524.41000000","0.00000000"],["111524.13000000","0.00000000"],["111523.99000000","0.00000000"],["111523.30000000","0.00000000"],["111522.46000000","0.00000000"],["111522.03000000","0.00005000"],["111521.99000000","0.00000000"],["111520.62000000","0.00000000"],["111520.28000000","0.25674000"],["111520.27000000","0.00005000"],["111520.26000000","0.00000000"],["111520.25000000","0.00000000"],["111520.24000000","0.00110000"],["111520.23000000","0.42998000"],["111520.22000000","0.01889000"],["111520.21000000","0.00010000"],["111520.16000000","0.00000000"],["111520.10000000","0.00000000"],["111520.09000000","0.00000000"],["111520.08000000","0.00000000"],["111519.85000000","0.00000000"],["111519.84000000","0.01355000"],["111519.40000000","0.05473000"],["111518.85000000","0.00000000"],["111518.84000000","0.00005000"],["111518.83000000","0.00005000"],["111518.04000000","0.00000000"],["111516.33000000","0.00543000"],["111515.23000000","0.00538000"],["111515.19000000","0.00010000"],["111515.18000000","0.30782000"],["111515.17000000","0.45000000"],["111514.70000000","0.00000000"],["111514.50000000","0.01005000"],["111513.45000000","0.00000000"],["111512.74000000","0.00005000"],["111512.46000000","0.04911000"],["111512.41000000","0.00010000"],["111511.83000000","0.10297000"],["111511.34000000","0.03966000"],["111510.30000000","0.00000000"],["111509.07000000","0.00310000"],["111507.67000000","0.00007000"],["111507.52000000","0.01165000"],["111506.78000000","0.00069000"],["111506.75000000","0.00000000"],["111506.50000000","0.00400000"],["111504.33000000","0.00000000"],["111504.02000000","0.00300000"],["111502.10000000","0.00000000"],["111501.82000000","1.25396000"],["111501.57000000","0.00000000"],["111501.24000000","0.00005000"],["111492.88000000","0.04481000"],["111492.87000000","0.00008000"],["111492.52000000","0.00000000"],["111491.35000000","0.00005000"],["111491.34000000","0.00000000"],["111490.74000000","0.00000000"],["111486.56000000","0.31864000"],["111484.30000000","0.00000000"],["111483.42000000","0.00000000"],["111483.19000000","0.00000000"],["111482.76000000","0.00218000"],["111481.28000000","0.30252000"],["111480.69000000","0.00000000"],["111480.43000000","0.00000000"],["111479.01000000","0.00000000"],["111477.83000000","0.00000000"],["111477.70000000","0.00000000"],["111477.36000000","0.00000000"],["111476.15000000","1.18245000"],["111475.97000000","0.00000000"],["111474.60000000","0.00000000"],["111474.03000000","0.00000000"],["111473.36000000","0.00000000"],["111471.25000000","0.00000000"],["111464.77000000","0.04426000"],["111459.41000000","0.00008000"],["111458.12000000","0.00000000"],["111445.55000000","0.00000000"],["111440.41000000","0.00000000"],["111430.03000000","0.00000000"],["111428.01000000","0.00223000"],["111425.96000000","0.00008000"],["111412.10000000","0.00000000"],["111404.41000000","0.00000000"],["111392.50000000","0.00008000"],["111378.65000000","0.00000000"],["111359.04000000","0.00008000"],["111345.19000000","0.00000000"],["111317.39000000","0.00000000"],["111199.54000000","0.00000000"],["111166.13000000","0.00000000"],["111158.83000000","0.00000000"],["111158.17000000","0.00080000"],["111148.79000000","0.00000000"],["110000.00000000","26.34414000"],["109853.43000000","0.00100000"],["109847.42000000","0.00000000"],["100373.00000000","0.00010000"],["100368.00000000","0.00051000"],["89221.07000000","0.00022000"],["89216.19000000","0.00000000"],["78066.19000000","0.00000000"]],"a":[["111520.24000000","0.00000000"],["111520.25000000","0.00000000"],["111520.26000000","0.00000000"],["111520.32000000","0.00000000"],["111520.62000000","0.00000000"],["111520.63000000","0.00000000"],["111520.64000000","0.00000000"],["111521.36000000","0.00000000"],["111521.50000000","0.00000000"],["111521.98000000","0.00000000"],["111521.99000000","0.00000000"],["111522.00000000","0.00000000"],["111522.01000000","0.00000000"],["111522.38000000","0.00000000"],["111522.47000000","0.00000000"],["111522.48000000","0.00000000"],["111522.84000000","0.00000000"],["111523.30000000","0.00000000"],["111523.31000000","0.00000000"],["111523.32000000","0.00000000"],["111523.58000000","0.00000000"],["111524.00000000","0.00000000"],["111524.14000000","0.00000000"],["111524.42000000","0.00000000"],["111524.63000000","0.00000000"],["111524.64000000","0.00000000"],["111524.85000000","0.00000000"],["111525.25000000","0.00000000"],["111525.32000000","0.00000000"],["111526.00000000","0.00000000"],["111526.32000000","0.00000000"],["111526.33000000","0.00000000"],["111526.34000000","3.36870000"],["111526.35000000","0.00025000"],["111526.36000000","0.00010000"],["111526.37000000","0.01828000"],["111526.38000000","0.00020000"],["111526.42000000","0.00010000"],["111526.82000000","0.00000000"],["111526.83000000","0.00000000"],["111527.16000000","0.00000000"],["111527.32000000","0.00010000"],["111527.33000000","0.05409000"],["111527.34000000","0.00020000"],["111527.79000000","0.00000000"],["111528.00000000","0.00205000"],["111528.01000000","0.00010000"],["111528.02000000","0.00005000"],["111528.19000000","0.00000000"],["111528.20000000","0.00005000"],["111528.21000000","0.00010000"],["111528.22000000","0.03606000"],["111528.23000000","0.00010000"],["111529.05000000","0.00010000"],["111529.06000000","0.03596000"],["111529.14000000","0.00000000"],["111529.15000000","0.00000000"],["111529.17000000","0.00000000"],["111529.34000000","0.00000000"],["111529.44000000","0.00010000"],["111529.45000000","0.03596000"],["111529.89000000","0.00000000"],["111529.90000000","0.03591000"],["111530.00000000","0.00205000"],["111530.01000000","0.00000000"],["111530.26000000","0.00000000"],["111530.27000000","0.00000000"],["111530.28000000","0.00000000"],["111530.33000000","0.00000000"],["111530.34000000","0.00000000"],["111530.97000000","0.00000000"],["111531.02000000","0.00000000"],["111531.03000000","0.04810000"],["111531.38000000","0.00000000"],["111531.39000000","0.04486000"],["111531.51000000","0.00155000"],["111531.64000000","0.00005000"],["111532.00000000","0.00205000"],["111532.14000000","0.00000000"],["111532.15000000","0.04810000"],["111532.51000000","0.03890000"],["111532.70000000","0.02691000"],["111533.32000000","0.35920000"],["111533.33000000","0.30252000"],["111533.34000000","0.00000000"],["111533.54000000","0.00005000"],["111533.62000000","0.00000000"],["111534.00000000","0.00205000"],["111534.62000000","0.00005000"],["111535.02000000","0.05698000"],["111536.00000000","0.00205000"],["111536.47000000","0.00000000"],["111536.97000000","0.00150000"],["111537.00000000","0.00000000"],["111537.08000000","0.00000000"],["111537.26000000","0.00000000"],["111537.29000000","0.04055000"],["111537.70000000","0.04800000"],["111537.72000000","0.04800000"],["111539.93000000","0.00100000"],["111540.35000000","0.35816000"],["111540.36000000","0.30000000"],["111540.39000000","0.00000000"],["111540.73000000","0.00000000"],["111540.84000000","0.08675000"],["111543.07000000","0.00150000"],["111543.36000000","0.00007000"],["111543.99000000","0.22384000"],["111544.10000000","0.04000000"],["111545.15000000","0.01164000"],["111545.56000000","0.40880000"],["111545.92000000","0.00000000"],["111546.47000000","0.35853000"],["111547.71000000","0.00000000"],["111547.72000000","0.00000000"],["111547.90000000","0.00000000"],["111551.42000000","0.00005000"],["111551.86000000","0.04481000"],["111552.10000000","0.00000000"],["111553.63000000","0.00005000"],["111555.60000000","0.01164000"],["111557.15000000","0.02620000"],["111558.30000000","0.00000000"],["111558.35000000","0.00005000"],["111559.79000000","0.04482000"],["111559.80000000","0.00308000"],["111560.96000000","0.96907000"],["111560.97000000","1.22329000"],["111561.00000000","0.00000000"],["111565.60000000","0.07304000"],["111575.67000000","0.00005000"],["111579.38000000","0.00000000"],["111580.14000000","0.00000000"],["111586.84000000","0.00000000"],["111592.78000000","0.00000000"],["111593.26000000","0.00008000"],["111593.91000000","0.06597000"],["111606.87000000","0.00000000"],["111606.88000000","0.04197000"],["111612.83000000","0.00000000"],["111617.75000000","0.00000000"],["111618.01000000","0.65985000"],["111619.94000000","1.25396000"],["111620.88000000","0.00005000"],["111625.18000000","0.00005000"],["111626.71000000","0.00008000"],["111629.97000000","0.04097000"],["111636.71000000","0.16788000"],["111641.57000000","0.04097000"],["111641.90000000","0.00000000"],["111641.91000000","0.00000000"],["111641.92000000","0.99232000"],["111642.59000000","0.00000000"],["111646.28000000","0.00000000"],["111649.99000000","0.04097000"],["111660.17000000","0.00008000"],["111679.74000000","0.00000000"],["111682.73000000","0.00000000"],["111687.01000000","0.00000000"],["111690.45000000","0.36365000"],["111690.46000000","0.17314000"],["111691.04000000","0.00000000"],["111691.83000000","0.00000000"],["111693.63000000","0.00008000"],["111694.26000000","0.00000000"],["111699.56000000","0.01236000"],["111702.33000000","0.44680000"],["111708.63000000","0.00000000"],["111712.80000000","0.04947000"],["111713.64000000","0.00000000"],["111722.85000000","0.34629000"],["111835.48000000","0.00010000"],["111841.05000000","0.00000000"],["113193.05000000","0.00000000"]]}
[2025-10-12T11:04:54.182Z] {"e":"depthUpdate","E":1760267094014,"s":"BTCUSDT","U":77965284384,"u":77965284595,"b":[["111526.33000000","4.34543000"],["111526.32000000","0.00080000"],["111526.19000000","0.00010000"],["111522.03000000","0.00000000"],["111520.94000000","0.00010000"],["111520.93000000","0.04677000"],["111520.92000000","0.00005000"],["111520.29000000","0.00000000"],["111520.28000000","0.00000000"],["111520.27000000","0.00000000"],["111520.25000000","0.00010000"],["111520.24000000","0.14179000"],["111520.23000000","0.29488000"],["111519.84000000","0.01350000"],["111519.41000000","0.00010000"],["111519.40000000","0.05473000"],["111518.47000000","0.00010000"],["111517.80000000","0.00005000"],["111516.69000000","0.00000000"],["111516.20000000","0.00000000"],["111515.19000000","0.00000000"],["111515.18000000","0.30772000"],["111514.28000000","0.01776000"],["111513.39000000","0.04000000"],["111512.46000000","0.04916000"],["111512.29000000","0.00100000"],["111509.07000000","0.00300000"],["111507.22000000","0.00000000"],["111505.65000000","0.00027000"],["111503.64000000","0.00000000"],["111503.62000000","0.87500000"],["111502.87000000","0.00000000"],["111501.84000000","0.15000000"],["111498.09000000","0.01388000"],["111497.94000000","0.00000000"],["111494.38000000","0.00000000"],["111492.88000000","0.00000000"],["111491.95000000","0.00000000"],["111482.76000000","0.00000000"],["111481.28000000","0.00000000"],["111481.27000000","0.00000000"],["111478.00000000","0.30458000"],["111474.60000000","0.00005000"],["111472.86000000","0.00005000"],["111469.02000000","0.04479000"],["111464.77000000","0.00000000"],["111454.00000000","0.00478000"],["111446.27000000","0.04426000"],["111432.14000000","0.00172000"],["111426.01000000","0.00000000"],["111407.35000000","0.00000000"],["111400.31000000","0.00089000"],["111323.39000000","0.99736000"],["111320.53000000","0.00065000"],["111314.17000000","0.00000000"],["111302.17000000","0.08894000"],["109853.43000000","0.00100000"],["100373.00000000","0.00010000"],["89221.07000000","0.00022000"],["60000.00000000","53.14042000"]],"a":[["111526.34000000","3.69426000"],["111527.33000000","0.05409000"],["111528.00000000","0.00210000"],["111528.01000000","0.00010000"],["111528.20000000","0.00015000"],["111528.21000000","0.10674000"],["111528.22000000","0.03606000"],["111528.23000000","0.00000000"],["111528.60000000","0.06656000"],["111528.77000000","0.03591000"],["111529.05000000","0.00000000"],["111529.06000000","0.03591000"],["111529.13000000","0.00005000"],["111529.44000000","0.00000000"],["111529.45000000","0.00005000"],["111530.97000000","0.00005000"],["111531.39000000","0.04481000"],["111532.15000000","0.04805000"],["111533.32000000","0.25432000"],["111533.33000000","0.00000000"],["111534.62000000","0.00000000"],["111535.02000000","0.05708000"],["111535.72000000","0.00100000"],["111536.00000000","0.00200000"],["111539.93000000","0.00000000"],["111540.00000000","0.00600000"],["111540.36000000","0.30000000"],["111543.49000000","0.03400000"],["111543.99000000","0.22384000"],["111551.50000000","0.00400000"],["111559.79000000","0.00000000"],["111575.67000000","0.00000000"],["111593.91000000","0.00000000"],["111594.06000000","0.06731000"],["111608.87000000","0.00000000"],["111608.88000000","0.00000000"],["111609.87000000","0.00100000"],["111609.88000000","0.00100000"],["111620.14000000","0.00000000"],["111653.41000000","0.04097000"],["111687.01000000","0.00000000"],["111896.96000000","0.55835000"],["113199.24000000","0.00100000"]]}
[2025-10-12T11:04:55.182Z] {"e":"depthUpdate","E":1760267095014,"s":"BTCUSDT","U":77965284596,"u":77965284770,"b":[["111526.33000000","4.33606000"],["111526.32000000","0.00090000"],["111526.19000000","0.00010000"],["111526.18000000","0.00947000"],["111526.17000000","0.00902000"],["111525.95000000","0.00010000"],["111525.94000000","0.01355000"],["111524.10000000","0.00364000"],["111522.43000000","0.00538000"],["111520.24000000","0.14184000"],["111520.23000000","0.29488000"],["111520.22000000","0.00884000"],["111520.07000000","0.00897000"],["111519.84000000","0.00005000"],["111519.41000000","0.00000000"],["111518.47000000","0.00000000"],["111518.15000000","0.00005000"],["111518.00000000","0.00364000"],["111516.33000000","0.00005000"],["111515.43000000","0.00100000"],["111512.46000000","0.04911000"],["111512.29000000","0.00000000"],["111510.84000000","0.00000000"],["111498.16000000","0.01388000"],["111498.11000000","0.00000000"],["111498.09000000","0.00000000"],["111482.46000000","0.00000000"],["111480.41000000","0.00000000"],["111480.40000000","0.00000000"],["111478.00000000","0.30458000"],["111477.95000000","0.00000000"],["111475.51000000","0.00000000"],["111454.00000000","0.00260000"],["111451.24000000","0.04426000"],["111446.27000000","0.00000000"],["111444.78000000","0.00448000"],["111440.08000000","0.00218000"],["111434.31000000","0.00000000"],["111432.06000000","0.00000000"],["111410.78000000","0.00000000"],["111389.90000000","0.04947000"],["111364.48000000","0.06000000"],["111357.89000000","0.00000000"],["111336.52000000","0.00000000"],["111322.37000000","0.00000000"],["111158.17000000","0.00000000"],["111144.46000000","0.00080000"],["109853.43000000","0.00100000"],["105900.00000000","0.07792000"],["102591.46000000","0.00000000"],["100373.00000000","0.00010000"],["89221.07000000","0.00022000"],["60000.00000000","53.14032000"]],"a":[["111526.34000000","3.71397000"],["111526.37000000","0.01833000"],["111526.38000000","0.00020000"],["111526.73000000","0.01375000"],["111526.74000000","0.00020000"],["111527.33000000","0.05389000"],["111527.34000000","0.00010000"],["111528.22000000","0.03601000"],["111529.06000000","0.03591000"],["111529.90000000","0.03591000"],["111530.00000000","0.00210000"],["111530.24000000","0.00538000"],["111531.03000000","0.04810000"],["111531.35000000","0.00717000"],["111532.47000000","0.01793000"],["111534.18000000","0.00000000"],["111535.02000000","0.05698000"],["111536.00000000","0.00200000"],["111540.28000000","0.11195000"],["111543.49000000","0.00000000"],["111544.10000000","0.00000000"],["111544.68000000","0.00000000"],["111550.20000000","0.04000000"],["111562.34000000","0.00000000"],["111573.19000000","0.00000000"],["111609.56000000","0.00005000"],["111615.71000000","0.04393000"],["111627.92000000","0.00000000"],["111632.69000000","0.00000000"],["111632.78000000","0.17932000"],["111633.99000000","0.00222000"],["111641.91000000","0.59736000"],["111738.60000000","0.00000000"],["111745.35000000","0.00089000"],["111835.91000000","0.00000000"],["111874.96000000","0.06000000"],["111901.35000000","0.00627000"],["113199.24000000","0.00100000"]]}
[2025-10-12T11:04:56.183Z] {"e":"depthUpdate","E":1760267096014,"s":"BTCUSDT","U":77965284771,"u":77965285847,"b":[["111526.33000000","5.33601000"],["111526.32000000","0.00010000"],["111526.31000000","0.00000000"],["111526.19000000","0.35826000"],["111526.18000000","0.15913000"],["111525.95000000","0.00000000"],["111525.94000000","0.01360000"],["111525.21000000","0.03997000"],["111524.70000000","0.00005000"],["111524.12000000","0.00000000"],["111524.10000000","0.00369000"],["111523.59000000","0.00005000"],["111522.90000000","0.04163000"],["111522.77000000","0.00000000"],["111522.69000000","0.35816000"],["111522.44000000","0.00000000"],["111522.43000000","0.00543000"],["111522.03000000","0.00005000"],["111521.98000000","0.06646000"],["111520.94000000","0.00000000"],["111520.93000000","0.00005000"],["111520.75000000","0.00033000"],["111520.50000000","0.00400000"],["111520.36000000","0.00044000"],["111520.26000000","0.38533000"],["111520.25000000","0.45020000"],["111520.24000000","0.00009000"],["111520.23000000","0.29344000"],["111519.40000000","0.05478000"],["111519.32000000","0.35816000"],["111519.27000000","0.08507000"],["111518.72000000","0.00000000"],["111518.46000000","0.02696000"],["111518.14000000","0.00043000"],["111518.11000000","0.08507000"],["111518.00000000","0.00359000"],["111515.43000000","0.00000000"],["111515.19000000","0.00000000"],["111514.50000000","0.01000000"],["111514.28000000","0.01771000"],["111513.48000000","0.06646000"],["111513.39000000","0.00000000"],["111513.08000000","0.04426000"],["111512.81000000","0.04479000"],["111512.74000000","0.00000000"],["111512.46000000","0.00943000"],["111511.34000000","0.00000000"],["111510.33000000","1.37334000"],["111510.32000000","1.25396000"],["111510.31000000","0.00000000"],["111510.27000000","0.04800000"],["111510.09000000","0.00000000"],["111507.92000000","0.13430000"],["111506.78000000","0.00000000"],["111506.71000000","0.06000000"],["111506.70000000","0.00000000"],["111506.68000000","0.49246000"],["111506.45000000","0.04427000"],["111506.34000000","0.00000000"],["111506.28000000","0.00000000"],["111506.26000000","0.00000000"],["111505.86000000","0.16185000"],["111505.85000000","0.00000000"],["111505.29000000","0.00000000"],["111505.27000000","1.25396000"],["111505.26000000","0.45020000"],["111504.76000000","0.05760000"],["111504.66000000","0.05760000"],["111503.65000000","0.07200000"],["111503.64000000","0.00000000"],["111502.47000000","0.00000000"],["111501.84000000","0.15000000"],["111501.74000000","0.00896000"],["111501.03000000","0.01388000"],["111500.80000000","0.04481000"],["111500.76000000","0.06720000"],["111499.09000000","0.00000000"],["111498.16000000","0.00000000"],["111498.15000000","0.00000000"],["111495.63000000","0.00000000"],["111495.08000000","0.58200000"],["111495.03000000","0.00000000"],["111493.50000000","0.00000000"],["111493.22000000","0.00000000"],["111492.88000000","0.04481000"],["111492.81000000","0.00274000"],["111491.83000000","0.30249000"],["111491.82000000","0.00000000"],["111491.80000000","0.00000000"],["111491.74000000","0.00000000"],["111491.09000000","0.00000000"],["111490.14000000","0.00000000"],["111490.06000000","0.00000000"],["111489.86000000","0.00000000"],["111488.68000000","0.00445000"],["111488.48000000","0.00000000"],["111487.93000000","0.00000000"],["111486.24000000","0.00000000"],["111484.64000000","0.00009000"],["111484.00000000","0.00200000"],["111483.19000000","0.00000000"],["111482.63000000","0.01068000"],["111482.43000000","0.00018000"],["111482.00000000","0.00200000"],["111481.43000000","0.08507000"],["111481.16000000","0.00000000"],["111481.02000000","0.00000000"],["111480.00000000","0.00200000"],["111479.48000000","0.13434000"],["111478.00000000","0.00205000"],["111477.84000000","0.00000000"],["111477.33000000","0.00000000"],["111475.62000000","0.00000000"],["111475.44000000","0.00000000"],["111474.27000000","0.00009000"],["111474.06000000","0.00000000"],["111472.89000000","0.00000000"],["111472.86000000","0.00000000"],["111470.37000000","0.00000000"],["111469.02000000","0.00000000"],["111467.46000000","0.00000000"],["111459.85000000","0.00000000"],["111459.59000000","0.00000000"],["111452.40000000","1.27906000"],["111452.01000000","0.02510000"],["111451.24000000","0.00000000"],["111450.55000000","0.00622000"],["111450.18000000","0.03002000"],["111448.90000000","0.00218000"],["111445.59000000","0.13430000"],["111444.62000000","0.00000000"],["111444.35000000","0.13430000"],["111442.19000000","0.00653000"],["111442.16000000","0.00622000"],["111440.08000000","0.00000000"],["111439.00000000","0.00090000"],["111437.96000000","0.00000000"],["111435.40000000","0.00000000"],["111434.11000000","0.00000000"],["111432.20000000","0.02219000"],["111431.97000000","0.00000000"],["111430.70000000","0.11402000"],["111430.01000000","0.03587000"],["111427.41000000","0.00000000"],["111427.22000000","0.00007000"],["111426.13000000","0.00000000"],["111426.12000000","0.00000000"],["111425.91000000","0.00000000"],["111425.66000000","0.00000000"],["111425.57000000","0.00000000"],["111424.97000000","0.00000000"],["111421.66000000","0.00000000"],["111421.65000000","0.00000000"],["111419.87000000","0.00000000"],["111419.74000000","0.00000000"],["111419.47000000","0.22384000"],["111418.74000000","0.22384000"],["111418.34000000","0.07253000"],["111413.06000000","0.00000000"],["111409.24000000","0.00000000"],["111408.99000000","0.00000000"],["111407.79000000","0.00000000"],["111407.30000000","0.08794000"],["111405.46000000","0.00000000"],["111404.45000000","0.08794000"],["111404.09000000","0.00196000"],["111403.26000000","0.08794000"],["111396.64000000","0.00000000"],["111394.89000000","0.00000000"],["111385.60000000","0.02420000"],["111362.96000000","0.00000000"],["111338.47000000","0.00000000"],["111331.75000000","0.00000000"],["111328.09000000","0.00000000"],["111327.98000000","0.00000000"],["111327.64000000","0.00000000"],["111326.66000000","0.00000000"],["111325.18000000","0.00000000"],["111323.39000000","0.00000000"],["111323.38000000","0.99826000"],["111284.59000000","0.00000000"],["111282.55000000","0.00000000"],["111282.12000000","0.00000000"],["111281.99000000","0.00000000"],["111186.23000000","0.00000000"],["111157.41000000","0.03596000"],["111153.26000000","0.00080000"],["111144.46000000","0.00000000"],["111110.40000000","0.03594000"],["111071.97000000","0.00000000"],["110998.30000000","0.00000000"],["110998.17000000","0.00000000"],["110940.60000000","0.00000000"],["110793.12000000","0.00000000"],["110630.31000000","0.00000000"],["110553.47000000","0.00000000"],["109853.43000000","0.00100000"],["100373.00000000","0.00010000"],["89221.07000000","0.00022000"],["42000.00000000","1.49196000"]],"a":[["111526.34000000","0.01278000"],["111526.35000000","0.00085000"],["111526.36000000","0.00030000"],["111526.37000000","0.01808000"],["111526.38000000","0.00010000"],["111526.72000000","0.00010000"],["111526.73000000","0.01355000"],["111526.74000000","0.00010000"],["111526.95000000","0.00010000"],["111527.32000000","0.00000000"],["111527.33000000","0.00000000"],["111527.34000000","0.00010000"],["111527.59000000","0.00010000"],["111528.00000000","0.00200000"],["111528.01000000","0.00000000"],["111528.04000000","0.00000000"],["111528.20000000","0.00005000"],["111528.21000000","0.00000000"],["111528.22000000","0.00000000"],["111528.59000000","0.00000000"],["111528.60000000","0.00000000"],["111528.77000000","0.00000000"],["111528.89000000","0.00000000"],["111528.90000000","0.00000000"],["111529.06000000","0.00000000"],["111529.07000000","0.00000000"],["111529.13000000","0.00000000"],["111529.45000000","0.00000000"],["111529.74000000","0.00000000"],["111529.90000000","0.00000000"],["111530.00000000","0.00205000"],["111530.24000000","0.00543000"],["111530.84000000","0.00000000"],["111530.85000000","0.00000000"],["111530.97000000","0.00000000"],["111531.02000000","0.00000000"],["111531.03000000","0.00005000"],["111531.35000000","0.00722000"],["111531.39000000","0.00000000"],["111531.51000000","0.00005000"],["111532.00000000","0.00200000"],["111532.15000000","0.00010000"],["111532.46000000","0.00010000"],["111532.47000000","0.01803000"],["111532.50000000","0.00010000"],["111532.51000000","0.03900000"],["111532.60000000","0.00000000"],["111532.61000000","0.00000000"],["111532.63000000","0.00000000"],["111532.64000000","0.00000000"],["111532.65000000","0.00000000"],["111532.67000000","0.00000000"],["111532.68000000","0.00000000"],["111532.69000000","0.00000000"],["111532.70000000","0.00000000"],["111532.74000000","0.00000000"],["111533.29000000","0.00000000"],["111533.32000000","0.00000000"],["111533.44000000","0.00005000"],["111533.45000000","0.02005000"],["111534.46000000","0.00000000"],["111535.02000000","0.05708000"],["111535.14000000","0.00000000"],["111535.15000000","0.00000000"],["111535.33000000","0.00005000"],["111535.52000000","0.00000000"],["111535.53000000","0.00000000"],["111535.55000000","0.04005000"],["111535.68000000","0.00000000"],["111535.72000000","0.00000000"],["111535.85000000","0.32000000"],["111536.00000000","0.00210000"],["111536.37000000","0.00000000"],["111536.46000000","0.00000000"],["111536.47000000","0.00000000"],["111536.48000000","0.00000000"],["111536.72000000","0.00000000"],["111536.75000000","0.00000000"],["111536.80000000","0.01351000"],["111536.85000000","0.24000000"],["111537.10000000","0.00000000"],["111537.29000000","0.00000000"],["111537.49000000","0.00000000"],["111537.50000000","0.45000000"],["111537.70000000","0.00000000"],["111537.72000000","0.00000000"],["111538.17000000","0.00000000"],["111538.18000000","0.00000000"],["111539.13000000","0.00000000"],["111539.19000000","0.00000000"],["111539.20000000","0.30249000"],["111539.91000000","0.00000000"],["111539.98000000","0.00000000"],["111540.00000000","0.00200000"],["111540.09000000","0.00000000"],["111540.28000000","0.00000000"],["111540.35000000","0.00000000"],["111540.36000000","0.00000000"],["111540.38000000","0.00000000"],["111540.42000000","0.00000000"],["111540.48000000","0.00000000"],["111540.57000000","0.00068000"],["111540.58000000","0.00072000"],["111540.84000000","0.00000000"],["111541.02000000","0.00000000"],["111541.03000000","0.00000000"],["111541.47000000","0.00324000"],["111542.31000000","0.00000000"],["111542.64000000","0.00000000"],["111542.65000000","0.00000000"],["111542.72000000","0.00000000"],["111543.02000000","0.00000000"],["111543.23000000","0.00000000"],["111543.24000000","0.00000000"],["111543.84000000","0.00000000"],["111543.99000000","0.00000000"],["111544.00000000","0.00200000"],["111544.27000000","0.00000000"],["111544.34000000","0.00000000"],["111545.38000000","0.00000000"],["111545.56000000","0.20179000"],["111545.57000000","0.00000000"],["111545.72000000","0.00000000"],["111546.47000000","0.00000000"],["111546.48000000","0.00000000"],["111546.94000000","0.03400000"],["111547.07000000","0.00000000"],["111547.82000000","0.00000000"],["111548.32000000","0.00000000"],["111548.47000000","0.00448000"],["111548.48000000","0.00000000"],["111548.49000000","0.00100000"],["111548.64000000","0.15671000"],["111548.66000000","0.00000000"],["111550.12000000","0.00000000"],["111550.20000000","0.00000000"],["111550.93000000","0.04800000"],["111551.50000000","0.00000000"],["111551.86000000","0.19481000"],["111551.87000000","0.21250000"],["111551.88000000","0.00000000"],["111551.90000000","0.04800000"],["111551.91000000","0.04800000"],["111553.53000000","0.00000000"],["111553.99000000","0.00000000"],["111554.50000000","0.00000000"],["111554.64000000","0.04800000"],["111555.07000000","0.00000000"],["111555.24000000","0.04800000"],["111555.35000000","0.00896000"],["111555.50000000","0.15000000"],["111555.51000000","0.35822000"],["111555.53000000","0.00000000"],["111556.36000000","0.04800000"],["111557.43000000","0.04097000"],["111557.48000000","0.04800000"],["111558.00000000","0.00529000"],["111558.33000000","0.17932000"],["111558.50000000","0.00000000"],["111559.10000000","0.00000000"],["111559.79000000","0.04482000"],["111561.20000000","0.04000000"],["111564.22000000","0.00449000"],["111565.60000000","0.00000000"],["111570.07000000","0.00000000"],["111570.63000000","0.01836000"],["111573.18000000","0.00000000"],["111574.14000000","0.01701000"],["111574.50000000","0.22384000"],["111575.67000000","0.00005000"],["111576.49000000","0.00000000"],["111576.89000000","0.00000000"],["111578.73000000","0.00000000"],["111579.59000000","0.08507000"],["111580.14000000","0.00005000"],["111582.58000000","0.00000000"],["111584.87000000","0.00000000"],["111587.96000000","0.06186000"],["111589.08000000","0.00005000"],["111594.06000000","0.00000000"],["111594.60000000","0.00000000"],["111597.57000000","0.00896000"],["111597.67000000","0.00000000"],["111597.75000000","0.00000000"],["111599.14000000","0.00000000"],["111600.06000000","0.35816000"],["111606.52000000","0.35816000"],["111609.87000000","0.00000000"],["111609.88000000","0.00000000"],["111615.71000000","0.00000000"],["111615.88000000","0.07043000"],["111620.46000000","0.03992000"],["111621.80000000","0.00000000"],["111622.05000000","0.00000000"],["111623.28000000","0.48559000"],["111623.29000000","0.00000000"],["111623.97000000","0.00000000"],["111626.64000000","1.25396000"],["111629.01000000","0.04800000"],["111631.71000000","0.00000000"],["111632.32000000","0.04800000"],["111632.72000000","0.04800000"],["111633.34000000","1.25396000"],["111633.45000000","0.04800000"],["111633.98000000","0.00222000"],["111633.99000000","0.00000000"],["111634.56000000","0.04800000"],["111636.85000000","0.00000000"],["111639.23000000","0.00196000"],["111640.77000000","0.00000000"],["111640.85000000","0.00000000"],["111641.91000000","0.00000000"],["111641.92000000","0.00000000"],["111642.82000000","0.02398000"],["111643.73000000","0.00000000"],["111643.74000000","0.00000000"],["111645.82000000","0.00000000"],["111647.99000000","0.00000000"],["111651.96000000","0.04197000"],["111651.98000000","0.00000000"],["111652.58000000","0.22384000"],["111654.78000000","0.99466000"],["111667.98000000","0.16112000"],["111675.07000000","0.00000000"],["111684.75000000","0.08684000"],["111688.53000000","0.00000000"],["111695.52000000","0.00000000"],["111700.06000000","0.00000000"],["111723.60000000","0.00000000"],["111727.40000000","0.08694000"],["111736.60000000","0.08694000"],["111739.46000000","0.08694000"],["111745.34000000","0.00089000"],["111745.35000000","0.00000000"],["111749.40000000","0.06000000"],["111754.54000000","0.02420000"],["111755.47000000","0.08794000"],["111756.95000000","0.08794000"],["111758.92000000","0.17788000"],["111761.10000000","0.08794000"],["111763.89000000","0.08794000"],["111766.84000000","0.08794000"],["111768.50000000","0.00000000"],["111769.31000000","0.00000000"],["111769.62000000","0.00000000"],["111770.34000000","0.00000000"],["111772.11000000","0.00000000"],["111773.24000000","0.00000000"],["111787.60000000","0.69990000"],["111799.81000000","0.00000000"],["111799.99000000","0.00000000"],["111801.25000000","0.00000000"],["111815.18000000","0.00000000"],["111844.32000000","0.00000000"],["111846.29000000","0.00000000"],["111847.04000000","0.00000000"],["111847.21000000","0.00000000"],["111847.38000000","0.00000000"],["111847.55000000","0.00000000"],["111847.71000000","0.00000000"],["111847.88000000","0.00000000"],["111848.05000000","0.00000000"],["111848.21000000","0.00000000"],["111848.38000000","0.00000000"],["111850.33000000","0.00000000"],["111864.62000000","0.05896000"],["111872.66000000","0.02689000"],["111874.96000000","0.02000000"],["111875.77000000","0.03586000"],["111876.42000000","0.03586000"],["111878.07000000","0.03586000"],["111878.39000000","0.03586000"],["111878.58000000","0.03586000"],["111878.60000000","0.03586000"],["111879.99000000","0.03586000"],["111883.24000000","0.03586000"],["111883.53000000","0.03586000"],["111887.04000000","0.03586000"],["111887.24000000","0.03586000"],["111888.21000000","0.03586000"],["111889.16000000","0.00000000"],["111892.29000000","0.00000000"],["111892.60000000","0.00000000"],["111893.11000000","0.00000000"],["111896.96000000","0.00000000"],["111905.64000000","0.00000000"],["111908.02000000","0.62481000"],["111914.62000000","0.02398000"],["111916.73000000","0.02398000"],["111919.04000000","0.04696000"],["111920.20000000","0.02398000"],["111921.82000000","0.02403000"],["111971.43000000","0.00000000"],["112027.60000000","0.03586000"],["112032.84000000","0.03586000"],["112040.58000000","0.45000000"],["112107.68000000","0.00000000"],["113199.24000000","0.00100000"]]}
