[2025-10-12T10:56:18.472Z] Snapshot loaded successfully.
[2025-10-12T10:56:21.502Z] WebSocket connected successfully.
[2025-10-12T10:56:22.186Z] {"e":"depthUpdate","E":1760266582014,"s":"BTCUSDT","U":77965051191,"u":77965051359,"b":[["111705.32000000","3.61131000"],["111705.31000000","0.00045000"],["111702.35000000","0.06651000"],["111701.45000000","0.00005000"],["111701.44000000","0.17899000"],["111701.43000000","0.00000000"],["111694.84000000","0.15005000"],["111688.96000000","0.00000000"],["111677.44000000","0.00000000"],["111677.05000000","0.01390000"],["111467.10000000","4.63694000"],["111035.09000000","0.00000000"],["110029.74000000","0.00100000"],["100534.79000000","0.00115000"],["100534.00000000","0.00010000"],["89364.26000000","0.00022000"],["33000.00000000","3.87311000"]],"a":[["111705.33000000","1.67097000"],["111705.34000000","0.00040000"],["111705.72000000","0.01348000"],["111706.72000000","0.00000000"],["111706.73000000","0.00000000"],["111706.75000000","0.00005000"],["111709.23000000","0.00547000"],["111709.25000000","0.00010000"],["111709.26000000","0.04912000"],["111710.49000000","0.00010000"],["111710.50000000","0.29525000"],["111710.51000000","0.00000000"],["111712.65000000","0.00010000"],["111712.66000000","0.04800000"],["111712.90000000","0.00000000"],["111712.94000000","0.00000000"],["111712.95000000","0.22269000"],["111712.96000000","0.00000000"],["111712.97000000","0.02697000"],["111713.46000000","0.00000000"],["111713.51000000","0.17192000"],["111714.82000000","0.04011000"],["111719.18000000","0.01761000"],["111719.59000000","0.00000000"],["111719.80000000","0.00000000"],["111719.81000000","0.00332000"],["111720.00000000","0.08159000"],["111720.01000000","0.00537000"],["111720.81000000","0.00447000"],["111788.32000000","0.00100000"],["111788.33000000","0.00100000"],["111948.83000000","4.85848000"],["112110.91000000","0.00000000"],["112114.60000000","0.55838000"],["113380.91000000","0.00100000"]]}
[2025-10-12T10:56:23.185Z] {"e":"depthUpdate","E":1760266583014,"s":"BTCUSDT","U":77965051360,"u":77965051564,"b":[["111705.32000000","3.85671000"],["111705.31000000","0.00195000"],["111705.27000000","0.23558000"],["111705.19000000","0.00010000"],["111705.16000000","0.00900000"],["111704.93000000","0.01358000"],["111704.63000000","0.00100000"],["111704.51000000","0.00005000"],["111703.09000000","0.00358000"],["111701.42000000","0.00547000"],["111700.73000000","0.03937000"],["111700.30000000","0.00721000"],["111699.75000000","0.04775000"],["111699.71000000","0.04480000"],["111699.18000000","0.01796000"],["111694.84000000","0.00005000"],["111688.96000000","0.15000000"],["111677.05000000","0.00000000"],["111676.89000000","0.01390000"],["111667.75000000","0.00000000"],["111664.01000000","0.30195000"],["111557.90000000","0.00000000"],["110568.91000000","0.00000000"],["110029.74000000","0.00100000"],["110000.00000000","26.18410000"],["106100.00000000","0.69851000"],["101900.00000000","0.65469000"],["100534.79000000","0.00120000"],["100534.00000000","0.00010000"],["100411.70000000","0.00000000"],["89364.26000000","0.00022000"]],"a":[["111705.33000000","1.81981000"],["111705.34000000","0.00045000"],["111705.49000000","0.00900000"],["111705.72000000","0.01353000"],["111707.56000000","0.00363000"],["111709.23000000","0.00552000"],["111709.24000000","0.00010000"],["111709.25000000","0.10783000"],["111709.26000000","0.04922000"],["111710.35000000","0.00726000"],["111710.38000000","0.00005000"],["111710.39000000","0.29535000"],["111710.49000000","0.00000000"],["111710.50000000","0.00000000"],["111711.46000000","0.00000000"],["111711.47000000","0.01795000"],["111712.65000000","0.00000000"],["111712.66000000","0.04800000"],["111712.91000000","0.00000000"],["111712.95000000","0.22264000"],["111712.97000000","0.02692000"],["111713.51000000","0.17187000"],["111714.82000000","0.04006000"],["111719.81000000","0.00332000"],["111720.00000000","0.08154000"],["111720.06000000","0.00000000"],["111720.24000000","0.00000000"],["111722.31000000","0.00000000"],["111723.95000000","0.15000000"],["111724.47000000","0.00100000"],["111727.60000000","0.04800000"],["111788.32000000","0.00000000"],["111788.33000000","0.00000000"],["112110.91000000","0.55838000"],["112114.60000000","0.00000000"],["112701.03000000","0.00000000"],["113380.91000000","0.00100000"]]}
[2025-10-12T10:56:24.186Z] {"e":"depthUpdate","E":1760266584014,"s":"BTCUSDT","U":77965051565,"u":77965051639,"b":[["111705.32000000","3.85660000"],["111704.93000000","0.01363000"],["111694.84000000","0.15005000"],["111688.96000000","0.00000000"],["111684.68000000","0.00000000"],["111677.19000000","0.01390000"],["111676.89000000","0.00000000"],["111663.50000000","0.00000000"],["111588.81000000","0.00196000"],["111572.88000000","0.00000000"],["111569.02000000","0.04947000"],["111565.43000000","0.02999000"],["111492.73000000","0.08894000"],["111374.70000000","0.02685000"],["111370.99000000","0.02685000"],["111328.09000000","0.00000000"],["111323.52000000","0.00000000"],["110029.74000000","0.00100000"],["89364.26000000","0.00022000"],["75000.00000000","37.36422000"],["60000.00000000","53.14032000"],["40213.92000000","0.00225000"]],"a":[["111705.33000000","1.81870000"],["111705.34000000","0.00045000"],["111709.25000000","0.02257000"],["111709.26000000","0.04922000"],["111710.35000000","0.00726000"],["111710.38000000","0.00000000"],["111710.39000000","0.00000000"],["111711.46000000","0.00005000"],["111711.47000000","0.01800000"],["111712.95000000","0.22269000"],["111713.33000000","0.29525000"],["111719.81000000","0.00332000"],["111720.07000000","0.00000000"],["111721.34000000","0.00000000"],["111724.47000000","0.00000000"],["111727.94000000","0.04000000"],["111742.26000000","0.00000000"],["111817.42000000","0.00000000"],["111827.34000000","0.00196000"],["111946.61000000","0.08894000"],["112110.91000000","0.00000000"],["112114.60000000","0.55838000"],["113380.91000000","0.00100000"]]}
[2025-10-12T10:56:25.186Z] {"e":"depthUpdate","E":1760266585014,"s":"BTCUSDT","U":77965051640,"u":77965051719,"b":[["111705.32000000","3.94390000"],["111705.31000000","0.00055000"],["111683.63000000","0.00000000"],["111678.53000000","0.00000000"],["111677.23000000","0.00000000"],["111677.19000000","0.00000000"],["111677.06000000","0.01390000"],["111671.78000000","0.63628000"],["111670.36000000","1.22852000"],["111669.26000000","0.13426000"],["111668.05000000","0.00000000"],["111664.01000000","0.30195000"],["111617.05000000","0.00000000"],["111612.05000000","0.00163000"],["111612.04000000","0.00000000"],["111606.70000000","0.13426000"],["111500.23000000","0.00065000"],["111500.22000000","0.00000000"],["111500.00000000","0.18944000"],["111421.64000000","0.00574000"],["111416.28000000","0.00000000"],["111035.09000000","0.00000000"],["110029.74000000","0.00100000"],["100534.00000000","0.00010000"],["89364.26000000","0.00022000"],["60000.00000000","53.14022000"],["42000.00000000","1.49196000"],["40213.92000000","0.00240000"]],"a":[["111705.33000000","1.81503000"],["111705.34000000","0.00050000"],["111705.72000000","0.01353000"],["111707.87000000","0.00010000"],["111707.88000000","0.17197000"],["111711.46000000","0.00000000"],["111711.47000000","0.01795000"],["111712.95000000","0.22264000"],["111713.51000000","0.00000000"],["111720.07000000","0.40306000"],["111744.69000000","1.22842000"],["111788.32000000","0.00000000"],["111788.33000000","0.00000000"],["111910.33000000","0.00000000"],["111917.47000000","0.07516000"],["112110.91000000","0.55838000"],["112114.60000000","0.00000000"],["113380.91000000","0.00100000"]]}
[2025-10-12T10:56:26.185Z] {"e":"depthUpdate","E":1760266586014,"s":"BTCUSDT","U":77965051720,"u":77965051772,"b":[["111705.32000000","3.88099000"],["111699.73000000","0.00000000"],["111694.84000000","0.00005000"],["111694.16000000","0.15000000"],["111694.14000000","0.56190000"],["111688.96000000","0.00000000"],["111678.42000000","0.01390000"],["111677.06000000","0.00000000"],["111472.53000000","0.00187000"],["111463.77000000","0.00000000"],["110029.74000000","0.00100000"],["102768.89000000","0.00010000"],["100534.00000000","0.00010000"],["89364.26000000","0.00022000"]],"a":[["111705.33000000","2.10725000"],["111705.34000000","0.00045000"],["111709.25000000","0.10780000"],["111709.26000000","0.04917000"],["111710.35000000","0.30251000"],["111713.33000000","0.00000000"],["111720.00000000","0.08159000"],["111727.26000000","0.00100000"],["112049.56000000","0.00000000"],["112058.36000000","0.00187000"],["112110.91000000","0.00000000"],["112118.29000000","0.55838000"],["112182.54000000","0.00000000"],["112191.34000000","0.00079000"],["113380.91000000","0.00100000"]]}
[2025-10-12T10:56:27.184Z] {"e":"depthUpdate","E":1760266587014,"s":"BTCUSDT","U":77965051773,"u":77965051822,"b":[["111668.05000000","0.30194000"],["111664.01000000","0.00000000"],["111405.32000000","0.00000000"],["110029.74000000","0.00100000"],["102768.89000000","0.00000000"],["100534.00000000","0.00010000"],["89364.26000000","0.00022000"],["33000.00000000","3.87311000"]],"a":[["111705.33000000","1.69250000"],["111726.37000000","0.00894000"],["111727.94000000","0.00000000"],["111731.54000000","0.04000000"],["111732.66000000","0.00000000"],["111789.22000000","0.00100000"],["111789.23000000","0.00100000"],["111875.11000000","0.00000000"],["111961.51000000","0.04004000"],["112110.91000000","0.55838000"],["112118.29000000","0.00000000"],["113380.91000000","0.00100000"],["116200.00000000","0.14060000"],["117000.00000000","14.14971000"],["117800.00000000","0.44454000"],["118600.00000000","0.59677000"],["119400.00000000","0.13389000"],["120200.00000000","0.06460000"],["121000.00000000","17.79837000"]]}
[2025-10-12T10:56:28.185Z] {"e":"depthUpdate","E":1760266588014,"s":"BTCUSDT","U":77965051823,"u":77965051979,"b":[["111705.32000000","3.57344000"],["111705.31000000","0.00055000"],["111704.93000000","0.01358000"],["111704.63000000","0.00000000"],["111702.35000000","0.06651000"],["111701.45000000","0.00000000"],["111701.44000000","0.00000000"],["111700.74000000","0.00005000"],["111700.73000000","0.03942000"],["111700.31000000","0.17894000"],["111694.16000000","0.00000000"],["111691.85000000","0.00000000"],["111691.06000000","0.00447000"],["111688.96000000","0.15000000"],["111685.53000000","0.32217000"],["111685.03000000","0.00043000"],["111680.88000000","0.13426000"],["111678.42000000","0.00000000"],["111677.54000000","0.00000000"],["111671.78000000","0.37389000"],["111670.40000000","1.19601000"],["111670.36000000","0.00000000"],["111668.05000000","0.00000000"],["111667.39000000","0.04549000"],["111666.94000000","0.00000000"],["111666.48000000","0.00000000"],["111664.01000000","0.00000000"],["111660.67000000","0.30196000"],["111653.61000000","0.00000000"],["111565.43000000","0.00000000"],["111472.53000000","0.00000000"],["111472.24000000","0.00000000"],["111461.25000000","0.00187000"],["111370.39000000","0.02685000"],["111035.09000000","0.00000000"],["110029.74000000","0.00100000"],["110000.00000000","26.25041000"],["109421.05000000","0.00000000"],["108842.10000000","0.00000000"],["108263.15000000","0.00005000"],["107684.21000000","0.00009000"],["107105.26000000","0.00025000"],["106526.31000000","0.00000000"],["105947.36000000","0.00000000"],["105368.42000000","0.00010000"],["104789.47000000","0.00006000"],["104210.52000000","0.00281000"],["103631.57000000","0.00000000"],["103052.63000000","0.00134000"],["102473.68000000","0.00000000"],["101894.73000000","0.00000000"],["101315.78000000","0.00092000"],["100736.84000000","0.00000000"],["100534.79000000","0.00132000"],["100534.00000000","0.00010000"],["100394.50000000","0.00020000"],["100157.89000000","0.00000000"],["99578.94000000","0.00000000"],["99000.00000000","298.98344000"],["89364.26000000","0.00022000"],["42000.00000000","1.49096000"]],"a":[["111705.33000000","2.88760000"],["111705.34000000","0.00296000"],["111705.72000000","0.01353000"],["111707.86000000","0.00015000"],["111707.87000000","0.16372000"],["111707.88000000","0.17197000"],["111709.23000000","0.00547000"],["111709.24000000","0.00000000"],["111709.25000000","0.00010000"],["111712.97000000","0.02697000"],["111714.50000000","0.00400000"],["111716.61000000","0.04815000"],["111719.17000000","0.00447000"],["111719.81000000","0.00327000"],["111720.00000000","0.08154000"],["111720.06000000","0.15000000"],["111720.81000000","0.00000000"],["111723.95000000","0.00000000"],["111724.73000000","0.06646000"],["111727.26000000","0.00000000"],["111736.04000000","0.32202000"],["111742.23000000","1.18689000"],["111744.69000000","0.00000000"],["111754.44000000","0.00000000"],["111800.29000000","0.00470000"],["111850.27000000","0.01236000"],["112047.03000000","0.00187000"],["112058.36000000","0.00000000"],["112110.91000000","0.00000000"],["112111.40000000","0.00000000"],["112118.29000000","0.55838000"],["112180.01000000","0.00079000"],["112191.34000000","0.00000000"],["113000.00000000","46.14565000"],["113380.91000000","0.00100000"],["113800.00000000","0.51121000"],["114600.00000000","3.50534000"],["115400.00000000","0.13102000"]]}
[2025-10-12T10:56:29.185Z] {"e":"depthUpdate","E":1760266589014,"s":"BTCUSDT","U":77965051980,"u":77965052071,"b":[["111705.32000000","3.51660000"],["111705.30000000","0.00020000"],["111702.65000000","0.00005000"],["111700.31000000","0.00000000"],["111699.18000000","0.01801000"],["111699.17000000","0.00100000"],["111698.37000000","0.17894000"],["111698.36000000","0.00000000"],["111696.07000000","0.04000000"],["111691.06000000","0.00000000"],["111690.50000000","0.00000000"],["111689.23000000","0.00447000"],["111689.22000000","0.00000000"],["111686.33000000","0.35788000"],["111677.22000000","0.00000000"],["111674.42000000","0.13426000"],["111671.78000000","0.68310000"],["111660.60000000","0.13438000"],["111624.00000000","0.00260000"],["111611.86000000","0.13426000"],["111562.14000000","0.02506000"],["111561.52000000","0.02506000"],["111535.04000000","0.00000000"],["111467.10000000","0.00000000"],["111400.00000000","1.09877000"],["111293.02000000","0.00000000"],["110600.00000000","0.95700000"],["110029.74000000","0.00100000"],["110000.00000000","26.25585000"],["109800.00000000","11.81902000"],["109421.05000000","0.00576000"],["109000.00000000","95.79395000"],["108842.10000000","0.00609000"],["108263.15000000","0.00645000"],["107684.21000000","0.00683000"],["107105.26000000","0.00731000"],["106526.31000000","0.00740000"],["106100.00000000","0.69851000"],["105947.36000000","0.00774000"],["105368.42000000","0.00818000"],["104789.47000000","0.00848000"],["104210.52000000","0.01159000"],["103631.57000000","0.00912000"],["103052.63000000","0.01083000"],["102473.68000000","0.00984000"],["101894.73000000","0.01022000"],["101315.78000000","0.01150000"],["100736.84000000","0.01095000"],["100534.79000000","0.00144000"],["100534.00000000","0.00010000"],["100394.50000000","0.00008000"],["100157.89000000","0.01133000"],["99578.94000000","0.01172000"],["99000.00000000","298.99554000"],["89364.26000000","0.00022000"]],"a":[["111705.33000000","3.17467000"],["111710.91000000","0.00000000"],["111716.50000000","0.11229000"],["111719.81000000","0.00332000"],["111721.51000000","0.00400000"],["111727.67000000","0.00000000"],["111842.20000000","0.03997000"],["111922.85000000","0.02506000"],["111948.83000000","0.00000000"],["113380.91000000","0.00100000"]]}
[2025-10-12T10:56:30.185Z] {"e":"depthUpdate","E":1760266590014,"s":"BTCUSDT","U":77965052072,"u":77965052210,"b":[["111705.32000000","3.71238000"],["111705.31000000","0.00050000"],["111703.78000000","0.00015000"],["111703.77000000","0.29537000"],["111703.09000000","0.00363000"],["111702.65000000","0.01820000"],["111700.73000000","0.03942000"],["111700.30000000","0.00721000"],["111700.11000000","0.05093000"],["111699.76000000","0.00100000"],["111699.18000000","0.01791000"],["111699.17000000","0.00000000"],["111697.02000000","0.05142000"],["111694.16000000","0.00000000"],["111688.96000000","0.15000000"],["111676.97000000","0.00000000"],["111676.83000000","0.01390000"],["111674.30000000","0.04549000"],["111667.39000000","0.00000000"],["111654.34000000","0.00000000"],["111630.64000000","0.01401000"],["111600.09000000","0.07516000"],["111592.99000000","0.00000000"],["111556.59000000","0.17089000"],["111554.87000000","0.08794000"],["111467.23000000","4.77758000"],["111452.26000000","0.02596000"],["111290.46000000","0.00000000"],["111035.09000000","0.00000000"],["110029.74000000","0.00100000"],["100534.00000000","0.00010000"],["89364.26000000","0.00022000"],["40213.92000000","0.00255000"]],"a":[["111705.33000000","2.87251000"],["111705.34000000","0.00296000"],["111720.00000000","0.09154000"],["111720.06000000","0.15000000"],["111721.51000000","0.00300000"],["111722.10000000","0.00100000"],["111723.95000000","0.00000000"],["111764.54000000","0.01401000"],["111945.41000000","4.70327000"],["112118.29000000","0.55838000"],["113380.91000000","0.00100000"]]}
[2025-10-12T10:56:31.185Z] {"e":"depthUpdate","E":1760266591015,"s":"BTCUSDT","U":77965052211,"u":77965052382,"b":[["111705.32000000","3.77897000"],["111700.11000000","0.05088000"],["111699.76000000","0.00000000"],["111694.16000000","0.15000000"],["111688.96000000","0.00000000"],["111686.16000000","0.00894000"],["111680.09000000","0.00000000"],["111677.11000000","0.01390000"],["111676.83000000","0.00000000"],["111666.48000000","0.30195000"],["111660.67000000","0.00000000"],["111638.93000000","0.00000000"],["111630.64000000","0.00000000"],["111616.78000000","0.00000000"],["111558.40000000","0.02690000"],["111525.93000000","0.00979000"],["111525.92000000","0.02685000"],["111507.15000000","0.00000000"],["111484.24000000","0.00000000"],["111473.81000000","0.00000000"],["111404.11000000","0.01611000"],["111374.01000000","0.02685000"],["111361.42000000","0.05896000"],["111361.39000000","0.00000000"],["111359.39000000","0.05896000"],["111358.03000000","0.05896000"],["111357.52000000","0.05896000"],["111311.26000000","0.00000000"],["111310.57000000","0.00000000"],["111309.30000000","0.00000000"],["111306.85000000","0.00016000"],["111217.22000000","0.03580000"],["111211.43000000","0.03580000"],["110029.74000000","0.00100000"],["100534.00000000","0.00010000"],["89364.26000000","0.00022000"]],"a":[["111705.33000000","1.83720000"],["111705.34000000","0.00291000"],["111705.72000000","0.01353000"],["111707.56000000","0.00363000"],["111707.86000000","0.00005000"],["111707.87000000","0.00010000"],["111707.88000000","0.17197000"],["111708.75000000","0.05976000"],["111709.23000000","0.00542000"],["111709.25000000","0.00000000"],["111709.26000000","0.00005000"],["111710.35000000","0.00726000"],["111711.46000000","0.00010000"],["111711.47000000","0.01800000"],["111712.65000000","0.00005000"],["111712.66000000","0.04805000"],["111712.95000000","0.22269000"],["111712.97000000","0.02702000"],["111713.01000000","0.29525000"],["111713.14000000","0.00000000"],["111715.40000000","0.00000000"],["111716.50000000","0.00039000"],["111716.61000000","0.04810000"],["111719.17000000","0.00000000"],["111719.81000000","0.00327000"],["111720.00000000","0.09154000"],["111720.06000000","0.00000000"],["111720.81000000","0.00447000"],["111722.08000000","0.11190000"],["111722.10000000","0.00000000"],["111723.95000000","0.15000000"],["111736.04000000","0.00000000"],["111736.26000000","0.00000000"],["111745.60000000","0.00000000"],["111753.00000000","0.32197000"],["111753.12000000","0.00000000"],["111764.54000000","0.00000000"],["111834.82000000","0.01401000"],["111907.03000000","0.08794000"],["111909.48000000","0.08794000"],["112118.29000000","0.55838000"],["113380.91000000","0.00100000"],["117414.26000000","0.00008000"]]}
[2025-10-12T10:56:32.185Z] {"e":"depthUpdate","E":1760266592014,"s":"BTCUSDT","U":77965052383,"u":77965052518,"b":[["111705.32000000","3.71198000"],["111702.65000000","0.01825000"],["111702.45000000","0.00100000"],["111694.16000000","0.00000000"],["111688.96000000","0.15000000"],["111677.21000000","0.01390000"],["111677.11000000","0.00000000"],["111671.78000000","0.67195000"],["111670.40000000","0.00000000"],["111669.88000000","1.20414000"],["111666.48000000","0.00000000"],["111664.01000000","0.30195000"],["111290.62000000","0.00000000"],["111210.03000000","0.03580000"],["110029.74000000","0.00100000"],["103997.00000000","0.00000000"],["102768.89000000","0.00010000"],["100534.00000000","0.00010000"],["89364.26000000","0.00022000"],["33000.00000000","3.87311000"]],"a":[["111705.33000000","2.12072000"],["111705.34000000","0.00291000"],["111705.72000000","0.01353000"],["111707.56000000","0.00368000"],["111707.86000000","0.00015000"],["111707.87000000","0.16681000"],["111707.88000000","0.17197000"],["111708.74000000","0.00010000"],["111708.75000000","0.05981000"],["111710.35000000","0.00726000"],["111710.54000000","0.00000000"],["111710.55000000","0.29530000"],["111711.46000000","0.00000000"],["111711.47000000","0.01795000"],["111712.65000000","0.00000000"],["111712.66000000","0.04795000"],["111712.95000000","0.22264000"],["111712.97000000","0.02697000"],["111713.01000000","0.00000000"],["111720.06000000","0.15000000"],["111723.95000000","0.00000000"],["111726.80000000","0.00100000"],["111736.07000000","0.32202000"],["111742.23000000","0.00000000"],["111744.64000000","1.17694000"],["111753.00000000","0.00000000"],["111789.22000000","0.00000000"],["111789.23000000","0.00000000"],["112110.91000000","0.55838000"],["112118.29000000","0.00000000"],["113380.91000000","0.00100000"],["131000.00000000","31.11867000"]]}
[2025-10-12T10:56:33.185Z] {"e":"depthUpdate","E":1760266593014,"s":"BTCUSDT","U":77965052519,"u":77965052635,"b":[["111705.32000000","3.77301000"],["111694.16000000","0.15000000"],["111693.10000000","0.00447000"],["111693.09000000","0.00498000"],["111689.23000000","0.00000000"],["111688.96000000","0.00000000"],["111677.21000000","0.00000000"],["111677.18000000","0.01390000"],["111669.99000000","0.00000000"],["111581.66000000","0.44760000"],["111571.72000000","0.21496000"],["111568.86000000","0.00000000"],["111467.23000000","0.00000000"],["111291.95000000","0.00000000"],["110029.74000000","0.00100000"],["103103.00000000","0.01033000"],["102768.89000000","0.00000000"],["100534.00000000","0.00010000"],["89364.26000000","0.00022000"],["40213.92000000","0.00270000"]],"a":[["111705.33000000","2.03068000"],["111707.87000000","0.16686000"],["111708.75000000","0.05986000"],["111720.06000000","0.00000000"],["111723.95000000","0.15000000"],["111789.22000000","0.00100000"],["111789.23000000","0.00100000"],["111945.41000000","0.00000000"],["112110.91000000","0.00000000"],["112118.29000000","0.55838000"],["113380.91000000","0.00100000"],["120127.27000000","0.00000000"]]}
[2025-10-12T10:56:34.184Z] {"e":"depthUpdate","E":1760266594014,"s":"BTCUSDT","U":77965052636,"u":77965052702,"b":[["111705.32000000","3.92258000"],["111705.31000000","0.27880000"],["111703.77000000","0.29532000"],["111700.74000000","0.00000000"],["111700.73000000","0.03937000"],["111678.18000000","0.01390000"],["111677.18000000","0.00000000"],["111655.32000000","0.00848000"],["111505.99000000","0.99321000"],["111499.90000000","0.00000000"],["111466.72000000","4.74121000"],["111398.71000000","0.00000000"],["111351.86000000","0.02685000"],["111349.42000000","0.02685000"],["111309.43000000","0.00000000"],["111306.60000000","0.00000000"],["111302.73000000","0.00000000"],["111299.71000000","0.00000000"],["111297.05000000","0.00000000"],["110029.74000000","0.00100000"],["107750.00000000","0.47577000"],["100534.00000000","0.00010000"],["89364.26000000","0.00022000"],["60000.00000000","53.14032000"],["40213.92000000","0.00300000"]],"a":[["111705.33000000","1.74461000"],["111712.97000000","0.02692000"],["111714.50000000","0.00000000"],["111719.81000000","0.00332000"],["111834.82000000","0.00000000"],["111945.60000000","4.69545000"],["112118.29000000","0.55838000"],["112813.20000000","0.00000000"],["113380.91000000","0.00100000"]]}
[2025-10-12T10:56:35.185Z] {"e":"depthUpdate","E":1760266595014,"s":"BTCUSDT","U":77965052703,"u":77965052768,"b":[["111705.32000000","3.92212000"],["111705.31000000","0.27885000"],["111702.65000000","0.01820000"],["111702.45000000","0.00000000"],["111696.34000000","0.00044000"],["111694.16000000","0.15000000"],["111684.68000000","0.00000000"],["111678.18000000","0.00000000"],["111677.26000000","0.01400000"],["111677.15000000","0.06013000"],["111670.69000000","0.00000000"],["111349.41000000","0.08581000"],["110029.74000000","0.00000000"],["106100.00000000","0.69851000"],["105000.00000000","217.11043000"],["100534.00000000","0.00010000"],["89364.26000000","0.00022000"],["60000.00000000","53.14022000"]],"a":[["111705.33000000","1.53044000"],["111705.72000000","0.01353000"],["111707.86000000","0.00005000"],["111707.87000000","0.00010000"],["111710.54000000","0.00005000"],["111710.55000000","0.29535000"],["111712.66000000","0.04800000"],["111712.97000000","0.02687000"],["111714.82000000","0.00005000"],["111716.61000000","0.04805000"],["111719.18000000","0.00000000"],["111719.81000000","0.00332000"],["112110.91000000","0.55838000"],["112118.29000000","0.00000000"],["112813.20000000","0.00159000"],["113380.91000000","0.00100000"]]}
[2025-10-12T10:56:36.185Z] {"e":"depthUpdate","E":1760266596014,"s":"BTCUSDT","U":77965052769,"u":77965052806,"b":[["111677.26000000","0.00010000"],["111677.16000000","0.01395000"],["111671.78000000","0.64660000"],["111669.94000000","1.18447000"],["111669.88000000","0.00000000"],["110029.74000000","0.00100000"],["109655.00000000","0.00562000"],["100534.00000000","0.00010000"],["89364.26000000","0.00022000"],["89364.00000000","0.00000000"],["42000.00000000","1.49196000"],["33000.00000000","3.87311000"]],"a":[["111705.33000000","1.52780000"],["111710.92000000","0.00000000"],["111720.00000000","0.09159000"],["111744.64000000","0.00000000"],["111745.56000000","0.76495000"],["111745.57000000","1.18745000"],["111747.48000000","0.00000000"],["112110.91000000","0.00000000"],["112118.29000000","0.55838000"],["113380.91000000","0.00100000"]]}
[2025-10-12T10:56:37.185Z] {"e":"depthUpdate","E":1760266597014,"s":"BTCUSDT","U":77965052807,"u":77965052839,"b":[["111705.32000000","3.92201000"],["111700.00000000","1.01168000"],["111677.16000000","0.00005000"],["111677.10000000","0.00000000"],["111677.04000000","0.01390000"],["111619.25000000","0.43989000"],["111597.49000000","0.02070000"],["111592.58000000","0.00000000"],["111466.72000000","0.00000000"],["111434.53000000","0.00000000"],["111349.40000000","0.02685000"],["110029.74000000","0.00100000"],["100534.00000000","0.00020000"],["89364.26000000","0.00022000"]],"a":[["111705.33000000","1.52774000"],["111716.51000000","0.45300000"],["111721.51000000","0.00000000"],["111727.68000000","0.00300000"],["111738.80000000","0.00000000"],["111945.60000000","0.00000000"],["112110.91000000","0.55838000"],["112118.29000000","0.00000000"],["113380.91000000","0.00100000"],["133333.00000000","5.06411000"]]}
[2025-10-12T10:56:38.185Z] {"e":"depthUpdate","E":1760266598014,"s":"BTCUSDT","U":77965052840,"u":77965053123,"b":[["111705.32000000","4.91812000"],["111705.31000000","0.27880000"],["111705.30000000","0.00025000"],["111704.94000000","0.00000000"],["111703.78000000","0.00005000"],["111702.36000000","0.00000000"],["111701.42000000","0.00547000"],["111701.31000000","0.05946000"],["111700.02000000","0.40306000"],["111699.75000000","0.04770000"],["111699.71000000","0.00005000"],["111699.18000000","0.01791000"],["111699.15000000","0.00000000"],["111698.37000000","0.00000000"],["111697.02000000","0.05147000"],["111696.89000000","0.00499000"],["111696.08000000","0.00447000"],["111696.07000000","0.00000000"],["111694.14000000","0.45000000"],["111693.42000000","0.04549000"],["111693.21000000","0.04800000"],["111693.10000000","0.00000000"],["111693.09000000","0.00000000"],["111692.14000000","0.05760000"],["111691.09000000","0.07200000"],["111691.06000000","0.00000000"],["111690.04000000","0.32215000"],["111689.90000000","0.09360000"],["111688.77000000","0.07200000"],["111686.55000000","0.06720000"],["111681.08000000","0.00000000"],["111680.03000000","0.00000000"],["111679.13000000","0.01390000"],["111677.04000000","0.00000000"],["111676.69000000","0.00000000"],["111674.47000000","0.00000000"],["111674.30000000","0.00000000"],["111673.72000000","0.00000000"],["111671.14000000","0.00000000"],["111669.95000000","0.30194000"],["111665.73000000","0.00009000"],["111664.01000000","0.00000000"],["111663.51000000","0.00018000"],["111661.83000000","0.00000000"],["111660.60000000","0.13433000"],["111659.61000000","0.00000000"],["111658.40000000","0.00005000"],["111655.32000000","0.00857000"],["111653.67000000","0.00430000"],["111651.42000000","0.00000000"],["111621.76000000","0.45709000"],["111619.94000000","0.00090000"],["111616.04000000","0.00000000"],["111598.99000000","0.22377000"],["111598.89000000","0.00000000"],["111598.15000000","0.00000000"],["111597.69000000","0.00000000"],["111592.59000000","0.00000000"],["111586.90000000","0.01086000"],["111534.76000000","0.00000000"],["111505.99000000","0.00000000"],["111505.23000000","0.99053000"],["111497.67000000","0.00000000"],["111486.42000000","0.00187000"],["111466.79000000","4.62385000"],["111461.25000000","0.00000000"],["111354.49000000","0.02685000"],["111209.11000000","0.03580000"],["111035.09000000","0.00019000"],["110150.00000000","0.02389000"],["110029.74000000","0.00100000"],["106970.40000000","0.00000000"],["102768.89000000","0.00000000"],["100534.00000000","0.00010000"],["89364.26000000","0.00022000"],["42000.00000000","1.49096000"],["40213.92000000","0.00315000"]],"a":[["111705.33000000","0.95235000"],["111705.34000000","0.03036000"],["111705.72000000","0.01353000"],["111707.56000000","0.00363000"],["111707.87000000","0.00000000"],["111707.88000000","0.00000000"],["111708.74000000","0.00000000"],["111708.75000000","0.00000000"],["111710.35000000","0.00726000"],["111710.54000000","0.00000000"],["111710.55000000","0.00000000"],["111711.46000000","0.00010000"],["111712.65000000","0.00005000"],["111712.66000000","0.04805000"],["111712.78000000","0.05223000"],["111712.95000000","0.00000000"],["111712.97000000","0.02692000"],["111713.62000000","0.30889000"],["111713.63000000","0.29525000"],["111714.82000000","0.00000000"],["111715.81000000","0.00000000"],["111715.82000000","0.00000000"],["111715.94000000","0.00000000"],["111716.51000000","0.45300000"],["111719.10000000","0.17187000"],["111720.01000000","0.00542000"],["111720.07000000","0.00000000"],["111720.34000000","0.00000000"],["111720.81000000","0.00000000"],["111720.82000000","0.04805000"],["111720.92000000","0.05280000"],["111722.08000000","0.00000000"],["111723.94000000","0.00447000"],["111723.95000000","0.15000000"],["111724.73000000","0.00000000"],["111724.99000000","0.00000000"],["111725.01000000","0.00000000"],["111725.07000000","0.00000000"],["111726.37000000","0.00000000"],["111726.80000000","0.00000000"],["111727.67000000","0.11190000"],["111727.69000000","0.45000000"],["111727.98000000","0.00000000"],["111728.26000000","0.00894000"],["111732.61000000","0.00000000"],["111736.07000000","0.00000000"],["111739.99000000","0.32201000"],["111740.98000000","0.00000000"],["111745.56000000","0.72051000"],["111755.30000000","0.32197000"],["111788.31000000","0.00100000"],["111788.32000000","0.00100000"],["111789.22000000","0.00000000"],["111789.23000000","0.00000000"],["111790.21000000","0.00000000"],["111790.22000000","0.00000000"],["111790.23000000","0.00000000"],["111800.29000000","0.00000000"],["111814.98000000","0.00223000"],["111814.99000000","0.00000000"],["111817.04000000","0.00000000"],["111820.39000000","0.00000000"],["111852.10000000","0.04735000"],["111852.11000000","0.09759000"],["111852.16000000","0.00000000"],["111928.33000000","0.00089000"],["111928.34000000","0.00000000"],["111951.16000000","4.84305000"],["112000.11000000","0.00000000"],["112047.03000000","0.00000000"],["112072.31000000","0.00187000"],["112110.91000000","0.00000000"],["112118.29000000","0.55838000"],["112180.01000000","0.00000000"],["112205.29000000","0.00079000"],["113380.91000000","0.00100000"]]}
[2025-10-12T10:56:39.185Z] {"e":"depthUpdate","E":1760266599014,"s":"BTCUSDT","U":77965053124,"u":77965053254,"b":[["111705.32000000","4.27912000"],["111705.31000000","0.27885000"],["111703.78000000","0.00015000"],["111702.65000000","0.01820000"],["111702.37000000","0.00005000"],["111702.36000000","0.17897000"],["111699.73000000","0.11190000"],["111699.71000000","0.04480000"],["111697.02000000","0.05142000"],["111696.34000000","0.00000000"],["111696.08000000","0.00000000"],["111694.82000000","0.93118000"],["111693.43000000","0.00447000"],["111691.85000000","1.25396000"],["111686.32000000","0.00000000"],["111685.14000000","0.00000000"],["111679.13000000","0.00000000"],["111677.11000000","0.01390000"],["111675.97000000","1.22273000"],["111675.47000000","0.00000000"],["111672.69000000","0.22377000"],["111672.63000000","0.30193000"],["111671.78000000","0.27271000"],["111669.95000000","0.00000000"],["111669.94000000","0.00000000"],["111590.75000000","0.16674000"],["111588.81000000","0.00196000"],["111529.93000000","0.02685000"],["111458.99000000","0.00000000"],["111035.09000000","0.00000000"],["110029.74000000","0.00100000"],["100534.00000000","0.00010000"],["89364.26000000","0.00022000"],["40213.92000000","0.00345000"]],"a":[["111705.33000000","3.17306000"],["111705.34000000","0.00296000"],["111705.72000000","0.01353000"],["111706.85000000","0.00010000"],["111706.86000000","0.00005000"],["111710.73000000","0.00000000"],["111712.65000000","0.00010000"],["111712.66000000","0.04800000"],["111712.77000000","0.00000000"],["111712.78000000","0.00005000"],["111712.82000000","0.17187000"],["111713.62000000","0.30889000"],["111713.63000000","0.00000000"],["111717.19000000","0.00000000"],["111718.31000000","0.00000000"],["111719.10000000","0.00000000"],["111720.01000000","0.00537000"],["111720.82000000","0.04800000"],["111724.77000000","0.00000000"],["111724.80000000","0.00000000"],["111735.23000000","0.32202000"],["111745.16000000","1.22157000"],["111745.56000000","0.41049000"],["111745.57000000","0.00000000"],["111755.30000000","0.00000000"],["111814.98000000","0.00000000"],["111815.03000000","0.00223000"],["111827.34000000","0.00196000"],["111925.00000000","0.16956000"],["111928.33000000","0.00000000"],["111928.36000000","0.00089000"],["112092.60000000","0.02398000"],["112118.29000000","0.00000000"],["112121.98000000","0.55838000"],["113380.91000000","0.00100000"]]}
[2025-10-12T10:56:40.185Z] {"e":"depthUpdate","E":1760266600014,"s":"BTCUSDT","U":77965053255,"u":77965053367,"b":[["111705.32000000","4.18438000"],["111705.31000000","0.27880000"],["111702.65000000","0.01820000"],["111702.37000000","0.00000000"],["111702.36000000","0.00005000"],["111701.42000000","0.00552000"],["111699.75000000","0.04775000"],["111694.16000000","0.00000000"],["111691.87000000","0.00000000"],["111688.96000000","0.15000000"],["111677.45000000","0.01390000"],["111677.11000000","0.00000000"],["111630.62000000","0.01401000"],["111593.62000000","0.00088000"],["111486.42000000","0.00000000"],["111477.64000000","0.00187000"],["110029.74000000","0.00100000"],["100534.00000000","0.00010000"],["89364.26000000","0.00022000"],["40213.92000000","0.00360000"]],"a":[["111705.33000000","3.03389000"],["111705.34000000","0.00286000"],["111705.72000000","0.01353000"],["111706.85000000","0.00000000"],["111706.86000000","0.00000000"],["111711.47000000","0.01800000"],["111712.66000000","0.04805000"],["111712.78000000","0.00000000"],["111712.81000000","0.00005000"],["111712.82000000","0.17197000"],["111713.62000000","0.14412000"],["111720.01000000","0.00542000"],["111720.82000000","0.04805000"],["111724.76000000","0.00000000"],["111724.90000000","0.00000000"],["111724.95000000","0.00010000"],["111725.47000000","0.00000000"],["111788.31000000","0.00000000"],["111788.32000000","0.00000000"],["111788.33000000","0.00000000"],["111822.96000000","0.01401000"],["111950.00000000","0.10434000"],["112045.71000000","0.03997000"],["112047.90000000","0.00000000"],["112055.52000000","0.07516000"],["112063.49000000","0.00215000"],["112072.31000000","0.00000000"],["112118.29000000","0.55838000"],["112121.98000000","0.00000000"],["112196.47000000","0.00079000"],["112205.29000000","0.00000000"],["113380.91000000","0.00100000"]]}
[2025-10-12T10:56:41.185Z] {"e":"depthUpdate","E":1760266601014,"s":"BTCUSDT","U":77965053368,"u":77965053474,"b":[["111705.32000000","4.18325000"],["111701.36000000","0.00000000"],["111691.87000000","0.15000000"],["111688.96000000","0.00000000"],["111677.73000000","0.00000000"],["111677.64000000","0.00000000"],["111677.45000000","0.00000000"],["111638.92000000","0.93375000"],["111630.62000000","0.00000000"],["111516.94000000","0.02596000"],["111081.75000000","0.89111000"],["111081.74000000","0.00000000"],["110640.13000000","0.00239000"],["110029.74000000","0.00100000"],["106100.00000000","0.69851000"],["100534.00000000","0.00010000"],["89364.26000000","0.00022000"]],"a":[["111705.33000000","2.83593000"],["111705.34000000","0.00291000"],["111711.47000000","0.01805000"],["111711.86000000","0.00010000"],["111711.87000000","0.05779000"],["111712.66000000","0.04805000"],["111712.81000000","0.29729000"],["111712.82000000","0.17192000"],["111712.97000000","0.02687000"],["111712.99000000","0.29525000"],["111713.62000000","0.00000000"],["111714.24000000","0.00000000"],["111716.61000000","0.04810000"],["111718.77000000","0.04096000"],["111719.81000000","0.00337000"],["111719.89000000","0.04056000"],["111720.01000000","0.00537000"],["111720.82000000","0.04800000"],["111724.80000000","0.00000000"],["111745.15000000","0.77515000"],["111745.56000000","0.00000000"],["111747.59000000","0.01401000"],["111758.94000000","0.00015000"],["111763.41000000","0.00000000"],["111822.96000000","0.00000000"],["112050.46000000","0.02596000"],["112765.49000000","0.00234000"],["113380.91000000","0.00100000"]]}
[2025-10-12T10:56:42.185Z] {"e":"depthUpdate","E":1760266602014,"s":"BTCUSDT","U":77965053475,"u":77965053562,"b":[["111705.32000000","4.18658000"],["111693.43000000","0.00000000"],["111692.15000000","0.00447000"],["111690.05000000","0.35787000"],["111686.33000000","0.00000000"],["111677.92000000","0.00000000"],["111677.14000000","0.01390000"],["111677.08000000","0.00000000"],["111551.86000000","0.00000000"],["111405.32000000","0.00000000"],["110150.00000000","0.02394000"],["110029.74000000","0.00100000"],["106970.40000000","0.00012000"],["103000.00000000","75.27822000"],["102000.00000000","86.39847000"],["100534.00000000","0.00010000"],["89364.26000000","0.00022000"],["33000.00000000","3.87311000"]],"a":[["111705.33000000","2.95543000"],["111705.34000000","0.00291000"],["111711.87000000","0.05779000"],["111712.56000000","0.00000000"],["111712.57000000","0.00000000"],["111712.65000000","0.00005000"],["111712.66000000","0.04805000"],["111712.81000000","0.20346000"],["111712.82000000","0.17192000"],["111712.99000000","0.00000000"],["111715.35000000","0.00000000"],["111719.84000000","0.00447000"],["111720.01000000","0.00542000"],["111723.94000000","0.35787000"],["111724.92000000","0.00000000"],["111725.33000000","0.00000000"],["111735.23000000","0.00000000"],["111735.52000000","0.00000000"],["111751.52000000","0.00000000"],["111751.70000000","0.32198000"],["111940.00000000","0.00189000"],["112118.29000000","0.55838000"],["113380.91000000","0.00100000"]]}
[2025-10-12T10:56:43.185Z] {"e":"depthUpdate","E":1760266603014,"s":"BTCUSDT","U":77965053563,"u":77965053923,"b":[["111705.32000000","4.33596000"],["111705.31000000","0.27855000"],["111704.93000000","0.01358000"],["111703.79000000","0.00010000"],["111703.78000000","0.40326000"],["111703.77000000","0.29532000"],["111703.09000000","0.00368000"],["111702.94000000","0.00000000"],["111702.93000000","0.02692000"],["111702.36000000","0.00000000"],["111702.35000000","0.06651000"],["111702.29000000","0.00499000"],["111701.42000000","0.00547000"],["111700.40000000","0.00005000"],["111699.75000000","0.04770000"],["111699.71000000","0.04480000"],["111697.02000000","0.05142000"],["111696.89000000","0.00000000"],["111695.75000000","0.00894000"],["111694.41000000","0.00000000"],["111693.42000000","0.00000000"],["111686.16000000","0.00000000"],["111676.05000000","1.21020000"],["111675.97000000","0.00000000"],["111674.58000000","0.04171000"],["111674.02000000","0.00000000"],["111673.84000000","0.00000000"],["111672.69000000","0.00000000"],["111671.13000000","0.00009000"],["111668.91000000","0.00018000"],["111665.73000000","0.00000000"],["111663.51000000","0.00000000"],["111660.72000000","0.00009000"],["111658.40000000","0.00005000"],["111655.32000000","0.00848000"],["111625.34000000","0.00090000"],["111619.94000000","0.00000000"],["111599.05000000","0.22377000"],["111598.99000000","0.00000000"],["111598.86000000","0.00000000"],["111598.58000000","0.00000000"],["111598.47000000","0.00000000"],["111598.06000000","0.22377000"],["111505.23000000","0.00000000"],["111503.57000000","0.99890000"],["111497.11000000","0.00000000"],["110640.13000000","0.00000000"],["110029.74000000","0.00100000"],["102768.89000000","0.00010000"],["100534.00000000","0.00010000"],["89364.26000000","0.00022000"],["40213.92000000","0.00375000"]],"a":[["111705.33000000","2.60943000"],["111705.34000000","0.00291000"],["111711.47000000","0.01805000"],["111711.50000000","0.00005000"],["111711.52000000","0.00000000"],["111711.86000000","0.00000000"],["111711.87000000","0.00000000"],["111712.16000000","0.00010000"],["111712.17000000","0.05782000"],["111712.65000000","0.00010000"],["111712.66000000","0.04810000"],["111712.81000000","0.00000000"],["111712.82000000","0.00000000"],["111712.97000000","0.00000000"],["111714.53000000","0.00000000"],["111714.54000000","0.00000000"],["111714.55000000","0.00000000"],["111714.56000000","0.02692000"],["111715.12000000","0.00000000"],["111716.36000000","0.26389000"],["111716.37000000","0.29529000"],["111716.50000000","0.00039000"],["111716.51000000","0.45300000"],["111716.61000000","0.00005000"],["111718.77000000","0.00000000"],["111718.89000000","0.00000000"],["111719.81000000","0.00332000"],["111719.84000000","0.00000000"],["111719.89000000","0.00000000"],["111720.01000000","0.00542000"],["111720.03000000","0.17187000"],["111720.81000000","0.00000000"],["111720.82000000","0.04805000"],["111720.92000000","0.05285000"],["111721.09000000","0.00000000"],["111721.21000000","0.00000000"],["111721.98000000","0.06720000"],["111722.16000000","0.00006000"],["111722.39000000","0.04074000"],["111723.51000000","0.04069000"],["111723.93000000","0.00447000"],["111723.94000000","0.00000000"],["111723.95000000","0.00000000"],["111724.89000000","0.00000000"],["111725.06000000","0.00068000"],["111725.67000000","0.35787000"],["111725.68000000","0.00000000"],["111725.85000000","0.00075000"],["111726.68000000","0.08000000"],["111727.39000000","0.00000000"],["111727.98000000","0.15000000"],["111728.26000000","0.00000000"],["111728.65000000","0.04800000"],["111729.57000000","0.31485000"],["111729.58000000","0.48000000"],["111730.49000000","0.00000000"],["111733.82000000","0.00894000"],["111735.28000000","0.00000000"],["111737.50000000","0.00000000"],["111739.99000000","0.00000000"],["111740.41000000","0.32201000"],["111745.15000000","0.37025000"],["111745.16000000","0.00000000"],["111748.47000000","1.20559000"],["111756.80000000","0.00000000"],["111757.71000000","0.07200000"],["111770.75000000","0.00000000"],["111773.88000000","0.06870000"],["111779.10000000","0.00223000"],["111779.98000000","0.00000000"],["111815.02000000","0.00223000"],["111815.03000000","0.00000000"],["111816.63000000","0.02392000"],["111827.17000000","0.04800000"],["111867.84000000","0.00000000"],["111890.16000000","0.02687000"],["111928.35000000","0.00089000"],["111928.36000000","0.00000000"],["112118.29000000","0.00000000"],["112121.98000000","0.55838000"],["112765.49000000","0.00000000"],["113000.00000000","46.14537000"],["113380.91000000","0.00100000"],["114000.00000000","14.45703000"]]}
[2025-10-12T10:56:44.185Z] {"e":"depthUpdate","E":1760266604014,"s":"BTCUSDT","U":77965053924,"u":77965053996,"b":[["111705.32000000","4.10038000"],["111699.94000000","0.00006000"],["111699.75000000","0.04775000"],["111697.02000000","0.05137000"],["111685.03000000","0.00000000"],["111674.04000000","0.22377000"],["111673.94000000","0.22377000"],["111672.63000000","0.00000000"],["111669.81000000","0.30193000"],["111643.90000000","0.01401000"],["111583.46000000","0.09894000"],["111569.93000000","0.00000000"],["111560.36000000","0.08795000"],["111537.09000000","0.05430000"],["111520.56000000","0.00000000"],["111512.53000000","0.00000000"],["111085.43000000","0.89111000"],["111081.75000000","0.00000000"],["110029.74000000","0.00100000"],["102768.89000000","0.00000000"],["100534.00000000","0.00010000"],["92500.00000000","3.56642000"],["89364.26000000","0.00022000"],["60000.00000000","53.14032000"]],"a":[["111705.33000000","2.78374000"],["111705.34000000","0.00296000"],["111712.66000000","0.04810000"],["111714.11000000","0.17192000"],["111714.56000000","0.02692000"],["111716.36000000","0.26389000"],["111716.37000000","0.29524000"],["111720.01000000","0.00547000"],["111720.03000000","0.00000000"],["111720.81000000","0.00447000"],["111720.92000000","0.05280000"],["111722.39000000","0.00000000"],["111723.50000000","0.35787000"],["111723.93000000","0.00000000"],["111725.67000000","0.00000000"],["111732.54000000","0.04800000"],["111745.15000000","0.71290000"],["111749.17000000","0.00000000"],["111790.26000000","0.00100000"],["111790.27000000","0.00100000"],["111814.61000000","0.00000000"],["111821.09000000","0.08897000"],["111827.17000000","0.00000000"],["113380.91000000","0.00100000"]]}
[2025-10-12T10:56:45.185Z] {"e":"depthUpdate","E":1760266605014,"s":"BTCUSDT","U":77965053997,"u":77965054021,"b":[["111705.32000000","4.10060000"],["111643.90000000","0.00000000"],["111606.42000000","0.07516000"],["111600.09000000","0.00000000"],["110029.74000000","0.00100000"],["89364.26000000","0.00022000"],["60000.00000000","53.14022000"],["40213.92000000","0.00405000"]],"a":[["111705.33000000","2.78541000"],["111722.42000000","0.00000000"],["111747.59000000","0.00000000"],["111773.88000000","0.00000000"],["111773.91000000","0.06855000"],["112118.29000000","0.55838000"],["112121.98000000","0.00000000"],["113380.91000000","0.00100000"]]}
[2025-10-12T10:56:46.185Z] {"e":"depthUpdate","E":1760266606014,"s":"BTCUSDT","U":77965054022,"u":77965054086,"b":[["111705.32000000","4.10070000"],["111484.58000000","0.00187000"],["111477.64000000","0.00000000"],["110029.74000000","0.00100000"],["109500.00000000","12.93539000"],["108000.00000000","92.78307000"],["100534.00000000","0.00010000"],["89364.26000000","0.00022000"],["42000.00000000","1.49196000"],["33000.00000000","3.87311000"]],"a":[["111705.33000000","2.79593000"],["111705.34000000","0.00301000"],["111712.66000000","0.04810000"],["111714.11000000","0.17192000"],["111714.56000000","0.00000000"],["111714.59000000","0.00000000"],["111714.63000000","0.02692000"],["111716.36000000","0.20692000"],["111716.37000000","0.00000000"],["111716.47000000","0.29524000"],["111716.51000000","0.45300000"],["111719.04000000","0.00000000"],["111722.43000000","0.00000000"],["111745.01000000","0.18862000"],["112063.49000000","0.00028000"],["112070.47000000","0.00187000"],["112196.47000000","0.00000000"],["112203.45000000","0.00079000"],["113380.91000000","0.00100000"]]}
[2025-10-12T10:56:47.185Z] {"e":"depthUpdate","E":1760266607014,"s":"BTCUSDT","U":77965054087,"u":77965054208,"b":[["111705.32000000","3.95917000"],["111705.28000000","0.35195000"],["111702.29000000","0.00509000"],["111702.26000000","0.04000000"],["111702.23000000","0.00100000"],["111699.73000000","0.00000000"],["111697.02000000","0.05132000"],["111694.14000000","0.56190000"],["111674.58000000","0.00000000"],["111669.81000000","0.00000000"],["111667.75000000","0.00000000"],["111664.01000000","0.30195000"],["111661.89000000","0.04171000"],["111503.57000000","0.00000000"],["111497.11000000","0.99528000"],["111494.65000000","0.00089000"],["111494.64000000","0.00187000"],["111494.01000000","0.00000000"],["111484.58000000","0.00000000"],["111456.55000000","0.02596000"],["110331.45000000","0.00000000"],["110029.74000000","0.00100000"],["106100.00000000","0.69851000"],["100534.00000000","0.00010000"],["89364.26000000","0.00022000"]],"a":[["111705.33000000","2.98301000"],["111705.34000000","0.00065000"],["111705.72000000","0.01358000"],["111706.56000000","0.00010000"],["111706.57000000","0.04545000"],["111706.75000000","0.00000000"],["111708.59000000","0.00010000"],["111708.60000000","0.17197000"],["111711.47000000","0.01800000"],["111712.16000000","0.00000000"],["111712.17000000","0.00000000"],["111712.65000000","0.00000000"],["111712.66000000","0.04805000"],["111713.98000000","0.23163000"],["111713.99000000","0.29524000"],["111714.11000000","0.00000000"],["111714.24000000","0.00005000"],["111714.63000000","0.02687000"],["111716.36000000","0.00000000"],["111716.47000000","0.00000000"],["111720.82000000","0.04805000"],["111722.43000000","0.03992000"],["111725.85000000","0.00005000"],["111725.95000000","0.00100000"],["111758.94000000","0.00010000"],["112070.47000000","0.00000000"],["112080.57000000","0.00187000"],["112118.29000000","0.00000000"],["112125.66000000","0.55838000"],["112203.45000000","0.00000000"],["112213.55000000","0.00079000"],["113380.91000000","0.00100000"],["145260.00000000","0.00004000"]]}
[2025-10-12T10:56:48.185Z] {"e":"depthUpdate","E":1760266608014,"s":"BTCUSDT","U":77965054209,"u":77965054231,"b":[["111705.32000000","3.95731000"],["111692.15000000","0.00000000"],["111691.10000000","0.00447000"],["110029.74000000","0.00100000"],["100534.00000000","0.00010000"],["89364.26000000","0.00022000"],["42000.00000000","1.49096000"]],"a":[["111705.33000000","2.98090000"],["111705.34000000","0.00060000"],["112118.29000000","0.55838000"],["112125.66000000","0.00000000"],["113380.91000000","0.00100000"]]}
[2025-10-12T10:56:49.185Z] {"e":"depthUpdate","E":1760266609014,"s":"BTCUSDT","U":77965054232,"u":77965054334,"b":[["111705.32000000","3.95098000"],["111705.28000000","0.25334000"],["111705.16000000","0.00905000"],["111705.10000000","0.00100000"],["111704.93000000","0.01358000"],["111703.79000000","0.00000000"],["111703.78000000","0.00015000"],["111702.36000000","0.00005000"],["111702.35000000","0.06656000"],["111702.29000000","0.00504000"],["111702.23000000","0.00000000"],["111697.02000000","0.05132000"],["111691.87000000","0.15000000"],["111689.66000000","0.13543000"],["111688.96000000","0.00000000"],["111688.02000000","0.00000000"],["111676.05000000","0.00000000"],["111497.11000000","0.99815000"],["111466.79000000","0.00000000"],["110029.74000000","0.00100000"],["102768.90000000","0.00000000"],["100534.00000000","0.00010000"],["89364.26000000","0.00022000"],["89364.00000000","0.00000000"],["40213.92000000","0.00420000"]],"a":[["111705.33000000","2.97711000"],["111705.34000000","0.00055000"],["111705.72000000","0.01353000"],["111706.56000000","0.00000000"],["111706.57000000","0.00000000"],["111712.65000000","0.00005000"],["111712.66000000","0.04810000"],["111713.99000000","0.29529000"],["111714.63000000","0.02692000"],["111718.31000000","0.00000000"],["111719.80000000","0.00447000"],["111720.01000000","0.00542000"],["111720.81000000","0.00000000"],["111720.92000000","0.05285000"],["111735.67000000","0.32202000"],["111751.70000000","0.00000000"],["111773.91000000","0.00000000"],["111773.98000000","0.06666000"],["111917.47000000","0.00000000"],["111924.03000000","0.07516000"],["111951.16000000","0.00000000"],["112185.78000000","0.00000000"],["113380.91000000","0.00100000"]]}
[2025-10-12T10:56:50.200Z] {"e":"depthUpdate","E":1760266610014,"s":"BTCUSDT","U":77965054335,"u":77965054467,"b":[["111705.32000000","4.51745000"],["111705.28000000","0.25245000"],["111702.35000000","0.06656000"],["111702.29000000","0.00499000"],["111702.26000000","0.00000000"],["111697.02000000","0.05137000"],["111674.58000000","0.00000000"],["111674.04000000","0.00000000"],["111673.94000000","0.00000000"],["111669.81000000","0.30194000"],["111664.01000000","0.00000000"],["111658.40000000","0.00005000"],["111645.48000000","0.01401000"],["111599.05000000","0.00000000"],["111598.95000000","0.22377000"],["111598.22000000","0.22377000"],["111598.06000000","0.00000000"],["111502.77000000","0.99707000"],["111497.11000000","0.00000000"],["111496.65000000","0.08795000"],["111471.38000000","4.68533000"],["111085.43000000","0.89111000"],["110029.74000000","0.00100000"],["109000.00000000","95.75033000"],["100534.00000000","0.00010000"],["89364.26000000","0.00022000"]],"a":[["111705.33000000","2.79336000"],["111705.34000000","0.00050000"],["111705.72000000","0.01353000"],["111706.75000000","0.00005000"],["111708.59000000","0.00000000"],["111708.60000000","0.00000000"],["111709.95000000","0.00000000"],["111712.65000000","0.00010000"],["111712.66000000","0.04810000"],["111713.97000000","0.00005000"],["111713.98000000","0.17197000"],["111713.99000000","0.00000000"],["111714.24000000","0.00000000"],["111714.59000000","0.02692000"],["111714.63000000","0.00005000"],["111716.50000000","0.22382000"],["111716.51000000","0.45300000"],["111716.78000000","0.00000000"],["111717.10000000","0.29524000"],["111720.92000000","0.05285000"],["111721.98000000","0.06720000"],["111722.16000000","0.00000000"],["111722.43000000","0.00000000"],["111723.51000000","0.00000000"],["111723.96000000","0.40306000"],["111723.97000000","2.18114000"],["111724.84000000","0.00070000"],["111725.95000000","0.00000000"],["111727.98000000","0.00000000"],["111729.56000000","0.15000000"],["111735.67000000","0.00000000"],["111748.47000000","0.00000000"],["111752.05000000","0.32198000"],["111758.94000000","0.00015000"],["111763.41000000","0.00000000"],["111773.98000000","0.00000000"],["111774.44000000","0.06621000"],["111822.93000000","0.01401000"],["111950.10000000","0.08795000"],["111951.02000000","4.81163000"],["112118.29000000","0.00000000"],["113380.91000000","0.00100000"]]}
[2025-10-12T10:56:51.185Z] {"e":"depthUpdate","E":1760266611014,"s":"BTCUSDT","U":77965054468,"u":77965054575,"b":[["111705.32000000","4.06962000"],["111705.27000000","0.23558000"],["111705.26000000","0.01345000"],["111705.25000000","0.00020000"],["111705.19000000","0.00000000"],["111704.93000000","0.01353000"],["111702.35000000","0.06651000"],["111691.87000000","0.15000000"],["111688.96000000","0.00000000"],["111676.59000000","1.18557000"],["111673.72000000","0.22377000"],["111672.61000000","0.78308000"],["111494.64000000","0.00000000"],["111486.68000000","0.00187000"],["110029.74000000","0.00100000"],["100534.00000000","0.00010000"],["89364.26000000","0.00022000"],["40213.92000000","0.00450000"],["33000.00000000","3.87311000"]],"a":[["111705.33000000","2.84293000"],["111705.34000000","0.00050000"],["111709.83000000","0.17187000"],["111711.47000000","0.01805000"],["111711.84000000","0.00010000"],["111711.85000000","0.05005000"],["111712.66000000","0.04810000"],["111713.97000000","0.00000000"],["111713.98000000","0.00005000"],["111714.59000000","0.00000000"],["111714.64000000","0.00000000"],["111714.65000000","0.00005000"],["111714.66000000","0.02687000"],["111716.50000000","0.22377000"],["111720.92000000","0.05280000"],["111722.43000000","0.00000000"],["111722.65000000","0.04112000"],["111723.55000000","0.04021000"],["111745.15000000","0.37025000"],["111750.75000000","1.17307000"],["111750.83000000","1.21443000"],["112072.58000000","0.00187000"],["112080.57000000","0.00000000"],["112205.56000000","0.00079000"],["112213.55000000","0.00000000"],["113380.91000000","0.00100000"],["133333.00000000","5.06424000"]]}
[2025-10-12T10:56:52.185Z] {"e":"depthUpdate","E":1760266612014,"s":"BTCUSDT","U":77965054576,"u":77965054653,"b":[["111705.32000000","3.96442000"],["111690.80000000","0.00000000"],["111669.81000000","0.00000000"],["111668.05000000","0.30194000"],["111000.00000000","16.83904000"],["110029.74000000","0.00100000"],["106100.00000000","0.69862000"],["100534.79000000","0.00156000"],["100534.00000000","0.00010000"],["100393.33000000","0.00012000"],["89364.26000000","0.00022000"]],"a":[["111705.33000000","2.85355000"],["111705.34000000","0.00067000"],["111705.72000000","0.01353000"],["111709.23000000","0.00542000"],["111709.82000000","0.00010000"],["111709.83000000","0.17197000"],["111712.65000000","0.00000000"],["111712.66000000","0.04805000"],["111713.98000000","0.00000000"],["111714.65000000","0.00000000"],["111714.66000000","0.00000000"],["111714.70000000","0.02692000"],["111719.85000000","0.00000000"],["111720.82000000","0.04805000"],["111720.92000000","0.05285000"],["111733.33000000","0.00007000"],["111733.73000000","0.01390000"],["111764.54000000","0.00000000"],["111822.93000000","0.00000000"],["111836.81000000","0.01401000"],["112118.29000000","0.55838000"],["113380.91000000","0.00100000"],["125000.99000000","0.00053000"]]}
[2025-10-12T10:56:53.185Z] {"e":"depthUpdate","E":1760266613014,"s":"BTCUSDT","U":77965054654,"u":77965054796,"b":[["111705.32000000","3.76634000"],["111705.28000000","0.41054000"],["111705.26000000","0.01345000"],["111705.17000000","0.00000000"],["111705.16000000","0.00905000"],["111705.10000000","0.00000000"],["111704.93000000","0.01353000"],["111703.09000000","0.00368000"],["111702.36000000","0.00005000"],["111702.16000000","0.04000000"],["111701.44000000","0.45020000"],["111701.43000000","0.00000000"],["111701.42000000","0.00547000"],["111700.31000000","0.17893000"],["111700.30000000","0.00721000"],["111699.18000000","0.01791000"],["111697.02000000","0.05132000"],["111694.15000000","0.00000000"],["111692.15000000","0.00447000"],["111691.87000000","0.15000000"],["111691.10000000","0.00000000"],["111688.96000000","0.00000000"],["111483.64000000","0.03000000"],["111471.38000000","0.00000000"],["111085.43000000","0.89111000"],["111035.09000000","0.00000000"],["110029.74000000","0.00100000"],["108211.00000000","0.01658000"],["106100.00000000","0.69851000"],["100534.79000000","0.00168000"],["100534.00000000","0.00010000"],["100393.33000000","0.00000000"],["89364.26000000","0.00022000"]],"a":[["111705.33000000","3.49620000"],["111705.34000000","0.00067000"],["111705.49000000","0.00905000"],["111705.68000000","0.00010000"],["111705.69000000","0.05095000"],["111705.72000000","0.01353000"],["111707.56000000","0.00363000"],["111709.23000000","0.00547000"],["111709.26000000","0.00000000"],["111709.83000000","0.17197000"],["111710.35000000","0.00726000"],["111711.47000000","0.01800000"],["111711.84000000","0.00000000"],["111711.85000000","0.00000000"],["111714.63000000","0.00000000"],["111714.70000000","0.02692000"],["111714.75000000","0.22351000"],["111714.76000000","0.29524000"],["111716.50000000","0.00039000"],["111717.10000000","0.00000000"],["111719.80000000","0.00000000"],["111720.92000000","0.05290000"],["111721.97000000","0.00447000"],["111721.98000000","0.06725000"],["111727.52000000","0.00000000"],["111727.98000000","0.00000000"],["111729.56000000","0.15000000"],["111735.28000000","0.00000000"],["111735.49000000","0.32202000"],["111752.05000000","0.00000000"],["111951.02000000","0.00000000"],["113380.91000000","0.00100000"]]}
[2025-10-12T10:56:54.187Z] {"e":"depthUpdate","E":1760266614014,"s":"BTCUSDT","U":77965054797,"u":77965054879,"b":[["111705.32000000","3.77829000"],["111705.31000000","0.27860000"],["111705.16000000","0.00900000"],["111702.35000000","0.06651000"],["111702.31000000","0.00499000"],["111702.29000000","0.00005000"],["111701.88000000","0.00100000"],["111688.00000000","0.45028000"],["111676.59000000","0.00000000"],["111668.05000000","0.00000000"],["111664.01000000","0.30195000"],["111627.70000000","0.24819000"],["111623.00000000","0.00000000"],["111591.61000000","0.00196000"],["111588.81000000","0.00000000"],["111483.64000000","0.00000000"],["111471.04000000","4.75478000"],["111085.43000000","0.89111000"],["110683.00000000","0.00000000"],["110292.00000000","0.00045000"],["110029.74000000","0.00100000"],["110000.00000000","26.25041000"],["109421.05000000","0.00000000"],["109289.00000000","0.04044000"],["108842.10000000","0.00000000"],["108731.00000000","0.00000000"],["108263.15000000","0.00005000"],["107684.21000000","0.00009000"],["107105.26000000","0.00025000"],["106526.31000000","0.00000000"],["105947.36000000","0.00000000"],["105368.42000000","0.00010000"],["104789.47000000","0.00006000"],["104210.52000000","0.00281000"],["103631.57000000","0.00000000"],["103052.63000000","0.00134000"],["102768.90000000","0.00010000"],["102473.68000000","0.00000000"],["101894.73000000","0.00000000"],["101315.78000000","0.00092000"],["100736.84000000","0.00000000"],["100534.00000000","0.00010000"],["100157.89000000","0.00000000"],["99578.94000000","0.00000000"],["99000.00000000","298.98344000"],["89364.26000000","0.00022000"],["60000.00000000","53.14032000"]],"a":[["111705.33000000","3.48756000"],["111706.75000000","0.00000000"],["111714.24000000","0.00005000"],["111724.22000000","0.00100000"],["111733.09000000","0.01390000"],["111733.73000000","0.00000000"],["111750.75000000","0.76893000"],["111750.83000000","0.00000000"],["111758.94000000","0.00010000"],["111774.44000000","0.00000000"],["111774.55000000","0.06783000"],["111790.25000000","0.00100000"],["111790.27000000","0.00000000"],["111815.49000000","0.00000000"],["111822.41000000","0.06013000"],["111827.34000000","0.00000000"],["111830.74000000","0.00196000"],["111925.00000000","0.00036000"],["111954.15000000","4.77147000"],["112162.00000000","0.00000000"],["112188.00000000","0.01932000"],["113380.91000000","0.00100000"]]}
[2025-10-12T10:56:55.185Z] {"e":"depthUpdate","E":1760266615014,"s":"BTCUSDT","U":77965054880,"u":77965054975,"b":[["111705.32000000","3.71582000"],["111702.16000000","0.04005000"],["111699.71000000","0.04480000"],["111692.15000000","0.00000000"],["111690.80000000","0.09398000"],["111690.06000000","0.00447000"],["111681.90000000","0.00000000"],["111674.24000000","1.16603000"],["111669.29000000","0.04375000"],["111612.05000000","0.00000000"],["111612.02000000","0.00163000"],["111565.04000000","0.02417000"],["111500.23000000","0.00000000"],["111500.20000000","0.00065000"],["110029.74000000","0.00100000"],["110000.00000000","26.25540000"],["109421.05000000","0.00528000"],["108842.10000000","0.00558000"],["108263.15000000","0.00592000"],["107684.21000000","0.00626000"],["107105.26000000","0.00673000"],["106526.31000000","0.00678000"],["105947.36000000","0.00709000"],["105368.42000000","0.00751000"],["104789.47000000","0.00778000"],["104210.52000000","0.01085000"],["103631.57000000","0.00837000"],["103052.63000000","0.01003000"],["102768.90000000","0.00000000"],["102473.68000000","0.00903000"],["101894.73000000","0.00936000"],["101315.78000000","0.01062000"],["100736.84000000","0.01004000"],["100534.00000000","0.00010000"],["100157.89000000","0.01039000"],["99578.94000000","0.01074000"],["99000.00000000","298.99453000"],["89364.26000000","0.00022000"],["60000.00000000","53.14022000"],["42000.00000000","1.49196000"],["40213.92000000","0.00480000"]],"a":[["111705.33000000","4.10422000"],["111719.85000000","0.09089000"],["111721.98000000","0.06720000"],["111724.71000000","0.00000000"],["111724.84000000","0.00000000"],["111745.15000000","0.70370000"],["111748.31000000","1.18880000"],["111774.55000000","0.00000000"],["111774.57000000","0.06850000"],["111790.25000000","0.00000000"],["111790.27000000","0.00100000"],["111825.57000000","0.01401000"],["111836.81000000","0.00000000"],["111926.77000000","0.02417000"],["113000.00000000","46.14552000"],["113380.91000000","0.00100000"],["145460.00000000","0.00004000"]]}
[2025-10-12T10:56:56.185Z] {"e":"depthUpdate","E":1760266616014,"s":"BTCUSDT","U":77965054976,"u":77965055386,"b":[["111705.32000000","0.86182000"],["111705.31000000","0.27865000"],["111705.30000000","0.00020000"],["111705.28000000","0.36723000"],["111703.79000000","0.00365000"],["111703.78000000","0.00010000"],["111703.77000000","0.00005000"],["111702.93000000","0.00005000"],["111702.65000000","0.00005000"],["111702.36000000","0.00000000"],["111702.35000000","0.00005000"],["111702.31000000","0.00000000"],["111702.29000000","0.00000000"],["111702.16000000","0.00000000"],["111701.88000000","0.00000000"],["111701.56000000","0.00000000"],["111701.45000000","0.00005000"],["111701.44000000","0.00000000"],["111700.83000000","0.00000000"],["111700.73000000","0.00005000"],["111700.31000000","0.00000000"],["111700.02000000","0.00000000"],["111699.75000000","0.04770000"],["111699.71000000","0.00005000"],["111699.61000000","0.00000000"],["111699.18000000","0.01791000"],["111699.06000000","0.00000000"],["111697.03000000","0.00000000"],["111697.02000000","0.05137000"],["111695.67000000","0.00000000"],["111695.50000000","0.00000000"],["111695.39000000","0.00100000"],["111695.20000000","0.00000000"],["111694.84000000","0.00005000"],["111694.82000000","0.63857000"],["111694.15000000","0.00000000"],["111694.14000000","0.45000000"],["111694.12000000","0.00000000"],["111691.87000000","0.00000000"],["111691.85000000","0.00000000"],["111691.84000000","0.00000000"],["111691.77000000","0.04000000"],["111690.06000000","0.00000000"],["111690.05000000","0.00000000"],["111690.04000000","0.00000000"],["111689.66000000","0.00000000"],["111688.96000000","0.00000000"],["111688.56000000","0.00000000"],["111688.06000000","0.00000000"],["111688.05000000","0.00000000"],["111688.04000000","0.00000000"],["111685.90000000","0.00000000"],["111685.80000000","0.00000000"],["111685.53000000","0.00000000"],["111684.68000000","0.15000000"],["111684.66000000","0.00000000"],["111684.01000000","0.00000000"],["111683.55000000","0.00000000"],["111682.97000000","0.11190000"],["111682.95000000","0.00005000"],["111680.88000000","0.00000000"],["111680.34000000","0.00000000"],["111677.28000000","0.00000000"],["111677.14000000","0.00000000"],["111675.68000000","0.00000000"],["111674.24000000","0.00000000"],["111673.94000000","0.32220000"],["111671.13000000","0.00000000"],["111669.29000000","0.00000000"],["111669.26000000","0.00000000"],["111668.91000000","0.00000000"],["111668.34000000","0.32222000"],["111666.21000000","0.13426000"],["111664.01000000","0.00000000"],["111661.89000000","0.00000000"],["111660.72000000","0.00000000"],["111660.67000000","0.00000000"],["111660.60000000","0.13438000"],["111658.38000000","0.00000000"],["111656.13000000","0.00005000"],["111655.93000000","0.13426000"],["111655.33000000","0.00000000"],["111654.66000000","0.04375000"],["111640.21000000","0.00000000"],["111627.62000000","0.04171000"],["111625.34000000","0.00000000"],["111617.37000000","0.00000000"],["111612.03000000","0.00000000"],["111612.02000000","0.00000000"],["111606.70000000","0.00000000"],["111603.65000000","0.13426000"],["111593.37000000","0.13426000"],["111554.26000000","0.00000000"],["111554.20000000","0.00000000"],["111502.77000000","0.00000000"],["111500.21000000","0.00000000"],["111500.20000000","0.00000000"],["111389.33000000","0.00000000"],["111350.10000000","0.03580000"],["111085.43000000","0.89111000"],["111000.00000000","16.83910000"],["110029.74000000","0.00100000"],["103997.00000000","0.00006000"],["100534.00000000","0.00010000"],["89364.26000000","0.00022000"]],"a":[["111705.33000000","5.03973000"],["111705.34000000","0.00032000"],["111705.72000000","0.01353000"],["111706.45000000","0.00000000"],["111707.56000000","0.00368000"],["111708.43000000","0.04019000"],["111709.21000000","0.00447000"],["111709.22000000","0.17015000"],["111709.55000000","0.03950000"],["111709.77000000","0.00005000"],["111709.82000000","0.00000000"],["111709.83000000","0.17192000"],["111710.29000000","0.00005000"],["111710.35000000","0.00726000"],["111710.83000000","0.00000000"],["111710.90000000","0.00000000"],["111710.91000000","0.11195000"],["111711.03000000","0.00000000"],["111711.46000000","0.00000000"],["111711.47000000","0.01790000"],["111711.95000000","0.00000000"],["111712.15000000","0.00000000"],["111712.63000000","0.36873000"],["111712.64000000","0.00000000"],["111712.66000000","0.04805000"],["111713.66000000","0.08504000"],["111713.89000000","0.06646000"],["111714.50000000","0.00400000"],["111714.70000000","0.02692000"],["111714.75000000","0.00000000"],["111714.76000000","0.00000000"],["111716.49000000","0.35787000"],["111716.50000000","0.40345000"],["111717.73000000","0.00100000"],["111718.34000000","0.04005000"],["111718.71000000","0.08509000"],["111719.18000000","0.01818000"],["111719.28000000","0.00000000"],["111719.81000000","0.00332000"],["111719.85000000","0.09089000"],["111720.00000000","0.09154000"],["111720.01000000","0.00537000"],["111720.06000000","0.15000000"],["111720.07000000","0.40306000"],["111720.82000000","0.04800000"],["111720.92000000","0.05280000"],["111720.95000000","0.13426000"],["111721.97000000","0.00000000"],["111722.65000000","0.00000000"],["111723.50000000","0.00000000"],["111723.55000000","0.00000000"],["111723.95000000","0.00000000"],["111724.22000000","0.00000000"],["111725.06000000","0.00000000"],["111725.19000000","0.06646000"],["111725.42000000","0.00000000"],["111726.10000000","0.32205000"],["111727.67000000","0.00000000"],["111728.24000000","0.32204000"],["111729.56000000","0.00000000"],["111731.54000000","0.00000000"],["111731.90000000","0.18864000"],["111734.74000000","0.00000000"],["111735.29000000","1.25502000"],["111736.76000000","0.00000000"],["111736.80000000","0.17904000"],["111737.13000000","0.00000000"],["111744.97000000","0.00000000"],["111745.01000000","0.00000000"],["111749.57000000","0.00000000"],["111752.45000000","0.00000000"],["111753.77000000","0.13433000"],["111754.47000000","0.00000000"],["111765.69000000","0.02392000"],["111780.55000000","0.00000000"],["111781.61000000","0.13433000"],["111797.83000000","0.00000000"],["111798.71000000","0.02130000"],["111811.85000000","0.00000000"],["111812.31000000","0.00000000"],["111813.48000000","0.00000000"],["111813.55000000","0.09759000"],["111813.81000000","0.13433000"],["111814.19000000","0.17904000"],["111816.63000000","0.00000000"],["111816.78000000","0.00000000"],["111817.02000000","0.01377000"],["111834.91000000","0.08695000"],["111837.29000000","0.08695000"],["111839.02000000","0.08695000"],["111852.11000000","0.00000000"],["111890.16000000","0.00000000"],["111923.13000000","0.00000000"],["111924.34000000","0.00000000"],["111969.21000000","0.00000000"],["111969.53000000","0.00000000"],["111970.71000000","0.00000000"],["111979.25000000","0.00000000"],["113380.91000000","0.00100000"]]}
[2025-10-12T10:56:57.191Z] {"e":"depthUpdate","E":1760266617018,"s":"BTCUSDT","U":77965055387,"u":77965057550,"b":[["111705.32000000","0.00000000"],["111705.31000000","0.00000000"],["111705.30000000","0.00000000"],["111705.29000000","0.00000000"],["111705.28000000","0.00000000"],["111705.27000000","0.00000000"],["111705.26000000","0.00000000"],["111705.25000000","0.00000000"],["111705.20000000","0.00000000"],["111705.19000000","0.00000000"],["111705.16000000","0.00000000"],["111704.93000000","0.00000000"],["111704.51000000","0.00000000"],["111704.20000000","0.00000000"],["111703.79000000","0.00000000"],["111703.78000000","0.00000000"],["111703.77000000","0.00000000"],["111703.43000000","0.00000000"],["111703.09000000","0.00000000"],["111703.08000000","0.00000000"],["111702.93000000","0.00000000"],["111702.65000000","0.00000000"],["111702.40000000","0.00000000"],["111702.35000000","0.00000000"],["111702.32000000","0.00000000"],["111701.45000000","0.00000000"],["111701.42000000","0.00000000"],["111701.41000000","0.00000000"],["111701.32000000","0.00000000"],["111701.31000000","0.00000000"],["111700.75000000","0.00000000"],["111700.74000000","0.00000000"],["111700.73000000","0.00000000"],["111700.40000000","0.00000000"],["111700.30000000","0.00000000"],["111700.12000000","0.00000000"],["111700.11000000","0.00000000"],["111700.02000000","0.00000000"],["111700.01000000","0.00000000"],["111700.00000000","1.35165000"],["111699.99000000","0.00090000"],["111699.94000000","0.00000000"],["111699.92000000","0.00010000"],["111699.76000000","0.00010000"],["111699.75000000","0.04795000"],["111699.74000000","0.00020000"],["111699.71000000","0.00000000"],["111699.68000000","0.00020000"],["111699.67000000","0.00020000"],["111699.59000000","0.00000000"],["111699.19000000","0.00010000"],["111699.18000000","0.01806000"],["111699.17000000","0.00010000"],["111699.05000000","0.00005000"],["111698.47000000","0.00000000"],["111698.27000000","0.00010000"],["111698.26000000","0.00010000"],["111698.21000000","0.00366000"],["111697.47000000","0.00000000"],["111697.46000000","0.00000000"],["111697.03000000","0.00010000"],["111697.02000000","0.05147000"],["111696.84000000","0.00000000"],["111696.83000000","0.00000000"],["111696.82000000","0.00000000"],["111696.65000000","0.00000000"],["111696.63000000","0.00000000"],["111696.62000000","0.00010000"],["111696.61000000","0.00010000"],["111696.36000000","0.00000000"],["111695.92000000","0.00000000"],["111695.84000000","0.00000000"],["111695.75000000","0.00000000"],["111695.74000000","0.00000000"],["111695.39000000","0.00005000"],["111695.21000000","0.00000000"],["111695.20000000","0.00000000"],["111694.82000000","0.00000000"],["111694.41000000","0.00151000"],["111694.14000000","0.00000000"],["111694.09000000","0.00305000"],["111693.89000000","0.00005000"],["111693.88000000","0.00010000"],["111693.21000000","0.00000000"],["111693.15000000","0.00000000"],["111693.02000000","0.00000000"],["111692.15000000","0.00000000"],["111692.14000000","0.00000000"],["111691.99000000","0.00000000"],["111691.89000000","0.00000000"],["111691.85000000","0.00000000"],["111691.84000000","0.00005000"],["111691.83000000","0.26465000"],["111691.77000000","0.00000000"],["111691.73000000","0.00330000"],["111691.09000000","0.00000000"],["111691.05000000","0.00005000"],["111690.92000000","0.01173000"],["111690.80000000","0.00000000"],["111690.20000000","0.00000000"],["111690.07000000","0.29531000"],["111689.91000000","0.00000000"],["111689.90000000","0.00000000"],["111689.21000000","0.00000000"],["111689.08000000","0.04066000"],["111688.95000000","0.00000000"],["111688.94000000","0.11442000"],["111688.87000000","0.00000000"],["111688.83000000","0.00000000"],["111688.77000000","0.00000000"],["111688.55000000","0.00156000"],["111688.47000000","0.00000000"],["111688.04000000","0.00000000"],["111688.03000000","0.00000000"],["111688.01000000","0.00000000"],["111688.00000000","0.00008000"],["111687.99000000","0.00205000"],["111687.43000000","0.00005000"],["111687.42000000","0.00000000"],["111687.38000000","0.00005000"],["111687.37000000","0.00005000"],["111687.08000000","0.00073000"],["111686.63000000","0.00000000"],["111686.55000000","0.00000000"],["111686.27000000","0.00000000"],["111685.89000000","0.00000000"],["111685.88000000","0.00000000"],["111685.87000000","0.00000000"],["111685.79000000","0.00000000"],["111685.59000000","0.00070000"],["111685.57000000","0.00000000"],["111685.48000000","0.00000000"],["111685.03000000","0.00000000"],["111684.93000000","0.00000000"],["111684.68000000","0.00000000"],["111684.65000000","0.00000000"],["111684.36000000","0.00000000"],["111684.09000000","0.00000000"],["111683.55000000","0.17896000"],["111683.54000000","0.00000000"],["111683.24000000","0.00151000"],["111683.02000000","0.01164000"],["111683.00000000","0.00000000"],["111682.99000000","0.00537000"],["111682.97000000","0.00000000"],["111682.95000000","0.04475000"],["111682.62000000","0.00000000"],["111682.60000000","0.31251000"],["111682.59000000","0.00000000"],["111681.86000000","0.00000000"],["111681.85000000","0.00000000"],["111681.80000000","0.00000000"],["111681.57000000","0.04000000"],["111681.43000000","0.00000000"],["111681.31000000","0.00007000"],["111681.21000000","0.00000000"],["111681.19000000","0.00000000"],["111681.09000000","0.00000000"],["111680.81000000","0.00068000"],["111680.39000000","0.00000000"],["111680.34000000","0.00000000"],["111680.33000000","0.00000000"],["111680.32000000","0.00000000"],["111680.27000000","0.00000000"],["111680.26000000","0.00000000"],["111680.03000000","0.00000000"],["111680.01000000","0.00000000"],["111679.99000000","0.32000000"],["111679.89000000","0.30000000"],["111679.85000000","0.00000000"],["111678.28000000","0.00000000"],["111677.39000000","0.00000000"],["111677.18000000","0.00447000"],["111677.17000000","0.00000000"],["111677.16000000","0.00005000"],["111677.04000000","0.00000000"],["111676.93000000","0.00000000"],["111676.49000000","0.15000000"],["111676.47000000","0.60705000"],["111676.46000000","0.00000000"],["111675.69000000","0.00000000"],["111675.46000000","0.00000000"],["111674.81000000","0.00000000"],["111674.42000000","0.00000000"],["111674.16000000","0.00000000"],["111673.94000000","0.00000000"],["111673.77000000","0.00000000"],["111673.73000000","0.35792000"],["111673.72000000","0.00000000"],["111672.64000000","0.00000000"],["111672.62000000","0.85326000"],["111672.61000000","0.51933000"],["111672.16000000","0.00000000"],["111672.07000000","0.11190000"],["111671.78000000","0.17411000"],["111669.80000000","0.00000000"],["111669.44000000","0.04800000"],["111669.05000000","0.00000000"],["111668.90000000","0.00005000"],["111668.34000000","0.00000000"],["111668.04000000","0.00000000"],["111667.66000000","0.00000000"],["111666.21000000","0.00000000"],["111663.85000000","0.00000000"],["111663.80000000","0.32223000"],["111663.04000000","0.00000000"],["111662.53000000","0.00000000"],["111661.91000000","1.20076000"],["111660.66000000","0.00000000"],["111660.29000000","0.00178000"],["111660.27000000","0.36760000"],["111660.25000000","0.00178000"],["111660.03000000","0.00000000"],["111659.48000000","0.00000000"],["111658.97000000","0.00000000"],["111658.92000000","0.13426000"],["111657.81000000","0.00000000"],["111657.78000000","0.32225000"],["111656.09000000","0.00000000"],["111655.32000000","0.00579000"],["111655.29000000","0.00000000"],["111654.78000000","0.00000000"],["111654.66000000","0.00000000"],["111653.67000000","0.00000000"],["111651.66000000","0.00005000"],["111651.24000000","0.00000000"],["111650.64000000","0.32227000"],["111650.34000000","0.03827000"],["111649.62000000","0.00000000"],["111649.61000000","0.00000000"],["111647.59000000","0.13426000"],["111647.19000000","0.00005000"],["111646.37000000","0.00000000"],["111645.48000000","0.00000000"],["111644.07000000","0.00000000"],["111642.72000000","0.00005000"],["111641.82000000","0.02125000"],["111641.37000000","0.00000000"],["111641.21000000","0.30202000"],["111640.88000000","0.22377000"],["111639.10000000","0.08503000"],["111638.25000000","0.00005000"],["111637.97000000","0.01700000"],["111636.56000000","0.00000000"],["111635.22000000","0.40306000"],["111634.07000000","0.08504000"],["111631.28000000","0.08504000"],["111630.30000000","0.00000000"],["111628.21000000","0.04375000"],["111627.62000000","0.00000000"],["111624.50000000","0.17904000"],["111622.29000000","0.02126000"],["111621.80000000","0.76202000"],["111621.79000000","1.25396000"],["111621.76000000","0.08995000"],["111617.24000000","0.08504000"],["111614.24000000","0.00000000"],["111614.15000000","0.04171000"],["111612.02000000","0.00000000"],["111611.86000000","0.08504000"],["111606.93000000","0.00000000"],["111606.92000000","0.00000000"],["111604.62000000","0.00000000"],["111603.65000000","0.00000000"],["111600.01000000","0.00221000"],["111596.36000000","0.13426000"],["111586.16000000","0.00000000"],["111585.03000000","0.13426000"],["111584.29000000","0.00223000"],["111584.27000000","0.00000000"],["111583.38000000","0.04800000"],["111583.32000000","0.00000000"],["111582.24000000","0.00000000"],["111578.88000000","0.00000000"],["111576.65000000","0.00000000"],["111575.45000000","0.09095000"],["111554.87000000","0.00000000"],["111548.04000000","0.09845000"],["111546.75000000","0.17904000"],["111544.42000000","0.08894000"],["111518.54000000","0.00000000"],["111500.20000000","0.00000000"],["111497.12000000","0.00007000"],["111497.11000000","0.00000000"],["111494.65000000","0.00000000"],["111492.74000000","0.00089000"],["111488.59000000","0.99629000"],["111486.68000000","0.00000000"],["111474.57000000","0.00000000"],["111472.39000000","0.00089000"],["111471.04000000","0.00000000"],["111459.29000000","0.00187000"],["111405.32000000","0.00000000"],["111384.73000000","0.00010000"],["111379.15000000","0.00010000"],["111287.50000000","0.45012000"],["111085.43000000","0.00000000"],["111066.99000000","0.89111000"],["110029.74000000","0.00000000"],["100534.00000000","0.00010000"],["89364.26000000","0.00000000"],["89360.00000000","0.00315000"],["78193.68000000","0.00000000"],["33000.00000000","3.87311000"]],"a":[["111700.01000000","7.44747000"],["111700.02000000","8.55189000"],["111700.03000000","0.00000000"],["111700.08000000","0.00000000"],["111700.10000000","0.00090000"],["111700.30000000","0.56121000"],["111700.31000000","0.04012000"],["111700.40000000","0.00010000"],["111700.41000000","0.00010000"],["111700.73000000","0.00010000"],["111700.74000000","0.00010000"],["111700.75000000","0.00005000"],["111700.76000000","0.00005000"],["111700.83000000","0.00005000"],["111701.43000000","0.00005000"],["111702.25000000","0.00000000"],["111702.31000000","0.00000000"],["111702.33000000","0.00005000"],["111702.41000000","0.00005000"],["111702.94000000","0.00000000"],["111702.95000000","0.00000000"],["111703.09000000","0.00000000"],["111703.10000000","0.75615000"],["111703.16000000","0.00000000"],["111703.97000000","0.00005000"],["111704.52000000","0.00000000"],["111704.93000000","0.00000000"],["111704.94000000","0.31710000"],["111705.00000000","0.00000000"],["111705.03000000","0.00000000"],["111705.05000000","0.00760000"],["111705.06000000","0.00000000"],["111705.17000000","0.00000000"],["111705.19000000","0.00000000"],["111705.21000000","0.00000000"],["111705.25000000","0.00000000"],["111705.26000000","0.00000000"],["111705.27000000","0.00000000"],["111705.28000000","0.00000000"],["111705.29000000","0.00005000"],["111705.30000000","0.00542000"],["111705.31000000","0.00000000"],["111705.32000000","0.98773000"],["111705.33000000","2.17588000"],["111705.34000000","0.00000000"],["111705.41000000","0.00000000"],["111705.48000000","0.00000000"],["111705.49000000","0.00900000"],["111705.50000000","0.00000000"],["111705.68000000","0.00000000"],["111705.69000000","0.05085000"],["111705.71000000","0.00005000"],["111705.72000000","0.01348000"],["111706.90000000","0.00000000"],["111706.91000000","0.06651000"],["111707.27000000","0.00100000"],["111707.56000000","0.00368000"],["111707.88000000","0.00000000"],["111707.89000000","0.01843000"],["111707.98000000","0.03581000"],["111708.42000000","0.00005000"],["111708.43000000","0.21916000"],["111708.44000000","0.02900000"],["111708.45000000","0.00000000"],["111708.88000000","0.40306000"],["111709.10000000","0.00005000"],["111709.21000000","0.00000000"],["111709.22000000","0.00000000"],["111709.23000000","0.00547000"],["111709.54000000","0.00000000"],["111709.55000000","0.00000000"],["111709.83000000","0.00000000"],["111709.89000000","0.05818000"],["111710.29000000","0.00000000"],["111710.35000000","0.00721000"],["111710.91000000","0.11199000"],["111711.21000000","0.00000000"],["111711.50000000","0.00044000"],["111712.63000000","0.53955000"],["111712.66000000","0.00000000"],["111713.12000000","0.15000000"],["111713.14000000","0.40306000"],["111713.50000000","0.00713000"],["111713.66000000","0.00000000"],["111713.88000000","0.00447000"],["111714.00000000","0.00000000"],["111714.08000000","0.03580000"],["111714.21000000","0.00010000"],["111714.41000000","0.00007000"],["111714.50000000","0.00400000"],["111714.70000000","0.00000000"],["111715.77000000","0.06000000"],["111716.35000000","0.04800000"],["111716.49000000","0.35787000"],["111716.61000000","0.00000000"],["111716.82000000","0.00000000"],["111716.99000000","0.00432000"],["111717.06000000","0.00007000"],["111717.73000000","0.00000000"],["111718.00000000","0.00000000"],["111718.03000000","0.00000000"],["111718.32000000","0.00000000"],["111718.34000000","0.00000000"],["111718.71000000","0.08509000"],["111719.25000000","0.00000000"],["111719.81000000","0.00000000"],["111720.06000000","0.00000000"],["111720.16000000","0.02125000"],["111720.26000000","0.04800000"],["111720.95000000","0.00000000"],["111721.07000000","0.00000000"],["111721.70000000","0.00000000"],["111722.16000000","0.00006000"],["111722.38000000","0.00000000"],["111722.95000000","0.32206000"],["111723.95000000","1.25396000"],["111723.98000000","0.45020000"],["111725.59000000","0.00000000"],["111726.10000000","0.00000000"],["111727.42000000","0.32205000"],["111727.52000000","1.25396000"],["111727.63000000","0.08151000"],["111727.90000000","0.40306000"],["111727.98000000","0.00000000"],["111728.24000000","0.00000000"],["111728.65000000","0.00000000"],["111729.28000000","0.02126000"],["111729.57000000","0.70760000"],["111729.82000000","0.00000000"],["111731.89000000","1.25396000"],["111732.54000000","0.00000000"],["111732.80000000","0.05538000"],["111733.82000000","0.00000000"],["111734.26000000","0.00000000"],["111735.07000000","0.00000000"],["111735.28000000","0.95528000"],["111735.30000000","0.00000000"],["111735.31000000","0.32202000"],["111735.48000000","0.00000000"],["111735.66000000","0.00000000"],["111736.80000000","0.00000000"],["111739.56000000","0.00000000"],["111739.77000000","0.18380000"],["111740.41000000","0.00000000"],["111740.87000000","0.00000000"],["111741.59000000","0.00000000"],["111742.60000000","0.00000000"],["111745.08000000","0.00000000"],["111745.53000000","0.00000000"],["111750.00000000","0.15253000"],["111752.25000000","0.00000000"],["111752.52000000","0.00000000"],["111752.87000000","0.00000000"],["111753.77000000","0.00000000"],["111753.98000000","0.00000000"],["111756.66000000","0.00000000"],["111760.61000000","0.00000000"],["111760.73000000","0.04457000"],["111762.96000000","0.00000000"],["111772.36000000","0.02596000"],["111773.32000000","0.02596000"],["111775.98000000","0.00370000"],["111776.66000000","0.00223000"],["111779.05000000","0.00000000"],["111779.10000000","0.00000000"],["111780.21000000","0.00000000"],["111780.24000000","0.00000000"],["111780.32000000","0.02130000"],["111780.76000000","0.00000000"],["111781.61000000","0.00007000"],["111785.13000000","0.00000000"],["111795.04000000","0.01377000"],["111798.71000000","0.00000000"],["111800.04000000","0.00380000"],["111802.30000000","0.00000000"],["111802.40000000","0.08894000"],["111803.48000000","0.35576000"],["111804.59000000","0.08894000"],["111804.85000000","0.08894000"],["111805.21000000","0.08894000"],["111805.22000000","0.00000000"],["111805.33000000","0.00000000"],["111805.46000000","0.09980000"],["111806.74000000","0.26682000"],["111806.84000000","0.08894000"],["111806.93000000","0.00000000"],["111807.12000000","0.09845000"],["111808.32000000","0.12891000"],["111809.48000000","0.07807000"],["111811.57000000","0.00000000"],["111811.62000000","0.00000000"],["111811.89000000","0.08894000"],["111812.04000000","0.00000000"],["111813.51000000","0.00000000"],["111813.81000000","0.00000000"],["111813.86000000","0.00000000"],["111814.19000000","0.00000000"],["111815.01000000","0.00223000"],["111815.02000000","0.00000000"],["111817.02000000","0.00000000"],["111820.15000000","0.00000000"],["111823.62000000","0.08694000"],["111823.66000000","0.00000000"],["111824.96000000","0.00000000"],["111825.57000000","0.00000000"],["111825.62000000","0.08694000"],["111828.49000000","0.08694000"],["111829.11000000","0.00000000"],["111829.61000000","0.00000000"],["111830.68000000","0.08694000"],["111831.69000000","0.00000000"],["111831.70000000","0.00000000"],["111833.22000000","0.00000000"],["111834.36000000","0.00000000"],["111834.37000000","0.00000000"],["111834.64000000","0.00000000"],["111834.65000000","0.00000000"],["111836.41000000","0.02596000"],["111836.97000000","0.00000000"],["111838.42000000","0.00000000"],["111838.55000000","0.00000000"],["111840.19000000","0.06005000"],["111840.52000000","0.00000000"],["111842.44000000","0.00000000"],["111844.76000000","0.03997000"],["111845.02000000","0.02596000"],["111845.21000000","0.00000000"],["111845.81000000","0.00000000"],["111850.31000000","0.00000000"],["111852.10000000","0.00000000"],["111858.41000000","0.00000000"],["111865.09000000","0.00000000"],["111867.84000000","0.02687000"],["111868.48000000","0.00000000"],["111873.46000000","0.00000000"],["111873.83000000","0.00000000"],["111876.92000000","0.00000000"],["111880.57000000","0.00000000"],["111881.82000000","0.00000000"],["111909.48000000","0.00000000"],["111909.78000000","0.00000000"],["111910.55000000","0.00000000"],["111911.03000000","0.00000000"],["111911.06000000","0.00000000"],["111911.16000000","0.00000000"],["111913.63000000","0.00000000"],["111914.15000000","0.00000000"],["111915.03000000","0.00000000"],["111916.29000000","0.00000000"],["111916.68000000","0.00000000"],["111919.70000000","0.00000000"],["111920.01000000","0.00000000"],["111920.83000000","0.00000000"],["111923.11000000","0.00000000"],["111926.76000000","0.00089000"],["111928.35000000","0.00000000"],["111954.15000000","0.00000000"],["111962.10000000","0.00000000"],["111963.03000000","0.00000000"],["111963.18000000","0.00000000"],["111964.49000000","0.00000000"],["111966.68000000","0.00000000"],["111967.11000000","0.00000000"],["111967.29000000","0.00000000"],["111976.58000000","0.00000000"],["111985.27000000","0.02685000"],["112045.07000000","0.00187000"],["112072.58000000","0.00000000"],["112098.19000000","0.00000000"],["112109.27000000","0.00000000"],["112118.29000000","0.00000000"],["112174.60000000","0.00000000"],["112178.04000000","0.00079000"],["112205.56000000","0.00000000"],["112220.43000000","0.00027000"],["112223.22000000","0.00000000"],["112324.15000000","0.02398000"],["112324.17000000","0.00000000"],["112325.54000000","0.00000000"],["112325.66000000","0.00000000"],["112325.71000000","0.00000000"],["113380.91000000","0.00000000"]]}
[2025-10-12T10:56:58.187Z] {"e":"depthUpdate","E":1760266618014,"s":"BTCUSDT","U":77965057551,"u":77965061184,"b":[["111700.00000000","0.00000000"],["111699.99000000","0.00000000"],["111699.98000000","0.00000000"],["111699.92000000","0.00000000"],["111699.76000000","0.00000000"],["111699.75000000","0.00000000"],["111699.74000000","0.00000000"],["111699.68000000","0.00000000"],["111699.67000000","0.00000000"],["111699.19000000","0.00000000"],["111699.18000000","0.00000000"],["111699.17000000","0.00000000"],["111699.05000000","0.00000000"],["111698.99000000","0.00000000"],["111698.27000000","0.00000000"],["111698.26000000","0.00000000"],["111698.21000000","0.00000000"],["111698.20000000","0.00000000"],["111697.03000000","0.00000000"],["111697.02000000","0.00000000"],["111697.01000000","0.00000000"],["111696.62000000","0.00000000"],["111696.61000000","0.00000000"],["111695.70000000","0.00000000"],["111695.39000000","0.00000000"],["111694.84000000","0.00000000"],["111694.41000000","0.00000000"],["111694.09000000","0.00000000"],["111693.89000000","0.00000000"],["111693.88000000","0.00000000"],["111693.03000000","0.00000000"],["111693.02000000","0.00000000"],["111693.01000000","0.00000000"],["111692.86000000","0.00000000"],["111692.85000000","0.00000000"],["111692.79000000","0.00000000"],["111692.35000000","0.00000000"],["111692.19000000","0.00000000"],["111692.18000000","0.00000000"],["111692.05000000","0.00000000"],["111692.04000000","0.00000000"],["111692.03000000","0.00000000"],["111692.02000000","0.00000000"],["111691.84000000","0.00000000"],["111691.83000000","0.00000000"],["111691.82000000","0.00000000"],["111691.76000000","0.00000000"],["111691.73000000","0.00000000"],["111691.32000000","0.00000000"],["111691.05000000","0.00000000"],["111690.93000000","0.00000000"],["111690.92000000","0.00000000"],["111690.53000000","0.00000000"],["111690.08000000","0.00000000"],["111690.07000000","0.00000000"],["111689.67000000","0.00000000"],["111689.28000000","0.00000000"],["111689.10000000","0.00000000"],["111689.09000000","0.00000000"],["111689.08000000","0.00000000"],["111689.00000000","0.00000000"],["111688.99000000","0.00000000"],["111688.94000000","0.00000000"],["111688.82000000","0.00000000"],["111688.55000000","0.00000000"],["111688.54000000","0.00000000"],["111688.00000000","0.00000000"],["111687.99000000","0.00000000"],["111687.98000000","0.00000000"],["111687.61000000","0.00000000"],["111687.60000000","0.00000000"],["111687.43000000","0.00000000"],["111687.38000000","0.00000000"],["111687.37000000","0.00000000"],["111687.10000000","0.00000000"],["111687.08000000","0.00000000"],["111686.87000000","0.00000000"],["111686.54000000","0.00000000"],["111686.53000000","0.00000000"],["111685.74000000","0.00000000"],["111685.65000000","0.00000000"],["111685.59000000","0.00000000"],["111684.80000000","0.48106000"],["111684.79000000","0.00130000"],["111684.78000000","0.00020000"],["111684.73000000","0.00010000"],["111684.58000000","0.00000000"],["111684.42000000","0.00010000"],["111684.41000000","0.01373000"],["111684.40000000","0.00020000"],["111684.20000000","0.00010000"],["111684.19000000","0.04704000"],["111684.18000000","0.05729000"],["111684.17000000","0.00010000"],["111683.72000000","0.00000000"],["111683.56000000","0.00000000"],["111683.55000000","0.00000000"],["111683.45000000","0.00005000"],["111683.41000000","0.00000000"],["111683.24000000","0.00005000"],["111683.20000000","0.00000000"],["111683.19000000","0.00010000"],["111683.18000000","0.01992000"],["111683.17000000","0.00000000"],["111683.06000000","0.00000000"],["111683.05000000","0.00000000"],["111683.03000000","0.00000000"],["111683.02000000","0.00005000"],["111682.99000000","0.00552000"],["111682.96000000","0.00000000"],["111682.95000000","0.00000000"],["111682.61000000","0.00000000"],["111682.60000000","0.00000000"],["111681.57000000","0.00000000"],["111681.31000000","0.00000000"],["111680.90000000","0.00547000"],["111680.81000000","0.00000000"],["111680.41000000","0.00005000"],["111680.18000000","0.00000000"],["111680.00000000","0.00000000"],["111679.99000000","0.00000000"],["111679.90000000","0.00000000"],["111679.89000000","0.00000000"],["111679.78000000","0.00726000"],["111679.50000000","0.00005000"],["111678.74000000","0.00000000"],["111678.67000000","0.00005000"],["111678.66000000","0.01796000"],["111678.59000000","0.00000000"],["111678.54000000","0.00000000"],["111678.48000000","0.00000000"],["111678.26000000","0.00005000"],["111678.25000000","0.05672000"],["111678.02000000","0.00000000"],["111678.01000000","0.01796000"],["111678.00000000","0.00205000"],["111677.98000000","0.00000000"],["111677.88000000","0.00000000"],["111677.34000000","0.00155000"],["111677.18000000","0.00000000"],["111677.16000000","0.00005000"],["111677.15000000","0.06013000"],["111677.07000000","0.00000000"],["111676.82000000","0.00005000"],["111676.77000000","0.00000000"],["111676.49000000","0.00000000"],["111676.47000000","0.27543000"],["111676.30000000","0.00000000"],["111676.00000000","0.00205000"],["111675.88000000","0.29535000"],["111675.68000000","0.00000000"],["111675.38000000","0.00000000"],["111674.57000000","0.00000000"],["111674.56000000","0.01803000"],["111674.01000000","0.00000000"],["111674.00000000","0.00205000"],["111673.73000000","0.00000000"],["111673.63000000","0.00151000"],["111672.87000000","0.00000000"],["111672.64000000","0.00000000"],["111672.63000000","0.00000000"],["111672.62000000","0.45020000"],["111672.61000000","0.45000000"],["111672.53000000","0.00000000"],["111672.52000000","0.00069000"],["111672.07000000","0.00000000"],["111672.02000000","0.00000000"],["111672.00000000","0.00200000"],["111671.98000000","0.00000000"],["111671.89000000","0.00005000"],["111671.81000000","0.00000000"],["111671.79000000","0.40306000"],["111671.78000000","0.25483000"],["111671.56000000","0.00000000"],["111671.50000000","0.00000000"],["111670.88000000","0.12000000"],["111670.83000000","0.04475000"],["111670.48000000","0.00000000"],["111670.21000000","0.00000000"],["111670.08000000","0.02000000"],["111670.07000000","0.00000000"],["111669.45000000","0.00000000"],["111669.39000000","0.04800000"],["111668.36000000","0.05760000"],["111668.35000000","0.05280000"],["111668.27000000","0.00000000"],["111668.26000000","0.04800000"],["111668.05000000","0.00150000"],["111667.82000000","0.01163000"],["111667.76000000","0.00000000"],["111667.64000000","0.00000000"],["111667.58000000","0.16000000"],["111667.19000000","0.07200000"],["111666.58000000","0.04000000"],["111666.47000000","0.00000000"],["111666.46000000","0.73315000"],["111666.45000000","0.00000000"],["111666.38000000","0.32000000"],["111666.23000000","0.00000000"],["111666.12000000","0.00007000"],["111666.02000000","0.09360000"],["111665.69000000","0.00000000"],["111664.45000000","0.06240000"],["111664.20000000","0.00000000"],["111664.02000000","0.17900000"],["111664.01000000","0.00000000"],["111663.80000000","0.00000000"],["111663.05000000","0.00000000"],["111662.74000000","0.05760000"],["111662.46000000","0.11490000"],["111662.43000000","0.00000000"],["111661.91000000","0.00000000"],["111661.89000000","0.00005000"],["111661.59000000","0.04800000"],["111660.61000000","0.00447000"],["111660.29000000","0.00000000"],["111660.25000000","0.00000000"],["111658.92000000","0.00000000"],["111658.39000000","0.15000000"],["111658.38000000","0.36957000"],["111658.30000000","0.07200000"],["111657.78000000","0.00000000"],["111657.19000000","0.05280000"],["111656.91000000","0.01390000"],["111656.07000000","0.06720000"],["111656.02000000","0.06720000"],["111656.01000000","0.05896000"],["111655.93000000","0.00000000"],["111655.92000000","0.00005000"],["111655.50000000","0.04483000"],["111654.95000000","0.00000000"],["111654.61000000","0.00276000"],["111654.23000000","0.00000000"],["111654.09000000","0.00000000"],["111653.70000000","0.00000000"],["111651.60000000","0.08504000"],["111651.29000000","0.00308000"],["111650.64000000","0.00000000"],["111650.34000000","0.00000000"],["111650.00000000","0.00521000"],["111648.60000000","0.00438000"],["111648.40000000","0.00000000"],["111648.37000000","0.00000000"],["111647.30000000","0.00012000"],["111647.20000000","0.00000000"],["111647.14000000","0.00000000"],["111647.02000000","0.00000000"],["111646.57000000","0.00000000"],["111646.26000000","0.00000000"],["111646.23000000","0.00178000"],["111646.12000000","0.00009000"],["111646.01000000","0.00000000"],["111645.75000000","0.00000000"],["111645.52000000","0.00000000"],["111645.13000000","0.32228000"],["111644.91000000","0.00178000"],["111643.95000000","0.00000000"],["111643.90000000","0.00018000"],["111643.40000000","0.13426000"],["111642.85000000","0.08504000"],["111642.72000000","0.01705000"],["111642.05000000","0.00000000"],["111641.27000000","0.00000000"],["111641.21000000","0.00000000"],["111640.85000000","0.13426000"],["111640.78000000","0.00000000"],["111640.70000000","1.21273000"],["111640.32000000","0.00000000"],["111638.92000000","0.93375000"],["111638.87000000","0.08504000"],["111638.76000000","0.00000000"],["111638.30000000","0.00000000"],["111638.18000000","0.00000000"],["111638.15000000","0.03581000"],["111638.09000000","0.37030000"],["111637.69000000","0.03827000"],["111637.67000000","0.00000000"],["111637.43000000","0.00136000"],["111637.27000000","0.00000000"],["111637.09000000","0.22377000"],["111636.74000000","0.00000000"],["111636.45000000","0.06549000"],["111635.72000000","0.00009000"],["111634.77000000","0.00000000"],["111633.78000000","0.00005000"],["111633.33000000","0.04430000"],["111632.87000000","0.30204000"],["111632.41000000","0.32232000"],["111631.28000000","0.00000000"],["111631.27000000","0.00000000"],["111629.81000000","0.00000000"],["111629.72000000","0.00000000"],["111629.31000000","0.00005000"],["111628.51000000","0.40306000"],["111628.21000000","0.00000000"],["111627.11000000","0.00000000"],["111627.04000000","0.18882000"],["111625.06000000","0.00000000"],["111624.51000000","0.00000000"],["111622.40000000","0.02506000"],["111621.81000000","0.40306000"],["111620.18000000","0.00000000"],["111620.01000000","0.16145000"],["111619.25000000","0.09360000"],["111619.04000000","0.00000000"],["111618.01000000","0.26882000"],["111617.79000000","0.00008000"],["111616.35000000","1.25396000"],["111615.94000000","0.02228000"],["111614.91000000","0.00000000"],["111614.42000000","0.00628000"],["111614.39000000","0.00000000"],["111614.15000000","0.00000000"],["111613.62000000","0.04375000"],["111612.43000000","0.00656000"],["111612.29000000","0.00000000"],["111611.41000000","0.00447000"],["111610.52000000","0.00420000"],["111610.40000000","0.00000000"],["111610.14000000","0.00000000"],["111609.64000000","1.25396000"],["111606.43000000","0.00000000"],["111604.79000000","0.00000000"],["111604.01000000","0.08894000"],["111602.35000000","0.00000000"],["111602.14000000","0.00005000"],["111600.34000000","0.00090000"],["111600.01000000","0.00000000"],["111599.06000000","0.00000000"],["111599.01000000","0.00005000"],["111598.54000000","0.00000000"],["111598.53000000","0.00000000"],["111595.10000000","0.00000000"],["111593.63000000","0.00000000"],["111593.37000000","0.00000000"],["111592.70000000","0.34629000"],["111592.49000000","0.07200000"],["111592.26000000","0.01800000"],["111591.61000000","0.00000000"],["111591.32000000","0.00163000"],["111591.31000000","0.09360000"],["111588.14000000","0.05267000"],["111586.90000000","0.00000000"],["111586.51000000","0.00223000"],["111586.50000000","0.04275000"],["111584.29000000","0.00000000"],["111584.28000000","0.00008000"],["111583.46000000","0.00000000"],["111583.38000000","0.00000000"],["111583.32000000","0.00000000"],["111582.25000000","0.00000000"],["111582.22000000","0.04800000"],["111582.21000000","0.00000000"],["111582.01000000","0.00000000"],["111581.87000000","0.00000000"],["111581.66000000","0.00000000"],["111580.39000000","0.00111000"],["111580.01000000","0.00000000"],["111580.00000000","0.02052000"],["111578.88000000","0.00000000"],["111578.34000000","0.00000000"],["111578.29000000","0.13426000"],["111577.78000000","0.00000000"],["111577.69000000","0.00000000"],["111576.67000000","0.00000000"],["111576.66000000","0.00000000"],["111576.61000000","0.06720000"],["111574.04000000","0.00000000"],["111574.01000000","0.02686000"],["111573.90000000","0.00000000"],["111572.01000000","0.09095000"],["111571.27000000","0.00000000"],["111570.00000000","0.00710000"],["111569.08000000","0.00196000"],["111569.02000000","0.00000000"],["111566.29000000","0.00223000"],["111560.37000000","0.02417000"],["111560.24000000","0.01236000"],["111558.46000000","0.44767000"],["111558.40000000","0.00005000"],["111558.12000000","0.00000000"],["111556.59000000","0.08794000"],["111556.50000000","0.00000000"],["111556.17000000","0.00010000"],["111553.99000000","0.09894000"],["111552.59000000","0.11212000"],["111550.78000000","0.00018000"],["111550.74000000","0.00000000"],["111549.06000000","0.59335000"],["111548.78000000","0.00000000"],["111548.57000000","0.09759000"],["111547.59000000","0.01086000"],["111546.41000000","0.04947000"],["111546.00000000","0.00260000"],["111545.81000000","0.02417000"],["111545.80000000","0.02417000"],["111545.09000000","0.08894000"],["111543.94000000","0.02417000"],["111542.84000000","0.02417000"],["111542.41000000","0.08894000"],["111540.16000000","0.08894000"],["111539.32000000","0.08894000"],["111539.11000000","0.04834000"],["111537.76000000","0.00000000"],["111537.09000000","0.00000000"],["111536.95000000","0.08894000"],["111536.76000000","0.08894000"],["111536.56000000","0.00000000"],["111534.70000000","0.00000000"],["111533.13000000","0.08894000"],["111529.93000000","0.00000000"],["111527.42000000","0.02596000"],["111525.92000000","0.00000000"],["111524.22000000","0.02596000"],["111517.27000000","0.00008000"],["111516.94000000","0.00000000"],["111515.95000000","0.02596000"],["111514.25000000","0.17314000"],["111503.98000000","0.05430000"],["111502.35000000","0.09462000"],["111498.48000000","0.02596000"],["111494.66000000","0.00000000"],["111493.73000000","0.02596000"],["111493.59000000","0.13655000"],["111492.74000000","0.00000000"],["111488.59000000","0.00000000"],["111484.01000000","0.00000000"],["111479.90000000","0.00065000"],["111476.75000000","0.00000000"],["111476.51000000","0.08695000"],["111475.88000000","0.00000000"],["111475.41000000","0.99635000"],["111475.23000000","0.08695000"],["111474.56000000","0.00000000"],["111474.01000000","0.00089000"],["111473.54000000","0.08695000"],["111472.39000000","0.00000000"],["111470.58000000","0.08714000"],["111469.83000000","0.00010000"],["111467.24000000","0.00000000"],["111459.29000000","0.00000000"],["111454.01000000","0.00089000"],["111453.40000000","0.00000000"],["111452.44000000","4.78455000"],["111421.64000000","0.00000000"],["111419.71000000","0.89705000"],["111416.27000000","0.00000000"],["111415.42000000","0.00574000"],["111413.30000000","0.00000000"],["111406.17000000","0.01700000"],["111405.27000000","0.00010000"],["111404.16000000","0.00000000"],["111404.11000000","0.00000000"],["111403.13000000","0.00000000"],["111397.86000000","0.03400000"],["111397.24000000","0.00000000"],["111397.07000000","0.00000000"],["111396.35000000","0.00000000"],["111395.29000000","0.00000000"],["111393.01000000","0.00000000"],["111389.58000000","0.00000000"],["111388.11000000","0.00000000"],["111387.49000000","0.00000000"],["111384.99000000","0.01701000"],["111384.72000000","0.00000000"],["111384.38000000","0.00000000"],["111384.03000000","0.00000000"],["111380.11000000","0.00010000"],["111379.15000000","0.00000000"],["111375.11000000","0.00010000"],["111374.53000000","0.00007000"],["111372.51000000","0.00000000"],["111370.82000000","0.00000000"],["111370.80000000","0.00000000"],["111370.53000000","0.00000000"],["111370.08000000","0.00000000"],["111369.88000000","0.00000000"],["111369.76000000","0.00000000"],["111369.53000000","0.00010000"],["111368.88000000","0.00000000"],["111366.33000000","0.00000000"],["111363.84000000","0.00000000"],["111363.58000000","0.00000000"],["111360.27000000","0.02596000"],["111357.49000000","0.05192000"],["111357.19000000","0.02596000"],["111354.49000000","0.00000000"],["111345.13000000","0.03581000"],["111343.51000000","0.05896000"],["111343.44000000","0.03581000"],["111343.05000000","0.05896000"],["111342.97000000","0.03581000"],["111342.48000000","0.05896000"],["111342.15000000","0.03581000"],["111342.13000000","0.05896000"],["111339.60000000","0.07162000"],["111336.63000000","0.05896000"],["111336.43000000","0.05896000"],["111335.43000000","0.05896000"],["111335.14000000","0.03581000"],["111296.83000000","0.00187000"],["111066.99000000","0.00000000"],["111016.43000000","0.00000000"],["110024.50000000","0.00000000"],["110009.52000000","0.00100000"],["106100.00000000","0.69851000"],["100534.00000000","0.00000000"],["100530.00000000","0.00130000"],["100515.00000000","0.00308000"],["89360.00000000","0.00293000"],["89347.84000000","0.00022000"],["78189.02000000","0.00000000"],["78184.37000000","0.00000000"],["78179.75000000","0.00000000"],["42000.00000000","1.49096000"]],"a":[["111684.81000000","6.78387000"],["111684.87000000","0.00000000"],["111684.89000000","0.00010000"],["111684.90000000","0.00080000"],["111684.92000000","0.00000000"],["111684.96000000","0.00010000"],["111684.97000000","0.00905000"],["111685.19000000","0.00010000"],["111685.20000000","0.01358000"],["111686.51000000","0.00010000"],["111686.52000000","0.41084000"],["111686.53000000","0.00010000"],["111686.54000000","0.29552000"],["111686.55000000","0.53999000"],["111686.61000000","0.00000000"],["111686.63000000","0.00000000"],["111687.04000000","0.00358000"],["111687.09000000","0.00000000"],["111687.10000000","0.17113000"],["111687.11000000","0.00000000"],["111687.42000000","0.00005000"],["111687.62000000","0.00000000"],["111688.00000000","0.00000000"],["111688.01000000","0.00000000"],["111688.03000000","0.00005000"],["111688.56000000","0.00000000"],["111688.71000000","0.00542000"],["111689.00000000","0.00000000"],["111689.01000000","0.17192000"],["111689.07000000","0.00000000"],["111689.09000000","0.00000000"],["111689.10000000","0.00000000"],["111689.11000000","0.00000000"],["111689.26000000","0.00000000"],["111689.28000000","0.00000000"],["111689.29000000","0.00000000"],["111689.64000000","0.00000000"],["111689.65000000","0.08010000"],["111690.90000000","0.00000000"],["111690.92000000","0.00000000"],["111690.93000000","0.04007000"],["111691.01000000","0.00000000"],["111691.06000000","0.00000000"],["111691.74000000","0.00000000"],["111691.77000000","0.00000000"],["111691.81000000","0.00000000"],["111691.82000000","0.28897000"],["111691.83000000","0.45020000"],["111691.84000000","0.03985000"],["111691.85000000","0.00000000"],["111691.89000000","0.00005000"],["111691.92000000","0.00000000"],["111692.00000000","0.00000000"],["111692.02000000","0.00000000"],["111692.04000000","0.00000000"],["111692.05000000","0.00000000"],["111692.06000000","0.00000000"],["111692.07000000","0.01760000"],["111692.09000000","0.00000000"],["111692.10000000","0.00000000"],["111692.16000000","0.00000000"],["111692.18000000","0.00000000"],["111692.19000000","0.04007000"],["111692.36000000","0.00000000"],["111692.69000000","0.11190000"],["111692.77000000","0.00000000"],["111692.79000000","0.00000000"],["111692.80000000","0.00000000"],["111692.86000000","0.00000000"],["111692.96000000","0.03991000"],["111693.00000000","0.00000000"],["111693.02000000","0.00000000"],["111693.03000000","0.04012000"],["111693.04000000","0.00000000"],["111693.89000000","0.00000000"],["111694.09000000","0.00000000"],["111694.10000000","0.30764000"],["111694.16000000","0.00000000"],["111694.42000000","0.00000000"],["111694.43000000","0.00000000"],["111694.85000000","0.00000000"],["111695.40000000","0.00000000"],["111695.98000000","0.00300000"],["111696.30000000","0.00088000"],["111696.36000000","0.00005000"],["111696.60000000","0.40306000"],["111696.89000000","0.00087000"],["111697.00000000","0.00000000"],["111697.02000000","0.51504000"],["111697.03000000","0.08002000"],["111697.04000000","0.00000000"],["111697.09000000","0.00000000"],["111697.63000000","0.00000000"],["111697.64000000","0.08012000"],["111698.21000000","0.00000000"],["111698.25000000","0.00000000"],["111698.27000000","0.00000000"],["111698.28000000","0.08002000"],["111698.34000000","0.00000000"],["111698.95000000","0.00000000"],["111698.97000000","0.00000000"],["111698.98000000","0.08007000"],["111698.99000000","0.00000000"],["111699.06000000","0.08504000"],["111699.19000000","0.00000000"],["111699.59000000","0.00000000"],["111699.75000000","0.00000000"],["111699.76000000","0.00000000"],["111699.77000000","0.00000000"],["111699.98000000","0.00000000"],["111700.00000000","0.76100000"],["111700.01000000","0.30863000"],["111700.02000000","0.00000000"],["111700.10000000","0.00000000"],["111700.29000000","0.00000000"],["111700.30000000","0.00000000"],["111700.31000000","0.04007000"],["111700.36000000","0.08509000"],["111700.40000000","0.00000000"],["111700.41000000","0.00000000"],["111700.49000000","0.00010000"],["111700.73000000","0.00000000"],["111700.74000000","0.00000000"],["111700.75000000","0.00000000"],["111700.76000000","0.00000000"],["111701.00000000","0.00405000"],["111701.07000000","0.08285000"],["111701.27000000","0.04800000"],["111701.36000000","0.05280000"],["111701.43000000","0.00000000"],["111701.79000000","0.00432000"],["111701.85000000","0.00007000"],["111702.33000000","0.00000000"],["111702.40000000","0.04800000"],["111702.41000000","0.00000000"],["111702.45000000","0.04800000"],["111703.09000000","0.00000000"],["111703.10000000","0.26379000"],["111703.21000000","0.00007000"],["111703.33000000","0.00000000"],["111703.59000000","0.00000000"],["111703.76000000","0.14000000"],["111703.79000000","0.02687000"],["111703.97000000","0.00000000"],["111704.33000000","0.00010000"],["111704.93000000","1.00962000"],["111704.94000000","0.00000000"],["111705.05000000","0.00000000"],["111705.30000000","0.00542000"],["111705.31000000","0.15000000"],["111705.32000000","0.85326000"],["111705.33000000","2.16978000"],["111705.49000000","0.00895000"],["111705.60000000","0.00033000"],["111705.69000000","0.00000000"],["111705.71000000","0.00000000"],["111705.72000000","0.00000000"],["111705.78000000","0.04800000"],["111705.96000000","0.00005000"],["111706.06000000","0.00000000"],["111706.42000000","0.04800000"],["111706.69000000","0.00000000"],["111706.89000000","0.04800000"],["111706.91000000","0.00000000"],["111707.04000000","0.00000000"],["111707.05000000","0.35489000"],["111707.06000000","0.48000000"],["111707.27000000","0.00000000"],["111707.48000000","0.00000000"],["111707.56000000","0.00358000"],["111707.77000000","0.00010000"],["111707.86000000","0.00000000"],["111707.89000000","0.01833000"],["111708.01000000","0.04800000"],["111708.07000000","0.04800000"],["111708.43000000","0.00000000"],["111708.62000000","0.00000000"],["111708.86000000","0.00000000"],["111708.89000000","0.00000000"],["111709.23000000","0.00000000"],["111709.38000000","0.00022000"],["111709.55000000","0.00000000"],["111709.78000000","0.00000000"],["111709.94000000","0.00005000"],["111710.35000000","0.00000000"],["111710.91000000","0.00000000"],["111710.95000000","0.03581000"],["111711.05000000","0.00006000"],["111711.36000000","0.00010000"],["111711.47000000","0.00000000"],["111711.50000000","0.00000000"],["111711.52000000","0.00005000"],["111712.60000000","0.00000000"],["111712.61000000","0.00000000"],["111712.62000000","1.25396000"],["111712.63000000","0.81997000"],["111713.02000000","0.01390000"],["111713.12000000","0.00000000"],["111713.50000000","0.00000000"],["111713.88000000","0.00000000"],["111713.89000000","0.06646000"],["111714.08000000","0.03580000"],["111714.41000000","0.08511000"],["111714.50000000","0.00400000"],["111715.16000000","0.32208000"],["111715.24000000","0.07200000"],["111715.68000000","0.00000000"],["111715.77000000","0.00000000"],["111716.07000000","0.00445000"],["111716.34000000","0.08503000"],["111716.35000000","0.00000000"],["111716.42000000","0.07200000"],["111716.48000000","1.25396000"],["111716.49000000","0.00000000"],["111716.50000000","0.40306000"],["111716.88000000","0.01700000"],["111717.06000000","0.00000000"],["111718.32000000","0.00008000"],["111718.71000000","0.00005000"],["111719.83000000","1.33579000"],["111719.84000000","1.25396000"],["111719.85000000","0.00000000"],["111719.98000000","0.00000000"],["111720.00000000","0.04679000"],["111720.58000000","0.18866000"],["111720.62000000","0.08000000"],["111720.69000000","0.32207000"],["111720.92000000","0.00000000"],["111722.00000000","0.00260000"],["111722.30000000","0.00000000"],["111722.51000000","0.04478000"],["111722.95000000","0.00000000"],["111724.58000000","0.18380000"],["111725.34000000","0.00000000"],["111726.33000000","0.00000000"],["111726.47000000","0.00000000"],["111726.68000000","0.00000000"],["111727.60000000","0.00000000"],["111727.64000000","0.00000000"],["111727.78000000","0.00000000"],["111728.49000000","0.00000000"],["111728.56000000","0.00269000"],["111728.77000000","0.00000000"],["111728.96000000","0.00000000"],["111729.57000000","0.31485000"],["111729.58000000","0.00000000"],["111730.26000000","0.00000000"],["111730.37000000","0.32204000"],["111731.47000000","0.00000000"],["111731.71000000","0.00000000"],["111731.90000000","0.00000000"],["111732.12000000","0.00000000"],["111732.58000000","0.00000000"],["111732.79000000","0.00000000"],["111733.09000000","0.00000000"],["111733.75000000","0.00000000"],["111733.84000000","0.00000000"],["111734.40000000","1.21473000"],["111735.28000000","0.00000000"],["111735.31000000","0.00000000"],["111735.49000000","0.00000000"],["111736.59000000","0.00000000"],["111736.82000000","0.00000000"],["111738.84000000","0.00000000"],["111738.85000000","0.00000000"],["111739.25000000","0.00000000"],["111739.77000000","0.00000000"],["111740.48000000","0.00000000"],["111741.06000000","0.00000000"],["111743.39000000","0.03024000"],["111745.15000000","0.37025000"],["111748.31000000","0.00000000"],["111748.63000000","0.00000000"],["111749.74000000","0.00000000"],["111750.77000000","0.00000000"],["111751.82000000","0.00008000"],["111752.36000000","0.00000000"],["111753.58000000","0.05280000"],["111756.15000000","0.06780000"],["111759.08000000","0.00222000"],["111759.27000000","0.02746000"],["111759.54000000","0.00656000"],["111760.73000000","0.00000000"],["111762.85000000","0.00624000"],["111763.14000000","0.00616000"],["111765.53000000","0.13426000"],["111766.44000000","0.13426000"],["111769.55000000","0.00000000"],["111769.82000000","0.00223000"],["111772.35000000","0.00000000"],["111774.57000000","0.00000000"],["111774.68000000","0.00000000"],["111774.92000000","0.00000000"],["111776.66000000","0.00000000"],["111777.17000000","0.00000000"],["111777.93000000","0.13536000"],["111778.25000000","0.00000000"],["111779.48000000","0.02447000"],["111779.65000000","0.89416000"],["111780.19000000","0.00000000"],["111781.56000000","0.00000000"],["111783.44000000","0.02151000"],["111783.51000000","0.00000000"],["111784.08000000","0.00112000"],["111785.33000000","0.00008000"],["111786.11000000","0.04017000"],["111789.39000000","0.00000000"],["111790.42000000","0.00000000"],["111790.99000000","0.13433000"],["111791.91000000","0.00000000"],["111792.30000000","0.00000000"],["111794.30000000","0.22377000"],["111794.40000000","0.22377000"],["111795.26000000","0.00000000"],["111796.03000000","0.00000000"],["111796.45000000","0.24626000"],["111798.62000000","0.00000000"],["111798.99000000","0.81478000"],["111799.37000000","0.00000000"],["111805.86000000","0.00000000"],["111806.73000000","0.02596000"],["111806.86000000","0.00000000"],["111806.92000000","0.00000000"],["111810.40000000","0.00000000"],["111811.61000000","0.00196000"],["111812.29000000","0.00000000"],["111812.30000000","0.00000000"],["111814.14000000","0.09436000"],["111815.05000000","0.00000000"],["111815.24000000","0.00000000"],["111817.88000000","0.42041000"],["111818.83000000","0.00008000"],["111819.02000000","0.00000000"],["111820.14000000","0.00000000"],["111821.76000000","0.00000000"],["111824.08000000","0.00000000"],["111824.10000000","0.00000000"],["111824.93000000","0.00000000"],["111825.02000000","0.99844000"],["111825.90000000","0.06000000"],["111827.33000000","0.00000000"],["111827.66000000","0.00000000"],["111827.82000000","0.00000000"],["111828.44000000","0.00000000"],["111828.47000000","0.00000000"],["111829.12000000","0.00000000"],["111829.36000000","0.00000000"],["111829.45000000","0.00007000"],["111830.74000000","0.00000000"],["111839.38000000","0.00000000"],["111840.19000000","0.00000000"],["111842.46000000","0.03997000"],["111845.82000000","0.00000000"],["111849.80000000","0.00000000"],["111852.34000000","0.00008000"],["111858.41000000","0.03506000"],["111866.19000000","0.00000000"],["111866.22000000","0.08894000"],["111868.08000000","0.08894000"],["111869.99000000","0.00089000"],["111871.73000000","0.08894000"],["111872.73000000","0.00009000"],["111872.89000000","0.00000000"],["111875.66000000","0.08894000"],["111878.50000000","0.08894000"],["111881.37000000","0.08894000"],["111881.89000000","0.00187000"],["111883.87000000","0.08894000"],["111886.95000000","0.08894000"],["111892.40000000","0.00000000"],["111907.03000000","0.00000000"],["111907.47000000","0.00000000"],["111907.63000000","0.00000000"],["111907.81000000","0.00000000"],["111915.41000000","0.08695000"],["111917.22000000","0.08695000"],["111918.94000000","0.08695000"],["111921.25000000","0.08695000"],["111923.94000000","0.08695000"],["111937.89000000","4.74490000"],["111946.46000000","0.03997000"],["111951.56000000","0.00000000"],["111953.05000000","0.00000000"],["111954.27000000","0.00000000"],["111956.86000000","0.00000000"],["111959.60000000","0.02596000"],["111959.96000000","0.00000000"],["111973.88000000","0.00000000"],["111974.42000000","0.00000000"],["111991.37000000","0.00000000"],["111991.83000000","0.00000000"],["112014.83000000","0.00079000"],["112028.84000000","0.00000000"],["112031.72000000","0.00000000"],["112037.28000000","0.00000000"],["112042.86000000","0.00000000"],["112045.07000000","0.00000000"],["112047.27000000","0.00000000"],["112069.95000000","0.00000000"],["112070.30000000","0.00000000"],["112095.18000000","0.00000000"],["112097.09000000","0.00000000"],["112178.04000000","0.00000000"],["112212.17000000","0.02398000"],["112217.56000000","0.00000000"],["112218.84000000","0.00000000"],["112220.24000000","0.00000000"],["112323.71000000","0.00000000"],["112324.01000000","0.00000000"],["112324.15000000","0.00000000"],["113361.85000000","0.00000000"]]}
[2025-10-12T10:56:59.185Z] {"e":"depthUpdate","E":1760266619014,"s":"BTCUSDT","U":77965061185,"u":77965061530,"b":[["111684.80000000","0.64736000"],["111684.79000000","0.00115000"],["111684.41000000","0.01378000"],["111684.19000000","0.08298000"],["111683.18000000","0.01992000"],["111682.34000000","0.00005000"],["111680.90000000","0.00552000"],["111680.41000000","0.00000000"],["111679.97000000","0.00005000"],["111679.96000000","0.03930000"],["111679.78000000","0.00736000"],["111679.25000000","0.00000000"],["111679.24000000","0.00005000"],["111678.84000000","0.03995000"],["111678.72000000","0.00000000"],["111678.67000000","0.00000000"],["111678.66000000","0.01791000"],["111678.26000000","0.00000000"],["111678.25000000","0.05667000"],["111675.88000000","0.00000000"],["111674.31000000","0.29535000"],["111672.52000000","0.00000000"],["111672.49000000","0.00069000"],["111671.80000000","0.44918000"],["111671.78000000","0.00000000"],["111670.88000000","0.00000000"],["111670.08000000","0.00000000"],["111668.78000000","0.02000000"],["111667.48000000","0.04000000"],["111667.42000000","0.00000000"],["111667.08000000","0.08000000"],["111662.55000000","0.00100000"],["111658.39000000","0.15000000"],["111655.50000000","0.00006000"],["111654.10000000","0.00000000"],["111637.70000000","0.03581000"],["111636.45000000","0.00000000"],["111636.01000000","0.06872000"],["111632.86000000","0.89265000"],["111629.82000000","0.32233000"],["111592.71000000","0.32634000"],["111590.75000000","0.00000000"],["111586.13000000","0.00005000"],["111582.22000000","0.00000000"],["111576.61000000","0.00000000"],["111559.23000000","0.63239000"],["111555.00000000","0.00005000"],["111527.43000000","0.01809000"],["111525.93000000","0.00000000"],["111196.56000000","0.03581000"],["111189.84000000","0.03581000"],["111055.92000000","0.89111000"],["110009.52000000","0.00100000"],["100516.00000000","0.00100000"],["100515.00000000","0.00308000"],["89347.84000000","0.00022000"]],"a":[["111684.81000000","6.78192000"],["111684.89000000","0.00425000"],["111684.94000000","0.03962000"],["111685.20000000","0.01368000"],["111685.92000000","0.00010000"],["111685.93000000","0.04056000"],["111686.52000000","0.19435000"],["111686.54000000","0.29542000"],["111686.55000000","0.00282000"],["111686.77000000","0.00005000"],["111687.09000000","0.00000000"],["111687.10000000","0.17113000"],["111689.01000000","0.17192000"],["111689.28000000","0.00005000"],["111689.65000000","0.00005000"],["111690.93000000","0.04007000"],["111691.03000000","0.00000000"],["111691.84000000","0.00005000"],["111692.19000000","0.04002000"],["111692.96000000","0.00010000"],["111693.03000000","0.04017000"],["111695.35000000","0.04000000"],["111695.91000000","0.00005000"],["111699.98000000","0.00000000"],["111700.31000000","0.04002000"],["111700.36000000","0.08504000"],["111701.00000000","0.00400000"],["111701.07000000","0.08280000"],["111702.44000000","0.06720000"],["111703.50000000","0.07200000"],["111704.68000000","0.07200000"],["111705.31000000","0.15000000"],["111706.28000000","0.04800000"],["111707.97000000","0.04800000"],["111708.87000000","1.25396000"],["111712.11000000","0.01390000"],["111712.61000000","1.36433000"],["111712.63000000","0.00000000"],["111713.02000000","0.00000000"],["111715.24000000","0.00000000"],["111716.03000000","0.00000000"],["111716.42000000","0.00000000"],["111717.91000000","0.22377000"],["111719.84000000","2.45734000"],["111720.26000000","0.00000000"],["111720.82000000","0.00000000"],["111721.98000000","0.00000000"],["111722.51000000","0.00000000"],["111725.99000000","0.03581000"],["111727.53000000","0.00000000"],["111727.63000000","0.00000000"],["111731.72000000","0.17904000"],["111731.94000000","0.00000000"],["111734.40000000","0.00000000"],["111742.60000000","0.00005000"],["111743.48000000","0.04419000"],["111759.77000000","0.13426000"],["111762.15000000","0.04800000"],["111790.99000000","0.00000000"],["111791.32000000","0.00000000"],["111791.53000000","0.00000000"],["111791.54000000","0.00000000"],["111792.13000000","0.00000000"],["111792.42000000","0.13433000"],["111793.24000000","0.06013000"],["111794.40000000","0.00000000"],["111796.09000000","0.22377000"],["111806.86000000","0.04800000"],["111808.34000000","0.00000000"],["111812.38000000","0.39993000"],["111821.09000000","0.04097000"],["111822.41000000","0.00000000"],["111846.65000000","0.54666000"],["111881.89000000","0.02783000"],["111888.09000000","0.02596000"],["111919.58000000","0.08695000"],["111921.38000000","0.08695000"],["111932.86000000","0.03997000"],["112070.83000000","0.03581000"],["112077.45000000","0.07250000"],["112083.30000000","0.03581000"],["112170.35000000","0.03581000"],["112176.06000000","0.03581000"],["112181.77000000","0.03581000"],["113360.09000000","0.00100000"]]}
[2025-10-12T10:57:00.185Z] {"e":"depthUpdate","E":1760266620014,"s":"BTCUSDT","U":77965061531,"u":77965061805,"b":[["111684.80000000","1.29630000"],["111684.79000000","0.00125000"],["111684.41000000","0.01378000"],["111684.19000000","0.08298000"],["111684.17000000","0.04307000"],["111683.18000000","0.01992000"],["111681.74000000","0.00000000"],["111680.90000000","0.00552000"],["111680.09000000","0.00000000"],["111680.08000000","0.00000000"],["111679.97000000","0.00000000"],["111679.96000000","0.00000000"],["111679.90000000","0.00005000"],["111679.89000000","0.04016000"],["111679.78000000","0.00736000"],["111679.24000000","0.00005000"],["111679.23000000","0.02692000"],["111679.01000000","0.00000000"],["111678.84000000","0.03995000"],["111678.25000000","0.00000000"],["111677.06000000","0.00000000"],["111676.21000000","0.00000000"],["111674.31000000","0.00000000"],["111674.00000000","0.00200000"],["111672.49000000","0.00000000"],["111672.36000000","0.00000000"],["111667.58000000","0.00000000"],["111667.00000000","0.00100000"],["111666.38000000","0.48000000"],["111665.55000000","0.00005000"],["111665.14000000","0.00894000"],["111663.05000000","0.15000000"],["111662.55000000","0.00000000"],["111658.39000000","0.00000000"],["111656.91000000","0.00000000"],["111656.35000000","0.01390000"],["111645.13000000","0.00000000"],["111644.37000000","0.32229000"],["111642.71000000","1.07586000"],["111629.82000000","0.00000000"],["111625.32000000","0.00000000"],["111610.50000000","0.60065000"],["111561.01000000","0.01401000"],["111560.00000000","0.00349000"],["111536.96000000","0.10751000"],["111371.79000000","0.00000000"],["111371.53000000","0.00000000"],["111338.88000000","0.05996000"],["111337.63000000","0.05996000"],["110009.52000000","0.00100000"],["100515.00000000","0.00308000"],["89347.84000000","0.00022000"]],"a":[["111684.81000000","6.25373000"],["111684.89000000","0.00425000"],["111684.93000000","0.00000000"],["111684.94000000","0.00000000"],["111684.97000000","0.00910000"],["111685.02000000","0.00010000"],["111685.03000000","0.00010000"],["111685.93000000","0.00010000"],["111686.53000000","0.00000000"],["111686.54000000","0.29537000"],["111687.10000000","0.00005000"],["111687.20000000","0.03997000"],["111687.88000000","0.00005000"],["111688.32000000","0.03958000"],["111688.71000000","0.00547000"],["111689.28000000","0.00000000"],["111689.34000000","0.00100000"],["111690.93000000","0.04002000"],["111691.11000000","0.00000000"],["111691.24000000","0.08504000"],["111692.35000000","0.00005000"],["111692.78000000","0.00005000"],["111697.03000000","0.04002000"],["111697.64000000","0.04012000"],["111698.28000000","0.04002000"],["111698.98000000","0.08007000"],["111699.04000000","0.00005000"],["111699.98000000","0.00000000"],["111700.01000000","0.30858000"],["111700.40000000","0.00005000"],["111700.57000000","0.13426000"],["111701.64000000","0.00000000"],["111705.08000000","0.00044000"],["111705.31000000","0.00000000"],["111707.05000000","0.68969000"],["111708.85000000","0.00000000"],["111712.11000000","0.00000000"],["111712.59000000","0.15000000"],["111712.71000000","0.01390000"],["111715.16000000","0.00000000"],["111716.08000000","0.00000000"],["111719.05000000","0.00000000"],["111731.72000000","0.00000000"],["111733.69000000","0.13433000"],["111734.25000000","0.32203000"],["111735.28000000","0.63108000"],["111735.90000000","0.00000000"],["111759.77000000","0.00000000"],["111763.12000000","0.13426000"],["111764.99000000","0.00100000"],["111765.00000000","0.00100000"],["111778.19000000","0.00322000"],["111790.26000000","0.00000000"],["111790.27000000","0.00000000"],["111791.02000000","0.00000000"],["111791.07000000","0.00000000"],["111791.35000000","0.00000000"],["111791.41000000","0.17904000"],["111791.97000000","0.00000000"],["111806.83000000","0.43430000"],["111808.26000000","0.01401000"],["111808.33000000","0.00000000"],["111841.76000000","0.16923000"],["111927.07000000","0.03997000"],["111978.26000000","0.02686000"],["111981.97000000","0.02398000"],["111985.00000000","0.02686000"],["113360.09000000","0.00100000"]]}
[2025-10-12T10:57:01.185Z] {"e":"depthUpdate","E":1760266621014,"s":"BTCUSDT","U":77965061806,"u":77965062176,"b":[["111684.80000000","1.09863000"],["111684.79000000","0.00110000"],["111684.41000000","0.01373000"],["111684.19000000","0.16323000"],["111684.18000000","0.05729000"],["111684.17000000","0.00010000"],["111683.18000000","0.01992000"],["111682.99000000","0.00552000"],["111681.82000000","0.00000000"],["111681.79000000","0.00005000"],["111681.78000000","0.05424000"],["111679.90000000","0.00005000"],["111679.78000000","0.00736000"],["111679.63000000","0.29534000"],["111679.24000000","0.00000000"],["111679.23000000","0.00000000"],["111678.94000000","0.02687000"],["111678.84000000","0.03995000"],["111674.00000000","0.00200000"],["111672.31000000","0.00000000"],["111672.20000000","0.00000000"],["111670.28000000","0.07612000"],["111670.21000000","0.00005000"],["111668.78000000","0.00000000"],["111667.48000000","0.02000000"],["111667.08000000","0.00000000"],["111667.00000000","0.00000000"],["111666.48000000","0.15000000"],["111666.38000000","0.00000000"],["111665.14000000","0.00000000"],["111664.88000000","0.04000000"],["111664.38000000","0.56000000"],["111663.05000000","0.00000000"],["111658.85000000","0.00005000"],["111658.39000000","0.00000000"],["111654.10000000","0.00000000"],["111650.65000000","0.00000000"],["111644.37000000","0.00000000"],["111644.25000000","0.32229000"],["111637.57000000","0.30203000"],["111636.01000000","0.00000000"],["111635.72000000","0.06890000"],["111632.87000000","0.00000000"],["111631.17000000","0.00000000"],["111624.89000000","0.32234000"],["111616.36000000","0.95187000"],["111616.32000000","0.00000000"],["111608.92000000","0.13581000"],["111602.93000000","1.25396000"],["111542.71000000","0.14250000"],["111307.19000000","0.00187000"],["111296.83000000","0.00000000"],["110581.59000000","0.00239000"],["110009.52000000","0.00100000"],["102768.90000000","0.00010000"],["100516.00000000","0.00100000"],["100515.00000000","0.00308000"],["89347.84000000","0.00022000"],["40206.53000000","0.00015000"],["33000.00000000","3.87311000"]],"a":[["111684.81000000","6.24924000"],["111684.82000000","0.00080000"],["111684.97000000","0.00905000"],["111685.02000000","0.00000000"],["111685.03000000","0.00000000"],["111685.20000000","0.01363000"],["111685.92000000","0.00000000"],["111685.93000000","0.00000000"],["111686.53000000","0.00010000"],["111686.54000000","0.29542000"],["111687.04000000","0.00363000"],["111687.10000000","0.00000000"],["111687.19000000","0.00005000"],["111687.20000000","0.04012000"],["111688.32000000","0.03963000"],["111688.45000000","0.00000000"],["111689.34000000","0.00005000"],["111690.92000000","0.00447000"],["111690.93000000","0.04012000"],["111691.16000000","0.08504000"],["111691.24000000","0.00000000"],["111691.80000000","0.28887000"],["111691.81000000","0.45020000"],["111691.82000000","0.00000000"],["111691.83000000","0.00000000"],["111692.19000000","0.04002000"],["111692.65000000","0.00000000"],["111692.96000000","0.00005000"],["111693.03000000","0.04012000"],["111695.35000000","0.00000000"],["111695.70000000","0.00005000"],["111696.59000000","0.40306000"],["111696.60000000","0.00000000"],["111697.03000000","0.04007000"],["111697.64000000","0.04007000"],["111698.28000000","0.04002000"],["111698.98000000","0.08002000"],["111699.98000000","0.15000000"],["111700.57000000","0.00000000"],["111700.75000000","0.04000000"],["111700.85000000","0.00000000"],["111700.99000000","0.13426000"],["111704.91000000","0.00000000"],["111705.31000000","0.00000000"],["111707.05000000","0.68969000"],["111708.85000000","0.00000000"],["111708.87000000","1.25396000"],["111712.59000000","0.00000000"],["111714.22000000","0.32208000"],["111715.99000000","0.17904000"],["111716.58000000","0.00894000"],["111717.08000000","0.00005000"],["111729.11000000","0.32204000"],["111729.57000000","0.55285000"],["111730.37000000","0.00000000"],["111731.72000000","0.13426000"],["111732.55000000","0.00000000"],["111734.25000000","0.00000000"],["111763.12000000","0.00000000"],["111791.41000000","0.00000000"],["111792.55000000","0.17904000"],["111797.99000000","0.04097000"],["111804.84000000","0.04097000"],["111824.96000000","0.72462000"],["111845.52000000","0.02688000"],["111867.84000000","0.00000000"],["111881.89000000","0.02596000"],["111892.29000000","0.00187000"],["111926.16000000","0.03997000"],["112014.83000000","0.00000000"],["112025.23000000","0.00079000"],["112081.40000000","0.00000000"],["112705.83000000","0.00234000"],["113360.09000000","0.00100000"],["145760.00000000","0.00004000"]]}
[2025-10-12T10:57:02.185Z] {"e":"depthUpdate","E":1760266622014,"s":"BTCUSDT","U":77965062177,"u":77965062672,"b":[["111684.80000000","0.10916000"],["111684.79000000","0.00100000"],["111684.56000000","0.00005000"],["111684.41000000","0.01378000"],["111684.19000000","0.00010000"],["111684.18000000","0.00010000"],["111684.17000000","0.00000000"],["111683.48000000","0.00010000"],["111683.18000000","0.01992000"],["111683.17000000","0.00010000"],["111682.99000000","0.00547000"],["111681.79000000","0.00000000"],["111681.78000000","0.00000000"],["111680.90000000","0.00552000"],["111680.58000000","0.11138000"],["111680.57000000","0.00005000"],["111679.90000000","0.00000000"],["111679.89000000","0.00000000"],["111679.86000000","0.00005000"],["111679.85000000","0.00005000"],["111679.78000000","0.00726000"],["111679.63000000","0.00000000"],["111678.95000000","0.00005000"],["111678.94000000","0.00000000"],["111678.84000000","0.00000000"],["111678.66000000","0.01796000"],["111678.01000000","0.01796000"],["111677.73000000","0.00000000"],["111677.72000000","0.00006000"],["111677.16000000","0.00010000"],["111677.15000000","0.06018000"],["111676.70000000","0.00000000"],["111676.49000000","0.00000000"],["111676.47000000","0.33031000"],["111676.25000000","0.00000000"],["111676.10000000","0.00000000"],["111676.09000000","0.02687000"],["111676.00000000","0.00205000"],["111675.58000000","0.00000000"],["111674.56000000","0.00005000"],["111674.53000000","0.00000000"],["111674.00000000","0.00205000"],["111673.54000000","0.00000000"],["111673.45000000","0.04067000"],["111672.61000000","0.00000000"],["111672.34000000","0.00070000"],["111672.33000000","0.04002000"],["111671.80000000","0.26206000"],["111671.79000000","0.00000000"],["111670.83000000","0.00000000"],["111670.54000000","0.00000000"],["111670.28000000","0.00000000"],["111669.54000000","0.00000000"],["111667.74000000","0.00000000"],["111667.48000000","0.00000000"],["111666.48000000","0.00000000"],["111666.46000000","0.54451000"],["111664.40000000","0.00000000"],["111663.98000000","0.02000000"],["111663.58000000","0.00100000"],["111663.05000000","0.00000000"],["111663.03000000","0.00000000"],["111662.22000000","0.00000000"],["111658.39000000","0.15000000"],["111658.37000000","0.00000000"],["111656.35000000","0.00000000"],["111656.01000000","0.00000000"],["111654.10000000","0.00000000"],["111652.19000000","0.01746000"],["111650.39000000","0.00000000"],["111650.28000000","0.02506000"],["111646.12000000","0.00000000"],["111646.00000000","1.22415000"],["111643.90000000","0.00000000"],["111642.71000000","0.66029000"],["111640.70000000","0.00000000"],["111640.02000000","0.00009000"],["111637.80000000","0.00028000"],["111637.57000000","0.00000000"],["111635.73000000","0.00000000"],["111635.72000000","0.00000000"],["111635.13000000","0.00000000"],["111633.33000000","0.00000000"],["111632.87000000","0.00000000"],["111631.55000000","0.00000000"],["111630.76000000","0.32233000"],["111630.50000000","0.00000000"],["111630.49000000","0.00000000"],["111629.62000000","0.00009000"],["111628.01000000","0.00000000"],["111627.53000000","0.00000000"],["111624.89000000","0.00000000"],["111624.51000000","0.30206000"],["111624.08000000","0.00000000"],["111620.37000000","0.00005000"],["111616.37000000","0.40306000"],["111615.18000000","0.08894000"],["111615.17000000","0.00000000"],["111610.56000000","0.00000000"],["111608.92000000","0.00000000"],["111604.23000000","0.08894000"],["111604.21000000","0.55376000"],["111604.01000000","0.00000000"],["111603.63000000","0.00617000"],["111600.34000000","0.00000000"],["111596.22000000","1.25396000"],["111594.25000000","0.00090000"],["111589.51000000","1.25396000"],["111548.01000000","0.02506000"],["111546.91000000","0.02596000"],["111545.09000000","0.00000000"],["111542.70000000","0.00000000"],["111542.22000000","0.02596000"],["111538.99000000","0.02596000"],["111535.24000000","0.08994000"],["111530.37000000","0.08994000"],["111530.19000000","0.02596000"],["111527.87000000","0.08994000"],["111527.43000000","0.04262000"],["111524.99000000","0.08994000"],["111502.35000000","0.00000000"],["111486.70000000","0.09464000"],["111485.29000000","0.00000000"],["111464.67000000","0.08794000"],["111462.77000000","0.08794000"],["111462.55000000","0.08794000"],["111462.29000000","0.08794000"],["111388.28000000","0.00000000"],["111377.77000000","0.00000000"],["111377.26000000","0.00000000"],["111375.80000000","0.00000000"],["111375.74000000","0.00000000"],["111374.66000000","0.00000000"],["111374.18000000","0.00000000"],["111373.96000000","0.00000000"],["111373.82000000","0.00000000"],["111373.80000000","0.00000000"],["111373.65000000","0.00000000"],["111373.20000000","0.00000000"],["111373.02000000","0.00000000"],["111373.00000000","0.00000000"],["111372.63000000","0.00000000"],["111351.86000000","0.00000000"],["111349.40000000","0.00000000"],["111337.34000000","0.05996000"],["111327.93000000","0.05996000"],["111327.02000000","0.05996000"],["111276.33000000","0.45000000"],["110009.52000000","0.00100000"],["102768.90000000","0.00000000"],["100515.00000000","0.00308000"],["89348.00000000","0.00335000"],["89347.84000000","0.00022000"]],"a":[["111684.81000000","7.40658000"],["111684.82000000","0.00000000"],["111684.96000000","0.00010000"],["111685.19000000","0.00000000"],["111685.20000000","0.01368000"],["111685.92000000","0.00100000"],["111686.51000000","0.00000000"],["111686.53000000","0.00000000"],["111686.54000000","0.29542000"],["111686.55000000","0.00287000"],["111686.87000000","0.00000000"],["111686.88000000","0.06656000"],["111687.19000000","0.00000000"],["111687.20000000","0.04007000"],["111688.32000000","0.03968000"],["111688.45000000","0.00005000"],["111688.71000000","0.00542000"],["111689.01000000","0.17187000"],["111689.34000000","0.00000000"],["111689.44000000","0.40306000"],["111689.66000000","0.00005000"],["111690.92000000","0.00000000"],["111690.93000000","0.04002000"],["111691.16000000","0.00000000"],["111692.12000000","0.05191000"],["111692.19000000","0.04002000"],["111692.88000000","0.00000000"],["111693.03000000","0.04007000"],["111693.22000000","0.40306000"],["111694.84000000","0.00005000"],["111695.98000000","0.00329000"],["111696.30000000","0.00044000"],["111697.03000000","0.04002000"],["111697.64000000","0.04002000"],["111698.28000000","0.04002000"],["111699.94000000","0.00006000"],["111700.75000000","0.00000000"],["111700.99000000","0.00000000"],["111702.17000000","0.00005000"],["111703.10000000","0.04002000"],["111704.92000000","1.25396000"],["111709.89000000","0.00000000"],["111712.71000000","0.00000000"],["111712.95000000","0.01390000"],["111715.99000000","0.00000000"],["111716.58000000","0.00000000"],["111717.91000000","0.00000000"],["111719.84000000","1.25396000"],["111719.86000000","1.16788000"],["111731.72000000","0.62658000"],["111732.39000000","0.00000000"],["111733.69000000","0.00000000"],["111737.37000000","0.04401000"],["111743.48000000","0.00000000"],["111752.26000000","0.00894000"],["111760.00000000","0.15659000"],["111766.44000000","0.00000000"],["111772.31000000","0.01800000"],["111775.18000000","0.00000000"],["111777.93000000","0.00000000"],["111778.72000000","0.00000000"],["111778.85000000","0.13644000"],["111785.20000000","0.00000000"],["111791.29000000","0.00000000"],["111791.63000000","0.00000000"],["111792.14000000","0.00000000"],["111792.42000000","0.00000000"],["111792.55000000","0.00000000"],["111792.70000000","0.00000000"],["111794.20000000","0.00000000"],["111794.30000000","0.00000000"],["111796.09000000","0.00000000"],["111801.63000000","0.00000000"],["111830.67000000","0.18283000"],["111830.79000000","0.02596000"],["112088.78000000","0.55838000"],["112215.91000000","0.02398000"],["113360.09000000","0.00100000"],["115776.01000000","0.00021000"],["116090.59000000","0.00000000"]]}
[2025-10-12T10:57:03.185Z] {"e":"depthUpdate","E":1760266623014,"s":"BTCUSDT","U":77965062673,"u":77965063240,"b":[["111684.80000000","0.26117000"],["111684.79000000","0.00090000"],["111684.73000000","0.00010000"],["111684.56000000","0.00000000"],["111684.41000000","0.01373000"],["111684.40000000","0.00020000"],["111684.20000000","0.00000000"],["111684.19000000","0.00000000"],["111684.18000000","0.00000000"],["111683.86000000","0.00000000"],["111683.83000000","0.00000000"],["111683.81000000","0.00000000"],["111683.48000000","0.00000000"],["111683.18000000","0.01992000"],["111682.98000000","0.00010000"],["111680.90000000","0.00547000"],["111680.59000000","0.00000000"],["111680.58000000","0.00000000"],["111680.57000000","0.00000000"],["111679.89000000","0.00000000"],["111679.88000000","0.00000000"],["111679.86000000","0.00000000"],["111679.85000000","0.00000000"],["111678.67000000","0.00010000"],["111678.66000000","0.01801000"],["111678.16000000","0.00005000"],["111678.02000000","0.00010000"],["111678.01000000","0.01806000"],["111677.72000000","0.00000000"],["111677.35000000","0.00000000"],["111677.34000000","0.00155000"],["111677.17000000","0.00005000"],["111677.16000000","0.15011000"],["111677.15000000","0.06023000"],["111676.47000000","0.05488000"],["111676.09000000","0.00000000"],["111676.00000000","0.00205000"],["111675.90000000","0.04248000"],["111674.00000000","0.00205000"],["111673.94000000","0.00000000"],["111673.93000000","0.00000000"],["111673.92000000","0.00000000"],["111673.64000000","0.00000000"],["111673.63000000","0.45151000"],["111673.45000000","0.00000000"],["111672.62000000","0.00000000"],["111672.33000000","0.04007000"],["111671.80000000","0.10565000"],["111671.47000000","0.00000000"],["111670.83000000","0.04475000"],["111670.21000000","0.00000000"],["111670.01000000","0.00000000"],["111669.45000000","0.00000000"],["111668.92000000","0.00000000"],["111667.68000000","0.04000000"],["111666.58000000","0.00000000"],["111666.47000000","0.45020000"],["111666.46000000","0.36480000"],["111665.07000000","0.00005000"],["111664.40000000","0.15000000"],["111664.00000000","0.00200000"],["111663.58000000","0.00000000"],["111663.28000000","0.00000000"],["111663.03000000","0.00100000"],["111662.95000000","0.00000000"],["111662.46000000","0.11490000"],["111660.60000000","0.00005000"],["111660.02000000","0.00000000"],["111660.00000000","0.93342000"],["111658.39000000","0.00000000"],["111658.28000000","0.00000000"],["111656.70000000","0.00895000"],["111656.33000000","0.00000000"],["111656.32000000","0.00000000"],["111655.98000000","0.40306000"],["111655.50000000","0.00011000"],["111655.29000000","0.00000000"],["111655.27000000","0.30036000"],["111654.10000000","0.00000000"],["111654.08000000","0.02999000"],["111651.60000000","0.00000000"],["111650.01000000","0.05996000"],["111647.95000000","0.00000000"],["111645.64000000","0.08504000"],["111642.72000000","0.00005000"],["111640.73000000","0.00000000"],["111638.15000000","0.00000000"],["111635.15000000","0.00000000"],["111635.04000000","0.08000000"],["111634.76000000","0.08901000"],["111632.01000000","0.02686000"],["111630.32000000","0.06742000"],["111627.70000000","0.38615000"],["111624.84000000","0.00005000"],["111624.01000000","0.06087000"],["111622.74000000","0.00809000"],["111621.44000000","0.00000000"],["111620.37000000","0.00000000"],["111620.04000000","0.08000000"],["111620.01000000","0.11311000"],["111617.16000000","0.00809000"],["111616.01000000","0.00000000"],["111615.18000000","0.00000000"],["111615.06000000","0.00000000"],["111614.71000000","0.13433000"],["111614.42000000","0.00000000"],["111610.51000000","0.40306000"],["111604.23000000","0.00000000"],["111604.22000000","0.40306000"],["111599.82000000","0.00615000"],["111598.24000000","0.00628000"],["111598.04000000","0.00000000"],["111595.09000000","0.00000000"],["111590.06000000","0.00000000"],["111585.09000000","0.00000000"],["111582.81000000","0.63663000"],["111582.80000000","1.25396000"],["111581.53000000","0.00000000"],["111577.37000000","0.40008000"],["111573.02000000","0.02464000"],["111569.09000000","0.02417000"],["111568.79000000","0.04045000"],["111566.28000000","0.00000000"],["111565.04000000","0.02417000"],["111561.01000000","0.00000000"],["111560.00000000","0.00260000"],["111558.95000000","0.02417000"],["111554.28000000","0.13433000"],["111554.13000000","0.00000000"],["111551.66000000","0.02417000"],["111550.07000000","0.00000000"],["111549.06000000","0.50441000"],["111548.56000000","0.00000000"],["111543.31000000","0.02417000"],["111539.01000000","0.02417000"],["111536.12000000","0.08994000"],["111532.83000000","0.08994000"],["111529.47000000","0.02596000"],["111529.06000000","0.08994000"],["111527.43000000","0.09318000"],["111526.39000000","0.08994000"],["111523.43000000","0.08994000"],["111480.11000000","0.99317000"],["111475.41000000","0.00000000"],["111468.41000000","0.00000000"],["111465.47000000","0.00000000"],["111465.14000000","0.00000000"],["111462.86000000","0.08794000"],["111462.41000000","0.00000000"],["111460.30000000","0.00000000"],["111456.55000000","0.00000000"],["111415.42000000","0.00000000"],["111410.46000000","0.00574000"],["111409.00000000","0.01739000"],["111406.17000000","0.00000000"],["111404.96000000","0.00000000"],["111402.19000000","0.00000000"],["111400.69000000","0.01701000"],["111397.86000000","0.00000000"],["111392.37000000","0.01701000"],["111384.06000000","0.01701000"],["111382.31000000","0.00000000"],["111374.01000000","0.00000000"],["111366.71000000","0.00000000"],["111354.61000000","0.00000000"],["111354.30000000","0.00000000"],["111351.63000000","0.02596000"],["111351.18000000","0.02686000"],["111349.42000000","0.00000000"],["111349.41000000","0.05896000"],["111348.54000000","0.02596000"],["111345.08000000","0.02686000"],["111341.99000000","0.02686000"],["111339.11000000","0.02686000"],["111335.96000000","0.02686000"],["111333.32000000","0.02686000"],["111333.25000000","0.05996000"],["111332.55000000","0.05996000"],["111331.67000000","0.05996000"],["111330.93000000","0.05996000"],["111330.68000000","0.02849000"],["111330.09000000","0.02686000"],["111330.03000000","0.05996000"],["111328.86000000","0.06005000"],["111327.93000000","0.11992000"],["111327.80000000","0.02686000"],["111327.35000000","0.02686000"],["111327.09000000","0.05996000"],["111326.71000000","0.03581000"],["111326.65000000","0.05996000"],["111326.08000000","0.05996000"],["111325.72000000","0.07162000"],["111325.31000000","0.02686000"],["111324.97000000","0.05996000"],["111324.09000000","0.02686000"],["111322.62000000","0.02686000"],["111307.19000000","0.00000000"],["111292.57000000","0.00000000"],["111275.23000000","0.00187000"],["111240.77000000","0.00000000"],["111235.23000000","0.00000000"],["111232.20000000","0.00000000"],["111205.31000000","0.03581000"],["111199.21000000","0.03581000"],["111193.58000000","0.03581000"],["111185.84000000","0.03581000"],["111055.92000000","0.00000000"],["111048.55000000","0.89111000"],["110581.59000000","0.00000000"],["110009.52000000","0.00100000"],["100516.00000000","0.00100000"],["100515.00000000","0.00308000"],["89347.84000000","0.00022000"],["40206.53000000","0.00030000"]],"a":[["111684.81000000","7.36356000"],["111684.96000000","0.00000000"],["111688.32000000","0.03963000"],["111688.35000000","0.00000000"],["111688.45000000","0.00000000"],["111689.01000000","0.17192000"],["111689.43000000","0.55697000"],["111691.80000000","0.00000000"],["111692.07000000","0.01765000"],["111692.19000000","0.04007000"],["111692.65000000","0.04000000"],["111695.98000000","0.00334000"],["111697.03000000","0.04007000"],["111697.64000000","0.04007000"],["111698.28000000","0.04002000"],["111699.05000000","0.00005000"],["111700.01000000","0.04006000"],["111701.20000000","0.13426000"],["111702.43000000","0.13426000"],["111704.12000000","0.22692000"],["111709.69000000","0.00012000"],["111716.34000000","0.30880000"],["111724.26000000","0.02685000"],["111729.20000000","0.00000000"],["111729.26000000","0.00000000"],["111729.84000000","0.02237000"],["111731.72000000","0.31330000"],["111740.86000000","0.06988000"],["111742.27000000","0.00000000"],["111745.99000000","0.02596000"],["111747.85000000","0.00000000"],["111748.35000000","0.00625000"],["111760.09000000","0.13426000"],["111762.85000000","0.00000000"],["111765.53000000","0.00000000"],["111790.95000000","0.00000000"],["111792.53000000","0.13433000"],["111792.82000000","0.22377000"],["111793.57000000","0.00000000"],["111795.34000000","0.00000000"],["111808.26000000","0.00000000"],["111811.71000000","0.02417000"],["111812.38000000","0.65263000"],["111814.04000000","0.02417000"],["111815.18000000","0.99369000"],["111824.96000000","0.00000000"],["111825.02000000","0.00000000"],["111832.55000000","0.03997000"],["111844.20000000","0.03997000"],["111852.16000000","0.01824000"],["111860.20000000","0.00187000"],["111865.65000000","0.00000000"],["111869.04000000","0.00000000"],["111870.30000000","0.00000000"],["111871.47000000","0.00000000"],["111892.29000000","0.00000000"],["111899.32000000","0.01701000"],["111939.48000000","0.00005000"],["111944.84000000","0.00000000"],["111951.59000000","0.00000000"],["111970.29000000","0.02596000"],["111982.01000000","0.03581000"],["111982.11000000","0.02686000"],["111993.12000000","0.00079000"],["112010.07000000","0.00000000"],["112025.23000000","0.00000000"],["112069.64000000","0.00000000"],["112077.59000000","0.03581000"],["112082.18000000","0.00000000"],["112095.17000000","0.00000000"],["112175.07000000","0.03581000"],["112215.02000000","0.00000000"],["112215.05000000","0.00000000"],["112215.69000000","0.00000000"],["112705.83000000","0.00000000"],["113360.09000000","0.00100000"]]}
[2025-10-12T10:57:04.185Z] {"e":"depthUpdate","E":1760266624014,"s":"BTCUSDT","U":77965063241,"u":77965063505,"b":[["111684.80000000","0.07984000"],["111684.79000000","0.00095000"],["111684.73000000","0.00010000"],["111684.56000000","0.00005000"],["111683.81000000","0.00000000"],["111683.76000000","0.00020000"],["111683.70000000","0.00010000"],["111682.98000000","0.00010000"],["111682.45000000","0.00010000"],["111682.17000000","0.00000000"],["111678.01000000","0.01806000"],["111677.38000000","0.25251000"],["111677.37000000","0.15455000"],["111677.36000000","0.00005000"],["111677.35000000","0.00000000"],["111677.31000000","0.00000000"],["111677.30000000","0.00000000"],["111677.29000000","0.00000000"],["111677.17000000","0.00000000"],["111677.16000000","0.00005000"],["111677.15000000","0.06018000"],["111674.46000000","0.29535000"],["111674.00000000","0.00205000"],["111673.63000000","0.00151000"],["111672.33000000","0.04002000"],["111671.80000000","0.15930000"],["111668.53000000","0.00000000"],["111668.37000000","0.00000000"],["111667.68000000","0.00000000"],["111667.20000000","0.17899000"],["111664.40000000","0.15000000"],["111664.02000000","0.00000000"],["111663.03000000","0.00000000"],["111660.61000000","0.00000000"],["111660.27000000","0.00000000"],["111660.02000000","0.00000000"],["111660.00000000","0.79441000"],["111659.29000000","0.00447000"],["111659.28000000","0.04000000"],["111658.38000000","0.01163000"],["111656.35000000","0.00000000"],["111656.33000000","0.00000000"],["111655.28000000","0.00000000"],["111653.55000000","0.35799000"],["111652.15000000","0.00010000"],["111644.10000000","0.36770000"],["111630.32000000","0.00000000"],["111592.71000000","0.64715000"],["111524.17000000","0.06000000"],["111522.97000000","0.02596000"],["111290.88000000","0.00000000"],["111289.54000000","0.00250000"],["110960.98000000","0.00000000"],["110843.76000000","0.00035000"],["110701.72000000","0.00231000"],["110554.53000000","0.00000000"],["110009.52000000","0.00100000"],["106100.00000000","0.69851000"],["100516.32000000","0.00019000"],["100515.00000000","0.00308000"],["89347.84000000","0.00022000"],["60000.00000000","53.14032000"]],"a":[["111684.81000000","7.25788000"],["111685.92000000","0.00105000"],["111686.51000000","0.00447000"],["111690.92000000","0.35799000"],["111692.19000000","0.04002000"],["111692.65000000","0.00000000"],["111697.02000000","0.34258000"],["111697.03000000","0.04007000"],["111697.15000000","0.07200000"],["111697.64000000","0.04002000"],["111698.33000000","0.07200000"],["111700.00000000","0.40306000"],["111703.15000000","0.00799000"],["111703.50000000","0.00000000"],["111704.68000000","0.00000000"],["111708.92000000","0.32210000"],["111710.37000000","0.00895000"],["111729.11000000","0.00000000"],["111729.20000000","0.00005000"],["111731.72000000","0.31330000"],["111731.82000000","0.13433000"],["111764.84000000","0.00100000"],["111764.85000000","0.00100000"],["111764.99000000","0.00000000"],["111765.00000000","0.00000000"],["111791.11000000","0.00000000"],["111792.77000000","0.22377000"],["111792.82000000","0.00000000"],["111793.28000000","0.22377000"],["111794.91000000","0.00223000"],["111815.01000000","0.00000000"],["111824.96000000","0.43434000"],["111825.26000000","0.06000000"],["111827.45000000","0.02596000"],["111852.16000000","0.00000000"],["111852.17000000","0.00000000"],["111881.68000000","0.00089000"],["111887.60000000","0.07517000"],["111902.54000000","0.00000000"],["111924.03000000","0.00000000"],["111967.58000000","0.00000000"],["111968.93000000","0.00250000"],["113360.09000000","0.00100000"]]}
[2025-10-12T10:57:05.185Z] {"e":"depthUpdate","E":1760266625014,"s":"BTCUSDT","U":77965063506,"u":77965063739,"b":[["111684.80000000","0.37637000"],["111684.79000000","0.00100000"],["111684.73000000","0.00010000"],["111684.56000000","0.00000000"],["111683.76000000","0.00010000"],["111683.70000000","0.00000000"],["111682.98000000","0.00010000"],["111682.45000000","0.00000000"],["111678.66000000","0.01806000"],["111678.31000000","0.00010000"],["111678.30000000","0.08837000"],["111678.29000000","0.29539000"],["111678.02000000","0.00000000"],["111678.01000000","0.01801000"],["111678.00000000","0.00210000"],["111677.39000000","0.00000000"],["111677.38000000","0.05734000"],["111677.37000000","0.00000000"],["111677.36000000","0.00000000"],["111677.15000000","0.06018000"],["111675.90000000","0.04253000"],["111674.73000000","0.02687000"],["111674.46000000","0.00000000"],["111674.00000000","0.00205000"],["111673.63000000","0.00151000"],["111668.41000000","0.00000000"],["111668.37000000","0.17899000"],["111667.20000000","0.00000000"],["111663.14000000","0.00100000"],["111660.01000000","0.60299000"],["111660.00000000","0.42520000"],["111656.64000000","0.00000000"],["111656.08000000","0.35798000"],["111653.55000000","0.00000000"],["111649.73000000","0.32227000"],["111630.76000000","0.00000000"],["111629.76000000","0.06714000"],["111624.51000000","0.00000000"],["111622.30000000","0.30207000"],["111605.26000000","0.00005000"],["111602.96000000","0.13261000"],["111591.32000000","0.00000000"],["111590.01000000","0.00163000"],["111566.29000000","0.00000000"],["111566.15000000","0.00223000"],["111550.00000000","0.00617000"],["111527.43000000","0.13922000"],["111525.20000000","0.08994000"],["111479.90000000","0.00000000"],["111478.26000000","0.00065000"],["111452.44000000","0.00000000"],["111275.23000000","0.00000000"],["111252.89000000","0.00187000"],["110009.52000000","0.00100000"],["100516.32000000","0.00000000"],["100515.00000000","0.00308000"],["89347.84000000","0.00022000"],["60000.00000000","53.14022000"]],"a":[["111684.81000000","7.33342000"],["111684.82000000","0.00005000"],["111685.92000000","0.00100000"],["111686.51000000","0.00000000"],["111686.55000000","0.00292000"],["111686.87000000","0.00447000"],["111687.20000000","0.04012000"],["111688.05000000","0.04005000"],["111689.01000000","0.17187000"],["111690.39000000","0.00056000"],["111693.95000000","0.00000000"],["111695.98000000","0.00329000"],["111697.03000000","0.04002000"],["111702.40000000","0.04805000"],["111725.85000000","0.00000000"],["111731.82000000","0.00000000"],["111790.99000000","0.22377000"],["111791.05000000","0.13433000"],["111791.99000000","0.00223000"],["111792.53000000","0.00000000"],["111792.77000000","0.00000000"],["111794.91000000","0.00000000"],["111834.90000000","0.11764000"],["111837.75000000","0.00187000"],["111860.20000000","0.00000000"],["111903.56000000","0.00089000"],["111926.76000000","0.00000000"],["111929.59000000","0.03997000"],["111937.89000000","0.00000000"],["111970.68000000","0.00079000"],["111993.12000000","0.00000000"],["112085.09000000","0.55838000"],["112088.78000000","0.00000000"],["113360.09000000","0.00100000"],["121118.53000000","0.00016000"],["121735.73000000","0.00016000"],["122352.93000000","0.00016000"],["122970.13000000","0.00016000"],["123587.33000000","0.00016000"],["124204.53000000","0.00016000"],["124821.73000000","0.00016000"],["125438.93000000","0.00016000"],["126056.13000000","0.00016000"]]}
[2025-10-12T10:57:06.187Z] {"e":"depthUpdate","E":1760266626014,"s":"BTCUSDT","U":77965063740,"u":77965067771,"b":[["111684.80000000","0.00000000"],["111684.79000000","0.00000000"],["111684.78000000","0.00000000"],["111684.73000000","0.00000000"],["111684.56000000","0.00000000"],["111684.42000000","0.00000000"],["111684.41000000","0.00000000"],["111684.40000000","0.00000000"],["111683.76000000","0.00000000"],["111683.73000000","0.00000000"],["111683.70000000","0.00000000"],["111683.45000000","0.00000000"],["111683.24000000","0.00000000"],["111683.19000000","0.00000000"],["111683.18000000","0.00000000"],["111683.17000000","0.00000000"],["111683.02000000","0.00000000"],["111682.99000000","0.00000000"],["111682.98000000","0.00000000"],["111682.34000000","0.00000000"],["111682.30000000","0.00000000"],["111682.25000000","0.00000000"],["111680.90000000","0.00000000"],["111680.69000000","0.00000000"],["111680.29000000","0.00000000"],["111679.78000000","0.00000000"],["111679.77000000","0.00000000"],["111679.50000000","0.00000000"],["111678.95000000","0.00000000"],["111678.67000000","0.00000000"],["111678.66000000","0.00000000"],["111678.65000000","0.00000000"],["111678.61000000","0.00000000"],["111678.31000000","0.00000000"],["111678.30000000","0.00000000"],["111678.29000000","0.00000000"],["111678.16000000","0.00000000"],["111678.02000000","0.00000000"],["111678.01000000","0.00000000"],["111678.00000000","0.00000000"],["111677.42000000","0.00000000"],["111677.41000000","0.00000000"],["111677.40000000","0.00000000"],["111677.39000000","0.00000000"],["111677.38000000","0.00000000"],["111677.34000000","0.00000000"],["111677.26000000","0.00000000"],["111677.16000000","0.00000000"],["111677.15000000","0.00000000"],["111677.14000000","0.00000000"],["111677.13000000","0.00000000"],["111677.12000000","0.00000000"],["111676.82000000","0.00000000"],["111676.48000000","0.00000000"],["111676.47000000","0.00000000"],["111676.00000000","0.00000000"],["111675.99000000","0.00000000"],["111675.98000000","0.00000000"],["111675.90000000","0.00000000"],["111675.71000000","0.00000000"],["111675.70000000","0.00000000"],["111675.60000000","0.00000000"],["111675.59000000","0.00000000"],["111675.29000000","0.00000000"],["111674.78000000","0.00000000"],["111674.73000000","0.00000000"],["111674.57000000","0.00000000"],["111674.56000000","0.00000000"],["111674.03000000","0.00000000"],["111674.00000000","0.00000000"],["111673.99000000","0.00000000"],["111673.76000000","0.00000000"],["111673.63000000","0.00000000"],["111673.62000000","0.00000000"],["111672.95000000","0.00000000"],["111672.60000000","0.00000000"],["111672.34000000","0.00000000"],["111672.33000000","0.00000000"],["111672.25000000","0.00000000"],["111672.00000000","0.00000000"],["111671.99000000","0.00000000"],["111671.89000000","0.00000000"],["111671.81000000","0.00000000"],["111671.80000000","0.00000000"],["111671.79000000","0.00000000"],["111671.67000000","0.00000000"],["111671.53000000","0.00000000"],["111670.90000000","0.00000000"],["111670.84000000","0.00000000"],["111670.83000000","0.00000000"],["111670.00000000","0.00000000"],["111669.83000000","0.00000000"],["111669.45000000","0.00000000"],["111669.44000000","0.00000000"],["111669.40000000","0.00000000"],["111669.39000000","0.00000000"],["111668.90000000","0.00000000"],["111668.37000000","0.00000000"],["111668.36000000","0.00000000"],["111668.35000000","0.00000000"],["111668.33000000","0.00000000"],["111668.30000000","0.84065000"],["111668.29000000","0.00115000"],["111668.28000000","0.00020000"],["111668.26000000","0.00000000"],["111668.23000000","0.00010000"],["111668.05000000","0.00005000"],["111668.00000000","0.00225000"],["111667.99000000","0.00020000"],["111667.83000000","0.00000000"],["111667.82000000","0.00000000"],["111667.78000000","0.00000000"],["111667.22000000","0.00000000"],["111667.21000000","0.00000000"],["111667.19000000","0.00000000"],["111666.61000000","0.00000000"],["111666.47000000","0.00010000"],["111666.46000000","0.06385000"],["111666.45000000","0.00010000"],["111666.36000000","0.00010000"],["111666.35000000","0.04482000"],["111666.34000000","0.00010000"],["111666.12000000","0.00000000"],["111666.02000000","0.00005000"],["111666.00000000","0.00200000"],["111665.97000000","0.00000000"],["111665.96000000","0.00005000"],["111665.84000000","0.04099000"],["111665.83000000","0.00000000"],["111665.82000000","0.00005000"],["111665.32000000","0.00000000"],["111665.28000000","0.00000000"],["111665.07000000","0.00000000"],["111664.88000000","0.00000000"],["111664.85000000","0.00010000"],["111664.84000000","0.03994000"],["111664.78000000","0.00000000"],["111664.45000000","0.00000000"],["111664.40000000","0.00000000"],["111664.38000000","0.00000000"],["111664.25000000","0.00000000"],["111664.03000000","0.00010000"],["111664.02000000","0.04850000"],["111664.00000000","0.00205000"],["111663.98000000","0.00000000"],["111663.94000000","0.00000000"],["111663.93000000","0.00000000"],["111663.66000000","0.00005000"],["111663.65000000","0.04392000"],["111663.14000000","0.00000000"],["111662.74000000","0.00005000"],["111662.50000000","0.00000000"],["111662.46000000","0.00305000"],["111662.00000000","0.00205000"],["111661.91000000","0.00155000"],["111661.89000000","0.00000000"],["111661.59000000","0.00000000"],["111660.60000000","0.00000000"],["111660.56000000","0.26385000"],["111660.55000000","0.29544000"],["111660.03000000","0.00000000"],["111660.02000000","0.00000000"],["111660.01000000","0.00000000"],["111660.00000000","0.02224000"],["111659.99000000","0.04142000"],["111659.88000000","0.00000000"],["111659.29000000","0.00000000"],["111659.28000000","0.00000000"],["111659.25000000","0.00160000"],["111659.24000000","0.04475000"],["111658.90000000","0.01164000"],["111658.68000000","0.00000000"],["111658.65000000","0.00069000"],["111658.47000000","0.00000000"],["111658.40000000","0.00005000"],["111658.39000000","0.00000000"],["111658.38000000","0.01163000"],["111658.30000000","0.00000000"],["111658.00000000","0.00200000"],["111657.44000000","0.00000000"],["111657.19000000","0.00000000"],["111656.92000000","0.00000000"],["111656.70000000","0.00000000"],["111656.68000000","0.00000000"],["111656.53000000","0.00000000"],["111656.47000000","0.00000000"],["111656.18000000","0.00000000"],["111656.13000000","0.00000000"],["111656.08000000","0.00000000"],["111656.07000000","0.00000000"],["111656.02000000","0.00000000"],["111655.98000000","0.00000000"],["111655.28000000","0.00000000"],["111655.27000000","0.44090000"],["111654.78000000","0.00000000"],["111654.61000000","0.00000000"],["111654.28000000","0.00000000"],["111654.09000000","0.00000000"],["111653.56000000","0.00005000"],["111653.55000000","0.00000000"],["111653.54000000","0.00000000"],["111652.97000000","0.00000000"],["111652.87000000","0.00000000"],["111652.75000000","0.00100000"],["111652.58000000","0.00022000"],["111652.48000000","0.04000000"],["111652.28000000","0.00000000"],["111652.25000000","0.00000000"],["111652.02000000","0.00005000"],["111651.54000000","0.11190000"],["111651.47000000","0.00000000"],["111651.30000000","0.17901000"],["111651.20000000","0.00000000"],["111650.28000000","0.00000000"],["111650.02000000","0.00000000"],["111650.01000000","0.00000000"],["111649.73000000","0.00000000"],["111649.67000000","0.14000000"],["111649.62000000","0.00007000"],["111649.61000000","0.00000000"],["111649.60000000","0.31514000"],["111649.59000000","0.00000000"],["111648.60000000","0.00000000"],["111648.47000000","0.00000000"],["111647.99000000","0.15000000"],["111647.97000000","0.48000000"],["111647.93000000","0.00000000"],["111647.59000000","0.00000000"],["111647.30000000","0.00000000"],["111646.36000000","0.00000000"],["111646.26000000","0.00000000"],["111646.25000000","0.00000000"],["111646.24000000","0.00000000"],["111646.23000000","0.00000000"],["111646.00000000","0.00260000"],["111645.64000000","0.00000000"],["111645.45000000","0.00005000"],["111644.91000000","0.00000000"],["111644.25000000","0.00000000"],["111644.13000000","0.00000000"],["111644.11000000","1.00306000"],["111643.41000000","0.35799000"],["111643.06000000","0.00000000"],["111642.85000000","0.00000000"],["111642.72000000","0.00005000"],["111642.71000000","0.00000000"],["111642.56000000","0.00000000"],["111641.87000000","0.01390000"],["111641.82000000","0.00000000"],["111641.21000000","0.00447000"],["111640.85000000","0.00000000"],["111640.02000000","0.00000000"],["111640.01000000","0.05995000"],["111639.10000000","0.00000000"],["111638.87000000","0.00000000"],["111638.14000000","0.00000000"],["111638.09000000","0.04800000"],["111637.97000000","0.00000000"],["111637.80000000","0.00010000"],["111637.70000000","0.00000000"],["111637.69000000","0.00000000"],["111636.44000000","0.01791000"],["111636.29000000","0.13426000"],["111635.76000000","0.00270000"],["111634.07000000","0.00000000"],["111633.92000000","0.00000000"],["111632.41000000","0.00000000"],["111631.85000000","0.06013000"],["111631.01000000","0.00000000"],["111630.40000000","0.32233000"],["111630.17000000","0.00000000"],["111629.97000000","0.13426000"],["111629.76000000","0.00000000"],["111629.71000000","0.00000000"],["111629.62000000","0.00000000"],["111628.59000000","0.08504000"],["111628.56000000","0.00178000"],["111627.70000000","0.24819000"],["111627.51000000","0.00009000"],["111627.04000000","0.00000000"],["111626.61000000","0.00447000"],["111626.12000000","0.08504000"],["111625.95000000","0.00012000"],["111625.75000000","0.00000000"],["111625.29000000","0.00018000"],["111625.05000000","0.00000000"],["111625.03000000","0.32234000"],["111624.77000000","0.00000000"],["111624.15000000","0.03827000"],["111623.41000000","0.02125000"],["111623.34000000","0.00000000"],["111623.33000000","0.00000000"],["111623.16000000","0.00000000"],["111623.08000000","0.00000000"],["111622.93000000","0.00000000"],["111622.74000000","0.00008000"],["111622.30000000","0.00000000"],["111622.01000000","0.02507000"],["111621.82000000","0.62677000"],["111621.80000000","0.00000000"],["111621.76000000","0.00000000"],["111620.37000000","0.00005000"],["111620.15000000","0.00000000"],["111620.01000000","0.00000000"],["111619.89000000","0.00000000"],["111618.11000000","0.32236000"],["111618.01000000","0.00000000"],["111617.92000000","0.00000000"],["111617.16000000","0.00008000"],["111617.11000000","0.00009000"],["111616.65000000","0.08504000"],["111616.38000000","0.00000000"],["111616.34000000","0.00000000"],["111616.33000000","0.00000000"],["111615.90000000","0.00005000"],["111613.63000000","0.30209000"],["111613.62000000","0.00000000"],["111612.43000000","0.00000000"],["111611.43000000","0.00005000"],["111611.41000000","0.00000000"],["111610.60000000","0.08504000"],["111609.06000000","0.18885000"],["111608.54000000","0.08694000"],["111606.01000000","0.08894000"],["111604.78000000","0.00000000"],["111604.02000000","0.08503000"],["111602.98000000","0.01700000"],["111602.96000000","0.00000000"],["111602.23000000","0.07251000"],["111599.24000000","0.40306000"],["111598.95000000","0.00000000"],["111598.62000000","0.00000000"],["111598.22000000","0.00000000"],["111597.49000000","0.00000000"],["111597.30000000","0.04375000"],["111596.28000000","0.00000000"],["111595.60000000","0.00661000"],["111594.25000000","0.00000000"],["111592.72000000","0.40306000"],["111592.70000000","0.00000000"],["111592.26000000","0.00000000"],["111591.82000000","0.00447000"],["111590.73000000","0.00000000"],["111590.01000000","0.00000000"],["111589.64000000","0.00005000"],["111588.02000000","0.00000000"],["111586.62000000","0.02125000"],["111586.51000000","0.00000000"],["111586.50000000","0.00000000"],["111585.03000000","0.00000000"],["111584.69000000","0.00000000"],["111584.68000000","0.25307000"],["111583.62000000","0.02173000"],["111583.39000000","0.04800000"],["111582.26000000","0.05280000"],["111582.22000000","0.04800000"],["111582.01000000","0.00000000"],["111581.75000000","0.00090000"],["111580.41000000","0.00163000"],["111580.40000000","0.00000000"],["111580.39000000","0.00000000"],["111578.29000000","0.00000000"],["111577.78000000","0.05280000"],["111577.37000000","0.46391000"],["111576.61000000","0.06720000"],["111576.59000000","0.00000000"],["111576.09000000","1.25396000"],["111575.86000000","0.00000000"],["111575.28000000","0.00000000"],["111575.19000000","0.01800000"],["111574.03000000","0.00000000"],["111573.74000000","0.13426000"],["111573.69000000","0.04277000"],["111572.79000000","0.00000000"],["111571.72000000","0.56934000"],["111570.29000000","0.00222000"],["111570.20000000","0.00000000"],["111569.38000000","1.25396000"],["111569.08000000","0.00000000"],["111567.82000000","0.34629000"],["111567.42000000","0.13426000"],["111566.15000000","0.00000000"],["111566.13000000","0.08547000"],["111563.09000000","0.00000000"],["111562.14000000","0.00000000"],["111561.52000000","0.00000000"],["111561.01000000","0.00000000"],["111561.00000000","0.00000000"],["111560.24000000","0.00000000"],["111560.00000000","0.02052000"],["111559.23000000","0.40696000"],["111558.46000000","0.00000000"],["111558.23000000","0.00111000"],["111558.09000000","0.00000000"],["111556.65000000","0.00000000"],["111556.01000000","0.00000000"],["111554.47000000","0.07251000"],["111554.21000000","0.58273000"],["111553.99000000","0.00000000"],["111553.22000000","0.00000000"],["111552.58000000","0.22377000"],["111552.47000000","0.00000000"],["111551.98000000","0.00000000"],["111551.55000000","0.00000000"],["111551.48000000","0.89599000"],["111550.49000000","0.00223000"],["111550.48000000","0.22377000"],["111550.39000000","0.00000000"],["111550.01000000","0.00000000"],["111550.00000000","0.00528000"],["111549.30000000","0.00000000"],["111549.06000000","0.41646000"],["111547.59000000","0.00000000"],["111547.57000000","0.02417000"],["111547.15000000","0.00000000"],["111546.41000000","0.00000000"],["111546.01000000","0.02702000"],["111542.24000000","0.07807000"],["111541.86000000","0.00000000"],["111539.70000000","0.02417000"],["111536.96000000","0.16842000"],["111534.54000000","0.01236000"],["111533.93000000","0.02417000"],["111533.06000000","0.00000000"],["111530.81000000","0.02417000"],["111527.43000000","0.39958000"],["111526.31000000","0.00000000"],["111526.04000000","0.02417000"],["111525.61000000","0.02417000"],["111525.41000000","0.44775000"],["111524.84000000","0.08894000"],["111524.82000000","0.08894000"],["111524.53000000","0.08924000"],["111522.40000000","0.08894000"],["111522.39000000","0.08894000"],["111521.50000000","0.02417000"],["111520.22000000","0.09894000"],["111520.01000000","0.13597000"],["111517.57000000","0.00000000"],["111515.95000000","0.00000000"],["111515.62000000","0.00010000"],["111514.25000000","0.00000000"],["111514.23000000","0.01086000"],["111510.60000000","0.08622000"],["111507.06000000","0.04947000"],["111503.98000000","0.00000000"],["111498.19000000","0.12054000"],["111493.71000000","0.00000000"],["111493.59000000","0.32979000"],["111487.36000000","0.17314000"],["111486.70000000","0.00000000"],["111480.12000000","0.26690000"],["111480.11000000","0.00000000"],["111479.70000000","0.15901000"],["111478.26000000","0.00000000"],["111476.01000000","0.10465000"],["111474.01000000","0.00000000"],["111473.95000000","0.09465000"],["111473.01000000","0.02596000"],["111470.90000000","0.00000000"],["111470.62000000","0.04634000"],["111470.61000000","0.05430000"],["111468.02000000","0.00065000"],["111468.01000000","0.00000000"],["111465.01000000","0.99835000"],["111460.06000000","0.08794000"],["111459.75000000","0.08794000"],["111458.01000000","0.00089000"],["111454.01000000","0.00000000"],["111452.26000000","0.00000000"],["111448.01000000","0.00000000"],["111438.61000000","0.00089000"],["111435.08000000","4.78544000"],["111423.11000000","0.00000000"],["111409.09000000","0.00467000"],["111404.65000000","0.00000000"],["111398.63000000","0.00010000"],["111396.10000000","0.89724000"],["111376.81000000","0.00000000"],["111376.25000000","0.00000000"],["111374.70000000","0.00000000"],["111374.48000000","0.94679000"],["111374.19000000","0.00000000"],["111371.32000000","0.00000000"],["111370.99000000","0.00000000"],["111370.39000000","0.00000000"],["111370.01000000","0.00000000"],["111368.56000000","0.00000000"],["111367.24000000","0.00000000"],["111367.05000000","0.00000000"],["111365.15000000","0.00000000"],["111364.73000000","0.00000000"],["111364.19000000","0.00010000"],["111361.42000000","0.00000000"],["111361.10000000","0.00000000"],["111360.39000000","0.00000000"],["111359.39000000","0.00000000"],["111359.37000000","0.00000000"],["111358.61000000","0.00010000"],["111358.03000000","0.00000000"],["111357.52000000","0.00000000"],["111355.80000000","0.00000000"],["111355.63000000","0.00000000"],["111355.44000000","0.00000000"],["111355.02000000","0.00000000"],["111354.77000000","0.00000000"],["111353.68000000","0.00000000"],["111353.03000000","0.00010000"],["111351.83000000","0.00000000"],["111350.95000000","0.00000000"],["111347.45000000","0.00000000"],["111347.25000000","0.00000000"],["111346.56000000","0.00000000"],["111345.82000000","0.00000000"],["111342.13000000","0.00000000"],["111341.00000000","0.02596000"],["111340.18000000","0.02596000"],["111337.62000000","0.02596000"],["111336.36000000","0.02596000"],["111335.43000000","0.00000000"],["111333.14000000","0.02596000"],["111330.20000000","0.02596000"],["111327.02000000","0.00000000"],["111326.65000000","0.00000000"],["111326.13000000","0.03581000"],["111325.58000000","0.03581000"],["111324.56000000","0.03581000"],["111324.00000000","0.03581000"],["111323.98000000","0.03581000"],["111323.73000000","0.03581000"],["111323.67000000","0.03581000"],["111323.51000000","0.05996000"],["111322.41000000","0.05996000"],["111322.12000000","0.05996000"],["111321.47000000","0.03581000"],["111321.26000000","0.05996000"],["111321.17000000","0.03581000"],["111321.00000000","0.03581000"],["111320.66000000","0.00000000"],["111320.63000000","0.03581000"],["111320.57000000","0.03581000"],["111319.21000000","0.05996000"],["111316.19000000","0.02686000"],["111311.77000000","0.02686000"],["111308.54000000","0.02686000"],["111305.44000000","0.02686000"],["111295.09000000","0.00000000"],["111292.52000000","0.00000000"],["111252.89000000","0.00000000"],["111242.60000000","0.00187000"],["111224.98000000","0.00000000"],["111048.55000000","0.00000000"],["110009.52000000","0.00000000"],["100516.00000000","0.00100000"],["100515.00000000","0.00308000"],["89347.84000000","0.00000000"],["89334.64000000","0.00022000"],["78175.13000000","0.00000000"],["78170.51000000","0.00000000"],["42000.00000000","1.49196000"],["40200.59000000","0.00015000"],["40000.00000000","14.93722000"]],"a":[["111668.31000000","7.55580000"],["111668.37000000","0.00000000"],["111668.39000000","0.00010000"],["111668.42000000","0.00000000"],["111668.91000000","0.00000000"],["111669.16000000","0.00287000"],["111669.54000000","0.00005000"],["111669.84000000","0.00000000"],["111669.98000000","0.23248000"],["111669.99000000","0.00015000"],["111670.00000000","0.34134000"],["111670.01000000","0.00010000"],["111670.02000000","0.04668000"],["111671.24000000","0.04020000"],["111671.44000000","0.00010000"],["111671.45000000","0.06656000"],["111671.68000000","0.00000000"],["111671.79000000","0.00000000"],["111671.81000000","0.00000000"],["111672.01000000","0.00000000"],["111672.36000000","0.04055000"],["111673.89000000","0.11190000"],["111673.98000000","0.00000000"],["111673.99000000","0.00000000"],["111674.00000000","0.00000000"],["111674.01000000","0.00005000"],["111674.04000000","0.00000000"],["111674.57000000","0.00000000"],["111674.79000000","0.00000000"],["111675.30000000","0.00000000"],["111675.58000000","0.00000000"],["111675.59000000","1.39898000"],["111675.60000000","0.00005000"],["111675.61000000","0.36255000"],["111675.67000000","0.00000000"],["111675.98000000","0.00000000"],["111675.99000000","0.00000000"],["111676.00000000","0.01010000"],["111676.01000000","0.41632000"],["111676.07000000","0.00000000"],["111676.09000000","0.00000000"],["111676.45000000","0.00000000"],["111676.47000000","0.00000000"],["111676.48000000","0.00000000"],["111676.49000000","0.00000000"],["111676.83000000","0.00000000"],["111677.13000000","0.00000000"],["111677.14000000","0.00000000"],["111677.15000000","0.13612000"],["111677.16000000","0.13426000"],["111677.17000000","0.00000000"],["111677.18000000","0.00000000"],["111677.19000000","0.00000000"],["111677.22000000","0.00000000"],["111677.24000000","0.00000000"],["111677.27000000","0.00000000"],["111677.41000000","0.40406000"],["111677.42000000","0.18818000"],["111677.43000000","0.00000000"],["111677.48000000","0.00000000"],["111677.50000000","0.00000000"],["111677.81000000","0.04000000"],["111677.99000000","0.00000000"],["111678.00000000","0.00005000"],["111678.01000000","0.45020000"],["111678.02000000","0.04007000"],["111678.03000000","0.00000000"],["111678.17000000","0.00000000"],["111678.48000000","0.00005000"],["111678.54000000","0.00005000"],["111678.64000000","0.00000000"],["111678.65000000","0.00087000"],["111678.66000000","0.00000000"],["111678.67000000","0.26379000"],["111678.68000000","0.00000000"],["111678.73000000","0.00000000"],["111678.96000000","0.00000000"],["111679.29000000","0.04511000"],["111679.51000000","0.00000000"],["111679.77000000","0.00000000"],["111679.78000000","0.45401000"],["111679.79000000","0.30585000"],["111679.80000000","0.00088000"],["111679.85000000","0.00000000"],["111679.87000000","0.00000000"],["111680.70000000","0.00000000"],["111680.81000000","0.00007000"],["111680.89000000","0.00000000"],["111680.90000000","0.40306000"],["111680.91000000","0.04012000"],["111681.91000000","0.15000000"],["111681.93000000","0.48000000"],["111682.25000000","0.00010000"],["111682.26000000","0.00000000"],["111682.35000000","0.00000000"],["111682.74000000","0.00000000"],["111682.83000000","0.07048000"],["111682.95000000","0.00005000"],["111682.99000000","0.00000000"],["111683.00000000","0.00000000"],["111683.06000000","0.00000000"],["111683.18000000","0.00000000"],["111683.19000000","0.04007000"],["111683.20000000","0.00000000"],["111683.25000000","0.00000000"],["111683.46000000","0.00000000"],["111683.71000000","0.00000000"],["111683.77000000","0.00000000"],["111684.02000000","0.00000000"],["111684.04000000","0.00000000"],["111684.05000000","0.00000000"],["111684.23000000","0.00000000"],["111684.25000000","0.00000000"],["111684.26000000","0.04007000"],["111684.41000000","0.00000000"],["111684.42000000","0.00000000"],["111684.43000000","0.00000000"],["111684.50000000","0.00405000"],["111684.57000000","0.00000000"],["111684.63000000","0.00000000"],["111684.74000000","0.00000000"],["111684.78000000","0.00000000"],["111684.79000000","0.21252000"],["111684.80000000","0.40306000"],["111684.81000000","0.08829000"],["111684.82000000","0.00000000"],["111684.89000000","0.00000000"],["111684.90000000","0.00000000"],["111684.97000000","0.00900000"],["111685.06000000","0.00086000"],["111685.20000000","0.01343000"],["111685.35000000","0.00007000"],["111685.92000000","0.00000000"],["111685.95000000","0.00000000"],["111686.00000000","0.00400000"],["111686.51000000","0.00000000"],["111686.52000000","0.00000000"],["111686.53000000","0.00005000"],["111686.54000000","0.00000000"],["111686.55000000","0.00000000"],["111686.65000000","0.00799000"],["111686.77000000","0.00000000"],["111686.87000000","0.00000000"],["111686.88000000","0.06646000"],["111687.04000000","0.00358000"],["111687.20000000","0.00000000"],["111687.88000000","0.00000000"],["111688.03000000","0.00000000"],["111688.05000000","0.00000000"],["111688.30000000","0.00000000"],["111688.32000000","0.45000000"],["111688.63000000","0.02000000"],["111688.71000000","0.00537000"],["111688.73000000","0.04000000"],["111689.00000000","0.00270000"],["111689.01000000","0.00000000"],["111689.26000000","0.08504000"],["111689.28000000","0.00005000"],["111689.41000000","0.00000000"],["111689.43000000","0.81064000"],["111689.65000000","0.00000000"],["111689.95000000","0.00010000"],["111690.01000000","0.04800000"],["111690.13000000","0.00000000"],["111690.39000000","0.00000000"],["111690.61000000","0.00000000"],["111690.92000000","0.00000000"],["111691.14000000","0.04800000"],["111691.20000000","0.04800000"],["111691.28000000","0.00000000"],["111691.56000000","0.00000000"],["111691.79000000","0.00000000"],["111691.84000000","0.00000000"],["111692.01000000","0.00007000"],["111692.07000000","0.01755000"],["111692.09000000","0.00000000"],["111692.12000000","0.00000000"],["111692.36000000","0.00000000"],["111692.37000000","1.25396000"],["111692.69000000","0.00000000"],["111692.96000000","0.00000000"],["111693.03000000","0.04002000"],["111693.05000000","0.00000000"],["111693.20000000","0.00000000"],["111693.73000000","0.00010000"],["111694.10000000","0.30585000"],["111694.31000000","0.00000000"],["111695.09000000","0.00000000"],["111695.59000000","0.04800000"],["111695.76000000","0.00432000"],["111695.98000000","0.00300000"],["111696.27000000","0.00044000"],["111696.30000000","0.00000000"],["111696.55000000","0.00000000"],["111696.57000000","1.26284000"],["111696.58000000","1.25396000"],["111696.78000000","0.04800000"],["111696.89000000","0.00000000"],["111696.94000000","0.00010000"],["111697.02000000","0.00000000"],["111697.52000000","0.32213000"],["111699.95000000","0.00000000"],["111699.97000000","1.25396000"],["111699.98000000","0.00000000"],["111701.07000000","0.00000000"],["111701.20000000","0.00000000"],["111701.85000000","0.00000000"],["111702.16000000","0.00895000"],["111702.40000000","0.00005000"],["111702.43000000","0.00000000"],["111702.45000000","0.00000000"],["111703.05000000","0.32212000"],["111703.15000000","0.00000000"],["111703.76000000","0.08000000"],["111705.08000000","0.00000000"],["111705.60000000","0.00000000"],["111705.93000000","0.18869000"],["111706.89000000","0.00000000"],["111707.06000000","0.00000000"],["111708.03000000","0.05492000"],["111708.06000000","0.18409000"],["111708.07000000","0.00000000"],["111709.52000000","0.00270000"],["111710.37000000","0.00000000"],["111710.55000000","0.00000000"],["111710.65000000","0.32209000"],["111712.95000000","0.00000000"],["111714.22000000","0.00000000"],["111714.24000000","0.00000000"],["111714.50000000","0.00000000"],["111715.22000000","0.17904000"],["111715.77000000","0.00000000"],["111716.34000000","0.08503000"],["111716.91000000","0.00000000"],["111716.99000000","0.00000000"],["111717.19000000","0.00000000"],["111718.71000000","0.00000000"],["111719.18000000","0.00000000"],["111720.58000000","0.00000000"],["111720.69000000","0.00000000"],["111723.18000000","0.00000000"],["111724.58000000","0.00000000"],["111725.09000000","0.07200000"],["111726.00000000","0.00260000"],["111726.27000000","0.07200000"],["111727.42000000","0.00000000"],["111727.50000000","0.00000000"],["111727.65000000","0.00000000"],["111728.56000000","0.00000000"],["111731.72000000","0.00000000"],["111732.78000000","0.00000000"],["111732.80000000","0.00000000"],["111736.62000000","0.00615000"],["111737.98000000","0.00629000"],["111739.00000000","0.06791000"],["111739.93000000","0.02201000"],["111742.73000000","0.00223000"],["111744.36000000","0.00648000"],["111744.48000000","0.13426000"],["111746.59000000","0.00894000"],["111746.76000000","0.02286000"],["111748.76000000","0.13426000"],["111750.44000000","0.00005000"],["111751.99000000","0.13426000"],["111753.18000000","0.00000000"],["111753.23000000","0.00000000"],["111754.29000000","0.00223000"],["111756.15000000","0.00000000"],["111756.60000000","0.89435000"],["111756.82000000","1.34390000"],["111758.04000000","0.00000000"],["111759.08000000","0.00000000"],["111759.27000000","0.02126000"],["111759.54000000","0.00000000"],["111760.00000000","0.02233000"],["111760.09000000","0.00000000"],["111761.01000000","0.00000000"],["111762.62000000","0.02130000"],["111763.14000000","0.00000000"],["111764.23000000","0.00111000"],["111765.69000000","0.00000000"],["111765.86000000","0.04052000"],["111767.72000000","0.00000000"],["111767.99000000","0.00000000"],["111769.21000000","0.60705000"],["111769.82000000","0.00000000"],["111771.00000000","0.00000000"],["111771.18000000","0.00000000"],["111772.01000000","0.00000000"],["111773.34000000","0.01377000"],["111777.25000000","0.00000000"],["111778.04000000","0.22377000"],["111778.19000000","0.00000000"],["111778.81000000","0.42043000"],["111779.34000000","0.13433000"],["111780.32000000","0.00000000"],["111780.38000000","0.00000000"],["111782.62000000","0.00000000"],["111784.08000000","0.00000000"],["111784.44000000","0.00000000"],["111785.66000000","0.00000000"],["111786.11000000","0.00000000"],["111786.13000000","0.00000000"],["111786.67000000","0.00000000"],["111786.99000000","0.00000000"],["111788.94000000","0.00000000"],["111790.99000000","0.00000000"],["111791.05000000","0.00000000"],["111791.73000000","0.00000000"],["111791.77000000","0.00196000"],["111791.95000000","0.00000000"],["111793.22000000","0.16132000"],["111793.28000000","0.00000000"],["111794.92000000","0.00005000"],["111795.04000000","0.00000000"],["111795.48000000","0.09438000"],["111796.45000000","0.27417000"],["111798.99000000","0.81478000"],["111801.53000000","0.00000000"],["111801.62000000","0.52665000"],["111806.83000000","0.46720000"],["111808.68000000","0.06000000"],["111809.25000000","0.08803000"],["111811.61000000","0.00000000"],["111812.38000000","0.72981000"],["111813.43000000","0.15971000"],["111813.93000000","0.02417000"],["111814.14000000","0.00000000"],["111817.86000000","0.31005000"],["111817.88000000","0.05190000"],["111817.91000000","0.00000000"],["111818.80000000","0.00000000"],["111819.17000000","0.02417000"],["111819.99000000","0.00000000"],["111821.08000000","0.00000000"],["111821.09000000","0.00000000"],["111821.68000000","0.00000000"],["111821.83000000","0.00000000"],["111822.24000000","0.00000000"],["111822.73000000","0.00000000"],["111822.74000000","0.00000000"],["111822.95000000","0.00000000"],["111824.96000000","0.47905000"],["111827.42000000","0.00187000"],["111828.40000000","0.08794000"],["111830.67000000","0.00000000"],["111830.78000000","0.19474000"],["111832.35000000","0.08685000"],["111834.90000000","0.11762000"],["111836.40000000","0.00000000"],["111837.75000000","0.00000000"],["111841.08000000","0.00000000"],["111841.76000000","0.00000000"],["111841.77000000","0.00000000"],["111842.45000000","0.12100000"],["111844.63000000","0.00000000"],["111846.65000000","0.00000000"],["111858.41000000","0.00000000"],["111870.32000000","0.00000000"],["111901.17000000","0.00000000"],["111901.63000000","0.08895000"],["111902.55000000","0.00000000"],["111903.57000000","0.00000000"],["111904.04000000","0.00000000"],["111904.70000000","0.00000000"],["111905.26000000","0.00000000"],["111905.75000000","0.00000000"],["111906.12000000","0.00005000"],["111906.16000000","0.00000000"],["111917.14000000","4.87063000"],["111929.53000000","0.00000000"],["111936.96000000","0.00000000"],["111937.40000000","0.00000000"],["111937.42000000","0.00000000"],["111937.86000000","0.00000000"],["111940.01000000","0.00000000"],["111941.72000000","0.20961000"],["111943.13000000","0.00000000"],["111944.97000000","0.00000000"],["111946.61000000","0.00000000"],["111948.24000000","0.00000000"],["111949.02000000","0.00000000"],["111949.39000000","0.00000000"],["111949.85000000","0.00000000"],["111950.00000000","0.01540000"],["111950.10000000","0.00000000"],["111960.34000000","0.00079000"],["111960.65000000","0.05995000"],["111961.91000000","0.00000000"],["111969.12000000","0.00000000"],["111970.68000000","0.00000000"],["111971.14000000","0.00000000"],["111985.17000000","0.02686000"],["111985.69000000","0.00000000"],["111989.97000000","0.00000000"],["112013.63000000","0.00000000"],["112016.43000000","0.00000000"],["112022.01000000","0.00012000"],["112025.58000000","0.00000000"],["112055.58000000","0.00000000"],["112057.46000000","0.00000000"],["112057.52000000","0.00000000"],["112058.53000000","0.00000000"],["112058.62000000","0.00000000"],["112059.14000000","0.94995000"],["112059.27000000","0.00000000"],["112059.86000000","0.00000000"],["112060.08000000","0.00000000"],["112060.14000000","0.00000000"],["112060.56000000","0.00000000"],["112060.87000000","0.00000000"],["112060.88000000","0.00000000"],["112061.38000000","0.00000000"],["112061.40000000","0.00000000"],["112061.97000000","0.00000000"],["112062.01000000","0.00000000"],["112062.57000000","0.00000000"],["112063.75000000","0.00000000"],["112085.09000000","0.00000000"],["112094.58000000","0.00000000"],["112098.96000000","0.00000000"],["112152.25000000","0.00000000"],["112163.42000000","0.00000000"],["112322.74000000","0.00000000"],["113360.09000000","0.00000000"],["118649.74000000","0.00016000"],["119266.94000000","0.00016000"],["119884.14000000","0.00016000"],["120501.33000000","0.00016000"]]}
